Workbook
Name _: [1]低值易耗品!$A$1:$I$225
Name _.dbf: '[2]12进销存'!$A$3:$Q$235
Name _0.dbf: [3]累计销售!$A$6:$E$62
Name _11: [4]其他业务利润!$A$5:$G$12
Name _999年12月31日股份应收帐款.dbf: #REF!
Name _999年12月31日股份应收帐款.dbf: #REF!
Name _999年12月31日股份应收帐款.dbf: #REF!
Name a: #REF!
Name a: #REF!
Name a: #REF!
Name AFSDGEGQ: #REF!
Name AFSDGEGQ: #REF!
Name AFSDGEGQ: #REF!
Name ASDFA: #REF!
Name ASDFA: #REF!
Name ASDFA: #REF!
Name ASFDA: #REF!
Name ASFDA: #REF!
Name ASFDA: #REF!
Name clah: #REF!
Name clah: #REF!
Name clah: #REF!
Name clz: #REF!
Name clz: #REF!
Name clz: #REF!
Name fuck: [6]资产负债表!#REF!
Name fuck: [6]资产负债表!#REF!
Name fuck: [6]资产负债表!#REF!
Name OLE_LINK1: 'RP 098'!$A$32
Name OLE_LINK2: 'RP 098'!$A$35
Name OLE_LINK4: 'RP 098'!$A$29
Name OLE_LINK9: 'RP 098'!$A$33
Name Print_Area_MI: #REF!
Name Print_Area_MI: #REF!
Name Print_Area_MI: #REF!
Name Print_Area_MI: #REF!
Name Print_Area_MI: #REF!
Name SD: #REF!
Name SD: #REF!
Name SD: #REF!
Name SDF: #REF!
Name SDF: #REF!
Name SDF: #REF!
Name SDFA: #REF!
Name SDFA: #REF!
Name SDFA: #REF!
Name SDFSD: #REF!
Name SDFSD: #REF!
Name SDFSD: #REF!
Name SF: #REF!
Name SF: #REF!
Name SF: #REF!
Name Sheet1: #REF!
Name Sheet1: #REF!
Name Sheet1: #REF!
Name Sheet10: #REF!
Name Sheet10: #REF!
Name Sheet10: #REF!
Name Sheet11: #REF!
Name Sheet11: #REF!

Sheet 目录
A2: 20XX年XX月XX日ABC公司报告文件包 | E2: A6-1
A4: 序号 | B4: 文件名称 | C4: 目的 | D4: 工作表 | E4: 核对（是否完成）
B5: 基础信息 | C5: 一般信息 | D5: 基础信息 | E5: 完成
A6: =1+A5 -> 1 | B6: 会计政策 | C6: 一般信息 | D6: RP 001 | E6: 完成
A7: 2.1 | B7: 资产负债表 | C7: 财务报表 | D7: RP 002-1 | E7: 完成
A8: 2.2 | B8: 资产负债表 | C8: 财务报表 | D8: RP 002-2 | E8: 完成
A9: 3 | B9: 利润表 | C9: 财务报表 | D9: RP 003 | E9: 完成
A10: =A9+1 -> 4 | B10: 现金流量表 | C10: 财务报表 | D10: RP 004 | E10: 完成
A11: =A10+1 -> 5 | B11: 所有者权益变动表 | C11: 财务报表 | D11: RP 005 | E11: 完成
A12: =A11+1 -> 6 | B12: 准则差异调节表 | C12: 备查信息 | D12: RP 006 | E12: 完成
A13: =A12+1 -> 7 | B13: 集团间交易（销售、采购、费用） | C13: 集团间交易 | D13: RP 007 | E13: 完成
A14: =A13+1 -> 8 | B14: 集团间交易（资产、负债） | C14: 集团间交易 | D14: RP 008 | E14: 完成
A15: =A14+1 -> 9 | B15: 集团间交易（存货） | C15: 未实现内部利润 | D15: RP 009 | E15: 完成
A16: =A15+1 -> 10 | B16: 集团间交易（销售采购固定资产） | C16: 未实现内部利润 | D16: RP 010 | E16: 完成
A17: =A16+1 -> 11 | B17: 集团间交易（现金流量） | C17: 集团间交易 | D17: RP 011 | E17: 完成
A18: =A17+1 -> 12 | B18: 货币资金 | C18: 披露信息 | D18: RP 012 | E18: 完成
A19: =A18+1 -> 13 | B19: 交易性金融资产 | C19: 披露信息 | D19: RP 013 | E19: 完成
A20: =A19+1 -> 14 | B20: 以公允价值计量且其变动计入当期损益的金融资产 | C20: 披露信息 | D20: RP 014 | E20: 完成
A21: =1+A20 -> 15 | B21: 衍生金融资产 | C21: 披露信息 | D21: RP 015 | E21: 完成
A22: =1+A21 -> 16 | B22: 应收票据 | C22: 披露信息 | D22: RP 016 | E22: 完成
A23: =1+A22 -> 17 | B23: 应收账款 | C23: 披露信息 | D23: RP 017 | E23: 完成
A24: =1+A23 -> 18 | B24: 应收款项融资 | C24: 披露信息 | D24: RP 018 | E24: 完成
A25: =1+A24 -> 19 | B25: 预付款项 | C25: 披露信息 | D25: RP 019 | E25: 完成
A26: =1+A25 -> 20 | B26: 其他应收款（应收利息、应收股利、其他应收款） | C26: 披露信息 | D26: RP 020 | E26: 完成
A27: =A26+0.1 -> 20.1 | B27: 其中：应收利息 | C27: 披露信息 | D27: RP 020-1 | E27: 完成
A28: =A27+0.1 -> 20.2 | B28: 应收股利 | C28: 披露信息 | D28: RP 020-2 | E28: 完成
A29: =A28+0.1 -> 20.3 | B29: 其他应收款 | C29: 披露信息 | D29: RP 020-3 | E29: 完成
A30: =A26+1 -> 21 | B30: 存货 | C30: 披露信息 | D30: RP 021 | E30: 完成
A31: =A30+1 -> 22 | B31: 合同资产 | C31: 披露信息 | D31: RP 022 | E31: 完成
A32: =A31+1 -> 23 | B32: 持有待售资产和持有待售负债 | C32: 披露信息 | D32: RP 023 | E32: 完成
A33: =A32+1 -> 24 | B33: 一年内到期的非流动资产 | C33: 披露信息 | D33: RP 024 | E33: 完成
A34: =A33+1 -> 25 | B34: 其他流动资产 | C34: 披露信息 | D34: RP 025 | E34: 完成
A35: =A34+1 -> 26 | B35: 债权投资 | C35: 披露信息 | D35: RP 026 | E35: 完成
A36: =A35+1 -> 27 | B36: 可供出售金融资产 | C36: 披露信息 | D36: RP 027 | E36: 完成
A37: =A36+1 -> 28 | B37: 其他债权投资 | C37: 披露信息 | D37: RP 028 | E37: 完成
A38: =A37+1 -> 29 | B38: 持有至到期投资 | C38: 披露信息 | D38: RP 029 | E38: 完成
A39: =A38+1 -> 30 | B39: 长期应收款 | C39: 披露信息 | D39: RP 030 | E39: 完成
A40: =A39+1 -> 31 | B40: 设定受益计划净资产 | C40: 披露信息 | D40: RP 031 | E40: 完成
A41: =A40+1 -> 32 | B41: 长期股权投资 | C41: 披露信息 | D41: RP 032 | E41: 完成
A42: =A41+1 -> 33 | B42: 其他权益工具投资 | C42: 披露信息 | D42: RP 033 | E42: 完成
...

Sheet 基础信息
A1: 基础信息 | G1: BACK
A2: 一般信息
A4: 公司代码
A5: 公司简称
A6: 公司名称
A7: 报告币种代码
A8: 报告币种
A9: 财务期间
A12: 地址
A13: 董事长
A14: 总经理
A15: 审计师
A16: 会计负责人
... A22: 电子邮件
A25: 项目 | B25: 人数
A26: 总经理、董事会秘书、内审
A27: 一般经理
A28: 员工
A29: 合计
A30: 临时工
A31: 外包人员

Sheet RP 001
A1: 公司名称 | B1: =基础信息!C5 -> 0 | E1: BACK
A2: 财务期间 | B2: =基础信息!B9 -> 0
A3: 内容 | B3: 主要会计政策、会计估计（根据具体情况适当增减）
A4: 1 | B4: 会计年度
A6: 2 | B6: 营业周期
A8: 3 | B8: 记账本位币
A10: 4 | B10: 同一控制下和非同一控制下企业合并的会计处理
A12: 5 | B12: 合并财务报表编制方法
A14: 6 | B14: 合营安排的分类及共同经营的会计处理
A16: 7 | B16: 现金等价物
A18: 8 | B18: 外币折算
A20: 9 | B20: 金融工具
A22: 10 | B22: 公允价值计量
A24: 11 | B24: 应收票据及应收账款
A26: 12 | B26: 存货
... A74: 36 | B74: 非金融资产证券化业务的主要会计处理方法

Sheet RP 002-1
A1: 资产负债表 | F1: BACK
A2: =基础信息!B6 -> 0 | D2: 单位：人民币元
A3: 项目 | B3: 附注 | C3: 20X9.12.31 | D3: 20X8.12.31
A4: 流动资产:
A5: 货币资金 | C5: ='RP 006'!E6 -> 0
A6: 交易性金融资产
A7: 以公允价值计量且其变动计入当期损益的金融资产 | C7: ='RP 006'!E8 -> 0
A8: 衍生金融资产 （不适用的删除）
A9: 应收票据 | C9: ='RP 006'!E13 -> 0
A10: 应收账款 | C10: ='RP 006'!E14 -> 0
A11: 应收款项融资 | C11: ='RP 006'!E15 -> 0
A12: 预付款项 | C12: ='RP 006'!E17 -> 0
A13: 其他应收款
A14: 存货 | C14: ='RP 006'!E23 -> 0
A15: 合同资产
A16: 持有待售资产 （不适用的删除）
A17: 一年内到期的非流动资产 | C17: ='RP 006'!E28 -> 0
A18: 其他流动资产 | C18: ='RP 006'!E39 -> 0
A19: 流动资产合计 | C19: =SUM(C5:C18) -> 0 | D19: =SUM(D5:D18) -> 0
A20: 非流动资产:
A21: 债权投资
A22: 可供出售金融资产 | C22: ='RP 006'!E44 -> 0
A23: 其他债权投资
A24: 持有至到期投资 | C24: ='RP 006'!E46 -> 0
A25: 长期应收款 | C25: ='RP 006'!E47 -> 0
A26: 设定受益计划净资产 （不适用的删除）
A27: 长期股权投资 | C27: ='RP 006'!E51 -> 0
A28: 其他权益工具投资
A29: 其他非流动金融资产
A30: 投资性房地产 | C30: ='RP 006'!E56 -> 0
A31: 固定资产 | C31: ='RP 006'!E61 -> 0
A32: 在建工程 | C32: ='RP 006'!E62 -> 0
A33: 生产性生物资产 | C33: ='RP 006'!E63 -> 0
A34: 油气资产 | C34: ='RP 006'!E64 -> 0
A35: 使用权资产 | C35: ='RP 006'!E67 -> 0
A36: 无形资产 | C36: ='RP 006'!E68 -> 0
A37: 开发支出 | C37: ='RP 006'!E69 -> 0
A38: 商誉 | C38: ='RP 006'!E70 -> 0
A39: 长期待摊费用 | C39: ='RP 006'!E71 -> 0
A40: 递延所得税资产 | C40: ='RP 006'!E72 -> 0
...

Sheet RP 002-2
A1: 资产负债表（续） | F1: BACK
A3: 项目 | B3: 附注 | C3: 20X9.12.31 | D3: 20X8.12.31
A4: 流动负债:
A5: 短期借款 | C5: ='RP 006'!E81 -> 0
A6: 交易性金融负债
A7: 以公允价值计量且其变动计入当期损益的金融负债 | C7: ='RP 006'!E83 -> 0
A8: 衍生金融负债 （不适用的删除）
A9: 应付票据 | C9: ='RP 006'!E84 -> 0
A10: 应付账款 | C10: ='RP 006'!E85 -> 0
A11: 预收款项 | C11: ='RP 006'!E87 -> 0
A12: 合同负债
A13: 应付职工薪酬 | C13: ='RP 006'!E89 -> 0
A14: 应交税费 | C14: ='RP 006'!E90 -> 0
A15: 其他应付款 | C15: ='RP 006'!E91 -> 0
A16: 持有待售负债（不适用的删除）
A17: 一年内到期的非流动负债 | C17: ='RP 006'!E93 -> 0
A18: 其他流动负债 | C18: ='RP 006'!E102 -> 0
A19: 流动负债合计 | C19: =SUM(C5:C18) -> 0 | D19: =SUM(D5:D18) -> 0
A20: 非流动负债:
A21: 长期借款 | C21: ='RP 006'!E105 -> 0
A22: 应付债券 | C22: ='RP 006'!E106 -> 0
A23: 其中：优先股（不适用的删除）
A24: 永续债（不适用的删除）
A25: 租赁负债 | C25: ='RP 006'!E106 -> 0
A26: 长期应付款 | C26: ='RP 006'!E108 -> 0
A27: 长期应付职工薪酬（不适用的删除）
A28: 预计负债 | C28: ='RP 006'!E111 -> 0
A29: 递延收益
A30: 递延所得税负债 | C30: ='RP 006'!E113 -> 0
A31: 其他非流动负债 | C31: ='RP 006'!E114 -> 0
A32: 非流动负债合计 | C32: =SUM(C21:C31) -> 0 | D32: =SUM(D21:D31) -> 0
A33: 负债合计 | C33: =C19+C32 -> 0 | D33: =D19+D32 -> 0
A34: 所有者权益（或股东权益）：
A35: 实收资本（或股本） | C35: ='RP 006'!E118 -> 0
A36: 其他权益工具（不适用的删除）
A37: 其中：优先股
A38: 永续债
A39: 资本公积 | C39: ='RP 006'!E122 -> 0
A40: 减：库存股 | C40: ='RP 006'!E123 -> 0
A41: 其他综合收益
...

Sheet RP 003 
A1: 利润表 | H1: BACK
A2: =基础信息!B6 -> 0 | F2: 单位：人民币元
A3: 项目 | B3: 附注 | C3: 20X9年度 | E3: 20X8年度
A5: 一、营业收入 | C5: ='RP 006'!E137 -> 0
A6: 减：营业成本 | C6: ='RP 006'!E138 -> 0
A7: 税金及附加 | C7: ='RP 006'!E139 -> 0
A8: 销售费用 | C8: ='RP 006'!E140 -> 0
A9: 管理费用 | C9: ='RP 006'!E141 -> 0
A10: 研发费用
A11: 财务费用 | C11: ='RP 006'!E143 -> 0
A12: 其中：利息费用
A13: 利息收入
A14: 加：其他收益
A15: 投资收益(损失以“-”号填列） | C15: ='RP 006'!E143 -> 0
A16: 其中：对联营企业和合营企业的投资收益 | C16: ='RP 006'!E153 -> 0
A17: 以摊余成本计量的金融资产终止确认收益（损失以“-”号填列） | C17: ='RP 006'!E152 -> 0
A18: 净敞口套期收益（损失以“-”号填列）
A19: 公允价值变动收益(损失以“-”号填列） | C19: ='RP 006'!E147 -> 0
A20: 信用减值损失(损失以“-”号填列）
A21: 资产减值损失(损失以“-”号填列） | C21: ='RP 006'!E153 -> 0
A22: 资产处置收益(损失以“-”号填列）
A23: 二、营业利润(亏损以“-”号填列） | C23: =C5-C6-C7-C8-C9-C10-C11-C21+C14+C15+C19+C22 -> 0 | D23: =D5-D6-D7-D8-D9-D10-D11-D21+D14+D15+D19+D22 -> 0 | E23: =E5-E6-E7-E8-E9-E10-E11-E21+E14+E15+E19+E22 -> 0
A24: 加：营业外收入 | C24: ='RP 006'!E156 -> 0
A25: 减：营业外支出 | C25: ='RP 006'!E157 -> 0
A26: 三、利润总额(亏损总额以“-”号填列） | C26: =C23+C24-C25 -> 0 | E26: =E23+E24-E25 -> 0
A27: 减：所得税费用 | C27: ='RP 006'!E159 -> 0
A28: 四、净利润(净亏损以“-”号填列） | C28: =C26-C27 -> 0 | E28: =E26-E27 -> 0
A29: （一）按经营持续性分类
A30: 1、持续经营净利润（净亏损以“-”号填列） | C30: ='RP 006'!E162 -> 0
A31: 2、终止经营净利润（净亏损以“-”号填列） | C31: ='RP 006'!E163 -> 0
A32: （二）按所有权归属分类
A33: 1、归属于母公司股东的净利润 | C33: ='RP 006'!E165 -> 0
A34: 2、少数股东损益 | C34: ='RP 006'!E166 -> 0
A35: 五、其他综合收益的税后净额
A36: 归属于母公司股东的其他综合收益的税后净额
A37: （一）以后不能重分类进损益的其他综合收益
A38: 1、重新计量设定受益计划变动额（不适用的删除）
A39: 2、权益法下不能转损益的其他综合收益（不适用的删除）
A40: 3、其他权益工具投资公允价值变动
A41: 4、企业自身信用风险公允价值变动
...

Sheet RP 004 
A1: 现金流量表 | K1: BACK
A2: =基础信息!B6 -> 0 | I2: 单位：人民币元
A3: 项目 | B3: 附注 | C3: 20X9年度 | E3: 20X3年度 | H3: 20X8年度
A5: 一、经营活动产生的现金流量：
A6: 销售商品、提供劳务收到的现金
A7: 收到的税费返还
A8: 收到其他与经营活动有关的现金
A9: 经营活动现金流入小计 | C9: =SUM(C6:C8) -> 0 | E9: =SUM(E6:E8) -> 0 | F9: =SUM(F6:F8) -> 0 | G9: =SUM(G6:G8) -> 0 | H9: =SUM(H6:H8) -> 0
A10: 购买商品、接受劳务支付的现金
A11: 支付给职工以及为职工支付的现金
A12: 支付的各项税费
A13: 支付其他与经营活动有关的现金
A14: 经营活动现金流出小计 | C14: =C10+C11+C12+C13 -> 0 | E14: =E10+E11+E12+E13 -> 0 | F14: =F10+F11+F12+F13 -> 0 | G14: =G10+G11+G12+G13 -> 0 | H14: =H10+H11+H12+H13 -> 0
A15: 经营活动产生的现金流量净额 | C15: =C9-C14 -> 0 | E15: =E9-E14 -> 0 | F15: =F9-F14 -> 0 | G15: =G9-G14 -> 0 | H15: =H9-H14 -> 0
A16: 二、投资活动产生的现金流量：
A17: 收回投资收到的现金
A18: 取得投资收益收到的现金
A19: 处置固定资产、无形资产和其他长期资产收回的 现金净额
A20: 处置子公司及其他营业单位收到的现金净额
A21: 收到其他与投资活动有关的现金
A22: 投资活动现金流入小计 | C22: =SUM(C17:C21) -> 0 | E22: =SUM(E17:E21) -> 0 | F22: =SUM(F17:F21) -> 0 | G22: =SUM(G17:G21) -> 0 | H22: =SUM(H17:H21) -> 0
A23: 购置固定资产、无形资产和其他长期资产支付的现金
A24: 投资支付的现金
A25: 取得子公司及其他营业单位支付的现金净额
A26: 支付其他与投资活动有关的现金
A27: 投资活动现金流出小计 | C27: =SUM(C23:C26) -> 0 | E27: =SUM(E23:E26) -> 0 | F27: =SUM(F23:F26) -> 0 | G27: =SUM(G23:G26) -> 0 | H27: =SUM(H23:H26) -> 0
A28: 投资活动产生的现金流量净额 | C28: =C22-C27 -> 0 | E28: =E22-E27 -> 0 | F28: =F22-F27 -> 0 | G28: =G22-G27 -> 0 | H28: =H22-H27 -> 0
A29: 三、筹资活动产生的现金流量：
A30: 吸收投资收到的现金
A31: 其中：子公司吸收少数股东权益性投资收到的现金
A32: 取得借款收到的现金
A33: 收到其他与筹资活动有关的现金
A34: 筹资活动现金流入小计 | C34: =C30+C32+C33 -> 0 | E34: =E30+E32+E33 -> 0 | F34: =F30+F32+F33 -> 0 | G34: =G30+G32+G33 -> 0 | H34: =H30+H32+H33 -> 0
A35: 偿还债务支付的现金
A36: 分配股利、利润或偿付利息支付的现金
A37: 其中：子公司支付少数股东的现金股利
A38: 支付其他与筹资活动有关的现金
A39: 其中：子公司减资支付给少数股东的现金
A40: 筹资活动现金流出小计 | C40: =C35+C36+C38 -> 0 | E40: =E35+E36+E38 -> 0 | F40: =F35+F36+F38 -> 0 | G40: =G35+G36+G38 -> 0 | H40: =H35+H36+H38 -> 0
A41: 筹资活动产生的现金流量净额 | C41: =C34-C40 -> 0 | E41: =E34-E40 -> 0 | F41: =F34-F40 -> 0 | G41: =G34-G40 -> 0 | H41: =H34-H40 -> 0
...

Sheet RP 005
B1: 合并股东（或所有者）权益变动表 | O1: 合并股东（或所有者）权益变动表
O2: BACK
A3: =基础信息!B6 -> 0 | N3: 单位：人民币元 | AA3: 单位：人民币元
A4: 项 目 | B4: 20X9年度 | O4: 20X7年度
B5: 归属于母公司股东权益 | M5: 少数股东 权益 | N5: 股东（或所有者）权益 合计 | O5: 归属于母公司股东权益 | Z5: 少数股东 权益 | AA5: 股东（或所有者）权益 合计
B6: 股本 | C6: 其他权益工具（不适用的删除） | F6: 资本公积 | G6: 减：库存股 | H6: 其他综合收益 | I6: 专项储备 | J6: 盈余公积 | K6: 未分配利润 | L6: 其他 | O6: 股本 | P6: 其他权益工具（不适用的删除） | S6: 资本公积 | T6: 减：库存股 | U6: 其他综合收益 | V6: 专项储备 | W6: 盈余公积 | X6: 未分配利润 | Y6: 其他
C7: 优先股 | D7: 永续债 | E7: 其他 | P7: 优先股 | Q7: 永续债 | R7: 其他
A8: 一、上年年末余额 | B8: =O36 -> 0 | C8: =P36 -> 0 | D8: =Q36 -> 0 | E8: =R36 -> 0 | F8: =S36 -> 0 | G8: =T36 -> 0 | H8: =U36 -> 0 | I8: =V36 -> 0 | ... M8: =Z36 -> 0 | N8: =B8+C8+D8+E8+F8-G8+H8+I8+J8+K8+L8+M8 -> 0 | AA8: =O8+P8+Q8+R8+S8-T8+V8+W8+X8+Y8+Z8+U8 -> 0
A9: 加：会计政策变更 | B9: —— | C9: —— | D9: —— | E9: —— | F9: —— | G9: —— | H9: —— | I9: —— | J9: —— | K9: —— | L9: —— | M9: —— | N9: —— | AA9: =O9+P9+Q9+R9+S9-T9+V9+W9+X9+Y9+Z9+U9 -> 0
A10: 前期差错更正 | B10: —— | C10: —— | D10: —— | E10: —— | F10: —— | G10: —— | H10: —— | I10: —— | J10: —— | K10: —— | L10: —— | M10: —— | N10: —— | AA10: =O10+P10+Q10+R10+S10-T10+V10+W10+X10+Y10+Z10+U10 -> 0
A11: 同一控制下企业合并 | N11: =B11+C11+D11+E11+F11-G11+H11+I11+J11+K11+L11+M11 -> 0 | AA11: =O11+P11+Q11+R11+S11-T11+V11+W11+X11+Y11+Z11+U11 -> 0
A12: 其他 | N12: =B12+C12+D12+E12+F12-G12+H12+I12+J12+K12+L12+M12 -> 0 | AA12: =O12+P12+Q12+R12+S12-T12+V12+W12+X12+Y12+Z12+U12 -> 0
A13: 二、本年年初余额 | B13: =B8+B12 -> 0 | C13: =C8+C12 -> 0 | D13: =D8+D12 -> 0 | E13: =E8+E12 -> 0 | F13: =F8+F12 -> 0 | G13: =G8+G12 -> 0 | H13: =H8+H12 -> 0 | I13: =I8+I12 -> 0 | ... M13: =M8+M12 -> 0 | N13: =B13+C13+D13+E13+F13-G13+H13+I13+J13+K13+L13+M13 -> 0 | O13: =O8+O9+O10+O12 -> 0 | P13: =P8+P9+P10+P12 -> 0 | Q13: =Q8+Q9+Q10+Q12 -> 0 | R13: =R8+R9+R10+R12 -> 0 | S13: =S8+S9+S10+S12 -> 0 | T13: =T8+T9+T10+T12 -> 0 | U13: =U8+U9+U10+U12 -> 0 | V13: =V8+V9+V10+V12 -> 0 | ... Z13: =Z8+Z9+Z10+Z12 -> 0 | AA13: =O13+P13+Q13+R13+S13-T13+V13+W13+X13+Y13+Z13+U13 -> 0
A14: 三、本年增减变动金额（减少以“-”号填列） | B14: =B15+B16+B21+B25+B32 -> 0 | C14: =C15+C16+C21+C25+C32 -> 0 | D14: =D15+D16+D21+D25+D32 -> 0 | E14: =E15+E16+E21+E25+E32 -> 0 | F14: =F15+F16+F21+F25+F32 -> 0 | G14: =G15+G16+G21+G25+G32 -> 0 | H14: =H15+H16+H21+H25+H32 -> 0 | I14: =I15+I16+I21+I25+I32 -> 0 | ... M14: =M15+M16+M21+M25+M32 -> 0 | N14: =B14+C14+D14+E14+F14-G14+H14+I14+J14+K14+L14+M14 -> 0 | O14: =O15+O16+O21+O25+O32 -> 0 | P14: =P15+P16+P21+P25+P32 -> 0 | Q14: =Q15+Q16+Q21+Q25+Q32 -> 0 | R14: =R15+R16+R21+R25+R32 -> 0 | S14: =S15+S16+S21+S25+S32 -> 0 | T14: =T15+T16+T21+T25+T32 -> 0 | U14: =U15+U16+U21+U25+U32 -> 0 | V14: =V15+V16+V21+V25+V32 -> 0 | ... Z14: =Z15+Z16+Z21+Z25+Z32 -> 0 | AA14: =O14+P14+Q14+R14+S14-T14+V14+W14+X14+Y14+Z14+U14 -> 0
A15: （一）综合收益总额 | N15: =B15+C15+D15+E15+F15-G15+H15+I15+J15+K15+L15+M15 -> 0 | AA15: =O15+P15+Q15+R15+S15-T15+V15+W15+X15+Y15+Z15+U15 -> 0
A16: （二）股东（或所有者）投入和减少资本 | B16: =SUM(B17:B20) -> 0 | C16: =SUM(C17:C20) -> 0 | D16: =SUM(D17:D20) -> 0 | E16: =SUM(E17:E20) -> 0 | F16: =SUM(F17:F20) -> 0 | G16: =SUM(G17:G20) -> 0 | H16: =SUM(H17:H20) -> 0 | I16: =SUM(I17:I20) -> 0 | ... M16: =SUM(M17:M20) -> 0 | N16: =B16+C16+D16+E16+F16-G16+H16+I16+J16+K16+L16+M16 -> 0 | O16: =SUM(O17:O20) -> 0 | P16: =SUM(P17:P20) -> 0 | Q16: =SUM(Q17:Q20) -> 0 | R16: =SUM(R17:R20) -> 0 | S16: =SUM(S17:S20) -> 0 | T16: =SUM(T17:T20) -> 0 | U16: =SUM(U17:U20) -> 0 | V16: =SUM(V17:V20) -> 0 | ... Z16: =SUM(Z17:Z20) -> 0 | AA16: =O16+P16+Q16+R16+S16-T16+V16+W16+X16+Y16+Z16+U16 -> 0
A17: 1．股东投入资本 | N17: =B17+C17+D17+E17+F17-G17+H17+I17+J17+K17+L17+M17 -> 0 | AA17: =O17+P17+Q17+R17+S17-T17+V17+W17+X17+Y17+Z17+U17 -> 0
A18: 2. 其他权益工具持有者投入资本（不适用的删除） | N18: =B18+C18+D18+E18+F18-G18+H18+I18+J18+K18+L18+M18 -> 0 | AA18: =O18+P18+Q18+R18+S18-T18+V18+W18+X18+Y18+Z18+U18 -> 0
A19: 3．股份支付计入股东权益的金额 | N19: =B19+C19+D19+E19+F19-G19+H19+I19+J19+K19+L19+M19 -> 0 | AA19: =O19+P19+Q19+R19+S19-T19+V19+W19+X19+Y19+Z19+U19 -> 0
A20: 4．其他 | N20: =B20+C20+D20+E20+F20-G20+H20+I20+J20+K20+L20+M20 -> 0 | AA20: =O20+P20+Q20+R20+S20-T20+V20+W20+X20+Y20+Z20+U20 -> 0
A21: （三）利润分配 | B21: =SUM(B22:B24) -> 0 | C21: =SUM(C22:C24) -> 0 | D21: =SUM(D22:D24) -> 0 | E21: =SUM(E22:E24) -> 0 | F21: =SUM(F22:F24) -> 0 | G21: =SUM(G22:G24) -> 0 | H21: =SUM(H22:H24) -> 0 | I21: =SUM(I22:I24) -> 0 | ... M21: =SUM(M22:M24) -> 0 | N21: =B21+C21+D21+E21+F21-G21+H21+I21+J21+K21+L21+M21 -> 0 | O21: =SUM(O22:O24) -> 0 | P21: =SUM(P22:P24) -> 0 | Q21: =SUM(Q22:Q24) -> 0 | R21: =SUM(R22:R24) -> 0 | S21: =SUM(S22:S24) -> 0 | T21: =SUM(T22:T24) -> 0 | U21: =SUM(U22:U24) -> 0 | V21: =SUM(V22:V24) -> 0 | ... Z21: =SUM(Z22:Z24) -> 0 | AA21: =O21+P21+Q21+R21+S21-T21+V21+W21+X21+Y21+Z21+U21 -> 0
A22: 1．提取盈余公积 | N22: =B22+C22+D22+E22+F22-G22+H22+I22+J22+K22+L22+M22 -> 0 | AA22: =O22+P22+Q22+R22+S22-T22+V22+W22+X22+Y22+Z22+U22 -> 0
A23: 2．对股东（或所有者）的分配 | N23: =B23+C23+D23+E23+F23-G23+H23+I23+J23+K23+L23+M23 -> 0 | AA23: =O23+P23+Q23+R23+S23-T23+V23+W23+X23+Y23+Z23+U23 -> 0
A24: 3．其他 | N24: =B24+C24+D24+E24+F24-G24+H24+I24+J24+K24+L24+M24 -> 0 | AA24: =O24+P24+Q24+R24+S24-T24+V24+W24+X24+Y24+Z24+U24 -> 0
A25: （四）股东权益内部结转 | B25: =SUM(B26:B31) -> 0 | C25: =SUM(C26:C31) -> 0 | D25: =SUM(D26:D31) -> 0 | E25: =SUM(E26:E31) -> 0 | F25: =SUM(F26:F31) -> 0 | G25: =SUM(G26:G31) -> 0 | H25: =SUM(H26:H31) -> 0 | I25: =SUM(I26:I31) -> 0 | ... M25: =SUM(M26:M31) -> 0 | N25: =B25+C25+D25+E25+F25-G25+H25+I25+J25+K25+L25+M25 -> 0 | O25: =SUM(O26:O31) -> 0 | P25: =SUM(P26:P31) -> 0 | Q25: =SUM(Q26:Q31) -> 0 | R25: =SUM(R26:R31) -> 0 | S25: =SUM(S26:S31) -> 0 | T25: =SUM(T26:T31) -> 0 | U25: =SUM(U26:U31) -> 0 | V25: =SUM(V26:V31) -> 0 | ... Z25: =SUM(Z26:Z31) -> 0 | AA25: =O25+P25+Q25+R25+S25-T25+V25+W25+X25+Y25+Z25+U25 -> 0
A26: 1．资本公积转增股本（或资本） | N26: =B26+C26+D26+E26+F26-G26+H26+I26+J26+K26+L26+M26 -> 0 | AA26: =O26+P26+Q26+R26+S26-T26+V26+W26+X26+Y26+Z26+U26 -> 0
A27: 2．盈余公积转增股本（或资本） | N27: =B27+C27+D27+E27+F27-G27+H27+I27+J27+K27+L27+M27 -> 0 | AA27: =O27+P27+Q27+R27+S27-T27+V27+W27+X27+Y27+Z27+U27 -> 0
A28: 3．盈余公积弥补亏损 | N28: =B28+C28+D28+E28+F28-G28+H28+I28+J28+K28+L28+M28 -> 0 | AA28: =O28+P28+Q28+R28+S28-T28+V28+W28+X28+Y28+Z28+U28 -> 0
A29: 4. 设定受益计划变动额结转留存收益（不适用的删除） | N29: =B29+C29+D29+E29+F29-G29+H29+I29+J29+K29+L29+M29 -> 0 | AA29: =O29+P29+Q29+R29+S29-T29+V29+W29+X29+Y29+Z29+U29 -> 0
A30: 5．其他综合收益结转留存收益
A31: 6．其他 | N31: =B31+C31+D31+E31+F31-G31+H31+I31+J31+K31+L31+M31 -> 0 | AA31: =O31+P31+Q31+R31+S31-T31+V31+W31+X31+Y31+Z31+U31 -> 0
A32: （五）专项储备 | B32: =B33+B34 -> 0 | C32: =C33+C34 -> 0 | D32: =D33+D34 -> 0 | E32: =E33+E34 -> 0 | F32: =F33+F34 -> 0 | G32: =G33+G34 -> 0 | H32: =H33+H34 -> 0 | I32: =SUM(I33:I34) -> 0 | J32: =SUM(J33:J34) -> 0 | K32: =SUM(K33:K34) -> 0 | L32: =SUM(L33:L34) -> 0 | M32: =SUM(M33:M34) -> 0 | N32: =B32+C32+D32+E32+F32-G32+H32+I32+J32+K32+L32+M32 -> 0 | O32: =SUM(O33:O34) -> 0 | P32: =SUM(P33:P34) -> 0 | Q32: =SUM(Q33:Q34) -> 0 | R32: =SUM(R33:R34) -> 0 | S32: =SUM(S33:S34) -> 0 | T32: =SUM(T33:T34) -> 0 | U32: =SUM(U33:U34) -> 0 | V32: =SUM(V33:V34) -> 0 | ... Z32: =SUM(Z33:Z34) -> 0 | AA32: =O32+P32+Q32+R32+S32-T32+V32+W32+X32+Y32+Z32+U32 -> 0
A33: 1．本期提取 | N33: =B33+C33+D33+E33+F33-G33+H33+I33+J33+K33+L33+M33 -> 0 | AA33: =O33+P33+Q33+R33+S33-T33+V33+W33+X33+Y33+Z33+U33 -> 0
A34: 2．本期使用（以负号填列） | N34: =B34+C34+D34+E34+F34-G34+H34+I34+J34+K34+L34+M34 -> 0 | AA34: =O34+P34+Q34+R34+S34-T34+V34+W34+X34+Y34+Z34+U34 -> 0
A35: （六）其他 | N35: =B35+C35+D35+E35+F35-G35+H35+I35+J35+K35+L35+M35 -> 0 | Z35: =SUM(O35:Y35) -> 0 | AA35: =SUM(P35:Z35) -> 0 | AB35: 备忘录第3号二、6
A36: 四、本年年末余额 | B36: =B13+B14 -> 0 | C36: =C13+C14 -> 0 | D36: =D13+D14 -> 0 | E36: =E13+E14 -> 0 | F36: =F13+F14 -> 0 | G36: =G13+G14 -> 0 | H36: =H13+H14 -> 0 | I36: =I13+I14 -> 0 | ... O36: =O13+O14 -> 0 | P36: 0 | Q36: 0 | R36: 0 | S36: =S13+S14 -> 0 | T36: =T13+T14 -> 0 | U36: 0 | V36: =V13+V14 -> 0 | W36: =W13+W14 -> 0 | X36: =X13+X14 -> 0 | Y36: =Y13+Y14 -> 0 | Z36: =Z13+Z14 -> 0 | AA36: =AA13+AA14 -> 0
A38: 公司法定代表人： | F38: 主管会计工作的公司负责人： | L38: 公司会计机构负责人： | S38: 主管会计工作的公司负责人： | Y38: 公司会计机构负责人：

Sheet RP 006
A1: 公司名称 | B1: =基础信息!B6 -> 0 | G1: BACK
A2: 财务期间 | B2: =基础信息!B9 -> 0 | J2: 准则差异调整-政策调整 | R2: 准则差异调整-列报调整
A3: 内容 | B3: 准则差异调节表
A4: 项目 | B4: HKFRS | C4: 准则列报调整 | D4: 准则政策调整调整 | E4: PRC | F4: 序号 | G4: 调整事项 | H4: 一级科目 | I4: 二级科目 | J4: 借方金额 | K4: 贷方金额 | L4: 备注 | M4: 索引号 | N4: 序号 | O4: 调整事项 | P4: 一级科目 | Q4: 二级科目 | R4: 借方金额 | S4: 贷方金额 | T4: 备注 | U4: 索引号
A5: 流动资产:
A6: 货币资金 | C6: =SUMIF($P:$P,A6,R:R)-SUMIF($P:$P,A6,S:S) -> 0 | D6: =SUMIF($H:$H,A6,J:J)-SUMIF($H:$H,A6,K:K) -> 0 | E6: =SUM(B6:D6) -> 0
A7: 交易性金融资产 | C7: =SUMIF($P:$P,A7,R:R)-SUMIF($P:$P,A7,S:S) -> 0 | D7: =SUMIF($H:$H,A7,J:J)-SUMIF($H:$H,A7,K:K) -> 0 | E7: =SUM(B7:D7) -> 0
A8: 以公允价值计量且其变动计入当期损益的金融资产 | C8: =SUMIF($P:$P,A8,R:R)-SUMIF($P:$P,A8,S:S) -> 0 | D8: =SUMIF($H:$H,A8,J:J)-SUMIF($H:$H,A8,K:K) -> 0 | E8: =SUM(B8:D8) -> 0
A9: 衍生金融资产 | C9: =SUMIF($P:$P,A9,R:R)-SUMIF($P:$P,A9,S:S) -> 0 | D9: =SUMIF($H:$H,A9,J:J)-SUMIF($H:$H,A9,K:K) -> 0 | E9: =SUM(B9:D9) -> 0
A10: 应收票据 | C10: =SUMIF($P:$P,A10,R:R)-SUMIF($P:$P,A10,S:S) -> 0 | D10: =SUMIF($H:$H,A10,J:J)-SUMIF($H:$H,A10,K:K) -> 0 | E10: =SUM(B10:D10) -> 0
A11: 应收票据坏账准备 | C11: =-SUMIF($P:$P,A11,R:R)+SUMIF($P:$P,A11,S:S) -> 0 | D11: =-SUMIF($H:$H,A11,J:J)+SUMIF($H:$H,A11,K:K) -> 0 | E11: =SUM(B11:D11) -> 0
A12: 应收票据净值 | B12: =B10-B11 -> 0 | C12: =C10-C11 -> 0 | D12: =D10-D11 -> 0 | E12: =E10-E11 -> 0
A13: 应收账款 | C13: =SUMIF($P:$P,A13,R:R)-SUMIF($P:$P,A13,S:S) -> 0 | D13: =SUMIF($H:$H,A13,J:J)-SUMIF($H:$H,A13,K:K) -> 0 | E13: =SUM(B13:D13) -> 0
A14: 应收账款坏账准备 | C14: =-SUMIF($P:$P,A14,R:R)+SUMIF($P:$P,A14,S:S) -> 0 | D14: =-SUMIF($H:$H,A14,J:J)+SUMIF($H:$H,A14,K:K) -> 0 | E14: =SUM(B14:D14) -> 0
A15: 应收账款净值 | B15: =B13-B14 -> 0 | C15: =C13-C14 -> 0 | D15: =D13-D14 -> 0 | E15: =E13-E14 -> 0
A16: 应收款项融资 | C16: =SUMIF($P:$P,A16,R:R)-SUMIF($P:$P,A16,S:S) -> 0 | D16: =SUMIF($H:$H,A16,J:J)-SUMIF($H:$H,A16,K:K) -> 0 | E16: =SUM(B16:D16) -> 0
A17: 预付款项 | C17: =SUMIF($P:$P,A17,R:R)-SUMIF($P:$P,A17,S:S) -> 0 | D17: =SUMIF($H:$H,A17,J:J)-SUMIF($H:$H,A17,K:K) -> 0 | E17: =SUM(B17:D17) -> 0
A18: 其他应收款 | C18: =SUMIF($P:$P,A18,R:R)-SUMIF($P:$P,A18,S:S) -> 0 | D18: =SUMIF($H:$H,A18,J:J)-SUMIF($H:$H,A18,K:K) -> 0 | E18: =SUM(B18:D18) -> 0
A19: 其他应收款坏账准备 | C19: =-SUMIF($P:$P,A19,R:R)+SUMIF($P:$P,A19,S:S) -> 0 | D19: =-SUMIF($H:$H,A19,J:J)+SUMIF($H:$H,A19,K:K) -> 0 | E19: =SUM(B19:D19) -> 0
A20: 其他应收款净值 | B20: =B18-B19 -> 0 | C20: =C18-C19 -> 0 | D20: =D18-D19 -> 0 | E20: =E18-E19 -> 0
A21: 存货 | C21: =SUMIF($P:$P,A21,R:R)-SUMIF($P:$P,A21,S:S) -> 0 | D21: =SUMIF($H:$H,A21,J:J)-SUMIF($H:$H,A21,K:K) -> 0 | E21: =SUM(B21:D21) -> 0
A22: 存货跌价准备 | C22: =-SUMIF($P:$P,A22,R:R)+SUMIF($P:$P,A22,S:S) -> 0 | D22: =-SUMIF($H:$H,A22,J:J)+SUMIF($H:$H,A22,K:K) -> 0 | E22: =SUM(B22:D22) -> 0
A23: 存货净值 | B23: =B21-B22 -> 0 | C23: =C21-C22 -> 0 | D23: =D21-D22 -> 0 | E23: =E21-E22 -> 0
A24: 合同资产 | C24: =C22-C23 -> 0 | D24: =D22-D23 -> 0 | E24: =E22-E23 -> 0
A25: 合同资产减值准备 | C25: =C23-C24 -> 0 | D25: =D23-D24 -> 0 | E25: =E23-E24 -> 0
A26: 合同资产净值 | B26: =B24-B25 -> 0 | C26: =C24-C25 -> 0 | D26: =D24-D25 -> 0 | E26: =E24-E25 -> 0
A27: 持有待售资产 | C27: =C22-C23 -> 0 | D27: =D22-D23 -> 0 | E27: =E22-E23 -> 0
A28: 一年内到期的非流动资产 | C28: =SUMIF($P:$P,A28,R:R)-SUMIF($P:$P,A28,S:S) -> 0 | D28: =SUMIF($H:$H,A28,J:J)-SUMIF($H:$H,A28,K:K) -> 0 | E28: =SUM(B28:D28) -> 0
A29: 待摊费用 | C29: =SUMIF($P:$P,A29,R:R)-SUMIF($P:$P,A29,S:S) -> 0 | D29: =SUMIF($H:$H,A29,J:J)-SUMIF($H:$H,A29,K:K) -> 0 | E29: =SUM(B29:D29) -> 0
A30: 内部应收 | C30: =SUMIF($P:$P,A30,R:R)-SUMIF($P:$P,A30,S:S) -> 0 | D30: =SUMIF($H:$H,A30,J:J)-SUMIF($H:$H,A30,K:K) -> 0 | E30: =SUM(B30:D30) -> 0
A31: 材料采购 | C31: =SUMIF($P:$P,A31,R:R)-SUMIF($P:$P,A31,S:S) -> 0 | D31: =SUMIF($H:$H,A31,J:J)-SUMIF($H:$H,A31,K:K) -> 0 | E31: =SUM(B31:D31) -> 0
A32: 公司间应收 | C32: =SUMIF($P:$P,A32,R:R)-SUMIF($P:$P,A32,S:S) -> 0 | D32: =SUMIF($H:$H,A32,J:J)-SUMIF($H:$H,A32,K:K) -> 0 | E32: =SUM(B32:D32) -> 0
A33: 应收下级单位利润 | C33: =SUMIF($P:$P,A33,R:R)-SUMIF($P:$P,A33,S:S) -> 0 | D33: =SUMIF($H:$H,A33,J:J)-SUMIF($H:$H,A33,K:K) -> 0 | E33: =SUM(B33:D33) -> 0
A34: 应收采购款 | C34: =SUMIF($P:$P,A34,R:R)-SUMIF($P:$P,A34,S:S) -> 0 | D34: =SUMIF($H:$H,A34,J:J)-SUMIF($H:$H,A34,K:K) -> 0 | E34: =SUM(B34:D34) -> 0
A35: 应收采购款坏账准备 | C35: =-SUMIF($P:$P,A35,R:R)+SUMIF($P:$P,A35,S:S) -> 0 | D35: =-SUMIF($H:$H,A35,J:J)+SUMIF($H:$H,A35,K:K) -> 0 | E35: =SUM(B35:D35) -> 0
A36: 应收采购款净额 | B36: =B34-B35 -> 0 | C36: =C34-C35 -> 0 | D36: =D34-D35 -> 0 | E36: =E34-E35 -> 0
A37: 空行 | C37: =SUMIF($P:$P,A37,R:R)-SUMIF($P:$P,A37,S:S) -> 0 | D37: =SUMIF($H:$H,A37,J:J)-SUMIF($H:$H,A37,K:K) -> 0 | E37: =SUM(B37:D37) -> 0
A38: 空行 | C38: =SUMIF($P:$P,A38,R:R)-SUMIF($P:$P,A38,S:S) -> 0 | D38: =SUMIF($H:$H,A38,J:J)-SUMIF($H:$H,A38,K:K) -> 0 | E38: =SUM(B38:D38) -> 0
A39: 其他流动资产 | C39: =SUMIF($P:$P,A39,R:R)-SUMIF($P:$P,A39,S:S) -> 0 | D39: =SUMIF($H:$H,A39,J:J)-SUMIF($H:$H,A39,K:K) -> 0 | E39: =SUM(B39:D39) -> 0
A40: 流动资产合计 | B40: =SUM(B6:B39)-B10-B11-B13-B14-B18-B19-B21-B22-B24-B25-B34-B35 -> 0 | C40: =SUM(C6:C39)-C10-C11-C13-C14-C18-C19-C21-C22-C24-C25-C34-C35 -> 0 | D40: =SUM(D6:D39)-D10-D11-D13-D14-D18-D19-D21-D22-D24-D25-D34-D35 -> 0 | E40: =SUM(E6:E39)-E10-E11-E13-E14-E18-E19-E21-E22-E24-E25-E34-E35 -> 0
...

Sheet RP 007
A1: 公司名称 | B1: =基础信息!B6 -> 0 | N1: BACK
A2: 财务期间 | B2: =基础信息!B9 -> 0
A3: 内容 | B3: 集团间交易（销售、采购、费用）
A4: 销售交易对象 | B4: 交易项目
B5: 主营业务收入 | F5: 主营业务成本 | J5: 其他业务收入 | K5: 财务费用 | L5: 营业外收入
B6: 小计 | C6: 硬件 | D6: 服务 | E6: 软件及软件开发 | F6: 小计 | G6: 硬件 | H6: 服务 | I6: 软件及软件开发 | K6: 利息收入
B7: =SUM(C7:E7) -> 0 | F7: =SUM(G7:I7) -> 0
B8: =SUM(C8:E8) -> 0 | F8: =SUM(G8:I8) -> 0
B9: =SUM(C9:E9) -> 0 | F9: =SUM(G9:I9) -> 0
B10: =SUM(C10:E10) -> 0 | F10: =SUM(G10:I10) -> 0
B11: =SUM(C11:E11) -> 0 | F11: =SUM(G11:I11) -> 0
B12: =SUM(C12:E12) -> 0 | F12: =SUM(G12:I12) -> 0
B13: =SUM(C13:E13) -> 0 | F13: =SUM(G13:I13) -> 0
B14: =SUM(C14:E14) -> 0 | F14: =SUM(G14:I14) -> 0
B15: =SUM(C15:E15) -> 0 | F15: =SUM(G15:I15) -> 0
B16: =SUM(C16:E16) -> 0 | F16: =SUM(G16:I16) -> 0
B17: =SUM(C17:E17) -> 0 | F17: =SUM(G17:I17) -> 0
B18: =SUM(C18:E18) -> 0 | F18: =SUM(G18:I18) -> 0
... B20: =SUM(C20:E20) -> 0 | F20: =SUM(G20:I20) -> 0
A21: 合计 | B21: =SUM(B7:B20) -> 0 | C21: =SUM(C7:C20) -> 0 | D21: =SUM(D7:D20) -> 0 | E21: =SUM(E7:E20) -> 0 | F21: =SUM(F7:F20) -> 0 | G21: =SUM(G7:G20) -> 0 | H21: =SUM(H7:H20) -> 0 | I21: =SUM(I7:I20) -> 0 | ... L21: =SUM(L7:L20) -> 0
A23: 采购及费用交易对象 | B23: 交易项目
B24: 采购 | F24: 其他业务成本 | G24: 财务费用 | I24: 营业外支出
B25: 小计 | C25: 硬件 | D25: 服务 | E25: 软件及软件开发 | G25: 利息支出 | H25: 手续费
B26: =SUM(C26:E26) -> 0
B27: =SUM(C27:E27) -> 0
B28: =SUM(C28:E28) -> 0
B29: =SUM(C29:E29) -> 0
B30: =SUM(C30:E30) -> 0
B31: =SUM(C31:E31) -> 0
B32: =SUM(C32:E32) -> 0
B33: =SUM(C33:E33) -> 0
B34: =SUM(C34:E34) -> 0
B35: =SUM(C35:E35) -> 0
B36: =SUM(C36:E36) -> 0
B37: =SUM(C37:E37) -> 0
... B39: =SUM(C39:E39) -> 0
A40: 合计 | B40: =SUM(B26:B39) -> 0 | C40: =SUM(C26:C39) -> 0 | D40: =SUM(D26:D39) -> 0 | E40: =SUM(E26:E39) -> 0 | F40: =SUM(F26:F39) -> 0 | G40: =SUM(G26:G39) -> 0 | I40: =SUM(I26:I39) -> 0

Sheet RP 008
A1: 公司名称 | B1: =基础信息!B6 -> 0 | L1: BACK
A2: =基础信息!A9 -> 财务期间 | B2: =日期2 -> 0
A3: 内容 | B3: 集团内部往来余额
A4: 债权交易项目 | B4: 应收票据 | G4: 应收账款 | L4: 预付账款 | Q4: 其他应收款
B5: 小计 | C5: 1年以内 | D5: 1-2年 | E5: 2-3年 | F5: 3年以上 | G5: 小计 | H5: 1年以内 | I5: 1-2年 | J5: 2-3年 | K5: 3年以上 | L5: 小计 | M5: 1年以内 | N5: 1-2年 | O5: 2-3年 | P5: 3年以上 | Q5: 小计 | R5: 1年以内 | S5: 1-2年 | T5: 2-3年 | U5: 3年以上
G6: =SUM(H6:K6) -> 0 | Q6: =SUM(R6:U6) -> 0
G7: =SUM(H7:K7) -> 0 | Q7: =SUM(R7:U7) -> 0
G8: =SUM(H8:K8) -> 0 | Q8: =SUM(R8:U8) -> 0
G9: =SUM(H9:K9) -> 0 | Q9: =SUM(R9:U9) -> 0
G10: =SUM(H10:K10) -> 0 | Q10: =SUM(R10:U10) -> 0
G11: =SUM(H11:K11) -> 0 | Q11: =SUM(R11:U11) -> 0
G12: =SUM(H12:K12) -> 0 | Q12: =SUM(R12:U12) -> 0
G13: =SUM(H13:K13) -> 0 | Q13: =SUM(R13:U13) -> 0
G14: =SUM(H14:K14) -> 0 | Q14: =SUM(R14:U14) -> 0
G15: =SUM(H15:K15) -> 0 | Q15: =SUM(R15:U15) -> 0
G16: =SUM(H16:K16) -> 0 | Q16: =SUM(R16:U16) -> 0
G17: =SUM(H17:K17) -> 0 | Q17: =SUM(R17:U17) -> 0
... G19: =SUM(H19:K19) -> 0 | Q19: =SUM(R19:U19) -> 0
A20: 合计 | G20: =SUM(G6:G19) -> 0 | H20: =SUM(H6:H19) -> 0 | I20: =SUM(I6:I19) -> 0 | J20: =SUM(J6:J19) -> 0 | K20: =SUM(K6:K19) -> 0 | Q20: =SUM(Q6:Q19) -> 0 | R20: =SUM(R6:R19) -> 0 | S20: =SUM(S6:S19) -> 0 | T20: =SUM(T6:T19) -> 0 | U20: =SUM(U6:U19) -> 0
A21: 债务交易项目 | B21: 应付票据 | G21: 应付账款 | L21: 预收账款 | Q21: 其他应付款
B22: 小计 | C22: 1年以内 | D22: 1-2年 | E22: 2-3年 | F22: 3年以上 | G22: 小计 | H22: 1年以内 | I22: 1-2年 | J22: 2-3年 | K22: 3年以上 | L22: 小计 | M22: 1年以内 | N22: 1-2年 | O22: 2-3年 | P22: 3年以上 | Q22: 小计 | R22: 1年以内 | S22: 1-2年 | T22: 2-3年 | U22: 3年以上
A23: =A6 -> 0 | G23: =SUM(H23:K23) -> 0 | Q23: =SUM(R23:U23) -> 0
A24: =A7 -> 0 | G24: =SUM(H24:K24) -> 0 | Q24: =SUM(R24:U24) -> 0
A25: =A8 -> 0 | G25: =SUM(H25:K25) -> 0 | Q25: =SUM(R25:U25) -> 0
A26: =A9 -> 0 | G26: =SUM(H26:K26) -> 0 | Q26: =SUM(R26:U26) -> 0
A27: =A10 -> 0 | G27: =SUM(H27:K27) -> 0 | Q27: =SUM(R27:U27) -> 0
A28: =A11 -> 0 | G28: =SUM(H28:K28) -> 0 | Q28: =SUM(R28:U28) -> 0
A29: =A12 -> 0 | G29: =SUM(H29:K29) -> 0 | Q29: =SUM(R29:U29) -> 0
A30: =A13 -> 0 | G30: =SUM(H30:K30) -> 0 | Q30: =SUM(R30:U30) -> 0
A31: =A14 -> 0 | G31: =SUM(H31:K31) -> 0 | Q31: =SUM(R31:U31) -> 0
A32: =A15 -> 0 | G32: =SUM(H32:K32) -> 0 | Q32: =SUM(R32:U32) -> 0
A33: =A16 -> 0 | G33: =SUM(H33:K33) -> 0 | Q33: =SUM(R33:U33) -> 0
A34: =A17 -> 0 | G34: =SUM(H34:K34) -> 0 | Q34: =SUM(R34:U34) -> 0
... A36: =A19 -> 0 | G36: =SUM(H36:K36) -> 0 | Q36: =SUM(R36:U36) -> 0
A37: 合计 | G37: =SUM(G23:G36) -> 0 | H37: =SUM(H23:H36) -> 0 | I37: =SUM(I23:I36) -> 0 | J37: =SUM(J23:J36) -> 0 | K37: =SUM(K23:K36) -> 0 | Q37: =SUM(Q23:Q36) -> 0 | R37: =SUM(R23:R36) -> 0 | S37: =SUM(S23:S36) -> 0 | T37: =SUM(T23:T36) -> 0 | U37: =SUM(U23:U36) -> 0

Sheet RP 009
A1: 公司名称 | B1: =基础信息!B6 -> 0 | I1: BACK
A2: =基础信息!A9 -> 财务期间 | B2: =基础信息!B9 -> 0
A3: 内容 | B3: 未实现内部利润
A4: 交易对象 | B4: 采购项目 | C4: 存货名称 | D4: 期末库存金额 | E4: 其中：期初结转至期末库存金额 | F4: 期末已计提跌价准备 | G4: 内部毛利率
A22: 合计

Sheet RP 010
A1: 公司名称 | B1: =基础信息!B6 -> 0 | K1: BACK
A2: =基础信息!A9 -> 财务期间 | B2: =基础信息!B9 -> 0
A3: 内容 | B3: 集团内部固定资产/无形资产交易
A4: 本期销售固定资产/无形资产
A5: 交易对象 | B5: 类别 | C5: 名称 | D5: 原值 | E5: 销售时累计折旧/累计摊销 | F5: 销售时已计提减值准备 | G5: 销售价款 | H5: 处置费用 | I5: 营业外收入（支出“-”） | J5: Check Box | R5: 交易主体 | S5: 类别 | T5: Category | U5: 是/否
J6: =IF(G6-(D6-E6-F6)-H6=I6,"OK","NO") -> OK | R6: TS | S6: 房屋及建筑物 | T6: Buildings | U6: √
J7: =IF(G7-(D7-E7-F7)-H7=I7,"OK","NO") -> OK | R7: JF | S7: 电子设备 | T7: Electronic equipment | U7: ×
J8: =IF(G8-(D8-E8-F8)-H8=I8,"OK","NO") -> OK | R8: US | S8: 办公设备 | T8: Office equipment
J9: =IF(G9-(D9-E9-F9)-H9=I9,"OK","NO") -> OK | R9: HK | S9: 运输设备 | T9: Transportation equipment
J10: =IF(G10-(D10-E10-F10)-H10=I10,"OK","NO") -> OK | R10: ST | S10: 房屋装修 | T10: House decoration
J11: =IF(G11-(D11-E11-F11)-H11=I11,"OK","NO") -> OK | R11: FJ | S11: 其他 | T11: Others
J12: =IF(G12-(D12-E12-F12)-H12=I12,"OK","NO") -> OK | R12: JDSY
J13: =IF(G13-(D13-E13-F13)-H13=I13,"OK","NO") -> OK | R13: SZ | S13: 类别 | T13: Category
J14: =IF(G14-(D14-E14-F14)-H14=I14,"OK","NO") -> OK | R14: NJ | S14: UCWEB软件
J15: =IF(G15-(D15-E15-F15)-H15=I15,"OK","NO") -> OK | R15: CD | S15: 其他软件 | T15: Other software
J16: =IF(G16-(D16-E16-F16)-H16=I16,"OK","NO") -> OK | R16: HWKJ | S16: 专利权及牌照 | T16: Patents and licences
J17: =IF(G17-(D17-E17-F17)-H17=I17,"OK","NO") -> OK | R17: HZWK | S17: 会所会籍 | T17: Club memberships
J18: =IF(G18-(D18-E18-F18)-H18=I18,"OK","NO") -> OK | R18: ITMS
J19: =IF(G19-(D19-E19-F19)-H19=I19,"OK","NO") -> OK | R19: HZKJ
J20: =IF(G20-(D20-E20-F20)-H20=I20,"OK","NO") -> OK | R20: HWST
J21: =IF(G21-(D21-E21-F21)-H21=I21,"OK","NO") -> OK | R21: GCGV
J22: =IF(G22-(D22-E22-F22)-H22=I22,"OK","NO") -> OK | R22: ASL
A23: 合计 | J23: =IF(G23-(D23-E23-F23)-H23=I23,"OK","NO") -> OK
A25: 采购固定资产/无形资产
A26: 交易对象 | B26: 类别 | C26: 名称 | D26: 购买日期 | E26: 采购成本 | F26: 折旧方法 | G26: 预计使用年限 | H26: 预计残值 | I26: 备注（发票）
A44: 合计

Sheet RP 011
A1: 公司名称 | B1: =基础信息!B6 -> 0 | M1: BACK
A2: =基础信息!A9 -> 财务期间 | B2: =基础信息!B9 -> 0
A3: 内容 | B3: 集团内部现金流
A4: 收到的现金 | B4: 销售商品、提供劳务收到的现金 | C4: 收到其他与经营活动有关的现金 | D4: 收回投资收到的现金 | E4: 取得投资收益收到的现金 | F4: 处置固定资产、无形资产和其他长期资产收回的现金净额 | G4: 处置子公司及其他营业单位收到的现金净额 | H4: 收到其他与投资活动有关的现金 | I4: 吸收投资收到的现金 | J4: 取得借款收到的现金 | K4: 收到其他与筹资活动有关的现金
A21: 合计 | B21: =SUM(B5:B20) -> 0 | C21: =SUM(C5:C20) -> 0
A23: 支付的现金 | B23: 购买商品、接受劳务支付的现金 | C23: 支付其他与经营活动有关的现金 | D23: 购置固定资产、无形资产和其他长期资产支付的现金 | E23: 投资支付的现金 | F23: 取得子公司及其他营业单位支付的现金净额 | G23: 支付其他与投资活动有关的现金 | I23: 偿还债务支付的现金 | J23: 分配股利、利润或偿付利息支付的现金 | K23: 支付其他与筹资活动有关的现金
A24: =A5 -> 0
A25: =A6 -> 0
A26: =A7 -> 0
A27: =A8 -> 0
A28: =A9 -> 0
A29: =A10 -> 0
A30: =A11 -> 0
A31: =A12 -> 0
A32: =A13 -> 0
A33: =A14 -> 0
A34: =A15 -> 0
A35: =A15 -> 0
A36: =A16 -> 0
A37: =A17 -> 0
A38: =A18 -> 0
A39: =A19 -> 0
A40: =A20 -> 0
A41: 合计 | B41: =SUM(B24:B40) -> 0 | C41: =SUM(C24:C40) -> 0

Sheet RP 012
A1: 公司名称 | B1: =基础信息!B5 -> 0 | F1: BACK
A2: 财务期间 | B2: =基础信息!B9 -> 0
A3: 内容 | B3: 货币资金
A5: 项 目 | B5: 期末
A6: 现金
A7: 银行存款
A8: 银行存款中：财务公司存款
A9: 其他货币资金
A10: 合 计 | B10: =SUM(B6:B9) -> 0
A11: 其中：存放在境外的款项总额
A12: 报表金额 | B12: ='RP 006'!E6 -> 0
B13: =B10-B12 -> 0
B14: =IF(B13=0,"OK","NO") -> OK
A15: 其中，外币如下：(除人民币以外的币种)
A16: 币 种 | B16: 期末
B17: 原 币 | C17: 汇率 | D17: 折合本位币
A18: 美元
A19: 港币
A22: 合 计 | B22: =SUM(B18:B21) -> 0 | D22: =SUM(D18:D21) -> 0
A24: 列示于现金流量表的现金及现金等价物包括： | B24: 金 额
A25: 期末货币资金
A26: 减：使用受到限制的存款
A27: 加：现金等价物
A28: 期末现金及现金等价物余额 | B28: =B25-B26+B27 -> 0
A29: 减：期初现金及现金等价物余额
A30: 现金及现金等价物净增加/（减少）额 | B30: =B28-B29 -> 0
A31: 说明：因抵押或冻结等对使用有限制、存放在境外、有潜在回收风险的款项内容

Sheet RP 013
A1: 公司名称 | B1: =基础信息!B6 -> 0 | D1: BACK
A2: 财务期间 | B2: =基础信息!B9 -> 0
A3: 内容 | B3: 交易性金融资产
A5: 项 目 | B5: 期末
A6: 债务工具投资
A7: 权益工具投资
A8: 衍生金融资产
A9: 其他
A10: 合 计 | B10: =SUM(B6:B9) -> 0
A11: 报表金额 | B11: ='RP 006'!E7 -> 0
B12: =B10-B11 -> 0
B13: =IF(B12=0,"OK","NO") -> OK
A14: 说明：
A15: （1）管理层认为交易性金融资产投资变现[不存在重大限制]。/〔存在下列限制：具体限制及原因〕）
A16: （2）请说明交易性金融资产期末公允价值的确认方法及对当期损益的影响，如采用估值技术确定公允价值时，应详细披露估值模型、重要参数的选取依据和估值过程，以及必要的敏感性分析。

Sheet RP 014
A1: 公司名称 | B1: =基础信息!B6 -> 0 | D1: BACK
A2: 财务期间 | B2: =基础信息!B9 -> 0
A3: 内容 | B3: 以公允价值计量且其变动计入当期损益的金融资产
A5: 项 目 | B5: 期末
A6: 交易性金融资产 | B6: =SUM(B7:B10) -> 0
A7: 其中：债务工具投资
A8: 权益工具投资
A9: 衍生金融资产
A10: 其他
A11: 指定为以公允价值计量且其变动计入当期损益的金融资产 | B11: =SUM(B12:B15) -> 0
A12: 其中：债务工具投资
A13: 权益工具投资
A14: 衍生金融资产
A15: 其他
A16: 合 计 | B16: =B6+B11 -> 0
A17: 报表金额 | B17: ='RP 006'!E8 -> 0
B18: =B16-B17 -> 0
B19: =IF(B18=0,"OK","NO") -> OK
A20: 说明：
A21: （1）管理层认为交易性金融资产投资变现[不存在重大限制]。/〔存在下列限制：具体限制及原因〕）
A22: （2）请说明交易性金融资产期末公允价值的确认方法及对当期损益的影响，如采用估值技术确定公允价值时，应详细披露估值模型、重要参数的选取依据和估值过程，以及必要的敏感性分析。

Sheet RP 015
A1: 公司名称 | B1: =基础信息!B6 -> 0 | D1: BACK
A2: 财务期间 | B2: =基础信息!B9 -> 0
A3: 内容 | B3: 衍生金融资产
A5: 项 目 | B5: 期末公允价值
A11: 合 计 | B11: =SUM(B6:B10) -> 0
A12: 报表金额 | B12: ='RP 006'!E9 -> 0
B13: =B11-B12 -> 0
B14: =IF(B13=0,"OK","NO") -> OK
A15: 说明：（衍生金融资产产生的原因以及相关会计处理。）

Sheet RP 016
A1: 公司名称 | B1: =基础信息!B6 -> 0 | F1: BACK
A2: 财务期间 | B2: =基础信息!B9 -> 0
A3: 内容 | B3: 应收票据
A5: 种 类 | B5: 期末
A6: 银行承兑汇票
A7: 商业承兑汇票
A8: 合 计 | B8: =SUM(B6:B7) -> 0
A10: 如发生减值披露格式如下：
A11: 种 类 | B11: 期末数
B12: 期末余额 | C12: 坏账准备 | D12: 期末账面价值
A13: 银行承兑汇票 | C13: 0
A14: 商业承兑汇票
A15: 合 计
A18: 其中，用于质押的票据如下：
A19: 种 类 | B19: 期末已质押金额
A20: 银行承兑汇票
A21: 商业承兑汇票
A23: 合 计 | B23: =SUM(B20:B22) -> 0
A25: 其中，已背书或贴现但尚未到期的应收票据
A26: 种 类 | B26: 期末终止确认金额 | C26: 期末未终止确认金额
A27: 银行承兑票据
A28: 商业承兑票据
A29: 可无限量添加行
A30: 合 计 | B30: =SUM(B27:B29) -> 0 | C30: =SUM(C27:C29) -> 0
A32: 其中，因出票人未履约而其转应收账款
A33: 种 类 | B33: 期末转应收账款金额
A34: 商业承兑票据
A37: 合 计 | B37: =SUM(B34:B36) -> 0

Sheet RP 017
A1: 公司名称 | B1: =基础信息!B6 -> 0 | H1: BACK
A2: 财务期间 | B2: =基础信息!B9 -> 0
A3: 内容 | B3: 应收账款
A4: （1）A、按风险分类
A5: 类 别 | B5: 期末
B6: 金 额 | C6: 坏账准备
A7: 单项金额重大的应收账款
A8: 单项金额不重大但按信用风险特征组合后该组合的风险较大的应收账款（组合依据见附注四（7））
A9: 其他不重大应收账款
A10: 合 计 | B10: =SUM(B7:B9) -> 0 | C10: =SUM(C7:C9) -> 0
A16: （1）B、期末单项金额重大并单项计提坏账准备的应收账款
A17: 应收账款（按单位） | B17: 账面余额 | C17: 坏账准备 | D17: 计提比例% | E17: 计提理由
A22: 合 计
A23: 核对金额 | B23: =B7 -> 0 | C23: =C7 -> 0
B24: =B22-B23 -> 0 | C24: =C22-C23 -> 0
B25: =IF(B24=0,"OK","NO") -> OK | C25: =IF(C24=0,"OK","NO") -> OK
A27: （1）C、账龄组合（和XX组合），按账龄分析法计提坏账准备的应收账款
A28: 账 龄 | B28: 期末
B29: 金 额 | C29: 坏账准备
A30: 1年以内
A31: 1至2年
A32: 2至3年
A33: 3至4年
A34: 4至5年
A35: 5年以上
A36: 合 计 | B36: =SUM(B30:B33) -> 0 | C36: =SUM(C30:C33) -> 0
A37: 核对金额 | B37: =B8 -> 0 | C37: =C8 -> 0
B38: =B36-B37 -> 0 | C38: =C36-C37 -> 0
B39: =IF(B38=0,"OK","NO") -> OK | C39: =IF(C38=0,"OK","NO") -> OK
A41: （2）本期计提、收回或转回的坏账准备情况
A42: 本期计提坏账准备金额XX元；本期收回或转回坏账准备金额XX元。
A43: 其中，本期坏账准备转回或收回金额重要的：
A44: 单位名称 | B44: 转回原因 | C44: 收回方式 | D44: 原确定坏账准备的依据 | E44: 转回或收回金额
A46: 可无限量添加行
A47: 合 计 | B47: =SUM(B45:B46) -> 0 | E47: =SUM(E45:E46) -> 0
A49: （3）本期实际核销的应收账款情况
A50: 项目 | B50: 核销金额
A51: 实际核销的应收账款
A53: 其中，重要的应收账款核销情况（逐项披露）：
A54: 单位名称 | B54: 应收账款性质 | C54: 核销金额 | D54: 核销原因 | E54: 履行的核销程序 | F54: 是否由关联交易产生
...

Sheet RP 018
A1: 公司名称 | B1: =基础信息!B6 -> 0 | E1: BACK
A2: 财务期间 | B2: =基础信息!B9 -> 0
A3: 内容 | B3: 应收款项融资
A12: 合 计 | B12: =SUM(B8:B11) -> 0
A13: 报表金额 | B13: ='RP 006'!E16 -> 0
B14: =B12-B13 -> 0
B15: =IF(B14=0,"OK","NO") -> OK

Sheet RP 019
A1: 公司名称 | B1: =基础信息!B6 -> 0 | E1: BACK
A2: 财务期间 | B2: =基础信息!B9 -> 0
A3: 内容 | B3: 预付款项
A4: （1）账龄分析
A5: 账 龄 | B5: 期 末
B6: 金 额 | C6: 比例%
A7: 1年以内
A8: 1至2年
A9: 2至3年
A10: 3年以上
A11: 合 计 | B11: =SUM(B7:B10) -> 0 | C11: =SUM(C7:C10) -> 0
A12: 报表金额 | B12: ='RP 006'!E17 -> 0
B13: =B11-B12 -> 0
B14: =IF(B13=0,"OK","NO") -> OK
A15: 说明：
A16: 账龄在1年以上的预付款项超过XX万元，请说明如下信息
A17: 公司名称 | B17: 预付款项金额 | C17: 账龄超过一年的原因
A19: （2）按预付对象归集的预付款项期末余额前五名单位情况
A20: 汇总披露格式：
A21: 本期按预付对象归集的期末余额前五名预付款项汇总金额XXXX元，占预付款项期末余额合计数的比例 %。
A22: 分别披露格式：
A23: 单位名称 | B23: 预付款项期末余额 | C23: 占预付款项期末余额合计数的比例%
A27: 合 计 | B27: =SUM(B24:B26) -> 0 | C27: =SUM(C24:C26) -> 0

Sheet RP 020
A1: 公司名称 | B1: =基础信息!B6 -> 0 | D1: BACK
A2: 财务期间 | B2: =基础信息!B9 -> 0
A3: 内容 | B3: 其他应收款
A4: 项 目 | B4: 期末
A5: 应收利息 | B5: ='RP 020-1'!B9 -> 0
A6: 应收股利 | B6: ='RP 020-2'!B8 -> 0
A7: 其他应收款 | B7: ='RP 020-3'!B10-'RP 020-3'!C10 -> 0
A8: 合 计 | B8: =SUM(B5:B7) -> 0
A9: 报表金额 | B9: ='RP 006'!E20 -> 0
B10: =B8-B9 -> 0
B11: =IF(B10=0,"OK","NO") -> OK

Sheet RP 020-1
A1: 公司名称 | B1: =基础信息!B6 -> 0 | G1: BACK
A2: 财务期间 | B2: =基础信息!B9 -> 0
A3: 内容 | B3: 应收利息
A4: 项 目 | B4: 期末
A5: 定期存款
A6: 委托贷款
A7: 债券投资
A8: 可无限量添加行
A9: 合 计 | B9: =SUM(B5:B8) -> 0
A13: 其中，重要的逾期应收利息如下：
A14: 借款单位 | B14: 期末数 | C14: 逾期时间 | D14: 逾期原因 | E14: 是否发生减值及其原因
A18: 合 计 | B18: =SUM(B15:B17) -> 0
A19: （对于重要的逾期应收利息，应按借款单位披露应收利息的期末余额、逾期时间和逾期原因、是否发生减值的判断。）

Sheet RP 020-2
A1: 公司名称 | B1: =基础信息!B6 -> 0 | G1: BACK
A2: 财务期间 | B2: =基础信息!B9 -> 0
A3: 内容 | B3: 应收股利
A5: 被投资单位名称 | B5: 期末
A8: 合 计 | B8: =SUM(B6:B7) -> 0
A13: 其中，重要的账龄超过1年的应收股利如下：
A14: 项目（或被投资单位） | B14: 期末数 | C14: 账龄 | D14: 未收回的原因 | E14: 是否发生减值及其判断依据
A18: 合 计 | B18: =SUM(B15:B17) -> 0
A19: （对于重要的账龄超过1 年的应收股利，应披露未收回的原因和对相关款项是否发生减值的判断。）

Sheet RP 020-3
A1: 公司名称 | B1: =基础信息!B6 -> 0 | H1: BACK
A2: 财务期间 | B2: =基础信息!B9 -> 0
A3: 内容 | B3: 其他应收款
A4: （1）A、按风险分类
A5: 类 别 | B5: 期末
B6: 金 额 | C6: 坏账准备
A7: 单项金额重大的其他应收款(XX万元以上)
A8: 单项金额不重大但按信用风险特征组合后该组合的风险较大的其他应收款
A9: 其他不重大其他应收款
A10: 合 计 | B10: =SUM(B7:B9) -> 0 | C10: =SUM(C7:C9) -> 0
A14: （1）B、期末单项金额重大并单项计提坏账准备的其他应收款
A15: 其他应收款（按单位） | B15: 账面余额 | C15: 坏账准备 | D15: 计提比例% | E15: 计提理由
A16: 可无限量添加行
A17: 合 计 | B17: =SUM(B16) -> 0 | C17: =SUM(C16) -> 0 | D17: =SUM(D16) -> 0
A19: （1）C、账龄组合（和XX组合），按账龄分析法计提坏账准备的其他应收账款
A20: 账 龄 | B20: 期末
B21: 金 额 | C21: 坏账准备
A22: 1年以内
A23: 1至2年
A24: 2至3年
A25: 3年以上
A26: 合 计 | B26: =SUM(B22:B25) -> 0 | C26: =SUM(C22:C25) -> 0
A27: 报表金额 | B27: =B8 -> 0 | C27: =C8 -> 0
B28: =B26-B27 -> 0 | C28: =C26-C27 -> 0
B29: =IF(B28=0,"OK","NO") -> OK | C29: =IF(C28=0,"OK","NO") -> OK
A31: （2）本期计提、收回或转回的坏账准备情况
A32: 本期计提坏账准备金额XX元；本期收回或转回坏账准备金额XX元。
A33: 其中，本期坏账准备转回或收回金额重要的：
A34: 单位名称 | B34: 转回原因 | C34: 收回方式 | D34: 原确定坏账准备的依据 | E34: 转回或收回金额
A36: 可无限量添加行
A37: 合 计 | E37: =SUM(E35:E36) -> 0
A39: （3）本期实际核销的其他应收账款情况
A40: 项目 | B40: 核销金额
A41: 实际核销的其他应收账款
A43: 其中，重要的其他应收账款核销情况（逐项披露）：
A44: 单位名称 | B44: 其他应收账款性质 | C44: 核销金额 | D44: 核销原因 | E44: 履行的核销程序 | F44: 是否由关联交易产生
A48: 合 计 | C48: =SUM(C45:C47) -> 0
A50: （4）其他应收款按款项性质披露
A51: 项 目 | B51: 期末余额
A52: 备用金
...

Sheet RP 021
A1: 公司名称 | B1: =基础信息!B6 -> 0 | I1: BACK
A2: 财务期间 | B2: =基础信息!B9 -> 0
A3: 内容 | B3: 存货
A4: （1）存货分项目列示
A5: 项 目 | B5: 期末数
B6: 账面余额 | C6: 跌价准备 | D6: 账面价值
A7: 原材料 | D7: =B7-C7 -> 0
A8: 自制半成品及在产品 | D8: =B8-C8 -> 0
A9: 库存商品（产成品） | D9: =B9-C9 -> 0
A10: 周转材料（包装物、低值易耗品等） | D10: =B10-C10 -> 0
A11: 消耗性生物资产 | D11: =B11-C11 -> 0
A12: 房地产开发成本 | D12: =B12-C12 -> 0
A13: 房地产开发产品 | D13: =B13-C13 -> 0
D14: =B14-C14 -> 0
A15: 其他 | D15: =B15-C15 -> 0
A16: 合 计 | B16: =SUM(B7:B15) -> 0 | C16: =SUM(C7:C15) -> 0 | D16: =SUM(D7:D15) -> 0
A17: 报表金额
B18: =B16-B17 -> 0 | C18: =C16-C17 -> 0 | D18: =D16-D17 -> 0
B19: =IF(B18=0,"OK","NO") -> OK | C19: =IF(C18=0,"OK","NO") -> OK | D19: =IF(D18=0,"OK","NO") -> OK
A20: （注：根据企业具体情况分类，房地产开发企业应增加“开发成本”、“开发产品”等种类）
A21: （2）存货跌价准备
A22: 存货种类 | B22: 期初数 | C22: 本期增加 | E22: 本期减少 | G22: 期末数
C23: 计提 | D23: 其他 | E23: 转回或转销 | F23: 其他
A24: 原材料
A25: 在产品
A26: 库存商品
A27: 周转材料
A28: 消耗性生物资产
A29: 合 计 | B29: =SUM(B24:B28) -> 0 | C29: =SUM(C24:C28) -> 0 | D29: =SUM(D24:D28) -> 0 | E29: =SUM(E24:E28) -> 0 | F29: =SUM(F24:F28) -> 0 | G29: =SUM(G24:G28) -> 0
A30: 报表金额 | G30: =C17 -> 0
G31: =IF(G30=0,"OK","NO") -> OK
A33: 存货跌价准备（续）
A34: 存货种类 | B34: 确定可变现净值的具体依据 | C34: 本期转回或转销存货跌价准备的原因
A35: 原材料
A36: 在产品
A37: 库存商品
A38: 周转材料
A39: 消耗性生物资产
A40: 合 计
A41: 【披露确定可变现净值的具体依据及本期转回或转销存货跌价准备的原因。】
...

Sheet RP 022
A1: 公司名称 | B1: =基础信息!B6 -> 0 | D1: BACK
A2: 财务期间 | B2: =基础信息!B9 -> 0
A3: 内容 | B3: 合同资产
A4: （1）合同资产
A5: 项 目 | B5: 期末数
B6: 账面余额 | C6: 跌价准备 | D6: 账面价值
D7: =B7-C7 -> 0
D8: =B8-C8 -> 0
D9: =B9-C9 -> 0
D10: =B10-C10 -> 0
D11: =B11-C11 -> 0
D12: =B12-C12 -> 0
A13: 合 计 | B13: =SUM(B7:B12) -> 0 | C13: =SUM(C7:C12) -> 0 | D13: =SUM(D7:D12) -> 0
A14: 报表金额
B15: =B13-B14 -> 0 | C15: =C13-C14 -> 0 | D15: =D13-D14 -> 0
B16: =IF(B15=0,"OK","NO") -> OK | C16: =IF(C15=0,"OK","NO") -> OK | D16: =IF(D15=0,"OK","NO") -> OK
A17: （注：根据企业具体情况分类。）
A18: （2）合同资产减值准备
A19: 合同资产种类 | B19: 期初数 | C19: 本期增加 | E19: 本期减少 | G19: 期末数
C20: 计提 | D20: 其他 | E20: 转回或转销 | F20: 其他
A27: 合 计 | B27: =SUM(B21:B26) -> 0 | C27: =SUM(C21:C26) -> 0 | D27: =SUM(D21:D26) -> 0 | E27: =SUM(E21:E26) -> 0 | F27: =SUM(F21:F26) -> 0 | G27: =SUM(G21:G26) -> 0
A28: 报表金额 | G28: =C14 -> 0
G29: =IF(G28=0,"OK","NO") -> OK

Sheet RP 023
A1: 公司名称 | B1: =基础信息!B6 -> 0 | G1: BACK
A2: 财务期间 | B2: =基础信息!B9 -> 0
A3: 内容 | B3: 持有待售资产和持有待售负债
A6: 项 目 | B6: 期末数
A7: 持有待售的资产：
A8: 持有待售的非流动资产
A9: 持有待售的处置组中的资产
A10: 其中：子公司A
A11: 分公司B
A12: 合 计 | B12: =SUM(B7:B11) -> 0
A13: 报表金额
B14: =B12-B13 -> 0
B15: =IF(B14=0,"OK","NO") -> OK
A17: 项 目 | B17: 期末数
A18: 持有待售的负债：
A19: 持有待售的处置组中的负债
A20: 其中：子公司A
A21: 分公司B
A22: 合 计 | B22: =SUM(B18:B21) -> 0
A23: 报表金额
B24: =B22-B23 -> 0
B25: =IF(B24=0,"OK","NO") -> OK
A27: 说明：（应当说明持有待售的非流动资产及持有待售的处置组中的资产产生的原因、内容及性质）
A28: （1）持有待售的非流动资产
A29: 期末，持有待售的资产的情况：
A30: 项 目 | B30: 账面价值 | C30: 公允价值 | D30: 预计处置费用 | E30: 预计处置时间
A35: 合 计
A37: （2）持有待售的处置组
A38: ①子公司A
A39: 项 目 | B39: 账面价值 | C39: 公允价值 | D39: 预计处置费用 | E39: 预计处置时间
A40: 持有待售的处置组中的资产
A41: 货币资金
A43: 固定资产
A44: ……
A46: 持有待售的处置组中的负债
A47: 应付账款
A48: 长期应付款
A49: ……
A51: ②分公司B
A52: 项 目 | B52: 账面价值 | C52: 公允价值 | D52: 预计处置费用 | E52: 预计处置时间
...

Sheet RP 024
A1: 公司名称 | B1: =基础信息!B6 -> 0 | D1: BACK
A2: 财务期间 | B2: =基础信息!B9 -> 0
A3: 内容 | B3: 一年内到期的非流动资产
A6: （1）项目分析
A7: 项 目 | B7: 期末数
A8: 1年内到期的长期应收款
A9: 1年内到期的持有至到期投资
A10: 1年内到期的长期待摊费用
A11: 其他
A12: 合 计 | B12: =SUM(B8:B11) -> 0
A13: 报表金额
B14: =B16-B13 -> 0
B15: =IF(B14=0,"OK","NO") -> OK
A16: 说明：（对于大额的一年内到期的非流动资产说明形成的原因、内容、性质。）
A18: 其他债权投资行项目，反映资产负债表日企业分类为以公允价值计量且其变动计入其他综合收益的长期债权投资的期末账面价值。该项目应根据"其他债权投资"科目的相关明细科目期末余额分析填列。自资产负债表日起一年内到期的长期债权投资的期末账面价值，在"一年内到期的非流动资产"行项目反映。

Sheet RP 025
A1: 公司名称 | B1: =基础信息!B6 -> 0 | D1: BACK
A2: 财务期间 | B2: =基础信息!B9 -> 0
A3: 内容 | B3: 其他流动资产
A4: 项 目 | B4: 期末
A5: 待抵扣进项税
A6: 预缴所得税
A7: 委托贷款
A8: 预缴其他税费
A9: 一年内到期的债权投资
A10: 合同取得成本
A11: 应收退货成本
A12: 合 计 | B12: =SUM(B5:B11) -> 0
A13: 报表金额
B14: =B12-B13 -> 0
B15: =IF(B14=0,"OK","NO") -> OK

Sheet RP 026
A1: 公司名称 | B1: =基础信息!B6 -> 0 | D1: BACK
A2: 财务期间 | B2: =基础信息!B9 -> 0
A3: 内容 | B3: 债权投资
A4: （1）债权投资情况
A5: 项 目 | B5: 期末数
B6: 账面余额 | C6: 减值准备 | D6: 账面价值
D7: =B7-C7 -> 0
D8: =B8-C8 -> 0
D9: =B9-C9 -> 0
D10: =B10-C10 -> 0
D11: =B11-C11 -> 0
A12: 小 计 | B12: =SUM(B7:B11) -> 0 | C12: =SUM(C7:C11) -> 0 | D12: =SUM(D7:D11) -> 0
A13: 减：1年内到期的债权投资
A14: 合 计 | B14: =B12-B13 -> 0 | C14: =C12-C13 -> 0 | D14: =D12-D13 -> 0
A15: 报表金额
D16: =D14-D15 -> 0
D17: =IF(D16=0,"OK","NO") -> OK
A19: （2）重要的债权投资
A20: 债权投资项目 | B20: 面值 | C20: 票面利率 | D20: 实际利率 | E20: 到期日
A22: 合 计 | B22: X.XX | C22: -- | D22: -- | E22: --

Sheet RP 027
A1: 公司名称 | B1: =基础信息!B6 -> 0 | D1: BACK
A2: 财务期间 | B2: =基础信息!B9 -> 0
A3: 内容 | B3: 可供出售金融资产
A4: （1）可供出售金融资产情况
A5: 项 目 | B5: 期末数
B6: 账面余额 | C6: 减值准备 | D6: 账面价值
A7: 可供出售债务工具 | D7: =B7-C7 -> 0
A8: 可供出售权益工具 | D8: =B8-C8 -> 0
A9: 其中：按公允价值计量 | D9: =B9-C9 -> 0
A10: 按成本计量 | D10: =B10-C10 -> 0
A11: 其他 | D11: =B11-C11 -> 0
A12: 合 计 | B12: =SUM(B7:B11) -> 0 | C12: =SUM(C7:C11) -> 0 | D12: =SUM(D7:D11) -> 0
A13: 报表金额
D14: =D12-D13 -> 0
D15: =IF(D14=0,"OK","NO") -> OK
A17: （2）按公允价值计量的可供出售金融资产
A18: 可供出售金融资产分类 | B18: 可供出售权益工具 | C18: 可供出售债务工具 | D18: 合计
A19: 权益工具的成本/债务工具的摊余成本A | D19: =B19+C19 -> 0
A20: 公允价值B | D20: =B20+C20 -> 0
A21: 累计计入其他综合收益的公允价值变动金额C | D21: =B21+C21 -> 0
A22: 已计提减值金额D | D22: =B22+C22 -> 0
A23: 报表金额 | D23: ='RP 006'!E44 -> 0
D24: =D20-D23 -> 0
D25: =IF(D24=0,"OK","NO") -> OK
A26: 【提示：C+D= A –B】
A27: （3）采用成本计量的可供出售权益工具
A28: 【15号文第十九条（十一），对划分为可供出售类别且采用成本计量的权益工具投资，应分项披露相关信息。】
A29: 【按照《CAS37-金融工具列报》第六十条 活跃市场中没有报价且其公允价值无法可靠计量的权益工具投资以及与该工具挂钩的衍生工具，企业应当披露下列信息：
A30: （一）对金融工具的描述及其账面价值，以及因公允价值无法可靠计量而未披露其公允价值的事实和说明。
A31: （二）金融工具的相关市场信息。
A32: （三）企业是否有意图及如何处置这些金融工具。
A33: （四）已终止确认金融工具的事实，以及终止确认时的账面价值和形成的利得或损失。】
A34: 被投资单位 | B34: 账面余额 | F34: 减值准备 | J34: 在被投资单位持股比例(%) | K34: 本期现金红利
B35: 期初 | C35: 本期增加 | D35: 本期减少 | E35: 期末 | F35: 期初 | G35: 本期增加 | H35: 本期减少 | I35: 期末
A36: 公司1
A37: 公司2
A38: 可无限量添加行
A39: 合 计 | J39: --
A40: 说明：按被投资单位逐项描述，说明因公允价值无法可靠计量而未披露其公允价值的事实和说明；相关市场信息；企业是否有意图及如何处置这些金融工具；已终止确认的事实，以及终止确认时的账面价值和形成的利得或损失（如，当期处置对损益的影响）。
A42: （4）报告期内可供出售金融资产减值的变动情况。
...

Sheet RP 028
A1: 公司名称 | B1: =基础信息!B6 -> 0 | D1: BACK
A2: 财务期间 | B2: =基础信息!B9 -> 0
A3: 内容 | B3: 其他债权投资
A4: （1）其他债权投资情况
A5: 项 目 | B5: 期末数
B6: 账面价值
A12: 小计 | B12: =SUM(B7:B11) -> 0
A13: 减：1年内到期的债权投资
A15: 合计 | B15: =B12-B14 -> 0
A16: 报表金额
B17: =B15-B16 -> 0

Sheet RP 029
A1: 公司名称 | B1: =基础信息!B6 -> 0 | D1: BACK
A2: 财务期间 | B2: =基础信息!B9 -> 0
A3: 内容 | B3: 持有至到期投资
A4: （1）持有至到期投资情况
A5: 项 目 | B5: 期末数
B6: 账面余额 | C6: 减值准备 | D6: 账面价值
D7: =B7-C7 -> 0
D8: =B8-C8 -> 0
D9: =B9-C9 -> 0
D10: =B10-C10 -> 0
D11: =B11-C11 -> 0
A12: 小 计 | B12: =SUM(B7:B11) -> 0 | C12: =SUM(C7:C11) -> 0 | D12: =SUM(D7:D11) -> 0
A13: 减：1年内到期的持有至到期投资
A14: 合 计 | B14: =B12-B13 -> 0 | C14: =C12-C13 -> 0 | D14: =D12-D13 -> 0
A15: 报表金额
D16: =D14-D15 -> 0
D17: =IF(D16=0,"OK","NO") -> OK
A19: （2）重要的持有至到期投资
A20: 债券项目 | B20: 面值 | C20: 票面利率 | D20: 实际利率 | E20: 到期日
A22: 合 计 | B22: X.XX | C22: -- | D22: -- | E22: --
A23: （对于重要的持有至到期投资，应分别列示其面值、票面利率、实际利率、到期日。）
A24: （3）持有至到期投资重分类情况
A25: （本期存在重分类的，应披露重分类的原因和具体情况。）
A26: 由于XX原因，本期将持有至到期投资重分类为可供出售金融资产，重分类的金额XX元，该金额占重分类前持有至到期投资总额的比例XX%。

Sheet RP 030
A1: 公司名称 | B1: =基础信息!B6 -> 0 | D1: BACK
A2: 财务期间 | B2: =基础信息!B9 -> 0
A3: 内容 | B3: 长期应收款
A4: （1）长期应收款按性质披露
A5: 项 目 | B5: 期末数 | E5: 折现率区间
B6: 账面余额 | C6: 坏账准备 | D6: 账面价值
A7: 融资租赁款 | D7: =B7-C7 -> 0
A8: 其中：未实现融资收益 | D8: =B8-C8 -> 0
A9: 分期收款销售商品 | D9: =B9-C9 -> 0
A10: 其中：未实现融资收益 | D10: =B10-C10 -> 0
A11: 分期收款提供劳务 | D11: =B11-C11 -> 0
A12: 其中：未实现融资收益 | D12: =B12-C12 -> 0
A13: 其他 | D13: =B13-C13 -> 0
A14: 可无限量添加行 | D14: =B14-C14 -> 0
A15: 小 计 | D15: =B15-C15 -> 0
A16: 减：1年内到期的长期应收款 | D16: =B16-C16 -> 0
A17: 合 计 | B17: =B15-B16 -> 0 | C17: =C15-C16 -> 0 | D17: =D15-D16 -> 0
A18: 报表金额
D19: =D17-D18 -> 0
D20: =IF(D19=0,"OK","NO") -> OK
A22: 说明：
A23: （2）长期应收款逾期情况分析：
A24: 逾 期 | B24: 期末数
A25: 1年以内
A26: 1至2年
A27: 2至3年
A28: 3年以上
A29: 合 计 | B29: =SUM(B25:B28) -> 0
A30: 说明：（逾期客户的名称、逾期年限、逾期原因等）
A33: （3）终止确认的长期应收款情况
A34: （因资产转移而终止确认的长期应收款，列示资产转移的方式、终止确认的长期应收款金额，以及与终止确认相关的利得或损失。）
A35: 项 目 | B35: 转移方式 | C35: 终止确认金额 | D35: 与终止确认相关的利得或损失
A39: 合 计 | C39: =SUM(C36:C38) -> 0 | D39: =SUM(D36:D38) -> 0
A40: 说明：
A43: （4）转移长期应收款且继续涉入形成的资产、负债的金额
A44: （转移长期应收款且继续涉入的，应披露资产转移方式、分项列示继续涉入形成的资产、负债的金额。）
A45: 项 目 | B45: 期末数
A46: 资产：
A51: 资产小计 | B51: =SUM(B47:B50) -> 0
A52: 负债：
...

Sheet RP 031
A1: 公司名称 | B1: =基础信息!B6 -> 0 | E1: BACK
A2: 财务期间 | B2: =基础信息!B9 -> 0
A3: 内容 | B3: 设定受益计划净资产
A4: （1）项目分析
A5: 项 目 | B5: 期初数 | C5: 本期增加 | D5: 本期减少 | E5: 期末数
A6: 设定受益计划净资产 | E6: =B6+C6-D6 -> 0
E7: =B7+C7-D7 -> 0
A8: 符合设定受益计划条件的其他长期职工福利的净资产（不适用删除） | E8: =B8+C8-D8 -> 0
A9: 合 计 | B9: =SUM(B6:B8) -> 0 | C9: =SUM(C6:C8) -> 0 | D9: =SUM(D6:D8) -> 0 | E9: =SUM(E6:E8) -> 0
A10: 报表金额
E11: =E9-E10 -> 0
E12: =IF(E11=0,"OK","NO") -> OK
A13: 【提示：需要按照五、46中的披露格式披露设定收益计划相关信息。】

Sheet RP 032
A1: 公司名称 | B1: =基础信息!B6 -> 0 | K1: BACK
A2: 财务期间 | B2: =基础信息!B9 -> 0
A3: 内容 | B3: 长期股权投资
A4: 被投资单位 | B4: 期初余额 | C4: 本期增减变动 | K4: 期末余额 | L4: 减值准备期末余额
C5: 追加投资 | D5: 减少投资 | E5: 权益法下确认的投资损益 | F5: 其他综合收益调整 | G5: 其他权益变动 | H5: 宣告发放现金股利或利润 | I5: 计提减准备值 | J5: 其他
A6: ①合营企业
A7: …
A9: 小计
A10: ②联营企业
A11: …
A16: 小计
A17: 合 计
A18: 报表金额 | K18: ='RP 006'!E49 -> 0 | L18: ='RP 006'!E50 -> 0
K20: =IF(K19=0,"OK","NO") -> OK | L20: =IF(L19=0,"OK","NO") -> OK
A22: （1）重要的合营企业或联营企业
A23: 合营企业或联营企业名称 | B23: 主要经营地 | C23: 注册地 | D23: 业务性质 | E23: 持股比例(%) | G23: 对合营企业或联营企业投资的会计处理方法
E24: 直接 | F24: 间接
A25: ①合营企业
A29: ②联营企业
A31: 可无限量添加行
A33: 说明：
A34: （1）持股比例不同于表决权比例的，应说明表决权比例及差异原因。
A35: （2）持有其他主体20%以下表决权但具有重大影响，或者持有其他主体20%或以上表决权但不具有重大影响的，应披露相关判断和依据。
A36: （2）重要合营企业的主要财务信息：（划分为持有待售的除外）
A37: （主要财务信息按照权益法调整后的金额披露；）
A38: （“调整事项”包括投资形成的正商誉、抵消的未实现内部交易损益、减值准备等事项；）
A39: （如果母公司为投资性主体，无需披露下列财务信息。）
A40: 项 目 | B40: （A公司） | D40: （B公司） | F40: （C公司）
B41: 期末数 | C41: 期初数 | D41: 期末数 | E41: 期初数 | F41: 期末数 | G41: 期初数
A42: 流动资产
A43: 其中：现金和现金等价物
A44: 非流动资产
A45: 资产合计
A46: 流动负债
A47: 非流动负债
A48: 负债合计
A49: 净资产
A50: 其中：少数股东权益
A51: 归属于母公司的所有制权益
A52: 按持股比例计算的净资产份额
...

Sheet RP 033
A1: 公司名称 | B1: =基础信息!B6 -> 0 | D1: BACK
A2: 财务期间 | B2: =基础信息!B9 -> 0
A3: 内容 | B3: 其他权益工具投资
A10: 合 计 | B10: =SUM(B4:B9) -> 0
A11: 报表金额
B12: =B10-B11 -> 0
B13: =IF(B12=0,"OK","NO") -> OK

Sheet RP 034
A1: 公司名称 | B1: =基础信息!B6 -> 0 | E1: BACK
A2: 财务期间 | B2: =基础信息!B9 -> 0
A3: 内容 | B3: 其他非流动金融资产
A10: 合 计 | B10: =SUM(B4:B9) -> 0
A11: 报表金额
B12: =B10-B11 -> 0
B13: =IF(B12=0,"OK","NO") -> OK

Sheet RP 035
A1: 公司名称 | B1: =基础信息!B6 -> 0 | G1: BACK
A2: 财务期间 | B2: =基础信息!B9 -> 0
A3: 内容 | B3: 投资性房地产
A4: （1）按成本计量的投资性房地产（如无按公允价值计量的投资性房地产，删除此标题）
A5: 项 目 | B5: 房屋、建筑物 | C5: 土地使用权 | D5: 在建工程 | E5: 合计
A6: 一、账面原值
A7: 1.期初余额 | E7: =SUM(B7:D7) -> 0
A8: 2.本期增加金额 | B8: =SUM(B9:B12) -> 0 | C8: =SUM(C9:C12) -> 0 | D8: =SUM(D9:D12) -> 0 | E8: =SUM(E9:E12) -> 0
A9: （1）外购
A10: （2）存货\固定资产\在建工程转入
A11: （3）企业合并增加
A12: 可无限量添加行
A13: 3.本期减少金额 | B13: =SUM(B14:B16) -> 0 | C13: =SUM(C14:C16) -> 0 | D13: =SUM(D14:D16) -> 0 | E13: =SUM(E14:E16) -> 0
A14: （1）处置
A15: （2）其他转出
A16: 可无限量添加行
A17: 4.期末余额 | B17: =B7+B8-B13 -> 0 | C17: =C7+C8-C13 -> 0 | D17: =D7+D8-D13 -> 0 | E17: =E7+E8-E13 -> 0
A18: 二、累计折旧和累计摊销
A19: 1.期初余额
A20: 2.本期增加金额 | B20: =SUM(B21:B24) -> 0 | C20: =SUM(C21:C24) -> 0 | D20: =SUM(D21:D24) -> 0 | E20: =SUM(E21:E24) -> 0
A21: （1）计提或摊销
A22: （2）企业合并增加
A23: （3）其他增加
A24: 可无限量添加行
A25: 3.本期减少金额 | B25: =SUM(B26:B28) -> 0 | C25: =SUM(C26:C28) -> 0 | D25: =SUM(D26:D28) -> 0 | E25: =SUM(E26:E28) -> 0
A26: （1）处置
A27: （2）其他转出
A28: 可无限量添加行
A29: 4.期末余额 | B29: =B19+B20-B25 -> 0 | C29: =C19+C20-C25 -> 0 | D29: =D19+D20-D25 -> 0 | E29: =E19+E20-E25 -> 0
A30: 三、减值准备
A31: 1.期初余额
A32: 2.本期增加金额 | B32: =SUM(B33:B35) -> 0 | C32: =SUM(C33:C35) -> 0 | D32: =SUM(D33:D35) -> 0 | E32: =SUM(E33:E35) -> 0
A33: （1）计提
A34: （2）其他增加
A35: 可无限量添加行
A36: 3、本期减少金额 | B36: =SUM(B37:B39) -> 0 | C36: =SUM(C37:C39) -> 0 | D36: =SUM(D37:D39) -> 0 | E36: =SUM(E37:E39) -> 0
A37: （1）处置
A38: （2）其他转出
A39: 可无限量添加行
A40: 4.期末余额
...

Sheet RP 036
A1: 公司名称 | B1: =基础信息!B6 -> 0 | E1: BACK
A2: 财务期间 | B2: =基础信息!B9 -> 0
A3: 内容 | B3: 固定资产
A4: 项 目 | B4: 期末数 | C4: 转入清理的原因
A5: 固定资产 | B5: ='RP 036-1'!F41 -> 0
A6: 固定资产清理 | B6: ='RP 036-2'!B7 -> 0
A7: 合 计 | B7: =SUM(B5:B6) -> 0
A8: 报表金额
B9: =B7-B8 -> 0
B10: =IF(B9=0,"OK","NO") -> OK

Sheet RP 036-1
A1: 公司名称 | B1: =基础信息!B6 -> 0
A2: 财务期间 | B2: =基础信息!B9 -> 0
A3: 内容 | B3: 固定资产及累计折旧
A4: （1）固定资产情况 | H4: BACK
A5: 项 目 | B5: 房屋及建筑物 | C5: 机器设备 | D5: 运输设备 | E5: …… | F5: 合 计
A6: 一、账面原值： | F6: =SUM(B6:E6) -> 0
A7: 1.期初余额 | F7: =SUM(B7:E7) -> 0
A8: 2.本期增加金额 | B8: =SUM(B9:B12) -> 0 | C8: =SUM(C9:C12) -> 0 | D8: =SUM(D9:D12) -> 0 | E8: =SUM(E9:E12) -> 0 | F8: =SUM(B8:E8) -> 0
A9: （1）购置 | F9: =SUM(B9:E9) -> 0
A10: （2）在建工程转入 | F10: =SUM(B10:E10) -> 0
A11: （3）企业合并增加 | F11: =SUM(B11:E11) -> 0
A12: …… | F12: =SUM(B12:E12) -> 0
A13: 3.本期减少金额 | F13: =SUM(B13:E13) -> 0
A14: （1）处置或报废 | F14: =SUM(B14:E14) -> 0
A15: （2）其他减少 | F15: =SUM(B15:E15) -> 0
A16: …… | F16: =SUM(B16:E16) -> 0
A17: 4.期末余额 | F17: =SUM(B17:E17) -> 0
A18: 二、累计折旧 | F18: =SUM(B18:E18) -> 0
A19: 1.期初余额 | F19: =SUM(B19:E19) -> 0
A20: 2.本期增加金额 | F20: =SUM(B20:E20) -> 0
... A42: 2.期初账面价值 | F42: =SUM(B42:E42) -> 0
A43: 报表金额
A46: 说明：
A47: ①（抵押、担保的固定资产情况）
A48: （注：本期发生以明显高于账面价值的价格出售固定资产交易的，应详细说明交易作价的基础和依据，如：估值模型、重要参数的选取依据和估值过程，以及必要的敏感性分析。）
A49: 【提示：在“其他减少”中列示本期收到的政府补助冲减固定资产账面价值的金额。对于冲减无形资产或其他资产账面价值的政府补助，比照披露。】
A50: （提示：对于冲减无形资产或其他资产账面价值的政府补助，在无形资产或其他资产的科目附注中比照上述要求进行披露。）
A51: （2）暂时闲置的固定资产情况
A52: 项 目 | B52: 账面原值 | C52: 累计折旧 | D52: 减值准备 | E52: 账面价值 | F52: 备注
A53: 房屋及建筑物 | E53: =B53-C53-D53 -> 0
A54: 机器设备 | E54: =B54-C54-D54 -> 0
A55: 电子设备 | E55: =B55-C55-D55 -> 0
A56: 运输设备 | E56: =B56-C56-D56 -> 0
A57: 可无限量添加行 | E57: =B57-C57-D57 -> 0
A58: 合 计 | B58: =SUM(B53:B57) -> 0 | C58: =SUM(C53:C57) -> 0 | D58: =SUM(D53:D57) -> 0 | E58: =SUM(E53:E57) -> 0
A61: （3）通过融资租赁租入的固定资产情况
A62: 项 目 | B62: 账面原值 | C62: 累计折旧 | D62: 减值准备 | E62: 账面价值
A63: 房屋及建筑物 | E63: =B63-C63-D63 -> 0
A64: 机器设备 | E64: =B64-C64-D64 -> 0
A65: 电子设备 | E65: =B65-C65-D65 -> 0
...

Sheet RP 036-2
A1: 公司名称 | B1: =基础信息!B6 -> 0 | E1: BACK
A2: 财务期间 | B2: =基础信息!B9 -> 0
A3: 内容 | B3: 固定资产清理
A4: 项 目 | B4: 期末数 | C4: 转入清理的原因
A7: 合 计 | B7: =SUM(B5:B6) -> 0
A11: 说明：（转入固定资产清理起始时间已超过1年的固定资产清理进展情况）

Sheet RP 037
A1: 公司名称 | B1: =基础信息!B6 -> 0 | D1: BACK
A2: 财务期间 | B2: =基础信息!B9 -> 0
A3: 内容 | B3: 在建工程
A4: 项 目 | B4: 期末数
A5: 在建工程 | B5: ='RP 037-1'!D10 -> 0
A6: 工程物资 | B6: ='RP 037-2'!B11 -> 0
A7: 合 计 | B7: =B6+B5 -> 0
A8: 报表金额
B9: =B7-B8 -> 0
B10: =IF(B9=0,"OK","NO") -> OK

Sheet RP 037-1
A1: 公司名称 | B1: =基础信息!B6 -> 0 | H1: BACK
A2: 财务期间 | B2: =基础信息!B9 -> 0
A3: 内容 | B3: 在建工程
A4: （1）在建工程明细
A5: 项 目 | B5: 期末数
B6: 账面余额 | C6: 减值准备 | D6: 账面净值
D7: =B7-C7 -> 0
D8: =B8-C8 -> 0
D9: =B9-C9 -> 0
A10: 合 计 | B10: =SUM(B7:B9) -> 0 | C10: =SUM(C7:C9) -> 0 | D10: =SUM(D7:D9) -> 0
A16: （2）重要在建工程项目变动情况
A17: 工程名称 | B17: 期初数 | C17: 本期增加 | D17: 转入固定资产 | E17: 其他减少 | F17: 利息资本化累计金额 | G17: 其中：本期利息资本化金额 | H17: 本期利息资本化率% | I17: 期末数
A20: 合 计 | B20: =SUM(B18:B19) -> 0 | C20: =SUM(C18:C19) -> 0 | D20: =SUM(D18:D19) -> 0 | E20: =SUM(E18:E19) -> 0 | F20: =SUM(F18:F19) -> 0 | G20: =SUM(G18:G19) -> 0 | H20: =SUM(H18:H19) -> 0 | I20: =SUM(I18:I19) -> 0
A21: 重大在建工程项目变动情况（续）：
A22: 工程名称 | B22: 预算数 | C22: 工程累计投入占预算比例% | D22: 工程进度 | E22: 资金来源
A25: 合 计 | B25: =SUM(B23:B24) -> 0 | C25: =SUM(C23:C24) -> 0 | D25: =SUM(D23:D24) -> 0 | E25: =SUM(E23:E24) -> 0
A26: （注：工程进度不一定是投入进度）
A27: 在建工程项目变动情况的说明：
A28: （资金来源应区分募股资金、金融机构贷款和自筹、其他来源等）
A31: （3）在建工程减值准备
A32: 项 目 | B32: 本期计提金额 | C32: 计提原因
A35: 合 计 | B35: =SUM(B33:B34) -> 0
A36: 说明： （分项列示本期计提的在建工程减值准备金额及计提原因。）

Sheet RP 037-2
A1: 公司名称 | B1: =基础信息!B6 -> 0 | D1: BACK
A2: 财务期间 | B2: =基础信息!B9 -> 0
A3: 内容 | B3: 工程物资
A4: 工程物资
A5: 项 目 | B5: 期末数
A6: 专用材料
A7: 专用设备
A8: 工器具
B9: =SUM(B6:B8) -> 0
A10: 工程物资减值准备
A11: 合 计 | B11: =B9-B10 -> 0

Sheet RP 038
A1: 公司名称 | B1: =基础信息!B6 -> 0 | I1: BACK
A2: 财务期间 | B2: =基础信息!B9 -> 0
A3: 内容 | B3: 生产性生物资产
A4: 项 目 | B4: 种植业 | D4: 畜牧养殖业 | F4: 林业 | H4: 水产业 | J4: 合计
B5: 类别 | C5: …… | D5: 类别 | E5: …… | F5: 类别 | G5: …… | H5: 类别 | I5: ……
A6: 一、账面原值 | J6: =SUM(B6:I6) -> 0
A7: 1.期初余额 | J7: =SUM(B7:I7) -> 0
A8: 2.本期增加金额 | B8: =SUM(B9:B11) -> 0 | C8: =SUM(C9:C11) -> 0 | D8: =SUM(D9:D11) -> 0 | E8: =SUM(E9:E11) -> 0 | F8: =SUM(F9:F11) -> 0 | G8: =SUM(G9:G11) -> 0 | H8: =SUM(H9:H11) -> 0 | I8: =SUM(I9:I11) -> 0 | J8: =SUM(B8:I8) -> 0
A9: （1）外购 | J9: =SUM(B9:I9) -> 0
A10: （2）自行培育 | J10: =SUM(B10:I10) -> 0
A11: （3）其他增加 | J11: =SUM(B11:I11) -> 0
A12: 3.本期减少金额 | J12: =SUM(B12:I12) -> 0
A13: （1）处置 | J13: =SUM(B13:I13) -> 0
A14: （2）其他 | J14: =SUM(B14:I14) -> 0
A15: …… | J15: =SUM(B15:I15) -> 0
A16: 4.期末余额 | J16: =SUM(B16:I16) -> 0
A17: 二、累计折旧 | J17: =SUM(B17:I17) -> 0
A18: 1.期初余额 | J18: =SUM(B18:I18) -> 0
A19: 2.本期增加金额 | J19: =SUM(B19:I19) -> 0
A20: （1）计提 | J20: =SUM(B20:I20) -> 0
... A39: 2.期初账面价值 | J39: =SUM(B39:I39) -> 0
A40: 报表金额
J41: =J38-J40 -> 0
J42: =IF(J41=0,"OK","NO") -> OK
A44: （2）以公允价值计量
A45: 项 目 | B45: 种植业 | D45: 畜牧养殖业 | F45: 林业 | H45: 水产业 | J45: 合计
B46: 类别 | C46: …… | D46: 类别 | E46: …… | F46: 类别 | G46: …… | H46: 类别 | I46: ……
A47: 一、期初余额
A48: 二、本期变动
A49: 加：外购
A50: 自行培育
A51: 企业合并增加
A52: 减：处置
A53: 其他转出
A54: 公允价值变动
A55: ……
A56: 三、期末余额
A57: 报表金额
J58: =J55-J57 -> 0
J59: =IF(J58=0,"OK","NO") -> OK
...

Sheet RP 039
A1: 公司名称 | B1: =基础信息!B6 -> 0 | E1: BACK
A2: 财务期间 | B2: =基础信息!B9 -> 0
A3: 内容 | B3: 油气资产

Sheet RP 040
A1: 公司名称 | B1: =基础信息!B6 -> 0 | E1: BACK
A2: 财务期间 | B2: =基础信息!B9 -> 0
A3: 内容 | B3: 使用权资产
A8: 合 计 | B8: =SUM(B4:B7) -> 0
A9: 报表金额
B10: =B8-B9 -> 0
B11: =IF(B10=0,"OK","NO") -> OK

Sheet RP 041
A1: 公司名称 | B1: =基础信息!B6 -> 0 | E1: BACK
A2: 财务期间 | B2: =基础信息!B9 -> 0
A3: 内容 | B3: 无形资产
A4: （1）无形资产情况
A5: 项目 | B5: 土地使用权 | C5: 专利权 | D5: 非专利技术 | E5: …… | F5: 合计
A6: 一、账面原值 | F6: =SUM(B6:E6) -> 0
A7: 1.期初余额 | F7: =SUM(B7:E7) -> 0
A8: 2.本期增加金额 | B8: =SUM(B9:B13) -> 0 | C8: =SUM(C9:C13) -> 0 | D8: =SUM(D9:D13) -> 0 | E8: =SUM(E9:E13) -> 0 | F8: =SUM(B8:E8) -> 0
A9: （1）购置 | F9: =SUM(B9:E9) -> 0
A10: （2）内部研发 | F10: =SUM(B10:E10) -> 0
A11: （3）企业合并增加 | F11: =SUM(B11:E11) -> 0
A12: （4）其他增加 | F12: =SUM(B12:E12) -> 0
A13: …… | F13: =SUM(B13:E13) -> 0
A14: 3.本期减少金额 | B14: =SUM(B15:B17) -> 0 | C14: =SUM(C15:C17) -> 0 | D14: =SUM(D15:D17) -> 0 | E14: =SUM(E15:E17) -> 0 | F14: =SUM(F15:F17) -> 0
A15: （1）处置 | F15: =SUM(B15:E15) -> 0
A16: （2）其他减少 | F16: =SUM(B16:E16) -> 0
A17: …… | F17: =SUM(B17:E17) -> 0
A18: 4.期末余额 | B18: =B7+B8-B14 -> 0 | C18: =C7+C8-C14 -> 0 | D18: =D7+D8-D14 -> 0 | E18: =E7+E8-E14 -> 0 | F18: =SUM(B18:E18) -> 0
A19: 二、累计摊销 | F19: =SUM(B19:E19) -> 0
A20: 1.期初余额 | F20: =SUM(B20:E20) -> 0
A21: 2.本期增加金额 | B21: =SUM(B22:B24) -> 0 | C21: =SUM(C22:C24) -> 0 | D21: =SUM(D22:D24) -> 0 | E21: =SUM(E22:E24) -> 0 | F21: =SUM(B21:E21) -> 0
A22: （1）计提 | F22: =SUM(B22:E22) -> 0
A23: （2）其他增加 | F23: =SUM(B23:E23) -> 0
A24: …… | F24: =SUM(B24:E24) -> 0
A25: 3.本期减少金额 | B25: =SUM(B26:B28) -> 0 | C25: =SUM(C26:C28) -> 0 | D25: =SUM(D26:D28) -> 0 | E25: =SUM(E26:E28) -> 0 | F25: =SUM(B25:E25) -> 0
A26: （1）处置 | F26: =SUM(B26:E26) -> 0
A27: （2）其他减少 | F27: =SUM(B27:E27) -> 0
A28: …… | F28: =SUM(B28:E28) -> 0
A29: 4.期末余额 | B29: =B7+B8-B14 -> 0 | C29: =C7+C8-C14 -> 0 | D29: =D7+D8-D14 -> 0 | E29: =E7+E8-E14 -> 0 | F29: =SUM(B29:E29) -> 0
A30: 三、减值准备 | F30: =SUM(B30:E30) -> 0
A31: 1.期初余额 | F31: =SUM(B31:E31) -> 0
A32: 2.本期增加金额 | B32: =SUM(B33:B35) -> 0 | C32: =SUM(C33:C35) -> 0 | D32: =SUM(D33:D35) -> 0 | E32: =SUM(E33:E35) -> 0 | F32: =SUM(B32:E32) -> 0
A33: （1）计提 | F33: =SUM(B33:E33) -> 0
A34: （2）其他增加 | F34: =SUM(B34:E34) -> 0
A35: …… | F35: =SUM(B35:E35) -> 0
A36: 3.本期减少金额 | B36: =SUM(B37:B39) -> 0 | C36: =SUM(C37:C39) -> 0 | D36: =SUM(D37:D39) -> 0 | E36: =SUM(E37:E39) -> 0 | F36: =SUM(B36:E36) -> 0
A37: （1）处置 | F37: =SUM(B37:E37) -> 0
A38: （2）其他减少 | F38: =SUM(B38:E38) -> 0
A39: …… | F39: =SUM(B39:E39) -> 0
A40: 4.期末余额 | B40: =B31+B32-B36 -> 0 | C40: =C31+C32-C36 -> 0 | D40: =D31+D32-D36 -> 0 | E40: =E31+E32-E36 -> 0 | F40: =F31+F32-F36 -> 0
...

Sheet RP 042
A1: 公司名称 | B1: =基础信息!B6 -> 0 | F1: BACK
A2: 财务期间 | B2: =基础信息!B9 -> 0
A3: 内容 | B3: 开发支出
A4: 项 目 | B4: 期初数 | C4: 本期增加 | E4: 本期减少 | G4: 期末数
C5: 内部开发支出 | D5: 其他增加 | E5: 确认为无形资产 | F5: 计入当期损益
A9: 合 计 | B9: =SUM(B6:B8) -> 0 | C9: =SUM(C6:C8) -> 0 | D9: =SUM(D6:D8) -> 0 | E9: =SUM(E6:E8) -> 0 | F9: =SUM(F6:F8) -> 0 | G9: =SUM(G6:G8) -> 0
A10: 报表金额
G11: =G9-G10 -> 0
G12: =IF(G11=0,"OK","NO") -> OK
A13: 【增减变动因素可根据实际情况自行添加】
A14: 续：
A15: 项 目 | B15: 资本化开始时点 | C15: 资本化的具体依据 | D15: 截至期末的研发进度
A19: 合 计
A20: 说明：（披露上述项目的资本化开始时点、资本化的具体依据、截至期末的研发进度等。）

Sheet RP 043
A1: 公司名称 | B1: =基础信息!B6 -> 0 | F1: BACK
A2: 财务期间 | B2: =基础信息!B9 -> 0
A3: 内容 | B3: 商誉
A4: （1）商誉账面原值
A5: 被投资单位名称或形成商誉的事项 | B5: 期初余额 | C5: 本期增加 | E5: 本期减少 | G5: 期末余额
C6: 企业合并形成 | D6: 可无限量添加列 | E6: 处置 | F6: 可无限量添加列
A7: 可无限量添加行 | G7: =B7+C7+D7-E7-F7 -> 0
G8: =B8+C8+D8-E8-F8 -> 0
G9: =B9+C9+D9-E9-F9 -> 0
A10: 合 计 | B10: =SUM(B7:B9) -> 0 | C10: =SUM(C7:C9) -> 0 | D10: =SUM(D7:D9) -> 0 | E10: =SUM(E7:E9) -> 0 | F10: =SUM(F7:F9) -> 0 | G10: =SUM(G7:G9) -> 0
A11: （提示：其他增减变动原因包括境外子公司汇率变化的影响等）
A12: （2）商誉减值准备
A13: 被投资单位名称或形成商誉的事项 | B13: 期初余额 | C13: 本期增加 | E13: 本期减少 | G13: 期末余额
C14: 计提 | D14: 可无限量添加行 | E14: 处置 | F14: 可无限量添加行
A15: 可无限量添加行 | G15: =B15+C15+D15-E15-F15 -> 0
G16: =B16+C16+D16-E16-F16 -> 0
G17: =B17+C17+D17-E17-F17 -> 0
A18: 合 计 | B18: =SUM(B15:B17) -> 0 | C18: =SUM(C15:C17) -> 0 | D18: =SUM(D15:D17) -> 0 | E18: =SUM(E15:E17) -> 0 | F18: =SUM(F15:F17) -> 0 | G18: =SUM(G15:G17) -> 0
A19: 说明：（商誉减值测试过程、参数及商誉减值损失的确认方法）
A20: 本集团采用预计未来现金流现值的方法计算资产组的可收回金额。本集团根据管理层批准的财务预算预计未来5年内现金流量，其后年度采用的现金流量增长率预计为XX%（上期：XX%），不会超过资产组经营业务的长期平均增长率。管理层根据过往表现及其对市场发展的预期编制上述财务预算。计算未来现金流现值所采用的税前折现率为XX%（上期：XX%），已反映了相对于有关分部的风险。根据减值测试的结果，本期期末商誉未发生减值（上期期末：无）。【或：本期期末对商誉计提减值准备XX元（上期期末：XX元）。】
A21: 报表金额
G22: =G10-G18-G21 -> 0
G23: =IF(G22=0,"OK","NO") -> OK

Sheet RP 044
A1: 公司名称 | B1: =基础信息!B6 -> 0 | E1: BACK
A2: 财务期间 | B2: =基础信息!B9 -> 0
A3: 内容 | B3: 长期待摊费用
A4: 项 目 | B4: 期初数 | C4: 本期增加 | D4: 本期减少 | F4: 期末数
D5: 本期摊销 | E5: 其他减少
