Workbook
Name a暗暗: [1]企业表一!$F$20
Name bbkm: [2]W!$B$2:$B$65
Name bbxml: #REF!
Name bbxml: #REF!
Name CarryKnown: #REF!
Name CarryKnown: #REF!
Name CarryKnownTable: #REF!
Name CarryKnownTable: #REF!
Name CarryLikely: #REF!
Name CarryLikely: #REF!
Name CarryLikelyTable: #REF!
Name CarryLikelyTable: #REF!
Name Carryover_Effect_of_Prior_Year: #REF!
Name Carryover_Effect_of_Prior_Year: #REF!
Name CarryoverTitle: #REF!
Name CarryoverTitle: #REF!
Name CC_Instruction: #REF!
Name CC_Instruction: #REF!
Name CE_CarryKnownProtection: #REF!
Name CE_CarryKnownProtection: #REF!
Name CE_CarryKnownTable: #REF!
Name CE_CarryKnownTable: #REF!
Name CE_CarryLikely1Protection: #REF!
Name CE_CarryLikely1Protection: #REF!
Name CE_CarryLikely1Table: #REF!
Name CE_CarryLikely1Table: #REF!
Name CE_CarryLikely2Protection: #REF!
Name CE_CarryLikely2Protection: #REF!
Name CE_CarryLikely2Table: #REF!
Name CE_CarryLikely2Table: #REF!
Name CE_CarryTaxable: #REF!
Name CE_CarryTaxable: #REF!
Name CE_Desc: #REF!
Name CE_Desc: #REF!
Name CE_Income: #REF!
Name CE_Income: #REF!
Name CE_KeepFormat: #REF!
Name CE_KeepFormat: #REF!
Name CE_KnownChange: #REF!
Name CE_KnownChange: #REF!
Name CE_KnownFormulaProtection: #REF!
Name CE_KnownFormulaProtection: #REF!
Name CE_KnownImpact: #REF!
Name CE_KnownImpact: #REF!
Name CE_Likely1Change: #REF!
Name CE_Likely1Change: #REF!
Name CE_Likely1FormulaProtection: #REF!
Name CE_Likely1FormulaProtection: #REF!
Name CE_Likely1Impact: #REF!
Name CE_Likely1Impact: #REF!
Name CE_Likely2Change: #REF!
Name CE_Likely2Change: #REF!
Name CE_Likely2FormulaProtection: #REF!
Name CE_Likely2FormulaProtection: #REF!
Name CE_Likely2Impact: #REF!
Name CE_Likely2Impact: #REF!
Name CE_SheetCorrect: #REF!
Name CE_SheetCorrect: #REF!
Name CE_StatementImpact: #REF!
Name CE_StatementImpact: #REF!

Sheet 底稿目录
A1: 底稿开列时，可先在以下单元格填写有关内容，以便其他底稿引用有关数据：
A2: 被审计单位：ABC公司 | D2: 序号 | E2: 内容 | F2: 索引号
A3: 截止日：202X年12月31日 | D3: 1 | E3: 审计程序（财报+内控） | F3: A11
A4: 编制人：张三 | D4: 2 | E4: 期后事项审定表 | F4: A11-1
A5: 编制日期：2025.7.1 | D5: 3 | E5: 期后事项调查问卷 | F5: A11-2
A6: 复核人：李四 | D6: 4 | E6: 期后内控事项调查问卷 | F6: A11-3
A7: 复核日期：2025.7.10
A8: 会计期间：20XX年度

Sheet 审计程序A11（财报+内控）
A1: 致同会计师事务所
A2: 期后事项程序表
A3: =底稿目录!A2 -> 被审计单位：ABC公司 | C3: =底稿目录!A4 -> 编制人：张三 | D3: =底稿目录!A5 -> 编制日期：2025.7.1 | G3: 索引号： | H3: A11
A4: =底稿目录!A8 -> 会计期间：20XX年度 | C4: =底稿目录!A6 -> 复核人：李四 | D4: =底稿目录!A7 -> 复核日期：2025.7.10
A5: 序号 | B5: 程序 | E5: 是否适用 | F5: 执行人 | G5: 执行情况说明 | H5: 索引号
A6: 1 | B6: 注明我们在审计报告中签署的日期。
A7: 2 | B7: 复核被审计单位管理层建立的用于确保识别期后事项的程序。
B8: 针对财务报表审计（3-17）：
A9: 3 | B9: 获取并阅读最新的中期财务信息，以及其他适当的管理报告例如预算、现金流量预测，并考虑在审计报告日期前，该信息是否包括可能需要在财务报表调整或披露的事项。
A10: 4 | B10: 获得在我们的审计计划之后由内部审计部门发布的报告，并考虑其对财务报表和我们的审计程序的影响。
A11: 5 | B11: 如果这些报告没有完成，与内审人员讨论它们的情况，安排当报告发布时接收副本，并确定我们的审计程序，适当解决它们的问题。
A12: 6 | B12: 查阅在财务报表日后股东、董事、审计委员会和其他重要委员会的会议记录并更新至接近审计报告日，在不能获取会议纪要的情况下，询问此类会议讨论的事项。
A13: 7 | B13: 查阅在财务报表日后被审计单位与客户、供应商、监管部门等的往来信函并更新至接近审计报告日。
A14: 8 | B14: 就诉讼和索赔事项询问被审计单位的法律顾问，或扩大之前口头或书面查询的范围。
A15: 9 | B15: 考虑企业咨询其他顾问的结果。
A16: 10 | B16: 询问管理层是否存在下列情况：
A17: （1） | B17: 是否已发生新的承诺、借款或担保；
A18: （2） | B18: 是否已出售或购置资产，或者计划出售或购置资产；
A19: （3） | B19: 是否已增加资本或发行债务工具（如发行新的股票或债券），或者是否已签订或计划签订合并或清算协议；
A20: （4） | B20: 资产是否已被政府征用或因不可抗力（如火灾或洪水）而遭受损失；
A21: （5） | B21: 或有事项是否已发生新的进展；
A22: （6） | B22: 是否已作出或考虑作出异常的会计调整；
A23: （7） | B23: 是否已发生或可能发生影响财务报表编制时所采用会计政策适当性的事项（如影响持续经营假设适当性的事项）；
A24: （8） | B24: 是否已发生与财务报表中会计估计或准备计提相关的事项；
A25: （9） | B25: 是否已发生与资产可收回性相关的事项；
A26: （10） | B26: 其他与舞弊风险因素相关或表明应当调整固有风险评估结果的期后事项。
A27: 11 | B27: 调查已经识别出的项目并确定：
A28: （1） | B28: 它们是否影响被审计的期间。
A29: （2） | B29: 这些事项在财务报表中是否得到恰当的会计处理并充分披露。
A30: 12 | B30: 询问管理层和治理层（IPO适用）：
A31: （1） | B31: 是否存在期后主要原材料的采购规模及采购价格重大变化的情形，并询问原因，了解并收集相关证据。
A32: （2） | B32: 是否存在期后主要产品的生产、销售规模及销售价格发生重大变化的情形，并询问原因，了解并收集相关证据。
A33: （3） | B33: 是否存在期后主要客户及供应商的构成、税收政策等发生重大变化，或发生其他可能影响投资者判断的重大事项。询问原因，了解并收集相关证据。
A34: （4） | B34: 询问管理层和治理层，被审计单位是否存在由于在市场价格出现较大幅度上升前提前囤积原材料或由于偶发因素导致其主要产品市场价格上升较快从而获取超额收益的情况
A35: （5） | B35: 资产负债表日后最新一期财务报表主要会计报表项目与财务报告审计截止日或上年同期相比，是否发生较大变化；如是，了解原因并收集相关证据。
A36: （6） | B36: 资产负债表日后最近一期营业收入或营业利润是否呈现下滑趋势；如是，了解原因并收集相关证据。
A37: （7） | B37: 发行人预计年初至发行上市后第一个报告期期末的累计净利润以及扣除非经常性损益后孰低的净利润，是否可能较上年同期发生重大变动，如是，了解原因并收集相关证据。
A38: 13 | B38: 查阅相关公告、董事会决议、会议纪要等，了解重大事项决策程序，充分识别财务报表日至审计报告日之间发生的事项，评价未披露事项对审计意见的影响等。
A39: 14 | B39: 获取科目余额表、明细账等，检查资产负债表日前后是否存在异常交易及资金往来，如临近资产负债表日大额收款且期后大额付款，期后发生大额销售退回、应收账款与应付账款对抵、冲销已计提未支付的期间费用、大额计提减值，存在会计差错更正、重大未决诉讼、以及大额票据置换、贴现或背书转让等。结合期后合同的履行、变更以及资金收付情况，调查异常交易的商业实质；复核临近资产负债表日及期后有关调整分录；关注重要事项、合同以及未决诉讼进展。
A40: 15 | B40: 对被审计单位资产负债表日后最近一期的财务报告审阅并执行以下程序（IPO适用）：
...

Sheet 期后事项审定表A11-1
A1: 致同会计师事务所
A2: 期后事项审定表
A3: =底稿目录!A2 -> 被审计单位：ABC公司 | C3: =底稿目录!A4 -> 编制人：张三 | E3: =底稿目录!A5 -> 编制日期：2025.7.1 | G3: 索引号：A11-1
A4: =底稿目录!A8 -> 会计期间：20XX年度 | C4: =底稿目录!A6 -> 复核人：李四 | E4: =底稿目录!A7 -> 复核日期：2025.7.10 | G4: 页次：
A5: 类别 | B5: 期后事项 | C5: 审计过程及结论 | F5: 索引号 | G5: 备注
A6: 1.资产负债表日至审计报告日
A14: 2.审计报告日后至财务报表报出日前
A20: 3.财务报表报出日后
A27: 1、审计说明（概述主要审计过程和所获取的关键证据）
A28: 2、重大事项说明（如适用，根据1332号等审计准则和指南的要求编制，说明涉及事项内容、应对措施、审计结论或解决方法，以及可能对审计报告的影响）
A29: 3、审计结论（说明基于获取的审计证据，在有关认定方面，是否发现重大错报或存在重大异常；以及有关调整分录）

Sheet 期后事项调查问卷A11-2
A1: 致同会计师事务所
A2: 期后事项调查问卷
A3: =底稿目录!A2 -> 被审计单位：ABC公司 | C3: =底稿目录!A4 -> 编制人：张三 | D3: =底稿目录!A5 -> 编制日期：2025.7.1 | F3: 索引号：A11-2
A4: =底稿目录!A8 -> 会计期间：20XX年度 | C4: =底稿目录!A6 -> 复核人：李四 | D4: =底稿目录!A7 -> 复核日期：2025.7.10 | F4: 页次：
A5: 序号 | B5: 调查内容 | D5: 适用情况 | F5: 简要说明
B6: 在资产负债表日至填写本调查问卷之日止，贵公司 | D6: 是 | E6: 否
A7: 1 | B7: 在资产负债日前根据初步或尚无定论的数据作出会计处理的项目，其状况是否发生改变；
A8: 2 | B8: 是否发生新的担承诺、借款或担保；
A9: 3 | B9: 是否已出售或购置资产，或者计划出售或购置资产；
A10: 4 | B10: 是否已增加资本或发行债务工具（如发行新的股票或债券），或者是否已签订或计划签订合并或清算协议（适用于有内审部门的主体）；
A11: 5 | B11: 资产是否已被政府征用或因不可抗力（如火灾或洪水）而遭受损失（适用于有内审部门的主体）；
A12: 6 | B12: 或有事项是否已发生新的进展；
A13: 7 | B13: 是否已作出或考虑作出异常的会计调整；
A14: 8 | B14: 是否已发生或可能发生影响财务报表编制时所采用会计政策适当性的事项（如影响持续经营假设适当性的事项）；
A15: 9 | B15: 是否已发生与财务报表中会计估计或准备计提相关的事项；
A16: 10 | B16: 是否已发生与资产可收回性相关的事项；
A17: 11 | B17: 是否存在重大经济纠纷或重要客户破产等情况；
A18: 12 | B18: 是否发生大额的销售退回；
A19: 13 | B19: 是否发生其他对本期会计报表的编制或理解产生重大影响的事项。
B20: *注：调查日期应尽量接近审计报告日。
B22: 被调查人： | E22: 调查人：
B24: 日期： | E24: 日期：

Sheet 期后内控事项调查问卷A11-3
A1: 致同会计师事务所
A2: 期后事项调查问卷—内部控制审计
A3: =底稿目录!A2 -> 被审计单位：ABC公司 | C3: =底稿目录!A4 -> 编制人：张三 | D3: =底稿目录!A5 -> 编制日期：2025.7.1 | F3: 索引号：A11-3
A4: =底稿目录!A8 -> 会计期间：20XX年度 | C4: =底稿目录!A6 -> 复核人：李四 | D4: =底稿目录!A7 -> 复核日期：2025.7.10 | F4: 页 次：
A5: 序号 | B5: 内部控制审计调查内容 | D5: 适用情况 | F5: 简要说明
B6: 在内部控制评价基准日至填写本调查问卷之日止，贵公司 | D6: 是 | E6: 否
A7: 1 | B7: 财务报告内部控制是否发生重大变化？如是，发生哪些变化？
A8: 2 | B8: 非财务报告内部控制是否发生重大变化？如是，发生哪些变化？
A9: 3 | B9: 其他机构是否出具了内部控制审计报告或类似报告？
A10: 4 | B10: 是否被其他机构或注册会计师出具涉及企业内部控制缺陷的报告？
A11: 5 | B11: 监管部门是否发布涉及本企业内部控制的报告？
A12: 6 | B12: 是否发生其他对基准日内部控制产生重大影响的事项？
B20: *注：调查日期应尽量接近审计报告日。
B22: 被调查人： | E22: 调查人：
B24: 日 期： | E24: 日 期：

Sheet GT_Custom
A1: C1 | B1: Custom 1
A2: C2 | B2: Custom 2
A3: C3 | B3: Custom 3
A4: C4 | B4: Custom 4
A5: C5 | B5: Custom 5
A6: C6 | B6: Custom 6
A7: C7 | B7: Custom 7
A8: C8 | B8: Custom 8
