Workbook

Sheet 底稿目录
A1: 底稿开列时，可先在以下单元格填写有关内容，以便其他底稿引用有关数据：
A2: 被审计单位：ABC公司
A3: 截止日：202X年12月31日 | C3: 序号 | D3: 内容 | E3: 索引号
A4: 编制人：张XX | C4: 1 | D4: 质量控制复核人复核表 | E4: A25-1
A5: 编制日期：2025.XX.XX | C5: =C4+1 -> 2 | D5: 复核记录 | E5: A25-1-1
A6: 回复人：李XX
A7: 回复日期：2025.XX.XX

Sheet 质量控制复核人复核表A25-1
A1: 致同会计师事务所
A2: 质量控制复核人复核表
A3: =底稿目录!A2 -> 被审计单位：ABC公司 | I3: 索引号: | J3: A25-1
A4: =底稿目录!A3 -> 截止日：202X年12月31日 | I4: 页 次：
A5: 质量控制复核人复核内容 | F5: 是 | G5: 否 | H5: 不适用 | I5: 备注 | K5: 开机启动项 | L5: 综合性问题
A6: 1 | B6: 本人对项目合伙人是独立的。本人对上市实体客户及其关联实体（或非上市实体客户及其控制的实体）没有任何承诺或自我利益等对独立性产生不利影响的因素。
A7: 2 | B7: 项目内各级复核是否均已得到满意的执行并保留复核记录？
A8: 3 | B8: 项目质量复核合伙人复核是否已得到满意的执行并记录？项目质量复核合伙人要求跟进的问题项目组是否已恰当解决并回复？
A9: 4 | B9: 业务承接或保持相关底稿是否已完成？鉴证业务分类是否正确？若存在分歧，是否已按照分歧解决程序处理？
A10: =A9+1 -> 5 | B10: 是否阅读并了解IMS系统流转过来的业务承接或保持评价相关资料，与项目组沟通项目和被审计单位的性质和具体情况？
A11: =A10+1 -> 6 | B11: 是否获取并阅读事务所对该项目的内部质量控制检查报告（如适用），特别是针对可能与项目组的重大判断相关或影响该重大判断的领域识别出的缺陷进行沟通？
A12: =A11+1 -> 7 | B12: 是否已与项目合伙人、项目组其他成员（如适用）讨论重大事项，以及在业务计划、实施和报告阶段作出的重大判断？
A13: =A12+1 -> 8 | B13: 总体审计策略、重大事项概要是否恰当反映了项目组作出的重大职业判断、实施的审计程序、获取的审计证据以及支持拟发表审计意见的结果？
A14: =A13+1 -> 9 | B14: 项目组是否已就疑难问题或分歧事项进行适当咨询，并已按照咨询的结果执行？
A15: =A14+1 -> 10 | B15: 收入确认原则是否符合企业会计准则的要求？对于附带特殊条款的合同，收入确认政策是否恰当？如营业收入和净利润在会计期间内出现较大幅度波动、营业毛利或净利润的增长幅度明显高于营业收入的增长幅度，项目组是否已取得充分审计证据以确定其真实性？
A16: =A15+1 -> 11 | B16: 项目组是否已进行实地监盘，并对异地存放、盘点过程存在特殊困难或由第三方保管或控制的存货执行了适当的审计程序？如实施监盘确有困难，项目组是否实施有效替代程序，否则是否考虑对审计意见的影响？
A17: =A16+1 -> 12 | B17: 项目组对项目的银行存款、往来款项等函证程序是否执行到位？
A18: =A17+1 -> 13 | B18: 项目组是否已取得并检查相关证据以确定被审计单位的客户、供应商（含外协厂商）与被审计单位实际控制人、董事、监事、高级管理人员及关系密切的家庭成员是否存在关联方关系?（仅适用A类） | K18: A类
A19: =A18+1 -> 14 | B19: 项目组是否对被审计单位主要客户和供应商（例如前十名客户或供应商）情况进行核查？对于IPO项目，根据重要性原则实地走访或核查，并将上述核查情况记录在工作底稿中?（仅适用A类） | K19: A类+IPO
A20: =A19+1 -> 15 | B20: 对于IPO项目，项目组核查发行人与其客户、供应商之间关联方关系时，是否不仅查阅了书面资料，而且采取了实地走访，核对工商、税务、银行等部门提供的资料，以确定客户和供应商的实际控制人及关键经办人员与发行人是否存在关联方关系? | K20: IPO
A21: =A20+1 -> 16 | B21: 对于集团审计项目，确定的重要性水平是否恰当？重要组成部分判断是否正确？是否复核组成部分注册会计师工作，对不符合要求的情况采取恰当应对措施？ | L21: 3.9-1
A22: =A21+1 -> 17 | B22: 项目合伙人及项目质量复核合伙人是否复核了项目组执行的内部控制审计程序？ | K22: 整合审计
A23: =A22+1 -> 18 | B23: 项目组所完成的与所有重大交易类别、账户余额和披露有关的内控流程记录的详尽程度能够了解可能导致错报的来源。 | K23: 整合审计
A24: =A23+1 -> 19 | B24: 对在内部控制流程中针对重大错报风险所选择的关键控制点与所执行的控制测试是恰当的。 | K24: 整合审计
A25: =A24+1 -> 20 | B25: 内控测试以及文档中有关复核与对账内控的相关证据都证明，项目组对内控的审计没有停留在观察“签字”或恰当的“复核和批准”上。对此我感到满意。 | K25: 整合审计
A26: =A25+1 -> 21 | B26: 如识别出控制缺陷，如果同时存在补偿性控制，项目组已经对补偿性控制的运行精准程度进行了测试，并已恰当评估所有控制缺陷的影响程度。 | K26: 整合审计
A27: =A26+1 -> 22 | B27: 项目组是否遵循审计准则和LEAP审计方法论？是否恰当识别了重大类别的交易、账户余额或披露（SCOT+）？
A28: =A27+1 -> 23 | B28: 重要底稿是否恰当完成？如独立性相关工作底稿、项目组讨论及与治理层、管理层的沟通、项目质量复核合伙人与项目合伙人参加风险评估讨论会、项目总结会的会议记录等。
A29: =A28+1 -> 24 | B29: 项目组对重大错报风险和特别风险事项的判断、分歧事项、重大职业判断的处理是否恰当？
A30: =A29+1 -> 25 | B30: 项目组是否通过实施风险评估程序，结合被审计单位的业务模式恰当记录了信息技术环境？是否识别了信息技术一般控制和信息处理控制？
A31: =A30+1 -> 26 | B31: 项目组是否恰当评估了使用信息技术导致的风险，并且与信息技术导致的风险相关的内部控制测试已被妥善的设计并执行？
A32: =A31+1 -> 27 | B32: 项目组是否依据IT复杂因素判断要素完成了IT复杂性判断底稿？出具报告前已完成IT审计并获取IT审计总结备忘录？已充分评价并应对信息技术相关控制缺陷？
A33: =A32+1 -> 28 | B33: 项目组对税务事项复杂性或风险的判断是否恰当？出具报告前已完成了税务复核并已恰当解决相关税务问题？
A34: =A33+1 -> 29 | B34: 是否执行业务质量控制委员会或专业技术委员会审核程序，审核意见适当落实？
A35: =A34+1 -> 30 | B35: 评价项目合伙人的以下方面工作： （1）对整个审计过程的参与程度是否充分和恰当； （2）确定独立性要求已得到遵循的依据是否充分。
A36: =A35+1 -> 31 | B36: 审计报告正文及经审计的财务报表等是否与准则规定及事务所规范的内容和格式一致？
A37: =A36+1 -> 32 | B37: 已经复核审计报告相关的其他鉴证报告、专项意见和说明，并确定：（1）报告中数据与已审计财务报表勾稽一致；（2）审计报告及财务报表的内容与获取的审计证据相一致；（3）被审计单位已经履行财务报表报出的审批手续；（4）依据准则及相关法规要求签章。
A38: =A37+1 -> 33 | B38: 是否复核管理层关于审计报告日后公布的其他信息的书面声明、其他信息比对记录和最终版本的年度报告（如适用）？
A39: =A38+1 -> 34 | B39: 本人已经按照《质量控制复核实施办法》实施了项目质量复核，所有复核意见均已得到解决，没有注意到存在任何尚未解决的、可能使本人认为项目组作出的重大判断和得出的结论不适当的事项。
A40: 质量控制复核人签字： 年 月 日
...

Sheet 复核记录A25-1-1
A1: 致同会计师事务所
A2: 质量控制复核人复核记录
A3: =底稿目录!A2 -> 被审计单位：ABC公司 | B3: =底稿目录!A4 -> 编制人：张XX | C3: =底稿目录!A5 -> 编制日期：2025.XX.XX | D3: 索引号: | E3: A25-1-1
A4: =底稿目录!A3 -> 截止日：202X年12月31日 | B4: =底稿目录!A6 -> 回复人：李XX | C4: =底稿目录!A7 -> 回复日期：2025.XX.XX | D4: 页次：
A5: 分阶段收到资料（至少包括如下内容）
A6: 请注明实际收到资料的内容、日期、提供资料的审计部门及具体人员
A7: 1、 审计报告及专项报告
A8: 2、 业务承接或保持相关资料
A9: 3、 总体审计策略及具体审计计划（仅适用A类）、审计小结、财务报表及相关分析（需有文字分析）、已更正错报和未更正错报汇总表、重大事项概要
A10: 4、 项目负责经理、项目合伙人复核记录、项目质量复核合伙人复核记录
A11: 5、 风险评估及重要控制测试、控制缺陷评价底稿（仅适用A类）
A12: 6、 关联方关系及其交易工作底稿（仅适用A类）
A13: 7、 与独立性相关的工作底稿
A14: 8、 函证、存货监盘、收入成本等其他认为必要的支持重大会计审计事项处理和报告的工作底稿
A15: 9、高风险事项或情形相关底稿（如适用）
A16: 10、与特别风险和SCOT+风险相关的内控和实质性程序底稿
... A22: 16、管理层关于审计报告日后公布的其他信息的书面声明、其他信息比对记录和最终版本的年度报告（如适用）
A24: 复核问题 | B24: 项目组回复 | C24: 确认复核问题已满意解决
A25: 一、复核中发现的问题
A26: （一）复核审计工作底稿发现的问题
A35: （二）复核审计报告发现的问题：（可以从以下几方面来描述）
A36: 1、审计报告格式
A37: 2、审计报告正文
A38: 3、已审财务报表
A39: 4、财务报表附注及审计报告附件
A44: （三）复核其他专项报告发现的问题：
A48: 二、对项目质量复核合伙人需要协助复核的具体事项或内容的跟进（如适用）
A55: 三、对专业技术委员会意见的跟进（如适用）
A58: 四、复核人员的最终复核意见（说明是否同意出具报告，并以手签字确认）
A60: 年 月 日
