Workbook
Name 财务费用: Word附注!$B$2010
Name 持有待售资产和负债: Word附注!$B$540
Name 持有至到期投资: Word附注!$B$687
Name 存货: Word附注!$B$434
Name 递延收益: Word附注!$B$1889
Name 递延所得税资产与递延所得税负债: Word附注!$B$1257
Name 短期借款: Word附注!$B$1307
Name 非经常性损益: Word附注!$B$2239
Name 工程物资: Word附注!$B$1018
Name 公允价值变动收益: Word附注!$B$2065
Name 固定资产: Word附注!$B$871
Name 固定资产明细: Word附注!$B$877
Name 固定资产清理: Word附注!$B$957
Name 管理费用: Word附注!$B$1979
Name 合同负债: Word附注!$B$1415
Name 合同资产: Word附注!$B$511
Name 货币资金: Word附注!$B$2
Name 交易性金融负债: Word附注!$B$1329
Name 交易性金融资产: Word附注!$B$23
Name 净敞口套期收益: Word附注!$B$2051
Name 开发支出: Word附注!$B$1200
Name 可供出售金融资产: Word附注!$B$629
Name 其他非流动负债: Word附注!$B$1904
Name 其他非流动金融资产: Word附注!$B$790
Name 其他非流动资产: Word附注!$B$1296
Name 其他流动负债: Word附注!$B$1609
Name 其他流动资产: Word附注!$B$597
Name 其他权益工具投资: Word附注!$B$780
Name 其他收益: Word附注!$B$2025
Name 其他应付款: Word附注!$B$1497
Name 其他应付款明细: Word附注!$B$1545
Name 其他应收款: Word附注!$B$252
Name 其他应收款_以下不适用的_请删除: Word附注!$B$298
Name 其他债权投资: Word附注!$B$675
Name 商誉: Word附注!$B$1221
Name 设定受益计划净资产: Word附注!$B$756
Name 生产性生物资产: Word附注!$B$1028
Name 使用权资产: Word附注!$B$1112
Name 税金及附加: Word附注!$B$1955
Name 所得税费用: Word附注!$B$2146
Name 所有权或使用权受到限制的资产: Word附注!$B$2280
Name 投资收益: Word附注!$B$2037
Name 投资性房地产: Word附注!$B$802
Name 无形资产: Word附注!$B$1139
Name 现金流量表项目注释: Word附注!$B$2170
Name 销售费用: Word附注!$B$1967
Name 信用减值损失: Word附注!$B$2076
Name 研发费用: Word附注!$B$1994
Name 衍生金融负债: Word附注!$B$1356
Name 衍生金融资产: Word附注!$B$50
Name 一年内到期的非流动负债: Word附注!$B$1561
Name 一年内到期的非流动资产: Word附注!$B$588
Name 以公允价值计量且其变动计入当期损益的金融负债: Word附注!$B$1341
Name 以公允价值计量且其变动计入当期损益的金融资产: Word附注!$B$34
Name 应付股利: Word附注!$B$1526
Name 应付利息: Word附注!$B$1505
Name 应付票据: Word附注!$B$1367
Name 应付债券: Word附注!$B$1667
Name 应付账款: Word附注!$B$1375
Name 应付职工薪酬: Word附注!$B$1432

Sheet 目录
A1: 序号 | B1: 资产 | C1: 序号 | D1: 负债 | E1: 序号 | F1: 损益 | G1: 序号 | H1: 其他 | I1: 序号 | J1: 期后事项
A2: 1 | B2: 货币资金 | C2: =A42+1 -> 35 | D2: 短期借款 | E2: =C29+1 -> 58 | F2: 营业收入 | G2: =E19+1 -> 76 | H2: 现金流量表附表 | I2: =G6+1 -> 81 | J2: 资产负债表日后事项
A3: =A2+1 -> 2 | B3: 交易性金融资产 | C3: =C2+1 -> 36 | D3: 交易性金融负债 | E3: =E2+1 -> 59 | F3: 营业成本 | G3: =G2+1 -> 77 | H3: 非经常性损益
A4: =A3+1 -> 3 | B4: 以公允价值计量且其变动计入当期损益的金融资产 | C4: =C3+1 -> 37 | D4: 以公允价值计量且其变动计入当期损益的金融负债 | E4: =E3+1 -> 60 | F4: 税金及附加 | G4: =G3+1 -> 78 | H4: 所有权受限资产
A5: =A4+1 -> 4 | B5: 衍生金融资产 | C5: =C4+1 -> 38 | D5: 衍生金融负债 | E5: =E4+1 -> 61 | F5: 销售费用 | G5: =G4+1 -> 79 | H5: 终止经营
A6: =A5+1 -> 5 | B6: 应收票据 | C6: =C5+1 -> 39 | D6: 应付票据 | E6: =E5+1 -> 62 | F6: 管理费用 | G6: =G5+1 -> 80 | H6: 政府补助
A7: =A6+1 -> 6 | B7: 应收账款 | C7: =C6+1 -> 40 | D7: 应付账款 | E7: =E6+1 -> 63 | F7: 研发费用
A8: =A7+1 -> 7 | B8: 预付款项 | C8: =C7+1 -> 41 | D8: 预收款项 | E8: =E7+1 -> 64 | F8: 财务费用
A9: =A8+1 -> 8 | B9: 其他应收款 | C9: =C8+1 -> 42 | D9: 合同负债 | E9: =E8+1 -> 65 | F9: 其他收益
A10: =A9+0.1 -> 8.1 | B10: 其中：应收利息 | C10: =C9+1 -> 43 | D10: 应付职工薪酬 | E10: =E9+1 -> 66 | F10: 投资收益
A11: =A10+0.1 -> 8.2 | B11: 应收股利 | C11: =C10+1 -> 44 | D11: 应交税费 | E11: =E10+1 -> 67 | F11: 净敞口套期收益
A12: =A11+0.1 -> 8.3 | B12: 其他应收款 | C12: =C11+1 -> 45 | D12: 其他应付款 | E12: =E11+1 -> 68 | F12: 公允价值变动收益
A13: =A9+1 -> 9 | B13: 存货 | C13: =C12+0.1 -> 45.1 | D13: 其中：应付利息 | E13: =E12+1 -> 69 | F13: 信用减值损失
A14: =A13+1 -> 10 | B14: 合同资产 | C14: =C13+0.1 -> 45.2 | D14: 应付股利 | E14: =E13+1 -> 70 | F14: 资产减值损失
A15: =A14+1 -> 11 | B15: 持有待售资产 | C15: =C14+0.1 -> 45.3 | D15: 其他应付款 | E15: =E14+1 -> 71 | F15: 资产减值准备
A16: =A15+1 -> 12 | B16: 一年内到期的非流动资产 | C16: =C12+1 -> 46 | D16: 持有待售负债 | E16: =E15+1 -> 72 | F16: 资产处置收益
A17: =A16+1 -> 13 | B17: 其他流动资产 | C17: =C16+1 -> 47 | D17: 一年内到期的非流动负债 | E17: =E16+1 -> 73 | F17: 营业外收入
A18: =A17+1 -> 14 | B18: 债权投资 | C18: =C17+1 -> 48 | D18: 其他流动负债 | E18: =E17+1 -> 74 | F18: 营业外支出
A19: =A18+1 -> 15 | B19: 可供出售金融资产 | C19: =C18+1 -> 49 | D19: 长期借款 | E19: =E18+1 -> 75 | F19: 所得税费用
A20: =A19+1 -> 16 | B20: 其他债权投资 | C20: =C19+1 -> 50 | D20: 应付债券
A21: =A20+1 -> 17 | B21: 持有至到期投资 | C21: =C20+1 -> 51 | D21: 租赁负债
A22: =A21+1 -> 18 | B22: 长期应收款 | C22: =C21+1 -> 52 | D22: 长期应付款
A23: =A22+1 -> 19 | B23: 设定受益计划净资产 | C23: =C22+0.1 -> 52.1 | D23: 其中：长期应付款
A24: =A23+1 -> 20 | B24: 长期股权投资 | C24: =C23+0.1 -> 52.2 | D24: 专项应付款
A25: =A24+1 -> 21 | B25: 其他权益工具投资 | C25: =C22+1 -> 53 | D25: 长期应付职工薪酬
A26: =A25+1 -> 22 | B26: 其他非流动金融资产 | C26: =C25+1 -> 54 | D26: 预计负债
A27: =A26+1 -> 23 | B27: 投资性房地产 | C27: =C26+1 -> 55 | D27: 递延收益
A28: =A27+1 -> 24 | B28: 固定资产 | C28: =C27+1 -> 56 | D28: 递延所得税负债
A29: =A28+0.1 -> 24.1 | B29: 其中：固定资产 | C29: =C28+1 -> 57 | D29: 其他非流动负债
A30: =A29+0.1 -> 24.2 | B30: 固定资产清理
A31: =A28+1 -> 25 | B31: 在建工程
A32: =A31+0.1 -> 25.1 | B32: 其中：在建工程
A33: =A32+0.1 -> 25.2 | B33: 工程物资
A34: =A31+1 -> 26 | B34: 生产性生物资产
A35: =A34+1 -> 27 | B35: 油气资产
A36: =A35+1 -> 28 | B36: 使用权资产
A37: =A36+1 -> 29 | B37: 无形资产
A38: =A37+1 -> 30 | B38: 开发支出
A39: =A38+1 -> 31 | B39: 商誉
A40: =A39+1 -> 32 | B40: 长期待摊费用
...

Sheet Word附注
A1: 序号 | B1: 科目名称
A2: 1 | B2: 货币资金 | E2: 汇总明细
C3: 项 目 | D3: 期末数 | G3: 期初数
D4: 外币金额 | E4: 折算率 | F4: 人民币金额 | G4: 外币金额 | H4: 折算率 | I4: 人民币金额
C5: 库存现金： | F5: =货币资金!B3 -> 0 | I5: =G5*H5 -> 0
C6: 人民币 | F6: =货币资金!B4 -> 0 | I6: =G6*H6 -> 0
C7: 美元 | F7: =货币资金!B5 -> 0 | I7: =G7*H7 -> 0
C8: 银行存款： | F8: =货币资金!B6 -> 0 | I8: =G8*H8 -> 0
C9: 人民币 | F9: =货币资金!B7 -> 0 | I9: =G9*H9 -> 0
C10: 美元 | F10: =货币资金!B8 -> 0 | I10: =G10*H10 -> 0
C11: 银行存款中：财务公司存款 | F11: =货币资金!B35 -> 0 | I11: =G11*H11 -> 0
C12: 其中：人民币 | F12: =货币资金!B33 -> 0 | I12: =G12*H12 -> 0
C13: 美元 | F13: =货币资金!B34 -> 0 | I13: =G13*H13 -> 0
C14: 其他货币资金： | F14: =货币资金!B9 -> 0 | I14: =G14*H14 -> 0
C15: 人民币 | F15: =货币资金!B10 -> 0 | I15: =G15*H15 -> 0
C16: 美元 | F16: =货币资金!B11 -> 0 | I16: =G16*H16 -> 0
C17: 合 计 | F17: =F5+F8+F14 -> 0 | I17: =I5+I8+I14 -> 0
C18: 其中：存放在境外的款项总额 | F18: =货币资金!B29 -> 0
C19: （如无外币，直接用库存现金、银行存款、其他货币资金三行）
C20: 期末，本集团不存在抵押、质押或冻结、或存放在境外且资金汇回受到限制的款项。
C21: （披露因抵押、质押或冻结等对使用有限制的款项，以及存放在境外的款项总额。公司应单独披露存放在境外且资金汇回受到限制的款项。）
A23: 2 | B23: 交易性金融资产 | E23: 汇总明细
C24: 项 目 | D24: 期末
C25: 债务工具投资 | D25: =交易性金融资产!D4 -> 0
C26: 权益工具投资 | D26: =交易性金融资产!D5 -> 0
C27: 衍生金融资产 | D27: =交易性金融资产!D6 -> 0
C28: 其他 | D28: =交易性金融资产!D7 -> 0
C29: 合 计 | D29: =SUM(D25:D28) -> 0
C30: （说明：
C31: （1）管理层认为交易性金融资产投资变现[不存在重大限制]。/〔存在下列限制：具体限制及原因〕）
C32: （2）请说明交易性金融资产期末公允价值的确认方法及对当期损益的影响，如采用估值技术确定公允价值时，应详细披露估值模型、重要参数的选取依据和估值过程，以及必要的敏感性分析。）
A34: 3 | B34: 以公允价值计量且其变动计入当期损益的金融资产 | E34: 汇总明细
G35: 证券公司格式 | H35: 项 目 | I35: 期末数 | K35: 期初数 | M35: 本期
C36: 项 目 | D36: 期末公允价值 | E36: 期初公允价值 | I36: 成本 | J36: 公允价值 | K36: 成本 | L36: 公允价值 | M36: 变动
C37: 交易性金融资产 | D37: =SUM(D38:D41) -> 0 | E37: =SUM(E38:E41) -> 0 | H37: 交易性金融资产 | I37: =SUM(I38:I41) -> 0 | J37: =SUM(J38:J41) -> 0 | K37: =SUM(K38:K41) -> 0 | L37: =SUM(L38:L41) -> 0 | M37: =J37-L37 -> 0
C38: 其中：债务工具投资 | D38: =以公允价值计量且其变动计入当期损益的金融资产!B4 -> 0 | H38: 其中：债务工具投资 | I38: =以公允价值计量且其变动计入当期损益的金融资产!B21 -> 0 | J38: =以公允价值计量且其变动计入当期损益的金融资产!B4 -> 0 | M38: =J38-L38 -> 0
C39: 权益工具投资 | D39: =以公允价值计量且其变动计入当期损益的金融资产!B5 -> 0 | H39: 权益工具投资 | I39: =以公允价值计量且其变动计入当期损益的金融资产!B22 -> 0 | J39: =以公允价值计量且其变动计入当期损益的金融资产!B5 -> 0 | M39: =J39-L39 -> 0
C40: 衍生金融资产 | D40: =以公允价值计量且其变动计入当期损益的金融资产!B6 -> 0 | H40: 衍生金融资产 | I40: =以公允价值计量且其变动计入当期损益的金融资产!B23 -> 0 | J40: =以公允价值计量且其变动计入当期损益的金融资产!B6 -> 0 | M40: =J40-L40 -> 0
C41: 其他 | D41: =以公允价值计量且其变动计入当期损益的金融资产!B7 -> 0 | H41: 其他 | I41: =以公允价值计量且其变动计入当期损益的金融资产!B24 -> 0 | J41: =以公允价值计量且其变动计入当期损益的金融资产!B7 -> 0 | M41: =J41-L41 -> 0
C42: 指定为以公允价值计量且其变动计入当期损益的金融资产 | D42: =SUM(D43:D46) -> 0 | E42: =SUM(E43:E46) -> 0 | H42: 指定为以公允价值计量且其变动计入当期损益的金融资产 | I42: =SUM(I43:I46) -> 0 | J42: =SUM(J43:J46) -> 0 | K42: =SUM(K43:K46) -> 0 | L42: =SUM(L43:L46) -> 0 | M42: =J42-L42 -> 0
...

Sheet 现金流量表主表
A1: 致同会计师事务所
A2: 现金流量表-主表核查记录
A3: 客户名称： | C3: 编制人： | E3: 日期： | F3: 索引： | G3: A5-1-2
A4: 会计期间： | C4: 复核人： | E4: 日期: | F4: 页次：
A5: 项目 | B5: 行次 | C5: 差异(按报表账户) | D5: 原报数 | E5: 测算数 | F5: 有关测算依据
C6: 1=3-2 | D6: 2 | E6: 3 | F6: 4
A7: 一、经营活动产生的现金流量：
A8: 销售商品、提供劳务收到的现金 | B8: 1 | C8: =E8-D8 -> 0 | E8: =G18 -> 0 | F8: = 营业收入 | G8: =营业收入!B12+营业收入!B54 -> 0
F9: ＋应收账款期初余额-应收账款期末余额 | G9: =现金流量表附表!I54 -> 0
F10: ＋应收票据期初余额-应收票据期末余额 | G10: =现金流量表附表!I53 -> 0
F11: ＋预收账款期末余额-预收账款期初余额 | G11: =现金流量表附表!I65 -> 0
F12: ＋当期收回前期核销的坏账
F13: —以非现金资产抵偿债务而减少的应收账款和应收票据
F14: —当期核销的坏账 | G14: =应收账款!B103+其他应收款!B91 -> 0
F15: —票据贴现的利息 | G15: =财务费用!B6 -> 0
F16: ＋当期收到的销项税
F17: ＋其他
F18: 小计 | G18: =G8+G9+G10+G11+G12-G13-G14-G15+G16+G17 -> 0
A20: 收到的税费返还 | B20: 2 | C20: =E20-D20 -> 0 | E20: =G28 -> 0 | F20: = 增值税退税： | G20: =G21+G22 -> 0
F21: 实际收到的出口退税(不包括用于抵减内销产品应纳税额的部分)=根据应收补贴款账户以及应交增值税(出口退税)专栏分析确定
F22: 先征后返增值税=补贴收入(返还增值税)账户发生额
F23: ＋所得税退税 | G23: =G24 -> 0
F24: 所得税账户当期退税数
F25: ＋先征后返的消费税、营业税 | G25: =G26 -> 0
F26: 根据营业税金及附加、其他业务支出等账户发生额分析确定
F27: ＋其他
F28: 小计 | G28: =G20+G23+G25+G27 -> 0
A30: 收到的其他与经营活动有关的现金 | B30: 3 | C30: =E30-D30 -> 0 | E30: =G35 -> 0 | F30: = 补贴收入
F31: + 财务费用-利息收入 | G31: =财务费用!B5 -> 0
F32: + 营业外收入（扣除处置长期资产利得、债务重组等）
F33: ＋(其他应收款期初余额-其他应收款期末余额) | G33: =现金流量表附表!I55 -> 0
F34: ＋其他
F35: 小计 | G35: =G30+G31+G32+G33+G34 -> 0
A37: 经营活动现金流入小计 | B37: 4 | C37: =C8+C20+C30 -> 0 | D37: =D8+D20+D30 -> 0 | E37: =E8+E20+E30 -> 0
A38: 购买商品、接受劳务支付的现金 | B38: 5 | C38: =E38-D38 -> 0 | E38: =G53 -> 0 | F38: = 营业成本 | G38: =营业成本!B12+营业成本!B54 -> 0
F39: - 存货期初余额-存货期末余额 | G39: =现金流量表附表!I50 -> 0
F40: + 应付账款期初余额-应付账款期末余额 | G40: =-现金流量表附表!I63 -> 0
F41: + 预付账款期初余额-预付账款期末余额 | G41: =现金流量表附表!I56 -> 0
F42: + 应付票据期初余额-应付票据期末余额 | G42: =-现金流量表附表!I64 -> 0
F43: - 当期以非现金资产清偿债务减少的应付账款和应付票据
...

Sheet 现金流量表附表
A1: 致同会计师事务所
A2: 现金流量表-补充资料的核查记录
A3: 客户名称： | C3: 编制人： | G3: 日期： | J3: 返回Excel目录 | M3: 索引： | N3: A5-1-3
A4: 会计期间： | C4: 复核人: | G4: 日期: | M4: 页次：
A5: （一）现金流量表补充资料
A6: 补充资料 | B6: 行次 | C6: 差异(按报表账户) | D6: 原报数 | E6: 测算数 | F6: 有关测算依据
C7: 1=3-2 | D7: 2 | E7: 3 | F7: 4
A8: 1、将净利润调节为经营活动现金流量：
A9: 净利润 | B9: 40 | C9: =E9-D9 -> 0
A10: 加：少数股东收益
A11: 加：计提的资产减值准备 | B11: 41 | C11: =E11-D11 -> 0 | E11: =G26 -> 0 | F11: = 本期计提应收帐款坏账准备
F12: + 本期计提其他应收款坏账准备
F13: + 本期计提存货跌价准备 | G13: =资产减值损失!B4 -> 0
F14: + 本期计提可供出售金融资产减值准备 | G14: =资产减值损失!B5 -> 0
F15: + 本期计提持有至到期投资减值准备 | G15: =资产减值损失!B6 -> 0
F16: + 本期计提长期投资减值准备 | G16: =资产减值损失!B7 -> 0
F17: + 本期计提投资性房地产减值准备 | G17: =资产减值损失!B8 -> 0
F18: + 本期计提固定资产减值准备 | G18: =资产减值损失!B9 -> 0
F19: + 本期计提工程物资减值准备 | G19: =资产减值损失!B10 -> 0
F20: + 本期计提在建工程减值准备 | G20: =资产减值损失!B11 -> 0
F21: + 本期计提生产性生物资产减值准备 | G21: =资产减值损失!B12 -> 0
F22: + 本期计提油气资产减值准备 | G22: =资产减值损失!B13 -> 0
F23: + 本期计提无形资产减值准备 | G23: =资产减值损失!B14 -> 0
F24: + 本期计提商誉减值准备 | G24: =资产减值损失!B15 -> 0
F25: + 本期计提其他减值准备 | G25: =资产减值损失!B16 -> 0
F26: 小计 | G26: =SUM(G11:G25) -> 0
A28: 固定资产折旧、油气资产折耗、生产性生物资产折旧 | B28: 43 | C28: =E28-D28 -> 0 | E28: =G30 -> 0 | F28: = 固定资产本期计提折旧额 | G28: =固定资产!B82 -> 0
F29: + 油气资产本期计提折耗额
F30: + 生产性生物资产本期计提折旧额 | G30: ='生产性生物资产（成本计量）'!B84 -> 0
F31: 小计 | G31: =SUM(G28:G30) -> 0
A33: 无形资产摊销 | B33: 44 | C33: =E33-D33 -> 0 | E33: =G33 -> 0 | F33: = 无形资产本期计提摊销额 | G33: =无形资产!B92 -> 0
A34: 长期待摊费用摊销 | B34: 45 | C34: =E34-D34 -> 0 | E34: =G34 -> 0 | F34: = 长期待摊费用本期摊销数 | G34: =长期待摊费用!B27 -> 0
A35: 处置固定资产、无形资产和其他长期资产的损失（收益以"-"填列） | B35: 46 | C35: =E35-D35 -> 0 | E35: =L40 -> 0 | G35: 原值 | H35: 累计折旧 | I35: 减值准备 | J35: 净值 | K35: 收现/付现 | L35: 净损失
F36: = 固定资产 | J36: =G36-H36-I36 -> 0 | L36: =J36-K36 -> 0
F37: = 无形资产 | J37: =G37-H37-I37 -> 0 | L37: =J37-K37 -> 0
F38: = 其他长期资产 | J38: =G38-H38-I38 -> 0 | L38: =J38-K38 -> 0
F39: = 其他 | J39: =G39-H39-I39 -> 0 | L39: =J39-K39 -> 0
F40: 小计 | G40: =SUM(G36:G39) -> 0 | H40: =SUM(H36:H39) -> 0 | I40: =SUM(I36:I39) -> 0 | J40: =SUM(J36:J39) -> 0 | K40: =SUM(K36:K39) -> 0 | L40: =SUM(L36:L39) -> 0
A41: 固定资产报废损失（收益以"-"填列） | B41: 47 | C41: =E41-D41 -> 0 | E41: =固定资产!B45-固定资产!B100-固定资产!B155-E35 -> 0
A42: 公允价值变动损失（收益以“－”号填列） | B42: 48 | C42: =E42-D42 -> 0 | E42: =G42 -> 0 | F42: = 公允价值变动损益本期发生额 | G42: =-公允价值变动收益!B9 -> 0
...

Sheet 货币资金
A1: 货币资金附注汇总 | D1: 返回Excel目录 | E1: 返回word附注
A2: 项目 | B2: 审定数 | C2: 抵消数 | D2: 汇总 | E2: 母公司审定 | F2: 子公司1 | G2: 子公司2 | H2: 子公司3 | I2: 子公司4 | J2: 子公司5 | K2: 子公司6 | L2: 子公司7 | M2: 子公司8 | N2: 子公司9 | O2: 子公司10 | P2: 子公司11 | Q2: 子公司12
A3: 现金 | B3: =SUM(B4:B5) -> 0 | C3: =SUM(C4:C5) -> 0 | D3: =SUM(E3:Q3) -> 0 | E3: =SUM(E4:E5) -> 0 | F3: =SUM(F4:F5) -> 0 | G3: =SUM(G4:G5) -> 0 | H3: =SUM(H4:H5) -> 0 | I3: =SUM(I4:I5) -> 0 | J3: =SUM(J4:J5) -> 0 | K3: =SUM(K4:K5) -> 0 | L3: =SUM(L4:L5) -> 0 | ... Q3: =SUM(Q4:Q5) -> 0
A4: 其中：人民币 | B4: =D4-C4 -> 0 | D4: =SUM(E4:Q4) -> 0 | E4: 0
A5: 美元 | B5: =D5-C5 -> 0 | D5: =SUM(E5:Q5) -> 0 | E5: 0
A6: 银行存款 | B6: =SUM(B7:B8) -> 0 | C6: =SUM(C7:C8) -> 0 | D6: =SUM(E6:Q6) -> 0 | E6: =SUM(E7:E8) -> 0 | F6: =SUM(F7:F8) -> 0 | G6: =SUM(G7:G8) -> 0 | H6: =SUM(H7:H8) -> 0 | I6: =SUM(I7:I8) -> 0 | J6: =SUM(J7:J8) -> 0 | K6: =SUM(K7:K8) -> 0 | L6: =SUM(L7:L8) -> 0 | ... Q6: =SUM(Q7:Q8) -> 0
A7: 其中：人民币 | B7: =D7-C7 -> 0 | D7: =SUM(E7:Q7) -> 0 | E7: 0
A8: 美元 | B8: =D8-C8 -> 0 | D8: =SUM(E8:Q8) -> 0 | E8: 0
A9: 其他货币资金 | B9: =SUM(B10:B11) -> 0 | C9: =SUM(C10:C11) -> 0 | D9: =SUM(E9:Q9) -> 0 | E9: =SUM(E10:E11) -> 0 | F9: =SUM(F10:F11) -> 0 | G9: =SUM(G10:G11) -> 0 | H9: =SUM(H10:H11) -> 0 | I9: =SUM(I10:I11) -> 0 | J9: =SUM(J10:J11) -> 0 | K9: =SUM(K10:K11) -> 0 | L9: =SUM(L10:L11) -> 0 | ... Q9: =SUM(Q10:Q11) -> 0
A10: 其中：人民币 | B10: =D10-C10 -> 0 | D10: =SUM(E10:Q10) -> 0 | E10: 0
A11: 美元 | B11: =D11-C11 -> 0 | D11: =SUM(E11:Q11) -> 0 | E11: 0
A12: 合计 | B12: =B3+B6+B9 -> 0 | C12: =C3+C6+C9 -> 0 | D12: =D3+D6+D9 -> 0 | E12: =E3+E6+E9 -> 0 | F12: =F3+F6+F9 -> 0 | G12: =G3+G6+G9 -> 0 | H12: =H3+H6+H9 -> 0 | I12: =I3+I6+I9 -> 0 | ... Q12: =Q3+Q6+Q9 -> 0
A13: 试算表链接： | B13: 0 | D13: =SUM(E13:Q13) -> 0 | E13: 0
A14: 差异 | B14: =B12-B13 -> 0 | D14: =D12-D13 -> 0 | E14: =E12-E13 -> 0 | F14: =F12-F13 -> 0 | G14: =G12-G13 -> 0 | H14: =H12-H13 -> 0 | I14: =I12-I13 -> 0 | J14: =J12-J13 -> 0 | K14: =K12-K13 -> 0 | ... Q14: =Q12-Q13 -> 0
A16: 说明存在抵押、冻结等对变现有限制或存放在境外、或有潜在回收风险的资金
A17: 其他货币资金明细
A18: 项目 | B18: 审定数 | C18: 抵消数 | D18: 汇总 | E18: 母公司 | F18: 子公司1 | G18: 子公司2 | H18: 子公司3 | I18: 子公司4 | J18: 子公司5 | K18: 子公司6 | L18: 子公司7 | M18: 子公司8 | N18: 子公司9 | O18: 子公司10 | P18: 子公司11 | Q18: 子公司12
A19: 票据保证金 | B19: =D19-C19 -> 0 | D19: =SUM(E19:Q19) -> 0 | E19: 0
A20: 信用证保证金 | B20: =D20-C20 -> 0 | D20: =SUM(E20:Q20) -> 0 | E20: 0
A21: 存出投资款 | B21: =D21-C21 -> 0 | D21: =SUM(E21:Q21) -> 0 | E21: 0
A22: … | B22: =D22-C22 -> 0 | D22: =SUM(E22:Q22) -> 0 | E22: 0
A23: 合计 | B23: =SUM(B19:B22) -> 0 | C23: =SUM(C19:C22) -> 0 | D23: =SUM(D19:D22) -> 0 | E23: =SUM(E19:E22) -> 0 | F23: =SUM(F19:F22) -> 0 | J23: =SUM(J19:J22) -> 0 | K23: =SUM(K19:K22) -> 0 | P23: =SUM(P19:P22) -> 0 | Q23: =SUM(Q19:Q22) -> 0
A24: 差异 | B24: =B9-B23 -> 0 | C24: =C9-C23 -> 0 | D24: =D9-D23 -> 0 | E24: =E9-E23 -> 0 | F24: =F9-F23 -> 0 | J24: =J9-J23 -> 0 | K24: =K9-K23 -> 0 | P24: =P9-P23 -> 0 | Q24: =Q9-Q23 -> 0
A26: 存放境外的款项
A27: 项目 | B27: 审定数 | C27: 抵消数 | D27: 汇总 | E27: 母公司 | F27: 子公司1 | G27: 子公司2 | H27: 子公司3 | I27: 子公司4 | J27: 子公司5 | K27: 子公司6 | L27: 子公司7 | M27: 子公司8 | N27: 子公司9 | O27: 子公司10 | P27: 子公司11 | Q27: 子公司12
B28: =D28-C28 -> 0 | D28: =SUM(E28:Q28) -> 0 | E28: 0
A29: 合计 | B29: =B28 -> 0 | C29: =C28 -> 0 | D29: =D28 -> 0 | E29: =E28 -> 0 | F29: =F28 -> 0 | J29: =J28 -> 0 | K29: =K28 -> 0 | P29: =P28 -> 0 | Q29: =Q28 -> 0
A31: 银行存款中：财务公司存款
A32: 项目 | B32: 审定数 | C32: 抵消数 | D32: 汇总 | E32: 母公司 | F32: 子公司1 | G32: 子公司2 | H32: 子公司3 | I32: 子公司4 | J32: 子公司5 | K32: 子公司6 | L32: 子公司7 | M32: 子公司8 | N32: 子公司9 | O32: 子公司10 | P32: 子公司11 | Q32: 子公司12
A33: 其中：人民币 | B33: =D33-C33 -> 0 | D33: =SUM(E33:Q33) -> 0 | E33: 0
A34: 美元 | B34: =D34-C34 -> 0 | D34: =SUM(E34:Q34) -> 0 | E34: 0
A35: 合计 | B35: =SUM(B33:B34) -> 0 | C35: =SUM(C33:C34) -> 0 | D35: =SUM(D33:D34) -> 0 | E35: =SUM(E33:E34) -> 0 | F35: =SUM(F33:F34) -> 0 | G35: =SUM(G33:G34) -> 0 | H35: =SUM(H33:H34) -> 0 | I35: =SUM(I33:I34) -> 0 | ... Q35: =SUM(Q33:Q34) -> 0

Sheet 交易性金融资产
A1: 交易性金融资产附注汇总 | D1: 返回Excel目录 | E1: 返回word附注
A3: 项目 | B3: 审定数 | C3: 抵消数 | D3: 汇总 | E3: 母公司审定 | F3: 子公司1 | G3: 子公司2 | H3: 子公司3 | I3: 子公司4 | J3: 子公司5 | K3: 子公司6 | L3: 子公司7 | M3: 子公司8 | N3: 子公司9 | O3: 子公司10 | P3: 子公司11 | Q3: 子公司12
A4: 债务工具投资 | B4: =D4-C4 -> 0 | D4: =SUM(E4:Q4) -> 0 | E4: 0
A5: 权益工具投资 | B5: =D5-C5 -> 0 | D5: =SUM(E5:Q5) -> 0 | E5: 0
A6: 衍生金融资产 | B6: =D6-C6 -> 0 | D6: =SUM(E6:Q6) -> 0 | E6: 0
A7: 其他 | B7: =D7-C7 -> 0 | D7: =SUM(E7:Q7) -> 0 | E7: 0
A8: 合计 | B8: =SUM(B4:B7) -> 0 | C8: =SUM(C4:C7) -> 0 | D8: =SUM(D4:D7) -> 0 | E8: =SUM(E4:E7) -> 0 | F8: =SUM(F4:F7) -> 0 | G8: =SUM(G4:G7) -> 0 | H8: =SUM(H4:H7) -> 0 | I8: =SUM(I4:I7) -> 0 | ... Q8: =SUM(Q4:Q7) -> 0
A9: 试算表链接：
A10: 差异 | B10: =B8-B9 -> 0
A11: 说明：
A12: （1）管理层认为交易性金融资产投资变现[不存在重大限制]。/〔存在下列限制：具体限制及原因〕）
A13: （2）请说明交易性金融资产期末公允价值的确认方法及对当期损益的影响，如采用估值技术确定公允价值时，应详细披露估值模型、重要参数的选取依据和估值过程，以及必要的敏感性分析。

Sheet 以公允价值计量且其变动计入当期损益的金融资产
A1: 以公允价值计量且其变动计入当期损益的金融资产 | E1: 返回Excel目录 | F1: 返回word附注
A2: 项目 | B2: 审定数 | C2: 抵消数 | D2: 汇总 | E2: 母公司审定 | F2: 子公司1 | G2: 子公司2 | H2: 子公司3 | I2: 子公司4 | J2: 子公司5 | K2: 子公司6 | L2: 子公司7 | M2: 子公司8 | N2: 子公司9 | O2: 子公司10 | P2: 子公司11 | Q2: 子公司12
A3: 交易性金融资产 | B3: =SUM(B4:B7) -> 0 | C3: =SUM(C4:C7) -> 0 | D3: =SUM(E3:Q3) -> 0 | E3: =SUM(E4:E7) -> 0 | F3: =SUM(F4:F7) -> 0 | G3: =SUM(G4:G7) -> 0 | H3: =SUM(H4:H7) -> 0 | I3: =SUM(I4:I7) -> 0 | J3: =SUM(J4:J7) -> 0 | K3: =SUM(K4:K7) -> 0 | L3: =SUM(L4:L7) -> 0 | ... Q3: =SUM(Q4:Q7) -> 0
A4: 其中：债务工具投资 | B4: =D4-C4 -> 0 | D4: =SUM(E4:Q4) -> 0 | E4: 0
A5: 权益工具投资 | B5: =D5-C5 -> 0 | D5: =SUM(E5:Q5) -> 0 | E5: 0
A6: 衍生金融资产 | B6: =D6-C6 -> 0 | D6: =SUM(E6:Q6) -> 0 | E6: 0
A7: 其他 | B7: =D7-C7 -> 0 | D7: =SUM(E7:Q7) -> 0 | E7: 0
A8: 指定为以公允价值计量且其变动计入当期损益的金融资产 | B8: =SUM(B9:B12) -> 0 | C8: =SUM(C9:C12) -> 0 | D8: =SUM(E8:Q8) -> 0 | E8: =SUM(E9:E12) -> 0 | F8: =SUM(F9:F12) -> 0 | G8: =SUM(G9:G12) -> 0 | H8: =SUM(H9:H12) -> 0 | I8: =SUM(I9:I12) -> 0 | J8: =SUM(J9:J12) -> 0 | K8: =SUM(K9:K12) -> 0 | L8: =SUM(L9:L12) -> 0 | ... Q8: =SUM(Q9:Q12) -> 0
A9: 其中：债务工具投资 | B9: =D9-C9 -> 0 | D9: =SUM(E9:Q9) -> 0 | E9: 0
A10: 权益工具投资 | B10: =D10-C10 -> 0 | D10: =SUM(E10:Q10) -> 0 | E10: 0
A11: 衍生金融资产 | B11: =D11-C11 -> 0 | D11: =SUM(E11:Q11) -> 0 | E11: 0
A12: 其他 | B12: =D12-C12 -> 0 | D12: =SUM(E12:Q12) -> 0 | E12: 0
A13: 合 计 | B13: =B3+B8 -> 0 | C13: =C3+C8 -> 0 | D13: =SUM(E13:Q13) -> 0 | E13: =E3+E8 -> 0 | F13: =F3+F8 -> 0 | G13: =G3+G8 -> 0 | H13: =H3+H8 -> 0 | I13: =I3+I8 -> 0 | J13: =J3+J8 -> 0 | K13: =K3+K8 -> 0 | L13: =L3+L8 -> 0 | ... Q13: =Q3+Q8 -> 0
A14: 试算表链接： | B14: 0 | D14: =SUM(E14:Q14) -> 0 | E14: 0
A15: 差异 | B15: =B13-B14 -> 0 | D15: =D13-D14 -> 0 | E15: =E13-E14 -> 0 | F15: =F13-F14 -> 0 | G15: =G13-G14 -> 0 | H15: =H13-H14 -> 0 | I15: =I13-I14 -> 0 | J15: =J13-J14 -> 0 | K15: =K13-K14 -> 0 | ... Q15: =Q13-Q14 -> 0
A16: 说明：
A18: 适用：证券公司披露成本金额
A19: 项目 | B19: 审定数 | C19: 抵消数 | D19: 汇总 | E19: 母公司审定 | F19: 子公司1 | G19: 子公司2 | H19: 子公司3 | I19: 子公司4 | J19: 子公司5 | K19: 子公司6 | L19: 子公司7 | M19: 子公司8 | N19: 子公司9 | O19: 子公司10 | P19: 子公司11 | Q19: 子公司12
A20: 交易性金融资产 | B20: =SUM(B21:B24) -> 0 | C20: =SUM(C21:C24) -> 0 | D20: =SUM(E20:Q20) -> 0 | E20: =SUM(E21:E24) -> 0 | F20: =SUM(F21:F24) -> 0 | G20: =SUM(G21:G24) -> 0 | H20: =SUM(H21:H24) -> 0 | I20: =SUM(I21:I24) -> 0 | J20: =SUM(J21:J24) -> 0 | K20: =SUM(K21:K24) -> 0 | L20: =SUM(L21:L24) -> 0 | ... Q20: =SUM(Q21:Q24) -> 0
A21: 其中：债务工具投资 | B21: =D21-C21 -> 0 | D21: =SUM(E21:Q21) -> 0 | E21: 0
A22: 权益工具投资 | B22: =D22-C22 -> 0 | D22: =SUM(E22:Q22) -> 0 | E22: 0
A23: 衍生金融资产 | B23: =D23-C23 -> 0 | D23: =SUM(E23:Q23) -> 0 | E23: 0
A24: 其他 | B24: =D24-C24 -> 0 | D24: =SUM(E24:Q24) -> 0 | E24: 0
A25: 指定为以公允价值计量且其变动计入当期损益的金融资产 | B25: =SUM(B26:B29) -> 0 | C25: =SUM(C26:C29) -> 0 | D25: =SUM(E25:Q25) -> 0 | E25: 0 | F25: =SUM(F26:F29) -> 0 | G25: =SUM(G26:G29) -> 0 | H25: =SUM(H26:H29) -> 0 | I25: =SUM(I26:I29) -> 0 | J25: =SUM(J26:J29) -> 0 | K25: =SUM(K26:K29) -> 0 | L25: =SUM(L26:L29) -> 0 | M25: =SUM(M26:M29) -> 0 | ... Q25: =SUM(Q26:Q29) -> 0
A26: 其中：债务工具投资 | B26: =D26-C26 -> 0 | D26: =SUM(E26:Q26) -> 0 | E26: 0
A27: 权益工具投资 | B27: =D27-C27 -> 0 | D27: =SUM(E27:Q27) -> 0 | E27: 0
A28: 衍生金融资产 | B28: =D28-C28 -> 0 | D28: =SUM(E28:Q28) -> 0 | E28: 0
A29: 其他 | B29: =D29-C29 -> 0 | D29: =SUM(E29:Q29) -> 0 | E29: 0
A30: 合 计 | B30: =B20+B25 -> 0 | C30: =C20+C25 -> 0 | D30: =SUM(E30:Q30) -> 0 | E30: =E20+E25 -> 0 | F30: =F20+F25 -> 0 | G30: =G20+G25 -> 0 | H30: =H20+H25 -> 0 | I30: =I20+I25 -> 0 | J30: =J20+J25 -> 0 | K30: =K20+K25 -> 0 | L30: =L20+L25 -> 0 | ... Q30: =Q20+Q25 -> 0

Sheet 衍生金融资产
A1: 衍生金融资产附注 | D1: 返回Excel目录 | E1: 返回word附注
A2: 项目 | B2: 审定数 | C2: 抵消数 | D2: 汇总 | E2: 母公司审定 | F2: 子公司1 | G2: 子公司2 | H2: 子公司3 | I2: 子公司4 | J2: 子公司5 | K2: 子公司6 | L2: 子公司7 | M2: 子公司8 | N2: 子公司9 | O2: 子公司10 | P2: 子公司11 | Q2: 子公司12
B3: =D3-C3 -> 0 | D3: =SUM(E3:Q3) -> 0 | E3: 0
B4: =D4-C4 -> 0 | D4: =SUM(E4:Q4) -> 0 | E4: 0
B5: =D5-C5 -> 0 | D5: =SUM(E5:Q5) -> 0 | E5: 0
B6: =D6-C6 -> 0 | D6: =SUM(E6:Q6) -> 0 | E6: 0
B7: =D7-C7 -> 0 | D7: =SUM(E7:Q7) -> 0 | E7: 0
B8: =D8-C8 -> 0 | D8: =SUM(E8:Q8) -> 0 | E8: 0
A9: 合计 | B9: =SUM(B3:B8) -> 0 | C9: =SUM(C3:C8) -> 0 | D9: =SUM(D3:D8) -> 0 | E9: =SUM(E3:E8) -> 0 | F9: =SUM(F3:F8) -> 0 | G9: =SUM(G3:G8) -> 0 | H9: =SUM(H3:H8) -> 0 | I9: =SUM(I3:I8) -> 0 | ... Q9: =SUM(Q3:Q8) -> 0
A10: 试算表链接： | B10: 0 | D10: =SUM(E10:Q10) -> 0 | E10: 0
A11: 差异 | B11: =B9-B10 -> 0 | D11: =D9-D10 -> 0 | E11: =E9-E10 -> 0 | F11: =F9-F10 -> 0 | G11: =G9-G10 -> 0 | H11: =H9-H10 -> 0 | I11: =I9-I10 -> 0 | J11: =J9-J10 -> 0 | K11: =K9-K10 -> 0 | ... Q11: =Q9-Q10 -> 0
A12: 说明：（衍生金融资产产生的原因以及相关会计处理。）

Sheet 应收票据
A1: 应收票据附注汇总 | D1: 返回Excel目录 | E1: 返回word附注
A2: 项目 | B2: 审定数 | C2: 抵消数 | D2: 汇总 | E2: 母公司审定 | F2: 子公司1 | G2: 子公司2 | H2: 子公司3 | I2: 子公司4 | J2: 子公司5 | K2: 子公司6 | L2: 子公司7 | M2: 子公司8 | N2: 子公司9 | O2: 子公司10 | P2: 子公司11 | Q2: 子公司12
A3: 银行承兑汇票 | B3: =D3-C3 -> 0 | D3: =SUM(E3:Q3) -> 0 | E3: 0
A4: 商业承兑汇票 | B4: =D4-C4 -> 0 | D4: =SUM(E4:Q4) -> 0 | E4: 0
A5: 合计 | B5: =SUM(B3:B4) -> 0 | C5: =SUM(C3:C4) -> 0 | D5: =SUM(E5:Q5) -> 0 | E5: =SUM(E3:E4) -> 0 | F5: =SUM(F3:F4) -> 0 | G5: =SUM(G3:G4) -> 0 | H5: =SUM(H3:H4) -> 0 | I5: =SUM(I3:I4) -> 0 | J5: =SUM(J3:J4) -> 0 | K5: =SUM(K3:K4) -> 0 | L5: =SUM(L3:L4) -> 0 | ... Q5: =SUM(Q3:Q4) -> 0
A6: 试算表链接： | B6: 0 | D6: =SUM(E6:Q6) -> 0 | E6: 0
A7: 差异 | B7: =B5-B6 -> 0 | C7: =C5-C6 -> 0 | D7: =D5-D6 -> 0 | E7: =E5-E6 -> 0 | F7: =F5-F6 -> 0 | G7: =G5-G6 -> 0 | H7: =H5-H6 -> 0 | I7: =I5-I6 -> 0 | ... Q7: =Q5-Q6 -> 0
A9: （1）期末本集团已质押的应收票据
A10: 项目 | B10: 审定数 | C10: 抵消数 | D10: 汇总 | E10: 母公司审定 | F10: 子公司1 | G10: 子公司2 | H10: 子公司3 | I10: 子公司4 | J10: 子公司5 | K10: 子公司6 | L10: 子公司7 | M10: 子公司8 | N10: 子公司9 | O10: 子公司10 | P10: 子公司11 | Q10: 子公司12
A11: 银行承兑汇票 | B11: =D11-C11 -> 0 | D11: =SUM(E11:Q11) -> 0 | E11: 0
A12: 商业承兑汇票 | B12: =D12-C12 -> 0 | D12: =SUM(E12:Q12) -> 0 | E12: 0
A13: 合计 | B13: =SUM(B11:B12) -> 0 | C13: =SUM(C11:C12) -> 0 | D13: =SUM(E13:Q13) -> 0 | E13: =SUM(E11:E12) -> 0 | F13: =SUM(F11:F12) -> 0 | G13: =SUM(G11:G12) -> 0 | H13: =SUM(H11:H12) -> 0 | I13: =SUM(I11:I12) -> 0 | J13: =SUM(J11:J12) -> 0 | K13: =SUM(K11:K12) -> 0 | L13: =SUM(L11:L12) -> 0 | ... Q13: =SUM(Q11:Q12) -> 0
A15: （2）期末本集团已背书或贴现但尚未到期的应收票据
A16: A、背书尚未到期
A17: 项目 | B17: 审定数 | C17: 抵消数 | D17: 汇总 | E17: 母公司审定 | F17: 子公司1 | G17: 子公司2 | H17: 子公司3 | I17: 子公司4 | J17: 子公司5 | K17: 子公司6 | L17: 子公司7 | M17: 子公司8 | N17: 子公司9 | O17: 子公司10 | P17: 子公司11 | Q17: 子公司12
A18: 银行承兑汇票 | B18: =D18-C18 -> 0 | D18: =SUM(E18:Q18) -> 0 | E18: 0
A19: 商业承兑汇票 | B19: =D19-C19 -> 0 | D19: =SUM(E19:Q19) -> 0 | E19: 0
A20: 合计 | B20: =SUM(B18:B19) -> 0 | C20: =SUM(C18:C19) -> 0 | D20: =SUM(E20:Q20) -> 0 | E20: =SUM(E18:E19) -> 0 | F20: =SUM(F18:F19) -> 0 | G20: =SUM(G18:G19) -> 0 | H20: =SUM(H18:H19) -> 0 | I20: =SUM(I18:I19) -> 0 | J20: =SUM(J18:J19) -> 0 | K20: =SUM(K18:K19) -> 0 | L20: =SUM(L18:L19) -> 0 | ... Q20: =SUM(Q18:Q19) -> 0
A21: B、贴现金额
A22: 项目 | B22: 审定数 | C22: 抵消数 | D22: 汇总 | E22: 母公司审定 | F22: 子公司1 | G22: 子公司2 | H22: 子公司3 | I22: 子公司4 | J22: 子公司5 | K22: 子公司6 | L22: 子公司7 | M22: 子公司8 | N22: 子公司9 | O22: 子公司10 | P22: 子公司11 | Q22: 子公司12
A23: 银行承兑汇票 | B23: =D23-C23 -> 0 | D23: =SUM(E23:Q23) -> 0 | E23: 0
A24: 商业承兑汇票 | B24: =D24-C24 -> 0 | D24: =SUM(E24:Q24) -> 0 | E24: 0
A25: 合计 | B25: =SUM(B23:B24) -> 0 | C25: =SUM(C23:C24) -> 0 | D25: =SUM(E25:Q25) -> 0 | E25: =SUM(E23:E24) -> 0 | F25: =SUM(F23:F24) -> 0 | G25: =SUM(G23:G24) -> 0 | H25: =SUM(H23:H24) -> 0 | I25: =SUM(I23:I24) -> 0 | J25: =SUM(J23:J24) -> 0 | K25: =SUM(K23:K24) -> 0 | L25: =SUM(L23:L24) -> 0 | ... Q25: =SUM(Q23:Q24) -> 0
A26: （如根据《企业会计准则第23号——金融资产转移》终止确认的应收票据，列示其终止确认的金额，及与终止确认相关的利得和损失）
A28: （3）期末本集团因出票人未履约而其转应收账款的票据
A29: 项目 | B29: 审定数 | C29: 抵消数 | D29: 汇总 | E29: 母公司审定 | F29: 子公司1 | G29: 子公司2 | H29: 子公司3 | I29: 子公司4 | J29: 子公司5 | K29: 子公司6 | L29: 子公司7 | M29: 子公司8 | N29: 子公司9 | O29: 子公司10 | P29: 子公司11 | Q29: 子公司12
A30: 商业承兑汇票 | B30: =D30-C30 -> 0 | D30: =SUM(E30:Q30) -> 0 | E30: 0
B31: =D31-C31 -> 0 | D31: =SUM(E31:Q31) -> 0 | E31: 0
A32: 合计 | B32: =SUM(B30:B31) -> 0 | C32: =SUM(C30:C31) -> 0 | D32: =SUM(E32:Q32) -> 0 | E32: =SUM(E30:E31) -> 0 | F32: =SUM(F30:F31) -> 0 | G32: =SUM(G30:G31) -> 0 | H32: =SUM(H30:H31) -> 0 | I32: =SUM(I30:I31) -> 0 | J32: =SUM(J30:J31) -> 0 | K32: =SUM(K30:K31) -> 0 | L32: =SUM(L30:L31) -> 0 | ... Q32: =SUM(Q30:Q31) -> 0

Sheet 应收账款
A1: 应收账款附注 | E1: 返回Excel目录 | F1: 返回word附注
A2: 一、单项金额分类（原值）
A3: 项目 | B3: 审定数 | C3: 各项占比 | D3: 抵消数 | E3: 汇总 | F3: 母公司审定 | G3: 子公司1 | H3: 子公司2 | I3: 子公司3 | J3: 子公司4 | K3: 子公司5 | L3: 子公司6 | M3: 子公司7 | N3: 子公司8 | O3: 子公司9 | P3: 子公司10 | Q3: 子公司11 | R3: 子公司12
A4: 单项金额重大单项计提 | B4: =E4-D4 -> 0 | C4: =IF(ISERROR(B4/$B$9),"",B4/$B$9%) | E4: =SUM(F4:R4) -> 0 | F4: 0
A5: 按组合计提坏账 | B5: =E5-D5 -> 0 | C5: =IF(ISERROR(B5/$B$9),"",B5/$B$9%) | E5: =SUM(F5:R5) -> 0 | F5: 0
A6: 组合1 | B6: =E6-D6 -> 0 | C6: =IF(ISERROR(B6/$B$9),"",B6/$B$9%) | E6: =SUM(F6:R6) -> 0 | F6: 0
A7: 组合2 | B7: =E7-D7 -> 0 | C7: =IF(ISERROR(B7/$B$9),"",B7/$B$9%) | E7: =SUM(F7:R7) -> 0 | F7: 0
A8: 单项不重大单项计提坏账 | B8: =E8-D8 -> 0 | C8: =IF(ISERROR(B8/$B$9),"",B8/$B$9%) | E8: =SUM(F8:R8) -> 0 | F8: 0
A9: 合计 | B9: =SUM(B4:B8) -> 0 | C9: =SUM(C4:C8) -> 0 | D9: =SUM(D4:D8) -> 0 | E9: =SUM(F9:R9) -> 0 | F9: =SUM(F4:F8) -> 0 | G9: =SUM(G4:G8) -> 0 | H9: =SUM(H4:H8) -> 0 | I9: =SUM(I4:I8) -> 0 | J9: =SUM(J4:J8) -> 0 | K9: =SUM(K4:K8) -> 0 | L9: =SUM(L4:L8) -> 0 | M9: =SUM(M4:M8) -> 0 | ... R9: =SUM(R4:R8) -> 0
A11: 二、单项金额分类（坏账准备）
A12: 项目 | B12: 审定数 | C12: 计提比例 | D12: 抵消数 | E12: 汇总 | F12: 母公司审定 | G12: 子公司1 | H12: 子公司2 | I12: 子公司3 | J12: 子公司4 | K12: 子公司5 | L12: 子公司6 | M12: 子公司7 | N12: 子公司8 | O12: 子公司9 | P12: 子公司10 | Q12: 子公司11 | R12: 子公司12
A13: 单项金额重大单项计提 | B13: =E13-D13 -> 0 | C13: =IF(ISERROR(B13/B4),"",B13/B4) | E13: =SUM(F13:R13) -> 0 | F13: 0
A14: 按组合计提坏账 | B14: =E14-D14 -> 0 | C14: =IF(ISERROR(B14/B5),"",B14/B5) | E14: =SUM(F14:R14) -> 0 | F14: 0
A15: 组合1 | B15: =E15-D15 -> 0 | C15: =IF(ISERROR(B15/B6),"",B15/B6) | E15: =SUM(F15:R15) -> 0 | F15: 0
A16: 组合2 | B16: =E16-D16 -> 0 | C16: =IF(ISERROR(B16/B7),"",B16/B7) | E16: =SUM(F16:R16) -> 0 | F16: 0
A17: 单项不重大单项计提坏账 | B17: =E17-D17 -> 0 | C17: =IF(ISERROR(B17/B8),"",B17/B8) | E17: =SUM(F17:R17) -> 0 | F17: 0
A18: 合计 | B18: =SUM(B13:B17) -> 0 | C18: =IF(ISERROR(B18/B9),"",B18/B9) | D18: =SUM(D13:D17) -> 0 | E18: =SUM(F18:R18) -> 0 | F18: =SUM(F13:F17) -> 0 | G18: =SUM(G13:G17) -> 0 | H18: =SUM(H13:H17) -> 0 | I18: =SUM(I13:I17) -> 0 | J18: =SUM(J13:J17) -> 0 | K18: =SUM(K13:K17) -> 0 | L18: =SUM(L13:L17) -> 0 | M18: =SUM(M13:M17) -> 0 | ... R18: =SUM(R13:R17) -> 0
A19: 净值 | B19: =B9-B18 -> 0 | D19: =D9-D18 -> 0 | E19: =SUM(F19:R19) -> 0 | F19: =F9-F18 -> 0 | G19: =G9-G18 -> 0 | H19: =H9-H18 -> 0 | I19: =I9-I18 -> 0 | J19: =J9-J18 -> 0 | K19: =K9-K18 -> 0 | L19: =L9-L18 -> 0 | M19: =M9-M18 -> 0 | ... R19: =R9-R18 -> 0
A20: 试算表链接： | B20: 0 | E20: =SUM(F20:R20) -> 0 | F20: 0
A21: 差异 | B21: =B19-B20 -> 0 | E21: =E19-E20 -> 0 | F21: =F19-F20 -> 0 | G21: =G19-G20 -> 0 | H21: =H19-H20 -> 0 | I21: =I19-I20 -> 0 | J21: =J19-J20 -> 0 | K21: =K19-K20 -> 0 | L21: =L19-L20 -> 0 | ... R21: =R19-R20 -> 0
A22: 三、按账龄组合计提坏账（原值）
A23: 项目 | B23: 审定数 | C23: 各项占比 | D23: 抵消数 | E23: 汇总 | F23: 母公司审定 | G23: 子公司1 | H23: 子公司2 | I23: 子公司3 | J23: 子公司4 | K23: 子公司5 | L23: 子公司6 | M23: 子公司7 | N23: 子公司8 | O23: 子公司9 | P23: 子公司10 | Q23: 子公司11 | R23: 子公司12
A24: 1年以内 | B24: =E24-D24 -> 0 | C24: =IF(ISERROR(B24/$B$30),"",B24/$B$30) | E24: =SUM(F24:R24) -> 0 | F24: 0
A25: 1-2年 | B25: =E25-D25 -> 0 | C25: =IF(ISERROR(B25/$B$30),"",B25/$B$30) | E25: =SUM(F25:R25) -> 0 | F25: 0
A26: 2-3年 | B26: =E26-D26 -> 0 | C26: =IF(ISERROR(B26/$B$30),"",B26/$B$30) | E26: =SUM(F26:R26) -> 0 | F26: 0
A27: 3-4年 | B27: =E27-D27 -> 0 | C27: =IF(ISERROR(B27/$B$30),"",B27/$B$30) | E27: =SUM(F27:R27) -> 0 | F27: 0
A28: 4-5年 | B28: =E28-D28 -> 0 | C28: =IF(ISERROR(B28/$B$30),"",B28/$B$30) | E28: =SUM(F28:R28) -> 0 | F28: 0
A29: 5年以上 | B29: =E29-D29 -> 0 | C29: =IF(ISERROR(B29/$B$30),"",B29/$B$30) | E29: =SUM(F29:R29) -> 0 | F29: 0
A30: 合计 | B30: =SUM(B24:B29) -> 0 | C30: =SUM(C24:C29) -> 0 | D30: =SUM(D24:D29) -> 0 | E30: =SUM(F30:R30) -> 0 | F30: =SUM(F24:F29) -> 0 | G30: =SUM(G24:G29) -> 0 | H30: =SUM(H24:H29) -> 0 | I30: =SUM(I24:I29) -> 0 | J30: =SUM(J24:J29) -> 0 | K30: =SUM(K24:K29) -> 0 | L30: =SUM(L24:L29) -> 0 | M30: =SUM(M24:M29) -> 0 | ... R30: =SUM(R24:R29) -> 0
A31: 差异 | B31: =B5-B30 -> 0 | E31: =E5-E30 -> 0 | F31: =F5-F30 -> 0 | G31: =G5-G30 -> 0 | H31: =H5-H30 -> 0 | I31: =I5-I30 -> 0 | J31: =J5-J30 -> 0 | K31: =K5-K30 -> 0 | L31: =L5-L30 -> 0 | ... R31: =R5-R30 -> 0
A33: 四、按账龄组合计提坏账（坏账准备）
A34: 项目 | B34: 审定数 | C34: 计提比例 | D34: 抵消数 | E34: 汇总 | F34: 母公司审定 | G34: 子公司1 | H34: 子公司2 | I34: 子公司3 | J34: 子公司4 | K34: 子公司5 | L34: 子公司6 | M34: 子公司7 | N34: 子公司8 | O34: 子公司9 | P34: 子公司10 | Q34: 子公司11 | R34: 子公司12
A35: 1年以内 | B35: =E35-D35 -> 0 | C35: =IF(ISERROR(B35/B24),"",B35/B24%) | E35: =SUM(F35:R35) -> 0 | F35: 0
A36: 1-2年 | B36: =E36-D36 -> 0 | C36: =IF(ISERROR(B36/B25),"",B36/B25%) | E36: =SUM(F36:R36) -> 0 | F36: 0
A37: 2-3年 | B37: =E37-D37 -> 0 | C37: =IF(ISERROR(B37/B26),"",B37/B26%) | E37: =SUM(F37:R37) -> 0 | F37: 0
A38: 3-4年 | B38: =E38-D38 -> 0 | C38: =IF(ISERROR(B38/B27),"",B38/B27%) | E38: =SUM(F38:R38) -> 0 | F38: 0
A39: 4-5年 | B39: =E39-D39 -> 0 | C39: =IF(ISERROR(B39/B28),"",B39/B28%) | E39: =SUM(F39:R39) -> 0 | F39: 0
A40: 5年以上 | B40: =E40-D40 -> 0 | C40: =IF(ISERROR(B40/B29),"",B40/B29%) | E40: =SUM(F40:R40) -> 0 | F40: 0
A41: 合计 | B41: =SUM(B35:B40) -> 0 | C41: =IF(ISERROR(B41/B30),"",B41/B30%) | D41: =SUM(D35:D40) -> 0 | E41: =SUM(F41:R41) -> 0 | F41: =SUM(F35:F40) -> 0 | G41: =SUM(G35:G40) -> 0 | H41: =SUM(H35:H40) -> 0 | I41: =SUM(I35:I40) -> 0 | J41: =SUM(J35:J40) -> 0 | K41: =SUM(K35:K40) -> 0 | L41: =SUM(L35:L40) -> 0 | M41: =SUM(M35:M40) -> 0 | ... R41: =SUM(R35:R40) -> 0
A42: 差异 | B42: =B41-B14 -> 0 | E42: =E41-E14 -> 0 | F42: =F41-F14 -> 0 | G42: =G41-G14 -> 0 | H42: =H41-H14 -> 0 | I42: =I41-I14 -> 0 | J42: =J41-J14 -> 0 | K42: =K41-K14 -> 0 | L42: =L41-L14 -> 0 | ... R42: =R41-R14 -> 0
...

Sheet 预付款项
A1: 预付款项附注 | E1: 返回Excel目录 | F1: 返回word附注
A2: 项目 | B2: 审定数 | C2: 各项占比 | D2: 抵消数 | E2: 汇总 | F2: 母公司审定 | G2: 子公司1 | H2: 子公司2 | I2: 子公司3 | J2: 子公司4 | K2: 子公司5 | L2: 子公司6 | M2: 子公司7 | N2: 子公司8 | O2: 子公司9 | P2: 子公司10 | Q2: 子公司11 | R2: 子公司12
A3: 1年以内 | B3: =E3-D3 -> 0 | C3: =B3/$B$7 -> #DIV/0! | E3: =SUM(F3:R3) -> 0 | F3: 0
A4: 1-2年 | B4: =E4-D4 -> 0 | C4: =B4/$B$7 -> #DIV/0! | E4: =SUM(F4:R4) -> 0 | F4: 0
A5: 2-3年 | B5: =E5-D5 -> 0 | C5: =B5/$B$7 -> #DIV/0! | E5: =SUM(F5:R5) -> 0 | F5: 0
A6: 3年以上 | B6: =E6-D6 -> 0 | C6: =B6/$B$7 -> #DIV/0! | E6: =SUM(F6:R6) -> 0 | F6: 0
A7: 合计 | B7: =SUM(B3:B6) -> 0 | C7: =B7/$B$7 -> #DIV/0! | D7: =SUM(D3:D6) -> 0 | E7: =SUM(F7:R7) -> 0 | F7: =SUM(F3:F6) -> 0 | G7: =SUM(G3:G6) -> 0 | H7: =SUM(H3:H6) -> 0 | I7: =SUM(I3:I6) -> 0 | J7: =SUM(J3:J6) -> 0 | K7: =SUM(K3:K6) -> 0 | L7: =SUM(L3:L6) -> 0 | M7: =SUM(M3:M6) -> 0 | ... R7: =SUM(R3:R6) -> 0
A8: 试算表链接： | B8: 0 | E8: =SUM(F8:R8) -> 0 | F8: 0
A9: 差异 | B9: =B7-B8 -> 0 | E9: =E7-E8 -> 0 | F9: =F7-F8 -> 0 | G9: =G7-G8 -> 0 | H9: =H7-H8 -> 0 | I9: =I7-I8 -> 0 | J9: =J7-J8 -> 0 | K9: =K7-K8 -> 0 | L9: =L7-L8 -> 0 | ... R9: =R7-R8 -> 0
A11: 说明：（账龄超过1年的金额重要预付账款，应说明未及时结算的原因。）
A14: 2、预付款项金额前五名单位情况
A15: （按预付对象集中度，汇总或分别披露期末余额前五名的预付款项的期末余额及占预付款项期末余额合计数的比例。）
A16: 汇总披露格式：
A17: 本期按预付对象归集的期末余额前五名预付款项汇总金额XXXX元，占预付款项期末余额合计数的比例 %。
A18: 分别披露格式：
A20: 债权人名称 | B20: 单位名称 | C20: 预付款项期末余额 | D20: 占预付款项期末余额合计数的比例%
D21: =C21/$B$7% -> #DIV/0!
D22: =C22/$B$7% -> #DIV/0!
D23: =C23/$B$7% -> #DIV/0!
D24: =C24/$B$7% -> #DIV/0!
D25: =C25/$B$7% -> #DIV/0!
A26: 合 计 | C26: =SUM(C21:C25) -> 0 | D26: =SUM(D21:D25) -> #DIV/0!

Sheet 应收利息、应收股利、其他应收款
A1: 其他应收款汇总附注 | D1: 返回Excel目录 | E1: 返回word附注
A2: 项目 | B2: 审定数 | C2: 抵消数 | D2: 汇总 | E2: 母公司审定 | F2: 子公司1 | G2: 子公司2 | H2: 子公司3 | I2: 子公司4 | J2: 子公司5 | K2: 子公司6 | L2: 子公司7 | M2: 子公司8 | N2: 子公司9 | O2: 子公司10 | P2: 子公司11 | Q2: 子公司12
A3: 应收利息 | B3: =D3-C3 -> 0 | D3: =SUM(E3:Q3) -> 0 | E3: =应收利息!E7 -> 0 | F3: =应收利息!F7 -> 0 | G3: =应收利息!G7 -> 0 | H3: =应收利息!H7 -> 0 | I3: =应收利息!I7 -> 0 | J3: =应收利息!J7 -> 0 | K3: =应收利息!K7 -> 0 | L3: =应收利息!L7 -> 0 | ... Q3: =应收利息!Q7 -> 0
A4: 应收股利 | B4: =D4-C4 -> 0 | D4: =SUM(E4:Q4) -> 0 | E4: =应收股利!E10 -> 0 | F4: =应收股利!F10 -> 0 | G4: =应收股利!G10 -> 0 | H4: =应收股利!H10 -> 0 | I4: =应收股利!I10 -> 0 | J4: =应收股利!J10 -> 0 | K4: =应收股利!K10 -> 0 | L4: =应收股利!L10 -> 0 | ... Q4: =应收股利!Q10 -> 0
A5: 其他应收款 | B5: =D5-C5 -> 0 | D5: =SUM(E5:Q5) -> 0 | E5: =其他应收款!F19 -> 0 | F5: =其他应收款!G19 -> 0 | G5: =其他应收款!H19 -> 0 | H5: =其他应收款!I19 -> 0 | I5: =其他应收款!J19 -> 0 | J5: =其他应收款!K19 -> 0 | K5: =其他应收款!L19 -> 0 | L5: =其他应收款!M19 -> 0 | ... Q5: =其他应收款!R19 -> 0
A6: 合 计 | B6: =SUM(B3:B5) -> 0 | C6: =SUM(C3:C5) -> 0 | D6: =SUM(D3:D5) -> 0 | E6: =SUM(E3:E5) -> 0 | F6: =SUM(F3:F5) -> 0 | G6: =SUM(G3:G5) -> 0 | H6: =SUM(H3:H5) -> 0 | I6: =SUM(I3:I5) -> 0 | ... Q6: =SUM(Q3:Q5) -> 0

Sheet 应收利息
A1: 应收利息附注 | D1: 返回Excel目录 | E1: 返回word附注
A2: 项目 | B2: 审定数 | C2: 抵消数 | D2: 汇总 | E2: 母公司审定 | F2: 子公司1 | G2: 子公司2 | H2: 子公司3 | I2: 子公司4 | J2: 子公司5 | K2: 子公司6 | L2: 子公司7 | M2: 子公司8 | N2: 子公司9 | O2: 子公司10 | P2: 子公司11 | Q2: 子公司12
A3: 定期存款 | B3: =D3-C3 -> 0 | D3: =SUM(E3:Q3) -> 0 | E3: 0
A4: 委托贷款 | B4: =D4-C4 -> 0 | D4: =SUM(E4:Q4) -> 0 | E4: 0
A5: 债券投资 | B5: =D5-C5 -> 0 | D5: =SUM(E5:Q5) -> 0 | E5: 0
A6: 可无限量添加行 | B6: =D6-C6 -> 0 | D6: =SUM(E6:Q6) -> 0 | E6: 0
A7: 合 计 | B7: =SUM(B3:B6) -> 0 | C7: =SUM(C3:C6) -> 0 | D7: =SUM(E7:Q7) -> 0 | E7: =SUM(E3:E6) -> 0 | F7: =SUM(F3:F6) -> 0 | G7: =SUM(G3:G6) -> 0 | H7: =SUM(H3:H6) -> 0 | I7: =SUM(I3:I6) -> 0 | J7: =SUM(J3:J6) -> 0 | K7: =SUM(K3:K6) -> 0 | L7: =SUM(L3:L6) -> 0 | ... Q7: =SUM(Q3:Q6) -> 0
A8: 试算表链接： | B8: 0 | D8: =SUM(E8:Q8) -> 0 | E8: 0
A9: 差异 | B9: =B7-B8 -> 0 | D9: =D7-D8 -> 0 | E9: =E7-E8 -> 0 | F9: =F7-F8 -> 0 | G9: =G7-G8 -> 0 | H9: =H7-H8 -> 0 | I9: =I7-I8 -> 0 | J9: =J7-J8 -> 0 | K9: =K7-K8 -> 0 | ... Q9: =Q7-Q8 -> 0
A11: 其中，重要的逾期应收利息如下：
A12: 债权单位 | B12: 借款单位 | C12: 期末数 | D12: 逾期时间 | E12: 逾期原因 | F12: 是否发生减值及其原因
A21: 合 计 | C21: =SUM(C13:C20) -> 0
A22: （对于重要的逾期应收利息，应按借款单位披露应收利息的期末余额、逾期时间和逾期原因、是否发生减值的判断。）
A23: 其他说明：

Sheet 应收股利
A1: 应收股利附注 | D1: 返回Excel目录 | E1: 返回word附注
A2: 项目 | B2: 审定数 | C2: 抵消数 | D2: 汇总 | E2: 母公司审定 | F2: 子公司1 | G2: 子公司2 | H2: 子公司3 | I2: 子公司4 | J2: 子公司5 | K2: 子公司6 | L2: 子公司7 | M2: 子公司8 | N2: 子公司9 | O2: 子公司10 | P2: 子公司11 | Q2: 子公司12
B3: =D3-C3 -> 0 | D3: =SUM(E3:Q3) -> 0 | E3: 0
B4: =D4-C4 -> 0 | D4: =SUM(E4:Q4) -> 0 | E4: 0
B5: =D5-C5 -> 0 | D5: =SUM(E5:Q5) -> 0 | E5: 0
B6: =D6-C6 -> 0 | D6: =SUM(E6:Q6) -> 0 | E6: 0
B7: =D7-C7 -> 0 | D7: =SUM(E7:Q7) -> 0 | E7: 0
B8: =D8-C8 -> 0 | D8: =SUM(E8:Q8) -> 0 | E8: 0
B9: =D9-C9 -> 0 | D9: =SUM(E9:Q9) -> 0 | E9: 0
A10: 合 计 | B10: =SUM(B3:B9) -> 0 | C10: =SUM(C3:C9) -> 0 | D10: =SUM(D3:D9) -> 0 | E10: =SUM(E3:E9) -> 0 | F10: =SUM(F3:F9) -> 0 | G10: =SUM(G3:G9) -> 0 | H10: =SUM(H3:H9) -> 0 | I10: =SUM(I3:I9) -> 0 | ... Q10: =SUM(Q3:Q9) -> 0
A11: 试算表链接： | B11: 0 | D11: =SUM(E11:Q11) -> 0 | E11: 0
A12: 差异 | B12: =B10-B11 -> 0 | D12: =D10-D11 -> 0 | E12: =E10-E11 -> 0 | F12: =F10-F11 -> 0 | G12: =G10-G11 -> 0 | H12: =H10-H11 -> 0 | I12: =I10-I11 -> 0 | J12: =J10-J11 -> 0 | K12: =K10-K11 -> 0 | ... Q12: =Q10-Q11 -> 0
A13: 其中，重要的账龄超过1年的应收股利如下：
A14: 投资单位名称 | B14: 被投资单位 | C14: 期末数 | D14: 账龄 | E14: 未收回的原因 | F14: 是否发生减值及其判断依据
A24: 合 计 | C24: =SUM(C15:C23) -> 0
A25: （对于重要的账龄超过1 年的应收股利，应披露未收回的原因和对相关款项是否发生减值的判断。）
A26: 其他说明：

Sheet 其他应收款
A1: 其他应收款附注汇总 | D1: 返回Excel目录 | E1: 返回word附注
A2: 一、单项金额分类（原值）（按照股份公司标准，300万元）
A3: 项目 | B3: 审定数 | C3: 计提比例 | D3: 抵消数 | E3: 汇总 | F3: 母公司审定 | G3: 子公司1 | H3: 子公司2 | I3: 子公司3 | J3: 子公司4 | K3: 子公司5 | L3: 子公司6 | M3: 子公司7 | N3: 子公司8 | O3: 子公司9 | P3: 子公司10 | Q3: 子公司11 | R3: 子公司12
A4: 单项金额重大单项计提 | B4: =E4-D4 -> 0 | C4: =IF(ISERROR(B4/$B$9),"",B4/$B$9%) | E4: =SUM(F4:R4) -> 0 | F4: 0
A5: 按组合计提坏账 | B5: =E5-D5 -> 0 | C5: =IF(ISERROR(B5/$B$9),"",B5/$B$9%) | E5: =SUM(F5:R5) -> 0 | F5: 0
A6: 组合1 | B6: =E6-D6 -> 0 | C6: =IF(ISERROR(B6/$B$9),"",B6/$B$9%) | E6: =SUM(F6:R6) -> 0 | F6: 0
A7: 组合2 | B7: =E7-D7 -> 0 | C7: =IF(ISERROR(B7/$B$9),"",B7/$B$9%) | E7: =SUM(F7:R7) -> 0 | F7: 0
A8: 单项不重大单项计提坏账 | B8: =E8-D8 -> 0 | C8: =IF(ISERROR(B8/$B$9),"",B8/$B$9%) | E8: =SUM(F8:R8) -> 0 | F8: 0
A9: 合计 | B9: =SUM(B4:B8) -> 0 | C9: =SUM(C4:C8) -> 0 | D9: =SUM(D4:D8) -> 0 | E9: =SUM(F9:R9) -> 0 | F9: =SUM(F4:F8) -> 0 | G9: =SUM(G4:G8) -> 0 | H9: =SUM(H4:H8) -> 0 | I9: =SUM(I4:I8) -> 0 | J9: =SUM(J4:J8) -> 0 | K9: =SUM(K4:K8) -> 0 | L9: =SUM(L4:L8) -> 0 | M9: =SUM(M4:M8) -> 0 | ... R9: =SUM(R4:R8) -> 0
A11: 二、单项金额分类（坏账准备）
A12: 项目 | B12: 审定数 | C12: 计提比例 | D12: 抵消数 | E12: 汇总 | F12: 母公司审定 | G12: 子公司1 | H12: 子公司2 | I12: 子公司3 | J12: 子公司4 | K12: 子公司5 | L12: 子公司6 | M12: 子公司7 | N12: 子公司8 | O12: 子公司9 | P12: 子公司10 | Q12: 子公司11 | R12: 子公司12
A13: 单项金额重大单项计提 | B13: =E13-D13 -> 0 | C13: =IF(ISERROR(B13/$B$18),"",B13/$B$18%) | E13: =SUM(F13:R13) -> 0 | F13: 0
A14: 按组合计提坏账 | B14: =E14-D14 -> 0 | C14: =IF(ISERROR(B14/$B$18),"",B14/$B$18%) | E14: =SUM(F14:R14) -> 0 | F14: 0
A15: 组合1 | B15: =E15-D15 -> 0 | C15: =IF(ISERROR(B15/$B$18),"",B15/$B$18%) | E15: =SUM(F15:R15) -> 0 | F15: 0
A16: 组合2 | B16: =E16-D16 -> 0 | C16: =IF(ISERROR(B16/$B$18),"",B16/$B$18%) | E16: =SUM(F16:R16) -> 0 | F16: 0
A17: 单项不重大单项计提坏账 | B17: =E17-D17 -> 0 | C17: =IF(ISERROR(B17/$B$18),"",B17/$B$18%) | E17: =SUM(F17:R17) -> 0 | F17: 0
A18: 合计 | B18: =SUM(B13:B17) -> 0 | C18: =SUM(C13:C17) -> 0 | D18: =SUM(D13:D17) -> 0 | E18: =SUM(F18:R18) -> 0 | F18: =SUM(F13:F17) -> 0 | G18: =SUM(G13:G17) -> 0 | H18: =SUM(H13:H17) -> 0 | I18: =SUM(I13:I17) -> 0 | J18: =SUM(J13:J17) -> 0 | K18: =SUM(K13:K17) -> 0 | L18: =SUM(L13:L17) -> 0 | M18: =SUM(M13:M17) -> 0 | ... R18: =SUM(R13:R17) -> 0
A19: 净值 | B19: =B9-B18 -> 0 | D19: =D9-D18 -> 0 | E19: =E9-E18 -> 0 | F19: =F9-F18 -> 0 | G19: =G9-G18 -> 0 | H19: =H9-H18 -> 0 | I19: =I9-I18 -> 0 | J19: =J9-J18 -> 0 | K19: =K9-K18 -> 0 | ... R19: =R9-R18 -> 0
A20: 试算表链接： | B20: 0 | E20: =SUM(F20:R20) -> 0 | F20: 0
A21: 差异 | B21: =B19-B20 -> 0 | D21: =D19-D20 -> 0 | E21: =E19-E20 -> 0 | F21: =F19-F20 -> 0 | G21: =G19-G20 -> 0 | H21: =H19-H20 -> 0 | I21: =I19-I20 -> 0 | J21: =J19-J20 -> 0 | K21: =K19-K20 -> 0 | ... R21: =R19-R20 -> 0
A23: 三、按账龄组合分类
A24: 项目 | B24: 审定数 | C24: 各项占比 | D24: 抵消数 | E24: 汇总 | F24: 母公司审定 | G24: 子公司1 | H24: 子公司2 | I24: 子公司3 | J24: 子公司4 | K24: 子公司5 | L24: 子公司6 | M24: 子公司7 | N24: 子公司8 | O24: 子公司9 | P24: 子公司10 | Q24: 子公司11 | R24: 子公司12
A25: 1年以内 | B25: =E25-D25 -> 0 | C25: =IF(ISERROR(B25/$B$31),"",B25/$B$31%) | E25: =SUM(F25:R25) -> 0 | F25: 0
A26: 1-2年 | B26: =E26-D26 -> 0 | C26: =IF(ISERROR(B26/$B$31),"",B26/$B$31%) | E26: =SUM(F26:R26) -> 0 | F26: 0
A27: 2-3年 | B27: =E27-D27 -> 0 | C27: =IF(ISERROR(B27/$B$31),"",B27/$B$31%) | E27: =SUM(F27:R27) -> 0 | F27: 0
A28: 3-4年 | B28: =E28-D28 -> 0 | C28: =IF(ISERROR(B28/$B$31),"",B28/$B$31%) | E28: =SUM(F28:R28) -> 0 | F28: 0
A29: 4-5年 | B29: =E29-D29 -> 0 | C29: =IF(ISERROR(B29/$B$31),"",B29/$B$31%) | E29: =SUM(F29:R29) -> 0 | F29: 0
A30: 5年以上 | B30: =E30-D30 -> 0 | C30: =IF(ISERROR(B30/$B$31),"",B30/$B$31%) | E30: =SUM(F30:R30) -> 0 | F30: 0
A31: 合计 | B31: =SUM(B25:B30) -> 0 | C31: =SUM(C25:C30) -> 0 | D31: =SUM(D25:D30) -> 0 | E31: =SUM(F31:R31) -> 0 | F31: =SUM(F25:F30) -> 0 | G31: =SUM(G25:G30) -> 0 | H31: =SUM(H25:H30) -> 0 | I31: =SUM(I25:I30) -> 0 | J31: =SUM(J25:J30) -> 0 | K31: =SUM(K25:K30) -> 0 | L31: =SUM(L25:L30) -> 0 | M31: =SUM(M25:M30) -> 0 | ... R31: =SUM(R25:R30) -> 0
A32: 差异 | B32: =B5-B31 -> 0 | D32: =D5-D31 -> 0 | E32: =E5-E31 -> 0 | F32: =F5-F31 -> 0 | G32: =G5-G31 -> 0 | H32: =H5-H31 -> 0 | I32: =I5-I31 -> 0 | J32: =J5-J31 -> 0 | K32: =K5-K31 -> 0 | ... R32: =R5-R31 -> 0
A34: 四、按账龄组合分类（坏账准备）
A35: 项目 | B35: 审定数 | C35: 计提比例 | D35: 抵消数 | E35: 汇总 | F35: 母公司审定 | G35: 子公司1 | H35: 子公司2 | I35: 子公司3 | J35: 子公司4 | K35: 子公司5 | L35: 子公司6 | M35: 子公司7 | N35: 子公司8 | O35: 子公司9 | P35: 子公司10 | Q35: 子公司11 | R35: 子公司12
A36: 1年以内 | B36: =E36-D36 -> 0 | C36: =IF(ISERROR(B36/B25),"",B36/B25%) | E36: =SUM(F36:R36) -> 0 | F36: 0
A37: 1-2年 | B37: =E37-D37 -> 0 | C37: =IF(ISERROR(B37/B26),"",B37/B26%) | E37: =SUM(F37:R37) -> 0 | F37: 0
A38: 2-3年 | B38: =E38-D38 -> 0 | C38: =IF(ISERROR(B38/B27),"",B38/B27%) | E38: =SUM(F38:R38) -> 0 | F38: 0
A39: 3-4年 | B39: =E39-D39 -> 0 | C39: =IF(ISERROR(B39/B28),"",B39/B28%) | E39: =SUM(F39:R39) -> 0 | F39: 0
A40: 4-5年 | B40: =E40-D40 -> 0 | C40: =IF(ISERROR(B40/B29),"",B40/B29%) | E40: =SUM(F40:R40) -> 0 | F40: 0
A41: 5年以上 | B41: =E41-D41 -> 0 | C41: =IF(ISERROR(B41/B30),"",B41/B30%) | E41: =SUM(F41:R41) -> 0 | F41: 0
A42: 合计 | B42: =SUM(B36:B41) -> 0 | C42: =IF(ISERROR(B42/B31),"",B42/B31%) | D42: =SUM(D36:D41) -> 0 | E42: =SUM(F42:R42) -> 0 | F42: =SUM(F36:F41) -> 0 | G42: =SUM(G36:G41) -> 0 | H42: =SUM(H36:H41) -> 0 | I42: =SUM(I36:I41) -> 0 | J42: =SUM(J36:J41) -> 0 | K42: =SUM(K36:K41) -> 0 | L42: =SUM(L36:L41) -> 0 | M42: =SUM(M36:M41) -> 0 | ... R42: =SUM(R36:R41) -> 0
A43: 差异 | B43: =B42-B14 -> 0 | D43: =D42-D14 -> 0 | E43: =E42-E14 -> 0 | F43: =F42-F14 -> 0 | G43: =G42-G14 -> 0 | H43: =H42-H14 -> 0 | I43: =I42-I14 -> 0 | J43: =J42-J14 -> 0 | K43: =K42-K14 -> 0 | ... R43: =R42-R14 -> 0
...

Sheet 存货
A1: 存货附注汇总 | D1: 返回Excel目录 | E1: 返回word附注
A2: 存货账面原值
A3: 1、存货期初数
A4: 项目 | B4: 审定数 | C4: 抵消数 | D4: 汇总 | E4: 母公司审定 | F4: 子公司1 | G4: 子公司2 | H4: 子公司3 | I4: 子公司4 | J4: 子公司5 | K4: 子公司6 | L4: 子公司7 | M4: 子公司8 | N4: 子公司9 | O4: 子公司10 | P4: 子公司11 | Q4: 子公司12
A5: 原材料 | B5: =D5-C5 -> 0 | D5: =SUM(E5:Q5) -> 0 | E5: 0
A6: 自制半成品及在产品（在研品） | B6: =D6-C6 -> 0 | D6: =SUM(E6:Q6) -> 0 | E6: 0
A7: 库存商品（产成品） | B7: =D7-C7 -> 0 | D7: =SUM(E7:Q7) -> 0 | E7: 0
A8: 周转材料（包装物、低值易耗品等） | B8: =D8-C8 -> 0 | D8: =SUM(E8:Q8) -> 0 | E8: 0
A9: 工程施工（工程施工减工程结算） | B9: =D9-C9 -> 0 | D9: =SUM(E9:Q9) -> 0 | E9: 0
A10: 其他(发出商品） | B10: =D10-C10 -> 0 | D10: =SUM(E10:Q10) -> 0 | E10: 0
A11: 合计 | B11: =SUM(B5:B10) -> 0 | C11: =SUM(C5:C10) -> 0 | D11: =SUM(E11:Q11) -> 0 | E11: =SUM(E5:E10) -> 0 | F11: =SUM(F5:F10) -> 0 | G11: =SUM(G5:G10) -> 0 | H11: =SUM(H5:H10) -> 0 | I11: =SUM(I5:I10) -> 0 | J11: =SUM(J5:J10) -> 0 | K11: =SUM(K5:K10) -> 0 | L11: =SUM(L5:L10) -> 0 | ... Q11: =SUM(Q5:Q10) -> 0
A13: 2、本期增加
A14: 项目 | B14: 审定数 | C14: 抵消数 | D14: 汇总 | E14: 母公司审定 | F14: 子公司1 | G14: 子公司2 | H14: 子公司3 | I14: 子公司4 | J14: 子公司5 | K14: 子公司6 | L14: 子公司7 | M14: 子公司8 | N14: 子公司9 | O14: 子公司10 | P14: 子公司11 | Q14: 子公司12
A15: =A5 -> 原材料 | B15: =D15-C15 -> 0 | D15: =SUM(E15:Q15) -> 0 | E15: 0
A16: =A6 -> 自制半成品及在产品（在研品） | B16: =D16-C16 -> 0 | D16: =SUM(E16:Q16) -> 0 | E16: 0
A17: =A7 -> 库存商品（产成品） | B17: =D17-C17 -> 0 | D17: =SUM(E17:Q17) -> 0 | E17: 0
A18: =A8 -> 周转材料（包装物、低值易耗品等） | B18: =D18-C18 -> 0 | D18: =SUM(E18:Q18) -> 0 | E18: 0
A19: =A9 -> 工程施工（工程施工减工程结算） | B19: =D19-C19 -> 0 | D19: =SUM(E19:Q19) -> 0 | E19: 0
A20: =A10 -> 其他(发出商品） | B20: =D20-C20 -> 0 | D20: =SUM(E20:Q20) -> 0 | E20: 0
A21: 合计 | B21: =SUM(B15:B20) -> 0 | C21: =SUM(C15:C20) -> 0 | D21: =SUM(E21:Q21) -> 0 | E21: =SUM(E15:E20) -> 0 | F21: =SUM(F15:F20) -> 0 | G21: =SUM(G15:G20) -> 0 | H21: =SUM(H15:H20) -> 0 | I21: =SUM(I15:I20) -> 0 | J21: =SUM(J15:J20) -> 0 | K21: =SUM(K15:K20) -> 0 | L21: =SUM(L15:L20) -> 0 | ... Q21: =SUM(Q15:Q20) -> 0
A23: 3、本期减少
A24: 项目 | B24: 审定数 | C24: 抵消数 | D24: 汇总 | E24: 母公司审定 | F24: 子公司1 | G24: 子公司2 | H24: 子公司3 | I24: 子公司4 | J24: 子公司5 | K24: 子公司6 | L24: 子公司7 | M24: 子公司8 | N24: 子公司9 | O24: 子公司10 | P24: 子公司11 | Q24: 子公司12
A25: =A15 -> 原材料 | B25: =D25-C25 -> 0 | D25: =SUM(E25:Q25) -> 0 | E25: 0
A26: =A16 -> 自制半成品及在产品（在研品） | B26: =D26-C26 -> 0 | D26: =SUM(E26:Q26) -> 0 | E26: 0
A27: =A17 -> 库存商品（产成品） | B27: =D27-C27 -> 0 | D27: =SUM(E27:Q27) -> 0 | E27: 0
A28: =A18 -> 周转材料（包装物、低值易耗品等） | B28: =D28-C28 -> 0 | D28: =SUM(E28:Q28) -> 0 | E28: 0
A29: =A19 -> 工程施工（工程施工减工程结算） | B29: =D29-C29 -> 0 | D29: =SUM(E29:Q29) -> 0 | E29: 0
A30: =A20 -> 其他(发出商品） | B30: =D30-C30 -> 0 | D30: =SUM(E30:Q30) -> 0 | E30: 0
A31: 合计 | B31: =SUM(B25:B30) -> 0 | C31: =SUM(C25:C30) -> 0 | D31: =SUM(E31:Q31) -> 0 | E31: =SUM(E25:E30) -> 0 | F31: =SUM(F25:F30) -> 0 | G31: =SUM(G25:G30) -> 0 | H31: =SUM(H25:H30) -> 0 | I31: =SUM(I25:I30) -> 0 | J31: =SUM(J25:J30) -> 0 | K31: =SUM(K25:K30) -> 0 | L31: =SUM(L25:L30) -> 0 | ... Q31: =SUM(Q25:Q30) -> 0
A33: 4、存货期末数
A34: 项目 | B34: 审定数 | C34: 抵消数 | D34: 汇总 | E34: 母公司审定 | F34: 子公司1 | G34: 子公司2 | H34: 子公司3 | I34: 子公司4 | J34: 子公司5 | K34: 子公司6 | L34: 子公司7 | M34: 子公司8 | N34: 子公司9 | O34: 子公司10 | P34: 子公司11 | Q34: 子公司12
A35: =A25 -> 原材料 | B35: =D35-C35 -> 0 | C35: =C5+C15-C25 -> 0 | D35: =SUM(E35:Q35) -> 0 | E35: =E5+E15-E25 -> 0 | F35: =F5+F15-F25 -> 0 | G35: =G5+G15-G25 -> 0 | H35: =H5+H15-H25 -> 0 | I35: =I5+I15-I25 -> 0 | J35: =J5+J15-J25 -> 0 | K35: =K5+K15-K25 -> 0 | L35: =L5+L15-L25 -> 0 | ... Q35: =Q5+Q15-Q25 -> 0
A36: =A26 -> 自制半成品及在产品（在研品） | B36: =D36-C36 -> 0 | C36: =C6+C16-C26 -> 0 | D36: =SUM(E36:Q36) -> 0 | E36: =E6+E16-E26 -> 0 | F36: =F6+F16-F26 -> 0 | G36: =G6+G16-G26 -> 0 | H36: =H6+H16-H26 -> 0 | I36: =I6+I16-I26 -> 0 | J36: =J6+J16-J26 -> 0 | K36: =K6+K16-K26 -> 0 | L36: =L6+L16-L26 -> 0 | ... Q36: =Q6+Q16-Q26 -> 0
A37: =A27 -> 库存商品（产成品） | B37: =D37-C37 -> 0 | C37: =C7+C17-C27 -> 0 | D37: =SUM(E37:Q37) -> 0 | E37: =E7+E17-E27 -> 0 | F37: =F7+F17-F27 -> 0 | G37: =G7+G17-G27 -> 0 | H37: =H7+H17-H27 -> 0 | I37: =I7+I17-I27 -> 0 | J37: =J7+J17-J27 -> 0 | K37: =K7+K17-K27 -> 0 | L37: =L7+L17-L27 -> 0 | ... Q37: =Q7+Q17-Q27 -> 0
A38: =A28 -> 周转材料（包装物、低值易耗品等） | B38: =D38-C38 -> 0 | C38: =C8+C18-C28 -> 0 | D38: =SUM(E38:Q38) -> 0 | E38: =E8+E18-E28 -> 0 | F38: =F8+F18-F28 -> 0 | G38: =G8+G18-G28 -> 0 | H38: =H8+H18-H28 -> 0 | I38: =I8+I18-I28 -> 0 | J38: =J8+J18-J28 -> 0 | K38: =K8+K18-K28 -> 0 | L38: =L8+L18-L28 -> 0 | ... Q38: =Q8+Q18-Q28 -> 0
A39: =A29 -> 工程施工（工程施工减工程结算） | B39: =D39-C39 -> 0 | C39: =C9+C19-C29 -> 0 | D39: =SUM(E39:Q39) -> 0 | E39: =E9+E19-E29 -> 0 | F39: =F9+F19-F29 -> 0 | G39: =G9+G19-G29 -> 0 | H39: =H9+H19-H29 -> 0 | I39: =I9+I19-I29 -> 0 | J39: =J9+J19-J29 -> 0 | K39: =K9+K19-K29 -> 0 | L39: =L9+L19-L29 -> 0 | ... Q39: =Q9+Q19-Q29 -> 0
A40: =A30 -> 其他(发出商品） | B40: =D40-C40 -> 0 | C40: =C10+C20-C30 -> 0 | D40: =SUM(E40:Q40) -> 0 | E40: =E10+E20-E30 -> 0 | F40: =F10+F20-F30 -> 0 | G40: =G10+G20-G30 -> 0 | H40: =H10+H20-H30 -> 0 | I40: =I10+I20-I30 -> 0 | J40: =J10+J20-J30 -> 0 | K40: =K10+K20-K30 -> 0 | L40: =L10+L20-L30 -> 0 | ... Q40: =Q10+Q20-Q30 -> 0
A41: 合计 | B41: =SUM(B35:B40) -> 0 | C41: =SUM(C35:C40) -> 0 | D41: =SUM(E41:Q41) -> 0 | E41: =SUM(E35:E40) -> 0 | F41: =SUM(F35:F40) -> 0 | G41: =SUM(G35:G40) -> 0 | H41: =SUM(H35:H40) -> 0 | I41: =SUM(I35:I40) -> 0 | J41: =SUM(J35:J40) -> 0 | K41: =SUM(K35:K40) -> 0 | L41: =SUM(L35:L40) -> 0 | ... Q41: =SUM(Q35:Q40) -> 0
A43: 存货减值准备
A44: 1、存货跌价准备期初数
...

Sheet 合同资产
A1: 合同资产附注汇总 | D1: 返回Excel目录 | E1: 返回word附注
A2: 合同资产
A3: 1、合同资产期初数
A4: 项目 | B4: 审定数 | C4: 抵消数 | D4: 汇总 | E4: 母公司审定 | F4: 子公司1 | G4: 子公司2 | H4: 子公司3 | I4: 子公司4 | J4: 子公司5 | K4: 子公司6 | L4: 子公司7 | M4: 子公司8 | N4: 子公司9 | O4: 子公司10 | P4: 子公司11 | Q4: 子公司12
A5: 一、合同资产原值
A6: 类别A | B6: =D6-C6 -> 0 | D6: =SUM(E6:Q6) -> 0 | E6: 0
A7: 类别B | B7: =D7-C7 -> 0 | D7: =SUM(E7:Q7) -> 0 | E7: 0
A8: 类别C | B8: =D8-C8 -> 0 | D8: =SUM(E8:Q8) -> 0 | E8: 0
A9: 小计 | B9: =SUM(B6:B8) -> 0 | C9: =SUM(C6:C8) -> 0 | D9: =SUM(D6:D8) -> 0 | E9: =SUM(E6:E8) -> 0 | F9: =SUM(F6:F8) -> 0 | G9: =SUM(G6:G8) -> 0 | H9: =SUM(H6:H8) -> 0 | I9: =SUM(I6:I8) -> 0 | ... Q9: =SUM(Q6:Q8) -> 0
A10: 二、合同资产坏账准备
A11: 类别A | B11: =D11-C11 -> 0 | C11: =C45 -> 0 | D11: =SUM(E11:Q11) -> 0 | E11: =E45 -> 0 | F11: =F45 -> 0 | G11: =G45 -> 0 | H11: =H45 -> 0 | I11: =I45 -> 0 | J11: =J45 -> 0 | K11: =K45 -> 0 | L11: =L45 -> 0 | ... Q11: =Q45 -> 0
A12: 类别B | B12: =D12-C12 -> 0 | C12: =C52 -> 0 | D12: =SUM(E12:Q12) -> 0 | E12: =E52 -> 0 | F12: =F52 -> 0 | G12: =G52 -> 0 | H12: =H52 -> 0 | I12: =I52 -> 0 | J12: =J52 -> 0 | K12: =K52 -> 0 | L12: =L52 -> 0 | ... Q12: =Q52 -> 0
A13: 类别C | B13: =D13-C13 -> 0 | C13: =C59 -> 0 | D13: =SUM(E13:Q13) -> 0 | E13: =E59 -> 0 | F13: =F59 -> 0 | G13: =G59 -> 0 | H13: =H59 -> 0 | I13: =I59 -> 0 | J13: =J59 -> 0 | K13: =K59 -> 0 | L13: =L59 -> 0 | ... Q13: =Q59 -> 0
A14: 小计 | B14: =SUM(B11:B13) -> 0 | C14: =SUM(C11:C13) -> 0 | D14: =SUM(D11:D13) -> 0 | E14: =SUM(E11:E13) -> 0 | F14: =SUM(F11:F13) -> 0 | G14: =SUM(G11:G13) -> 0 | H14: =SUM(H11:H13) -> 0 | I14: =SUM(I11:I13) -> 0 | ... Q14: =SUM(Q11:Q13) -> 0
A15: 三、合同资产净值
A16: 类别A | B16: =D16-C16 -> 0 | C16: =C6-C11 -> 0 | D16: =SUM(E16:Q16) -> 0 | E16: =E6-E11 -> 0 | F16: =F6-F11 -> 0 | G16: =G6-G11 -> 0 | H16: =H6-H11 -> 0 | I16: =I6-I11 -> 0 | J16: =J6-J11 -> 0 | K16: =K6-K11 -> 0 | L16: =L6-L11 -> 0 | ... Q16: =Q6-Q11 -> 0
A17: 类别B | B17: =D17-C17 -> 0 | C17: =C7-C12 -> 0 | D17: =SUM(E17:Q17) -> 0 | E17: =E7-E12 -> 0 | F17: =F7-F12 -> 0 | G17: =G7-G12 -> 0 | H17: =H7-H12 -> 0 | I17: =I7-I12 -> 0 | J17: =J7-J12 -> 0 | K17: =K7-K12 -> 0 | L17: =L7-L12 -> 0 | ... Q17: =Q7-Q12 -> 0
A18: 类别C | B18: =D18-C18 -> 0 | C18: =C8-C13 -> 0 | D18: =SUM(E18:Q18) -> 0 | E18: =E8-E13 -> 0 | F18: =F8-F13 -> 0 | G18: =G8-G13 -> 0 | H18: =H8-H13 -> 0 | I18: =I8-I13 -> 0 | J18: =J8-J13 -> 0 | K18: =K8-K13 -> 0 | L18: =L8-L13 -> 0 | ... Q18: =Q8-Q13 -> 0
A19: 合计 | B19: =SUM(B16:B18) -> 0 | C19: =SUM(C16:C18) -> 0 | D19: =SUM(D16:D18) -> 0 | E19: =SUM(E16:E18) -> 0 | F19: =SUM(F16:F18) -> 0 | G19: =SUM(G16:G18) -> 0 | H19: =SUM(H16:H18) -> 0 | I19: =SUM(I16:I18) -> 0 | ... Q19: =SUM(Q16:Q18) -> 0
A20: 2、合同资产期末数
A21: 项目 | B21: 审定数 | C21: 抵消数 | D21: 汇总 | E21: 母公司审定 | F21: 子公司1 | G21: 子公司2 | H21: 子公司3 | I21: 子公司4 | J21: 子公司5 | K21: 子公司6 | L21: 子公司7 | M21: 子公司8 | N21: 子公司9 | O21: 子公司10 | P21: 子公司11 | Q21: 子公司12
A22: 一、合同资产原值
A23: 类别A | B23: =D23-C23 -> 0 | D23: =SUM(E23:Q23) -> 0 | E23: 0
A24: 类别B | B24: =D24-C24 -> 0 | D24: =SUM(E24:Q24) -> 0 | E24: 0
A25: 类别C | B25: =D25-C25 -> 0 | D25: =SUM(E25:Q25) -> 0 | E25: 0
A26: 小计 | B26: =SUM(B23:B25) -> 0 | C26: =SUM(C23:C25) -> 0 | D26: =SUM(D23:D25) -> 0 | E26: =SUM(E23:E25) -> 0 | F26: =SUM(F23:F25) -> 0 | G26: =SUM(G23:G25) -> 0 | H26: =SUM(H23:H25) -> 0 | I26: =SUM(I23:I25) -> 0 | ... Q26: =SUM(Q23:Q25) -> 0
A27: 二、合同资产坏账准备
A28: 类别A | B28: =D28-C28 -> 0 | C28: =C160 -> 0 | D28: =SUM(E28:Q28) -> 0 | E28: =E160 -> 0 | F28: =F160 -> 0 | G28: =G160 -> 0 | H28: =H160 -> 0 | I28: =I160 -> 0 | J28: =J160 -> 0 | K28: =K160 -> 0 | L28: =L160 -> 0 | ... Q28: =Q160 -> 0
A29: 类别B | B29: =D29-C29 -> 0 | C29: =C167 -> 0 | D29: =SUM(E29:Q29) -> 0 | E29: =E167 -> 0 | F29: =F167 -> 0 | G29: =G167 -> 0 | H29: =H167 -> 0 | I29: =I167 -> 0 | J29: =J167 -> 0 | K29: =K167 -> 0 | L29: =L167 -> 0 | ... Q29: =Q167 -> 0
A30: 类别C | B30: =D30-C30 -> 0 | C30: =C174 -> 0 | D30: =SUM(E30:Q30) -> 0 | E30: =E174 -> 0 | F30: =F174 -> 0 | G30: =G174 -> 0 | H30: =H174 -> 0 | I30: =I174 -> 0 | J30: =J174 -> 0 | K30: =K174 -> 0 | L30: =L174 -> 0 | ... Q30: =Q174 -> 0
A31: 小计 | B31: =SUM(B28:B30) -> 0 | C31: =SUM(C28:C30) -> 0 | D31: =SUM(D28:D30) -> 0 | E31: =SUM(E28:E30) -> 0 | F31: =SUM(F28:F30) -> 0 | G31: =SUM(G28:G30) -> 0 | H31: =SUM(H28:H30) -> 0 | I31: =SUM(I28:I30) -> 0 | ... Q31: =SUM(Q28:Q30) -> 0
A32: 三、合同资产净值
A33: 类别A | B33: =D33-C33 -> 0 | C33: =C23-C28 -> 0 | D33: =SUM(E33:Q33) -> 0 | E33: =E23-E28 -> 0 | F33: =F23-F28 -> 0 | G33: =G23-G28 -> 0 | H33: =H23-H28 -> 0 | I33: =I23-I28 -> 0 | J33: =J23-J28 -> 0 | K33: =K23-K28 -> 0 | L33: =L23-L28 -> 0 | ... Q33: =Q23-Q28 -> 0
A34: 类别B | B34: =D34-C34 -> 0 | C34: =C24-C29 -> 0 | D34: =SUM(E34:Q34) -> 0 | E34: =E24-E29 -> 0 | F34: =F24-F29 -> 0 | G34: =G24-G29 -> 0 | H34: =H24-H29 -> 0 | I34: =I24-I29 -> 0 | J34: =J24-J29 -> 0 | K34: =K24-K29 -> 0 | L34: =L24-L29 -> 0 | ... Q34: =Q24-Q29 -> 0
A35: 类别C | B35: =D35-C35 -> 0 | C35: =C25-C30 -> 0 | D35: =SUM(E35:Q35) -> 0 | E35: =E25-E30 -> 0 | F35: =F25-F30 -> 0 | G35: =G25-G30 -> 0 | H35: =H25-H30 -> 0 | I35: =I25-I30 -> 0 | J35: =J25-J30 -> 0 | K35: =K25-K30 -> 0 | L35: =L25-L30 -> 0 | ... Q35: =Q25-Q30 -> 0
A36: 合计 | B36: =SUM(B33:B35) -> 0 | C36: =SUM(C33:C35) -> 0 | D36: =SUM(D33:D35) -> 0 | E36: =SUM(E33:E35) -> 0 | F36: =SUM(F33:F35) -> 0 | G36: =SUM(G33:G35) -> 0 | H36: =SUM(H33:H35) -> 0 | I36: =SUM(I33:I35) -> 0 | ... Q36: =SUM(Q33:Q35) -> 0
A37: 坏账准备情况
A38: 1、坏账准备期初数
A39: 一、类别A | B39: 审定数 | C39: 抵消数 | D39: 汇总 | E39: 母公司审定 | F39: 子公司1 | G39: 子公司2 | H39: 子公司3 | I39: 子公司4 | J39: 子公司5 | K39: 子公司6 | L39: 子公司7 | M39: 子公司8 | N39: 子公司9 | O39: 子公司10 | P39: 子公司11 | Q39: 子公司12
A40: 未逾期 | B40: =D40-C40 -> 0 | D40: =SUM(E40:Q40) -> 0 | E40: 0
...

Sheet 持有待售资产
A1: 持有待售资产附注汇总 | D1: 返回Excel目录 | E1: 返回word附注
A2: 项目 | B2: 审定数 | C2: 抵消数 | D2: 汇总 | E2: 母公司审定 | F2: 子公司1 | G2: 子公司2 | H2: 子公司3 | I2: 子公司4 | J2: 子公司5 | K2: 子公司6 | L2: 子公司7 | M2: 子公司8 | N2: 子公司9 | O2: 子公司10 | P2: 子公司11 | Q2: 子公司12
A3: 持有待售资产：
A4: 持有待售非流动资产 | B4: =D4-C4 -> 0 | D4: =SUM(E4:Q4) -> 0 | E4: 0
A5: 持有待售的处置组中的资产 | B5: =B6+B7 -> 0 | C5: =C6+C7 -> 0 | D5: =SUM(E5:Q5) -> 0 | E5: =E6+E7 -> 0 | F5: =F6+F7 -> 0 | G5: =G6+G7 -> 0 | H5: =H6+H7 -> 0 | I5: =I6+I7 -> 0 | J5: =J6+J7 -> 0 | K5: =K6+K7 -> 0 | L5: =L6+L7 -> 0 | ... Q5: =Q6+Q7 -> 0
A6: 其中：子公司A | B6: =D6-C6 -> 0 | D6: =SUM(E6:Q6) -> 0 | E6: 0
A7: 子公司B | B7: =D7-C7 -> 0 | D7: =SUM(E7:Q7) -> 0 | E7: 0
A8: 合 计 | B8: =B4+B5 -> 0 | C8: =C4+C5 -> 0 | D8: =D4+D5 -> 0 | E8: =E4+E5 -> 0 | F8: =F4+F5 -> 0 | G8: =G4+G5 -> 0 | H8: =H4+H5 -> 0 | I8: =I4+I5 -> 0 | ... Q8: =Q4+Q5 -> 0
A9: 试算表链接： | B9: 0 | D9: =SUM(E9:Q9) -> 0 | E9: 0
A10: 差异 | B10: =B8-B9 -> 0 | C10: =C8-C9 -> 0 | D10: =D8-D9 -> 0 | E10: =E8-E9 -> 0 | F10: =F8-F9 -> 0 | G10: =G8-G9 -> 0 | H10: =H8-H9 -> 0 | I10: =I8-I9 -> 0 | ... Q10: =Q8-Q9 -> 0
A12: 项目 | B12: 审定数 | C12: 抵消数 | D12: 汇总 | E12: 母公司审定 | F12: 子公司1 | G12: 子公司2 | H12: 子公司3 | I12: 子公司4 | J12: 子公司5 | K12: 子公司6 | L12: 子公司7 | M12: 子公司8 | N12: 子公司9 | O12: 子公司10 | P12: 子公司11 | Q12: 子公司12
A13: 持有待售负债：
A14: 持有待售的处置组中的负债 | B14: =B15+B16 -> 0 | C14: =C15+C16 -> 0 | D14: =SUM(E14:Q14) -> 0 | E14: =E15+E16 -> 0 | F14: =F15+F16 -> 0 | G14: =G15+G16 -> 0 | H14: =H15+H16 -> 0 | I14: =I15+I16 -> 0 | J14: =J15+J16 -> 0 | K14: =K15+K16 -> 0 | L14: =L15+L16 -> 0 | ... Q14: =Q15+Q16 -> 0
A15: 其中：子公司A | B15: =D15-C15 -> 0 | D15: =SUM(E15:Q15) -> 0 | E15: 0
A16: 子公司B | B16: =D16-C16 -> 0 | D16: =SUM(E16:Q16) -> 0 | E16: 0
A17: 合 计 | B17: =B14 -> 0 | C17: =C14 -> 0 | D17: =D14 -> 0 | E17: =E14 -> 0 | F17: =F14 -> 0 | G17: =G14 -> 0 | H17: =H14 -> 0 | I17: =I14 -> 0 | ... Q17: =Q14 -> 0
A18: 试算表链接： | B18: 0 | D18: =SUM(E18:Q18) -> 0 | E18: 0
A19: 差异 | B19: =B17-B18 -> 0 | C19: =C17-C18 -> 0 | D19: =D17-D18 -> 0 | E19: =E17-E18 -> 0 | F19: =F17-F18 -> 0 | G19: =G17-G18 -> 0 | H19: =H17-H18 -> 0 | I19: =I17-I18 -> 0 | ... Q19: =Q17-Q18 -> 0
A21: 说明：（应当说明持有待售的非流动资产及持有待售的处置组中的资产产生的原因、内容及性质）
A22: （1）持有待售的非流动资产
A23: 期末，持有待售的资产的情况：
A24: 项 目 | B24: 账面价值 | C24: 公允价值 | D24: 预计处置费用 | E24: 预计处置时间
A29: 合 计 | B29: =SUM(B25:B28) -> 0 | C29: =SUM(C25:C28) -> 0 | D29: =SUM(D25:D28) -> 0
A30: （2）持有待售的处置组
A31: ①子公司A
A32: 项 目 | B32: 账面价值 | C32: 公允价值 | D32: 预计处置费用 | E32: 预计处置时间
A33: 持有待售的处置组中的资产
A34: 货币资金
A36: 固定资产
A37: ……
A39: 持有待售的处置组中的负债
A40: 应付账款
A41: 长期应付款
A42: ……
A43: ②子公司B
A44: 项 目 | B44: 账面价值 | C44: 公允价值 | D44: 预计处置费用 | E44: 预计处置时间
A45: 持有待售的处置组中的资产
A46: 货币资金
A48: 固定资产
A49: ……
...

Sheet 一年内到期的非流动资产
A1: 一年内到期的非流动资产附注汇总 | D1: 返回Excel目录 | E1: 返回word附注
A2: 项目 | B2: 审定数 | C2: 抵消数 | D2: 汇总 | E2: 母公司审定 | F2: 子公司1 | G2: 子公司2 | H2: 子公司3 | I2: 子公司4 | J2: 子公司5 | K2: 子公司6 | L2: 子公司7 | M2: 子公司8 | N2: 子公司9 | O2: 子公司10 | P2: 子公司11 | Q2: 子公司12
A3: 1年内到期的长期应收款 | B3: =D3-C3 -> 0 | D3: =SUM(E3:Q3) -> 0 | E3: 0
A4: 1年内到期的持有至到期投资 | B4: =D4-C4 -> 0 | D4: =SUM(E4:Q4) -> 0 | E4: 0
A5: 1年内到期的长期待摊费用 | B5: =D5-C5 -> 0 | D5: =SUM(E5:Q5) -> 0 | E5: 0
A6: 其他 | B6: =D6-C6 -> 0 | D6: =SUM(E6:Q6) -> 0 | E6: 0
A7: 合 计 | B7: =SUM(B3:B6) -> 0 | C7: =SUM(C3:C6) -> 0 | D7: =SUM(D3:D6) -> 0 | E7: =SUM(E3:E6) -> 0 | F7: =SUM(F3:F6) -> 0 | G7: =SUM(G3:G6) -> 0 | H7: =SUM(H3:H6) -> 0 | I7: =SUM(I3:I6) -> 0 | ... Q7: =SUM(Q3:Q6) -> 0
A8: 试算表链接： | B8: 0 | D8: =SUM(E8:Q8) -> 0 | E8: 0
A9: 差异 | B9: =B7-B8 -> 0 | D9: =D7-D8 -> 0 | E9: =E7-E8 -> 0 | F9: =F7-F8 -> 0 | G9: =G7-G8 -> 0 | H9: =H7-H8 -> 0 | I9: =I7-I8 -> 0 | J9: =J7-J8 -> 0 | K9: =K7-K8 -> 0 | ... Q9: =Q7-Q8 -> 0
A11: 说明：（对于大额的一年内到期的非流动资产说明形成的原因、内容、性质。）

Sheet 其他流动资产
A1: 其他流动资产附注 | D1: 返回Excel目录 | E1: 返回word附注
A2: 项目 | B2: 审定数 | C2: 抵消数 | D2: 汇总 | E2: 母公司审定 | F2: 子公司1 | G2: 子公司2 | H2: 子公司3 | I2: 子公司4 | J2: 子公司5 | K2: 子公司6 | L2: 子公司7 | M2: 子公司8 | N2: 子公司9 | O2: 子公司10 | P2: 子公司11 | Q2: 子公司12
A3: 待抵扣进项税 | B3: =D3-C3 -> 0 | D3: =SUM(E3:Q3) -> 0 | E3: 0
A4: 预缴所得税 | B4: =D4-C4 -> 0 | D4: =SUM(E4:Q4) -> 0 | E4: 0
A5: 委托贷款 | B5: =D5-C5 -> 0 | D5: =SUM(E5:Q5) -> 0 | E5: 0
A6: 预缴其他税费 | B6: =D6-C6 -> 0 | D6: =SUM(E6:Q6) -> 0 | E6: 0
B7: =D7-C7 -> 0 | D7: =SUM(E7:Q7) -> 0 | E7: 0
B8: =D8-C8 -> 0 | D8: =SUM(E8:Q8) -> 0 | E8: 0
A9: 合计 | B9: =SUM(B3:B8) -> 0 | C9: =SUM(C3:C8) -> 0 | D9: =SUM(D3:D8) -> 0 | E9: =SUM(E3:E8) -> 0 | F9: =SUM(F3:F8) -> 0 | G9: =SUM(G3:G8) -> 0 | H9: =SUM(H3:H8) -> 0 | I9: =SUM(I3:I8) -> 0 | ... Q9: =SUM(Q3:Q8) -> 0
A10: 试算表链接： | B10: 0 | D10: =SUM(E10:Q10) -> 0 | E10: 0
A11: 差异 | B11: =B9-B10 -> 0 | D11: =D9-D10 -> 0 | E11: =E9-E10 -> 0 | F11: =F9-F10 -> 0 | G11: =G9-G10 -> 0 | H11: =H9-H10 -> 0 | I11: =I9-I10 -> 0 | J11: =J9-J10 -> 0 | K11: =K9-K10 -> 0 | ... Q11: =Q9-Q10 -> 0
A12: （金额较大的其他流动资产，应说明其内容、性质）

Sheet 债权投资
A1: 债权投资附注 | D1: 返回Excel目录 | E1: 返回word附注
A2: （1）债权投资情况
A3: 项目 | B3: 审定数 | C3: 抵消数 | D3: 汇总 | E3: 母公司审定 | F3: 子公司1 | G3: 子公司2 | H3: 子公司3 | I3: 子公司4 | J3: 子公司5 | K3: 子公司6 | L3: 子公司7 | M3: 子公司8 | N3: 子公司9 | O3: 子公司10 | P3: 子公司11 | Q3: 子公司12
A4: 项目A | B4: =D4-C4 -> 0 | D4: =SUM(E4:Q4) -> 0 | E4: 0
A5: 项目B | B5: =D5-C5 -> 0 | D5: =SUM(E5:Q5) -> 0 | E5: 0
A6: 项目C | B6: =D6-C6 -> 0 | D6: =SUM(E6:Q6) -> 0 | E6: 0
A7: …… | B7: =D7-C7 -> 0 | D7: =SUM(E7:Q7) -> 0 | E7: 0
A8: 合计 | B8: =SUM(B4:B7) -> 0 | C8: =SUM(C4:C7) -> 0 | D8: =SUM(D4:D7) -> 0 | E8: =SUM(E4:E7) -> 0 | F8: =SUM(F4:F7) -> 0 | G8: =SUM(G4:G7) -> 0 | H8: =SUM(H4:H7) -> 0 | I8: =SUM(I4:I7) -> 0 | ... Q8: =SUM(Q4:Q7) -> 0
A9: 减值准备
A10: 项目 | B10: 审定数 | C10: 抵消数 | D10: 汇总 | E10: 母公司审定 | F10: 子公司1 | G10: 子公司2 | H10: 子公司3 | I10: 子公司4 | J10: 子公司5 | K10: 子公司6 | L10: 子公司7 | M10: 子公司8 | N10: 子公司9 | O10: 子公司10 | P10: 子公司11 | Q10: 子公司12
A11: 项目A | B11: =D11-C11 -> 0 | D11: =SUM(E11:Q11) -> 0 | E11: 0
A12: 项目B | B12: =D12-C12 -> 0 | D12: =SUM(E12:Q12) -> 0 | E12: 0
A13: 项目C | B13: =D13-C13 -> 0 | D13: =SUM(E13:Q13) -> 0 | E13: 0
A14: …… | B14: =D14-C14 -> 0 | D14: =SUM(E14:Q14) -> 0 | E14: 0
A15: 合计 | B15: =SUM(B11:B14) -> 0 | C15: =SUM(C11:C14) -> 0 | D15: =SUM(D11:D14) -> 0 | E15: =SUM(E11:E14) -> 0 | F15: =SUM(F11:F14) -> 0 | G15: =SUM(G11:G14) -> 0 | H15: =SUM(H11:H14) -> 0 | I15: =SUM(I11:I14) -> 0 | ... Q15: =SUM(Q11:Q14) -> 0
A16: 账面价值
A17: 项目 | B17: 审定数 | C17: 抵消数 | D17: 汇总 | E17: 母公司审定 | F17: 子公司1 | G17: 子公司2 | H17: 子公司3 | I17: 子公司4 | J17: 子公司5 | K17: 子公司6 | L17: 子公司7 | M17: 子公司8 | N17: 子公司9 | O17: 子公司10 | P17: 子公司11 | Q17: 子公司12
A18: 项目A | B18: =D18-C18 -> 0 | C18: =C4-C11 -> 0 | D18: =SUM(E18:Q18) -> 0 | E18: =E4-E11 -> 0 | F18: =F4-F11 -> 0 | G18: =G4-G11 -> 0 | H18: =H4-H11 -> 0 | I18: =I4-I11 -> 0 | J18: =J4-J11 -> 0 | K18: =K4-K11 -> 0 | L18: =L4-L11 -> 0 | ... Q18: =Q4-Q11 -> 0
A19: 项目B | B19: =D19-C19 -> 0 | C19: =C5-C12 -> 0 | D19: =SUM(E19:Q19) -> 0 | E19: =E5-E12 -> 0 | F19: =F5-F12 -> 0 | G19: =G5-G12 -> 0 | H19: =H5-H12 -> 0 | I19: =I5-I12 -> 0 | J19: =J5-J12 -> 0 | K19: =K5-K12 -> 0 | L19: =L5-L12 -> 0 | ... Q19: =Q5-Q12 -> 0
A20: 项目C | B20: =D20-C20 -> 0 | C20: =C6-C13 -> 0 | D20: =SUM(E20:Q20) -> 0 | E20: =E6-E13 -> 0 | F20: =F6-F13 -> 0 | G20: =G6-G13 -> 0 | H20: =H6-H13 -> 0 | I20: =I6-I13 -> 0 | J20: =J6-J13 -> 0 | K20: =K6-K13 -> 0 | L20: =L6-L13 -> 0 | ... Q20: =Q6-Q13 -> 0
A21: …… | B21: =D21-C21 -> 0 | C21: =C7-C14 -> 0 | D21: =SUM(E21:Q21) -> 0 | E21: =E7-E14 -> 0 | F21: =F7-F14 -> 0 | G21: =G7-G14 -> 0 | H21: =H7-H14 -> 0 | I21: =I7-I14 -> 0 | J21: =J7-J14 -> 0 | K21: =K7-K14 -> 0 | L21: =L7-L14 -> 0 | ... Q21: =Q7-Q14 -> 0
