Workbook
Name OLE_LINK1: '表头（请先填写）'!#REF!

Sheet 表头（请先填写）
A1: 底稿开列时，可先在以下单元格填写有关内容，以便其他底稿引用有关数据：
A2: 客户名称：
A3: 会计期间： | D3: 序号 | E3: 内容 | F3: 性质
A4: 编制人： | D4: 1 | E4: 现金流量审计程序A5-1 | F4: 程序表
A5: 日期： | D5: 2 | E5: 列示于现金流量表的现金及现金等价物A5-1-1 | F5: 审定表
D6: 3 | E6: 相关报表勾稽关系核对A5-1-3 | F6: 检查表
D7: 4 | E7: 现金流量核查A5-1-4 | F7: 检查表
D8: 5 | E8: 现金流量核查A5-1-5 | F8: 检查表
A9: 关于工作底稿索引号的编制方法的说明 | D9: 6 | E9: 其他现金流量A5-1-6 | F9: 检查表
A10: 1、 工作底稿的分类
A12: 作为具体审计程序的支持性工作底稿，共有三类，分别为审定表，明细表，检查表。
A13: 2、 工作底稿与审计程序的对应与索引
A14: 为提高工作底稿编制的针对性，各项目负责人提供的所有支持性工作底稿，均应当
A15: 按自然顺序依次编制索引号，并通过唯一的索引号将审计程序表中的特定程序与相关
A16: 支持性工作底稿进行一一对应。
A17: 3、 工作底稿索引号的编码规则（以销售循环为例，假设D为项目名称代码）
A18: 索引号的说明：实质性程序索引号从“D”到“N”,循环内账户以顺序号排列，如：销售循环的程序表即为D，D1为应收票据审定表，D1-1为附注披露信息，D1-2为明细表........

Sheet A5-1现金流量审计程序
A1: 致同会计师事务所
A2: 现金流量具体审计计划
A3: ='表头（请先填写）'!A2 -> 客户名称： | C3: ='表头（请先填写）'!A4 -> 编制人： | D3: ='表头（请先填写）'!A5 -> 日期： | G3: 索引号：A5-1
A4: ='表头（请先填写）'!A3 -> 会计期间： | C4: 复核人： | D4: 日期： | G4: 页次：
A5: 一、审计目标
A6: 1、现金流量表的内容、性质和数额是否正确、合理、完整
A7: 2、现金流量有关项目数额与其他报表及附注的勾稽关系是否正确
A8: 3、现金流量表各项目的披露是否恰当
A9: 二、审计程序：
A10: 序号 | B10: 审计程序 | E10: 是否适用 | F10: 执行人 | G10: 执行情况说明 | H10: 索引号
A11: 1 | B11: 获取编制现金流量表的基础资料：
A12: 1.1 | B12: 复核加计是否正确
A13: 1.2 | B13: 将基础资料中的有关数据和会计报表及附注、帐册凭证、辅助帐簿、审计工作底稿等核对相符，并进行详细分析，检查数额是否正确、完整、现金流量是否合理
A14: 1.3 | B14: 根据审计调整分录，对基础资料的有关数额作相应调整
A15: 2 | B15: 审查对现金及现金等价物的界定是否符合规定，界定范围在前后会计期间是否保持一致
A16: 3 | B16: 审查现金流量表编制方法：
A17: 3.1 | B17: 了解现金流量表编制方法。如果被审计单位未利用计算机程序编制现金流量表，应查明其是否专门为编制现金流量表设置辅助帐簿记录，并取得现金流量表编制底稿；如果被审计单位利用计算机程序编制现金流量表，应对其计算机程序进行了解分析，必要时可聘请专家协助工作。
A18: 3.2 | B18: 检查合并现金流量表编制方法，关注集团内部往来及购销业务是否已作抵销。对本期存在收购子公司或部门以及出售子公司或部门情况的，检查是否已作正确处理
A19: 3.3 | B19: 关注现金流量表编制过程中，对有关特殊事项的处理是否正确，如：以非货币资产对外投资；收购其他公司时，权益性投资所支付的现金是否已扣除被收购公司被收购日的现金；已净资产或非货币性资产认缴股本；债务重组；非货币性交易；新设改制公司年度及股份公司上市年度现金流量表的特殊处理；金融保险等特殊行业现金流量表的编制。
A20: 4 | B20: 对现金流量表进行分析性复核，并检查：
A21: 4.1 | B21: 主表与附注之“现金及现金等价物净增加额”是否一致
A22: 4.2 | B22: 主表与附注之“经营活动产生的现金流量净额”的勾稽是否合理
... A25: 4.5 | B25: 是否存在金额异常的现金流量表项目，并做追查调整。如：
A26: 4.5.1 | B26: 若以净额为基础分析经营性其他应收款、其他应付款时，其本期增减变动金额是否已正确列入“收到的其他与经营活动有关的现金”或“支付的其他与经营活动有关的现金”
A27: 4.5.2 | B27: 是否出现金额异常的项目，如“支付的其他与经营活动有关的现金”金额大大低于本期管理费用和营业费用的合计数
A28: 4.5.3 | B28: 是否存在未发生某项现金流量，而现金流量表对应项目却有发生额的情形，或发生了某项现金流量，而现金流量表对应项目却无发生额的情形
A29: 4.5.4 | B29: 比较个别现金流量表和合并现金流量表相同项目金额，分析是否存在异常
A30: 5 | B30: 检查现金流量表附注中不涉及现金收支的投资和筹资活动各项目金额是否正确、合理、完整
A31: 6 | B31: 验明现金流量表各项目的披露是否恰当
A32: 审计程序批准:
A34: 经理： | E34: 日期：

Sheet A5-1-1列示于现金流量表的现金及现金等价物
A1: 致同会计师事务所
A2: 列示于现金流量表的现金及现金等价物
A3: ='表头（请先填写）'!A2 -> 客户名称： | D3: ='表头（请先填写）'!A4 -> 编制人： | F3: ='表头（请先填写）'!A5 -> 日期： | H3: 索引号：A5-1-1
A4: ='表头（请先填写）'!A3 -> 会计期间： | D4: 复核人： | F4: 日期： | H4: 页次：
A5: 列示于现金流量表的现金及现金等价物包括：
A6: 项目 | D6: 未审金额 | E6: 审计调整 | F6: 调整说明 | G6: 审定数 | H6: 备注
A7: 2009年12月31日货币资金 | G7: =D7+E7 -> 0
A8: 减：使用受到限制的存款 | G8: =D8+E8 -> 0
A9: …… | G9: =D9+E9 -> 0
A10: 加：持有期限不超过三个月的国债投资 | G10: =D10+E10 -> 0
A11: …… | G11: =D11+E11 -> 0
A12: 2009年12月31日现金及现金等价物余额 | D12: =D7-D8-D9+D10+D11 -> 0 | E12: =E7-E8-E9+E10+E11 -> 0 | G12: =G7-G8-G9+G10+G11 -> 0
A13: 减：2008年12月31日现金及现金等价物余额 | G13: =D13+E13 -> 0
A14: 现金及现金等价物净增加/(减少)额 | D14: =D12-D13 -> 0 | E14: =E12-E13 -> 0 | G14: =G12-G13 -> 0
A15: 审计说明：
A24: 编制说明：
A25: 1、现金，是指企业库存现金以及可以随时用于支付的存款。
A26: 2、现金等价物，是指企业持有的期限短、流动性强、易于转换为已知金额现金、价值变动风险很小的投资。
A27: 3、信用证保证金存款和银行承兑汇票保证金存款，在资产负债表日后3个月内可以用于支付的，在编制现金流量表时不从“现金”中扣除。
A28: 反之，在资产负债表日后3个月内不可以用于支付的，在编制现金流量表时应从“现金”中扣除。
A29: 4、不能随时支取的定期存款等不应作为现金；提前通知金融机构便可支取的定期存款则应包括在现金范围内。
A30: 5、权益性投资变现的金额通常不确定，因而不属于现金等价物。
A31: 6、企业应当根据具体情况，确定现金及现金等价物的范围，一经确定不得随意变更。如果发生变更，应当按照会计政策变更处理。

Sheet A5-1-3相关报表勾稽关系核对
A1: 致同会计师事务所
A2: 现金流量表相关报表勾稽关系核对
A3: ='表头（请先填写）'!A2 -> 客户名称： | B3: ='表头（请先填写）'!A4 -> 编制人： | C3: ='表头（请先填写）'!A5 -> 日期： | D3: 索引号：A5-1-3
A4: ='表头（请先填写）'!A3 -> 会计期间： | B4: 复核人： | C4: 日期： | D4: 页次：
A6: 1、销售商品、提供劳务收到的现金
A7: 项目 | B7: 金额 | C7: 备注 | D7: 索引号
A8: 1、主营业务收入总额
A9: 2、其他业务收入总额
A10: 3、应收账款净减少额
A11: 4、预收款项、合同负债净增加额
A12: 5、增值税销项税额影响
A13: 6、……
A14: 7、
A15: 8、
A16: 9、
A17: 10、其他
A18: 合计 | B18: =SUM(B8:B17) -> 0
A19: 报表数
A20: 差异 | B20: =B18-B19 -> 0
A22: 2、购买商品、接受劳务支付的现金
A23: 项目 | B23: 金额 | C23: 备注 | D23: 索引号
A24: 1、原材料采购金额
A25: 2、应付账款本期减少数
A26: 3、应付票据本期减少数
A27: 4、预付款项本期增加数
A28: 5、
A29: 6、
A30: 7、
A31: 8、
A32: 9、
A33: 10、其他
A34: 合计 | B34: =SUM(B24:B33) -> 0
A35: 报表数
A36: 差异 | B36: =B34-B35 -> 0
A38: 3、支付给职工以及为职工支付的现金
A39: 项目 | B39: 金额 | C39: 备注 | D39: 索引号
A40: 1、应付职工薪酬本期减少数
A41: 2、……
A42: 3、其他
A43: 合计 | B43: =SUM(B40:B42) -> 0
...

Sheet A5-1-4现金流量核查
A1: 致同会计师事务所
A2: 现金流量表-补充资料的核查记录
A4: ='表头（请先填写）'!A2 -> 客户名称： | E4: ='表头（请先填写）'!A4 -> 编制人： | G4: ='表头（请先填写）'!A5 -> 日期： | L4: 索引： | M4: A5-1-4
A5: ='表头（请先填写）'!A3 -> 会计期间： | E5: 复核人： | G5: 日期： | L5: 页次：
A7: （二）当期取得或处置子公司及其他营业单位的有关信息
A8: 项目 | B8: 行次 | C8: 差异(按报表账户) | D8: 原报数 | E8: 测算数 | F8: 有关测算依据
C9: 1=3-3 | D9: 2 | E9: 3 | F9: 4
A10: 一、取得子公司及其他营业单位的有关信息：
A11: 1．取得子公司及其他营业单位的价格
A12: 2．取得子公司及其他营业单位支付的现金和现金等价物
A13: 减：子公司及其他营业单位持有的现金和现金等价物
A14: 3．取得子公司及其他营业单位支付的现金净额
A15: 4．取得子公司的净资产
A16: 流动资产
A17: 非流动资产
A18: 流动负债
A19: 非流动负债
A20: 二、处置子公司及其他营业单位的有关信息：
A21: 1．处置子公司及其他营业单位的价格
... A29: 非流动负债

Sheet A5-1-5现金流量核查
A1: 致同会计师事务所
A2: 现金流量表-补充资料的核查记录
A4: 客户名称： | D4: 编制人: | G4: 日期: | L4: 索引： | M4: A5-1-5
A5: 会计期间： | D5: 复核人: | G5: 日期: | L5: 页次：
A7: （三）现金和现金等价物
A8: 项目 | B8: 行次 | C8: 差异(按报表账户) | D8: 原报数 | E8: 测算数 | F8: 有关测算依据
C9: 1=3-2 | D9: 2 | E9: 3 | F9: 4
A10: 一、现金 | C10: =E10-D10 -> 0
A11: 其中：库存现金 | C11: =E11-D11 -> 0
A12: 可随时用于支付的银行存款 | C12: =E12-D12 -> 0
A13: 可随时用于支付的其他货币资金 | C13: =E13-D13 -> 0
A14: 可用于支付的存放中央银行款项 | C14: =E14-D14 -> 0
A15: 存放同业款项 | C15: =E15-D15 -> 0
A16: 拆放同业款项 | C16: =E16-D16 -> 0
A17: 二、现金等价物 | C17: =E17-D17 -> 0
A18: 其中：三个月内到期的债券投资 | C18: =E18-D18 -> 0
A19: 三、期末现金及现金等价物余额 | C19: =E19-D19 -> 0
A20: 其中：母公司或集团内子公司使用受限制的现金和现金等价物 | C20: =E20-D20 -> 0
A22: 注释：持有待售资产和负债的资产组中的货币资金，在编制现金流量表时应作为现金及现金等价物。

Sheet A5-1-6其他现金流量
A1: 致同会计师事务所
A2: 其他现金流量
A3: ='表头（请先填写）'!A2 -> 客户名称： | B3: ='表头（请先填写）'!A4 -> 编制人： | C3: ='表头（请先填写）'!A5 -> 日期： | D3: 索引号：A5-1-6
A4: ='表头（请先填写）'!A3 -> 会计期间： | B4: 复核人： | C4: 日期： | D4: 页次：
A6: 现金流量中其他现金资料
A7: 1、收到的其他与经营活动有关的现金 | C7: 2、支付的其他与经营活动有关的现金
A8: 项目 | B8: 金额 | C8: 项目 | D8: 金额
A9: 1、收到单位及个人往来 | C9: 1、办公费、差旅费、业务招待费等费用开支
A10: 2、收到的住房按揭保证金 | C10: 2、职工借支款及备用金
A11: 3、收到的投标保证金、履约保证金 | C11: 3、支付的往来款
A12: 4、收到的质保金和尾工款 | C12: 4、支付的履约保证金、投标保证金
A13: 5、代收代付款 | C13: 5、代收代付款
A14: 6、代垫费用、备用金 | C14: 6、手续费
A15: 7、收到的利息收入 | C15: 7、支付各子公司调剂款
A16: 8、罚没、赔款等收入 | C16: 8、支付不符合现金及现金等价物定义的银行承兑汇票保证金
A17: 9、 | C17: 9、
A18: 10、其他 | C18: 10、其他
A19: 收到的其他与经营活动有关的现金合计 | B19: =SUM(B9:B18) -> 0 | C19: 支付的其他与经营活动有关的现金合计 | D19: =SUM(D9:D18) -> 0
A21: 3、收到的其他与投资活动有关的现金 | C21: 4、支付的其他与投资活动有关的现金
A22: 项目 | B22: 金额 | C22: 项目 | D22: 金额
A23: 1、收到的投资款 | C23: 1、支付的投资款
A24: 2、收到定期存款利息 | C24: 2、不再纳入合并范围公司期初货币资金
A25: 3、增加合并范围子公司期初货币资金 | C25: 3、
A26: 4、政府补助 | C26: 4、
A27: 5、 | C27: 5、
A28: 6、 | C28: 6、
A29: 7、 | C29: 7、
A30: 8、 | C30: 8、
A31: 9、 | C31: 9、
A32: 10、其他 | C32: 10、其他
A33: 收到的其他与投资活动有关的现金合计 | B33: =SUM(B23:B32) -> 0 | C33: 支付的其他与投资活动有关的现金合计 | D33: =SUM(D23:D32) -> 0
A35: 5、收到的其他与筹资活动有关的现金 | C35: 6、支付的其他与筹资活动有关的现金
A36: 项目 | B36: 金额 | C36: 项目 | D36: 金额
A37: 1、票据贴现 | C37: 1、票据融资
A38: 2、收回银行承兑汇票保证金 | C38: 2、支付银行承兑汇票保证金
A39: 3、暂借款 | C39: 3、归还其他企业暂借款
A40: 4、募集资金利息收入 | C40: 4、上市中介费用
A41: 5、 | C41: 5、财务顾问费
A42: 6、 | C42: 6、
A43: 7、 | C43: 7、
...

Sheet 会计提示
B1: 关于现金流量表的列报
B2: （一）实务问题
B3: 1、如何确定现金及现金等价物的包括范围，如因随时不可以支取的存款，应否包括？
B4: 2、增加或收回受限存款及有关利息收入时，如何在现金流量表的列报？
B6: （二）我们的理解
B7: 1、现金及现金等价物的范围
B8: 根据现金等价物的四个条件（①期限短；②流动性强；③易于转换为已知金额的现金；④价值变动风险很小），
B9: 以下存款可作为现金流量表的现金列示：
B10: （1）提前通知便可支取的定期存款；（2）自由支取的集团财务公司存款；（3）合同期限小于3个月的银行理财产品等。
B11: 而质押、冻结的活期或定期存款，合同期限大于3月的定期存款、各类性质的保证金存款
B12: （包括票据、信用、保函保证金，投标、合同履约、工程质量保证金等），不可作为现金流量表的现金列示。
B13: 2、支付或收回受限存款及其利息收入的列报
... B16: 具体参考如下：
B17: 项目 | C17: 现金流量表列示
B18: （1）存款及利息收入
B19: 活期存款利息收入 | C19: 经营活动（收到其他）
B20: 活期存款转为定期存款 | C20: 投资支付的现金
B21: 受限定期存款利息收入 | C21: 投资活动（收到其他）
B22: 定期存款到期转为活期存款 | C22: 收回投资收到的现金
B23: 为取得借款而质押的定期存单 | C23: 筹资活动（支付其他）
B24: 质押的定期存单利息收入 | C24: 筹资活动（收到其他）
B25: 解除（收回）质押定期存单 | C25: 筹资活动（收到其他）
B26: （2）保证金
B27: 支付/收回的用于经营活动的票据、信用、保函保证金 | C27: 经营活动（支付/收到其他）
B28: 支付/收回的用于筹资活动的票据、信用保证金（如，与集团公司之间开具的、不具有商业实质的、用于贴现的银行承兑汇票保证金） | C28: 筹资活动（支付/收到其他）
B29: 支付/收回的用于投资活动的保函保证金 | C29: 投资活动（支付/收到其他）
B30: 上述保证金存款的利息收入 | C30: 经营/筹资/投资（收到其他）
B31: （3）政府补助
B32: 收到的与资产相关的政府补助 | C32: 投资活动（收到其他）
B33: （如，收到的国产设备退还增值税）
B34: 收到的与收益相关的政府补助 | C34: 经营活动（收到其他）
B35: （4）固定资产进项税
B36: 购买固定资产所支付的增值税进项税额 | C36: 投资活动-购建固定资产、无形资产和其他长期资产支付的现金

Sheet GT_Custom
A1: C1 | B1: Custom 1
A2: C2 | B2: Custom 2
A3: C3 | B3: Custom 3
A4: C4 | B4: Custom 4
A5: C5 | B5: Custom 5
A6: C6 | B6: Custom 6
A7: C7 | B7: Custom 7
A8: C8 | B8: Custom 8
