Workbook

Sheet 底稿目录
A1: 底稿开列时，可先在以下单元格填写有关内容，以便其他底稿引用有关数据：
A2: 被审计单位：
A3: 截止日：202X年12月31日 | D3: 序号 | E3: 内容 | F3: 索引号
A4: 编制人： | D4: 1 | E4: 预付账款实质性程序表 | F4: F1A
A5: 编制日期： | D5: 2 | E5: 预付账款审定表 | F5: F1-1
A6: 复核人： | D6: =D5+1 -> 3 | E6: 附注披露信息（上市公司） | G6: 无需打印
A7: 复核日期： | D7: =D6+1 -> 4 | E7: 附注披露信息（国企） | G7: 无需打印
D8: =D7+1 -> 5 | E8: 预付账款明细表 | F8: F1-2
A9: 关于工作底稿与审计程序索引号对应的说明 | D9: =D8+1 -> 6 | E9: 调整分录汇总 | F9: F1-3
A10: 1.编制的审计工作底稿应与审计程序对应。审计项目组应根据被审计单位实际情况和风险评估情况在实质性程序表中裁剪、修改或增加审计程序，根据实际执行的审计程序完成相应审计工作底稿，编制的工作底稿中应按自然顺序依次编制索引号，并通过唯一的索引号将与实质性程序表中的程序对应关联（即将工作底稿的索引号填入实质性程序表中的底稿索引号列）。 | D10: =D9+1 -> 7 | E10: 实质性分析 | F10: F1-4
D11: =D9+1 -> 7 | E11: 函证结果汇总表 | F11: F0-1
D12: =D11+1 -> 8 | E12: 核实被函证单位信息 | F12: F0-2
D13: =D12+1 -> 9 | E13: 跟函函证过程控制 | F13: F0-3
A14: 2.获取的支持性证据应与审计底稿或程序对应。审计项目组在完成底稿时获取的支持性证据应根据底稿索引号编制下一级按自然顺序排序的索引号（如D1-2-1、D1-2-2、……），并在底稿中说明引用的支持性证据、关联索引号。 | D14: =D13+1 -> 10 | E14: 函证差异调节表 | F14: F0-4
D15: =D14+1 -> 11 | E15: 预付及采购替代程序检查表 | F15: F0-5
D16: =D15+1 -> 12 | E16: 邮件传真回函可靠性验证 | F16: F0-7
A17: 3.工作底稿索引号的编码规则：实质性程序索引号按循环从“D”到“N”,循环内账户以顺序号排列，模板中底稿索引号按账户顺序+自然数顺序（即模板中索引号按二级自然顺序排列，如D1-1、D1-2、D1-3、……D1-N）。 | D17: =D16+1 -> 13 | E17: 函证程序舞弊风险评价表 | F17: F0-8
D18: =D10+1 -> 8 | E18: 长期挂账预付账款检查表 | F18: F1-5
D19: =D17+1 -> 14 | E19: 关联方及交易检查表 | F19: F1-6
D20: =D19+1 -> 15 | E20: 预付账款检查表 | F20: F1-7

Sheet 预付账款实质性程序表F1A
A1: 致同会计师事务所
A2: 预付账款实质性程序
A3: =底稿目录!A2 -> 被审计单位： | C3: =底稿目录!A4 -> 编制人： | E3: =底稿目录!A5 -> 编制日期： | H3: 索引号： | I3: =底稿目录!F4 -> F1A
A4: =底稿目录!A3 -> 截止日：202X年12月31日 | C4: =底稿目录!A6 -> 复核人： | E4: =底稿目录!A7 -> 复核日期： | H4: 页 次：
A5: 一、本账户涉及的科目
A6: 预付账款
A7: 二、审计目标与认定的对应关系
A8: 审计目标 | G8: 财务报表的认定
A9: A. 资产负债表中记录的预付账款是存在的，且已经记录在恰当的账户中 | G9: 存在
A10: B. 所有应记录的预付账款均已记录，所有应当包括在财务报表中的相关披露均已包括 | G10: 完整性
A11: C. 记录的预付账款由被审计单位拥有或控制 | G11: 权利和义务
A12: D. 预付账款以恰当的金额包括在财务报表中，与之相关的计价或分摊调整已恰当记录，相关披露已得到恰当计量和描述 | G12: 准确性、计价和分摊
A13: E. 预付账款已被恰当地汇总或分解且表述清楚，相关披露在按照企业会计准则的编制基础下是相关的、可理解的 | G13: 列报
A14: 三、计划实施的实质性程序
A15: 序号 | B15: 审计程序 | C15: 程序分类 | D15: 财务报表的认定 | I15: 底稿索引号
D16: 存在 | E16: 完整性 | F16: 权利和 义务 | G16: 准确性、计价和分摊 | H16: 列报 | J16: 根据被审计单位实际情况和风险评估情况裁剪、修改或增加审计程序
A17: 1 | B17: 获取或编制预付账款的明细表，完成以下工作，并编制审定表 （1）复核加计是否正确，与总账、明细账合计数核对是否相符，期初余额与上期审定期末余额是否相符； （2）获取管理层编制的预付账款账龄分析表，检查账龄划分是否正确； （3）结合应付账款等往来项目的明细余额，检查有无重复付款或将同一笔已付清的款项在预付账款和应付账款两个科目中同时挂账的情况、异常余额或与购货无关的其他款项； （4）检查贷方余额是否需要重分类、非记账本位币预付账款折算是否正确。 | C17: 常规★ | D17: √ | E17: √ | G17: √ | I17: F1-1 /F1-2
A18: 2 | B18: 在使用手工编制、自定义信息报告、系统生成的非固定格式报告等由被审计单位生成的信息时，测试有关信息准确性和完整性，并考虑针对编制和维护由被审计单位生成的信息的相关控制实施控制测试，以评价该信息是否能够为实现审计目的提供基础。 | C18: 常规★ | E18: √ | G18: √ | I18: T1 /F0-2 / | J18: 可参见《审计手册》4.2.6，由被审计单位生成的信息可能是由系统生成的、或手工编制的、或二者兼而有之的方式生成的。例如，由被审计单位生成的信息可能包括： • 不涉及自定义的、由系统生成的报告（如，固定格式报告）； • 可能通过人工自定义的、由系统生成的报告，例如，（计算机）查询信息或特别定制的报告； • 手工编制的信息，例如，汇总信息的电子表格或用以支持分配、计算以及调节的电子表格； • 其他系统生成或手工编制的信息，例如，由被审计单位编制的客户发票； • 通过影印、拍摄、扫描或其他方式转换成电子形式的文件记录。
A19: 3 | B19: 对期初余额的审计，取得预付账款期初余额明细表复核加计是否正确，与总账、明细账合计数是否相符，检查上期预付账款在本期转销情况，函证期初余额以及其他必要追加的审计程序。（适用于首次承接） | C19: 备选 | D19: √ | E19: √ | F19: √ | G19: √ | J19: 由被审计单位生成的信息不包括： • 总分类账或明细分类账、试算平衡表、或经审计的财务报表； • 第三方（除了服务机构）的报表或报告，例如，原始银行对账单，或函证的回函； • 外部数据（例如，第三方发布的数据，如，定价来源）。
A20: 4 | B20: 关注会计政策、会计估计合理性、一贯性，关注其是否利用会计政策和会计估计及其变更操纵利润。 | C20: 常规★ | D20: √ | E20: √ | G20: √ | I20: F1-1 /F1-2 | J20: 预付账款中的由被审计单位生成的信息例如：采购合同台账、被函证方信息、单独提供的账龄明细表等
A21: 5 | B21: 分析预付款余额及发生额： （1）分析预付账款期末余额本期与上期变化情况、与期末存货余额占比是否合理 （2）分析预付账款发生额本期与上期变化情况、与存货采购金额占比是否合理、是否存在大预付账款款项收回； （3）分析主要供应商期末预付账款余额，关注期末大额预付款项商业合理性、真实性。 | C21: 常规★ | D21: √ | G21: √ | I21: F1-4
A22: 6 | B22: 关注主要供应商采购金额、结合市场惯例判断款项支付的合理性，结合存货及在建工程明细账，核实期后是否收到货物，是否存在变更交易、取消交易等情形。 | C22: 常规★ | D22: √ | E22: √ | G22: √ | I22: F1-2 /F1-4
A23: 7 | B23: 实施函证程序： （1）以积极方式对预付账款进行函证，设计询证函、发函前核实被函证单位信息； （2）注册会计师独立收发询证函； （3）编制函证结果汇总表，检查发函、回函物流信息和轨迹、比对回函印章和签字等以核实回函的真实性，检查回函是否相符，对不符事项查明原因确定是否存在错报； （4）如果未收到回函，应当考虑与被询证者联系，要求对方作出回应或再次寄发询证函，无法收到的回函实施替代程序； （5）如果管理层不允许寄发询证函的，询问管理层不允许寄发的原因，并就其原因的正当、合理性收集证据；考虑实施替代审计程序以获取相关、可靠的审计证据； （6）如果管理层不允许寄发询证函的原因不合理、或者认为回函不可靠，评价对评估的重大错报风险以及其他审计程序的性质、时间安排和范围的影响，并确定其对审计工作和审计意见的影响。 | C23: 常规★ | D23: √ | E23: √ | F23: √ | G23: √ | I23: F0
A24: 8 | B24: 针对舞弊风险较大的供应商，考虑对采购额、合同条款、是否存在关联方关系及是否存在补充协议等实施函证程序。 | C24: IPO/上市/新三板/重组/舞弊应对 | D24: √ | E24: √ | F24: √ | G24: √ | I24: F0
A25: 9 | B25: 检查一年以上预付款项挂账原因，是否存在减值，不符合预付款项性质的是否需要调整至正确科目，因供货单位破产、撤销等原因无法再收到所购货物的预付款项是否应转入其他应收款计提坏账准备。 | C25: 常规★ | D25: √ | G25: √ | I25: F1-5
A26: 10 | B26: 检查预付关联方款项： （1）了解交易的商业理由、交易事项的目的、价格和条件，考虑对关联方预付账款的合理性、合法性； （2）检查对关联方预付账款的真实性相关的支持性文件、检查会计处理是否正确； （3）考虑向关联方或其他注册会计师函证重大的关联采购交易和余额（包括担保和其他重要信息）； （4）必要时，向与交易相关的人员和机构（如银行、律师）函证或与其讨论有关信息； （5）考虑是否存在未识别的关联方，关联交易和余额披露是否正确。 | C26: 常规★ | D26: √ | E26: √ | F26: √ | G26: √ | H26: √ | I26: F1-6 /F1-7 /F0
A27: 11 | B27: 检查与预付账款有关的的记账凭证和相应的支持性证据以确定交易的真实性，是否按规定进行相应的会计处理和披露 | C27: 常规★ | D27: √ | F27: √ | G27: √ | I27: F1-7
A28: 12 | B28: 关注是否存在重要采购承诺、预付账款对外投资和抵押等或有承诺事项。 | C28: 常规★ | F28: √ | G28: √ | H28: √
A29: 13 | B29: 结合存货审计，考虑对重大、新增、异常等供应商进行背景调查、电话访谈、实地走访等。 | C29: IPO/上市/新三板/重组/舞弊应对 | D29: √ | E29: √ | F29: √ | G29: √ | I29: F2-70 /F2-71 /F2-72
A30: 14 | B30: 根据评估的舞弊风险等因素增加的审计程序。 | C30: IPO/上市/新三板/重组/舞弊应对
A31: 15 | B31: 检查预付账款是否已按企业会计准则或其他适用的规定在财务报表中做出恰当列报和披露。 | C31: 常规★ | H31: √ | I31: A1-1/A1-15 /A1-16

Sheet 预付账款实质性程序表G1A-修订前
A1: 致同会计师事务所
A2: 预付账款实质性程序
A3: 客户名称： | C3: 编制人： | E3: 编制日期： | I3: 索引号： | J3: G1A
A4: 截止日：201X年12月31日 | C4: 复核人： | E4: 复核日期： | I4: 页 次：
A5: 一、本账户涉及的科目
A6: 预付账款
A7: 二、重大错报风险需从实质性程序获取的保证程度
A8: 审计目标与认定对应关系 | C8: 财务报表的认定 | H8: 信赖/不信赖/不适用 | I8: 索引号
C9: 存在 | D9: 完整性 | E9: 权利和义务 | F9: 计价和分摊 | G9: 列报与披露
A10: A. 资产负债表中记录的预付账款是存在的，且已经记录在恰当的账户中 | C10: √
A11: B. 所有应记录的预付账款均已记录 | D11: √
A12: C. 记录的预付账款由被审计单位拥有或控制 | E12: √
A13: D. 预付账款以恰当的金额包括在财务报表中，与之相关的计价调整已恰当记录 | F13: √
A14: E. 预付账款已按照企业会计准则的规定在财务报表中作出恰当列报和披露 | G14: √
A15: 序号 | B15: 审计程序 | D15: 程序分类 | E15: 审计目标 | I15: 执行情况说明 （含底稿索引） | K15: 修订类别 | L15: 修改后的程序 | M15: 风险 | N15: 开机启动项 | O15: 问题
A16: 一 | B16: 编制审定表 | D16: 常规★ | E16: B | I16: G1 | K16: 整合 | L16: 获取或编制预付账款的明细表，完成以下工作，并编制审定表 （1）复核加计是否正确，与总账、明细账合计数核对是否相符； （2）获取管理层编制的预付账款账龄分析表，检查账龄划分是否正确； （3）结合应付账款等往来项目的明细余额，检查有无重复付款或将同一笔已付清的款项在预付账款和应付账款两个科目中同时挂账的情况、异常余额或与购货无关的其他款项； （4）检查贷方余额是否需要重分类、非记账本位币预付账款折算是否正确。
A17: 二 | B17: 获取或编制预付账款的明细表，并完成以下工作 | D17: 常规★ | E17: ABD | I17: G1-2 | K17: 整合
A18: 1 | B18: 复核加计正确 | D18: 常规★ | K18: 整合
A19: 2 | B19: 将总金额与总账、明细账合计数核对相符 | D19: 常规★ | K19: 整合
A20: 3 | B20: 调查重大或者异常的调节项目。 | D20: 常规★ | K20: 整合
A21: 4 | B21: 获取管理层编制的预付账款账龄分析表，检查账龄划分是否正确。 | D21: 常规★ | K21: 整合
A22: 5 | B22: 浏览预付账款大额贷方余额，确定是否需要重分类。 | D22: 常规★ | K22: 整合
A23: 7 | B23: 检查非记账本位币预付账款的折算汇率及折算是否正确。 | D23: 备选 | K23: 整合
A24: 8 | B24: 检查有无重复付款或将同一笔已付清的账款在预付账款和应付账款两个科目中同时挂账的情况、异常余额或与购货无关的其他款项（如关联方账户或雇员账户）。 | D24: 常规★ | K24: 整合
A25: 9 | B25: 审核有无长期挂账的预付账款，如有，应查明原因，必要时作调整。 | D25: 常规★ | K25: 整合 | L25: 检查一年以上预付款项挂账原因，是否存在减值，不符合预付款项性质的是否需要调整至正确科目，因供货单位破产、撤销等原因无法再收到所购货物的预付款项是否应转入其他应收款计提坏账准备。
A26: 三 | B26: 在使用被审计单位生成的信息（IPE）时，应当评价该信息对实现审计目的是否足够可靠，包括根据具体情况在必要时实施下列程序： | D26: 常规★ | E26: B | I26: T1 | K26: 保留 | L26: 在使用手工编制、自定义信息报告、系统生成的非固定格式报告等IPE时（如采购合同台账、被函证方信息等），应当评价该信息对实现审计目的是否足够可靠，包括根据具体情况在必要时 获取有关信息准确性和完整性的审计证据。
A27: 1 | B27: 获取有关信息准确性和完整性的审计证据。 | K27: 保留
A28: 2 | B28: 评价信息对实现审计目的是否足够准确和详细。 | K28: 保留
A29: 四 | B29: 对期初余额的审计:（适用于首年审计） | D29: 备选 | E29: B | K29: 整合 | L29: 对期初余额的审计，取得预付账款期初余额明细表复核加计是否正确，与总账、明细账合计数是否相符，检查上期预付账款在本期转销情况，函证期初余额以及其他必要追加的审计程序。（适用于首次承接）
A30: 1 | B30: 取得预付账款期初余额明细表，并完成以下工作： | D30: 备选 | K30: 整合
A31: （1） | B31: 复核加计正确 | D31: 备选 | K31: 整合
A32: （2） | B32: 将总金额与总账、明细账合计数核对相符 | D32: 备选 | K32: 整合
A33: （3） | B33: 检查上期预付账款在本期转销情况。 | D33: 备选 | K33: 整合
A34: 2 | B34: 取得本期前几个月的现金支出日记账： | D34: 备选 | K34: 删除
A35: （1） | B35: 选择单项金额重大的项目。 | D35: 备选 | K35: 删除
A36: （2） | B36: 有判断性的考虑选择其他非单项金额重大的项目。 | D36: 备选 | K36: 删除
A37: （3） | B37: 确定所选择的项目是否记录在适当的会计期内。 | D37: 备选 | K37: 删除
A38: （4） | B38: 根据执行程序的结果，确定是否需要实施追加的审计程序。 | D38: 备选 | K38: 整合
A39: 五 | B39: 执行分析程序，以识别需要增加审计程序的领域: | D39: 常规★ | E39: A.D | K39: 保留、修改 | L39: 分析预付款余额及发生额： （1）分析预付账款期末余额本期与上期变化情况、与期末存货余额占比是否合理 （2）分析预付账款发生额本期与上期变化情况、与存货采购金额占比是否合理、是否存在大预付账款款项收回； （3）分析主要供应商期末预付账款余额，关注期末大额预付款项商业合理性、真实性。
A40: 1 | B40: 比较当年度、资产负债表日后至现场审计期间及以前年度预付账款的构成、账龄及主要供货商的变化，并查明异常情况的原因。 | D40: 常规 | I40: G1-3 | K40: 保留、修改
...

Sheet 审定表F1-1
A1: 致同会计师事务所
A2: 预付账款审定表
A3: =底稿目录!A2 -> 被审计单位： | E3: =底稿目录!A4 -> 编制人： | I3: =底稿目录!A5 -> 编制日期： | K3: 索引号： | L3: =底稿目录!F5 -> F1-1
A4: =底稿目录!A3 -> 截止日：202X年12月31日 | E4: =底稿目录!A6 -> 复核人： | I4: =底稿目录!A7 -> 复核日期： | K4: 页 次：
A5: 一、按照性质分类
A6: 项目 | B6: 期初数 | F6: 期末数 | J6: 本期审定数与上期 审定数的比较 | L6: 原因分析
B7: 未审数 | C7: 账项调整 | D7: 重分类调整 | E7: 审定数 | F7: 未审数 | G7: 账项调整 | H7: 重分类调整 | I7: 审定数 | J7: 变动额 | K7: 变动率
A8: 货款 | E8: =B8+C8+D8 -> 0 | F8: =SUMIF('明细表F1-2'!$D$14:$D$35,'审定表F1-1'!A8,'明细表F1-2'!$O$14:$O$35) -> 0 | G8: =SUMIF('明细表F1-2'!$D$14:$D$35,'审定表F1-1'!A8,'明细表F1-2'!$V$14:$V$35) -> 0 | H8: =SUMIF('明细表F1-2'!$D$14:$D$35,'审定表F1-1'!A8,'明细表F1-2'!$W$14:$W$35) -> 0 | I8: =F8+G8+H8 -> 0 | J8: =I8-E8 -> 0 | K8: =IF(AND(E8=0,J8=0),0,IF(AND(E8=0,J8>0),1,J8/E8)) -> 0
A9: 工程款 | E9: =B9+C9+D9 -> 0 | F9: =SUMIF('明细表F1-2'!$D$14:$D$35,'审定表F1-1'!A9,'明细表F1-2'!$O$14:$O$35) -> 0 | G9: =SUMIF('明细表F1-2'!$D$14:$D$35,'审定表F1-1'!A9,'明细表F1-2'!$V$14:$V$35) -> 0 | H9: =SUMIF('明细表F1-2'!$D$14:$D$35,'审定表F1-1'!A9,'明细表F1-2'!$W$14:$W$35) -> 0 | I9: =F9+G9+H9 -> 0 | J9: =I9-E9 -> 0 | K9: =IF(AND(E9=0,J9=0),0,IF(AND(E9=0,J9>0),1,J9/E9)) -> 0
A10: 设备款 | E10: =B10+C10+D10 -> 0 | F10: =SUMIF('明细表F1-2'!$D$14:$D$35,'审定表F1-1'!A10,'明细表F1-2'!$O$14:$O$35) -> 0 | G10: =SUMIF('明细表F1-2'!$D$14:$D$35,'审定表F1-1'!A10,'明细表F1-2'!$V$14:$V$35) -> 0 | H10: =SUMIF('明细表F1-2'!$D$14:$D$35,'审定表F1-1'!A10,'明细表F1-2'!$W$14:$W$35) -> 0 | I10: =F10+G10+H10 -> 0 | J10: =I10-E10 -> 0 | K10: =IF(AND(E10=0,J10=0),0,IF(AND(E10=0,J10>0),1,J10/E10)) -> 0
A11: 服务费 | E11: =B11+C11+D11 -> 0 | F11: =SUMIF('明细表F1-2'!$D$14:$D$35,'审定表F1-1'!A11,'明细表F1-2'!$O$14:$O$35) -> 0 | G11: =SUMIF('明细表F1-2'!$D$14:$D$35,'审定表F1-1'!A11,'明细表F1-2'!$V$14:$V$35) -> 0 | H11: =SUMIF('明细表F1-2'!$D$14:$D$35,'审定表F1-1'!A11,'明细表F1-2'!$W$14:$W$35) -> 0 | I11: =F11+G11+H11 -> 0 | J11: =I11-E11 -> 0 | K11: =IF(AND(E11=0,J11=0),0,IF(AND(E11=0,J11>0),1,J11/E11)) -> 0
A12: 其他 | E12: =B12+C12+D12 -> 0 | F12: =SUMIF('明细表F1-2'!$D$14:$D$35,'审定表F1-1'!A12,'明细表F1-2'!$O$14:$O$35) -> 0 | G12: =SUMIF('明细表F1-2'!$D$14:$D$35,'审定表F1-1'!A12,'明细表F1-2'!$V$14:$V$35) -> 0 | H12: =SUMIF('明细表F1-2'!$D$14:$D$35,'审定表F1-1'!A12,'明细表F1-2'!$W$14:$W$35) -> 0 | I12: =F12+G12+H12 -> 0 | J12: =I12-E12 -> 0 | K12: =IF(AND(E12=0,J12=0),0,IF(AND(E12=0,J12>0),1,J12/E12)) -> 0
A13: 合计 | B13: =SUM(B8:B12) -> 0 | C13: =SUM(C8:C12) -> 0 | D13: =SUM(D8:D12) -> 0 | E13: =SUM(E8:E12) -> 0 | F13: =SUM(F8:F12) -> 0 | G13: =SUM(G8:G12) -> 0 | H13: =SUM(H8:H12) -> 0 | I13: =SUM(I8:I12) -> 0 | J13: =SUM(J8:J12) -> 0 | K13: =IF(AND(E13=0,J13=0),0,IF(AND(E13=0,J13>0),1,J13/E13)) -> 0 | L13: =SUM(L8:L12) -> 0
A14: 二、按照账龄分类
A15: 项目 | B15: 期初数 | F15: 期末数 | J15: 本期审定数与上期 审定数的比较 | L15: 原因分析
B16: 未审数 | C16: 账项调整 | D16: 重分类调整 | E16: 审定数 | F16: 未审数 | G16: 账项调整 | H16: 重分类调整 | I16: 审定数 | J16: 变动额 | K16: 变动率
A17: 1年以内（含1年） | F17: ='明细表F1-2'!R35 -> 0 | G17: =I17-F17-H17 -> 0 | I17: ='明细表F1-2'!Y35 -> 0 | J17: =I17-E17 -> 0 | K17: =IF(AND(E17=0,J17=0),0,IF(AND(E17=0,J17>0),1,J17/E17)) -> 0
A18: 1至2年（含2年） | F18: ='明细表F1-2'!S35 -> 0 | G18: =I18-F18-H18 -> 0 | I18: ='明细表F1-2'!Z35 -> 0 | J18: =I18-E18 -> 0 | K18: =IF(AND(E18=0,J18=0),0,IF(AND(E18=0,J18>0),1,J18/E18)) -> 0 | M18: =IF(I18>E17,FALSE,TRUE) -> TRUE
A19: 2至3年（含3年） | F19: ='明细表F1-2'!T35 -> 0 | G19: =I19-F19-H19 -> 0 | I19: ='明细表F1-2'!AA35 -> 0 | J19: =I19-E19 -> 0 | K19: =IF(AND(E19=0,J19=0),0,IF(AND(E19=0,J19>0),1,J19/E19)) -> 0 | M19: =IF(I19>E18,FALSE,TRUE) -> TRUE
A20: 3年以上 | F20: ='明细表F1-2'!U35 -> 0 | G20: =I20-F20-H20 -> 0 | I20: ='明细表F1-2'!AB35 -> 0 | J20: =I20-E20 -> 0 | K20: =IF(AND(E20=0,J20=0),0,IF(AND(E20=0,J20>0),1,J20/E20)) -> 0 | M20: =IF(I20>(E19+E20),FALSE,TRUE) -> TRUE
I21: =F21+G21+H21 -> 0 | J21: =I21-E21 -> 0 | K21: =IF(AND(E21=0,J21=0),0,IF(AND(E21=0,J21>0),1,J21/E21)) -> 0
A22: 合计 | B22: =SUM(B17:B21) -> 0 | C22: =SUM(C17:C21) -> 0 | D22: =SUM(D17:D21) -> 0 | E22: =SUM(E17:E21) -> 0 | F22: =SUM(F17:F21) -> 0 | G22: =SUM(G17:G21) -> 0 | H22: =SUM(H17:H21) -> 0 | I22: =SUM(I17:I21) -> 0 | J22: =SUM(J17:J21) -> 0 | K22: =IF(AND(E22=0,J22=0),0,IF(AND(E22=0,J22>0),1,J22/E22)) -> 0 | L22: =SUM(L17:L21) -> 0
A23: 试算平衡表数
A24: 差异数 | E24: =E22-E23 -> 0 | I24: =I22-I23 -> 0
A25: 三、审计说明 | G25: 四、审计结论
A26: 1.预付账款本期较上期增加： | C26: =K13 -> 0
A27: 主要原因（比例超过30%的）：
A28: 2.账龄超过1年的大额重要预付账款

Sheet 附注披露信息(上市公司)
A1: 致同会计师事务所
A2: 预付账款附注披露信息（上市公司） | G2: 返回目录
A3: =底稿目录!A2 -> 被审计单位： | C3: =底稿目录!A4 -> 编制人： | D3: =底稿目录!A5 -> 编制日期： | E3: 索引号：
A4: =底稿目录!A3 -> 截止日：202X年12月31日 | C4: =底稿目录!A6 -> 复核人： | D4: =底稿目录!A7 -> 复核日期： | E4: 页次：
A5: 预付账款附注披露信息：
A6: 预付款项
A7: （1）预付款项按账龄披露
A8: 账 龄 | B8: 期末数 | D8: 上年年末数
B9: 金 额 | C9: 比例% | D9: 金 额 | E9: 比例%
A10: 1年以内 | B10: ='审定表F1-1'!I17 -> 0 | C10: =IF(ISERROR(B10/$B$14),0,B10/$B$14) -> 0 | D10: ='审定表F1-1'!E17 -> 0 | E10: =IF(ISERROR(D10/$D$14),0,D10/$D$14) -> 0
A11: 1至2年 | B11: ='审定表F1-1'!I18 -> 0 | C11: =IF(ISERROR(B11/$B$14),0,B11/$B$14) -> 0 | D11: ='审定表F1-1'!E18 -> 0 | E11: =IF(ISERROR(D11/$D$14),0,D11/$D$14) -> 0
A12: 2至3年 | B12: ='审定表F1-1'!I19 -> 0 | C12: =IF(ISERROR(B12/$B$14),0,B12/$B$14) -> 0 | D12: ='审定表F1-1'!E19 -> 0 | E12: =IF(ISERROR(D12/$D$14),0,D12/$D$14) -> 0
A13: 3年以上 | B13: ='审定表F1-1'!I20 -> 0 | C13: =IF(ISERROR(B13/$B$14%),0,B13/$B$14%) -> 0 | D13: ='审定表F1-1'!E20 -> 0 | E13: =IF(ISERROR(D13/$D$14),0,D13/$D$14) -> 0
A14: 合 计 | B14: =SUM(B10:B13) -> 0 | C14: =SUM(C10:C13) -> 0 | D14: =SUM(D10:D13) -> 0 | E14: =SUM(E10:E13) -> 0
A15: （2）账龄超过1年的重要预付款项
A16: 债务人名称 | B16: 账面余额 | C16: 占预付款项合计的比例（%） | D16: 减值准备
C17: =IF(ISERROR(B17/$B$14),0,B17/$B$14) -> 0
C18: =IF(ISERROR(B18/$B$14),0,B18/$B$14) -> 0
C19: =IF(ISERROR(B19/$B$14),0,B19/$B$14) -> 0
A20: 合 计 | B20: =SUM(B17:B19) -> 0 | C20: =IF(ISERROR(B20/$B$14),0,B20/$B$14) -> 0 | D20: =SUM(D17:D19) -> 0
A21: 说明：（账龄超过1年的金额重要预付账款，应说明未及时结算的原因。）
A22: （3）按预付对象归集的预付款项期末余额前五名单位情况
A23: （按预付对象集中度，汇总或分别披露期末余额前五名的预付款项的期末余额及占预付款项期末余额合计数的比例。）
A24: 汇总披露格式：
A25: 本期按预付对象归集的期末余额前五名预付款项汇总金额XXXX元，占预付款项期末余额合计数的比例 %。
A26: 分别披露格式：
A27: 单位名称 | B27: 预付款项期末余额 | C27: 占预付款项期末余额合计数的比例%
A28: ='实质性分析F1-4'!A41 -> 0 | B28: ='实质性分析F1-4'!B41 -> 0 | C28: =IF(ISERROR(B28/$B$14),0,B28/$B$14) -> 0
A29: ='实质性分析F1-4'!A42 -> 0 | B29: ='实质性分析F1-4'!B42 -> 0 | C29: =IF(ISERROR(B29/$B$14),0,B29/$B$14) -> 0
A30: ='实质性分析F1-4'!A43 -> 0 | B30: ='实质性分析F1-4'!B43 -> 0 | C30: =IF(ISERROR(B30/$B$14),0,B30/$B$14) -> 0
A31: ='实质性分析F1-4'!A44 -> 0 | B31: ='实质性分析F1-4'!B44 -> 0 | C31: =IF(ISERROR(B31/$B$14),0,B31/$B$14) -> 0
A32: ='实质性分析F1-4'!A45 -> 0 | B32: ='实质性分析F1-4'!B45 -> 0 | C32: =IF(ISERROR(B32/$B$14),0,B32/$B$14) -> 0
A33: 合 计 | B33: =SUM(B28:B32) -> 0 | C33: =SUM(C28:C32) -> 0

Sheet 附注披露信息(国企)
A1: 致同会计师事务所
A2: 预付账款附注披露信息（国企） | H2: 返回目录
A3: =底稿目录!A2 -> 被审计单位： | C3: =底稿目录!A4 -> 编制人： | E3: =底稿目录!A5 -> 编制日期： | G3: 索引号：
A4: =底稿目录!A3 -> 截止日：202X年12月31日 | C4: =底稿目录!A6 -> 复核人： | E4: =底稿目录!A7 -> 复核日期： | G4: 页次：
A5: 预付账款附注披露信息：
A6: 预付款项
A7: （1）预付款项按账龄列示
A8: 账 龄 | B8: 期末数 | E8: 期初数
B9: 账面余额 | D9: 坏账准备 | E9: 账面余额 | G9: 坏账准备
B10: 金 额 | C10: 比例（%） | E10: 金 额 | F10: 比例（%）
A11: 1年以内（含1年） | B11: ='审定表F1-1'!I17 -> 0 | C11: =IF(ISERROR(B11/$B$15),0,B11/$B$15) -> 0 | E11: ='审定表F1-1'!E17 -> 0 | F11: =IF(ISERROR(E11/$E$15),0,E11/$E$15) -> 0
A12: 1至2年 | B12: ='审定表F1-1'!I18 -> 0 | C12: =IF(ISERROR(B12/$B$15),0,B12/$B$15) -> 0 | E12: ='审定表F1-1'!E18 -> 0 | F12: =IF(ISERROR(E12/$E$15),0,E12/$E$15) -> 0
A13: 2至3年 | B13: ='审定表F1-1'!I19 -> 0 | C13: =IF(ISERROR(B13/$B$15),0,B13/$B$15) -> 0 | E13: ='审定表F1-1'!E19 -> 0 | F13: =IF(ISERROR(E13/$E$15),0,E13/$E$15) -> 0
A14: 3年以上 | B14: ='审定表F1-1'!I20 -> 0 | C14: =IF(ISERROR(B14/$B$15),0,B14/$B$15) -> 0 | E14: ='审定表F1-1'!E20 -> 0 | F14: =IF(ISERROR(E14/$E$15),0,E14/$E$15) -> 0
A15: 合 计 | B15: =SUM(B11:B14) -> 0 | C15: =SUM(C11:C14) -> 0 | D15: =SUM(D11:D14) -> 0 | E15: =SUM(E11:E14) -> 0 | F15: =SUM(F11:F14) -> 0 | G15: =SUM(G11:G14) -> 0
A16: （2）账龄超过1年的大额预付款项
A17: 债权单位 | B17: 债务单位 | C17: 期末余额 | D17: 账龄 | E17: 未结算的原因
A18: =RIGHT($A$3,LEN($A$3)-SEARCH("：",$A$3)) | B18: ='长期挂款检查表F1-5'!A6 -> 0 | C18: ='长期挂款检查表F1-5'!J6 -> 0 | D18: ='长期挂款检查表F1-5'!C6 -> 0 | E18: ='长期挂款检查表F1-5'!E6 -> 0
A19: =RIGHT($A$3,LEN($A$3)-SEARCH("：",$A$3)) | B19: ='长期挂款检查表F1-5'!A7 -> 0 | C19: ='长期挂款检查表F1-5'!J7 -> 0 | D19: ='长期挂款检查表F1-5'!C7 -> 0 | E19: ='长期挂款检查表F1-5'!E7 -> 0
A20: =RIGHT($A$3,LEN($A$3)-SEARCH("：",$A$3)) | B20: ='长期挂款检查表F1-5'!A14 -> 0 | C20: ='长期挂款检查表F1-5'!J14 -> 0 | D20: ='长期挂款检查表F1-5'!C14 -> 0 | E20: ='长期挂款检查表F1-5'!E14 -> 0
A21: 合 计 | C21: =SUM(C18:C20) -> 0 | D21: —— | E21: ——
A22: （3）按欠款方归集的期末余额前五名的预付款项情况
A23: 债务人名称 | B23: 账面余额 | C23: 占预付款项合计的比例（%） | D23: 坏账准备
C24: =IFERROR(B24/$B$15,0) -> 0
C25: =IFERROR(B25/$B$15,0) -> 0
C26: =IFERROR(B26/$B$15,0) -> 0
C27: =IFERROR(B27/$B$15,0) -> 0
C28: =IFERROR(B28/$B$15,0) -> 0
A29: 合 计 | B29: =SUM(B24:B28) -> 0 | C29: =IFERROR(B29/$B$15,0) -> 0 | D29: ——

Sheet 明细表F1-2
A1: 致同会计师事务所
A2: 预付账款明细表
A3: =底稿目录!A2 -> 被审计单位： | K3: =底稿目录!A4 -> 编制人： | T3: =底稿目录!A5 -> 编制日期： | AD3: 索引号： | AE3: =底稿目录!F8 -> F1-2
A4: =底稿目录!A3 -> 截止日：202X年12月31日 | K4: =底稿目录!A6 -> 复核人： | T4: =底稿目录!A7 -> 复核日期： | AD4: 页次：
A5: 一、审计目标:
A6: 1.资产负债表中记录的预付账款是存在的，且已经记录在恰当的账户中； 2.所有应记录的预付账款均已记录，所有应当包括在财务报表中的相关披露均已包括； 3.预付账款以恰当的金额包括在财务报表中，与之相关的计价或分摊调整已恰当记录，相关披露已得到恰当计量和描述
A7: 二、审计过程：
A8: 1.取得预付账款明细表，检查账龄划分是否正确、贷方余额是否需要重分类，检查有无重复付款或将同一笔已付清的账款在预付款项和应付账款两个科目中同时挂账的情况、异常余额或与购货无关的其他款项（如关联方账户或雇员账户）
A9: 2.关注大额预付账款交易真实性及期后合同执行情况，检查期后是否已收到实物并转销预付款项
A10: 3.结合市场惯例，关注大额预付款项支付的合理性
A11: 4.获取并检查被审计单位与其供应商之间的对账单以及被审计单位编制的差异调节表，确定预付款项金额的准确性。
A12: 债权人名称 | B12: 公司代码 | C12: 关联方类型 | D12: 款项性质 | E12: 期初未审余额 | F12: 期初账项调整 | G12: 期初重分类调整 | H12: 期初审定余额 | I12: 期初审定账龄 | M12: 借方发生 | N12: 贷方发生 | O12: 期末余额 | P12: 被审计单位重分类调整 | Q12: 期末未审余额 | R12: 期末未审账龄 | V12: 账项调整 | W12: 重分类调整 | X12: 审定数 | Y12: 期末审定账龄 | AC12: 是否函证 | AD12: 期后到货 | AE12: 备注
C13: 关联方类型 | D13: 款项性质 | E13: 期初余额 | F13: 账项调整 | G13: 重分类调整 | H13: 期初审定 | I13: 1年以下 | J13: 1～2年 | K13: ２～3年 | L13: 3年以上 | M13: 借方发生 | N13: 贷方发生 | O13: 期末余额 | Q13: 期末余额 | R13: 1年以下 | S13: 1～2年 | T13: ２～3年 | U13: 3年以上 | Y13: 1年以下 | Z13: 1～2年 | AA13: ２～3年 | AB13: 3年以上
D14: 货款 | H14: =E14+F14+G14 -> 0 | O14: =E14+M14-N14 -> 0 | Q14: =O14+P14 -> 0 | X14: =O14+V14+W14 -> 0
D15: 工程款 | H15: =E15+F15+G15 -> 0 | O15: =E15+M15-N15 -> 0 | Q15: =O15+P15 -> 0 | X15: =O15+V15+W15 -> 0
D16: 货款 | H16: =E16+F16+G16 -> 0 | O16: =E16+M16-N16 -> 0 | Q16: =O16+P16 -> 0 | X16: =O16+V16+W16 -> 0
D17: 工程款 | H17: =E17+F17+G17 -> 0 | O17: =E17+M17-N17 -> 0 | Q17: =O17+P17 -> 0 | X17: =O17+V17+W17 -> 0
D18: 货款 | H18: =E18+F18+G18 -> 0 | O18: =E18+M18-N18 -> 0 | Q18: =O18+P18 -> 0 | X18: =O18+V18+W18 -> 0
D19: 其他 | H19: =E19+F19+G19 -> 0 | O19: =E19+M19-N19 -> 0 | Q19: =O19+P19 -> 0 | X19: =O19+V19+W19 -> 0
D20: 设备款 | H20: =E20+F20+G20 -> 0 | O20: =E20+M20-N20 -> 0 | Q20: =O20+P20 -> 0 | X20: =O20+V20+W20 -> 0
D21: 其他 | H21: =E21+F21+G21 -> 0 | O21: =E21+M21-N21 -> 0 | Q21: =O21+P21 -> 0 | X21: =O21+V21+W21 -> 0
D22: 服务费 | H22: =E22+F22+G22 -> 0 | O22: =E22+M22-N22 -> 0 | Q22: =O22+P22 -> 0 | X22: =O22+V22+W22 -> 0
H23: =E23+F23+G23 -> 0 | O23: =E23+M23-N23 -> 0 | Q23: =O23+P23 -> 0 | X23: =O23+V23+W23 -> 0
H24: =E24+F24+G24 -> 0 | O24: =E24+M24-N24 -> 0 | Q24: =O24+P24 -> 0 | X24: =O24+V24+W24 -> 0
H25: =E25+F25+G25 -> 0 | O25: =E25+M25-N25 -> 0 | Q25: =O25+P25 -> 0 | X25: =O25+V25+W25 -> 0
H26: =E26+F26+G26 -> 0 | O26: =E26+M26-N26 -> 0 | Q26: =O26+P26 -> 0 | X26: =O26+V26+W26 -> 0
H27: =E27+F27+G27 -> 0 | O27: =E27+M27-N27 -> 0 | Q27: =O27+P27 -> 0 | X27: =O27+V27+W27 -> 0
H28: =E28+F28+G28 -> 0 | O28: =E28+M28-N28 -> 0 | Q28: =O28+P28 -> 0 | X28: =O28+V28+W28 -> 0
H29: =E29+F29+G29 -> 0 | O29: =E29+M29-N29 -> 0 | Q29: =O29+P29 -> 0 | X29: =O29+V29+W29 -> 0
H30: =E30+F30+G30 -> 0 | O30: =E30+M30-N30 -> 0 | Q30: =O30+P30 -> 0 | X30: =O30+V30+W30 -> 0
H31: =E31+F31+G31 -> 0 | O31: =E31+M31-N31 -> 0 | Q31: =O31+P31 -> 0 | X31: =O31+V31+W31 -> 0
H32: =E32+F32+G32 -> 0 | O32: =E32+M32-N32 -> 0 | Q32: =O32+P32 -> 0 | X32: =O32+V32+W32 -> 0
H33: =E33+F33+G33 -> 0 | O33: =E33+M33-N33 -> 0 | Q33: =O33+P33 -> 0 | X33: =O33+V33+W33 -> 0
H34: =E34+F34+G34 -> 0 | O34: =E34+M34-N34 -> 0 | Q34: =O34+P34 -> 0 | X34: =O34+V34+W34 -> 0
A35: 合计 | E35: =SUM(E14:E34) -> 0 | F35: =SUM(F14:F34) -> 0 | G35: =SUM(G14:G34) -> 0 | H35: =SUM(H14:H34) -> 0 | I35: =SUM(I14:I34) -> 0 | J35: =SUM(J14:J34) -> 0 | K35: =SUM(K14:K34) -> 0 | L35: =SUM(L14:L34) -> 0 | ... AB35: =SUM(AB14:AB34) -> 0 | AC35: -- | AD35: =SUM(AD14:AD34) -> 0
A36: 账龄占比 | H36: =IF((H35-I35-J35-K35-L35)=0,"OK","账龄与审定不匹配") -> OK | I36: =ROUND(I35/$H$35,2) -> #DIV/0! | J36: =J35/$H$35 -> #DIV/0! | K36: =K35/$H$35 -> #DIV/0! | L36: =L35/$H$35 -> #DIV/0! | O36: =IF((O35-R35-S35-T35-U35)=0,"OK","账龄与审定不匹配") -> OK | Q36: =IF((Q35-R35-S35-T35-U35)=0,"OK","账龄与审定不匹配") -> OK | X36: =IF((X35-Y35-Z35-AA35-AB35)=0,"OK","账龄与审定不匹配") -> OK | Y36: =ROUND(Y35/$X$35,2) -> #DIV/0! | Z36: =ROUND(Z35/$X$35,2) -> #DIV/0! | AA36: =ROUND(AA35/$X$35,2) -> #DIV/0! | AB36: =ROUND(AB35/$X$35,2) -> #DIV/0!
A37: 账龄逻辑校验 | Z37: =IF(Z35<=I35,TRUE,FALSE) -> TRUE | AA37: =IF(AA35<=J35,TRUE,FALSE) -> TRUE | AB37: =IF(AB35<=(K35+L35),TRUE,FALSE) -> TRUE
A38: 三、审计说明：
A39: 1.期初数与上期审定数一致,期末总账、明细账、报表相符。
A40: 2.**预付款项发生额大，其主要原因列示如下：
...

Sheet 调整分录汇总F1-3
A1: 致同会计师事务所
A2: 预付账款调整分录汇总表
A3: =底稿目录!A2 -> 被审计单位： | D3: =底稿目录!A4 -> 编制人： | G3: =底稿目录!A5 -> 编制日期： | I3: 索引号： | J3: =底稿目录!F9 -> F1-3
A4: =底稿目录!A3 -> 截止日：202X年12月31日 | D4: =底稿目录!A6 -> 复核人： | G4: =底稿目录!A7 -> 复核日期： | I4: 页 次： | J4: 1
A5: 调整事项说明 | B5: 类别（报表调整/账项调整/其他） | C5: 报表项目 | D5: 科目名称 | E5: 附注项目 | F5: …… | G5: 借方调整金额 | H5: 贷方调整金额 | I5: 索引 | J5: 备注
A23: 注：本底稿适用于调整分录较多、较复杂的项目，且仅列示与本报表项目相关的审计调整。项目组可根据项目实际情况选择是否使用该底稿。

Sheet 实质性分析F1-4
A1: 致同会计师事务所
A2: 预付账款实质性分析表
A3: =底稿目录!A2 -> 被审计单位： | C3: =底稿目录!A4 -> 编制人： | G3: =底稿目录!A5 -> 编制日期： | I3: 索引号： | J3: =底稿目录!F10 -> F1-4
A4: =底稿目录!A3 -> 截止日：202X年12月31日 | C4: =底稿目录!A6 -> 复核人： | G4: =底稿目录!A7 -> 复核日期： | I4: 页 次：
A5: 一、审计目标:
A6: 1.资产负债表中记录的预付账款是存在的，且已经记录在恰当的账户中；
A7: 2.预付账款以恰当的金额包括在财务报表中，与之相关的计价或分摊调整已恰当记录，相关披露已得到恰当计量和描述
A8: 二、审计过程：
A9: 分析预付账款余额、借方发生额、贷方发生额、期末大额预付款情况，分析异常原因、关注期末对供应商支付大额预付款项的合理性
A10: 1.预付账款余额分析
A11: 项目 | D11: 本期金额 | E11: 上期金额 | F11: 变动金额 | G11: 变动比例
A12: 预付账款余额 | D12: =SUM(D13:D16) -> 0 | E12: =SUM(E13:E16) -> 0 | F12: =D12-E12 -> 0 | G12: =F12/E12 -> #DIV/0!
A13: 其中： 与存货有关的预付账款余额 | F13: =D13-E13 -> 0 | G13: =F13/E13 -> #DIV/0!
A14: 与费用有关的预付账款余额 | F14: =D14-E14 -> 0 | G14: =F14/E14 -> #DIV/0!
A15: 与工程、固定资产有关的预付账款余额 | F15: =D15-E15 -> 0 | G15: =F15/E15 -> #DIV/0!
A16: 其他 | F16: =D16-E16 -> 0 | G16: =F16/E16 -> #DIV/0!
A17: 存货余额 | F17: =D17-E17 -> 0 | G17: =F17/E17 -> #DIV/0!
A18: 期末与存货有关预付款项余额占存货比重 | D18: =IF(D17=0,0,D13/D17) -> 0 | E18: =IF(E17=0,0,E13/E17) -> 0 | F18: =D18-E18 -> 0 | G18: =F18/E18 -> #DIV/0!
A19: 审计说明：
A21: 2.预付账款借方发生额分析
A22: 项目 | D22: 本期金额 | E22: 上期金额 | F22: 变动金额 | G22: 变动比例
A23: 预付账款借方发生额 | D23: =SUM(D24:D27) -> 0 | E23: =SUM(E24:E27) -> 0 | F23: =D23-E23 -> 0 | G23: =F23/E23 -> #DIV/0!
A24: 其中： 与存货有关的预付账款借方发生额 | F24: =D24-E24 -> 0 | G24: =F24/E24 -> #DIV/0!
A25: 与费用有关的预付账款借方发生额 | F25: =D25-E25 -> 0 | G25: =F25/E25 -> #DIV/0!
A26: 与工程、固定资产有关的预付账款借方发生额 | F26: =D26-E26 -> 0 | G26: =F26/E26 -> #DIV/0!
A27: 其他 | F27: =D27-E27 -> 0 | G27: =F27/E27 -> #DIV/0!
A28: 存货采购金额 | F28: =D28-E28 -> 0 | G28: =F28/E28 -> #DIV/0!
A29: 与存货有关的预付账款借方发生额占存货采购金额比重 | D29: =IF(D28=0,0,D24/D28) -> 0 | E29: =IF(E28=0,0,E24/E28) -> 0 | F29: =D29-E29 -> 0 | G29: =F29/E29 -> #DIV/0!
A30: 审计说明：
A32: 3.预付账款贷方发生额分析
A33: 预付账款贷方发生额：
A34: 其中： 转销计入存货金额 | C34: 转销工程、固定资产金额
A35: 转销计入费用金额 | C35: 收回款项金额 | K35: 如存在大额预付账款收回，关注合理性、是否存在关联方资金占用等情形
A36: 其他
A37: 审计说明：
A39: 4.大额供应商预付账款期末余额分析
A40: 供应商名称 | B40: 期初余额 | C40: 借方发生 | D40: 贷方发生 | E40: 期末余额 | F40: 减：坏账准备 | G40: 账面价值 | H40: 发生时间及账龄 | I40: 发生原因 | J40: 期后到货 | K40: 如存在大额预付账款期末余额，应重点关注支付预付款的商业合理性、交易是否真实、是否存在关联方资金占用
E41: =B41+C41-D41 -> 0 | G41: =E41-F41 -> 0
E42: =B42+C42-D42 -> 0 | G42: =E42-F42 -> 0
E43: =B43+C43-D43 -> 0 | G43: =E43-F43 -> 0
...

Sheet 长期挂款检查表F1-5
A1: 致同会计师事务所
A2: 账龄1年以上的大额预付账款检查表
A3: =底稿目录!A2 -> 被审计单位： | D3: =底稿目录!A4 -> 编制人： | G3: =底稿目录!A5 -> 编制日期： | L3: 索引号： | M3: =底稿目录!F18 -> F1-5
A4: =底稿目录!A3 -> 截止日：202X年12月31日 | D4: =底稿目录!A6 -> 复核人： | G4: =底稿目录!A7 -> 复核日期： | L4: 页 次：
A5: 债务人名称 | B5: 期末余额 | C5: 账龄 | D5: 经济业务说明 | E5: 未偿还或未结转的原因 | F5: 计划供货还是退款 | G5: 是否诉讼 | H5: 是否转入其他应收款 | I5: 计提坏账准备金额 | J5: 审定余额 | K5: 期后供货或退款金额 | L5: 支持性证据 | M5: 备注
A15: 合计 | B15: =SUM(B6:B14) -> 0 | I15: =SUM(I6:I14) -> 0 | J15: =SUM(J6:J14) -> 0 | K15: =SUM(K6:K14) -> 0
A16: 1、审计说明：
A19: 2、审计结论：

Sheet 关联方及交易检查表F1-6
A1: 致同会计师事务所
A2: 预付账款关联方及交易检查表
A3: =底稿目录!A2 -> 被审计单位： | E3: =底稿目录!A4 -> 编制人： | I3: =底稿目录!A5 -> 编制日期： | L3: 索引号： | M3: =底稿目录!F19 -> F1-6
A4: =底稿目录!A3 -> 截止日：202X年12月31日 | E4: =底稿目录!A6 -> 复核人： | I4: =底稿目录!A7 -> 复核日期： | L4: 页 次：
A5: 关注对关联方预付款项的真实性、合理性、合法性、会计处理是否正确，考虑是否存在未识别的关联方，检查关联交易和余额披露是否正确。
A6: 关联方名称 | B6: 关联关系 | C6: 期初余额 | D6: 借方发生额 | E6: 贷方发生额 | F6: 期末余额 | G6: 减：坏账准备 | H6: 账面价值 | I6: 发生时间及账龄 | J6: 发生原因（款项性质） | K6: 期后到货 | L6: 索引号 | M6: 备注
A7: 债务人（股东）1 | F7: =C7+D7-E7 -> 0 | H7: =F7-G7 -> 0
A8: 债务人（股东）2 | F8: =C8+D8-E8 -> 0 | H8: =F8-G8 -> 0
A9: …… | F9: =C9+D9-E9 -> 0 | H9: =F9-G9 -> 0
A10: 合计 | C10: =SUM(C7:C9) -> 0 | D10: =SUM(D7:D9) -> 0 | E10: =SUM(E7:E9) -> 0 | F10: =SUM(F7:F9) -> 0 | G10: =SUM(G7:G9) -> 0 | H10: =SUM(H7:H9) -> 0 | K10: =SUM(K7:K9) -> 0
A11: 1、审计说明：
A13: 2、审计结论：
B15: 勿删、勿改
B16: 实际控制人
B17: 控股股东
B18: 控股股东、实际控制人的附属企业
B19: 持有5%以上股份的法人或其他组织
B20: 联营企业
B21: 合营企业
B22: 董高监等关键管理人员
B23: 其他关联方

Sheet 预付账款检查表F1-7
A1: 致同会计师事务所
A2: 预付账款检查表
A3: =底稿目录!A2 -> 被审计单位： | H3: =底稿目录!A4 -> 编制人： | L3: =底稿目录!A5 -> 编制日期： | Q3: 索引号： | R3: =底稿目录!F20 -> F1-7
A4: =底稿目录!A3 -> 截止日：202X年12月31日 | H4: =底稿目录!A6 -> 复核人： | L4: =底稿目录!A7 -> 复核日期： | Q4: 页次：
A5: 一、审计目标：
A6: 1.资产负债表中记录的预付账款是存在的，且已经记录在恰当的账户中； 2.记录的预付账款由被审计单位拥有或控制；
A7: 3.预付账款以恰当的金额包括在财务报表中，与之相关的计价或分摊调整已恰当记录，相关披露已得到恰当计量和描述
A8: 二、样本选取标准与规模：
A9: 测试总体： | B9: 如预付账款借方发生额所有凭证共XX笔金额XX、贷方发生额所有凭证共XX笔金额XX | I9: 特定样本： | J9: XX金额以上（大额）、关联方/关联交易形成的款项、XX异常款项全部测试，共XX笔；
A10: 抽样总体： | B10: 测试总体扣除特定样本以外的样本，共XX笔、金额XX | I10: 确定的抽样样本量： | K10: 抽取XX笔 | L10: （如果使用了样本计算器计算样本量，样本量计算过程见<XX>底稿）
A11: 抽样方法： | B11: 随机选样/系统选样/货币单元抽样/随意选样（非统计抽样适用） | I11: 抽样过程： | J11: 使用IDEA（XX抽样工具）选择XX数量、金额XX的样本进行测试，抽样工具中的样本选择过程和结果见<XX>底稿
A12: 三、测试：
A13: 测试内容说明：1.原始凭证是否齐全； 2.记账凭证与原始凭证是否相符；3.账务处理是否正确；4.是否记录于恰当的会计期间；5.……
A14: 1.本期借方金额检查
A15: 记账凭证 | H15: 付款审批单 | J15: 银行回单 | M15: 合同/协议/订单 | P15: …… | Q15: 索引号 | R15: 是否异常
A16: 供应商名称 | B16: 日期 | C16: 凭证编号 | D16: 业务内容 | E16: 对方科目 | F16: 对方明细科目 | G16: 借方金额 | H16: 日期/编号 | I16: 是否经过恰当审批 | J16: 日期 | K16: 收款方 | L16: 金额 | M16: 供应商名称 | N16: 合同金额 | O16: 预付比例 | S16: 检查的关键证据和要素根据被审计单位具体情况修改
A38: 合计 | G38: =SUM(G17:G37) -> 0 | L38: =SUM(L17:L37) -> 0 | N38: =SUM(N17:N37) -> 0
A39: 2.本期贷方金额检查
A40: 记账凭证 | H40: 入库单/验收单 | L40: 采购发票 | O40: …… | P40: 索引号 | Q40: 是否异常
A41: 供应商名称 | B41: 日期 | C41: 凭证编号 | D41: 业务内容 | E41: 对方科目 | F41: 对方明细科目 | G41: 贷方金额 | H41: 日期/编号 | I41: 品名 | J41: 单位 | K41: 数量 | L41: 日期/编号 | M41: 对手方名称 | N41: 金额 | S41: 检查的关键证据和要素根据被审计单位具体情况修改
A65: 合计 | G65: =SUM(G42:G64) -> 0 | N65: =SUM(N42:N64) -> 0
A66: 3.资产负债表日后贷方检查
A67: 记账凭证 | H67: 入库单/验收单 | L67: 采购发票 | O67: …… | P67: 索引号 | Q67: 是否异常
A68: 供应商名称 | B68: 日期 | C68: 凭证编号 | D68: 业务内容 | E68: 对方科目 | F68: 对方明细科目 | G68: 贷方金额 | H68: 日期/编号 | I68: 品名 | J68: 单位 | K68: 数量 | L68: 日期/编号 | M68: 对手方名称 | N68: 金额 | S68: 检查的关键证据和要素根据被审计单位具体情况修改
A86: 合计 | G86: =SUM(G69:G85) -> 0 | N86: =SUM(N69:N85) -> 0
A87: 四、审计说明：
A88: 1.本期发生额、期末余额检查比例： | D88: 方向 | E88: 账面金额 | F88: 检查金额 | G88: 检查比例 | H88: 如果检查比例较低应扩大检查样本量或说明原因
D89: 本期借方 | E89: ='明细表F1-2'!M35 -> 0 | F89: =G38 -> 0 | G89: =ROUND(F89/E89,4) -> #DIV/0!
D90: 本期贷方 | E90: ='明细表F1-2'!N35 -> 0 | F90: =G65 -> 0 | G90: =ROUND(F90/E90,2) -> #DIV/0!
D91: 期末余额 | E91: ='明细表F1-2'!X35 -> 0 | F91: =G86 -> 0 | G91: =ROUND(F91/E91,2) -> #DIV/0!
A92: 2.……
A93: 五、审计结论：
