Workbook
Name bs: {#N/A,#N/A,FALSE,"BBPREP"}
Name bs: {#N/A,#N/A,FALSE,"BBPREP"}
Name bs_1: {#N/A,#N/A,FALSE,"BBPREP"}
Name bs: {#N/A,#N/A,FALSE,"BBPREP"}
Name bs_1: {#N/A,#N/A,FALSE,"BBPREP"}
Name _?: #REF!
Name _??????: #REF!
Name __?: #REF!
Name __??????: #REF!
Name __2003002K8: #REF!
Name __2003002KA: #REF!
Name __2003002KC: #REF!
Name __2003002P1: #REF!
Name __2003007KA: #REF!
Name __2004001KF: #REF!
Name __2004001P1: #REF!
Name __2004009P1: #REF!
Name __2004012P1: #REF!
Name _1_?: #REF!
Name _10_2003002KA: #REF!
Name _10_2003002P1: #REF!
Name _10_2004009P1: #REF!
Name _11_2003002KC: #REF!
Name _11_2003007KA: #REF!
Name _11_2004012P1: #REF!
Name _12_??????: #REF!
Name _12_2003002P1: #REF!
Name _12_2004001KF: #REF!
Name _13_2003002K8: #REF!
Name _13_2003007KA: #REF!
Name _13_2004001P1: #REF!
Name _14_2003002KA: #REF!
Name _14_2004001KF: #REF!
Name _14_2004009P1: #REF!
Name _15_2003002KC: #REF!
Name _15_2004001P1: #REF!
Name _15_2004012P1: #REF!
Name _16_2003002P1: #REF!
Name _16_2004009P1: #REF!
Name _17_2003007KA: #REF!
Name _17_2004012P1: #REF!
Name _18_2004001KF: #REF!
Name _19_2004001P1: #REF!
Name _2_??????: #REF!
Name _20_2004009P1: #REF!
Name _2003002K8: #REF!
Name _2003002KA: #REF!
Name _2003002KC: #REF!
Name _2003002P1: #REF!
Name _2003007KA: #REF!
Name _2004001KF: #REF!
Name _2004001P1: #REF!
Name _2004009P1: #REF!
Name _2004012P1: #REF!
Name _21_2004012P1: #REF!
Name _3_?: #REF!
Name _3_2003002K8: #REF!
Name _4_?: #REF!
Name _4_2003002KA: #REF!
Name _5_2003002KC: #REF!

Sheet 底稿目录
A1: 底稿开列时，可先在以下单元格填写有关内容，以便其他底稿引用有关数据：
A2: 被审计单位： | D2: 序号 | E2: 内容 | F2: 索引号
A3: 截止日：202X年12月21日 | D3: 1 | E3: 存货实质性程序表 | F3: F2A
A4: 编制人： | D4: 2 | E4: 存货审定表 | F4: F2-1
A5: 编制日期： | D5: 3 | E5: 附注披露信息(上市公司） | G5: 无需打印
A6: 复核人： | D6: 4 | E6: 附注披露信息(国企） | G6: 无需打印
A7: 复核日期： | D7: 5 | E7: 存货明细汇总表 | F7: F2-2
D8: 6 | E8: 一、原材料明细表 | F8: F2-3
A9: 关于工作底稿与审计程序索引号对应的说明 | D9: 7 | E9: 二、材料采购、在途物资明细表 | F9: F2-4
A10: 1.编制的审计工作底稿应与审计程序对应。审计项目组应根据被审计单位实际情况和风险评估情况在实质性程序表中裁剪、修改或增加审计程序，根据实际执行的审计程序完成相应审计工作底稿，编制的工作底稿中应按自然顺序依次编制索引号，并通过唯一的索引号将与实质性程序表中的程序对应关联（即将工作底稿的索引号填入实质性程序表中的底稿索引号列）。 | D10: 8 | E10: 三、周转材料、低值易耗品，包装物明细表 | F10: F2-5
D11: 9 | E11: 四、自制半成品明细表 | F11: F2-6
D12: 10 | E12: 五、委托加工物资明细表 | F12: F2-7
D13: 11 | E13: 六、库存商品明细表 | F13: F2-8
A14: 2.获取的支持性证据应与审计底稿或程序对应。审计项目组在完成底稿时获取的支持性证据应根据底稿索引号编制下一级按自然顺序排序的索引号（如D1-2-1、D1-2-2、……），并在底稿中说明引用的支持性证据、关联索引号。 | D14: 12 | E14: 七、发出商品明细表 | F14: F2-9
D15: 13 | E15: 八、开发产品明细表 | F15: F2-10
D16: 14 | E16: 九、开发成本明细表 | F16: F2-11
A17: 3.工作底稿索引号的编码规则：实质性程序索引号按循环从“D”到“N”,循环内账户以顺序号排列，模板中底稿索引号按账户顺序+自然数顺序（即模板中索引号按二级自然顺序排列，如D1-1、D1-2、D1-3、……D1-N）。 | D17: 15 | E17: 十、合同履约成本明细表 | F17: F2-12
D18: 16 | E18: 十一、消耗性生物资产明细表 | F18: F2-13
D19: 17 | E19: 调整分录汇总 | F19: F2-14

Sheet 存货实质性程序表F2A
A1: 致同会计师事务所
A2: 存货实质性程序
A3: =[1]底稿目录!A2 -> 被审计单位： | D3: =[1]底稿目录!A4 -> 编制人： | F3: =[1]底稿目录!A5 -> 编制日期： | I3: 索引号： | J3: =[1]底稿目录!F3 -> F2A
A4: =[1]底稿目录!A3 -> 截止日：202X年12月21日 | D4: =[1]底稿目录!A6 -> 复核人： | F4: =[1]底稿目录!A7 -> 复核日期： | I4: 页 次：
A5: 一、本账户涉及的科目
A6: 存货及跌价准备
A7: 二、审计目标与认定的对应关系
A8: 审计目标 | H8: 财务报表的认定
A9: A. 资产负债表中记录的存货是存在的，且已经记录在恰当的账户中 | H9: 存在
A10: B. 所有应记录的存货均已记录，所有应当包括在财务报表中的相关披露均已包括 | H10: 完整性
A11: C. 记录的存货由被审计单位拥有或控制 | H11: 权利和义务
A12: D. 存货以恰当的金额包括在财务报表中，与之相关的计价或分摊调整已恰当记录，相关披露已得到恰当计量和描述 | H12: 准确性、计价和分摊
A13: E. 存货已被恰当地汇总或分解且表述清楚，相关披露在按照企业会计准则的编制基础下是相关的、可理解的 | H13: 列报
A14: 三、计划实施的实质性程序
A15: 序号 | B15: 与Leap对应 | C15: 审计程序 | D15: 程序分类 | E15: 财务报表的认定 | J15: 底稿索引号
E16: 存在 | F16: 完整性 | G16: 权利和 义务 | H16: 准确性、计价和分摊 | I16: 列报 | K16: 根据被审计单位实际情况和风险评估情况裁剪、修改或增加审计程序
A17: 1 | B17: 常规程序 | C17: 获取或编制存货的（收发存）明细表，完成以下工作，并编制审定表 （1）复核加计是否正确，与总账、明细账合计数核对是否相符，期初余额与上期审定期末余额是否相符； （2）获取管理层编制的存货库龄分析表，检查库龄划分是否正确； （3）检查存货明细表中是否有异常或负余额（包括数量为负或金额为负）的项目。 | D17: 常规★ | E17: √ | F17: √ | H17: √ | J17: F2-1/F2-2至F2-14
A18: 2 | B18: 常规程序 | C18: 抽查核对存货收发存明细账是否与仓储台账（ERP业务数据）、卡片记录相符（双向核对），存货是否及时入账，存货编号存在漏记、重复等。 | D18: 常规★ | E18: √ | F18: √ | H18: √ | J18: F2-24
A19: 3 | B19: IPE程序 | C19: 在使用手工编制、自定义信息报告、系统生成的非固定格式报告等由被审计单位生成的信息时，测试有关信息准确性和完整性，并考虑针对编制和维护由被审计单位生成的信息的相关控制实施控制测试，以评价该信息是否能够为实现审计目的提供基础。 | D19: 常规★ | F19: √ | H19: √ | J19: T1/ | K19: 可参见《审计手册》4.2.6，由被审计单位生成的信息可能是由系统生成的、或手工编制的、或二者兼而有之的方式生成的。例如，由被审计单位生成的信息可能包括： • 不涉及自定义的、由系统生成的报告（如，固定格式报告）； • 可能通过人工自定义的、由系统生成的报告，例如，（计算机）查询信息或特别定制的报告； • 手工编制的信息，例如，汇总信息的电子表格或用以支持分配、计算以及调节的电子表格； • 其他系统生成或手工编制的信息，例如，由被审计单位编制的客户发票； • 通过影印、拍摄、扫描或其他方式转换成电子形式的文件记录。
A20: 4 | B20: 期初余额程序 | C20: 对期初余额的审计，取得存货期初余额明细表复核加计是否正确，与总账、明细账合计数是否相符，检查期初存货在本期结转情况，取得上期存货盘点表核对差异，通过监盘当前的存货数量并调节至期初存货数量、对期初存货项目的计价实施审计程序、对毛利进行分析和存货截止实施审计程序。（适用于首次承接） | D20: 备选 | E20: √ | F20: √ | G20: √ | H20: √ | K20: 由被审计单位生成的信息不包括： • 总分类账或明细分类账、试算平衡表、或经审计的财务报表； • 第三方（除了服务机构）的报表或报告，例如，原始银行对账单，或函证的回函； • 外部数据（例如，第三方发布的数据，如，定价来源）。
A21: 5 | B21: 常规程序、应对措施-会计估计 | C21: 了解会计政策、会计估计合理性、一贯性，关注其是否利用会计政策和会计估计及其变更操纵利润。主要的会计政策和会计估计包括： （1）存货购入和发出的入账基础和计价方法、周转材料与固定资产的划分标准和摊销方法等； （2）生产工艺流程、辅助生产成本和制造费用摊销方法、自制半成品与完工产品的分配方法等； （3）存货跌价准备的计提方法、可变现净值的估计方法等； | D21: 常规★ | E21: √ | F21: √ | H21: √ | J21: F2-16
A22: 6 | B22: 应对措施-实质性/非实质性分析程序 | C22: 总体分析存货构成及重要指标： （1）分析本期及前期的构成，结构比变化情况； （2）分析整体存货周转率、存货跌价准备比率等存货关键指标的本期与前期变化、与同行业公司对比情况，主要产品的存货周转率本期与前期的变化情况； | D22: 常规★ | E22: √ | H22: √ | J22: F2-18
A23: 7 | B23: 应对措施-实质性/非实质性分析程序 | C23: 分析本期各月及前期主要产品的产量与销售量情况，分析前期及本期各月主要原材料本期采购与耗用情况，分析单位成本构成及变化情况，关注是否存在异常； | D23: 常规★ | E23: √ | H23: √ | J23: F2-19 /F2-20
A24: 8 | B24: 存货程序（选择“被审计单位执行定期盘点”“存货存放在多个地点”）、LEAP应对措施-检查（存货监盘） | C24: 实施存货监盘程序： （1）初步了解存货形态、存货存放地点等，初步确定监盘方式、时间和范围； （2）参与被审计单位存货盘点规划完成存货盘点问卷，获取盘点计划，评价被审计单位盘点内部控制、程序和指令是否恰当； （3）确定监盘时间、范围、人员、重点关注事项等，编制存货监盘计划； （4）观察被审计单位制定的盘点程序的执行情况，并检查存货的状况，是否存在过时、毁损或陈旧的存货； （5）执行抽盘，从存货盘点记录中选取项目追查至存货实物，以及从存货实物中选取项目追查至盘点记录，将抽盘结果与账面核对； （6）评价存货盘点结果，完成存货监盘小结。 | D24: 常规★ | E24: √ | F24: √ | G24: √ | H24: √ | J24: F2-21A
A25: 9 | B25: 存货程序（选择“被审计单位执行定期盘点”“存货存放在多个地点”）、LEAP应对措施-检查（存货监盘） | C25: 如果在存货盘点现场实施存货监盘不可行，实施替代审计程序。如果不能实施替代审计程序或实施替代审计程序无法获取有关存货的存在和状况的充分、适当的审计证据，考虑对审计意见的影响。替代程序主要包括： （1）检查进货交易凭证或生产记录以及其他相关资料； （2）检查资产负债表日后发生的销货交易凭证； （3）向顾客或供应商函证。 | D25: 常规★ | E25: √ | F25: √ | G25: √ | H25: √
A26: 10 | B26: 存货程序（选择“被审计单位存在由第三方保管或控制的存货”） | C26: 如果由第三方保管或控制的存货对财务报表是重要的，考虑： （1）现场盘点第三方保管或控制的存货； （2）向持有被审计单位存货的第三方函证存货的数量和状况； （3）实施检查或其他适合具体情况的审计程序。 | D26: 备选 | E26: √ | F26: √ | G26: √ | H26: √
A27: 11 | B27: 存货程序（选择“被审计单位存在寄售货物”） | C27: 如果存在他人委托被审计单位代售的商品（寄售商品），考虑： （1）该寄售商品未包含在被审计单位存货盘点范围内； （2）向寄售品所有者函证寄售商品； （3）检查受托代销的商品临近期末的重大销售，账务处理是否正确。 | D27: 备选 | E27: √ | F27: √ | G27: √ | H27: √
A28: 12 | B28: 应对措施-检查 | C28: 结合存货监盘程序，执行存货入库截止性测试： （1）从存货明细账借方发生额中抽取资产负债表日前后若干天、一定金额以上的凭证，与入库记录（如入库单，或购货发票，或运输单据）核对，以确定存货入库被记录在正确的会计期间； （2）从入库记录（如入库单或购货发票或运输单据）或其他表明所有权转移的单据中选取资产负债表日前后若干天、一定金额以上的凭据，与存货明细账的借方发生额进行核对，以确定存货人库被记录在正确的会计期间； （3）检查入库记录编号是否与执行存货监盘程序中获取的截止性资料编号存在冲突。 | D28: 常规★ | E28: √ | F28: √ | J28: F2-29 /F2-30
A29: 13 | B29: 应对措施-检查 | C29: 结合存货监盘、产成品结合营业收入截止程序，执行存货出库截止性测试： （1）从存货明细账贷方发生额中抽取资产负债表日前后若干张、一定金额以上的凭证，与出库记录（如出库单、原材料领用单）核对，以确定存货出库被记录在正确的会计期间； （2）从出库记录（如出库单、原材料领用单）中选取资产负债表日前后若干张、一定金额以上的凭据，与存货明细账的贷方发生额进行核对，以确定存货出库被记录在正确的会计期间； （3）检查出库记录编号是否与执行存货监盘程序中获取的截止性资料编号存在冲突。 | D29: 常规★ | E29: √ | F29: √ | J29: F2-31 /F2-32
A30: 14 | B30: 应对措施-检查 | C30: 采用恰当的抽样方法，从原材料、外购库存商品明细表中选择样本，检查入库单等支持性证据，确认会计处理是否正确。 | D30: 常规★ | E30: √ | G30: √ | H30: √ | J30: F2-33
A31: 15 | B31: 应对措施-检查 | C31: 采用恰当的抽样方法，从原材料发出明细账中选择样本，检查材料发出及领用的原始凭证，检查领料单的签发是否经过授权批准，手续是否齐全，会计处理是否正确。 | D31: 常规★ | E31: √ | F31: √ | H31: √ | J31: F2-34
A32: 16 | B32: 存货程序（存货成本） | C32: 采用恰当的抽样方法，从存货明细表中选择样本测试存货计价： （1）对原材料等外购存货，基于被审计单位原材料计价方法(如先进先出法，加权平均法等)，结合原材料的历史购买成本，测试其账面入库、出库、结存金额是否准确。 （2）对产成品，基于被审计单位产成品计价方法(如先进先出法，加权平均法等)，结合产成品入库成本，测试其账面入库、出库、结存金额是否准确。 | D32: 常规★ | H32: √ | J32: F2-38 /F2-39
A33: 17 | B33: 存货程序（存货成本） | C33: 在以标准成本计价时，应考虑标准成本的合理性并测试实际成本与标准成本差异的归集和分摊： （1）评价标准成本的合理性，检查标准成本在本期有无重大变动； （2）对直接材料结合采购等入库检查，测试材料成本差异的构成和分摊是否合理、正确；评估人工和间接费用分配方法和假设的合理性；评价标准制造费用中所包含的成本的适当性； （3）结合产成品成本计算单等，检查产成品实际价格与标准成本的差异分配是否正确； | D33: 备选 | H33: √ | J33: F2-40
A34: 18 | B34: 存货程序（存货成本） | C34: 检查生产成本/制造费用归集、分配是否合理、正确： （1）取得本期各月及前期的存货成本构成（料、工、费）明细情况，评价本期发生额和余额的总体合理性，将直接材料与材料耗用、直接人工与工资分配表等核对一致，检查生产成本分配方法，以及在完工产品与在产品间分配是否合理、一致、正确； （2）分析主要产品本期与上期的单位成本的变化，是否存在异常波动； （3）分析本期各月及前期产品计入生产成本的直接人工成本、单位人工成本情况，关注直接人工分摊是否合理，是否存在异常； （4）取得本期各月及前期制造费用明细情况，将资产折旧与折旧分配表、资产摊销与各项资产摊销分配表等核对一致，检查制造费用分配方法是否合理、适当，制造费用截止是否正确； （4）抽取成本计算单，检查直接材料、直接人工及制造费用的计算和分配是否正确。 | D34: 常规★ | H34: √ | J34: F2-41 /F2-20 /F2-42 /F2-43 /F2-44
A35: 19 | C35: 如果存在委托加工物资： （1）选取委托加工合同，检查有关发料凭证、加工费、运费结算凭证，关注所有权归属，核对其计费、计价是否正确，会计处理是否及时、正确； （2）检查加工完成物资的验收入库手续是否齐全，会计处理是否正确； （3）函证委托加工物资，必要时现场查看或利用其他注册会计师的工作。 | D35: 备选 | E35: √ | F35: √ | G35: √ | H35: √ | J35: F2-35 /F0
A36: 20 | B36: 存货程序（存货成本） | C36: 如果存在劳务成本： （1）选取劳务成本项目，检查有关劳务合同、劳务费结算等原始凭证，关注是否存在资本性支出，核对会计处理是否正确； （2）结合成本计算单等，检查劳务成本的分配是否合理、正确； （3）必要时对劳务成本实施截止测试，以确定被记录在正确的会计期间。 | D36: 备选 | H36: √
A37: 21 | B37: 存货程序（存货成本） | C37: 对于计入生产成本的借款费用，结合对长短期借款、应付债券或长期应付款等付息债务的审计，检查借款费用资本化的计算方法和资本化金额以及会计处理是否正确。 | D37: 备选 | H37: √
A38: 22 | B38: 存货程序（选择“期末存在在途货物”） | C38: 如果存在材料采购或在途物资： （1）选取期末物资采购或在途物资，检查有关原始单据； （2）抽取资产负债表日前后若干天物资采购或在途物资增减变动的有关账簿记录和收料报告单等资料，以确定被记录在正确的会计期间； （3）如采用标准成本计价，检查物资采购有关的材料成本差异归集和分配是否正确。 | D38: 备选 | E38: √ | F38: √ | G38: √ | H38: √
A39: 23 | C39: 如果存在周转材料（低值易耗品、包装物）： （1）检查周转材料的入库和领用的手续是否齐全，关注是否存在包装物押金，会计处理是否正确； （2）检查周转材料摊销方法是否正确，前后期是否一致； | D39: 备选 | E39: √ | F39: √ | G39: √ | H39: √
A40: 24 | B40: 应对措施-检查 | C40: 结合营业成本审计，检查发出库存商品的品种、数量和实际成本与“主营业务成本”是否相符。 | D40: 常规★ | E40: √ | F40: √ | H40: √ | J40: F5-6
...

Sheet 存货审定表F2-1
A1: 致同会计师事务所
A2: 存货及跌价准备审定表
A3: =[1]底稿目录!A2 -> 被审计单位： | B3: =[1]底稿目录!A4 -> 编制人： | C3: =[1]底稿目录!A5 -> 编制日期： | E3: 索引号： | F3: =[1]底稿目录!F4 -> F2-1
A4: =[1]底稿目录!A3 -> 截止日：202X年12月21日 | B4: =[1]底稿目录!A6 -> 复核人： | C4: =[1]底稿目录!A7 -> 复核日期： | E4: 页 次：
A5: 项目 | B5: 期初数 | C5: 本期增加 | D5: 本期减少 | E5: 期末数 | F5: 索引
A6: 一、原值
A7: 未审数 | B7: =SUM(B8:B20) -> 0 | C7: =SUM(C8:C20) -> 0 | D7: =SUM(D8:D20) -> 0 | E7: =SUM(E8:E20) -> 0
A8: ='[1]明细汇总表F2-2'!A17 -> 原材料 | B8: ='[1]明细汇总表F2-2'!B17 -> 0 | C8: ='[1]明细汇总表F2-2'!C17 -> 0 | D8: ='[1]明细汇总表F2-2'!D17 -> 0 | E8: =B8+C8-D8 -> 0
A9: ='[1]明细汇总表F2-2'!A18 -> 材料采购/在途物资 | B9: ='[1]明细汇总表F2-2'!B18 -> 0 | C9: ='[1]明细汇总表F2-2'!C18 -> 0 | D9: ='[1]明细汇总表F2-2'!D18 -> 0 | E9: =B9+C9-D9 -> 0
A10: ='[1]明细汇总表F2-2'!A19 -> 周转材料/低值易耗品/包装物 | B10: ='[1]明细汇总表F2-2'!B19 -> 0 | C10: ='[1]明细汇总表F2-2'!C19 -> 0 | D10: ='[1]明细汇总表F2-2'!D19 -> 0 | E10: =B10+C10-D10 -> 0
A11: ='[1]明细汇总表F2-2'!A20 -> 在产品 | B11: ='[1]明细汇总表F2-2'!B20 -> 0 | C11: ='[1]明细汇总表F2-2'!C20 -> 0 | D11: ='[1]明细汇总表F2-2'!D20 -> 0 | E11: =B11+C11-D11 -> 0
A12: ='[1]明细汇总表F2-2'!A21 -> 自制半成品 | B12: ='[1]明细汇总表F2-2'!B21 -> 0 | C12: ='[1]明细汇总表F2-2'!C21 -> 0 | D12: ='[1]明细汇总表F2-2'!D21 -> 0 | E12: =B12+C12-D12 -> 0
A13: ='[1]明细汇总表F2-2'!A22 -> 委托加工物资 | B13: ='[1]明细汇总表F2-2'!B22 -> 0 | C13: ='[1]明细汇总表F2-2'!C22 -> 0 | D13: ='[1]明细汇总表F2-2'!D22 -> 0 | E13: =B13+C13-D13 -> 0
A14: ='[1]明细汇总表F2-2'!A23 -> 库存商品 | B14: ='[1]明细汇总表F2-2'!B23 -> 0 | C14: ='[1]明细汇总表F2-2'!C23 -> 0 | D14: ='[1]明细汇总表F2-2'!D23 -> 0 | E14: =B14+C14-D14 -> 0
A15: ='[1]明细汇总表F2-2'!A24 -> 发出商品 | B15: ='[1]明细汇总表F2-2'!B24 -> 0 | C15: ='[1]明细汇总表F2-2'!C24 -> 0 | D15: ='[1]明细汇总表F2-2'!D24 -> 0 | E15: =B15+C15-D15 -> 0
A16: ='[1]明细汇总表F2-2'!A25 -> 开发产品 | B16: ='[1]明细汇总表F2-2'!B25 -> 0 | C16: ='[1]明细汇总表F2-2'!C25 -> 0 | D16: ='[1]明细汇总表F2-2'!D25 -> 0 | E16: =B16+C16-D16 -> 0
A17: ='[1]明细汇总表F2-2'!A26 -> 开发成本 | B17: ='[1]明细汇总表F2-2'!B26 -> 0 | C17: ='[1]明细汇总表F2-2'!C26 -> 0 | D17: ='[1]明细汇总表F2-2'!D26 -> 0 | E17: =B17+C17-D17 -> 0
A18: 合同履约成本 | B18: ='[1]明细汇总表F2-2'!B27 -> 0 | C18: ='[1]明细汇总表F2-2'!C27 -> 0 | D18: ='[1]明细汇总表F2-2'!D27 -> 0 | E18: =B18+C18-D18 -> 0
A19: ='[1]明细汇总表F2-2'!A28 -> 消耗性生物资产 | B19: ='[1]明细汇总表F2-2'!B28 -> 0 | C19: ='[1]明细汇总表F2-2'!C28 -> 0 | D19: ='[1]明细汇总表F2-2'!D28 -> 0 | E19: =B19+C19-D19 -> 0
A20: 数据资源 | B20: ='[1]明细汇总表F2-2'!B29 -> 0 | C20: ='[1]明细汇总表F2-2'!C29 -> 0 | D20: ='[1]明细汇总表F2-2'!D29 -> 0 | E20: =B20+C20-D20 -> 0
A21: 账项调整 | B21: =SUM(B22:B34) -> 0 | C21: =SUM(C22:C34) -> 0 | D21: =SUM(D22:D34) -> 0 | E21: =SUM(E22:E34) -> 0
A22: =A8 -> 原材料 | B22: ='[1]明细汇总表F2-2'!F17 -> 0 | C22: ='[1]明细汇总表F2-2'!G17 -> 0 | D22: ='[1]明细汇总表F2-2'!H17 -> 0 | E22: =B22+C22-D22 -> 0
A23: =A9 -> 材料采购/在途物资 | B23: ='[1]明细汇总表F2-2'!F18 -> 0 | C23: ='[1]明细汇总表F2-2'!G18 -> 0 | D23: ='[1]明细汇总表F2-2'!H18 -> 0 | E23: =B23+C23-D23 -> 0
A24: =A10 -> 周转材料/低值易耗品/包装物 | B24: ='[1]明细汇总表F2-2'!F19 -> 0 | C24: ='[1]明细汇总表F2-2'!G19 -> 0 | D24: ='[1]明细汇总表F2-2'!H19 -> 0 | E24: =B24+C24-D24 -> 0
A25: =A11 -> 在产品 | B25: ='[1]明细汇总表F2-2'!F20 -> 0 | C25: ='[1]明细汇总表F2-2'!G20 -> 0 | D25: ='[1]明细汇总表F2-2'!H20 -> 0 | E25: =B25+C25-D25 -> 0
A26: =A12 -> 自制半成品 | B26: ='[1]明细汇总表F2-2'!F21 -> 0 | C26: ='[1]明细汇总表F2-2'!G21 -> 0 | D26: ='[1]明细汇总表F2-2'!H21 -> 0 | E26: =B26+C26-D26 -> 0
A27: =A13 -> 委托加工物资 | B27: ='[1]明细汇总表F2-2'!F22 -> 0 | C27: ='[1]明细汇总表F2-2'!G22 -> 0 | D27: ='[1]明细汇总表F2-2'!H22 -> 0 | E27: =B27+C27-D27 -> 0
A28: =A14 -> 库存商品 | B28: ='[1]明细汇总表F2-2'!F23 -> 0 | C28: ='[1]明细汇总表F2-2'!G23 -> 0 | D28: ='[1]明细汇总表F2-2'!H23 -> 0 | E28: =B28+C28-D28 -> 0
A29: =A15 -> 发出商品 | B29: ='[1]明细汇总表F2-2'!F24 -> 0 | C29: ='[1]明细汇总表F2-2'!G24 -> 0 | D29: ='[1]明细汇总表F2-2'!H24 -> 0 | E29: =B29+C29-D29 -> 0
A30: =A16 -> 开发产品 | B30: ='[1]明细汇总表F2-2'!F25 -> 0 | C30: ='[1]明细汇总表F2-2'!G25 -> 0 | D30: ='[1]明细汇总表F2-2'!H25 -> 0 | E30: =B30+C30-D30 -> 0
A31: =A17 -> 开发成本 | B31: ='[1]明细汇总表F2-2'!F26 -> 0 | C31: ='[1]明细汇总表F2-2'!G26 -> 0 | D31: ='[1]明细汇总表F2-2'!H26 -> 0 | E31: =B31+C31-D31 -> 0
A32: =A18 -> 合同履约成本 | B32: ='[1]明细汇总表F2-2'!F27 -> 0 | C32: ='[1]明细汇总表F2-2'!G27 -> 0 | D32: ='[1]明细汇总表F2-2'!H27 -> 0 | E32: =B32+C32-D32 -> 0
A33: =A19 -> 消耗性生物资产 | B33: ='[1]明细汇总表F2-2'!F28 -> 0 | C33: ='[1]明细汇总表F2-2'!G28 -> 0 | D33: ='[1]明细汇总表F2-2'!H28 -> 0 | E33: =B33+C33-D33 -> 0
A34: 数据资源 | B34: ='[1]明细汇总表F2-2'!F29 -> 0 | C34: ='[1]明细汇总表F2-2'!G29 -> 0 | D34: ='[1]明细汇总表F2-2'!H29 -> 0 | E34: =B34+C34-D34 -> 0
A35: 审定数（原值） | B35: =SUM(B36:B48) -> 0 | C35: =SUM(C36:C48) -> 0 | D35: =SUM(D36:D48) -> 0 | E35: =SUM(E36:E48) -> 0
A36: =A8 -> 原材料 | B36: =B8+B22 -> 0 | C36: =C8+C22 -> 0 | D36: =D8+D22 -> 0 | E36: =E8+E22 -> 0
A37: =A9 -> 材料采购/在途物资 | B37: =B9+B23 -> 0 | C37: =C9+C23 -> 0 | D37: =D9+D23 -> 0 | E37: =E9+E23 -> 0
A38: =A10 -> 周转材料/低值易耗品/包装物 | B38: =B10+B24 -> 0 | C38: =C10+C24 -> 0 | D38: =D10+D24 -> 0 | E38: =E10+E24 -> 0
A39: =A11 -> 在产品 | B39: =B11+B25 -> 0 | C39: =C11+C25 -> 0 | D39: =D11+D25 -> 0 | E39: =E11+E25 -> 0
A40: =A12 -> 自制半成品 | B40: =B12+B26 -> 0 | C40: =C12+C26 -> 0 | D40: =D12+D26 -> 0 | E40: =E12+E26 -> 0
...

Sheet 附注披露信息（上市公司）
A1: 致同会计师事务所
A2: 存货附注披露信息（上市公司）
A3: =[1]底稿目录!A2 -> 被审计单位： | C3: =[1]底稿目录!A4 -> 编制人： | E3: =[1]底稿目录!A5 -> 编制日期： | G3: 索引号：
A4: =[1]底稿目录!A3 -> 截止日：202X年12月21日 | C4: =[1]底稿目录!A6 -> 复核人： | E4: =[1]底稿目录!A7 -> 复核日期： | G4: 页次：
A5: 存货附注披露信息：
A6: 存货
A7: （1）存货分类
A8: 存货种类 | B8: 期末数 | E8: 上年年末数
B9: 账面余额 | C9: 跌价准备/合同履约成本减值准备 | D9: 账面价值 | E9: 账面余额 | F9: 跌价准备/合同履约成本减值准备 | G9: 账面价值
A10: ='[1]存货审定表F2-1'!A36 -> 原材料 | B10: ='[1]存货审定表F2-1'!E36+'[1]存货审定表F2-1'!E37 -> 0 | C10: ='[1]存货审定表F2-1'!E79+'[1]存货审定表F2-1'!E80 -> 0 | D10: =B10-C10 -> 0 | E10: ='[1]存货审定表F2-1'!B36+'[1]存货审定表F2-1'!B37 -> 0 | F10: ='[1]存货审定表F2-1'!B79+'[1]存货审定表F2-1'!B80 -> 0 | G10: =E10-F10 -> 0
A11: ='[1]存货审定表F2-1'!A39 -> 在产品 | B11: ='[1]存货审定表F2-1'!E39+'[1]存货审定表F2-1'!E40 -> 0 | C11: ='[1]存货审定表F2-1'!E82+'[1]存货审定表F2-1'!E83 -> 0 | D11: =B11-C11 -> 0 | E11: ='[1]存货审定表F2-1'!B39+'[1]存货审定表F2-1'!B40 -> 0 | F11: ='[1]存货审定表F2-1'!B82+'[1]存货审定表F2-1'!B83 -> 0 | G11: =E11-F11 -> 0
A12: ='[1]存货审定表F2-1'!A41 -> 委托加工物资 | B12: ='[1]存货审定表F2-1'!E41 -> 0 | C12: ='[1]存货审定表F2-1'!E84 -> 0 | D12: =B12-C12 -> 0 | E12: ='[1]存货审定表F2-1'!B41 -> 0 | F12: ='[1]存货审定表F2-1'!B84 -> 0 | G12: =E12-F12 -> 0
A13: ='[1]存货审定表F2-1'!A42 -> 库存商品 | B13: ='[1]存货审定表F2-1'!E42 -> 0 | C13: ='[1]存货审定表F2-1'!E85 -> 0 | D13: =B13-C13 -> 0 | E13: ='[1]存货审定表F2-1'!B42 -> 0 | F13: ='[1]存货审定表F2-1'!B85 -> 0 | G13: =E13-F13 -> 0
A14: ='[1]存货审定表F2-1'!A43 -> 发出商品 | B14: ='[1]存货审定表F2-1'!E43 -> 0 | C14: ='[1]存货审定表F2-1'!E86 -> 0 | D14: =B14-C14 -> 0 | E14: ='[1]存货审定表F2-1'!B43 -> 0 | F14: ='[1]存货审定表F2-1'!B86 -> 0 | G14: =E14-F14 -> 0
A15: 周转材料 | B15: ='[1]存货审定表F2-1'!E38 -> 0 | C15: ='[1]存货审定表F2-1'!E81 -> 0 | D15: =B15-C15 -> 0 | E15: ='[1]存货审定表F2-1'!B38 -> 0 | F15: ='[1]存货审定表F2-1'!B81 -> 0 | G15: =E15-F15 -> 0
A16: 合同履约成本 | B16: ='[1]存货审定表F2-1'!E46 -> 0 | C16: ='[1]存货审定表F2-1'!E89 -> 0 | D16: =B16-C16 -> 0 | E16: ='[1]存货审定表F2-1'!B46 -> 0 | F16: ='[1]存货审定表F2-1'!B89 -> 0 | G16: =E16-F16 -> 0
A17: ='[1]存货审定表F2-1'!A47 -> 消耗性生物资产 | B17: ='[1]存货审定表F2-1'!E47 -> 0 | C17: ='[1]存货审定表F2-1'!E90 -> 0 | D17: =B17-C17 -> 0 | E17: ='[1]存货审定表F2-1'!B47 -> 0 | F17: ='[1]存货审定表F2-1'!B90 -> 0 | G17: =E17-F17 -> 0
A18: 数据资源 | B18: ='[1]存货审定表F2-1'!E48 -> 0 | C18: ='[1]存货审定表F2-1'!E91 -> 0 | D18: =B18-C18 -> 0 | E18: ='[1]存货审定表F2-1'!B48 -> 0 | F18: ='[1]存货审定表F2-1'!B91 -> 0 | G18: =E18-F18 -> 0
A19: 合 计 | B19: =SUM(B10:B18) -> 0 | C19: =SUM(C10:C18) -> 0 | D19: =SUM(D10:D18) -> 0 | E19: =SUM(E10:E18) -> 0 | F19: =SUM(F10:F18) -> 0 | G19: =SUM(G10:G18) -> 0
A20: （注：根据企业具体情况分类，房地产开发企业应增加“开发成本”、“开发产品”等种类）
A21: （2）存货跌价准备及合同履约成本减值准备
A22: 存货种类 | B22: 期初余额 | C22: 本期增加 | E22: 本期减少 | G22: 期末余额
C23: 计提 | D23: 其他 | E23: 转回或转销 | F23: 其他
A24: =A10 -> 原材料 | B24: ='[1]存货审定表F2-1'!B79+'[1]存货审定表F2-1'!B80 -> 0 | C24: ='[1]明细汇总表F2-2'!K35+'[1]明细汇总表F2-2'!K36 -> 0 | D24: ='[1]明细汇总表F2-2'!L35+'[1]明细汇总表F2-2'!L36 -> 0 | E24: ='[1]明细汇总表F2-2'!N35+'[1]明细汇总表F2-2'!O35+'[1]明细汇总表F2-2'!N36+'[1]明细汇总表F2-2'!O36 -> 0 | F24: ='[1]明细汇总表F2-2'!P35+'[1]明细汇总表F2-2'!P36 -> 0 | G24: =B24+C24+D24-E24-F24 -> 0
A25: =A11 -> 在产品 | B25: ='[1]存货审定表F2-1'!B82+'[1]存货审定表F2-1'!B83 -> 0 | C25: ='[1]明细汇总表F2-2'!K38+'[1]明细汇总表F2-2'!K39 -> 0 | D25: ='[1]明细汇总表F2-2'!L38+'[1]明细汇总表F2-2'!L39 -> 0 | E25: ='[1]明细汇总表F2-2'!N38+'[1]明细汇总表F2-2'!O38+'[1]明细汇总表F2-2'!N39+'[1]明细汇总表F2-2'!O39 -> 0 | F25: ='[1]明细汇总表F2-2'!P38+'[1]明细汇总表F2-2'!P39 -> 0 | G25: =B25+C25+D25-E25-F25 -> 0
A26: =A12 -> 委托加工物资 | B26: ='[1]存货审定表F2-1'!B84 -> 0 | C26: ='[1]明细汇总表F2-2'!K40 -> 0 | D26: ='[1]明细汇总表F2-2'!L40 -> 0 | E26: ='[1]明细汇总表F2-2'!N40+'[1]明细汇总表F2-2'!O40 -> 0 | F26: ='[1]明细汇总表F2-2'!P40 -> 0 | G26: =B26+C26+D26-E26-F26 -> 0
A27: =A13 -> 库存商品 | B27: ='[1]存货审定表F2-1'!B85 -> 0 | C27: ='[1]明细汇总表F2-2'!K41 -> 0 | D27: ='[1]明细汇总表F2-2'!L41 -> 0 | E27: ='[1]明细汇总表F2-2'!N41+'[1]明细汇总表F2-2'!O41 -> 0 | F27: ='[1]明细汇总表F2-2'!P41 -> 0 | G27: =B27+C27+D27-E27-F27 -> 0
A28: =A14 -> 发出商品 | B28: ='[1]存货审定表F2-1'!B86 -> 0 | C28: ='[1]明细汇总表F2-2'!K42 -> 0 | D28: ='[1]明细汇总表F2-2'!L42 -> 0 | E28: ='[1]明细汇总表F2-2'!N42+'[1]明细汇总表F2-2'!O42 -> 0 | F28: ='[1]明细汇总表F2-2'!P42 -> 0 | G28: =B28+C28+D28-E28-F28 -> 0
A29: =A15 -> 周转材料 | B29: ='[1]存货审定表F2-1'!B81 -> 0 | C29: ='[1]明细汇总表F2-2'!K37 -> 0 | D29: ='[1]明细汇总表F2-2'!L37 -> 0 | E29: ='[1]明细汇总表F2-2'!N37+'[1]明细汇总表F2-2'!O37 -> 0 | F29: ='[1]明细汇总表F2-2'!P37 -> 0 | G29: =B29+C29+D29-E29-F29 -> 0
A30: 合同履约成本 | B30: ='[1]存货审定表F2-1'!B89 -> 0 | C30: ='[1]明细汇总表F2-2'!K46 -> 0 | D30: ='[1]明细汇总表F2-2'!L46 -> 0 | E30: ='[1]明细汇总表F2-2'!N46+'[1]明细汇总表F2-2'!O46 -> 0 | F30: ='[1]明细汇总表F2-2'!P46 -> 0 | G30: =B30+C30+D30-E30-F30 -> 0
A31: =A17 -> 消耗性生物资产 | B31: ='[1]存货审定表F2-1'!B90 -> 0 | C31: ='[1]明细汇总表F2-2'!K46 -> 0 | D31: ='[1]明细汇总表F2-2'!L46 -> 0 | E31: ='[1]明细汇总表F2-2'!N46+'[1]明细汇总表F2-2'!O46 -> 0 | F31: ='[1]明细汇总表F2-2'!P46 -> 0 | G31: =B31+C31+D31-E31-F31 -> 0
A32: 数据资源 | B32: ='[1]存货审定表F2-1'!B91 -> 0 | C32: ='[1]明细汇总表F2-2'!K47 -> 0 | D32: ='[1]明细汇总表F2-2'!L47 -> 0 | E32: ='[1]明细汇总表F2-2'!N47+'[1]明细汇总表F2-2'!O47 -> 0 | F32: ='[1]明细汇总表F2-2'!P47 -> 0 | G32: =B32+C32+D32-E32-F32 -> 0
A33: 合 计 | B33: =SUM(B24:B32) -> 0 | C33: =SUM(C24:C32) -> 0 | D33: =SUM(D24:D32) -> 0 | E33: =SUM(E24:E32) -> 0 | F33: =SUM(F24:F32) -> 0 | G33: =SUM(G24:G32) -> 0
A34: 存货跌价准备及合同履约成本减值准备（续）
A35: 存货种类 | B35: 确定可变现净值/剩余对价与将要发生的成本的具体依据 | C35: 本期转回或转销存货跌价准备/合同履约成本减值准备的原因
A36: =A24 -> 原材料 | B36: ='[1]明细汇总表F2-2'!I53+'[1]明细汇总表F2-2'!I54 -> 0 | C36: ='[1]明细汇总表F2-2'!J53+'[1]明细汇总表F2-2'!J54 -> 0
A37: =A25 -> 在产品 | B37: ='[1]明细汇总表F2-2'!I56+'[1]明细汇总表F2-2'!I57 -> 0 | C37: ='[1]明细汇总表F2-2'!J56+'[1]明细汇总表F2-2'!J57 -> 0
A38: =A26 -> 委托加工物资 | B38: ='[1]明细汇总表F2-2'!I58 -> 0 | C38: ='[1]明细汇总表F2-2'!J58 -> 0
A39: =A27 -> 库存商品 | B39: ='[1]明细汇总表F2-2'!I59 -> 0 | C39: ='[1]明细汇总表F2-2'!J59 -> 0
A40: =A28 -> 发出商品 | B40: ='[1]明细汇总表F2-2'!I60 -> 0 | C40: ='[1]明细汇总表F2-2'!J60 -> 0
...

Sheet 附注披露信息（国企）
A1: 致同会计师事务所
A2: 存货附注披露信息（国企）
A3: =[1]底稿目录!A2 -> 被审计单位： | B3: =[1]底稿目录!A4 -> 编制人： | E3: =[1]底稿目录!A5 -> 编制日期： | H3: 索引号：
A4: =[1]底稿目录!A3 -> 截止日：202X年12月21日 | B4: =[1]底稿目录!A6 -> 复核人： | E4: =[1]底稿目录!A7 -> 复核日期： | H4: 页次：
A5: 存货附注披露信息：
A6: （1）存货分类
A7: 项 目 | B7: 期末数 | E7: 期初数
B8: 账面余额 | C8: 跌价准备/合同履约成本减值准备 | D8: 账面价值 | E8: 账面余额 | F8: 跌价准备/合同履约成本减值准备 | G8: 账面价值
A9: ='[1]存货审定表F2-1'!A94 -> 原材料 | B9: ='[1]存货审定表F2-1'!E36+'[1]存货审定表F2-1'!E37 -> 0 | C9: ='[1]存货审定表F2-1'!E79+'[1]存货审定表F2-1'!E80 -> 0 | D9: =B9-C9 -> 0 | E9: ='[1]存货审定表F2-1'!B36+'[1]存货审定表F2-1'!B37 -> 0 | F9: ='[1]存货审定表F2-1'!B79+'[1]存货审定表F2-1'!B80 -> 0 | G9: =E9-F9 -> 0
A10: 自制半成品及在产品 | B10: ='[1]存货审定表F2-1'!E39+'[1]存货审定表F2-1'!E40+'[1]存货审定表F2-1'!E45 -> 0 | C10: ='[1]存货审定表F2-1'!E82+'[1]存货审定表F2-1'!E83+'[1]存货审定表F2-1'!E88 -> 0 | D10: =B10-C10 -> 0 | E10: ='[1]存货审定表F2-1'!B39+'[1]存货审定表F2-1'!B40+'[1]存货审定表F2-1'!B45 -> 0 | F10: ='[1]存货审定表F2-1'!B82+'[1]存货审定表F2-1'!B83+'[1]存货审定表F2-1'!B88 -> 0 | G10: =E10-F10 -> 0
A11: 其中：开发成本 | B11: ='[1]存货审定表F2-1'!E45 -> 0 | C11: ='[1]存货审定表F2-1'!E88 -> 0 | D11: =B11-C11 -> 0 | E11: ='[1]存货审定表F2-1'!B45 -> 0 | F11: ='[1]存货审定表F2-1'!B88 -> 0 | G11: =E11-F11 -> 0
A12: ='[1]存货审定表F2-1'!A99 -> 委托加工物资 | B12: ='[1]存货审定表F2-1'!E41 -> 0 | C12: ='[1]存货审定表F2-1'!E84 -> 0 | D12: =B12-C12 -> 0 | E12: ='[1]存货审定表F2-1'!B41 -> 0 | F12: ='[1]存货审定表F2-1'!B84 -> 0 | G12: =E12-F12 -> 0
A13: 库存商品（产成品） | B13: ='[1]存货审定表F2-1'!E42+'[1]存货审定表F2-1'!E44 -> 0 | C13: ='[1]存货审定表F2-1'!E85+'[1]存货审定表F2-1'!E87 -> 0 | D13: =B13-C13 -> 0 | E13: ='[1]存货审定表F2-1'!B42+'[1]存货审定表F2-1'!B44 -> 0 | F13: ='[1]存货审定表F2-1'!B85+'[1]存货审定表F2-1'!B87 -> 0 | G13: =E13-F13 -> 0
A14: 其中：开发产品 | B14: ='[1]存货审定表F2-1'!E44 -> 0 | C14: ='[1]存货审定表F2-1'!E87 -> 0 | D14: =B14-C14 -> 0 | E14: ='[1]存货审定表F2-1'!B44 -> 0 | F14: ='[1]存货审定表F2-1'!B87 -> 0 | G14: =E14-F14 -> 0
A15: 周转材料（包装物、低值易耗品等） | B15: ='[1]存货审定表F2-1'!E38 -> 0 | C15: ='[1]存货审定表F2-1'!E81 -> 0 | D15: =B15-C15 -> 0 | E15: ='[1]存货审定表F2-1'!B38 -> 0 | F15: ='[1]存货审定表F2-1'!B81 -> 0 | G15: =E15-F15 -> 0
A16: ='[1]存货审定表F2-1'!A101 -> 发出商品 | B16: ='[1]存货审定表F2-1'!E43 -> 0 | C16: ='[1]存货审定表F2-1'!E86 -> 0 | D16: =B16-C16 -> 0 | E16: ='[1]存货审定表F2-1'!B43 -> 0 | F16: ='[1]存货审定表F2-1'!B86 -> 0 | G16: =E16-F16 -> 0
A17: ='[1]存货审定表F2-1'!A105 -> 消耗性生物资产 | B17: ='[1]存货审定表F2-1'!E47 -> 0 | C17: ='[1]存货审定表F2-1'!E90 -> 0 | D17: =B17-C17 -> 0 | E17: ='[1]存货审定表F2-1'!B47 -> 0 | F17: ='[1]存货审定表F2-1'!B90 -> 0 | G17: =E17-F17 -> 0
A18: 合同履约成本 | B18: ='[1]存货审定表F2-1'!E46 -> 0 | C18: ='[1]存货审定表F2-1'!E89 -> 0 | D18: =B18-C18 -> 0 | E18: ='[1]存货审定表F2-1'!B46 -> 0 | F18: ='[1]存货审定表F2-1'!B89 -> 0 | G18: =E18-F18 -> 0
A19: 数据资源 | B19: ='[1]存货审定表F2-1'!E48 -> 0 | C19: ='[1]存货审定表F2-1'!E91 -> 0 | D19: =B19-C19 -> 0 | E19: ='[1]存货审定表F2-1'!B48 -> 0 | F19: ='[1]存货审定表F2-1'!B91 -> 0 | G19: =E19-F19 -> 0
A20: 其他
A21: 其中：尚未开发的土地储备(由房地产开发企业填列）
A22: 合 计 | B22: =SUM(B9:B21)-B11-B14-B21 -> 0 | C22: =SUM(C9:C21)-C11-C14-C21 -> 0 | D22: =SUM(D9:D21)-D11-D14-D21 -> 0 | E22: =SUM(E9:E21)-E11-E14-E21 -> 0 | F22: =SUM(F9:F21)-F11-F14-F21 -> 0 | G22: =SUM(G9:G21)-G11-G14-G21 -> 0
A23: （注：其他项中应说明房地产企业土地储备的情况，包括土地储备的面积、本期增加及土地储备年末余额。）
A24: （2）存货跌价准备及合同履约成本减值准备
A25: 存货种类 | B25: 期初数 | C25: 本期增加 | E25: 本期减少 | H25: 期末数
C26: 计提 | D26: 其他 | E26: 转回 | F26: 转销 | G26: 其他
A27: =A9 -> 原材料 | B27: ='[1]明细汇总表F2-2'!I35+'[1]明细汇总表F2-2'!I36 -> 0 | C27: ='[1]明细汇总表F2-2'!K35+'[1]明细汇总表F2-2'!K36 -> 0 | D27: ='[1]明细汇总表F2-2'!L35+'[1]明细汇总表F2-2'!L36 -> 0 | E27: ='[1]明细汇总表F2-2'!N35+'[1]明细汇总表F2-2'!N36 -> 0 | F27: ='[1]明细汇总表F2-2'!O35+'[1]明细汇总表F2-2'!O36 -> 0 | G27: ='[1]明细汇总表F2-2'!P35+'[1]明细汇总表F2-2'!P36 -> 0 | H27: =B27+C27+D27-E27-F27-G27 -> 0
A28: =A10 -> 自制半成品及在产品 | B28: ='[1]明细汇总表F2-2'!I38+'[1]明细汇总表F2-2'!I39+'[1]明细汇总表F2-2'!I44 -> 0 | C28: ='[1]明细汇总表F2-2'!K38+'[1]明细汇总表F2-2'!K39+'[1]明细汇总表F2-2'!K44 -> 0 | D28: ='[1]明细汇总表F2-2'!L38+'[1]明细汇总表F2-2'!L39+'[1]明细汇总表F2-2'!L44 -> 0 | E28: ='[1]明细汇总表F2-2'!N38+'[1]明细汇总表F2-2'!N39+'[1]明细汇总表F2-2'!N44 -> 0 | F28: ='[1]明细汇总表F2-2'!O38+'[1]明细汇总表F2-2'!O39+'[1]明细汇总表F2-2'!O44 -> 0 | G28: ='[1]明细汇总表F2-2'!P38+'[1]明细汇总表F2-2'!P39+'[1]明细汇总表F2-2'!P44 -> 0 | H28: =B28+C28+D28-E28-F28-G28 -> 0
A29: =A11 -> 其中：开发成本 | B29: ='[1]明细汇总表F2-2'!I44 -> 0 | C29: ='[1]明细汇总表F2-2'!K44 -> 0 | D29: ='[1]明细汇总表F2-2'!L44 -> 0 | E29: ='[1]明细汇总表F2-2'!N44 -> 0 | F29: ='[1]明细汇总表F2-2'!O44 -> 0 | G29: ='[1]明细汇总表F2-2'!P44 -> 0 | H29: =B29+C29+D29-E29-F29-G29 -> 0
A30: =A12 -> 委托加工物资 | B30: ='[1]明细汇总表F2-2'!I40 -> 0 | C30: ='[1]明细汇总表F2-2'!K40 -> 0 | D30: ='[1]明细汇总表F2-2'!L40 -> 0 | E30: ='[1]明细汇总表F2-2'!N40 -> 0 | F30: ='[1]明细汇总表F2-2'!O40 -> 0 | G30: ='[1]明细汇总表F2-2'!P40 -> 0 | H30: =B30+C30+D30-E30-F30-G30 -> 0
A31: =A13 -> 库存商品（产成品） | B31: ='[1]明细汇总表F2-2'!I41 -> 0 | C31: ='[1]明细汇总表F2-2'!K41 -> 0 | D31: ='[1]明细汇总表F2-2'!L41 -> 0 | E31: ='[1]明细汇总表F2-2'!N41 -> 0 | F31: ='[1]明细汇总表F2-2'!O41 -> 0 | G31: ='[1]明细汇总表F2-2'!P41 -> 0 | H31: =B31+C31+D31-E31-F31-G31 -> 0
A32: =A14 -> 其中：开发产品 | B32: ='[1]明细汇总表F2-2'!I43 -> 0 | C32: ='[1]明细汇总表F2-2'!K43 -> 0 | D32: ='[1]明细汇总表F2-2'!L43 -> 0 | E32: ='[1]明细汇总表F2-2'!N43 -> 0 | F32: ='[1]明细汇总表F2-2'!O43 -> 0 | G32: ='[1]明细汇总表F2-2'!P43 -> 0 | H32: =B32+C32+D32-E32-F32-G32 -> 0
A33: =A15 -> 周转材料（包装物、低值易耗品等） | B33: ='[1]明细汇总表F2-2'!I37 -> 0 | C33: ='[1]明细汇总表F2-2'!K37 -> 0 | D33: ='[1]明细汇总表F2-2'!L37 -> 0 | E33: ='[1]明细汇总表F2-2'!N37 -> 0 | F33: ='[1]明细汇总表F2-2'!O37 -> 0 | G33: ='[1]明细汇总表F2-2'!P37 -> 0 | H33: =B33+C33+D33-E33-F33-G33 -> 0
A34: =A16 -> 发出商品 | B34: ='[1]明细汇总表F2-2'!I42 -> 0 | C34: ='[1]明细汇总表F2-2'!K42 -> 0 | D34: ='[1]明细汇总表F2-2'!L42 -> 0 | E34: ='[1]明细汇总表F2-2'!N42 -> 0 | F34: ='[1]明细汇总表F2-2'!O42 -> 0 | G34: ='[1]明细汇总表F2-2'!P42 -> 0 | H34: =B34+C34+D34-E34-F34-G34 -> 0
A35: =A17 -> 消耗性生物资产 | B35: ='[1]明细汇总表F2-2'!I46 -> 0 | C35: ='[1]明细汇总表F2-2'!K46 -> 0 | D35: ='[1]明细汇总表F2-2'!L46 -> 0 | E35: ='[1]明细汇总表F2-2'!N46 -> 0 | F35: ='[1]明细汇总表F2-2'!O46 -> 0 | G35: ='[1]明细汇总表F2-2'!P46 -> 0 | H35: =B35+C35+D35-E35-F35-G35 -> 0
A36: =A18 -> 合同履约成本 | B36: ='[1]明细汇总表F2-2'!I45 -> 0 | C36: ='[1]明细汇总表F2-2'!K45 -> 0 | D36: ='[1]明细汇总表F2-2'!L45 -> 0 | E36: ='[1]明细汇总表F2-2'!N45 -> 0 | F36: ='[1]明细汇总表F2-2'!O45 -> 0 | G36: ='[1]明细汇总表F2-2'!P45 -> 0 | H36: =B36+C36+D36-E36-F36-G36 -> 0
A37: 数据资源 | B37: ='[1]明细汇总表F2-2'!I47 -> 0 | C37: ='[1]明细汇总表F2-2'!K47 -> 0 | D37: ='[1]明细汇总表F2-2'!L47 -> 0 | E37: ='[1]明细汇总表F2-2'!N47 -> 0 | F37: ='[1]明细汇总表F2-2'!O47 -> 0 | G37: ='[1]明细汇总表F2-2'!P47 -> 0 | H37: =B37+C37+D37-E37-F37-G37 -> 0
A38: =A20 -> 其他
A39: 其中：尚未开发的土地储备(由房地产开发企业填列）
A40: 合 计 | B40: =SUM(B27:B39)-B29-B32-B39 -> 0 | C40: =SUM(C27:C39)-C29-C32-C39 -> 0 | D40: =SUM(D27:D39)-D29-D32-D39 -> 0 | E40: =SUM(E27:E39)-E29-E32-E39 -> 0 | F40: =SUM(F27:F39)-F29-F32-F39 -> 0 | G40: =SUM(G27:G39)-G29-G32-G39 -> 0 | H40: =SUM(H27:H39)-H29-H32-H39 -> 0
...

Sheet 明细汇总表F2-2
A1: 致同会计师事务所
A2: 存货明细汇总表
A3: =[1]底稿目录!A2 -> 被审计单位： | F3: =[1]底稿目录!A4 -> 编制人： | K3: =[1]底稿目录!A5 -> 编制日期： | P3: 索引号： | Q3: =[1]底稿目录!F7 -> F2-2
A4: =[1]底稿目录!A3 -> 截止日：202X年12月21日 | F4: =[1]底稿目录!A6 -> 复核人： | K4: =[1]底稿目录!A7 -> 复核日期： | P4: 页 次：
A5: 一、审计目标：
A6: 1.资产负债表中记录的存货是存在的，且已经记录在恰当的账户中
A7: 2.所有应记录的存货均已记录，所有应当包括在财务报表中的相关披露均已包括
A8: 3.存货以恰当的金额包括在财务报表中，与之相关的计价或分摊调整已恰当记录，相关披露已得到恰当计量和描述
A9: 二、审计过程：
A10: 1.获取或编制存货（收发存）数量金额式明细表，复核加计正确，与总账、明细账合计数核对是否相符，期初余额与上期审定期末余额是否相符；
A11: 2.抽查核对存货收发存明细账是否与仓储台账（ERP业务数据）、卡片记录相符（双向核对），存货是否及时入账，存货编号存在漏记、重复等；
A12: 3.检查存货明细表中是否有异常或负余额（包括数量为负或金额为负）的项目；
A13: 4.获取管理层编制的存货库龄分析表，检查库龄划分是否正确；检查有无长期挂账的存货，如有，应查明原因，必要时作调整。
A14: （一）原值
A15: 项目 | B15: 未审数 | F15: 期初调整 | G15: 期末调整 | I15: 审定数 | M15: 备注 | N15: 索引号
B16: 期初余额 | C16: 本期增加 | D16: 本期减少 | E16: 期末数 | G16: 本期增加 | H16: 本期减少 | I16: 期初余额 | J16: 本期增加 | K16: 本期减少 | L16: 期末数
A17: 原材料 | B17: ='[1]一、原材料明细表F2-3'!$G$25 -> 0 | C17: ='[1]一、原材料明细表F2-3'!$J$25 -> 0 | D17: ='[1]一、原材料明细表F2-3'!$M$25 -> 0 | E17: =B17+C17-D17 -> 0 | I17: =B17+F17 -> 0 | J17: =C17+G17 -> 0 | K17: =D17+H17 -> 0 | L17: =I17+J17-K17 -> 0
A18: 材料采购/在途物资 | B18: ='[1]二、材料采购、在途物资明细表F2-4'!$F$25 -> 0 | C18: ='[1]二、材料采购、在途物资明细表F2-4'!$I$25 -> 0 | D18: ='[1]二、材料采购、在途物资明细表F2-4'!$L$25 -> 0 | E18: =B18+C18-D18 -> 0 | I18: =B18+F18 -> 0 | J18: =C18+G18 -> 0 | K18: =D18+H18 -> 0 | L18: =I18+J18-K18 -> 0
A19: 周转材料/低值易耗品/包装物 | B19: ='[1]三、周转材料、低值易耗品，包装物明细表F2-5'!$G$27 -> 0 | C19: ='[1]三、周转材料、低值易耗品，包装物明细表F2-5'!$J$27 -> 0 | D19: ='[1]三、周转材料、低值易耗品，包装物明细表F2-5'!$M$27 -> 0 | E19: =B19+C19-D19 -> 0 | I19: =B19+F19 -> 0 | J19: =C19+G19 -> 0 | K19: =D19+H19 -> 0 | L19: =I19+J19-K19 -> 0
A20: 在产品 | E20: =B20+C20-D20 -> 0 | I20: =B20+F20 -> 0 | J20: =C20+G20 -> 0 | K20: =D20+H20 -> 0 | L20: =I20+J20-K20 -> 0
A21: 自制半成品 | B21: ='[1]四、自制半成品明细表F2-6'!$G$25 -> 0 | C21: ='[1]四、自制半成品明细表F2-6'!$J$25 -> 0 | D21: ='[1]四、自制半成品明细表F2-6'!$M$25 -> 0 | E21: =B21+C21-D21 -> 0 | I21: =B21+F21 -> 0 | J21: =C21+G21 -> 0 | K21: =D21+H21 -> 0 | L21: =I21+J21-K21 -> 0
A22: 委托加工物资 | E22: =B22+C22-D22 -> 0 | I22: =B22+F22 -> 0 | J22: =C22+G22 -> 0 | K22: =D22+H22 -> 0 | L22: =I22+J22-K22 -> 0
A23: 库存商品 | B23: ='[1]六、库存商品明细表F2-8'!$G$25 -> 0 | C23: ='[1]六、库存商品明细表F2-8'!$J$25 -> 0 | D23: ='[1]六、库存商品明细表F2-8'!$M$25 -> 0 | E23: =B23+C23-D23 -> 0 | I23: =B23+F23 -> 0 | J23: =C23+G23 -> 0 | K23: =D23+H23 -> 0 | L23: =I23+J23-K23 -> 0
A24: 发出商品 | B24: ='[1]七、发出商品F2-9'!$F$25 -> 0 | C24: ='[1]七、发出商品F2-9'!$I$25 -> 0 | D24: ='[1]七、发出商品F2-9'!$L$25 -> 0 | E24: =B24+C24-D24 -> 0 | I24: =B24+F24 -> 0 | J24: =C24+G24 -> 0 | K24: =D24+H24 -> 0 | L24: =I24+J24-K24 -> 0
A25: 开发产品 | B25: ='[1]八、开发产品F2-10'!$H$19 -> 0 | C25: ='[1]八、开发产品F2-10'!$O$19 -> 0 | D25: ='[1]八、开发产品F2-10'!$R$19 -> 0 | E25: =B25+C25-D25 -> 0 | F25: ='[1]八、开发产品F2-10'!I19+'[1]八、开发产品F2-10'!J19 -> 0 | G25: ='[1]八、开发产品F2-10'!V19+'[1]八、开发产品F2-10'!W19 -> 0 | I25: =B25+F25 -> 0 | J25: =C25+G25 -> 0 | K25: =D25+H25 -> 0 | L25: =I25+J25-K25 -> 0
A26: 开发成本 | B26: ='[1]九、开发成本F2-11'!G19 -> 0 | C26: ='[1]九、开发成本F2-11'!H19 -> 0 | D26: ='[1]九、开发成本F2-11'!I19 -> 0 | E26: =B26+C26-D26 -> 0 | F26: ='[1]九、开发成本F2-11'!K19+'[1]九、开发成本F2-11'!L19 -> 0 | G26: ='[1]九、开发成本F2-11'!M19+'[1]九、开发成本F2-11'!O19 -> 0 | H26: ='[1]九、开发成本F2-11'!N19+'[1]九、开发成本F2-11'!P19 -> 0 | I26: =B26+F26 -> 0 | J26: =C26+G26 -> 0 | K26: =D26+H26 -> 0 | L26: =I26+J26-K26 -> 0
A27: 合同履约成本 | B27: ='[1]十、合同履约成本F2-12'!F20 -> 0 | C27: ='[1]十、合同履约成本F2-12'!G20 -> 0 | D27: ='[1]十、合同履约成本F2-12'!H20 -> 0 | E27: =B27+C27-D27 -> 0 | I27: =B27+F27 -> 0 | J27: =C27+G27 -> 0 | K27: =D27+H27 -> 0 | L27: =I27+J27-K27 -> 0
A28: 消耗性生物资产 | B28: ='[1]十一、消耗性生物资产F2-13'!$F$25 -> 0 | C28: ='[1]十一、消耗性生物资产F2-13'!$I$25 -> 0 | D28: ='[1]十一、消耗性生物资产F2-13'!$L$25 -> 0 | E28: =B28+C28-D28 -> 0 | I28: =B28+F28 -> 0 | J28: =C28+G28 -> 0 | K28: =D28+H28 -> 0 | L28: =I28+J28-K28 -> 0
A29: 数据资源 | E29: =B29+C29-D29 -> 0 | I29: =B29+F29 -> 0 | J29: =C29+G29 -> 0 | K29: =D29+H29 -> 0 | L29: =I29+J29-K29 -> 0
A30: …… | E30: =B30+C30-D30 -> 0 | I30: =B30+F30 -> 0 | J30: =C30+G30 -> 0 | K30: =D30+H30 -> 0 | L30: =I30+J30-K30 -> 0
A31: 合计 | B31: =SUM(B17:B30) -> 0 | C31: =SUM(C17:C30) -> 0 | D31: =SUM(D17:D30) -> 0 | E31: =SUM(E17:E30) -> 0 | F31: =SUM(F17:F30) -> 0 | G31: =SUM(G17:G30) -> 0 | H31: =SUM(H17:H30) -> 0 | I31: =SUM(I17:I30) -> 0 | ... L31: =SUM(L17:L30) -> 0
A32: （二）跌价准备
A33: 项目 | B33: 未审数 | F33: 期初调整 | G33: 期末调整 | I33: 审定数
B34: 期初余额 | C34: 本期增加 | D34: 本期减少 | E34: 期末数 | G34: 本期增加 | H34: 本期减少 | I34: 期初余额 | J34: 本期增加 | K34: 其中：(1)计提 | L34: (2)其他 | M34: 本期减少 | N34: 其中：(1)转回 | O34: (2)转销 | P34: (3)其他 | Q34: 期末数
A35: 原材料 | B35: ='[1]一、原材料明细表F2-3'!G26 -> 0 | C35: ='[1]一、原材料明细表F2-3'!J26 -> 0 | D35: ='[1]一、原材料明细表F2-3'!M26 -> 0 | E35: =B35+C35-D35 -> 0 | I35: =B35+F35 -> 0 | J35: =C35+G35 -> 0 | L35: =J35-K35 -> 0 | M35: =D35+H35 -> 0 | P35: =M35-N35-O35 -> 0 | Q35: =I35+J35-M35 -> 0
A36: 材料采购/在途物资 | B36: ='[1]二、材料采购、在途物资明细表F2-4'!F26 -> 0 | C36: ='[1]二、材料采购、在途物资明细表F2-4'!I26 -> 0 | D36: ='[1]二、材料采购、在途物资明细表F2-4'!L26 -> 0 | E36: =B36+C36-D36 -> 0 | I36: =B36+F36 -> 0 | J36: =C36+G36 -> 0 | L36: =J36-K36 -> 0 | M36: =D36+H36 -> 0 | P36: =M36-N36-O36 -> 0 | Q36: =I36+J36-M36 -> 0
A37: 周转材料/低值易耗品/包装物 | B37: ='[1]三、周转材料、低值易耗品，包装物明细表F2-5'!G28 -> 0 | C37: ='[1]三、周转材料、低值易耗品，包装物明细表F2-5'!J28 -> 0 | D37: ='[1]三、周转材料、低值易耗品，包装物明细表F2-5'!M28 -> 0 | E37: =B37+C37-D37 -> 0 | I37: =B37+F37 -> 0 | J37: =C37+G37 -> 0 | L37: =J37-K37 -> 0 | M37: =D37+H37 -> 0 | P37: =M37-N37-O37 -> 0 | Q37: =I37+J37-M37 -> 0
A38: 在产品 | E38: =B38+C38-D38 -> 0 | I38: =B38+F38 -> 0 | J38: =C38+G38 -> 0 | L38: =J38-K38 -> 0 | M38: =D38+H38 -> 0 | P38: =M38-N38-O38 -> 0 | Q38: =I38+J38-M38 -> 0
A39: 自制半成品 | B39: ='[1]四、自制半成品明细表F2-6'!G26 -> 0 | C39: ='[1]四、自制半成品明细表F2-6'!J26 -> 0 | D39: ='[1]四、自制半成品明细表F2-6'!M26 -> 0 | E39: =B39+C39-D39 -> 0 | I39: =B39+F39 -> 0 | J39: =C39+G39 -> 0 | L39: =J39-K39 -> 0 | M39: =D39+H39 -> 0 | P39: =M39-N39-O39 -> 0 | Q39: =I39+J39-M39 -> 0
A40: 委托加工物资 | E40: =B40+C40-D40 -> 0 | I40: =B40+F40 -> 0 | J40: =C40+G40 -> 0 | L40: =J40-K40 -> 0 | M40: =D40+H40 -> 0 | P40: =M40-N40-O40 -> 0 | Q40: =I40+J40-M40 -> 0
...

Sheet 一、原材料明细表F2-3
A1: 致同会计师事务所
A2: 存货明细表
A3: =[1]底稿目录!A2 -> 被审计单位： | F3: =[1]底稿目录!A4 -> 编制人： | M3: =[1]底稿目录!A5 -> 编制日期： | T3: 索引号： | U3: =[1]底稿目录!F8 -> F2-3
A4: =[1]底稿目录!A3 -> 截止日：202X年12月21日 | F4: =[1]底稿目录!A6 -> 复核人： | M4: =[1]底稿目录!A7 -> 复核日期： | T4: 页次：
A5: 一、原材料明细表
A6: 存货编码 | B6: 存货名称 | C6: 规格 | D6: 单位 | E6: 期初库存 | H6: 本期购进 | K6: 本期发出 | N6: 期末结存 | Q6: 库龄 | U6: 品质状况（正常、残次、毁损、滞销等）
E7: 数量 | F7: 单价 | G7: 金额 | H7: 数量 | I7: 单价 | J7: 金额 | K7: 数量 | L7: 单价 | M7: 金额 | N7: 数量 | O7: 单价 | P7: 金额 | Q7: 1年以内 | R7: 1-2年 | S7: 2-3年 | T7: 3年以上
F9: =IF(E9=0,0,G9/E9) -> 0 | I9: =IF(H9=0,0,J9/H9) -> 0 | L9: =IF(K9=0,0,M9/K9) -> 0 | N9: =E9+H9-K9 -> 0 | O9: =IF(N9=0,0,P9/N9) -> 0 | P9: =G9+J9-M9 -> 0
F10: =IF(E10=0,0,G10/E10) -> 0 | I10: =IF(H10=0,0,J10/H10) -> 0 | L10: =IF(K10=0,0,M10/K10) -> 0 | N10: =E10+H10-K10 -> 0 | O10: =IF(N10=0,0,P10/N10) -> 0 | P10: =G10+J10-M10 -> 0
F11: =IF(E11=0,0,G11/E11) -> 0 | I11: =IF(H11=0,0,J11/H11) -> 0 | L11: =IF(K11=0,0,M11/K11) -> 0 | N11: =E11+H11-K11 -> 0 | O11: =IF(N11=0,0,P11/N11) -> 0 | P11: =G11+J11-M11 -> 0
F12: =IF(E12=0,0,G12/E12) -> 0 | I12: =IF(H12=0,0,J12/H12) -> 0 | L12: =IF(K12=0,0,M12/K12) -> 0 | N12: =E12+H12-K12 -> 0 | O12: =IF(N12=0,0,P12/N12) -> 0 | P12: =G12+J12-M12 -> 0
F13: =IF(E13=0,0,G13/E13) -> 0 | I13: =IF(H13=0,0,J13/H13) -> 0 | L13: =IF(K13=0,0,M13/K13) -> 0 | N13: =E13+H13-K13 -> 0 | O13: =IF(N13=0,0,P13/N13) -> 0 | P13: =G13+J13-M13 -> 0
F14: =IF(E14=0,0,G14/E14) -> 0 | I14: =IF(H14=0,0,J14/H14) -> 0 | L14: =IF(K14=0,0,M14/K14) -> 0 | N14: =E14+H14-K14 -> 0 | O14: =IF(N14=0,0,P14/N14) -> 0 | P14: =G14+J14-M14 -> 0
F15: =IF(E15=0,0,G15/E15) -> 0 | I15: =IF(H15=0,0,J15/H15) -> 0 | L15: =IF(K15=0,0,M15/K15) -> 0 | N15: =E15+H15-K15 -> 0 | O15: =IF(N15=0,0,P15/N15) -> 0 | P15: =G15+J15-M15 -> 0
F16: =IF(E16=0,0,G16/E16) -> 0 | I16: =IF(H16=0,0,J16/H16) -> 0 | L16: =IF(K16=0,0,M16/K16) -> 0 | N16: =E16+H16-K16 -> 0 | O16: =IF(N16=0,0,P16/N16) -> 0 | P16: =G16+J16-M16 -> 0
F17: =IF(E17=0,0,G17/E17) -> 0 | I17: =IF(H17=0,0,J17/H17) -> 0 | L17: =IF(K17=0,0,M17/K17) -> 0 | N17: =E17+H17-K17 -> 0 | O17: =IF(N17=0,0,P17/N17) -> 0 | P17: =G17+J17-M17 -> 0
F18: =IF(E18=0,0,G18/E18) -> 0 | I18: =IF(H18=0,0,J18/H18) -> 0 | L18: =IF(K18=0,0,M18/K18) -> 0 | N18: =E18+H18-K18 -> 0 | O18: =IF(N18=0,0,P18/N18) -> 0 | P18: =G18+J18-M18 -> 0
F19: =IF(E19=0,0,G19/E19) -> 0 | I19: =IF(H19=0,0,J19/H19) -> 0 | L19: =IF(K19=0,0,M19/K19) -> 0 | N19: =E19+H19-K19 -> 0 | O19: =IF(N19=0,0,P19/N19) -> 0 | P19: =G19+J19-M19 -> 0
F20: =IF(E20=0,0,G20/E20) -> 0 | I20: =IF(H20=0,0,J20/H20) -> 0 | L20: =IF(K20=0,0,M20/K20) -> 0 | N20: =E20+H20-K20 -> 0 | O20: =IF(N20=0,0,P20/N20) -> 0 | P20: =G20+J20-M20 -> 0
... F23: =IF(E23=0,0,G23/E23) -> 0 | I23: =IF(H23=0,0,J23/H23) -> 0 | L23: =IF(K23=0,0,M23/K23) -> 0 | N23: =E23+H23-K23 -> 0 | O23: =IF(N23=0,0,P23/N23) -> 0 | P23: =G23+J23-M23 -> 0
B24: …… | F24: =IF(E24=0,0,G24/E24) -> 0 | I24: =IF(H24=0,0,J24/H24) -> 0 | L24: =IF(K24=0,0,M24/K24) -> 0 | N24: =E24+H24-K24 -> 0 | O24: =IF(N24=0,0,P24/N24) -> 0 | P24: =G24+J24-M24 -> 0
B25: 合计 | E25: -- | F25: -- | G25: =SUM(G9:G24) -> 0 | H25: -- | I25: -- | J25: =SUM(J9:J24) -> 0 | K25: -- | L25: -- | M25: =SUM(M9:M24) -> 0 | N25: -- | O25: -- | P25: =SUM(P9:P24) -> 0 | Q25: =SUM(Q9:Q24) -> 0 | R25: =SUM(R9:R24) -> 0 | S25: =SUM(S9:S24) -> 0 | T25: =SUM(T9:T24) -> 0
B26: 减：存货跌价准备
B27: 原材料净额 | E27: -- | F27: -- | G27: =G25-G26 -> 0 | H27: -- | I27: -- | J27: =J25-J26 -> 0 | K27: -- | L27: -- | M27: =M25-M26 -> 0 | N27: -- | O27: -- | P27: =P25-P26 -> 0 | Q27: =Q25-Q26 -> 0 | R27: =R25-R26 -> 0 | S27: =S25-S26 -> 0 | T27: =T25-T26 -> 0
A28: 审计说明： | P28: =IF((P25-Q25-R25-S25-T25)=0,"OK","库龄与期末金额不匹配") -> OK
A29: 1.原材料计价方法： | J29: 3.原材料——**库龄较长的原因：
A30: 2.原材料本期发生重大变动的原因： | J30: 4.计提跌价准备的主要项目及原因：

Sheet 二、材料采购、在途物资明细表F2-4
A1: 致同会计师事务所
A2: 存货明细表
A3: =[1]底稿目录!A2 -> 被审计单位： | F3: =[1]底稿目录!A4 -> 编制人： | N3: =[1]底稿目录!A5 -> 编制日期： | V3: 索引号： | W3: =[1]底稿目录!F9 -> F2-4
A4: =[1]底稿目录!A3 -> 截止日：202X年12月21日 | F4: =[1]底稿目录!A6 -> 复核人： | N4: =[1]底稿目录!A7 -> 复核日期： | V4: 页次：
A5: 二、材料采购/在途物资明细表
A6: 供货单位 | B6: 采购物资名称及规格 | C6: 单位 | D6: 期初库存 | G6: 本期购进 | J6: 本期转出 | M6: 期末结存 | P6: 期后结转 | S6: 库龄 | W6: 品质状况（正常、残次、毁损、滞销等）
D7: 数量 | E7: 单价 | F7: 金额 | G7: 数量 | H7: 单价 | I7: 金额 | J7: 数量 | K7: 单价 | L7: 金额 | M7: 数量 | N7: 单价 | O7: 金额 | P7: 数量 | Q7: 单价 | R7: 金额 | S7: 1年以内 | T7: 1-2年 | U7: 2-3年 | V7: 3年以上
E9: =IF(D9=0,0,F9/D9) -> 0 | H9: =IF(G9=0,0,I9/G9) -> 0 | K9: =IF(J9=0,0,L9/J9) -> 0 | M9: =D9+G9-J9 -> 0 | N9: =IF(M9=0,0,O9/M9) -> 0 | O9: =F9+I9-L9 -> 0 | Q9: =IF(P9=0,0,R9/P9) -> 0
E10: =IF(D10=0,0,F10/D10) -> 0 | H10: =IF(G10=0,0,I10/G10) -> 0 | K10: =IF(J10=0,0,L10/J10) -> 0 | M10: =D10+G10-J10 -> 0 | N10: =IF(M10=0,0,O10/M10) -> 0 | O10: =F10+I10-L10 -> 0 | Q10: =IF(P10=0,0,R10/P10) -> 0
E11: =IF(D11=0,0,F11/D11) -> 0 | H11: =IF(G11=0,0,I11/G11) -> 0 | K11: =IF(J11=0,0,L11/J11) -> 0 | M11: =D11+G11-J11 -> 0 | N11: =IF(M11=0,0,O11/M11) -> 0 | O11: =F11+I11-L11 -> 0 | Q11: =IF(P11=0,0,R11/P11) -> 0
E12: =IF(D12=0,0,F12/D12) -> 0 | H12: =IF(G12=0,0,I12/G12) -> 0 | K12: =IF(J12=0,0,L12/J12) -> 0 | M12: =D12+G12-J12 -> 0 | N12: =IF(M12=0,0,O12/M12) -> 0 | O12: =F12+I12-L12 -> 0 | Q12: =IF(P12=0,0,R12/P12) -> 0
E13: =IF(D13=0,0,F13/D13) -> 0 | H13: =IF(G13=0,0,I13/G13) -> 0 | K13: =IF(J13=0,0,L13/J13) -> 0 | M13: =D13+G13-J13 -> 0 | N13: =IF(M13=0,0,O13/M13) -> 0 | O13: =F13+I13-L13 -> 0 | Q13: =IF(P13=0,0,R13/P13) -> 0
E14: =IF(D14=0,0,F14/D14) -> 0 | H14: =IF(G14=0,0,I14/G14) -> 0 | K14: =IF(J14=0,0,L14/J14) -> 0 | M14: =D14+G14-J14 -> 0 | N14: =IF(M14=0,0,O14/M14) -> 0 | O14: =F14+I14-L14 -> 0 | Q14: =IF(P14=0,0,R14/P14) -> 0
E15: =IF(D15=0,0,F15/D15) -> 0 | H15: =IF(G15=0,0,I15/G15) -> 0 | K15: =IF(J15=0,0,L15/J15) -> 0 | M15: =D15+G15-J15 -> 0 | N15: =IF(M15=0,0,O15/M15) -> 0 | O15: =F15+I15-L15 -> 0 | Q15: =IF(P15=0,0,R15/P15) -> 0
E16: =IF(D16=0,0,F16/D16) -> 0 | H16: =IF(G16=0,0,I16/G16) -> 0 | K16: =IF(J16=0,0,L16/J16) -> 0 | M16: =D16+G16-J16 -> 0 | N16: =IF(M16=0,0,O16/M16) -> 0 | O16: =F16+I16-L16 -> 0 | Q16: =IF(P16=0,0,R16/P16) -> 0
E17: =IF(D17=0,0,F17/D17) -> 0 | H17: =IF(G17=0,0,I17/G17) -> 0 | K17: =IF(J17=0,0,L17/J17) -> 0 | M17: =D17+G17-J17 -> 0 | N17: =IF(M17=0,0,O17/M17) -> 0 | O17: =F17+I17-L17 -> 0 | Q17: =IF(P17=0,0,R17/P17) -> 0
E18: =IF(D18=0,0,F18/D18) -> 0 | H18: =IF(G18=0,0,I18/G18) -> 0 | K18: =IF(J18=0,0,L18/J18) -> 0 | M18: =D18+G18-J18 -> 0 | N18: =IF(M18=0,0,O18/M18) -> 0 | O18: =F18+I18-L18 -> 0 | Q18: =IF(P18=0,0,R18/P18) -> 0
E19: =IF(D19=0,0,F19/D19) -> 0 | H19: =IF(G19=0,0,I19/G19) -> 0 | K19: =IF(J19=0,0,L19/J19) -> 0 | M19: =D19+G19-J19 -> 0 | N19: =IF(M19=0,0,O19/M19) -> 0 | O19: =F19+I19-L19 -> 0 | Q19: =IF(P19=0,0,R19/P19) -> 0
E20: =IF(D20=0,0,F20/D20) -> 0 | H20: =IF(G20=0,0,I20/G20) -> 0 | K20: =IF(J20=0,0,L20/J20) -> 0 | M20: =D20+G20-J20 -> 0 | N20: =IF(M20=0,0,O20/M20) -> 0 | O20: =F20+I20-L20 -> 0 | Q20: =IF(P20=0,0,R20/P20) -> 0
... E23: =IF(D23=0,0,F23/D23) -> 0 | H23: =IF(G23=0,0,I23/G23) -> 0 | K23: =IF(J23=0,0,L23/J23) -> 0 | M23: =D23+G23-J23 -> 0 | N23: =IF(M23=0,0,O23/M23) -> 0 | O23: =F23+I23-L23 -> 0 | Q23: =IF(P23=0,0,R23/P23) -> 0
A24: …… | E24: =IF(D24=0,0,F24/D24) -> 0 | H24: =IF(G24=0,0,I24/G24) -> 0 | K24: =IF(J24=0,0,L24/J24) -> 0 | M24: =D24+G24-J24 -> 0 | N24: =IF(M24=0,0,O24/M24) -> 0 | O24: =F24+I24-L24 -> 0 | Q24: =IF(P24=0,0,R24/P24) -> 0
A25: 合计 | D25: -- | E25: -- | F25: =SUM(F9:F24) -> 0 | G25: -- | H25: -- | I25: =SUM(I9:I24) -> 0 | J25: -- | K25: -- | L25: =SUM(L9:L24) -> 0 | M25: -- | N25: -- | O25: =SUM(O9:O24) -> 0 | P25: -- | Q25: -- | R25: =SUM(R9:R24) -> 0 | S25: =SUM(S9:S24) -> 0 | T25: =SUM(T9:T24) -> 0 | U25: =SUM(U9:U24) -> 0 | V25: =SUM(V9:V24) -> 0
A26: 减：存货跌价准备
A27: 材料采购/在途物资净额 | D27: -- | E27: -- | F27: =F25-F26 -> 0 | G27: -- | H27: -- | I27: =I25-I26 -> 0 | J27: -- | K27: -- | L27: =L25-L26 -> 0 | M27: -- | N27: -- | O27: =O25-O26 -> 0 | P27: -- | Q27: -- | R27: =R25-R26 -> 0 | S27: =S25-S26 -> 0 | T27: =T25-T26 -> 0 | U27: =U25-U26 -> 0 | V27: =V25-V26 -> 0
A28: 审计说明： | O28: =IF((O25-S25-T25-U25-V25)=0,"OK","库龄与期末金额不匹配") -> OK
A29: 1.在途物资资产负债表日后入库情况： | J29: 3.物资采购/在途物资——**库龄较长的原因：
A30: 2.物资采购/在途物资本期发生重大变动的原因： | J30: 4.计提跌价准备的主要项目及原因：

Sheet 三、周转材料、低值易耗品，包装物明细表F2-5
A1: 致同会计师事务所
A2: 存货明细表
A3: =[1]底稿目录!A2 -> 被审计单位： | G3: =[1]底稿目录!A4 -> 编制人： | K3: =[1]底稿目录!A5 -> 编制日期： | T3: 索引号： | U3: =[1]底稿目录!F10 -> F2-5
A4: =[1]底稿目录!A3 -> 截止日：202X年12月21日 | G4: =[1]底稿目录!A6 -> 复核人： | K4: =[1]底稿目录!A7 -> 复核日期： | T4: 页次：
A5: 三、周转材料/低值易耗品/包装物明细表
A6: 类别 | B6: 存货编码 | C6: 名称及规格 | D6: 单位 | E6: 期初库存 | H6: 本期购进 | K6: 本期发出 | N6: 期末结存 | Q6: 库龄 | U6: 品质状况（正常、残次、毁损、滞销等）
E7: 数量 | F7: 单价 | G7: 金额 | H7: 数量 | I7: 单价 | J7: 金额 | K7: 数量 | L7: 单价 | M7: 金额 | N7: 数量 | O7: 单价 | P7: 金额 | Q7: 1年以内 | R7: 1-2年 | S7: 2-3年 | T7: 3年以上
A9: （一）周转材料
F10: =IF(E10=0,0,G10/E10) -> 0 | I10: =IF(H10=0,0,J10/H10) -> 0 | L10: =IF(K10=0,0,M10/K10) -> 0 | N10: =E10+H10-K10 -> 0 | O10: =IF(N10=0,0,P10/N10) -> 0 | P10: =G10+J10-M10 -> 0
A11: … | F11: =IF(E11=0,0,G11/E11) -> 0 | I11: =IF(H11=0,0,J11/H11) -> 0 | L11: =IF(K11=0,0,M11/K11) -> 0 | N11: =E11+H11-K11 -> 0 | O11: =IF(N11=0,0,P11/N11) -> 0 | P11: =G11+J11-M11 -> 0
A12: 小计 | E12: -- | F12: -- | G12: =SUM(G10:G11) -> 0 | H12: -- | I12: -- | J12: =SUM(J10:J11) -> 0 | K12: -- | L12: -- | M12: =SUM(M10:M11) -> 0 | N12: -- | O12: -- | P12: =SUM(P10:P11) -> 0 | Q12: =SUM(Q10:Q11) -> 0 | R12: =SUM(R10:R11) -> 0 | S12: =SUM(S10:S11) -> 0 | T12: =SUM(T10:T11) -> 0
A13: （二）低值易耗品
F14: =IF(E14=0,0,G14/E14) -> 0 | I14: =IF(H14=0,0,J14/H14) -> 0 | L14: =IF(K14=0,0,M14/K14) -> 0 | N14: =E14+H14-K14 -> 0 | O14: =IF(N14=0,0,P14/N14) -> 0 | P14: =G14+J14-M14 -> 0
A15: … | F15: =IF(E15=0,0,G15/E15) -> 0 | I15: =IF(H15=0,0,J15/H15) -> 0 | L15: =IF(K15=0,0,M15/K15) -> 0 | N15: =E15+H15-K15 -> 0 | O15: =IF(N15=0,0,P15/N15) -> 0 | P15: =G15+J15-M15 -> 0
A16: 小计 | E16: -- | F16: -- | G16: =SUM(G14:G15) -> 0 | H16: -- | I16: -- | J16: =SUM(J14:J15) -> 0 | K16: -- | L16: -- | M16: =SUM(M14:M15) -> 0 | N16: -- | O16: -- | P16: =SUM(P14:P15) -> 0 | Q16: =SUM(Q14:Q15) -> 0 | R16: =SUM(R14:R15) -> 0 | S16: =SUM(S14:S15) -> 0 | T16: =SUM(T14:T15) -> 0
A17: （三）包装物
A18: 1.生产过程中用于包装产品作为产品组成部分的包装物 | F18: =IF(E18=0,0,G18/E18) -> 0 | I18: =IF(H18=0,0,J18/H18) -> 0 | L18: =IF(K18=0,0,M18/K18) -> 0 | N18: =E18+H18-K18 -> 0 | O18: =IF(N18=0,0,P18/N18) -> 0 | P18: =G18+J18-M18 -> 0
A19: … | F19: =IF(E19=0,0,G19/E19) -> 0 | I19: =IF(H19=0,0,J19/H19) -> 0 | L19: =IF(K19=0,0,M19/K19) -> 0 | N19: =E19+H19-K19 -> 0 | O19: =IF(N19=0,0,P19/N19) -> 0 | P19: =G19+J19-M19 -> 0
A20: 2.随同商品出售而不单独计价的包装物 | F20: =IF(E20=0,0,G20/E20) -> 0 | I20: =IF(H20=0,0,J20/H20) -> 0 | L20: =IF(K20=0,0,M20/K20) -> 0 | N20: =E20+H20-K20 -> 0 | O20: =IF(N20=0,0,P20/N20) -> 0 | P20: =G20+J20-M20 -> 0
A21: … | F21: =IF(E21=0,0,G21/E21) -> 0 | I21: =IF(H21=0,0,J21/H21) -> 0 | L21: =IF(K21=0,0,M21/K21) -> 0 | N21: =E21+H21-K21 -> 0 | O21: =IF(N21=0,0,P21/N21) -> 0 | P21: =G21+J21-M21 -> 0
A22: 3.随同商品出售而单独计价的包装物 | F22: =IF(E22=0,0,G22/E22) -> 0 | I22: =IF(H22=0,0,J22/H22) -> 0 | L22: =IF(K22=0,0,M22/K22) -> 0 | N22: =E22+H22-K22 -> 0 | O22: =IF(N22=0,0,P22/N22) -> 0 | P22: =G22+J22-M22 -> 0
A23: … | F23: =IF(E23=0,0,G23/E23) -> 0 | I23: =IF(H23=0,0,J23/H23) -> 0 | L23: =IF(K23=0,0,M23/K23) -> 0 | N23: =E23+H23-K23 -> 0 | O23: =IF(N23=0,0,P23/N23) -> 0 | P23: =G23+J23-M23 -> 0
A24: 4.出租或出借给购买单位使用的包装物 | F24: =IF(E24=0,0,G24/E24) -> 0 | I24: =IF(H24=0,0,J24/H24) -> 0 | L24: =IF(K24=0,0,M24/K24) -> 0 | N24: =E24+H24-K24 -> 0 | O24: =IF(N24=0,0,P24/N24) -> 0 | P24: =G24+J24-M24 -> 0
A25: … | F25: =IF(E25=0,0,G25/E25) -> 0 | I25: =IF(H25=0,0,J25/H25) -> 0 | L25: =IF(K25=0,0,M25/K25) -> 0 | N25: =E25+H25-K25 -> 0 | O25: =IF(N25=0,0,P25/N25) -> 0 | P25: =G25+J25-M25 -> 0
A26: 小计 | E26: -- | F26: -- | G26: =G18+G20+G22+G24 -> 0 | H26: -- | I26: -- | J26: =J18+J20+J22+J24 -> 0 | K26: -- | L26: -- | M26: =M18+M20+M22+M24 -> 0 | N26: -- | O26: -- | P26: =P18+P20+P22+P24 -> 0 | Q26: =Q18+Q20+Q22+Q24 -> 0 | R26: =R18+R20+R22+R24 -> 0 | S26: =S18+S20+S22+S24 -> 0 | T26: =T18+T20+T22+T24 -> 0
A27: 合计 | E27: -- | F27: -- | G27: =SUM(G12,G16,G26) -> 0 | H27: -- | I27: -- | J27: =SUM(J12,J16,J26) -> 0 | K27: -- | L27: -- | M27: =SUM(M12,M16,M26) -> 0 | N27: -- | O27: -- | P27: =SUM(P12,P16,P26) -> 0 | Q27: =SUM(Q12,Q16,Q26) -> 0 | R27: =SUM(R12,R16,R26) -> 0 | S27: =SUM(S12,S16,S26) -> 0 | T27: =SUM(T12,T16,T26) -> 0
A28: 减：存货跌价准备
A29: 周转材料/低值易耗品/包装物净额 | E29: -- | F29: -- | G29: =G27-G28 -> 0 | H29: -- | I29: -- | J29: =J27-J28 -> 0 | K29: -- | L29: -- | M29: =M27-M28 -> 0 | N29: -- | O29: -- | P29: =P27-P28 -> 0 | Q29: =Q27-Q28 -> 0 | R29: =R27-R28 -> 0 | S29: =S27-S28 -> 0 | T29: =T27-T28 -> 0
A30: 审计说明： | P30: =IF((P27-Q27-R27-S27-T27)=0,"OK","库龄与期末金额不匹配") -> OK
A31: 1.摊销方法说明： | K31: 3.周转材料/低值易耗品/包装物——**库龄较长的原因：
A32: 2.周转材料/低值易耗品/包装物本期发生重大变动的原因： | K32: 4.计提跌价准备的主要项目及原因：
A34: 提示：摊销方法采用五五、分次摊销法摊销时，金额按摊余价值列示，并作出说明。

Sheet 四、自制半成品明细表F2-6
A1: 致同会计师事务所
A2: 存货明细表
A3: =[1]底稿目录!A2 -> 被审计单位： | G3: =[1]底稿目录!A4 -> 编制人： | K3: =[1]底稿目录!A5 -> 编制日期： | T3: 索引号： | U3: =[1]底稿目录!F11 -> F2-6
A4: =[1]底稿目录!A3 -> 截止日：202X年12月21日 | G4: =[1]底稿目录!A6 -> 复核人： | K4: =[1]底稿目录!A7 -> 复核日期： | T4: 页次：
A5: 四、自制半成品明细表
A6: 存货编码 | B6: 自制半成品名称 | C6: 规格 | D6: 单位 | E6: 期初库存 | H6: 本期购进 | K6: 本期发出 | N6: 期末结存 | Q6: 库龄 | U6: 品质状况（正常、残次、毁损、滞销等）
E7: 数量 | F7: 单价 | G7: 金额 | H7: 数量 | I7: 单价 | J7: 金额 | K7: 数量 | L7: 单价 | M7: 金额 | N7: 数量 | O7: 单价 | P7: 金额 | Q7: 1年以内 | R7: 1-2年 | S7: 2-3年 | T7: 3年以上
F9: =IF(E9=0,0,G9/E9) -> 0 | I9: =IF(H9=0,0,J9/H9) -> 0 | L9: =IF(K9=0,0,M9/K9) -> 0 | N9: =E9+H9-K9 -> 0 | O9: =IF(N9=0,0,P9/N9) -> 0 | P9: =G9+J9-M9 -> 0
F10: =IF(E10=0,0,G10/E10) -> 0 | I10: =IF(H10=0,0,J10/H10) -> 0 | L10: =IF(K10=0,0,M10/K10) -> 0 | N10: =E10+H10-K10 -> 0 | O10: =IF(N10=0,0,P10/N10) -> 0 | P10: =G10+J10-M10 -> 0
F11: =IF(E11=0,0,G11/E11) -> 0 | I11: =IF(H11=0,0,J11/H11) -> 0 | L11: =IF(K11=0,0,M11/K11) -> 0 | N11: =E11+H11-K11 -> 0 | O11: =IF(N11=0,0,P11/N11) -> 0 | P11: =G11+J11-M11 -> 0
F12: =IF(E12=0,0,G12/E12) -> 0 | I12: =IF(H12=0,0,J12/H12) -> 0 | L12: =IF(K12=0,0,M12/K12) -> 0 | N12: =E12+H12-K12 -> 0 | O12: =IF(N12=0,0,P12/N12) -> 0 | P12: =G12+J12-M12 -> 0
F13: =IF(E13=0,0,G13/E13) -> 0 | I13: =IF(H13=0,0,J13/H13) -> 0 | L13: =IF(K13=0,0,M13/K13) -> 0 | N13: =E13+H13-K13 -> 0 | O13: =IF(N13=0,0,P13/N13) -> 0 | P13: =G13+J13-M13 -> 0
F14: =IF(E14=0,0,G14/E14) -> 0 | I14: =IF(H14=0,0,J14/H14) -> 0 | L14: =IF(K14=0,0,M14/K14) -> 0 | N14: =E14+H14-K14 -> 0 | O14: =IF(N14=0,0,P14/N14) -> 0 | P14: =G14+J14-M14 -> 0
F15: =IF(E15=0,0,G15/E15) -> 0 | I15: =IF(H15=0,0,J15/H15) -> 0 | L15: =IF(K15=0,0,M15/K15) -> 0 | N15: =E15+H15-K15 -> 0 | O15: =IF(N15=0,0,P15/N15) -> 0 | P15: =G15+J15-M15 -> 0
F16: =IF(E16=0,0,G16/E16) -> 0 | I16: =IF(H16=0,0,J16/H16) -> 0 | L16: =IF(K16=0,0,M16/K16) -> 0 | N16: =E16+H16-K16 -> 0 | O16: =IF(N16=0,0,P16/N16) -> 0 | P16: =G16+J16-M16 -> 0
F17: =IF(E17=0,0,G17/E17) -> 0 | I17: =IF(H17=0,0,J17/H17) -> 0 | L17: =IF(K17=0,0,M17/K17) -> 0 | N17: =E17+H17-K17 -> 0 | O17: =IF(N17=0,0,P17/N17) -> 0 | P17: =G17+J17-M17 -> 0
F18: =IF(E18=0,0,G18/E18) -> 0 | I18: =IF(H18=0,0,J18/H18) -> 0 | L18: =IF(K18=0,0,M18/K18) -> 0 | N18: =E18+H18-K18 -> 0 | O18: =IF(N18=0,0,P18/N18) -> 0 | P18: =G18+J18-M18 -> 0
F19: =IF(E19=0,0,G19/E19) -> 0 | I19: =IF(H19=0,0,J19/H19) -> 0 | L19: =IF(K19=0,0,M19/K19) -> 0 | N19: =E19+H19-K19 -> 0 | O19: =IF(N19=0,0,P19/N19) -> 0 | P19: =G19+J19-M19 -> 0
F20: =IF(E20=0,0,G20/E20) -> 0 | I20: =IF(H20=0,0,J20/H20) -> 0 | L20: =IF(K20=0,0,M20/K20) -> 0 | N20: =E20+H20-K20 -> 0 | O20: =IF(N20=0,0,P20/N20) -> 0 | P20: =G20+J20-M20 -> 0
... F24: =IF(E24=0,0,G24/E24) -> 0 | I24: =IF(H24=0,0,J24/H24) -> 0 | L24: =IF(K24=0,0,M24/K24) -> 0 | N24: =E24+H24-K24 -> 0 | O24: =IF(N24=0,0,P24/N24) -> 0 | P24: =G24+J24-M24 -> 0
A25: 合计 | E25: -- | F25: -- | G25: =SUM(G9:G24) -> 0 | H25: -- | I25: -- | J25: =SUM(J9:J24) -> 0 | K25: -- | L25: -- | M25: =SUM(M9:M24) -> 0 | N25: -- | O25: -- | P25: =SUM(P9:P24) -> 0 | Q25: =SUM(Q9:Q24) -> 0 | R25: =SUM(R9:R24) -> 0 | S25: =SUM(S9:S24) -> 0 | T25: =SUM(T9:T24) -> 0
A26: 减：存货跌价准备
A27: 自制半成品净额 | E27: -- | F27: -- | G27: =G25-G26 -> 0 | H27: -- | I27: -- | J27: =J25-J26 -> 0 | K27: -- | L27: -- | M27: =M25-M26 -> 0 | N27: -- | O27: -- | P27: =P25-P26 -> 0 | Q27: =Q25-Q26 -> 0 | R27: =R25-R26 -> 0 | S27: =S25-S26 -> 0 | T27: =T25-T26 -> 0
A28: 审计说明： | P28: =IF((P25-Q25-R25-S25-T25)=0,"OK","库龄与期末金额不匹配") -> OK
A29: 1、自制半成品的计价方法： | K29: 3、自制半成品——**库龄较长的原因：
A30: 2、自制半成品本期发生重大变动的原因： | K30: 4、计提跌价准备的主要项目及原因：

Sheet 五、委托加工物资明细表F2-7
A1: 致同会计师事务所
A2: 存货明细表
A3: =[1]底稿目录!A2 -> 被审计单位： | E3: =[1]底稿目录!A4 -> 编制人： | J3: =[1]底稿目录!A5 -> 编制日期： | N3: 索引号： | O3: =[1]底稿目录!F12 -> F2-7
A4: =[1]底稿目录!A3 -> 截止日：202X年12月21日 | E4: =[1]底稿目录!A6 -> 复核人： | J4: =[1]底稿目录!A7 -> 复核日期： | N4: 页次：
A5: 五、委托加工物资明细表
A6: 加工单位名称 | C6: 加工合同号 | D6: 发出加工物资名称 | E6: 数量 | F6: 单价 | G6: 金额 | H6: 加工费用 | I6: 运杂费 | J6: 计入加工物资成本的税金 | K6: 加工物资成本 | L6: 库龄
L7: 1年以内 | M7: 1-2年 | N7: 2-3年 | O7: 3年以上
G8: =E8*F8 -> 0
G9: =E9*F9 -> 0
G10: =E10*F10 -> 0
G11: =E11*F11 -> 0
G12: =E12*F12 -> 0
G13: =E13*F13 -> 0
G14: =E14*F14 -> 0
G15: =E15*F15 -> 0
G16: =E16*F16 -> 0
A17: 合计 | G17: =SUM(G8:G16) -> 0 | H17: =SUM(H8:H16) -> 0 | I17: =SUM(I8:I16) -> 0 | J17: =SUM(J8:J16) -> 0 | K17: =SUM(K8:K16) -> 0 | L17: =SUM(L8:L16) -> 0 | M17: =SUM(M8:M16) -> 0 | N17: =SUM(N8:N16) -> 0 | O17: =SUM(O8:O16) -> 0
A18: 减：存货减值准备
A19: 存货净额 | G19: =G17-G18 -> 0 | L19: =L17-L18 -> 0 | M19: =M17-M18 -> 0 | N19: =N17-N18 -> 0 | O19: =O17-O18 -> 0
A20: 审计说明： | G20: =IF((G17-L17-M17-N17-O17)=0,"OK","库龄与期末金额不匹配") -> OK
A21: 1.委托加工物资的成本核算方法： | G21: 3.委托加工物资——**库龄较长的原因：
A22: 2.委托加工物资本期发生重大变动的原因： | G22: 4.计提跌价准备的主要项目及原因：

Sheet 六、库存商品明细表F2-8
A1: 致同会计师事务所
A2: 存货明细表
A3: =[1]底稿目录!A2 -> 被审计单位： | G3: =[1]底稿目录!A4 -> 编制人： | M3: =[1]底稿目录!A5 -> 编制日期： | W3: 索引号： | X3: =[1]底稿目录!F13 -> F2-8
A4: =[1]底稿目录!A3 -> 截止日：202X年12月21日 | G4: =[1]底稿目录!A6 -> 复核人： | M4: =[1]底稿目录!A7 -> 复核日期： | W4: 页次：
A5: 六、库存商品明细表
A6: 存货编码 | B6: 存货名称 | C6: 规格 | D6: 单位 | E6: 期初库存 | H6: 本期购进 | K6: 本期发出 | N6: 期末结存 | Q6: 库龄 | U6: 品质状况（正常、残次、毁损、滞销等） | V6: 是否有在手订单 | W6: 订单编号 | X6: 销售单价
E7: 数量 | F7: 单价 | G7: 金额 | H7: 数量 | I7: 单价 | J7: 金额 | K7: 数量 | L7: 单价 | M7: 金额 | N7: 数量 | O7: 单价 | P7: 金额 | Q7: 1年以内 | R7: 1-2年 | S7: 2-3年 | T7: 3年以上
F9: =IF(E9=0,0,G9/E9) -> 0 | I9: =IF(H9=0,0,J9/H9) -> 0 | L9: =IF(K9=0,0,M9/K9) -> 0 | N9: =E9+H9-K9 -> 0 | O9: =IF(N9=0,0,P9/N9) -> 0 | P9: =G9+J9-M9 -> 0
F10: =IF(E10=0,0,G10/E10) -> 0 | I10: =IF(H10=0,0,J10/H10) -> 0 | L10: =IF(K10=0,0,M10/K10) -> 0 | N10: =E10+H10-K10 -> 0 | O10: =IF(N10=0,0,P10/N10) -> 0 | P10: =G10+J10-M10 -> 0
F11: =IF(E11=0,0,G11/E11) -> 0 | I11: =IF(H11=0,0,J11/H11) -> 0 | L11: =IF(K11=0,0,M11/K11) -> 0 | N11: =E11+H11-K11 -> 0 | O11: =IF(N11=0,0,P11/N11) -> 0 | P11: =G11+J11-M11 -> 0
F12: =IF(E12=0,0,G12/E12) -> 0 | I12: =IF(H12=0,0,J12/H12) -> 0 | L12: =IF(K12=0,0,M12/K12) -> 0 | N12: =E12+H12-K12 -> 0 | O12: =IF(N12=0,0,P12/N12) -> 0 | P12: =G12+J12-M12 -> 0
F13: =IF(E13=0,0,G13/E13) -> 0 | I13: =IF(H13=0,0,J13/H13) -> 0 | L13: =IF(K13=0,0,M13/K13) -> 0 | N13: =E13+H13-K13 -> 0 | O13: =IF(N13=0,0,P13/N13) -> 0 | P13: =G13+J13-M13 -> 0
F14: =IF(E14=0,0,G14/E14) -> 0 | I14: =IF(H14=0,0,J14/H14) -> 0 | L14: =IF(K14=0,0,M14/K14) -> 0 | N14: =E14+H14-K14 -> 0 | O14: =IF(N14=0,0,P14/N14) -> 0 | P14: =G14+J14-M14 -> 0
F15: =IF(E15=0,0,G15/E15) -> 0 | I15: =IF(H15=0,0,J15/H15) -> 0 | L15: =IF(K15=0,0,M15/K15) -> 0 | N15: =E15+H15-K15 -> 0 | O15: =IF(N15=0,0,P15/N15) -> 0 | P15: =G15+J15-M15 -> 0
F16: =IF(E16=0,0,G16/E16) -> 0 | I16: =IF(H16=0,0,J16/H16) -> 0 | L16: =IF(K16=0,0,M16/K16) -> 0 | N16: =E16+H16-K16 -> 0 | O16: =IF(N16=0,0,P16/N16) -> 0 | P16: =G16+J16-M16 -> 0
F17: =IF(E17=0,0,G17/E17) -> 0 | I17: =IF(H17=0,0,J17/H17) -> 0 | L17: =IF(K17=0,0,M17/K17) -> 0 | N17: =E17+H17-K17 -> 0 | O17: =IF(N17=0,0,P17/N17) -> 0 | P17: =G17+J17-M17 -> 0
F18: =IF(E18=0,0,G18/E18) -> 0 | I18: =IF(H18=0,0,J18/H18) -> 0 | L18: =IF(K18=0,0,M18/K18) -> 0 | N18: =E18+H18-K18 -> 0 | O18: =IF(N18=0,0,P18/N18) -> 0 | P18: =G18+J18-M18 -> 0
F19: =IF(E19=0,0,G19/E19) -> 0 | I19: =IF(H19=0,0,J19/H19) -> 0 | L19: =IF(K19=0,0,M19/K19) -> 0 | N19: =E19+H19-K19 -> 0 | O19: =IF(N19=0,0,P19/N19) -> 0 | P19: =G19+J19-M19 -> 0
F20: =IF(E20=0,0,G20/E20) -> 0 | I20: =IF(H20=0,0,J20/H20) -> 0 | L20: =IF(K20=0,0,M20/K20) -> 0 | N20: =E20+H20-K20 -> 0 | O20: =IF(N20=0,0,P20/N20) -> 0 | P20: =G20+J20-M20 -> 0
... F23: =IF(E23=0,0,G23/E23) -> 0 | I23: =IF(H23=0,0,J23/H23) -> 0 | L23: =IF(K23=0,0,M23/K23) -> 0 | N23: =E23+H23-K23 -> 0 | O23: =IF(N23=0,0,P23/N23) -> 0 | P23: =G23+J23-M23 -> 0
A24: …… | F24: =IF(E24=0,0,G24/E24) -> 0 | I24: =IF(H24=0,0,J24/H24) -> 0 | L24: =IF(K24=0,0,M24/K24) -> 0 | N24: =E24+H24-K24 -> 0 | O24: =IF(N24=0,0,P24/N24) -> 0 | P24: =G24+J24-M24 -> 0
A25: 合计 | E25: -- | F25: -- | G25: =SUM(G9:G24) -> 0 | H25: -- | I25: -- | J25: =SUM(J9:J24) -> 0 | K25: =SUM(K9:K24) -> 0 | L25: -- | M25: =SUM(M9:M24) -> 0 | N25: -- | O25: -- | P25: =SUM(P9:P24) -> 0 | Q25: =SUM(Q9:Q24) -> 0 | R25: =SUM(R9:R24) -> 0 | S25: =SUM(S9:S24) -> 0 | T25: =SUM(T9:T24) -> 0
A26: 减：存货跌价准备
A27: 库存商品净额 | E27: -- | F27: -- | G27: =G25-G26 -> 0 | H27: -- | I27: -- | J27: =J25-J26 -> 0 | K27: -- | L27: -- | M27: =M25-M26 -> 0 | N27: -- | O27: -- | P27: =P25-P26 -> 0 | Q27: =Q25-Q26 -> 0 | R27: =R25-R26 -> 0 | S27: =S25-S26 -> 0 | T27: =T25-T26 -> 0
A28: 销售出库数量（销售台账） | P28: =IF((P25-Q25-R25-S25-T25)=0,"OK","库龄与期末金额不匹配") -> OK
A29: 差异 | K29: =K25-K28 -> 0
A30: 审计说明：
A31: 1.库存商品的计价方法： | K31: 3.库存商品——**库龄较长的原因：
A32: 2.库存商品本期发生重大变动的原因： | K32: 4.计提跌价准备的主要项目及原因：

Sheet 七、发出商品F2-9
A1: 致同会计师事务所
A2: 存货明细表
A3: =[1]底稿目录!A2 -> 被审计单位： | F3: =[1]底稿目录!A4 -> 编制人： | J3: =[1]底稿目录!A5 -> 编制日期： | V3: 索引号： | W3: =[1]底稿目录!F14 -> F2-9
A4: =[1]底稿目录!A3 -> 截止日：202X年12月21日 | F4: =[1]底稿目录!A6 -> 复核人： | J4: =[1]底稿目录!A7 -> 复核日期： | V4: 页次：
A5: 七、发出商品明细表
A6: 购货单位 | B6: 发出商品名称及规格 | C6: 单位 | D6: 期初库存 | G6: 本期转入 | J6: 本期转出 | M6: 期末结存 | P6: 期后结转 | S6: 库龄 | W6: 品质状况（正常、残次、毁损、滞销等）
D7: 数量 | E7: 单价 | F7: 金额 | G7: 数量 | H7: 单价 | I7: 金额 | J7: 数量 | K7: 单价 | L7: 金额 | M7: 数量 | N7: 单价 | O7: 金额 | P7: 数量 | Q7: 单价 | R7: 金额 | S7: 1年以内 | T7: 1-2年 | U7: 2-3年 | V7: 3年以上
E9: =IF(D9=0,0,F9/D9) -> 0 | H9: =IF(G9=0,0,I9/G9) -> 0 | K9: =IF(J9=0,0,L9/J9) -> 0 | M9: =D9+G9-J9 -> 0 | N9: =IF(M9=0,0,O9/M9) -> 0 | O9: =F9+I9-L9 -> 0 | Q9: =IF(P9=0,0,R9/P9) -> 0
E10: =IF(D10=0,0,F10/D10) -> 0 | H10: =IF(G10=0,0,I10/G10) -> 0 | K10: =IF(J10=0,0,L10/J10) -> 0 | M10: =D10+G10-J10 -> 0 | N10: =IF(M10=0,0,O10/M10) -> 0 | O10: =F10+I10-L10 -> 0 | Q10: =IF(P10=0,0,R10/P10) -> 0
E11: =IF(D11=0,0,F11/D11) -> 0 | H11: =IF(G11=0,0,I11/G11) -> 0 | K11: =IF(J11=0,0,L11/J11) -> 0 | M11: =D11+G11-J11 -> 0 | N11: =IF(M11=0,0,O11/M11) -> 0 | O11: =F11+I11-L11 -> 0 | Q11: =IF(P11=0,0,R11/P11) -> 0
E12: =IF(D12=0,0,F12/D12) -> 0 | H12: =IF(G12=0,0,I12/G12) -> 0 | K12: =IF(J12=0,0,L12/J12) -> 0 | M12: =D12+G12-J12 -> 0 | N12: =IF(M12=0,0,O12/M12) -> 0 | O12: =F12+I12-L12 -> 0 | Q12: =IF(P12=0,0,R12/P12) -> 0
E13: =IF(D13=0,0,F13/D13) -> 0 | H13: =IF(G13=0,0,I13/G13) -> 0 | K13: =IF(J13=0,0,L13/J13) -> 0 | M13: =D13+G13-J13 -> 0 | N13: =IF(M13=0,0,O13/M13) -> 0 | O13: =F13+I13-L13 -> 0 | Q13: =IF(P13=0,0,R13/P13) -> 0
E14: =IF(D14=0,0,F14/D14) -> 0 | H14: =IF(G14=0,0,I14/G14) -> 0 | K14: =IF(J14=0,0,L14/J14) -> 0 | M14: =D14+G14-J14 -> 0 | N14: =IF(M14=0,0,O14/M14) -> 0 | O14: =F14+I14-L14 -> 0 | Q14: =IF(P14=0,0,R14/P14) -> 0
E15: =IF(D15=0,0,F15/D15) -> 0 | H15: =IF(G15=0,0,I15/G15) -> 0 | K15: =IF(J15=0,0,L15/J15) -> 0 | M15: =D15+G15-J15 -> 0 | N15: =IF(M15=0,0,O15/M15) -> 0 | O15: =F15+I15-L15 -> 0 | Q15: =IF(P15=0,0,R15/P15) -> 0
E16: =IF(D16=0,0,F16/D16) -> 0 | H16: =IF(G16=0,0,I16/G16) -> 0 | K16: =IF(J16=0,0,L16/J16) -> 0 | M16: =D16+G16-J16 -> 0 | N16: =IF(M16=0,0,O16/M16) -> 0 | O16: =F16+I16-L16 -> 0 | Q16: =IF(P16=0,0,R16/P16) -> 0
E17: =IF(D17=0,0,F17/D17) -> 0 | H17: =IF(G17=0,0,I17/G17) -> 0 | K17: =IF(J17=0,0,L17/J17) -> 0 | M17: =D17+G17-J17 -> 0 | N17: =IF(M17=0,0,O17/M17) -> 0 | O17: =F17+I17-L17 -> 0 | Q17: =IF(P17=0,0,R17/P17) -> 0
E18: =IF(D18=0,0,F18/D18) -> 0 | H18: =IF(G18=0,0,I18/G18) -> 0 | K18: =IF(J18=0,0,L18/J18) -> 0 | M18: =D18+G18-J18 -> 0 | N18: =IF(M18=0,0,O18/M18) -> 0 | O18: =F18+I18-L18 -> 0 | Q18: =IF(P18=0,0,R18/P18) -> 0
E19: =IF(D19=0,0,F19/D19) -> 0 | H19: =IF(G19=0,0,I19/G19) -> 0 | K19: =IF(J19=0,0,L19/J19) -> 0 | M19: =D19+G19-J19 -> 0 | N19: =IF(M19=0,0,O19/M19) -> 0 | O19: =F19+I19-L19 -> 0 | Q19: =IF(P19=0,0,R19/P19) -> 0
E20: =IF(D20=0,0,F20/D20) -> 0 | H20: =IF(G20=0,0,I20/G20) -> 0 | K20: =IF(J20=0,0,L20/J20) -> 0 | M20: =D20+G20-J20 -> 0 | N20: =IF(M20=0,0,O20/M20) -> 0 | O20: =F20+I20-L20 -> 0 | Q20: =IF(P20=0,0,R20/P20) -> 0
... E23: =IF(D23=0,0,F23/D23) -> 0 | H23: =IF(G23=0,0,I23/G23) -> 0 | K23: =IF(J23=0,0,L23/J23) -> 0 | M23: =D23+G23-J23 -> 0 | N23: =IF(M23=0,0,O23/M23) -> 0 | O23: =F23+I23-L23 -> 0 | Q23: =IF(P23=0,0,R23/P23) -> 0
A24: …… | E24: =IF(D24=0,0,F24/D24) -> 0 | H24: =IF(G24=0,0,I24/G24) -> 0 | K24: =IF(J24=0,0,L24/J24) -> 0 | M24: =D24+G24-J24 -> 0 | N24: =IF(M24=0,0,O24/M24) -> 0 | O24: =F24+I24-L24 -> 0 | Q24: =IF(P24=0,0,R24/P24) -> 0
A25: 合计 | D25: -- | E25: -- | F25: =SUM(F9:F24) -> 0 | G25: -- | H25: -- | I25: =SUM(I9:I24) -> 0 | J25: =SUM(J9:J24) -> 0 | K25: -- | L25: =SUM(L9:L24) -> 0 | M25: -- | N25: -- | O25: =SUM(O9:O24) -> 0 | P25: -- | Q25: -- | R25: =SUM(R9:R24) -> 0 | S25: =SUM(S9:S24) -> 0 | T25: =SUM(T9:T24) -> 0 | U25: =SUM(U9:U24) -> 0 | V25: =SUM(V9:V24) -> 0
A26: 减：存货跌价准备
A27: 发出商品净额 | D27: -- | E27: -- | F27: =F25-F26 -> 0 | G27: -- | H27: -- | I27: =I25-I26 -> 0 | J27: -- | K27: -- | L27: =L25-L26 -> 0 | M27: -- | N27: -- | O27: =O25-O26 -> 0 | P27: -- | Q27: -- | R27: =R25-R26 -> 0 | S27: =S25-S26 -> 0 | T27: =T25-T26 -> 0 | U27: =U25-U26 -> 0 | V27: =V25-V26 -> 0
A28: 销售出库数量（销售台账） | O28: =IF((O25-S25-T25-U25-V25)=0,"OK","库龄与期末金额不匹配") -> OK
A29: 差异 | J29: =J25-J28 -> 0
A31: 审计说明：
A32: 1.发出商品资产负债表日后销售情况： | I32: 3.发出商品——**库龄较长的原因：
A33: 2.发出商品本期发生重大变动的原因： | I33: 4.计提跌价准备的主要项目及原因：
A35: 审计提示：
A36: 关注产品退换货情况

Sheet 八、开发产品F2-10
A1: 致同会计师事务所
A2: 存货明细表
A3: =[1]底稿目录!A2 -> 被审计单位： | H3: =[1]底稿目录!A4 -> 编制人： | Q3: =[1]底稿目录!A5 -> 编制日期： | Z3: 索引号： | AA3: =[1]底稿目录!F15 -> F2-10
A4: =[1]底稿目录!A3 -> 截止日：202X年12月21日 | H4: =[1]底稿目录!A6 -> 复核人： | Q4: =[1]底稿目录!A7 -> 复核日期： | Z4: 页次：
A5: 八、开发产品明细表
A6: （一）原值
A7: 序号 | B7: 项目名称 | C7: 总建筑面积/万平米 | D7: 开工时间 | E7: 竣工时间 | F7: 期初结存（未审） | I7: 期初调整 | K7: 期初审定 | M7: 本期转入 | P7: 本期转出 | S7: 期末结存（未审） | V7: 期末调整 | X7: 期末审定 | Z7: 库龄 | AA7: 品质状况（正常、停建、毁损、报废等）
F8: 面积 （平方米） | G8: 单位成本 | H8: 金额 | I8: 账项调整 | J8: 重分类调整 | K8: 单位成本 | L8: 金额 | M8: 面积 （平方米） | N8: 单位成本 | O8: 金额 | P8: 面积 （平方米） | Q8: 单位成本 | R8: 金额 | S8: 面积 （平方米） | T8: 单位成本 | U8: 金额 | V8: 账项调整 | W8: 重分类调整 | X8: 单位成本 | Y8: 金额
A9: 1 | G9: =IF(F9=0,0,H9/F9) -> 0 | K9: =IF(F9=0,0,L9/F9) -> 0 | L9: =H9+I9+J9 -> 0 | N9: =IF(M9=0,0,O9/M9) -> 0 | Q9: =IF(P9=0,0,R9/P9) -> 0 | S9: =F9+M9-P9 -> 0 | T9: =IF(S9=0,0,U9/S9) -> 0 | U9: =H9+O9-R9 -> 0 | X9: =IF(S9=0,0,Y9/S9) -> 0 | Y9: =U9+V9+W9 -> 0
A10: 2 | G10: =IF(F10=0,0,H10/F10) -> 0 | K10: =IF(F10=0,0,L10/F10) -> 0 | L10: =H10+I10+J10 -> 0 | N10: =IF(M10=0,0,O10/M10) -> 0 | Q10: =IF(P10=0,0,R10/P10) -> 0 | S10: =F10+M10-P10 -> 0 | T10: =IF(S10=0,0,U10/S10) -> 0 | U10: =H10+O10-R10 -> 0 | X10: =IF(S10=0,0,Y10/S10) -> 0 | Y10: =U10+V10+W10 -> 0
