Workbook
Name _1、: #REF!
Name _1、: #REF!
Name _1、: #REF!
Name _1、: #REF!
Name _1、: #REF!
Name _1、: #REF!
Name _1、受本循环影响的相关交易和账户余额: #REF!
Name _1、受本循环影响的相关交易和账户余额: #REF!
Name _1、受本循环影响的相关交易和账户余额: #REF!
Name _1、受本循环影响的相关交易和账户余额: #REF!
Name _1、受本循环影响的相关交易和账户余额: #REF!
Name _1、受本循环影响的相关交易和账户余额: #REF!
Name _2、主要业务活动: #REF!
Name _2、主要业务活动: #REF!
Name _2、主要业务活动: #REF!
Name _2、主要业务活动: #REF!
Name _2、主要业务活动: #REF!
Name _2、主要业务活动: #REF!
Name _2、注册会计师通常应在本循环中了解与上述业务活动相关的内部控制_如果计划在其他业务循环中对上述: #REF!
Name _2、注册会计师通常应在本循环中了解与上述业务活动相关的内部控制_如果计划在其他业务循环中对上述: #REF!
Name _2、注册会计师通常应在本循环中了解与上述业务活动相关的内部控制_如果计划在其他业务循环中对上述: #REF!
Name _2、注册会计师通常应在本循环中了解与上述业务活动相关的内部控制_如果计划在其他业务循环中对上述: #REF!
Name _2、注册会计师通常应在本循环中了解与上述业务活动相关的内部控制_如果计划在其他业务循环中对上述: #REF!
Name _2、注册会计师通常应在本循环中了解与上述业务活动相关的内部控制_如果计划在其他业务循环中对上述: #REF!
Name a暗暗: [1]企业表一!$F$20
Name CarryKnown: #REF!
Name CarryKnown: #REF!
Name CarryKnown: #REF!
Name CarryKnown: #REF!
Name CarryKnown: #REF!
Name CarryKnown: #REF!
Name CarryKnownTable: #REF!
Name CarryKnownTable: #REF!
Name CarryKnownTable: #REF!
Name CarryKnownTable: #REF!
Name CarryKnownTable: #REF!
Name CarryKnownTable: #REF!
Name CarryLikely: #REF!
Name CarryLikely: #REF!
Name CarryLikely: #REF!
Name CarryLikely: #REF!
Name CarryLikely: #REF!
Name CarryLikely: #REF!
Name CarryLikelyTable: #REF!
Name CarryLikelyTable: #REF!
Name CarryLikelyTable: #REF!
Name CarryLikelyTable: #REF!
Name CarryLikelyTable: #REF!
Name CarryLikelyTable: #REF!
Name Carryover_Effect_of_Prior_Year: #REF!
Name Carryover_Effect_of_Prior_Year: #REF!
Name Carryover_Effect_of_Prior_Year: #REF!
Name Carryover_Effect_of_Prior_Year: #REF!
Name Carryover_Effect_of_Prior_Year: #REF!
Name Carryover_Effect_of_Prior_Year: #REF!
Name CarryoverTitle: #REF!
Name CarryoverTitle: #REF!
Name CarryoverTitle: #REF!
Name CarryoverTitle: #REF!
Name CarryoverTitle: #REF!

Sheet 表头（请先填写）
A1: 底稿开列时，可先在以下单元格填写有关内容，以便其他底稿引用有关数据： | B1: 序号 | C1: 目录
A2: 客户名称： | B2: 1 | C2: C14控制测试汇总表
A3: 会计期间：2013年度 | B3: 2 | C3: C14-1控制测试程序和过程记录表（记录控制测试程序与过程）
A4: 编制人： | B4: 3 | C4: C14-2评价控制偏差表
A5: 日 期： | B5: 4
A8: 附录、关于工作底稿索引号的编制方法
A10: 1、 工作底稿与审计程序的对应与索引
A11: 为提高工作底稿编制的针对性，各项目负责人提供的所有支持性工作底稿，均应当按自然顺序依次编制索引号，并通过唯一的索引号将审计程序表中的特定程序与相关支持性工作底稿进行一一对应。
A12: 2、 工作底稿索引号的编码规则
A13: （1）索引号的结构：包括三要素，即“项目名称代码”、“—”和“索引顺序号”，如“C2-1”、“C2-2”、........
A14: （2）索引顺序号的分层：可分为多层，如“C2-1-1”；“C2-1-2”；........

Sheet C14控制测试汇总表
A1: 致同会计师事务所
A2: 债务循环-控制测试汇总表
A3: ='表头（请先填写）'!A2 -> 客户名称： | D3: ='表头（请先填写）'!A4 -> 编制人： | H3: ='表头（请先填写）'!A5 -> 日 期： | K3: 索引号： | L3: C14
A4: ='表头（请先填写）'!A3 -> 会计期间：2013年度 | D4: 复核人： | H4: 日 期： | K4: 页 次： | L4: 1
A5: 1、测试本循环控制运行有效性的工作包括：
A6: （1）针对了解的被审计单位债务循环的控制活动，确定拟进行测试的控制活动。
A7: （2）测试控制运行的有效性，记录测试过程和结论。
A8: （3）根据测试结论，确定对实质性程序的性质、时间和范围的影响。
A9: 2、测试本循环控制运行有效性形成下列审计工作底稿：
A10: （1）控制测试汇总表（汇总对本循环内部控制运行有效性进行测试的主要内容和结论） | F10: C14
A11: （2）控制测试程序和过程记录表（记录控制测试程序与过程） | F11: C14-1
A12: （3）评价控制偏差表（记录控制偏差的评价过程） | F12: C14-2
A13: 3、控制测试结论
A14: 活动 | B14: 关键控制 | D14: MA | E14: PD | F14: 认定 | G14: 风险 | H14: 测试方法（询问观察/CAAT/抽样（检查）/重新执行/管理层-重新执行/管理层-仅复核) | I14: 样本量 | J14: 控制活动是否有效运行(是/否) | K14: 控制测试结果是否支持风险评估结论 (支持/不支持) | L14: 索引号 (C14-1,C14-2)
A15: 债务工具Debt instruments
B16: 1
B17: 2
B18: ……
A19: 利息Interest and fees
B20: 1
B21: 2
B22: ……
A23: 维护记录Maintain records
B24: 1
B25: 2
B26: ……
A27: 与债务相关的调整Debt-Related Adjustments
B28: 1
B29: 2
B30: ……
A33: 编制说明：
A34: 1、当存在下列情形之一时，注册会计师应当设计和实施控制测试，针对相关控制运行的有效性，获取充分、适当的审计证据：
A35: （1）在评估认定层次重大错报风险时，预期控制的运行是有效的（即在确定实质性程序的性质、时间安排和范围时，注册会计师拟信赖控制运行的有效性）；
A36: （2）仅实施实质性程序并不能够提供认定层次充分、适当的审计证据。
A37: 2、本审计工作底稿中“控制活动是否有效运行”一栏，应根据C2-1控制测试的结果填写；“控制测试结果是否支持风险评估结论”一栏，应根据了解和测试内部控制中获取的审计证据分析填写
A59: 询问&观察
A60: 抽样
A61: 重新执行
A62: CAAT
A63: 管理层-重新执行
...

Sheet C14-1控制测试过程记录表（询问&观察）
A1: 致同会计师事务所
A2: 控制测试程序和过程记录表
A3: ='表头（请先填写）'!A2 -> 客户名称： | C3: ='表头（请先填写）'!A4 -> 编制人： | D3: ='表头（请先填写）'!A5 -> 日 期： | F3: 索引号：C14-1-*
A4: ='表头（请先填写）'!A3 -> 会计期间：2013年度 | C4: 复核人： | D4: 日 期： | F4: 页 次：
A5: 认定：
A6: 活动名:
A7: 客户控制点描述:
A8: 客户控制点编号:
A9: 控制频率:
A10: 开始执行日期:
A11: 过程的执行人:
A12: 控制的执行人:
A13: 访问的人员:
A14: 访问日期:
A15: 测试方法: | B15: 询问&观察
A16: 与控制相关的风险：
A17: 样本量：
A18: 程序:
A19: 1.就_________向_________经理提出询问。Inquire of the __________ manager about _________.
A20: 2.审阅_________，并与对我们询问的回答进行比较，以检查其一致性。 Review _________ and contrast consistency with the responses to our inquiries.
A21: 3.观察超出或低于被授权_________流程。Observe _________process above and below the authorized edit settings.
A22: 4.观察数据录入和具体内容比对的流程。Observe the data entry and details comparison process.
A23: 5.观察配比与后续流程。Observe the matching and follow-up process.
A24: 6.获得关于 应用的接入控制一览表。Obtain the access control list for the __________ application.
A25: 7.考虑IT管理控制是否影响这项控制的有效性。 Consider whether IT governance controls impact on the effectiveness of this control.
A26: 8.评估_________控制的有效性。Assess the effectiveness of the _________ control.
A27: 如何测试:
... A41: 结论:

Sheet C14-1控制测试过程记录表（抽样）
A1: 致同会计师事务所
A2: 控制测试程序和过程记录表
A3: ='表头（请先填写）'!A2 -> 客户名称： | C3: ='表头（请先填写）'!A4 -> 编制人： | D3: ='表头（请先填写）'!A5 -> 日 期： | F3: 索引号：C14-1-*
A4: ='表头（请先填写）'!A3 -> 会计期间：2013年度 | C4: 复核人： | D4: 日 期： | F4: 页 次：
A5: 认定：
A6: 活动名:
A7: 客户控制点描述:
A8: 客户控制点编号:
A9: 控制频率:
A10: 开始执行日期:
A11: 过程的执行人:
A12: 控制的执行人:
A13: 访问的人员:
A14: 访问日期:
A15: 测试方法: | B15: 抽样
A16: 与控制相关的风险：
A17: 样本量：
A18: 程序:
A19: 1.观察_________流程。Observe _________ process.
A20: 2.从该期间的交易中，选择一份无偏向的、未分层的 %样本,并检查关于例外情况已得到适当调查并已解决的证据。From the period's transactions, select an unbiased, unstratified sample % items and examine evidence that the exceptions were appropriately investigated and resolved.
A21: 3.检查文件并证实其在处理时已做了标识。Examine document and verify that the document has been marked as processed.
A22: 4.检查已登记的详细资料已与源文件进行了比较的证据。Examine evidence that the recorded details was compared to the source documents.
A23: 5.评估_________的有效性。Assess the effectiveness of the _________.
A24: 如何测试:
A37: 审计说明：
A38: 结论:

Sheet C14-1控制测试过程记录表（重新执行）
A1: 致同会计师事务所
A2: 控制测试程序和过程记录表
A3: ='表头（请先填写）'!A2 -> 客户名称： | C3: ='表头（请先填写）'!A4 -> 编制人： | D3: ='表头（请先填写）'!A5 -> 日 期： | F3: 索引号：C14-1-*
A4: ='表头（请先填写）'!A3 -> 会计期间：2013年度 | C4: 复核人： | D4: 日 期： | F4: 页 次：
A5: 认定：
A6: 活动名:
A7: 客户控制点描述:
A8: 客户控制点编号:
A9: 控制频率:
A10: 开始执行日期:
A11: 过程的执行人:
A12: 控制的执行人:
A13: 访问的人员:
A14: 访问日期:
A15: 测试方法: | B15: 重新执行
A16: 与控制相关的风险：
A17: 样本量：
A18: 程序:
A19: 1. 判断选取____个样本，并核实这些样本执行没有偏差（或核实这些样本经过恰当的人员批准）。Judgmentally select ______and verify that these samples without exception( or verify that they are reviewed by appropriate personnel.)
A20: 2. 记录____样本是如何执行的。Note documentation of the_____ performed.
A21: 3. 确认那些有问题的项目已经过适当的调查和汇报给____经理。Verify any exceptional items are appropriately investigated and report to____ Manager.
A22: 4. 评估_________的有效性。Assess the effectiveness of the _________.
A23: 如何测试:
A36: 审计说明：
A37: 结论:

Sheet C14-1控制测试过程记录表（CAAT）
A1: 致同会计师事务所
A2: 控制测试程序和过程记录表
A3: ='表头（请先填写）'!A2 -> 客户名称： | C3: ='表头（请先填写）'!A4 -> 编制人： | D3: ='表头（请先填写）'!A5 -> 日 期： | F3: 索引号：C14-1-*
A4: ='表头（请先填写）'!A3 -> 会计期间：2013年度 | C4: 复核人： | D4: 日 期： | F4: 页 次：
A5: 认定：
A6: 活动名:
A7: 客户控制点描述:
A8: 客户控制点编号:
A9: 控制频率:
A10: 开始执行日期:
A11: 过程的执行人:
A12: 控制的执行人:
A13: 访问的人员:
A14: 访问日期:
A15: 测试方法: | B15: CAAT
A16: 与控制相关的风险：
A17: 样本量：
A18: 程序:
A19: 1.就____________参数向____________经理提出询问。考虑：Inquire of the ____________ manager about the parameters used to ____________. Consider:
A20: 2.运行_______软件。Run _________ software.
A21: 3.获取__交易的电子副本。Obtain an electronic copy of the ___________ transactions.
A22: 4.获得关于__________ 的评估控制一览表。 Obtain the access control list for the __________ application.
A23: 5.分析组访问权利和此组中用户的任务。确定谁可以访问___________应用程序。 Analyze groups access rights and user assignment to the groups. Determine who can access the ___________ application
A24: 6.评价此访问是否适当(例如，人数，履行职责所必需的访问)。Evaluate the appropriateness of this access (e.g., number of people, access required to perform duties)
A25: 7.确定被授权访问这个程序的人员名单多久被审查一次并且是被谁审查的。 Determine how often the list of people authorized to access this application is reviewed and by who
A26: 8.考虑IT管理控制是否影响这项控制的有效性。 Consider whether IT governance controls impact on the effectiveness of this control.
A27: 9.评估对___________应用程序访问的控制的有效性。Assess the effectiveness of the controls over access to the ___________ application.
... A42: 结论:

Sheet C14-1控制测试过程记录表（管理层-重新执行）
A1: 致同会计师事务所
A2: 控制测试程序和过程记录表
A3: ='表头（请先填写）'!A2 -> 客户名称： | C3: ='表头（请先填写）'!A4 -> 编制人： | D3: ='表头（请先填写）'!A5 -> 日 期： | F3: 索引号：C14-1-*
A4: ='表头（请先填写）'!A3 -> 会计期间：2013年度 | C4: 复核人： | D4: 日 期： | F4: 页 次：
A5: 认定：
A6: 活动名:
A7: 客户控制点描述:
A8: 客户控制点编号:
A9: 控制频率:
A10: 开始执行日期:
A11: 过程的执行人:
A12: 控制的执行人:
A13: 访问的人员:
A14: 访问日期:
A15: 测试方法: | B15: 管理层-重新执行
A16: 与控制相关的风险：
A17: 样本量：
A18: 程序:
A19: 1.确定所进行检验的类型和被检验项目的数量是否合理地考虑到此次控制的性质和控制目的。 Determine whether the type of test employed and the number of items tested is appropriate considering the nature of the control and the control objective.
A20: 2.对_________的质量进行评估。 Assess the quality of the_________.
A21: 3.对监督依据和已进行检验的审查进行检查。 Examine evidence of supervision and review of the testing performed.
A22: 4.确定关于控制有效性的结论是否与检验结果一致。 Determine whether the conclusion reached about the effectiveness of the control is consistent with the test results.
A23: 5.选择至少一个由其他审计师测试的项目，并且重新进行测试。记录所执行的测试。 Select at least one item tested by others and reperform the test. Document testing performed.
A24: 6.对执行测试的人员的专业胜任能力与客观性进行评价。 Assess the competency and objectivity of the individuals who performed the test.
A25: 5.对其他人员完成的测试结果作出结论。 Conclude on the effectiveness of the testing performed by others.
A26: 如何测试:
A39: 审计说明：
A40: 结论:

Sheet C14-1控制测试过程记录表（管理层-仅复核）
A1: 致同会计师事务所
A2: 控制测试程序和过程记录表
A3: ='表头（请先填写）'!A2 -> 客户名称： | C3: ='表头（请先填写）'!A4 -> 编制人： | D3: ='表头（请先填写）'!A5 -> 日 期： | F3: 索引号：C14-1-*
A4: ='表头（请先填写）'!A3 -> 会计期间：2013年度 | C4: 复核人： | D4: 日 期： | F4: 页 次：
A5: 认定：
A6: 活动名:
A7: 客户控制点描述:
A8: 客户控制点编号:
A9: 控制频率:
A10: 开始执行日期:
A11: 过程的执行人:
A12: 控制的执行人:
A13: 访问的人员:
A14: 访问日期:
A15: 测试方法: | B15: 管理层-仅复核
A16: 与控制相关的风险：
A17: 样本量：
A18: 程序:
A19: 1.确定所进行检验的类型和被检验项目的数量是否合理地考虑到此次控制的性质和控制目的。Determine whether the type of test employed and the number of items tested is appropriate considering the nature of the control and the control objective.
A20: 2.对文件编制的质量进行评估。 Assess the quality of the documentation.
A21: 3.确定关于控制有效性的结论是否与检验结果一致。 Determine whether the conclusion reached about the effectiveness of the control is consistent with the test results.
A22: 4.对执行测试的人员的专业胜任能力与客观性进行评价。 Assess the competency and objectivity of the individuals who performed the test.
A23: 5.对其他人员完成的测试结果作出结论。 Conclude on the effectiveness of the testing performed by others.
A24: 如何测试:
A37: 审计说明：
A38: 结论:

Sheet C14-2评价控制偏差
A1: 致同会计师事务所
A2: 评价控制偏差
A3: ='表头（请先填写）'!A2 -> 客户名称： | D3: ='[8]表头（请先填写）'!A4 -> 编制人： | E3: ='[8]表头（请先填写）'!A5 -> 日 期： | F3: 索引号：C14-2
A4: ='表头（请先填写）'!A3 -> 会计期间：2013年度 | D4: 复核人： | E4: 日期： | F4: 页 次：
A6: 控制例外情况描述：
A11: 评价步骤 | C11: 是/否 | D11: 评价分析过程 | F11: 备注
A12: 步骤一： 确认发现的控制例外情况（选定的样本无法执行控制测试）是否属于控制偏差（内部控制运行偏离设计）？ [注1]
D13: =IF(C12="否","不属于控制偏差；进入步骤六",IF(C12="是","进入步骤二",""))
A14: 步骤二： 确定控制偏差的性质：系统性偏差？人为有意造成的偏差？随机性偏差？ [注2]
D15: =IF(C14="随机性偏差","确定应对措施；进入步骤三",IF(OR(C14="系统性偏差",C14="人为偏差"),"属于控制缺陷；进入步骤五",""))
A16: 步骤三： 对于随机性的偏差，确定适当的审计应对措施：扩大样本量进行测试？直接将该项控制偏差视作缺陷？ [注3]
D17: =IF(C16="直接认定为偏差","进入步骤五",IF(C16="扩大样本量","进入步骤四",""))
A18: 步骤四： 根据发现的控制偏差的数量来确定扩大样本量的范围，扩大样本量进行测试后是否发现新的偏差？ [注4]
D19: =IF(C18="否","控制有效",IF(C18="是","该控制无效；进入步骤五",""))
A20: 步骤五： 评价控制缺陷。 [注5] | C20: =IF(OR(D17="进入步骤五",D19="该控制无效；进入步骤五"),"评价缺陷","")
D21: =IF(OR(D17="进入步骤五",D19="该控制无效；进入步骤五"),"进入内部控制缺陷评价底稿","") | F21: =IF(LEN(D21)>0,"T2","")
A22: 步骤六： 若确定发现的控制例外情况不属于控制偏差，则可以选取替代样本以获得证明控制运行有效的充分、适当的审计证据。 但需确定控制例外情况是否表明相关控制的设计存在缺陷？ [注6]
D23: =IF(C22="否","该控制例外情况不构成偏差或缺陷",IF(C22="是","存在设计缺陷；回到步骤五",""))
A24: 评 价 结 论 | D24: 该控制例外情况不构成控制偏差/该偏差构成缺陷/该控制有效。
A27: 注1：控制例外情况及控制偏差
A28: 控制例外情况
A29: 对于一个选定的样本或替代性样本，如果无法执行注册会计师所设计的控制测试或适当的替代性测试，则注册会计师应认为
A30: 该样本是一项控制例外情况。
A31: 例如，对于一个选定的样本，如果由于企业不能提供支持性文档而无法执行控制测试，则其属于一项控制例外情况并需要
A32: 确定适当的应对措施。
A33: 对于发现的控制例外情况，首先应当确定其是否构成一项控制偏差。
A34: 当出现以下情况时，一般可以认为控制例外情况不是控制偏差：
A35: （1）根据进一步的了解和评价，注册会计师确定识别出的例外情况事实上不是对控制预设目标的偏离，即注册会计师原先
A36: 对重大业务流程及相关控制的理解有误。
A37: （2）基于对控制设计的了解，注册会计师能够通过追加执行除询问以外的审计程序获取充分、适当的审计证据，以确认该
A38: 例外情况引发的错误在可以接受的水平，即小于临界值（明显微小的错报金额SAD）。
... A79: 设计缺陷是指缺少为实现控制目标所必需的控制，或现有控制设计不适当、即使正常运行也难以实现预期的控制目标。

Sheet 示例-评价控制偏差
A1: 致同会计师事务所
A2: 示例-评价控制偏差
A3: 客户名称：甲公司 | D3: 编制人：BBB | E3: 日期：2014.1.5 | F3: 索引号：C*-2
A4: 基准日：2013年12月31日 | D4: 复核人：DDD | E4: 日期：2014.1.8 | F4: 页 次：
A6: 控制例外情况描述：
A7: 经理层监督客户投诉的数量及类型并把这些信息作为估计销售退回的依据。然而，注册会计师在执行控制测试
A8: 时发现某一期间计算出的投诉率没有包含某一地区收到的投诉。
A10: 评价步骤 | C10: 是/否 | D10: 评价分析过程 | F10: 备注
A11: 步骤一： 确认发现的控制例外情况（选定的样本无法执行控制测试）是否属于控制偏差（内部控制运行偏离设计）？ | C11: 是 | D11: 该控制例外情况影响销售收入的金额，且金额不属于无关紧要。
D12: =IF(C11="是","进入步骤二","") -> 进入步骤二
D14: =IF(C11="否","不属于控制偏差；进入步骤六","")
A15: 步骤二： 确定控制偏差的性质：系统性偏差？人为有意造成的偏差？随机性偏差？ | C15: 随机性偏差
D16: =IF(OR(C15="系统性偏差",C15="人为偏差"),"属于控制缺陷；进入步骤五","")
D17: 注册会计师确定这只是众多地区中唯一的一个没有报告投诉率的，而且其他所有月份都完成了投诉率的报告。
D18: =IF(C15="随机性偏差","确定应对措施；进入步骤三","") -> 确定应对措施；进入步骤三
A19: 步骤三： 对于随机性的偏差，确定适当的审计应对措施：扩大样本量进行测试？直接将该项控制偏差视作缺陷？ | C19: 扩大样本量 | D19: 注册会计师确定该项控制偏差是随机性的，并应扩大样本量来予以确认。
D20: =IF(C19="扩大样本量","进入步骤四","") -> 进入步骤四
D22: =IF(C19="直接认定为偏差","进入步骤五","")
A23: 步骤四： 根据发现的控制偏差的数量来确定扩大样本量的范围，扩大样本量进行测试后是否发现新的偏差？ | C23: 否
D24: =IF(C23="是","该控制无效；进入步骤五","")
D25: 尽管存在一项控制偏差，但测试范围内的错误率在可容忍范围内且该控制偏差不具有代表性。
D26: =IF(C23="否","控制有效","") -> 控制有效
A27: 步骤五： 评价控制缺陷。 | C27: =IF(OR(D22="进入步骤五",D24="该控制无效；进入步骤五"),"评价缺陷","")
D28: =IF(C27="评价缺陷","进入内部控制缺陷评价底稿","") | F28: =IF(LEN(D28)>0,"T2","")
A29: 步骤六： 若确定发现的控制例外情况不属于控制偏差，则可以选取替代样本以获得证明控制运行有效的充分、适当的审计证据。 但需确定控制例外情况是否表明相关控制的设计存在缺陷？
D30: =IF(C29="是","存在设计缺陷；回到步骤五","")
D32: =IF(C29="否","该控制例外情况不构成偏差或缺陷","")
A33: 评 价 结 论 | D33: 该控制例外情况不构成控制偏差，控制运行有效。

Sheet GT_Custom
A1: C1 | B1: Custom 1
A2: C2 | B2: Custom 2
A3: C3 | B3: Custom 3
A4: C4 | B4: Custom 4
A5: C5 | B5: Custom 5
A6: C6 | B6: Custom 6
A7: C7 | B7: Custom 7
A8: C8 | B8: Custom 8
