Workbook

Sheet S13 利用管理层的专家形成审计证据程序表
A1: 致同会计师事务所
A2: 利用管理层的专家编制的信息形成审计证据程序表
A3: 客户名称： | D3: 编制人： | G3: 日期： | I3: 索引号： | J3: S13
A4: 截止日：202X年12月31日 | D4: 复核人： | G4: 日期： | I4: 页 次：
A5: 序号 | B5: 程序 | G5: 是否适用 | H5: 执行人 | I5: 执行情况说明 | J5: 索引号
A6: 1 | B6: 确定管理层是否恰当利用了专家的工作，考虑下列因素：
A7:  | B7: 与管理层的专家相关的事项的性质和复杂性；
A8:  | B8: 某事项存在的重大错报风险；
A9:  | B9: 审计证据可否从替代来源获得；
A10:  | B10: 管理层的专家工作的性质、范围和目标；
A11:  | B11: 为被审计单位提供相关服务的专家是被审计单位内部专家还是外部专家；
A12:  | B12: 管理层在多大程度上对其专家的工作施加控制和影响；
A13:  | B13: 管理层的专家是否受到技术标准、职业准则或行业要求的约束；
A14:  | B14: 被审计单位对管理层的专家的工作实施的各种控制的性质和范围；
A15:  | B15: 注册会计师对管理层的专家的专长领域拥有的了解和经验；
A16:  | B16: 注册会计师以前与该专家交往的经验。
A17: 2 | B17: 评价管理层的专家的胜任能力、专业素质和客观性 | G17: 是 | J17: S13-1
A18: 2.1 | B18: 考虑以前与专家交往的个人经验；
A19: 2.2 | B19: 与专家进行讨论；
A20: 2.3 | B20: 与熟悉专家工作的其他注册会计师、其他机构或人员进行讨论；
A21: 2.4 | B21: 对专家的资格、会员身份、执业资格或其他形式的外部认证进行了解；
A22: 2.5 | B22: 阅读专家发表的论文或出版的书籍（若适用）；
A23: 2.6 | B23: 利用注册会计师的专家的工作（若适用）； | J23: S12
A24: 2.7 | B24: 评价被审计单位外部专家的客观性
A25:  | B25: 与管理层和该专家讨论可能影响专家客观性的任何利益和关系；
A26:  | B26: 与管理层和该专家讨论各种适用的防范措施（包括适用于该专家的任何职业要求），并评价这些防范措施是否适当；
A27:  | B27: 记录利用与被审计单位存在关联关系的专家的理由，并考虑影响该专家客观性的风险。
A28: 3 | B28: 了解管理层的专家的工作 | G28: 是 | J28: S13-2
A29: 4 | B29: 评价管理层的专家工作的适当性： | G29: 是 | J29: S13-3
A30: 4.1 | B30: 取得管理层专家的工作报告； | J30: S13-3-1
A31: 4.2 | B31: 专家的发现和结论的相关性和合理性，与其他审计证据的一致性； | J31: S13-3
A32: 4.3 | B32: 管理层的专家的发现和结论是否在财务报表中适当反映； | J32: S13-3
A33: 4.4 | B33: 专家的工作使用的重要的假设和方法的相关性和合理性； | J33: S13-3-2
A34: 4.5 | B34: 专家的工作使用的原始数据的相关性、完整性和准确性。 | J34: S13-3-2
A35: 5 | B35: 比较专家以前期间的发现（若适用）与实际结果
A36: 6 | B36: 如果确定将管理层的专家工作用作相关认定的审计证据与从其他来源获取的不一致或对审计证据可靠性存有疑虑，按照《中国注册会计师审计准则第1131号——审计工作底稿》的规定记录如何处理该不一致。

Sheet S13-1 评价胜任能力、专业素质和客观性
A1: 致同会计师事务所
A2: 评价管理层的专家的胜任能力、专业素质和客观性
A3: ='S13 利用管理层的专家形成审计证据程序表'!A3 -> 客户名称： | E3: 编制人： | H3: 日期： | J3: 索引号： | K3: S13-1
A4: ='S13 利用管理层的专家形成审计证据程序表'!A4 -> 截止日：202X年12月31日 | E4: 复核人： | H4: 日期： | J4: 页 次：
A5: 一、审计目标
B6: 对于在编制时利用了管理层的专家的工作的信息，获取充分、适当的审计证据，确定管理层的专家的工作是否足以实现审计目的。 | L6: 管理层的专家，是指在会计、审计以外的某一领域具有专长的个人或组织，其工作被管理层利用以协助编制财务报表。
A7: 二、审计过程：
A8: 评价管理层的专家的胜任能力、专业素质和客观性
B9: 项目 | H9: 记录
B10: 管理层的专家姓名/组织名称
B11: 管理层的专家在其领域的专长
B12: 体现专家胜任能力的证书、执业资质或专业组织的认可文件
B13: 管理层聘请的资产评估机构（若有）是否具有证券期货相关业务资格 | L13: 利用资产评估机构的工作辅助开展商誉减值测试时，公司应聘请具有证券期货相关业务资格的资产评估机构，明确约定该工作用于商誉减值测试。
B14: 管理层的专家的行业声誉
B15: 管理层的专家在专业领域中的经验
B16: 管理层的专家需要遵守的技术标准、职业准则或行业要求（如职业团体或行业协会的职业道德守则和其他会员要求，特许机构提出的认证标准）以及法律法规的要求等
B17: 影响管理层的专家客观性的情况（如自身利益、自我评价、过度推介、密切关系和外在压力等）及防范措施（如管理层的专家所属的职业团体、法律法规的要求、质量控制政策和程序）
B18: 影响被审计单位外部专家客观性的情况（如经济利益、商业关系和私人关系、提供的其他服务等）及防范措施（包括适用于该专家的任何职业要求）是否适当
B20: 结论：未识别出导致对管理层的专家的胜任能力、专业素质和客观性产生疑虑的事项或情况。

Sheet S13-2 了解专家的工作
A1: 致同会计师事务所
A2: 了解管理层的专家的工作
A3: ='S13-1 评价胜任能力、专业素质和客观性'!A3 -> 客户名称： | E3: ='S13-1 评价胜任能力、专业素质和客观性'!E3 -> 编制人： | H3: ='S13-1 评价胜任能力、专业素质和客观性'!H3 -> 日期： | J3: 索引号： | K3: S13-2
A4: ='S13-1 评价胜任能力、专业素质和客观性'!A4 -> 截止日：202X年12月31日 | E4: 复核人： | H4: 日期： | J4: 页 次：
A5: 一、审计目标
B6: 对于在编制时利用了管理层的专家的工作的信息，获取充分、适当的审计证据，确定管理层的专家的工作是否足以实现审计目的。
A7: 二、审计过程：
A8: 了解管理层的专家的工作
B9: 项目 | H9: 记录
B10: 管理层的专家报告的名称和索引
B11: 与审计相关的、管理层的专家专长领域的进一步细分信息
B12: 职业准则或其他准则以及法律法规是否适用
B13: 管理层的专家使用的假设和方法
B14: 上述假设和方法在该专家的专长领域是否得到普遍认可
B15: 管理层的专家使用的内外部数据或信息的性质
B16: 管理层与其外部专家的约定书或协议的名称和索引
B17: 询问被审计单位的内部专家、管理层的其他人员或评价被审计单位与其外部专家的协议，以了解：
B18:  管理层的专家工作的性质、范围和目标（询问被审计单位的内部专家或评价被审计单位与其外部专家的协议） | L18: 评估机构应明确将用于商誉减值测试目的的评估事项约定为以财务报告为目的的评估，并明确约定涉及商誉减值测试的评估基准日、评估对象、评估范围、价值类型等重要要素。
B19:  管理层和管理层的专家各自的角色和责任
B20:  管理层和管理层的专家沟通的性质、时间安排和范围（包括由该专家提交的各种报告的形式）
B22: 结论：管理层的专家的工作对实现财务报告目的是适当的。

Sheet S13-3 评价管理层专家工作的适当性
A1: 致同会计师事务所
A2: 评价管理层专家工作的适当性
A3: ='S13-1 评价胜任能力、专业素质和客观性'!A3 -> 客户名称： | E3: ='S13-1 评价胜任能力、专业素质和客观性'!E3 -> 编制人： | H3: ='S13-1 评价胜任能力、专业素质和客观性'!H3 -> 日期： | J3: 索引号： | K3: S13-3
A4: ='S13-1 评价胜任能力、专业素质和客观性'!A4 -> 截止日：202X年12月31日 | E4: 复核人： | H4: 日期： | J4: 页 次：
A5: 一、审计目标
B6: 对于在编制时利用了管理层的专家的工作的信息，获取充分、适当的审计证据，确定管理层的专家的工作是否足以实现审计目的。
A7: 二、审计过程：
A8: 评价管理层专家工作的适当性 | L8: 【例如：用于商誉减值测试目的的评估事项应约定为以财务报告为目的的评估，并明确约定涉及商誉减值测试的评估基准日、评估对象、评估范围、价值类型等重要要素。不得以股权、企业价值的评估报告代替以财务报告为目的的评估报告。】
B9: 项目 | E9: 记录
B10: 取得管理层专家的工作报告 | E10: 管理层专家的工作报告详见S13-3-1 | L10: （1）财务报告目的减值测试报告、PPA合并对价分摊报告、企业价值或某项资产估值报告、土地估价报告、矿业权评估报告、 珠宝玉石评估报告等；（2）精算报告；（3）法律意见书；（4）税务专家工作报告等。
B11: 评价管理层专家的工作报告合规性
B12: 管理层的专家的发现和结论的相关性和合理性，与其他审计证据的一致性 | L12: 【例如：专家的工作结果或结论是否与历史数据、运营计划、商业机会、行业数据、行业研究报告、宏观经济运行状况，以及利用观察、询问、访谈、核对、函证、监盘、勘查、书面审查、实地调查等方式取得的证据相符】
B13: 管理层的专家的发现和结论是否在财务报表中适当反映，相关索引 | L13: 【例如：在披露商誉减值金额的同时，详细披露商誉减值测试的过程与方法，包括但不限于可收回金额的确定方法、重要假设及其合理理由、关键参数（如预计未来现金流量现值时的预测期增长率、稳定期增长率、利润率、折现率、预测期等）及其确定依据等信息。】
B14: 管理层的专家的工作涉及的重要假设和方法的相关性和合理性 | E14: 详见S13-3-2/S13-3-3/S13-3-4 | L14: 【例如：需充分考虑假设和方法与市场、行业情况、历史信息、行业惯例、价值类型的一致性。】
B15: 管理层的专家的工作使用的原始数据的相关性、完整性和准确性 | E15: 详见S13-3-2/S13-3-3/S13-3-4 | L15: 【例如：原始数据是否经审计，行业数据是否来源于独立第三方】
A17: 三、审计说明：
B18: 将管理层的专家工作用作相关认定的审计证据是适当的。
B19: 利用专家对管理层的专家的工作进行了评价，详见S12-3-1/S12-3-2/S12-3-3/S12-3-4。
A20: 四、审计结论：
B21: 管理层的专家的工作可以用作审计证据。
B22: 或者：管理层的专家的工作不能作为审计证据。（应说明原因并考虑是否追加适当的审计程序）
B25: 编制说明：
B26: 1、管理层的专家，是指在会计、审计以外的某一领域具有专长的个人或组织，其工作被管理层利用以协助编制财务报表。
B27: 2、如果用作审计证据的信息在编制时利用了管理层的专家的工作，注册会计师应当考虑管理层的专家的工作对实现注册会计师目的的重要性，并在必要的范围内实施下列程序：
B28: （一）评价管理层的专家的胜任能力、专业素质和客观性；
B29: （二）了解管理层的专家的工作；
B30: （三）评价将管理层的专家的工作用作相关认定的审计证据的适当性。

Sheet S13-3-1 管理层专家的报告
A1: 致同会计师事务所
A2: 管理层专家的报告
A3: ='S13-1 评价胜任能力、专业素质和客观性'!A3 -> 客户名称： | E3: ='S13-1 评价胜任能力、专业素质和客观性'!E3 -> 编制人： | H3: ='S13-1 评价胜任能力、专业素质和客观性'!H3 -> 日期： | J3: 索引号： | K3: S13-3-1
A4: ='S13-1 评价胜任能力、专业素质和客观性'!A4 -> 截止日：202X年12月31日 | E4: 复核人： | H4: 日期： | J4: 页 次：
A6: 管理层专家的报告

Sheet S13-3-2 评价管理层专家工作的适当性
A1: 致同会计师事务所
A2: 评价管理层的专家的工作过程及其结果或结论
A3: ='S13-1 评价胜任能力、专业素质和客观性'!A3 -> 客户名称： | E3: ='S13-1 评价胜任能力、专业素质和客观性'!E3 -> 编制人： | H3: ='S13-1 评价胜任能力、专业素质和客观性'!H3 -> 日期： | J3: 索引号： | K3: S13-3-2
A4: ='S13-1 评价胜任能力、专业素质和客观性'!A4 -> 截止日：202X年12月31日 | E4: 复核人： | H4: 日期： | J4: 页 次：
A6: 一、评价管理层的专家的工作过程（主要适用于减值测试及公允价值计量）
B7: 若利用专家（注册会计师的专家）的工作，则该底稿被S12-3-1或S12-3-2替代。
B8: 1、评估对象及评估范围是否与评估目的相匹配
L9: 评估机构应明确将用于商誉减值测试目的的评估事项约定为以财务报告为目的的评估。不得以股权、企业价值的评估报告代替以财务报告为目的的评估报告。
B11: 2、评估结果或价值类型是否与报告目的相符 | L11: （如商誉减值测试、公允价值计量）
B12: 将原收购的标的公司“全部资产和全部负债组成的资产组（股东权益）”界定为评估对象采用股东权益价值方法，不符合会计准则的要求。商誉减值测试的范围不是原标的公司的股权，而是被分摊商誉的资产组或资产组组合。 | L12: 当聘请的资产评估机构未对商誉所在资产组或资产组组合的可收回金额发表专门意见时，会计师事务所应着重考虑专家工作对审计工作的支持程度，并对专家工作成果进行必要调整，以适应财务报表审计目的。
B14: 3、评估基准日是否符合经济行为需要
B17: 4、评估假设与评估目的、评估方法的选择是否相符，是否合理
B20: 5、评估方法及其选择是否合理
L21: 将原收购的标的公司“全部资产和全部负债组成的资产组（股东权益）”界定为评估对象采用股东权益价值方法，不符合会计准则的要求。商誉减值测试的范围不是原标的公司的股权，而是被分摊商誉的资产组或资产组组合。
B23: 6、评价收益法/使用价值选用的参数和具体处理
B24: （1）盈利预测是否有可靠的数据来源，是否与历史数据、运营计划、商业机会、行业数据、行业研究报告、宏观经济运行状况相符
L25: 对未来现金净流量预测时，应以资产的当前状况为基础，以税前口径为预测依据，并充分关注选取的关键参数（包括但不限于销量、价格、成本、费用、预测期增长率、稳定期增长率）是否有可靠的数据来源，是否与历史数据、运营计划、商业机会、行业数据、行业研究报告、宏观经济运行状况相符；与此相关的重大假设是否与可获取的内部、外部信息相符，在不符时是否有合理理由支持。
B27: （2）对于营运资金的口径判断是否与非经营性资产负债一致
L28: 若在确定可收回金额的未来现金流量时考虑了期初营运资金的影响，则资产组的账面价值中也应包括营运资金，即资产组不得扣除与经营相关的流动资产和流动负债。
B30: （3）资本性支出预测是否与预算、运营计划一致
L31: 资本性支出=资产性更新投资+新增长期资产投资（新增固定资产或其他长期资产）
B33: （4）折旧摊销费用预测是否合理
B36: （5）收益期（增长期及永续期）选择是否合理
L37: 在确定未来现金净流量的预测期时，应建立在经管理层批准的最近财务预算或预测数据基础上，原则上最多涵盖5年。
B39: （6）可比公司或可比交易的选择是否合理
B42: （7）折现率计算是否合理
L43: 对折现率预测时，是否与相应的宏观、行业、地域、特定市场、特定市场主体的风险因素相匹配，是否与未来现金净流量均一致采用税前口径。
B45: （8）终值的处理是否合理
L46: 假设使用后续现金流量永续增长模型，根据销售增长率估计现金流量增长率。绝大多数可以持续生存的企业，其销售增长率可以按宏观经济增长率估计。
B48: （9）对关键假设（如增长率、毛利率、折现率等）的敏感性分析结果
B54: 7、评价市场法选用的参数和具体处理
B55: （1）价值乘数的选择是否合理
B58: （2）可比公司或可比交易的选择是否与收益法中一致，是否合理
B61: （3）价值乘数的计算时间是否合理
B64: （4）对价值乘数的调整是否合理
B67: （5）对关键假设的敏感性分析结果
B70: 8、评价成本法选用的参数和具体处理
B71: （1）采用成本法是否恰当
B72: 重置成本法适用于企业价值主要来源于其资产的公允价值的情形。
B74: （2）重置成本的来源
...

Sheet S13-3-3 评价管理层专家工作的适当性(股份支付)
A1: 致同会计师事务所
A2: 评价管理层的专家的工作过程及其结果或结论
A3: ='S13-1 评价胜任能力、专业素质和客观性'!A3 -> 客户名称： | E3: ='S13-1 评价胜任能力、专业素质和客观性'!E3 -> 编制人： | H3: ='S13-1 评价胜任能力、专业素质和客观性'!H3 -> 日期： | J3: 索引号： | K3: S13-3-3
A4: ='S13-1 评价胜任能力、专业素质和客观性'!A4 -> 截止日：202X年12月31日 | E4: 复核人： | H4: 日期： | J4: 页 次：
A6: 一、评价管理层的专家的工作过程（主要适用于股份支付）
B7: 若利用专家（注册会计师的专家）的工作，则该底稿被S12-3-1或S12-3-3替代。
B8: 1、估值方法是否与估值对象相匹配
B9: 对于股票期权，通常使用期权定价模型计算看涨期权的价值。 对于限制性股票，非市场可行权条件（服务条件、业绩条件等）不应在确定授予日公允价值时予以考虑，因此限制性股票的锁定因素并不影响其公允价值的确定。但解锁后，对于部分高管人员所持股份的限售条款则属于非可行权条件，可以在计量公允价值时予以考虑。
B11: 2、估值基准日是否符合经济行为需要
B12: 应评估权益工具授予日的公允价值。授予日，是指股份支付协议获得批准的日期，是企业和另一方（包括职工）同意一项以股份为基础的支付安排的日期，即企业和交易对方对安排的条款和条件有着共同理解的日期。
B14: 3、是否恰当划分为多个独立的期权估值
B15: 对于“一次授予、分期行权”的股份支付，其在授予日一次授予职工若干权益工具，之后每期分批达到可行权。每个批次是否可行权的结果通常是相对独立的，即每一期是否达到可行权条件并不会直接决定其他几期是否能够达到可行权条件，在会计处理时应将其作为几个独立的股份支付计划处理。即此时需要分别计算各个期权的公允价值。
B17: 4、评价期权定价模型选用的参数和具体处理
B18: （1）标的股份的现行价格是否合理
B19: 对于上市公司股份，应来自于授予日的收盘价（即期权对应标的股份在活跃市场中的报价）； 对于非上市股权（包括交易不活跃的新三板股票），应合理考虑入股时间阶段、业绩基础与变动预期、市场环境变化、行业特点及市盈率与市净率等因素的影响；可优先参考熟悉情况并按公平原则自愿交易的各方最近达成的入股价格或相似股权价格确定公允价值，如近期合理的PE入股价；也可采用恰当的估值技术确定公允价值，但要避免采取有争议的、结果显失公平的估值技术或公允价值确定方法，如明显增长预期下按照成本法评估的每股净资产价值或账面净资产。
B21: （2）期权的行权价格是否激励计划中的约定一致
B24: （3）期权有效期的确定是否合理
... B27: （4）股价预计波动率的计算是否合理
B28: 期权定价模型中所用的波动率的度量，是一段时间内股份的连续复利回报率的年度标准差。股价预计波动率通常根据与期权的预计期限（考虑期权剩余期限和预计提早行权的影响）大体相当的最近一个时期内企业股价的历史波动率计算。 如果企业因新近上市而没有历史波动率的充分信息，应按可获得交易活动数据的最长期间计算历史波动率，也可考虑类似企业在类似阶段可比期间的历史波动率。如果企业是非上市企业，在估计预计波动率时没有历史信息可循，可考虑类似上市企业股价的历史或内含波动率。 | L28: 历史波动率是为了模拟未来，若公司自身股票价格有较长的历史记录，且波动率变化不大，应使用自身波动率，而不是所属板块的波动率。
B30: （5）股份的预计股利率的计算是否合理
B31: 预计股利应以公开可获取的信息为基础。不支付股利且没有支付股利计划的企业应假设预计股利收益率为零。
B33: （6）期权有效期内的无风险利率的选择是否合理
B34: 无风险利率应当用无违约风险的固定证券收益来估计，例如与期权到期日相同的国债利率，如果没有相同期限的，可选择期间最接近的国债的利率。
B36: 5、限制性股票是否恰当考虑锁定因素的影响
B37: （1）锁定期限制的是否恰当处理
B38: 按照我国上市公司限制性股票股权激励的常见条款，锁定期实质上相当于等待期，解锁日为可行权日，解锁条件为非市场可行权条件（服务条件、业绩条件等）。根据股份支付准则，非市场可行权条件不应在确定授予日公允价值时予以考虑，因此限制性股票的锁定因素并不影响其公允价值的确定。 | L38: 限制性股票的单位成本＝限制性股票的公允价值－授予价格。对于非董事、高级管理人员的激励，限制性股票的公允价值＝授予日收盘价；对于董事、高级管理人员的激励，限制性股票的公允价值 = 授予日收盘价－限制性因素。
B40: （2）解锁后限售条款的是否恰当处理
B41: 解锁后，对于部分高管人员所持股份的限售条款则属于非可行权条件，可以在计量公允价值时予以考虑。
B43: 6、评价股份支付成本费用的分摊
B44: （1）是否恰当划分为多个独立的期权分摊费用
B45: 对于“一次授予、分期行权”的股份支付，每个批次是否可行权的结果通常是相对独立的，即每一期是否达到可行权条件并不会直接决定其他几期是否能够达到可行权条件，在会计处理时应将其作为几个独立的股份支付计划处理。相当于职工同时在为多个期权工作，各年费用递减。每年按当年等待时间长度占总等待期长度的比例分摊各期的成本费用。
B47: （2）是否恰当考虑可行权人数的变动
B48: 在各个资产负债表日，应根据最新取得的可行权人数变动、业绩指标完成情况等后续信息，修正预计可行权的股票期权数量，并以此为依据确认各期应分摊的费用。
B50: （3）等待期内费用分摊是否正确
B51: 等待期是指可行权条件得到满足的期间，对于可行权条件为规定服务期间的股份支付，等待期为授予日至可行权日的期间（假设服务从授予日开始）。
B53: 7、作废与主动取消的会计处理是否正确
B54: （1）被动作废的会计处理是否正确
B55: 如果权益工具由于一项服务条件或者非市场的业绩条件的结果未被授予，则对于接受的商品或服务累计确认的费用为零。
... B64: （2）与同行业惯例是否一致
A67: 二、评价管理层的专家工作的结果或结论
...

Sheet S13-3-4 评价管理层专家工作的适当性(金融工具公允价值)
A1: 致同会计师事务所
A2: 评价管理层的专家的工作过程及其结果或结论
A3: ='S13-1 评价胜任能力、专业素质和客观性'!A3 -> 客户名称： | E3: ='S13-1 评价胜任能力、专业素质和客观性'!E3 -> 编制人： | H3: ='S13-1 评价胜任能力、专业素质和客观性'!H3 -> 日期： | J3: 索引号： | K3: S13-3-4
A4: ='S13-1 评价胜任能力、专业素质和客观性'!A4 -> 截止日：202X年12月31日 | E4: 复核人： | H4: 日期： | J4: 页 次：
A6: 一、评价管理层的专家的工作过程（主要适用于金融工具公允价值）
B7: 若利用专家（注册会计师的专家）的工作，则该底稿被S12-3-1或S12-3-4替代。
B8: 1、估值方法是否与估值对象相匹配
B11: 2、估值基准日是否符合经济行为需要
B12: 公允价值，是指市场参与者在计量日发生的有序交易中，出售一项资产所能收到或者转移一项负债所需支付的价格。
B14: 3、是否恰当考虑流动性折扣
B15: 根据《证券公司金融工具估值指引》（中证协发〔2018〕216号），通过公开、非公开等方式取得且有明确限售期的股票，在限售期内，应以证券交易所上市交易的同一股票的公允价值为基础，引入流动性折扣进行估值。流动性折扣可依据第三方估值机构提供的数据，或采用看跌期权法以及其他合理的估值方法分析确定。 | L15: 直线摊销（即根据《关于证券投资基金执行<企业会计准则>估值业务及份额净值计价有关事项的通知（证监会计字[2007]21号）》中的公式）已被《中国证监会关于证券投资基金估值业务的指导意见》（公告〔2017〕13号）废止。
B17: 4、评价期权定价模型选用的参数和具体处理
B18: （1）标的股份的现行价格是否合理
B19: 对于上市公司股份，应来自于授予日的收盘价（即期权对应标的股份在活跃市场中的报价）； 对于非上市股权（包括交易不活跃的新三板股票），应合理考虑入股时间阶段、业绩基础与变动预期、市场环境变化、行业特点及市盈率与市净率等因素的影响；可优先参考熟悉情况并按公平原则自愿交易的各方最近达成的入股价格或相似股权价格确定公允价值，如近期合理的PE入股价；也可采用恰当的估值技术确定公允价值，但要避免采取有争议的、结果显失公平的估值技术或公允价值确定方法，如明显增长预期下按照成本法评估的每股净资产价值或账面净资产。 | L19: 看跌期权价值的估算根据《证券投资基金投资流通受限股票估值指引（试行）》（中基协发〔2017〕6号），可以使用平均价格亚式期权模型（“AAP模型”）。
B21: （2）期权的行权价格是否恰当选择
B24: （3）期权有效期的确定是否合理
B27: （4）股价预计波动率的计算是否合理
B28: 期权定价模型中所用的波动率的度量，是一段时间内股份的连续复利回报率的年度标准差。股价预计波动率通常根据与期权的预计期限（考虑期权剩余期限和预计提早行权的影响）大体相当的最近一个时期内企业股价的历史波动率计算。 如果企业因新近上市而没有历史波动率的充分信息，应按可获得交易活动数据的最长期间计算历史波动率，也可考虑类似企业在类似阶段可比期间的历史波动率。如果企业是非上市企业，在估计预计波动率时没有历史信息可循，可考虑类似上市企业股价的历史或内含波动率。 | L28: 历史波动率是为了模拟未来，若公司自身股票价格有较长的历史记录，且波动率变化不大，应使用自身波动率，而不是所属板块的波动率。
B30: （5）股份的预计股利率的计算是否合理
B31: 预计股利应以公开可获取的信息为基础。不支付股利且没有支付股利计划的企业应假设预计股利收益率为零。
B33: （6）期权有效期内的无风险利率的选择是否合理
B34: 无风险利率应当用无违约风险的固定证券收益来估计，例如与期权到期日相同的国债利率，如果没有相同期限的，可选择期间最接近的国债的利率。
B36: 5、评价收益法选用的参数和具体处理
B37: （1）未来现金流是否与对本金和利息的预期一致，或盈利预测是否有可靠的数据来源，是否与历史数据、运营计划、商业机会、行业数据、行业研究报告、宏观经济运行状况相符
L38: 对未来现金净流量预测时，应以资产的当前状况为基础，以税前口径为预测依据，并充分关注选取的关键参数（包括但不限于销量、价格、成本、费用、预测期增长率、稳定期增长率）是否有可靠的数据来源，是否与历史数据、运营计划、商业机会、行业数据、行业研究报告、宏观经济运行状况相符；与此相关的重大假设是否与可获取的内部、外部信息相符，在不符时是否有合理理由支持。
B40: （2）对于营运资金的口径判断是否与非经营性资产负债一致（若适用）
B43: （3）资本性支出预测是否与预算、运营计划一致（若适用）
B46: （4）折旧摊销费用预测是否合理（若适用）
B49: （5）收益期（增长期及永续期）选择是否合理（若适用）
L50: 在确定未来现金净流量的预测期时，应建立在经管理层批准的最近财务预算或预测数据基础上，原则上最多涵盖5年。
B52: （6）可比公司或可比交易的选择是否合理
B55: （7）市场收益率/折现率计算是否合理
L56: 对折现率预测时，是否与相应的宏观、行业、地域、特定市场、特定市场主体的风险因素相匹配，是否与未来现金净流量均一致采用税前口径。
B58: （8）终值的处理是否合理
B61: （9）是否恰当考虑持股情况、流动性折扣等因素
B64: （10）对关键假设（如增长率、毛利率、折现率等）的敏感性分析结果
B67: 6、评价市场法选用的参数和具体处理
B68: （1）价值乘数的选择是否合理
B71: （2）可比公司或可比交易的选择是否与收益法中一致，是否合理
L72: 采用最近融资价格法评估非上市公司股权公允价值时，需充分考虑时间因素。 如果被投资单位近期进行过新一轮融资的，可以最近融资价格作为非上市公司股权估值。
...
