Workbook

Sheet 底稿目录
A1: 底稿开列时，可先在以下单元格填写有关内容，以便其他底稿引用有关数据：
A2: 被审计单位： | D2: 序号 | E2: 内容 | F2: 索引表
A3: 截止日：202X年12月31日 | D3: 1 | E3: 应交税费实质性程序表 | F3: N2A
A4: 编制人： | D4: 2 | E4: 应交税费审定表 | F4: N2-1
A5: 编制日期： | D5: 3 | E5: 附注披露信息（上市公司）
A6: 复核人： | D6: 4 | E6: 附注披露信息（国企）
A7: 复核日期： | D7: 5 | E7: 应交税费明细表 | F7: N2-2
D8: 6 | E8: 调整分录汇总表 | F8: N2-3
A9: 关于工作底稿与审计程序索引号对应的说明 | D9: 7 | E9: 税收政策检查 | F9: N2-4
A10: 1.编制的审计工作底稿应与审计程序对应。审计项目组应根据被审计单位实际情况和风险评估情况在实质性程序表中裁剪、修改或增加审计程序，根据实际执行的审计程序完成相应审计工作底稿，编制的工作底稿中应按自然顺序依次编制索引号，并通过唯一的索引号将与实质性程序表中的程序对应关联（即将工作底稿的索引号填入实质性程序表中的底稿索引号列）。 | D10: 8 | E10: 应交税金认定表 | F10: N2-5
D11: 9 | E11: 增值税测算表 | F11: N2-6
D12: 10 | E12: 出口退税核对表 | F12: N2-7
D13: 11 | E13: 应交其他税费测算表 | F13: N2-8
A14: 2.获取的支持性证据应与审计底稿或程序对应。审计项目组在完成底稿时获取的支持性证据应根据底稿索引号编制下一级按自然顺序排序的索引号（如D1-2-1、D1-2-2、……），并在底稿中说明引用的支持性证据、关联索引号。 | D14: 12 | E14: 房产税测算表 | F14: N2-9
D15: 13 | E15: 土地增值税测算表 | F15: N2-10
D16: 14 | E16: 应交税费检查表 | F16: N2-11
A17: 3.工作底稿索引号的编码规则：实质性程序索引号按循环从“D”到“N”,循环内账户以顺序号排列，模板中底稿索引号按账户顺序+自然数顺序（即模板中索引号按二级自然顺序排列，如D1-1、D1-2、D1-3、……D1-N）。

Sheet 应交税费审计程序表N2A
A1: 致同会计师事务所
A2: 应交税费实质性程序表
A3: =底稿目录!A2 | C3: =底稿目录!A4 | E3: =底稿目录!A5 | H3: 索引号： | I3: =底稿目录!F3
A4: =底稿目录!A3 | C4: =底稿目录!A6 | E4: =底稿目录!A7 | H4: 页次：
A5: 一、本账户涉及的科目
A6: 应交税费
A7: 二、审计目标与财务报表认定的关系
A8: 审计目标 | G8: 财务报表的认定
A9: A.资产负债表中记录的应交税费是存在的，且已记录于恰当的账户 | G9: 存在
A10: B.所有应当记录的货币应交税费均已记录，所有应当包括在财务报表中的相关披露均已包括 | G10: 完整性
A11: C.记录的应交税费是被审计单位应当履行的现时义务 | G11: 权利和义务
A12: D.应交税费以恰当的金额包括在财务报表中，与之相关的计价或分摊调整已恰当记录，相关披露已得到恰当计量和描述 | G12: 准确性、计价和分摊
A13: E.应交税费已被恰当地汇总或分解且表述清楚，相关披露在按照企业会计准则的编制基础下是相关的、可理解的 | G13: 列报
A14: 三、计划实施的实质性程序
A15: 序号 | B15: 审计程序 | C15: 程序分类 | D15: 财务报表的认定 | I15: 底稿索引号
D16: 存在 | E16: 完整性 | F16: 权利和义务 | G16: 准确性、计价和分摊 | H16: 列报 | J16: 根据被审计单位实际情况和风险评估情况裁剪、修改或增加审计程序
A17: 1 | B17: 获取应交税费明细表,编制审定表，并完成下面工作。 （1）复核加计正确，与总账、明细账合计数核对是否相符，期初余额与上期审定期末余额是否相符； （2）分析应交税费存在借方余额的项目，查明原因，判断是否由被审计单位预缴税款引起。 （3）注意印花税、耕地占用税以及其他不需要预计应缴数的税金有无误记入应交税费项目。 （4)如期初存在延期纳税的事项，检查是否经过税务机关批准。是否存在长期欠缴的应交税金，关注合理性。 | C17: 常规★ | D17: √ | E17: √ | G17: √ | I17: N2-1 /N2-2
A18: 2 | B18: 在使用手工编制、自定义信息报告、系统生成的非固定格式报告等由被审计单位生成的信息时，测试有关信息准确性和完整性，并考虑针对编制和维护由被审计单位生成的信息的相关控制实施控制测试，以评价该信息是否能够为实现审计目的提供基础。 | C18: 常规★ | E18: √ | G18: √ | I18: T1 | J18: 可参见《审计手册》4.2.6，由被审计单位生成的信息可能是由系统生成的、或手工编制的、或二者兼而有之的方式生成的。例如，由被审计单位生成的信息可能包括： • 不涉及自定义的、由系统生成的报告（如，固定格式报告）； • 可能通过人工自定义的、由系统生成的报告，例如，（计算机）查询信息或特别定制的报告； • 手工编制的信息，例如，汇总信息的电子表格或用以支持分配、计算以及调节的电子表格； • 其他系统生成或手工编制的信息，例如，由被审计单位编制的客户发票； • 通过影印、拍摄、扫描或其他方式转换成电子形式的文件记录。
A19: 3 | B19: 获取前期纳税申报表和其他有持续影响的税收文件资料，确认应交税费余额与纳税申报表税务机关认定金额一致；检查期初金额在本期缴纳情况；如果发现税收申报等存在异常，考虑向税务专家咨询。（适用于首次承接） | C19: 备选 | D19: √ | E19: √ | F19: √ | G19: √ | J19: 由被审计单位生成的信息不包括： • 总分类账或明细分类账、试算平衡表、或经审计的财务报表； • 第三方（除了服务机构）的报表或报告，例如，原始银行对账单，或函证的回函； • 外部数据（例如，第三方发布的数据，如，定价来源）。
A20: 4 | B20: 取得被审计单位的纳税鉴定、纳税通知、减免税批准文件等，了解被审计单位适用的税种、附加税费、计税（费）基础、税（费）率，以及征、免、减税（费）的范围与期限。如果被审计单位适用特定的税基式优惠或税额式优惠、或减低适用税率的，且该项税收优惠需办理规定的审批或备案手续的，应检查相关的手续是否完整、有效。连续接受委托时，关注其变化情况。 | C20: 常规★ | E20: √ | G20: √ | I20: N2-4 | J20: 应交税费中的由被审计单位生成的信息例如：发票清单、报税清单等
A21: 5 | B21: 取得税务部门汇算清缴或其他确认文件、有关政府部门的专项检查报告、税务代理机构专业报告、被审计单位纳税申报资料等，分析其有效性，并与上述明细表及账面数据进行核对。对于超过法定交纳期限的税费，取得主管税务机关的批准文件。确定相关税务调整是否恰当记录，确定重大罚款或其他涉税负债的会计处理是否正确。 | C21: 常规★ | E21: √ | F21: √ | G21: √ | I21: N2-5
A22: 6 | B22: 检查应交增值税： （1）获取或编制应交增值税测算表，复核加计正确，并与明细账核对相符。 （2）检查适用税率是否符合税法规定。 （3）将“应交增值税测算表”与被审计单位增值税纳税申报表进行核对，检查进项、销项的入账与申报期间是否一致，金额是否相符，增值税纳税申报表有无经税务机关认定。 (4)通过“原材料”等相关科目匡算增值税进项税是否合理。 (5)抽取一定期间的进项税抵扣汇总表，与应交增值税明细表相关数额合计数核对，如有差异，查明原因并作适当处理。 (6)检查重要的进项税发票、海关完税凭证、收购凭证或运费发票等支持性文件，与网上申报系统进行核对,并注意进口货物、购进的免税农产品或废旧物资、支付运费、接受投资或捐赠、接受应税劳务等应计的进项税额是否按规定进行了会计处理,检查某些特殊事项的进项税处理是否正确（如存货改变用途或发生非常损失应计的进项税转出数的计算），确定会计处理是否正确。 (7)根据与增值税销项税额相关的账户审定的有关数据，复核销项税额存货销售,或视同销售（例如，将存货用于投资、无偿馈赠他人、分配给股东（或投资者）应计的销项税额，以及将自产、委托加工的产品用于非应税项目）的计税依据确定是否正确，以及应计的销项税额的计算是否正确，确定会计处理是否正确。 | C22: 常规★ | D22: √ | E22: √ | G22: √ | I22: N2-6
A23: 7 | B23: 根据普通发票或增值税发票申报表，估算全年的收入，与实际入账收入金额核对，并检查是否存在虚开发票或已销售但未开发票的情况。 | C23: IPO/上市公司/新三板/舞弊应对 | G23: √ | I23: D4-23
A24: 8 | B24: 对于采用差额纳税的交通运输业、物流辅助服务、融资租赁、代理行业等行业，应检查扣除的价款是否符合税务机关的规定，计算是否正确，会计处理是否适当。 | C24: 备选 | G24: √
A25: 9 | B25: 获取《出口货物退（免）税申报表》及办理出口退税有关凭证，复核出口货物退税的计算是否正确，是否按规定进行了会计处理。 | C25: 备选 | G25: √ | I25: N2-7
A26: 10 | B26: 对经主管税务机关批准实行核定征收率征收增值税的被审计单位，检查是否按照有关规定正确执行。 | C26: 常规★ | G26: √
A27: 11 | B27: 将资产负债表日的应交增值税或可抵扣额与支持性文件进行核对，关注期后的缴纳或支付情况。 | C27: 常规★ | D27: √ | G27: √
A28: 12 | B28: 对于应交和已交消费税、资源税、城建税、教育费附加、地方教育费附加、车船税、房产税、土地使用税等其他税项进行测算，核对计提金额是否正确，会计处理是否适当。 （1）结合税金及附加等项目的审计，根据审定的当期营业额、或其他计税基础等相关数据，检查各项税费的计税依据是否正确，适用税率是否符合税法规定，是否按规定进行了会计处理，并分项复核本期应交数。 （2）检查本期已交税款，确定已交税款的正确性。 （3）与纳税申报表核对，复核应交税费余额的合理性。 （4）对于车船使用税和房产税： ①获取被审计单位自有车船数量、吨位（或座位）及自有房屋建筑面积、用途、造价（购入原价）、购建年月等资料，并与固定资产（含融资租入固定资产）明细账复核一致；了解其使用、停用时间及其原因等情况； ②通过审核本期完税单，检查其是否如实申报和按期缴纳，是否按规定进行了会计处理。 | C28: 常规★ | D28: √ | E28: √ | G28: √ | I28: N2-8 /N2-9
B29: 对于土地增值税进行测算，核对计提金额是否正确，会计处理是否适当。 （1）根据审定的预售房地产的预收账款，复核预交税款是否准确。 （2）对符合项目清算条件的房地产开发项目，检查被审计单位是否按规定进行土地增值税清算；如果被审计单位已聘请中介机构办理土地增值税清算鉴证的，应检查、核对相关鉴证报告。 （3）如果被审计单位被主管税务机关核定征收土地增值税的，应检查、核对相关的手续。 | C29: 备选 | D29: √ | E29: √ | G29: √ | I29: N2-10
A30: 13 | B30: 检査矿产资源补偿费等的计算是否正确，是否按规定进行了会计处理 | C30: 备选 | G30: √
A31: 14 | B31: 结合所得税底稿，复核应交企业所得税的计算是否正确，是否按规定进行了会计处理；抽查本期已交所得税资料，确定已交数的正确性。汇总纳税企业所得税汇算清缴，并按税法规定追加相应的程序。 | C31: 常规★ | G31: √
A32: 15 | B32: 抽查应交税费相关的凭证，检查是否有合法依据，会计处理是否正确。 | C32: 常规★ | D32: √ | F32: √ | G32: √ | I32: N2-11
A33: 16 | B33: 确定当期企业的各项税费申报计缴情况是否被税务机关检查，如是，则对于已完成的检查，获取检查报告复印件及税务部门对额外金额的评估。对于正在进行的检查，确定是否需要额外的预提。 | C33: 常规★ | E33: √ | F33: √ | G33: √
A34: 17 | B34: 考虑取得税务机关出具的纳税证明文件的复印件，并与网上电子数据核对。检查发票等重要原始凭证时，关注销售客户有无异常的注册地、联系方式、银行账号等情况，必要时通过全国发票系统检查各项税费发票的真实性。 | C34: IPO/上市公司/新三板/舞弊应对 | D34: √ | E34: √ | F34: √ | G34: √
A35: 18 | B35: 根据评估的舞弊风险等因素增加的审计程序。 | C35: IPO/上市公司/新三板/舞弊应对
A36: 19 | B36: 检查应交税费是否已按企业会计准则或其他适用的规定在财务报表中做出恰当列报和披露。 | C36: 常规★ | I36: A1-1/A1-15 /A1-16

Sheet 应交税费审计程序表O1A （原底稿）
A1: 致同会计师事务所
A2: 应交税费实质性程序表
A3: =底稿目录!A2 | D3: =底稿目录!A4 | G3: =底稿目录!A5 | J3: 索引号：O1A
A4: =底稿目录!A3 | D4: =底稿目录!A6 | G4: =底稿目录!A7 | J4: 页 次：
A5: 一、本账户涉及的科目
A6: 应交税费
A7: 二、重大错报风险需从实质性程序获取的保证程度
A8: 审计目标与认定对应关系 | D8: 财务报表的认定 | I8: 信赖/不信赖/不适用 | J8: 索引号
D9: 存在 | E9: 完整性 | F9: 权利和义务 | G9: 计价和分摊 | H9: 列报与披露
A10: A.资产负债表中记录的应交税费是存在的。 | D10: √
A11: B.所有应当记录的应交税费均已记录。 | E11: √
A12: C.记录的应交税费是被审计单位应当履行的现实义务。 | F12: √
A13: D.应交税费以恰当的金额包括在财务报表中，与之相关的计价调整已恰当记录。 | G13: √
A14: E.应交税费已按照企业会计准则的规定在财务报表中作出恰当列报。 | H14: √
A15: 三、计划实施的实质性程序
A16: 序号 | B16: 对应LEAP程序 | D16: 程序分类 | E16: 审计目标 | I16: 执行情况说明 （含底稿索引）
A17: （一） | B17: 常规程序 | C17: 编制审定表 | D17: 常规★ | E17: D | I17: O1 | K17: 整合
A18: （二） | B18: 常规程序 | C18: 获取应交税费明细表。 | D18: 常规★ | E18: D | I18: O1-2 | K18: 整合 | L18: 获取应交税费明细表,编制审定表，并完成下面工作。 （1）复核加计正确 ，将总金额与总账核对。 （2）分析应交税费存在借方余额的项目，查明原因，判断是否由被审计单位预缴税款引起。 （3）注意印花税、耕地占用税以及其他不需要预计应缴数的税金有无误记入应交税费项目。 （4)如期初存在延期纳税的事项，检查是否经过税务机关批准。是否存在长期欠缴的应交税金，关注合理性。
A19: 1 | B19: 常规程序 | C19: 复核加计正确 | D19: 常规★
A20: 2 | B20: 常规程序 | C20: 将总金额与总账核对。 | D20: 常规★
A21: 3 | B21: 常规程序 | C21: 分析应交税费存在借方余额的项目，查明原因，判断是否由被审计单位预缴税款引起。 | D21: 常规★
A22: 4 | B22: 常规程序 | C22: 注意印花税、耕地占用税以及其他不需要预计应缴数的税金有无误记入应交税费项目。 | D22: 常规★
A23: 5 | B23: 常规程序 | C23: 核对期初余额与上期审定期末余额、纳税申报表及税务机关的认定数是否相符。 | D23: 常规★
A24: 6 | B24: 常规程序 | C24: 如期初存在延期纳税的事项，检查是否经过税务机关批准。是否存在长期欠缴的应交税金，关注合理性。 | D24: 常规
A25: （三） | B25: IPE程序 | C25: 在使用被审计单位生成的信息（IPE）时，应当评价该信息对实现审计目的是否足够可靠，包括根据具体情况在必要时实施下列程序： | D25: 常规★ | E25: B | I25: T1 | K25: 简化
A26: 1 | B26: IPE程序 | C26: 获取有关信息准确性和完整性的审计证据。
A27: 2 | B27: IPE程序 | C27: 评价信息对实现审计目的是否足够准确和详细。
A28: （四） | B28: 期初余额 | C28: 对于上期应交税费的期末余额和上期税金及附加发生额（适用于首次审计时对期初余额的审计）： | D28: 备选 | E28: ABD | I28: O1-2、O1-3 | K28: 简化 | L28: 获取前期纳税申报表和其他有持续影响的税收文件资料，确认应交税费余额与纳税申报表税务机关认定金额一致。如果发现税收申报等存在异常，考虑向税务专家咨询。
A29: 1 | B29: 期初余额 | C29: 获取前期纳税申报表和其他有持续影响的税收文件资料（适用于首次审计）。 | D29: 备选
A30: 2 | B30: 期初余额 | C30: 获得并查阅账户余额明细表。 | D30: 备选
A31: 3 | B31: 期初余额 | C31: 确定采用的会计政策和程序是适当的。 | D31: 备选
A32: 4 | B32: 期初余额 | C32: 获取前期应交税费纳税申报表和其他有持续影响的税收文件资料。 | D32: 备选
A33: 5 | B33: 期初余额 | C33: 确认应交税费余额与纳税申报表金额一致。 | D33: 备选
A34: 6 | B34: 期初余额 | C34: 就任何激进的或可疑的税务状况向税务专家咨询。 | D34: 备选
K35: 新增 | L35: 取得被审计单位的纳税鉴定、纳税通知、减免税批准文件等，了解被审计单位适用的税种、附加税费、计税（费）基础、税（费）率，以及征、免、减税（费）的范围与期限。如果被审计单位适用特定的税基式优惠或税额式优惠、或减低适用税率的，且该项税收优惠需办理规定的审批或备案手续的，应检查相关的手续是否完整、有效。连续接受委托时，关注其变化情况。
A36: （五） | B36: 应对措施-检查 | C36: 取得税务部门汇算清缴或其他确认文件、有关政府部门的专项检查报告、税务代理机构专业报告、被审计单位纳税申报资料等，分析其有效性，并与上述明细表及账面数据进行核对。对于超过法定交纳期限的税费，取得主管税务机关的批准文件。 | D36: 常规★ | E36: BCD | I36: O1-4 | K36: 修改
A37: （六） | B37: 应对措施-检查 | C37: 检查本期应交及已交增值税： | D37: 常规★ | E37: ABD | I37: O1-4、O1-5 | K37: 整合 | L37: 检查应交增值税： （1）获取或编制应交增值税测算表，复核加计正确，并与明细账核对相符。 （2）检查适用税率是否符合税法规定。 （3）将“应交增值税测算表”与被审计单位增值税纳税申报表进行核对，检查进项、销项的入账与申报期间是否一致，金额是否相符，增值税纳税申报表有无经税务机关认定。 (4)通过“原材料”等相关科目匡算增值税进项税是否合理。 (5)抽取一定期间的进项税抵扣汇总表，与应交增值税明细表相关数额合计数核对，如有差异，查明原因并作适当处理。 (6)检查重要的进项税发票、海关完税凭证、收购凭证或运费发票等支持性文件，与网上申报系统进行核对,并注意进口货物、购进的免税农产品或废旧物资、支付运费、接受投资或捐赠、接受应税劳务等应计的进项税额是否按规定进行了会计处理,检查某些特殊事项的进项税处理是否正确（如存货改变用途或发生非常损失应计的进项税转出数的计算），确定会计处理是否正确。 (7)根据与增值税销项税额相关的账户审定的有关数据，复核销项税额存货销售,或视同销售（例如，将存货用于投资、无偿馈赠他人、分配给股东（或投资者）应计的销项税额，以及将自产、委托加工的产品用于非应税项目）的计税依据确定是否正确，以及应计的销项税额的计算是否正确，确定会计处理是否正确。
A38: 1 | B38: 应对措施-检查 | C38: 获取或编制应交增值税测算表，复核加计正确，并与明细账核对相符。 | D38: 常规★
A39: 2 | B39: 应对措施-检查 | C39: 将“应交增值税测算表”与被审计单位增值税纳税申报表进行核对，检查进项、销项的入账与申报期间是否一致，金额是否相符，增值税纳税申报表有无经税务机关认定。 | D39: 常规★
A40: 3 | B40: 应对措施-检查 | C40: 通过“原材料”等相关科目匡算增值税进项税是否合理。 | D40: 常规★
...

Sheet 应交税费审定表N2-1
A1: 致同会计师事务所
A2: 应交税费审定表
A3: =底稿目录!A2 | C3: =底稿目录!A4 | H3: =底稿目录!A5 | M3: 索引号： | N3: =底稿目录!F4
A4: =底稿目录!A3 | C4: =底稿目录!A6 | H4: =底稿目录!A7 | M4: 页次：
A5: 项目 | B5: 期初数 | F5: 期末数 | J5: 本期未审数与上期 未审数的比较 | L5: 本期审定数与上期 审定数的比较 | N5: 原因分析
B6: 未审数 | C6: 账项调整 | D6: 重分类调整 | E6: 审定数 | F6: 未审数 | G6: 账项调整 | H6: 重分类调整 | I6: 审定数 | J6: 变动额 | K6: 变动率 | L6: 变动额 | M6: 变动率
A7: ='应交税费明细表N2-2'!A10 | B7: ='应交税费明细表N2-2'!C10 | C7: ='应交税费明细表N2-2'!G10 | D7: ='应交税费明细表N2-2'!H10 | E7: =B7+C7+D7 | F7: ='应交税费明细表N2-2'!F10 | G7: ='应交税费明细表N2-2'!G10+'应交税费明细表N2-2'!I10-'应交税费明细表N2-2'!J10 | H7: ='应交税费明细表N2-2'!H10+'应交税费明细表N2-2'!K10-'应交税费明细表N2-2'!L10 | I7: =F7+G7+H7 | J7: =F7-B7 | K7: =IF(AND(B7=0,J7=0),0,IF(AND(B7=0,J7>0),1,J7/B7)) | L7: =I7-E7 | M7: =IF(AND(E7=0,L7=0),0,IF(AND(E7=0,L7>0),1,L7/E7))
A8: ='应交税费明细表N2-2'!A11 | B8: ='应交税费明细表N2-2'!C11 | C8: ='应交税费明细表N2-2'!G11 | D8: ='应交税费明细表N2-2'!H11 | E8: =B8+C8+D8 | F8: ='应交税费明细表N2-2'!F11 | G8: ='应交税费明细表N2-2'!G11+'应交税费明细表N2-2'!I11-'应交税费明细表N2-2'!J11 | H8: ='应交税费明细表N2-2'!H11+'应交税费明细表N2-2'!K11-'应交税费明细表N2-2'!L11 | I8: =F8+G8+H8 | J8: =F8-B8 | K8: =IF(AND(B8=0,J8=0),0,IF(AND(B8=0,J8>0),1,J8/B8)) | L8: =I8-E8 | M8: =IF(AND(E8=0,L8=0),0,IF(AND(E8=0,L8>0),1,L8/E8))
A9: ='应交税费明细表N2-2'!A12 | B9: ='应交税费明细表N2-2'!C12 | C9: ='应交税费明细表N2-2'!G12 | D9: ='应交税费明细表N2-2'!H12 | E9: =B9+C9+D9 | F9: ='应交税费明细表N2-2'!F12 | G9: ='应交税费明细表N2-2'!G12+'应交税费明细表N2-2'!I12-'应交税费明细表N2-2'!J12 | H9: ='应交税费明细表N2-2'!H12+'应交税费明细表N2-2'!K12-'应交税费明细表N2-2'!L12 | I9: =F9+G9+H9 | J9: =F9-B9 | K9: =IF(AND(B9=0,J9=0),0,IF(AND(B9=0,J9>0),1,J9/B9)) | L9: =I9-E9 | M9: =IF(AND(E9=0,L9=0),0,IF(AND(E9=0,L9>0),1,L9/E9))
A10: ='应交税费明细表N2-2'!A13 | B10: ='应交税费明细表N2-2'!C13 | C10: ='应交税费明细表N2-2'!G13 | D10: ='应交税费明细表N2-2'!H13 | E10: =B10+C10+D10 | F10: ='应交税费明细表N2-2'!F13 | G10: ='应交税费明细表N2-2'!G13+'应交税费明细表N2-2'!I13-'应交税费明细表N2-2'!J13 | H10: ='应交税费明细表N2-2'!H13+'应交税费明细表N2-2'!K13-'应交税费明细表N2-2'!L13 | I10: =F10+G10+H10 | J10: =F10-B10 | K10: =IF(AND(B10=0,J10=0),0,IF(AND(B10=0,J10>0),1,J10/B10)) | L10: =I10-E10 | M10: =IF(AND(E10=0,L10=0),0,IF(AND(E10=0,L10>0),1,L10/E10))
A11: ='应交税费明细表N2-2'!A14 | B11: ='应交税费明细表N2-2'!C14 | C11: ='应交税费明细表N2-2'!G14 | D11: ='应交税费明细表N2-2'!H14 | E11: =B11+C11+D11 | F11: ='应交税费明细表N2-2'!F14 | G11: ='应交税费明细表N2-2'!G14+'应交税费明细表N2-2'!I14-'应交税费明细表N2-2'!J14 | H11: ='应交税费明细表N2-2'!H14+'应交税费明细表N2-2'!K14-'应交税费明细表N2-2'!L14 | I11: =F11+G11+H11 | J11: =F11-B11 | K11: =IF(AND(B11=0,J11=0),0,IF(AND(B11=0,J11>0),1,J11/B11)) | L11: =I11-E11 | M11: =IF(AND(E11=0,L11=0),0,IF(AND(E11=0,L11>0),1,L11/E11))
A12: ='应交税费明细表N2-2'!A15 | B12: ='应交税费明细表N2-2'!C15 | C12: ='应交税费明细表N2-2'!G15 | D12: ='应交税费明细表N2-2'!H15 | E12: =B12+C12+D12 | F12: ='应交税费明细表N2-2'!F15 | G12: ='应交税费明细表N2-2'!G15+'应交税费明细表N2-2'!I15-'应交税费明细表N2-2'!J15 | H12: ='应交税费明细表N2-2'!H15+'应交税费明细表N2-2'!K15-'应交税费明细表N2-2'!L15 | I12: =F12+G12+H12 | J12: =F12-B12 | K12: =IF(AND(B12=0,J12=0),0,IF(AND(B12=0,J12>0),1,J12/B12)) | L12: =I12-E12 | M12: =IF(AND(E12=0,L12=0),0,IF(AND(E12=0,L12>0),1,L12/E12))
A13: ='应交税费明细表N2-2'!A16 | B13: ='应交税费明细表N2-2'!C16 | C13: ='应交税费明细表N2-2'!G16 | D13: ='应交税费明细表N2-2'!H16 | E13: =B13+C13+D13 | F13: ='应交税费明细表N2-2'!F16 | G13: ='应交税费明细表N2-2'!G16+'应交税费明细表N2-2'!I16-'应交税费明细表N2-2'!J16 | H13: ='应交税费明细表N2-2'!H16+'应交税费明细表N2-2'!K16-'应交税费明细表N2-2'!L16 | I13: =F13+G13+H13 | J13: =F13-B13 | K13: =IF(AND(B13=0,J13=0),0,IF(AND(B13=0,J13>0),1,J13/B13)) | L13: =I13-E13 | M13: =IF(AND(E13=0,L13=0),0,IF(AND(E13=0,L13>0),1,L13/E13))
A14: ='应交税费明细表N2-2'!A17 | B14: ='应交税费明细表N2-2'!C17 | C14: ='应交税费明细表N2-2'!G17 | D14: ='应交税费明细表N2-2'!H17 | E14: =B14+C14+D14 | F14: ='应交税费明细表N2-2'!F17 | G14: ='应交税费明细表N2-2'!G17+'应交税费明细表N2-2'!I17-'应交税费明细表N2-2'!J17 | H14: ='应交税费明细表N2-2'!H17+'应交税费明细表N2-2'!K17-'应交税费明细表N2-2'!L17 | I14: =F14+G14+H14 | J14: =F14-B14 | K14: =IF(AND(B14=0,J14=0),0,IF(AND(B14=0,J14>0),1,J14/B14)) | L14: =I14-E14 | M14: =IF(AND(E14=0,L14=0),0,IF(AND(E14=0,L14>0),1,L14/E14))
A15: ='应交税费明细表N2-2'!A18 | B15: ='应交税费明细表N2-2'!C18 | C15: ='应交税费明细表N2-2'!G18 | D15: ='应交税费明细表N2-2'!H18 | E15: =B15+C15+D15 | F15: ='应交税费明细表N2-2'!F18 | G15: ='应交税费明细表N2-2'!G18+'应交税费明细表N2-2'!I18-'应交税费明细表N2-2'!J18 | H15: ='应交税费明细表N2-2'!H18+'应交税费明细表N2-2'!K18-'应交税费明细表N2-2'!L18 | I15: =F15+G15+H15 | J15: =F15-B15 | K15: =IF(AND(B15=0,J15=0),0,IF(AND(B15=0,J15>0),1,J15/B15)) | L15: =I15-E15 | M15: =IF(AND(E15=0,L15=0),0,IF(AND(E15=0,L15>0),1,L15/E15))
A16: ='应交税费明细表N2-2'!A19 | B16: ='应交税费明细表N2-2'!C19 | C16: ='应交税费明细表N2-2'!G19 | D16: ='应交税费明细表N2-2'!H19 | E16: =B16+C16+D16 | F16: ='应交税费明细表N2-2'!F19 | G16: ='应交税费明细表N2-2'!G19+'应交税费明细表N2-2'!I19-'应交税费明细表N2-2'!J19 | H16: ='应交税费明细表N2-2'!H19+'应交税费明细表N2-2'!K19-'应交税费明细表N2-2'!L19 | I16: =F16+G16+H16 | J16: =F16-B16 | K16: =IF(AND(B16=0,J16=0),0,IF(AND(B16=0,J16>0),1,J16/B16)) | L16: =I16-E16 | M16: =IF(AND(E16=0,L16=0),0,IF(AND(E16=0,L16>0),1,L16/E16))
A17: ='应交税费明细表N2-2'!A20 | B17: ='应交税费明细表N2-2'!C20 | C17: ='应交税费明细表N2-2'!G20 | D17: ='应交税费明细表N2-2'!H20 | E17: =B17+C17+D17 | F17: ='应交税费明细表N2-2'!F20 | G17: ='应交税费明细表N2-2'!G20+'应交税费明细表N2-2'!I20-'应交税费明细表N2-2'!J20 | H17: ='应交税费明细表N2-2'!H20+'应交税费明细表N2-2'!K20-'应交税费明细表N2-2'!L20 | I17: =F17+G17+H17 | J17: =F17-B17 | K17: =IF(AND(B17=0,J17=0),0,IF(AND(B17=0,J17>0),1,J17/B17)) | L17: =I17-E17 | M17: =IF(AND(E17=0,L17=0),0,IF(AND(E17=0,L17>0),1,L17/E17))
A18: ='应交税费明细表N2-2'!A21 | B18: ='应交税费明细表N2-2'!C21 | C18: ='应交税费明细表N2-2'!G21 | D18: ='应交税费明细表N2-2'!H21 | E18: =B18+C18+D18 | F18: ='应交税费明细表N2-2'!F21 | G18: ='应交税费明细表N2-2'!G21+'应交税费明细表N2-2'!I21-'应交税费明细表N2-2'!J21 | H18: ='应交税费明细表N2-2'!H21+'应交税费明细表N2-2'!K21-'应交税费明细表N2-2'!L21 | I18: =F18+G18+H18 | J18: =F18-B18 | K18: =IF(AND(B18=0,J18=0),0,IF(AND(B18=0,J18>0),1,J18/B18)) | L18: =I18-E18 | M18: =IF(AND(E18=0,L18=0),0,IF(AND(E18=0,L18>0),1,L18/E18))
A19: ='应交税费明细表N2-2'!A22 | B19: ='应交税费明细表N2-2'!C22 | C19: ='应交税费明细表N2-2'!G22 | D19: ='应交税费明细表N2-2'!H22 | E19: =B19+C19+D19 | F19: ='应交税费明细表N2-2'!F22 | G19: ='应交税费明细表N2-2'!G22+'应交税费明细表N2-2'!I22-'应交税费明细表N2-2'!J22 | H19: ='应交税费明细表N2-2'!H22+'应交税费明细表N2-2'!K22-'应交税费明细表N2-2'!L22 | I19: =F19+G19+H19 | J19: =F19-B19 | K19: =IF(AND(B19=0,J19=0),0,IF(AND(B19=0,J19>0),1,J19/B19)) | L19: =I19-E19 | M19: =IF(AND(E19=0,L19=0),0,IF(AND(E19=0,L19>0),1,L19/E19))
J20: =F20-B20 | K20: =IF(AND(B20=0,J20=0),0,IF(AND(B20=0,J20>0),1,J20/B20)) | L20: =I20-E20 | M20: =IF(AND(E20=0,L20=0),0,IF(AND(E20=0,L20>0),1,L20/E20))
J21: =F21-B21 | K21: =IF(AND(B21=0,J21=0),0,IF(AND(B21=0,J21>0),1,J21/B21)) | L21: =I21-E21 | M21: =IF(AND(E21=0,L21=0),0,IF(AND(E21=0,L21>0),1,L21/E21))
A22: 合计 | B22: =SUM(B7:B21) | C22: =SUM(C7:C21) | D22: =SUM(D7:D21) | E22: =SUM(E7:E21) | F22: =SUM(F7:F21) | G22: =SUM(G7:G21) | H22: =SUM(H7:H21) | I22: =SUM(I7:I21) | J22: =SUM(J7:J21) | K22: =IF(AND(B22=0,J22=0),0,IF(AND(B22=0,J22>0),1,J22/B22)) | L22: =I22-E22 | M22: =IF(AND(E22=0,L22=0),0,IF(AND(E22=0,L22>0),1,L22/E22))
A23: 试算平衡表数
A24: 差异数 | E24: =E22-E23 | I24: =I22-I23
A25: 1.审计说明:
A29: 2.审计结论：

Sheet 附注披露信息（上市公司）
A1: 致同会计师事务所
A2: 附注披露信息（上市公司）
A3: =底稿目录!A2 | B3: =底稿目录!$A$4 | C3: =底稿目录!A5 | D3: 索引：
A4: =底稿目录!A3 | B4: =底稿目录!$A$6 | C4: =底稿目录!A7 | D4: 页次：1
A5: 附注披露信息：
A6: 应交税费
A7: 税 项 | B7: 期末余额 | C7: 上年年末余额
A8: ='应交税费审定表N2-1'!A7 | B8: ='应交税费审定表N2-1'!I7 | C8: ='应交税费审定表N2-1'!E7
A9: ='应交税费审定表N2-1'!A8 | B9: ='应交税费审定表N2-1'!I8 | C9: ='应交税费审定表N2-1'!E8
A10: ='应交税费审定表N2-1'!A9 | B10: ='应交税费审定表N2-1'!I9 | C10: ='应交税费审定表N2-1'!E9
A11: ='应交税费审定表N2-1'!A10 | B11: ='应交税费审定表N2-1'!I10 | C11: ='应交税费审定表N2-1'!E10
A12: ='应交税费审定表N2-1'!A11 | B12: ='应交税费审定表N2-1'!I11 | C12: ='应交税费审定表N2-1'!E11
A13: ='应交税费审定表N2-1'!A12 | B13: ='应交税费审定表N2-1'!I12 | C13: ='应交税费审定表N2-1'!E12
A14: ='应交税费审定表N2-1'!A13 | B14: ='应交税费审定表N2-1'!I13 | C14: ='应交税费审定表N2-1'!E13
A15: ='应交税费审定表N2-1'!A14 | B15: ='应交税费审定表N2-1'!I14 | C15: ='应交税费审定表N2-1'!E14
A16: ='应交税费审定表N2-1'!A15 | B16: ='应交税费审定表N2-1'!I15 | C16: ='应交税费审定表N2-1'!E15
A17: ='应交税费审定表N2-1'!A16 | B17: ='应交税费审定表N2-1'!I16 | C17: ='应交税费审定表N2-1'!E16
A18: ='应交税费审定表N2-1'!A17 | B18: ='应交税费审定表N2-1'!I17 | C18: ='应交税费审定表N2-1'!E17
A19: ='应交税费审定表N2-1'!A18 | B19: ='应交税费审定表N2-1'!I18 | C19: ='应交税费审定表N2-1'!E18
A20: ='应交税费审定表N2-1'!A19 | B20: ='应交税费审定表N2-1'!I19 | C20: ='应交税费审定表N2-1'!E19
A23: 合 计 | B23: =SUM(B8:B22) | C23: =SUM(C8:C22)
A24: 说明：
A25: （小税（费）种可合并反映。）
A26: （对于满足条件将当期所得税资产及当期所得税负债以抵销后的净额列示的情况，当企业实际交纳的所得税税款大于按照税法规定计算的应交税时，超过部分在资产负债表中应当列示为“其他流动资产”；当企业实际交纳的所得税税款小于按照税法规定计算的应交税时，差额部分应当作为资产负债表中的“应交税费”项目列示。）
A27: 【提示：增值税，根据“应交税费-为交增值税、简易计税、转让金融商品应交增值税、代扣代缴增值税”科目贷方余额计算填列；】

Sheet 附注披露信息（国企）
A1: 致同会计师事务所
A2: 附注披露信息（国企）
A3: =底稿目录!A2 | C3: =底稿目录!$A$4 | D3: =底稿目录!A5 | E3: 索引：
A4: =底稿目录!A3 | C4: =底稿目录!$A$6 | D4: =底稿目录!A7 | E4: 页次：1
A5: 附注披露信息：
A6: 应交税费
A7: 项 目 | B7: 期初余额 | C7: 本期应交 | D7: 本期已交 | E7: 期末余额
A8: ='应交税费明细表N2-2'!A10 | B8: ='应交税费明细表N2-2'!M10 | C8: ='应交税费明细表N2-2'!N10 | D8: ='应交税费明细表N2-2'!O10 | E8: =B8+C8-D8
A9: ='应交税费明细表N2-2'!A11 | B9: ='应交税费明细表N2-2'!M11 | C9: ='应交税费明细表N2-2'!N11 | D9: ='应交税费明细表N2-2'!O11 | E9: =B9+C9-D9
A10: ='应交税费明细表N2-2'!A12 | B10: ='应交税费明细表N2-2'!M12 | C10: ='应交税费明细表N2-2'!N12 | D10: ='应交税费明细表N2-2'!O12 | E10: =B10+C10-D10
A11: ='应交税费明细表N2-2'!A13 | B11: ='应交税费明细表N2-2'!M13 | C11: ='应交税费明细表N2-2'!N13 | D11: ='应交税费明细表N2-2'!O13 | E11: =B11+C11-D11
A12: ='应交税费明细表N2-2'!A14 | B12: ='应交税费明细表N2-2'!M14 | C12: ='应交税费明细表N2-2'!N14 | D12: ='应交税费明细表N2-2'!O14 | E12: =B12+C12-D12
A13: ='应交税费明细表N2-2'!A15 | B13: ='应交税费明细表N2-2'!M15 | C13: ='应交税费明细表N2-2'!N15 | D13: ='应交税费明细表N2-2'!O15 | E13: =B13+C13-D13
A14: ='应交税费明细表N2-2'!A16 | B14: ='应交税费明细表N2-2'!M16 | C14: ='应交税费明细表N2-2'!N16 | D14: ='应交税费明细表N2-2'!O16 | E14: =B14+C14-D14
A15: ='应交税费明细表N2-2'!A17 | B15: ='应交税费明细表N2-2'!M17 | C15: ='应交税费明细表N2-2'!N17 | D15: ='应交税费明细表N2-2'!O17 | E15: =B15+C15-D15
A16: ='应交税费明细表N2-2'!A18 | B16: ='应交税费明细表N2-2'!M18 | C16: ='应交税费明细表N2-2'!N18 | D16: ='应交税费明细表N2-2'!O18 | E16: =B16+C16-D16
A17: ='应交税费明细表N2-2'!A19 | B17: ='应交税费明细表N2-2'!M19 | C17: ='应交税费明细表N2-2'!N19 | D17: ='应交税费明细表N2-2'!O19 | E17: =B17+C17-D17
A18: ='应交税费明细表N2-2'!A20 | B18: ='应交税费明细表N2-2'!M20 | C18: ='应交税费明细表N2-2'!N20 | D18: ='应交税费明细表N2-2'!O20 | E18: =B18+C18-D18
A19: ='应交税费明细表N2-2'!A21 | B19: ='应交税费明细表N2-2'!M21 | C19: ='应交税费明细表N2-2'!N21 | D19: ='应交税费明细表N2-2'!O21 | E19: =B19+C19-D19
A20: ='应交税费明细表N2-2'!A22 | B20: ='应交税费明细表N2-2'!M22 | C20: ='应交税费明细表N2-2'!N22 | D20: ='应交税费明细表N2-2'!O22 | E20: =B20+C20-D20
E21: =B21+C21-D21
E22: =B22+C22-D22
A23: 合 计 | B23: =SUM(B8:B22) | C23: =SUM(C8:C22) | D23: =SUM(D8:D22) | E23: =SUM(E8:E22)
A24: 【提示：增值税，根据“应交税费-未交增值税、简易计税、转让金融商品应交增值税、代扣代缴增值税”科目贷方余额计算填列。】

Sheet 应交税费明细表N2-2
A1: 致同会计师事务所
A2: 应交税费明细表
A3: =底稿目录!A2 | F3: =底稿目录!$A$4 | L3: =底稿目录!A5 | P3: 索引号： | Q3: =底稿目录!F7
A4: =底稿目录!A3 | F4: =底稿目录!$A$6 | L4: =底稿目录!A7 | P4: 页次：
A5: 一、审计目标
A6: 应交税费以恰当的金额包括在财务报表中，与之相关的计价或分摊调整已恰当记录，相关披露已得到恰当计量和描述
A7: 二、审计过程
A8: 项目 | B8: 税率或税收优惠 | C8: 未审数 | G8: 期初调整 | I8: 账项调整 | K8: 重分类调整 | M8: 审定数 | Q8: 备注
C9: 期初数 | D9: 本期应交数 | E9: 本期已交数 | F9: 期末数 | G9: 账项调整 | H9: 重分类调整 | I9: 本期应交 | J9: 本期已交 | K9: 本期应交 | L9: 本期已交 | M9: 期初数 | N9: 本期应交数 | O9: 本期已交数 | P9: 期末数
A10: 企业所得税 | F10: =C10+D10-E10 | M10: =C10+G10+H10 | N10: =D10+I10+K10 | O10: =E10+J10+L10 | P10: =M10+N10-O10
A11: 增值税 | F11: =C11+D11-E11 | M11: =C11+G11+H11 | N11: =D11+I11+K11 | O11: =E11+J11+L11 | P11: =M11+N11-O11
A12: 消费税 | F12: =C12+D12-E12 | M12: =C12+G12+H12 | N12: =D12+I12+K12 | O12: =E12+J12+L12 | P12: =M12+N12-O12
A13: 资源税 | F13: =C13+D13-E13 | M13: =C13+G13+H13 | N13: =D13+I13+K13 | O13: =E13+J13+L13 | P13: =M13+N13-O13
A14: 土地增值税 | F14: =C14+D14-E14 | M14: =C14+G14+H14 | N14: =D14+I14+K14 | O14: =E14+J14+L14 | P14: =M14+N14-O14
A15: 城市维护建设税 | F15: =C15+D15-E15 | M15: =C15+G15+H15 | N15: =D15+I15+K15 | O15: =E15+J15+L15 | P15: =M15+N15-O15
A16: 车船牌照税 | F16: =C16+D16-E16 | M16: =C16+G16+H16 | N16: =D16+I16+K16 | O16: =E16+J16+L16 | P16: =M16+N16-O16
A17: 房产税 | F17: =C17+D17-E17 | M17: =C17+G17+H17 | N17: =D17+I17+K17 | O17: =E17+J17+L17 | P17: =M17+N17-O17
A18: 土地使用税 | F18: =C18+D18-E18 | M18: =C18+G18+H18 | N18: =D18+I18+K18 | O18: =E18+J18+L18 | P18: =M18+N18-O18
A19: 教育费附加 | F19: =C19+D19-E19 | M19: =C19+G19+H19 | N19: =D19+I19+K19 | O19: =E19+J19+L19 | P19: =M19+N19-O19
A20: 矿产资源补偿费 | F20: =C20+D20-E20 | M20: =C20+G20+H20 | N20: =D20+I20+K20 | O20: =E20+J20+L20 | P20: =M20+N20-O20
A21: 代扣代缴外国企业所得税 | F21: =C21+D21-E21 | M21: =C21+G21+H21 | N21: =D21+I21+K21 | O21: =E21+J21+L21 | P21: =M21+N21-O21
A22: 代扣代缴个人所得税 | F22: =C22+D22-E22 | M22: =C22+G22+H22 | N22: =D22+I22+K22 | O22: =E22+J22+L22 | P22: =M22+N22-O22
F23: =C23+D23-E23 | M23: =C23+G23+H23 | N23: =D23+I23+K23 | O23: =E23+J23+L23 | P23: =M23+N23-O23
F24: =C24+D24-E24 | M24: =C24+G24+H24 | N24: =D24+I24+K24 | O24: =E24+J24+L24 | P24: =M24+N24-O24
A25: 合计 | C25: =SUM(C10:C24) | D25: =SUM(D10:D24) | E25: =SUM(E10:E24) | F25: =SUM(F10:F24) | G25: =SUM(G10:G24) | H25: =SUM(H10:H24) | I25: =SUM(I10:I24) | J25: =SUM(J10:J24) | ... P25: =SUM(P10:P24)
A26: 三、审计说明：
A30: 四、审计结论：
A32: 提示：
A33: 1.本科目核算企业按照税法等规定计算应交纳的各种税费，包括增值税、消费税、营业税、所得税、资源税、土地增值税、城市维护建设税、房产税、土地使用税、
A34: 车船使用税、教育费附加、矿产资源补偿费等。企业代扣代交的个人所得税等，也通过本科目核算。
A35: 2.财政部会计司：我部、税务总局和海关总署印发了《关于深化增值税改革有关政策的公告》（财政部税务总局 海关总署公告2019年第39号，以下简称“第39号公告”），规定“自2019年4月1日至2021年12月31日，允许生产、生活性服务业纳税人按照当期可抵扣进项税额加计10%，抵减应纳税额”。现就该规定适用《增值税会计处理规定》（财会〔2016〕22号）的有关问题解读如下： 生产、生活性服务业纳税人取得资产或接受劳务时，应当按照《增值税会计处理规定》的相关规定对增值税相关业务进行会计处理；实际缴纳增值税时，按应纳税额借记“应交税费——未交增值税”等科目，按实际纳税金额贷记“银行存款”科目，按加计抵减的金额贷记“其他收益”科目。
A36: 3.应交税费的借方余额应重分类到其他流动资产等项目。
A37: 4.IPO、特殊行业、首次承接、重大资产重组业务，需要利用税务专家工作。

Sheet 调整分录汇总表N2-3
A1: 致同会计师事务所
A2: 应交税费调整分录汇总表
A3: =底稿目录!A2 | D3: =底稿目录!$A$4 | G3: =底稿目录!$A$5 | I3: 索引号： | J3: =底稿目录!F8
A4: =底稿目录!A3 | D4: =底稿目录!$A$6 | G4: =底稿目录!$A$7 | I4: 页次：
A5: 调整事项说明 | B5: 类别（报表调整/账项调整/其他） | C5: 报表项目 | D5: 科目名称 | E5: 附注项目 | F5: …… | G5: 借方调整金额 | H5: 贷方调整金额 | I5: 索引 | J5: 备注
A21: 1.审计说明
A25: 2.审计结论
A27: 提示：本底稿适用于调整分录较多、较复杂的项目，且仅列示与本报表项目相关的审计调整。项目组可根据项目实际情况选择是否使用该底稿。

Sheet 税收政策检查N2-4
A1: 致同会计师事务所
A2: 税收政策检查表
A3: =底稿目录!A2 | C3: =底稿目录!$A$4 | E3: =底稿目录!$A$5 | G3: 索引号： | H3: =底稿目录!F9
A4: =底稿目录!A3 | C4: =底稿目录!$A$6 | E4: =底稿目录!$A$7 | G4: 页次：
A5: 一、审计目标：
A6: 应交税费以恰当的金额包括在财务报表中，与之相关的计价或分摊调整已恰当记录，相关披露已得到恰当计量和描述
A7: 二、审计过程：
A8: 1.……
A9: 税费项目及适用税率 | F9: 文件名称 | G9: 文号 | H9: 索引号
A10: 税种 | B10: 计税(费)基础 | C10: 税(费)率 | D10: 征、免、减税(费)的范围 | E10: 征、免、减税(费)的期限
A11: 增值税
A12: 消费税
A13: 资源税
A14: 企业所得税
A15: 城市维护建设税
A16: 房产税
A17: 土地使用税
A18: 个人所得税
A19: 教育费附加
A20: 地方教育费附加
A21: 土地增值税
A22: 堤防费
... A35: 四、审计结论

Sheet 应交税金认定表N2-5
A1: 致同会计师事务所
A2: 应交税费认定表
A3: =底稿目录!A2 | D3: =底稿目录!$A$4 | G3: =底稿目录!$A$5 | I3: 索引号： | J3: =底稿目录!F10
A4: =底稿目录!A3 | D4: =底稿目录!$A$6 | G4: =底稿目录!$A$7 | I4: 页次：
A5: 一、审计目标：
A6: 1.所有应当记录的货币应交税费均已记录，所有应当包括在财务报表中的相关披露均已包括。2.记录的应交税费是被审计单位应当履行的现时义务。
A7: 3.应交税费以恰当的金额包括在财务报表中，与之相关的计价或分摊调整已恰当记录，相关披露已得到恰当计量和描述 .
A8: 二、审计过程：
A9: 1.……
A11: 税种 | B11: 期末法定税率 | C11: 期末未交数（账面） | D11: 税务机构期末认定数 | E11: 差异 | F11: 本年度已纳金额（账面） | G11: 完税证明金额 | H11: 差异 | I11: 差异原因 | J11: 税务机构认定相关文件依据说明
A13: ='应交税费明细表N2-2'!A10 | E13: =C13-D13 | H13: =F13-G13
A14: ='应交税费明细表N2-2'!A11 | E14: =C14-D14 | H14: =F14-G14
A15: ='应交税费明细表N2-2'!A12 | E15: =C15-D15 | H15: =F15-G15
A16: ='应交税费明细表N2-2'!A13 | E16: =C16-D16 | H16: =F16-G16
A17: ='应交税费明细表N2-2'!A14 | E17: =C17-D17 | H17: =F17-G17
A18: ='应交税费明细表N2-2'!A15 | E18: =C18-D18 | H18: =F18-G18
A19: ='应交税费明细表N2-2'!A16 | E19: =C19-D19 | H19: =F19-G19
A20: ='应交税费明细表N2-2'!A17 | E20: =C20-D20 | H20: =F20-G20
A21: ='应交税费明细表N2-2'!A18 | E21: =C21-D21 | H21: =F21-G21
A22: ='应交税费明细表N2-2'!A19 | E22: =C22-D22 | H22: =F22-G22
A23: ='应交税费明细表N2-2'!A20 | E23: =C23-D23 | H23: =F23-G23
A24: ='应交税费明细表N2-2'!A21 | E24: =C24-D24 | H24: =F24-G24
A25: ='应交税费明细表N2-2'!A22 | E25: =C25-D25 | H25: =F25-G25
E26: =C26-D26 | H26: =F26-G26
E27: =C27-D27 | H27: =F27-G27
A28: 合 计 | C28: =SUM(C13:C27) | D28: =SUM(D13:D27) | E28: =SUM(E13:E27) | F28: =SUM(F13:F27) | G28: =SUM(G13:G27) | H28: =SUM(H13:H27)
A31: 税种 | B31: 期初法定税率 | C31: 期初未交数（账面） | D31: 税务机构期初认定数 | E31: 差异 | F31: 上年度已纳金额（账面） | G31: 完税证明金额 | H31: 差异 | I31: 差异原因 | J31: 税务机构认定相关文件依据说明
A33: ='应交税费明细表N2-2'!A10 | E33: =C33-D33 | H33: =F33-G33
A34: ='应交税费明细表N2-2'!A11 | E34: =C34-D34 | H34: =F34-G34
A35: ='应交税费明细表N2-2'!A12 | E35: =C35-D35 | H35: =F35-G35
A36: ='应交税费明细表N2-2'!A13 | E36: =C36-D36 | H36: =F36-G36
A37: ='应交税费明细表N2-2'!A14 | E37: =C37-D37 | H37: =F37-G37
A38: ='应交税费明细表N2-2'!A15 | E38: =C38-D38 | H38: =F38-G38
A39: ='应交税费明细表N2-2'!A16 | E39: =C39-D39 | H39: =F39-G39
A40: ='应交税费明细表N2-2'!A17 | E40: =C40-D40 | H40: =F40-G40
A41: ='应交税费明细表N2-2'!A18 | E41: =C41-D41 | H41: =F41-G41
A42: ='应交税费明细表N2-2'!A19 | E42: =C42-D42 | H42: =F42-G42
A43: ='应交税费明细表N2-2'!A20 | E43: =C43-D43 | H43: =F43-G43
A44: ='应交税费明细表N2-2'!A21 | E44: =C44-D44 | H44: =F44-G44
A45: ='应交税费明细表N2-2'!A22 | E45: =C45-D45 | H45: =F45-G45
...

Sheet 增值税测算表N2-6
A1: 致同会计师事务所
A2: 应交增值税测算表
A3: =底稿目录!A2 | B3: =底稿目录!$A$4 | D3: =底稿目录!$A$5 | E3: 索引号： | F3: =底稿目录!F11
A4: =底稿目录!A3 | B4: =底稿目录!$A$6 | D4: =底稿目录!$A$7 | E4: 页次：
A5: 一、审计目标：
A6: 1.资产负债表中记录的应交税费是存在的，且已记录于恰当的账户。
A7: 2.所有应当记录的货币应交税费均已记录，所有应当包括在财务报表中的相关披露均已包括。
A8: 3.应交税费以恰当的金额包括在财务报表中，与之相关的计价或分摊调整已恰当记录，相关披露已得到恰当计量和描述
A9: 二、审计过程：
A10: （一）增值税纳税申报表核对
A11: 项目 | C11: 账面数据 | D11: 纳税申报表数据 | E11: 差异 | F11: 原因
A12: 1.按适用税率征税销售额
A13: 2.视同销售
A14: 3.按简易征收办法征税货物
A15: 4.免、抵、退办法出口销售额
A16: 5.免税销售额
A17: 6.销项税额
A18: 7.进项税额
A19: 8.进项税额转出
A20: 9.免、抵、退应退税额
A21: 10.其他
A22: （二）增值税销项税金测算
A23: 品种 | B23: 销售额 | C23: 免税/扣除销售额 | D23: 计税收入 | E23: 税率 | F23: 应计销项税
D24: =B24-C24 | F24: =D24*E24
D25: =B25-C25 | F25: =D25*E25
D26: =B26-C26 | F26: =D26*E26
D27: =B27-C27 | F27: =D27*E27
A28: 合计 | B28: =SUM(B24:B27) | C28: =SUM(C24:C27) | D28: =SUM(D24:D27) | F28: =SUM(F24:F27)
A29: 待转销项税额期末减期初金额
A30: 差异 | F30: =C17-F28-F29
A31: （三）增值税进项税测算
A32: 项目 | D32: 购进货物/固定资产及接受劳务发生额 | E32: 税率 | F32: 测算数
F33: =D33*E33
F34: =D34*E34
A35: 合计 | D35: =SUM(D33:D34) | F35: =SUM(F33:F34)
A36: 待抵扣进项税额期末减期初金额
A37: 待认证进项税额期末减期初金额
A38: 增值税留抵税额期末减期初金额
A39: 差异 | F39: =F35-F36-F37-F38-C18
A40: （四）特殊情况检查
...

Sheet 出口退税核对表N2-7
A1: 致同会计师事务所
A2: 出口退税核对表
A3: =底稿目录!A2 | B3: =底稿目录!$A$4 | C3: =底稿目录!$A$5 | E3: 索引号： | F3: =底稿目录!F12
A4: =底稿目录!A3 | B4: =底稿目录!$A$6 | C4: =底稿目录!$A$7 | E4: 页次：
A5: 一、审计目标：
A6: 1.资产负债表中记录的应交税费是存在的，且已记录于恰当的账户。
A7: 2.所有应当记录的货币应交税费均已记录，所有应当包括在财务报表中的相关披露均已包括。
A8: 3.应交税费以恰当的金额包括在财务报表中，与之相关的计价或分摊调整已恰当记录，相关披露已得到恰当计量和描述
A9: 二、审计过程：
A10: 1.取得《出口货物退（免）税申报表》及办理出口退税有关凭证，复核出口货物退税的计算是否正确，是否按规定进行了会计处理；
A11: 2.……
A13: 项 目 | B13: 栏次 | C13: 出口退税申报表金额 | D13: 账面金额 | E13: 差异 | F13: 差异原因
A14: 免抵退出口货物销售额(美元) | B14: 1 | E14: =D14-C14
A15: 免抵退出口货物销售额 | B15: 2=3+4 | C15: =C16+C17 | D15: =D16+D17 | E15: =D15-C15
A16: 其中：单证不齐销售额 | B16: 3 | E16: =D16-C16
A17: 单证齐全销售额 | B17: 4 | E17: =D17-C17
A18: 前期出口货物当期收齐单证销售额 | B18: 5 | E18: =D18-C18
A19: 单证齐全出口货物销售额 | B19: 6=4+5 | C19: =C17+C18 | D19: =D17+D18 | E19: =D19-C19
A20: 不予免抵退出口货物销售额 | B20: 7 | E20: =D20-C20
A21: 出口销售额乘征退税率之差 | B21: 8[6×(出口货物征税率-出口货物退税率)] | E21: =D21-C21
A22: 上期结转免抵退税不得免征和抵扣税额抵减额 | B22: 9 | E22: =D22-C22
A23: 免抵退税不得免征和抵扣税额抵减额 | B23: 10[免税购进原材料价格×(出口货物征税率-出口货物退税率)] | E23: =D23-C23
A24: 免抵退税不得免征和抵扣税额 | B24: 11(如8>9+10则为8-9-10,否则为0) | C24: =IF(C21>C22+C23,C21-C22-C23,0) | D24: =IF(D21>D22+D23,D21-D22-D23,0) | E24: =D24-C24
A25: 结转下期免抵退税不得免征和抵扣税额抵减额 | B25: 12(如9+10>8则为9+10-8,否则为0) | C25: =IF(C21<C22+C23,C22+C23-C21,0) | D25: =IF(D21<D22+D23,D22+D23-D21,0) | E25: =D25-C25
A26: 出口销售额乘退税率 | B26: 13(6×出口货物退税率) | E26: =D26-C26
A27: 上期结转免抵退税额抵减额 | B27: 14 | E27: =D27-C27
A28: 免抵退税额抵减额 | B28: 15(免税购进原材料价格×出口货物退税率) | E28: =D28-C28
A29: 免抵退税额 | B29: 16(如13>14+15则为13-14-15,否则为0) | C29: =IF(C26>C27+C28,C26-C27-C28,0) | D29: =IF(D26>D27+D28,D26-D27-D28,0) | E29: =D29-C29
A30: 结转下期免抵退税额抵减额 | B30: 17(如14+15>13则为14+15-13,否则为0) | C30: =IF(C26<C27+C28,C27+C28-C26,0) | D30: =IF(D26<D27+D28,D27+D28-D26,0) | E30: =D30-C30
A31: 增值税纳税申报表期末留抵税额 | B31: 18 | E31: =D31-C31
A32: 免抵退税不得免征和抵扣税额调整数 | B32: 19 | E32: =D32-C32
A33: 计算退税的期末留抵税额 | B33: 20=18-19 | E33: =D33-C33
A34: 当期应退税额 | B34: 21(如16>20则为20,否则为16) | C34: =IF(C29>C33,C33,C29) | D34: =IF(D29>D33,D33,D29) | E34: =D34-C34
A35: 当期免抵税额 | B35: 22=16-21 | C35: =C29-C34 | D35: =D29-D34 | E35: =D35-C35
A36: 三、审计说明
A39: 四、审计结论
A41: 提示：
A42: 1. 本测算表适用于执行“免、抵、退”办法的生产企业。一般的商贸企业出口退税程序较为简单，即：免征最后环节增值部分应纳税款，按购进金额计算退还应退税款，应退税额＝购进货物的购进金额×退税率
A43: 2. 表中第19栏“免抵退税不得免征和抵扣税额调整数”产生原因：当出现企业的增值税纳税申报和出口退税申报两者存在时间差等特殊情况时，“免抵退税不得免征和抵扣税额”可能会有差异，根据相关规定，企业应对该项差异进行相应的账务调整，并且在下期增值税纳税申报时对《增值税纳税申报表》相应项目做出调整。
A44: 3.对于生产出口企业，因采用“免、抵、退”政策，建议
...

Sheet 应交其他税费测算表N2-8
A1: 致同会计师事务所
A2: 应交其他税费测算表
A3: =底稿目录!A2 | D3: =底稿目录!$A$4 | G3: =底稿目录!$A$5 | H3: 索引号： | I3: =底稿目录!F13
A4: =底稿目录!A3 | D4: =底稿目录!$A$6 | G4: =底稿目录!$A$7 | H4: 页次：
A5: 一、审计目标：
A6: 1.资产负债表中记录的应交税费是存在的，且已记录于恰当的账户。
A7: 2.所有应当记录的货币应交税费均已记录，所有应当包括在财务报表中的相关披露均已包括。
A8: 3.应交税费以恰当的金额包括在财务报表中，与之相关的计价或分摊调整已恰当记录，相关披露已得到恰当计量和描述
A9: 二、审计过程：
A10: 税种 | B10: 应税项目 | C10: 计税依据 | D10: 计税金额 | E10: 税率/税额 | F10: 应计税额 | G10: 账面计提税额 | H10: 差额 | I10: 备注
A11: 消费税 | C11: 销售额/销售数量 | F11: =D11*E11 | H11: =F11-G11
A12: 资源税 | C12: 销售额/销售数量 | F12: =D12*E12 | H12: =F12-G12
A13: 城建税 | C13: 应交增值税/消费税 | F13: =D13*E13 | H13: =F13-G13
A14: 教育费附加 | C14: 应交增值税/消费税 | F14: =D14*E14 | H14: =F14-G14
A15: 地方教育费附加 | C15: 应交增值税/消费税 | F15: =D15*E15 | H15: =F15-G15
A16: 土地使用税 | C16: 土地面积 | F16: =D16*E16 | H16: =F16-G16
A17: 车船税 | F17: =D17*E17 | H17: =F17-G17 | I17: 计税单位（每辆）/每吨/……
A18: …… | F18: =D18*E18 | H18: =F18-G18
A19: 三、审计说明：
A23: 四、审计结论：

Sheet 房产税测算表N2-9
A1: 致同会计师事务所
A2: 应交房产税测算表
A3: =底稿目录!A2 | C3: =底稿目录!$A$4 | E3: =底稿目录!$A$5 | F3: 索引号： | G3: =底稿目录!F14
A4: =底稿目录!A3 | C4: =底稿目录!$A$6 | E4: =底稿目录!$A$7 | F4: 页次：
A5: 一、审计目标：
A6: 1.资产负债表中记录的应交税费是存在的，且已记录于恰当的账户。
A7: 2.所有应当记录的货币应交税费均已记录，所有应当包括在财务报表中的相关披露均已包括。
A8: 3.应交税费以恰当的金额包括在财务报表中，与之相关的计价或分摊调整已恰当记录，相关披露已得到恰当计量和描述。
A9: 二、审计过程：
A10: 1.从价计征（法定年税率为1.2%）
A11: 房产名称 | B11: 房产原值 | C11: 不计税原值 | D11: 计税原值 | E11: 扣除比率 | F11: 当年使用月份 | G11: 应缴税额
B12: ① | C12: ② | D12: ③=①-② | E12: ④ | F12: ⑤ | G12: ⑥=③×（100%-④）×1.2%×⑤÷12个月
D13: =B13-C13 | G13: =D13*(1-E13)*1.2%*F13/12
D14: =B14-C14 | G14: =D14*(1-E14)*1.2%*F14/12
D15: =B15-C15 | G15: =D15*(1-E15)*1.2%*F15/12
D16: =B16-C16 | G16: =D16*(1-E16)*1.2%*F16/12
A17: 合计 | B17: =SUM(B13:B16) | C17: =SUM(C13:C16) | D17: =SUM(D13:D16) | G17: =SUM(G13:G16)
A18: 2.从租计征（法定年税率为12%）
A19: 房产名称 | B19: 出租开始日 | C19: 出租结束日 | D19: 年租金收入 | E19: 税率 | F19: 当年出租月份 | G19: 应缴税额
B20: ① | C20: ② | D20: ③ | E20: ④ | F20: ⑤ | G20: ⑥=③×④×⑤÷12个月
G21: =D21*E21*F21/12
G22: =D22*E22*F22/12
G23: =D23*E23*F23/12
G24: =D24*E24*F24/12
A25: 合计 | D25: =SUM(D21:D24) | G25: =SUM(G21:G24)
A26: 三、审计说明：
A30: 四、审计结论：

Sheet 土地增值税测算表N2-10
A1: 致同会计师事务所
A2: 土地增值税测算表
A3: =底稿目录!A2 | B3: =底稿目录!$A$4 | C3: =底稿目录!$A$5 | D3: 索引号： | E3: =底稿目录!F15
A4: =底稿目录!A3 | B4: =底稿目录!$A$6 | C4: =底稿目录!$A$7 | D4: 页次：
A5: 一、审计目标：
A6: 1.资产负债表中记录的应交税费是存在的，且已记录于恰当的账户。
A7: 2.所有应当记录的货币应交税费均已记录，所有应当包括在财务报表中的相关披露均已包括。
A8: 3.应交税费以恰当的金额包括在财务报表中，与之相关的计价或分摊调整已恰当记录，相关披露已得到恰当计量和描述
A9: 二、审计过程：
A10: 1.根据审定的预售房地产的预收账款，复核预交税款是否准确。
A11: 2.对符合项目清算条件的房地产开发项目，检查被审计单位是否按规定进行土地增值税清算；
A12: 被审计单位已聘请中介机构办理土地增值税清算鉴证的，检查、核对相关鉴证报告。
A13: 3.被审计单位被主管税务机关核定征收土地增值税的，检查、核对相关的手续。
A14: 4.……
A15: 项目 | B15: 可销售面积 | C15: 已销售面积 | D15: 未销售面积 | E15: 索引号
A16: 数量（平方米） | D16: =B16-C16
A17: 收入（元） | B17: =C17+D17
A18: 单价（元） | B18: =IF(B16<>0,ROUND(B17/B16,2),0) | C18: =IF(C16<>0,ROUND(C17/C16,2),0) | D18: =IF(D16<>0,ROUND(D17/D16,2),0)
A19: 成本（元） | D19: =B19-C19
A20: 单位成本（元） | B20: =IF(B16<>0,ROUND(B19/B16,2),0) | C20: =IF(C16<>0,ROUND(C19/C16,2),0) | D20: =IF(D16<>0,ROUND(D19/D16,2),0)
A22: 项目 | B22: 行次 | C22: 公式说明 | D22: 测算金额 | E22: 索引号
A23: 一、转让房地产收入总额 | B23: 1
A24: 转让土地收入 | B24: 2
A25: 转让地上建筑物及附着物收入 | B25: 3
A26: 二、扣除项目金额合计 | B26: 4 | D26: =SUM(D27,D28,D29,D32,D33,D34)
A27: 1.取得土地使用权所支付的金额 | B27: 5
A28: 2.房地产开发成本 | B28: 6
A29: 3.房地产开发费用 | B29: 13 | D29: =SUM(D30:D31)
A30: 利息支出 | B30: 14
A31: 其他房地产开发费用 | B31: 15
A32: 4.与转让房地产有关的税金（实缴） | B32: 16
A33: 5.财政部规定的加计20%扣除数 | B33: 20
A34: 6.财政部规定的其他扣除项目金额 | B34: 21
A35: 三、增值额 | B35: 22 | D35: =D23-D26
A36: 四、增值额与扣除项目金额之比（％） | B36: 23 | D36: =IF(D26=0,0,D35/D26)
A37: 五、适用税率（％） | B37: 24 | D37: =IF(D35=0,0,IF(D36<=50%,30%,IF(D36<=100%,40%,IF(D36<=200%,50%,60%))))
A38: 六、速算扣除系数（％） | B38: 25 | D38: =IF(D37=30%,0,IF(D37=40%,5%,IF(D37=50%,15%,IF(D37=60%,35%,0))))
A39: 七、预征比例（％） | B39: 26
A40: 八、应缴土地增值税税款 | B40: 27 | D40: =D35*D37-D26*D38
A41: 九、免缴土地增值税税款 | B41: 28
...

Sheet 应交税费检查表N2-11
A1: 致同会计师事务所
A2: 土地增值税测算表
A3: =底稿目录!A2 | D3: =底稿目录!$A$4 | H3: =底稿目录!$A$5 | O3: 索引号： | P3: =底稿目录!F16
A4: =底稿目录!A3 | D4: =底稿目录!$A$6 | H4: =底稿目录!$A$7 | O4: 页次：
A5: 一、审计目标：
A6: 1.资产负债表中记录的应交税费是存在的，且已记录于恰当的账户。2.所有应当记录的货币应交税费均已记录，所有应当包括在财务报表中的相关披露均已包括。
A7: 3.应交税费以恰当的金额包括在财务报表中，与之相关的计价或分摊调整已恰当记录，相关披露已得到恰当计量和描述
A8: 二、测试： | C8: 测试原因：大额（）关联方（）大额交易频繁（）异常（）其他（）
A9: 测试内容说明：1.原始凭证是否齐全； 2.记账凭证与原始凭证是否相符；3.账务处理是否正确；4.是否记录于恰当的会计期间；5.……
A10: 记账凭证 | H10: 支持性文件 | I10: 核对内容 | N10: 索引号 | O10: 是否异常 | P10: 备注说明
A11: 日期 | B11: 凭证编号 | C11: 业务内容 | D11: 对方科目 | E11: 对方明细科目 | F11: 借方金额 | G11: 贷方金额 | I11: 1 | J11: 2 | K11: 3 | L11: 4 | M11: 5
A19: 合计 | F19: =SUM(F12:F18) | G19: =SUM(G12:G18)
A20: 本期发生额 | F20: ='应交税费明细表N2-2'!E25 | G20: ='应交税费明细表N2-2'!D25
A21: 检查比例 | F21: =F19/F20 | G21: =G19/G20
A22: 三、审计说明：
A26: 四、审计结论：

Sheet 出口退税额复核示例
A1: 致同会计师事务所
A2: 出口退税额复核
A3: =底稿目录!A2 | C3: =底稿目录!$A$4 | E3: =底稿目录!$A$5 | G3: 索引号： | H3: N2-
A4: =底稿目录!A3 | C4: =底稿目录!$A$6 | E4: =底稿目录!$A$7 | G4: 页次：
A6: 提示：出口退税额的核对应区别生产出口企业、外贸出口企业选择不同的审计程序，以下审计方法供审计人员参考：
A7: 建议实施的审计程序 | G7: 检查记录索引 | H7: 查验结果
A8: 1、对于生产出口企业，因采用“免、抵、退”政策，建议
A9: （1）取得被审计单位的生产企业出口货物免抵退税申报汇总表并与账面数进行核对（重点核对免抵退税不得免征和抵扣税额）。
A10: （2）取证税务部门出具的出口免税证明。
A11: （3）复核免抵退税额的计算是否正确，会计处理是否恰当，应结转销售成本或存货的金额是否正确。关注财务账面外销收入采用的核算汇率与出口货物离岸（报关）时的汇率差异对免抵退税额计算的影响，是否及时进行了调整。
A12: （4）关注期末应退税额期后是否已收到退税款。
A13: （5）对于出口业务较少的生产企业，可逐笔进行核对；对于出口业务较多的生产企业，可按月进行分析、审核。
A14: …
A16: 2、对于外贸出口企业，因采用“先征后退”政策，建议
A17: （1）与外贸出口退税总申报表等资料核对（重点核对进项税转出-出口产品不予抵扣的进项税）。
A18: （2）根据当期应结转的出口商品成本与相应退税率匡算应退税额，检查征、退税之差是否已计入当期销售成本。
A19: （3）关注期末应退税额期后是否已收到退税款。对于期后未收到退税款的，检查期末应收出口退税款是否均在正常退税期内，并针对期末大额出口收入复核单证是否齐全，是否符合退税要求。
A20: （4）检查出口退税收款情况，判断出口退税收款周期（一般实现销售后多少时间内可以申报并收到退税款），根据退税周期和报告期末外销情况判断期末应收出口退税款是否合理。
... A24: 审计结论：

Sheet GT_Custom
A1: C1 | B1: Custom 1
A2: C2 | B2: Custom 2
A3: C3 | B3: Custom 3
A4: C4 | B4: Custom 4
A5: C5 | B5: Custom 5
A6: C6 | B6: Custom 6
A7: C7 | B7: Custom 7
A8: C8 | B8: Custom 8
