Workbook
Name _13102: #REF!
Name _13102: #REF!
Name _13102: #REF!
Name _13302: #REF!
Name _13302: #REF!
Name _13302: #REF!
Name _13398: #REF!
Name _13398: #REF!
Name _13398: #REF!
Name _18102: #REF!
Name _18102: #REF!
Name _18102: #REF!
Name _18198: #REF!
Name _18198: #REF!
Name _18198: #REF!
Name _1其他资产_开办费除外_明细表: #REF!
Name _2003附注: [1]附注汇总!$C$5:$AY$646
Name _2其他资产_开办费除外_明细表: #REF!
Name _2其他资产_开办费除外_明细表: #REF!
Name _scn11: #REF!
Name _scn11: #REF!
Name _scn11: #REF!
Name _scn15: #REF!
Name _scn15: #REF!
Name _scn15: #REF!
Name _scn16: #REF!
Name _scn16: #REF!
Name _scn16: #REF!
Name _scn17: #REF!
Name _scn17: #REF!
Name _scn17: #REF!
Name _scn19: #REF!
Name _scn19: #REF!
Name _scn19: #REF!
Name _scn2: #REF!
Name _scn2: #REF!
Name _scn2: #REF!
Name _scn20: #REF!
Name _scn20: #REF!
Name _scn20: #REF!
Name _scn3: #REF!
Name _scn3: #REF!
Name _scn3: #REF!
Name _scn4: #REF!
Name _scn4: #REF!
Name _scn4: #REF!
Name _scn5: #REF!
Name _scn5: #REF!
Name _scn5: #REF!
Name _scn6: #REF!
Name _scn6: #REF!
Name _scn6: #REF!
Name _scn7: #REF!
Name _scn7: #REF!
Name _scn7: #REF!
Name _scn8: #REF!
Name _scn8: #REF!
Name _scn8: #REF!
Name _scn9: #REF!
Name _scn9: #REF!

Sheet 完成阶段的分析性复核A1-14
A1: 致同会计师事务所
A2: 审计完成阶段的分析性复核（合并报表）
A3: 被审计单位名称： | B3: 编制人： | D3: 日期： | E3: 索引号：A1-14-1
A4: 截止日/会计期间： | B4: 复核人： | D4: 日期： | E4: 页 次：
A5: 一、审计目标
A6: 1、确定财务报表整体是否与注册会计师对被审单位了解一致；
A7: 2、是否存在以前未识别的重大错报风险。
A9: 二、审计程序 | D9: 执行人及日期 | E9: 工作底稿索引
A10: （一）财务信息各构成要素之间的关系
A11: 1、以前期间可比信息
A12: 2、与被审单位预期结果的比较
A13: 3、与被审单位实际结果的比较
A16: （二）财务信息与相关非财务信息之间的关系
A17: 1、以前期间可比信息
A18: 2、与被审单位预期结果的比较
A19: 3、与被审单位实际结果的比较
A21: （三）与同行业的比较
A22: 1、同行业公司选择
A23: 2、同行业公司主要财务数据
A24: 3、同行业公司对比分析
... A34: 3、需要实施的进一步审计程序

Sheet 已审资产负债横向分析A1-14-1
A1: 已审资产负债表（合并）横向趋势分析－资产 | I1: 已审资产负债表（合并）横向趋势分析－负债
A2: 客户名称： | D2: 编制人： | F2: 日期： | H2: 索引：A1-14-1 | I2: =A2 -> 客户名称： | L2: =D2 -> 编制人： | N2: =F2 -> 日期： | P2: 索引：A1-14-1
A3: 会计时点：2017.12.31 | D3: 复核人： | F3: 日期： | H3: 页次：1 | I3: =A3 -> 会计时点：2017.12.31 | L3: =D3 -> 复核人： | N3: =F3 -> 日期： | P3: 页次：2
A4: 资产 | B4: 行次 | C4: 上年审定数 | D4: 本年审定数 | E4: 本年比上年增长 | G4: 变动状况（显著/关注) | H4: 显著变动原因分析；需进一步调查或解释的差异 | I4: 负债及股东权益 | J4: 行次 | K4: 上年审定数 | L4: 本年审定数 | M4: 本年比上年增长 | O4: 变动状况（显著/关注) | P4: 显著变动原因分析；需进一步调查或解释的差异
E5: 变动额 | F5: 变动％ | M5: 变动额 | N5: 变动％
C6: ① | D6: ② | E6: ③=②-① | F6: ④=③/① | K6: ① | L6: ② | M6: ③=②-① | N6: ④=③/①
A7: 流动资产： | B7: 1 | I7: 流动负债： | J7: =B49+1 -> 44
A8: 货币资金 | B8: =B7+1 -> 2 | E8: =D8-C8 -> 0 | F8: =IF(AND(C8=0,D8=0),"",IF(C8=0,100%,IF(D8=0,-100%,E8/C8))) | G8: =IF(F8="","",IF(OR(ABS(F8)>=30%,ABS(E8)>=$D$49*5%,ABS(E8)>='[31]已审利润纵向分析A1-13-4'!$E$27*10%),"显著",IF(ABS(F8)>=10%,"关注",""))) | I8: 短期借款 | J8: =J7+1 -> 45 | M8: =L8-K8 -> 0 | N8: =IF(AND(K8=0,L8=0),"",IF(K8=0,100%,IF(L8=0,-100%,M8/K8))) | O8: =IF(N8="","",IF(OR(ABS(N8)>=30%,ABS(M8)>=$D$49*5%,ABS(M8)>='[31]已审利润纵向分析A1-13-4'!$E$27*10%),"显著",IF(ABS(N8)>=10%,"关注","")))
A9: 以公允价值计量且其变动计入当期损益的金融资产 | B9: =B8+1 -> 3 | E9: =D9-C9 -> 0 | F9: =IF(AND(C9=0,D9=0),"",IF(C9=0,100%,IF(D9=0,-100%,E9/C9))) | G9: =IF(F9="","",IF(OR(ABS(F9)>=30%,ABS(E9)>=$D$49*5%,ABS(E9)>='[31]已审利润纵向分析A1-13-4'!$E$27*10%),"显著",IF(ABS(F9)>=10%,"关注",""))) | I9: 以公允价值计量且其变动计入当期损益的金融负债 | J9: =J8+1 -> 46 | M9: =L9-K9 -> 0 | N9: =IF(AND(K9=0,L9=0),"",IF(K9=0,100%,IF(L9=0,-100%,M9/K9))) | O9: =IF(N9="","",IF(OR(ABS(N9)>=30%,ABS(M9)>=$D$49*5%,ABS(M9)>='[31]已审利润纵向分析A1-13-4'!$E$27*10%),"显著",IF(ABS(N9)>=10%,"关注","")))
A10: 衍生金融资产 | B10: =B9+1 -> 4 | I10: 衍生金融负债 | J10: =J9+1 -> 47
A11: 应收票据及应收账款 | B11: =B10+1 -> 5 | E11: =D11-C11 -> 0 | F11: =IF(AND(C11=0,D11=0),"",IF(C11=0,100%,IF(D11=0,-100%,E11/C11))) | G11: =IF(F11="","",IF(OR(ABS(F11)>=30%,ABS(E11)>=$D$49*5%,ABS(E11)>='[31]已审利润纵向分析A1-13-4'!$E$27*10%),"显著",IF(ABS(F11)>=10%,"关注",""))) | I11: 应付票据及应付账款 | J11: =J10+1 -> 48 | M11: =L11-K11 -> 0 | N11: =IF(AND(K11=0,L11=0),"",IF(K11=0,100%,IF(L11=0,-100%,M11/K11))) | O11: =IF(N11="","",IF(OR(ABS(N11)>=30%,ABS(M11)>=$D$49*5%,ABS(M11)>='[31]已审利润纵向分析A1-13-4'!$E$27*10%),"显著",IF(ABS(N11)>=10%,"关注","")))
A12: 预付账款 | B12: =B11+1 -> 6 | E12: =D12-C12 -> 0 | F12: =IF(AND(C12=0,D12=0),"",IF(C12=0,100%,IF(D12=0,-100%,E12/C12))) | G12: =IF(F12="","",IF(OR(ABS(F12)>=30%,ABS(E12)>=$D$49*5%,ABS(E12)>='[31]已审利润纵向分析A1-13-4'!$E$27*10%),"显著",IF(ABS(F12)>=10%,"关注",""))) | I12: 预收账款 | J12: =J11+1 -> 49 | M12: =L12-K12 -> 0 | N12: =IF(AND(K12=0,L12=0),"",IF(K12=0,100%,IF(L12=0,-100%,M12/K12))) | O12: =IF(N12="","",IF(OR(ABS(N12)>=30%,ABS(M12)>=$D$49*5%,ABS(M12)>='[31]已审利润纵向分析A1-13-4'!$E$27*10%),"显著",IF(ABS(N12)>=10%,"关注","")))
A13: 其他应收款 | B13: =B12+1 -> 7 | E13: =D13-C13 -> 0 | F13: =IF(AND(C13=0,D13=0),"",IF(C13=0,100%,IF(D13=0,-100%,E13/C13))) | G13: =IF(F13="","",IF(OR(ABS(F13)>=30%,ABS(E13)>=$D$49*5%,ABS(E13)>='[31]已审利润纵向分析A1-13-4'!$E$27*10%),"显著",IF(ABS(F13)>=10%,"关注",""))) | I13: 应付职工薪酬 | J13: =J12+1 -> 50 | M13: =L13-K13 -> 0 | N13: =IF(AND(K13=0,L13=0),"",IF(K13=0,100%,IF(L13=0,-100%,M13/K13))) | O13: =IF(N13="","",IF(OR(ABS(N13)>=30%,ABS(M13)>=$D$49*5%,ABS(M13)>='[31]已审利润纵向分析A1-13-4'!$E$27*10%),"显著",IF(ABS(N13)>=10%,"关注","")))
A14: 存货 | B14: =B13+1 -> 8 | E14: =D14-C14 -> 0 | F14: =IF(AND(C14=0,D14=0),"",IF(C14=0,100%,IF(D14=0,-100%,E14/C14))) | G14: =IF(F14="","",IF(OR(ABS(F14)>=30%,ABS(E14)>=$D$49*5%,ABS(E14)>='[31]已审利润纵向分析A1-13-4'!$E$27*10%),"显著",IF(ABS(F14)>=10%,"关注",""))) | I14: 应交税费 | J14: =J13+1 -> 51 | M14: =L14-K14 -> 0 | N14: =IF(AND(K14=0,L14=0),"",IF(K14=0,100%,IF(L14=0,-100%,M14/K14))) | O14: =IF(N14="","",IF(OR(ABS(N14)>=30%,ABS(M14)>=$D$49*5%,ABS(M14)>='[31]已审利润纵向分析A1-13-4'!$E$27*10%),"显著",IF(ABS(N14)>=10%,"关注","")))
A15: 其中：原材料 | B15: =B14+1 -> 9 | E15: =D15-C15 -> 0 | F15: =IF(AND(C15=0,D15=0),"",IF(C15=0,100%,IF(D15=0,-100%,E15/C15))) | G15: =IF(F15="","",IF(OR(ABS(F15)>=30%,ABS(E15)>=$D$49*5%,ABS(E15)>='[31]已审利润纵向分析A1-13-4'!$E$27*10%),"显著",IF(ABS(F15)>=10%,"关注",""))) | I15: 其他应付款 | J15: =J14+1 -> 52 | M15: =L15-K15 -> 0 | N15: =IF(AND(K15=0,L15=0),"",IF(K15=0,100%,IF(L15=0,-100%,M15/K15))) | O15: =IF(N15="","",IF(OR(ABS(N15)>=30%,ABS(M15)>=$D$49*5%,ABS(M15)>='[31]已审利润纵向分析A1-13-4'!$E$27*10%),"显著",IF(ABS(N15)>=10%,"关注","")))
A16: 库存商品（产成品） | B16: =B15+1 -> 10 | E16: =D16-C16 -> 0 | F16: =IF(AND(C16=0,D16=0),"",IF(C16=0,100%,IF(D16=0,-100%,E16/C16))) | G16: =IF(F16="","",IF(OR(ABS(F16)>=30%,ABS(E16)>=$D$49*5%,ABS(E16)>='[31]已审利润纵向分析A1-13-4'!$E$27*10%),"显著",IF(ABS(F16)>=10%,"关注",""))) | I16: 持有待售负债 | J16: =J15+1 -> 53 | M16: =L16-K16 -> 0 | N16: =IF(AND(K16=0,L16=0),"",IF(K16=0,100%,IF(L16=0,-100%,M16/K16))) | O16: =IF(N16="","",IF(OR(ABS(N16)>=30%,ABS(M16)>=$D$49*5%,ABS(M16)>='[31]已审利润纵向分析A1-13-4'!$E$27*10%),"显著",IF(ABS(N16)>=10%,"关注","")))
A17: 持有待售资产 | B17: =B16+1 -> 11 | E17: =D17-C17 -> 0 | I17: 一年内到期的非流动负债 | J17: =J16+1 -> 54 | M17: =L17-K17 -> 0
A18: 一年内到期的非流动资产 | B18: =B17+1 -> 12 | E18: =D18-C18 -> 0 | F18: =IF(AND(C18=0,D18=0),"",IF(C18=0,100%,IF(D18=0,-100%,E18/C18))) | G18: =IF(F18="","",IF(OR(ABS(F18)>=30%,ABS(E18)>=$D$49*5%,ABS(E18)>='[31]已审利润纵向分析A1-13-4'!$E$27*10%),"显著",IF(ABS(F18)>=10%,"关注",""))) | I18: 其他流动负债 | J18: =J17+1 -> 55 | M18: =L18-K18 -> 0 | N18: =IF(AND(K18=0,L18=0),"",IF(K18=0,100%,IF(L18=0,-100%,M18/K18))) | O18: =IF(N18="","",IF(OR(ABS(N18)>=30%,ABS(M18)>=$D$49*5%,ABS(M18)>='[31]已审利润纵向分析A1-13-4'!$E$27*10%),"显著",IF(ABS(N18)>=10%,"关注","")))
A19: 其他流动资产 | B19: =B18+1 -> 13 | E19: =D19-C19 -> 0 | F19: =IF(AND(C19=0,D19=0),"",IF(C19=0,100%,IF(D19=0,-100%,E19/C19))) | G19: =IF(F19="","",IF(OR(ABS(F19)>=30%,ABS(E19)>=$D$49*5%,ABS(E19)>='[31]已审利润纵向分析A1-13-4'!$E$27*10%),"显著",IF(ABS(F19)>=10%,"关注",""))) | I19: 0 | J19: =J18+1 -> 56 | M19: =L19-K19 -> 0 | N19: =IF(AND(K19=0,L19=0),"",IF(K19=0,100%,IF(L19=0,-100%,M19/K19))) | O19: =IF(N19="","",IF(OR(ABS(N19)>=30%,ABS(M19)>=$D$49*5%,ABS(M19)>='[31]已审利润纵向分析A1-13-4'!$E$27*10%),"显著",IF(ABS(N19)>=10%,"关注","")))
A20: 0 | B20: =B19+1 -> 14 | E20: =D20-C20 -> 0 | F20: =IF(AND(C20=0,D20=0),"",IF(C20=0,100%,IF(D20=0,-100%,E20/C20))) | G20: =IF(F20="","",IF(OR(ABS(F20)>=30%,ABS(E20)>=$D$49*5%,ABS(E20)>='[31]已审利润纵向分析A1-13-4'!$E$27*10%),"显著",IF(ABS(F20)>=10%,"关注",""))) | I20: 0 | J20: =J19+1 -> 57 | M20: =L20-K20 -> 0 | N20: =IF(AND(K20=0,L20=0),"",IF(K20=0,100%,IF(L20=0,-100%,M20/K20))) | O20: =IF(N20="","",IF(OR(ABS(N20)>=30%,ABS(M20)>=$D$49*5%,ABS(M20)>='[31]已审利润纵向分析A1-13-4'!$E$27*10%),"显著",IF(ABS(N20)>=10%,"关注","")))
A21: 流动资产合计 | B21: =B20+1 -> 15 | C21: =SUM(C8:C20)-C15-C16 -> 0 | D21: =SUM(D8:D20)-D15-D16 -> 0 | E21: =D21-C21 -> 0 | F21: =IF(AND(C21=0,D21=0),"",IF(C21=0,100%,IF(D21=0,-100%,E21/C21))) | G21: =IF(F21="","",IF(OR(ABS(F21)>=30%,ABS(E21)>=$D$49*5%,ABS(E21)>='[31]已审利润纵向分析A1-13-4'!$E$27*10%),"显著",IF(ABS(F21)>=10%,"关注",""))) | I21: 流动负债合计 | J21: =J20+1 -> 58 | K21: =SUM(K8:K20) -> 0 | L21: =SUM(L8:L20) -> 0 | M21: =L21-K21 -> 0 | N21: =IF(AND(K21=0,L21=0),"",IF(K21=0,100%,IF(L21=0,-100%,M21/K21))) | O21: =IF(N21="","",IF(OR(ABS(N21)>=30%,ABS(M21)>=$D$49*5%,ABS(M21)>='[31]已审利润纵向分析A1-13-4'!$E$27*10%),"显著",IF(ABS(N21)>=10%,"关注","")))
A22: 非流动资产: | B22: =B21+1 -> 16 | G22: =IF(F22="","",IF(OR(ABS(F22)>=30%,ABS(E22)>=$D$49*5%,ABS(E22)>='[31]已审利润纵向分析A1-13-4'!$E$27*10%),"显著",IF(ABS(F22)>=10%,"关注",""))) | I22: 非流动负债: | J22: =J21+1 -> 59 | O22: =IF(N22="","",IF(OR(ABS(N22)>=30%,ABS(M22)>=$D$49*5%,ABS(M22)>='[31]已审利润纵向分析A1-13-4'!$E$27*10%),"显著",IF(ABS(N22)>=10%,"关注","")))
A23: 可供出售金融资产 | B23: =B22+1 -> 17 | E23: =D23-C23 -> 0 | F23: =IF(AND(C23=0,D23=0),"",IF(C23=0,100%,IF(D23=0,-100%,E23/C23))) | G23: =IF(F23="","",IF(OR(ABS(F23)>=30%,ABS(E23)>=$D$49*5%,ABS(E23)>='[31]已审利润纵向分析A1-13-4'!$E$27*10%),"显著",IF(ABS(F23)>=10%,"关注",""))) | I23: 长期借款 | J23: =J22+1 -> 60 | M23: =L23-K23 -> 0 | N23: =IF(AND(K23=0,L23=0),"",IF(K23=0,100%,IF(L23=0,-100%,M23/K23))) | O23: =IF(N23="","",IF(OR(ABS(N23)>=30%,ABS(M23)>=$D$49*5%,ABS(M23)>='[31]已审利润纵向分析A1-13-4'!$E$27*10%),"显著",IF(ABS(N23)>=10%,"关注","")))
A24: 持有至到期投资 | B24: =B23+1 -> 18 | E24: =D24-C24 -> 0 | F24: =IF(AND(C24=0,D24=0),"",IF(C24=0,100%,IF(D24=0,-100%,E24/C24))) | G24: =IF(F24="","",IF(OR(ABS(F24)>=30%,ABS(E24)>=$D$49*5%,ABS(E24)>='[31]已审利润纵向分析A1-13-4'!$E$27*10%),"显著",IF(ABS(F24)>=10%,"关注",""))) | I24: 应付债券 | J24: =J23+1 -> 61 | M24: =L24-K24 -> 0 | N24: =IF(AND(K24=0,L24=0),"",IF(K24=0,100%,IF(L24=0,-100%,M24/K24))) | O24: =IF(N24="","",IF(OR(ABS(N24)>=30%,ABS(M24)>=$D$49*5%,ABS(M24)>='[31]已审利润纵向分析A1-13-4'!$E$27*10%),"显著",IF(ABS(N24)>=10%,"关注","")))
A25: 长期应收款 | B25: =B24+1 -> 19 | E25: =D25-C25 -> 0 | F25: =IF(AND(C25=0,D25=0),"",IF(C25=0,100%,IF(D25=0,-100%,E25/C25))) | G25: =IF(F25="","",IF(OR(ABS(F25)>=30%,ABS(E25)>=$D$49*5%,ABS(E25)>='[31]已审利润纵向分析A1-13-4'!$E$27*10%),"显著",IF(ABS(F25)>=10%,"关注",""))) | I25: 其中：优先股 | J25: =J24+1 -> 62 | M25: =L25-K25 -> 0 | N25: =IF(AND(K25=0,L25=0),"",IF(K25=0,100%,IF(L25=0,-100%,M25/K25))) | O25: =IF(N25="","",IF(OR(ABS(N25)>=30%,ABS(M25)>=$D$49*5%,ABS(M25)>='[31]已审利润纵向分析A1-13-4'!$E$27*10%),"显著",IF(ABS(N25)>=10%,"关注","")))
A26: 设定受益计划净资产 | B26: =B25+1 -> 20 | E26: =D26-C26 -> 0 | I26: 永续债 | J26: =J25+1 -> 63
A27: 长期股权投资 | B27: =B26+1 -> 21 | E27: =D27-C27 -> 0 | F27: =IF(AND(C27=0,D27=0),"",IF(C27=0,100%,IF(D27=0,-100%,E27/C27))) | G27: =IF(F27="","",IF(OR(ABS(F27)>=30%,ABS(E27)>=$D$49*5%,ABS(E27)>='[31]已审利润纵向分析A1-13-4'!$E$27*10%),"显著",IF(ABS(F27)>=10%,"关注",""))) | I27: 长期应付款 | J27: =J26+1 -> 64 | M27: =L27-K27 -> 0 | N27: =IF(AND(K27=0,L27=0),"",IF(K27=0,100%,IF(L27=0,-100%,M27/K27))) | O27: =IF(N27="","",IF(OR(ABS(N27)>=30%,ABS(M27)>=$D$49*5%,ABS(M27)>='[31]已审利润纵向分析A1-13-4'!$E$27*10%),"显著",IF(ABS(N27)>=10%,"关注","")))
A28: 投资性房地产 | B28: =B27+1 -> 22 | E28: =D28-C28 -> 0 | F28: =IF(AND(C28=0,D28=0),"",IF(C28=0,100%,IF(D28=0,-100%,E28/C28))) | G28: =IF(F28="","",IF(OR(ABS(F28)>=30%,ABS(E28)>=$D$49*5%,ABS(E28)>='[31]已审利润纵向分析A1-13-4'!$E$27*10%),"显著",IF(ABS(F28)>=10%,"关注",""))) | I28: 长期应付职工薪酬 | J28: =J27+1 -> 65 | M28: =L28-K28 -> 0 | N28: =IF(AND(K28=0,L28=0),"",IF(K28=0,100%,IF(L28=0,-100%,M28/K28))) | O28: =IF(N28="","",IF(OR(ABS(N28)>=30%,ABS(M28)>=$D$49*5%,ABS(M28)>='[31]已审利润纵向分析A1-13-4'!$E$27*10%),"显著",IF(ABS(N28)>=10%,"关注","")))
A29: 固定资产 | B29: =B28+1 -> 23 | E29: =D29-C29 -> 0 | F29: =IF(AND(C29=0,D29=0),"",IF(C29=0,100%,IF(D29=0,-100%,E29/C29))) | G29: =IF(F29="","",IF(OR(ABS(F29)>=30%,ABS(E29)>=$D$49*5%,ABS(E29)>='[31]已审利润纵向分析A1-13-4'!$E$27*10%),"显著",IF(ABS(F29)>=10%,"关注",""))) | I29: 预计负债 | J29: =J28+1 -> 66 | M29: =L29-K29 -> 0 | N29: =IF(AND(K29=0,L29=0),"",IF(K29=0,100%,IF(L29=0,-100%,M29/K29))) | O29: =IF(N29="","",IF(OR(ABS(N29)>=30%,ABS(M29)>=$D$49*5%,ABS(M29)>='[31]已审利润纵向分析A1-13-4'!$E$27*10%),"显著",IF(ABS(N29)>=10%,"关注","")))
A30: 在建工程 | B30: =B29+1 -> 24 | E30: =D30-C30 -> 0 | F30: =IF(AND(C30=0,D30=0),"",IF(C30=0,100%,IF(D30=0,-100%,E30/C30))) | G30: =IF(F30="","",IF(OR(ABS(F30)>=30%,ABS(E30)>=$D$49*5%,ABS(E30)>='[31]已审利润纵向分析A1-13-4'!$E$27*10%),"显著",IF(ABS(F30)>=10%,"关注",""))) | I30: 递延收益 | J30: =J29+1 -> 67
A31: 生产性生物资产 | B31: =B30+1 -> 25 | E31: =D31-C31 -> 0 | F31: =IF(AND(C31=0,D31=0),"",IF(C31=0,100%,IF(D31=0,-100%,E31/C31))) | G31: =IF(F31="","",IF(OR(ABS(F31)>=30%,ABS(E31)>=$D$49*5%,ABS(E31)>='[31]已审利润纵向分析A1-13-4'!$E$27*10%),"显著",IF(ABS(F31)>=10%,"关注",""))) | I31: 递延所得税负债 | J31: =J30+1 -> 68 | M31: =L31-K31 -> 0 | N31: =IF(AND(K31=0,L31=0),"",IF(K31=0,100%,IF(L31=0,-100%,M31/K31))) | O31: =IF(N31="","",IF(OR(ABS(N31)>=30%,ABS(M31)>=$D$49*5%,ABS(M31)>='[31]已审利润纵向分析A1-13-4'!$E$27*10%),"显著",IF(ABS(N31)>=10%,"关注","")))
A32: 油气资产 | B32: =B31+1 -> 26 | E32: =D32-C32 -> 0 | F32: =IF(AND(C32=0,D32=0),"",IF(C32=0,100%,IF(D32=0,-100%,E32/C32))) | G32: =IF(F32="","",IF(OR(ABS(F32)>=30%,ABS(E32)>=$D$49*5%,ABS(E32)>='[31]已审利润纵向分析A1-13-4'!$E$27*10%),"显著",IF(ABS(F32)>=10%,"关注",""))) | I32: 其他非流动负债 | J32: =J31+1 -> 69 | M32: =L32-K32 -> 0 | N32: =IF(AND(K32=0,L32=0),"",IF(K32=0,100%,IF(L32=0,-100%,M32/K32))) | O32: =IF(N32="","",IF(OR(ABS(N32)>=30%,ABS(M32)>=$D$49*5%,ABS(M32)>='[31]已审利润纵向分析A1-13-4'!$E$27*10%),"显著",IF(ABS(N32)>=10%,"关注","")))
A33: 无形资产 | B33: =B32+1 -> 27 | E33: =D33-C33 -> 0 | F33: =IF(AND(C33=0,D33=0),"",IF(C33=0,100%,IF(D33=0,-100%,E33/C33))) | G33: =IF(F33="","",IF(OR(ABS(F33)>=30%,ABS(E33)>=$D$49*5%,ABS(E33)>='[31]已审利润纵向分析A1-13-4'!$E$27*10%),"显著",IF(ABS(F33)>=10%,"关注",""))) | I33: 非流动负债合计 | J33: =J32+1 -> 70 | K33: =SUM(K23:K32)-K25-K26 -> 0 | L33: =SUM(L23:L32)-L25-L26 -> 0 | M33: =L33-K33 -> 0 | N33: =IF(AND(K33=0,L33=0),"",IF(K33=0,100%,IF(L33=0,-100%,M33/K33))) | O33: =IF(N33="","",IF(OR(ABS(N33)>=30%,ABS(M33)>=$D$49*5%,ABS(M33)>='[31]已审利润纵向分析A1-13-4'!$E$27*10%),"显著",IF(ABS(N33)>=10%,"关注","")))
A34: 开发支出 | B34: =B33+1 -> 28 | E34: =D34-C34 -> 0 | F34: =IF(AND(C34=0,D34=0),"",IF(C34=0,100%,IF(D34=0,-100%,E34/C34))) | G34: =IF(F34="","",IF(OR(ABS(F34)>=30%,ABS(E34)>=$D$49*5%,ABS(E34)>='[31]已审利润纵向分析A1-13-4'!$E$27*10%),"显著",IF(ABS(F34)>=10%,"关注",""))) | I34: 负债合计 | J34: =J33+1 -> 71 | K34: =SUM(K21,K33) -> 0 | L34: =SUM(L21,L33) -> 0 | M34: =L34-K34 -> 0 | N34: =IF(AND(K34=0,L34=0),"",IF(K34=0,100%,IF(L34=0,-100%,M34/K34))) | O34: =IF(N34="","",IF(OR(ABS(N34)>=30%,ABS(M34)>=$D$49*5%,ABS(M34)>='[31]已审利润纵向分析A1-13-4'!$E$27*10%),"显著",IF(ABS(N34)>=10%,"关注","")))
A35: 商誉 | B35: =B34+1 -> 29 | E35: =D35-C35 -> 0 | F35: =IF(AND(C35=0,D35=0),"",IF(C35=0,100%,IF(D35=0,-100%,E35/C35))) | G35: =IF(F35="","",IF(OR(ABS(F35)>=30%,ABS(E35)>=$D$49*5%,ABS(E35)>='[31]已审利润纵向分析A1-13-4'!$E$27*10%),"显著",IF(ABS(F35)>=10%,"关注",""))) | I35: 股东权益： | J35: =J34+1 -> 72 | O35: =IF(N35="","",IF(OR(ABS(N35)>=30%,ABS(M35)>=$D$49*5%,ABS(M35)>='[31]已审利润纵向分析A1-13-4'!$E$27*10%),"显著",IF(ABS(N35)>=10%,"关注","")))
A36: 长期待摊费用 | B36: =B35+1 -> 30 | E36: =D36-C36 -> 0 | I36: 股本 | J36: =J35+1 -> 73 | M36: =L36-K36 -> 0 | N36: =IF(AND(K36=0,L36=0),"",IF(K36=0,100%,IF(L36=0,-100%,M36/K36))) | O36: =IF(N36="","",IF(OR(ABS(N36)>=30%,ABS(M36)>=$D$49*5%,ABS(M36)>='[31]已审利润纵向分析A1-13-4'!$E$27*10%),"显著",IF(ABS(N36)>=10%,"关注","")))
A37: 递延所得税资产 | B37: =B36+1 -> 31 | E37: =D37-C37 -> 0 | I37: 其他权益工具 | J37: =J36+1 -> 74
A38: 其他非流动资产 | B38: =B37+1 -> 32 | E38: =D38-C38 -> 0 | I38: 其中：优先股 | J38: =J37+1 -> 75
B39: =B38+1 -> 33 | E39: =D39-C39 -> 0 | F39: =IF(AND(C39=0,D39=0),"",IF(C39=0,100%,IF(D39=0,-100%,E39/C39))) | G39: =IF(F39="","",IF(OR(ABS(F39)>=30%,ABS(E39)>=$D$49*5%,ABS(E39)>='[31]已审利润纵向分析A1-13-4'!$E$27*10%),"显著",IF(ABS(F39)>=10%,"关注",""))) | I39: 永续债 | J39: =J38+1 -> 76
B40: =B39+1 -> 34 | E40: =D40-C40 -> 0 | F40: =IF(AND(C40=0,D40=0),"",IF(C40=0,100%,IF(D40=0,-100%,E40/C40))) | G40: =IF(F40="","",IF(OR(ABS(F40)>=30%,ABS(E40)>=$D$49*5%,ABS(E40)>='[31]已审利润纵向分析A1-13-4'!$E$27*10%),"显著",IF(ABS(F40)>=10%,"关注",""))) | I40: 资本公积 | J40: =J39+1 -> 77 | M40: =L40-K40 -> 0 | N40: =IF(AND(K40=0,L40=0),"",IF(K40=0,100%,IF(L40=0,-100%,M40/K40))) | O40: =IF(N40="","",IF(OR(ABS(N40)>=30%,ABS(M40)>=$D$49*5%,ABS(M40)>='[31]已审利润纵向分析A1-13-4'!$E$27*10%),"显著",IF(ABS(N40)>=10%,"关注","")))
...

Sheet 已审资产负债纵向分析A1-14-2
A1: 已审资产负债表（合并）纵向趋势分析－资产 | J1: 已审资产负债表（合并）纵向趋势分析－负债
A2: ='[31]已审资产负债横向分析A1-13-1'!A2 -> 客户名称： | E2: ='[31]已审资产负债横向分析A1-13-1'!D2 -> 编制人： | G2: ='[31]已审资产负债横向分析A1-13-1'!F2 -> 日期： | I2: 索引：A1-13-2 | J2: =A2 -> 客户名称： | N2: =E2 -> 编制人： | P2: =G2 -> 日期： | R2: 索引：A1-13-2
A3: ='已审资产负债横向分析A1-14-1'!A3 -> 会计时点：2017.12.31 | E3: ='[31]已审资产负债横向分析A1-13-1'!D3 -> 复核人： | G3: ='[31]已审资产负债横向分析A1-13-1'!F3 -> 日期： | I3: 页次：1 | J3: =A3 -> 会计时点：2017.12.31 | N3: =E3 -> 复核人： | P3: =G3 -> 日期： | R3: 页次：2
A4: 资产 | B4: 行次 | C4: 上年审定数 | E4: 本年审定数 | G4: 本年比上年 增长差异 | H4: 变动状况（显著/关注) | I4: 显著变动原因分析；需进一步调查或解释的差异 | J4: ='[31]已审资产负债横向分析A1-13-1'!I4:I6 -> 负债及股东权益 | K4: 行次 | L4: 上年审定数 | N4: 本年审定数 | P4: 本年比上年 增长差异 | Q4: 变动状况（显著/关注) | R4: 显著变动原因分析；需进一步调查或解释的差异
C5: 审定数 | D5: 比重% | E5: 审定数 | F5: 比重% | L5: 审定数 | M5: 比重% | N5: 审定数 | O5: 比重%
C6: ① | D6: ② | E6: ③ | F6: ④ | G6: ⑤=④-② | L6: ① | M6: ② | N6: ③ | O6: ④ | P6: ⑤=④-②
A7: 流动资产： | B7: 1 | J7: 流动负债： | K7: =B49+1 -> 44
A8: 货币资金 | B8: =B7+1 -> 2 | D8: =IF(AND(C8<>0,$C$49<>0),C8/$C$49,"") | F8: =IF(AND(E8<>0,$E$49<>0),E8/$E$49,"") | G8: =IF(AND(D8="",F8=""),"",IF(D8="",F8,IF(F8="",-D8,F8-D8))) | H8: =IF(G8="","",IF(ABS(G8)>=30%,"显著",IF(ABS(G8)>=10%,"关注",""))) | J8: 短期借款 | K8: =K7+1 -> 45 | M8: =IF(AND(L8<>0,$L$49<>0),L8/$L$49,"") | O8: =IF(AND(N8<>0,$N$49<>0),N8/$N$49,"") | P8: =IF(AND(M8="",O8=""),"",IF(M8="",O8,IF(O8="",-M8,O8-M8))) | Q8: =IF(P8="","",IF(ABS(P8)>=30%,"显著",IF(ABS(P8)>=10%,"关注","")))
A9: 以公允价值计量且其变动计入当期损益的金融资产 | B9: =B8+1 -> 3 | D9: =IF(AND(C9<>0,$C$49<>0),C9/$C$49,"") | F9: =IF(AND(E9<>0,$E$49<>0),E9/$E$49,"") | G9: =IF(AND(D9="",F9=""),"",IF(D9="",F9,IF(F9="",-D9,F9-D9))) | H9: =IF(G9="","",IF(ABS(G9)>=30%,"显著",IF(ABS(G9)>=10%,"关注",""))) | J9: 以公允价值计量且其变动计入当期损益的金融负债 | K9: =K8+1 -> 46 | M9: =IF(AND(L9<>0,$L$49<>0),L9/$L$49,"") | O9: =IF(AND(N9<>0,$N$49<>0),N9/$N$49,"") | P9: =IF(AND(M9="",O9=""),"",IF(M9="",O9,IF(O9="",-M9,O9-M9))) | Q9: =IF(P9="","",IF(ABS(P9)>=30%,"显著",IF(ABS(P9)>=10%,"关注","")))
A10: 衍生金融资产 | B10: =B9+1 -> 4 | J10: 衍生金融负责 | K10: =K9+1 -> 47
A11: 应收票据及应收账款 | B11: =B10+1 -> 5 | D11: =IF(AND(C11<>0,$C$49<>0),C11/$C$49,"") | F11: =IF(AND(E11<>0,$E$49<>0),E11/$E$49,"") | G11: =IF(AND(D11="",F11=""),"",IF(D11="",F11,IF(F11="",-D11,F11-D11))) | H11: =IF(G11="","",IF(ABS(G11)>=30%,"显著",IF(ABS(G11)>=10%,"关注",""))) | J11: 应付票据及应付账款 | K11: =K10+1 -> 48 | M11: =IF(AND(L11<>0,$L$49<>0),L11/$L$49,"") | O11: =IF(AND(N11<>0,$N$49<>0),N11/$N$49,"") | P11: =IF(AND(M11="",O11=""),"",IF(M11="",O11,IF(O11="",-M11,O11-M11))) | Q11: =IF(P11="","",IF(ABS(P11)>=30%,"显著",IF(ABS(P11)>=10%,"关注","")))
A12: 预付账款 | B12: =B11+1 -> 6 | D12: =IF(AND(C12<>0,$C$49<>0),C12/$C$49,"") | F12: =IF(AND(E12<>0,$E$49<>0),E12/$E$49,"") | G12: =IF(AND(D12="",F12=""),"",IF(D12="",F12,IF(F12="",-D12,F12-D12))) | H12: =IF(G12="","",IF(ABS(G12)>=30%,"显著",IF(ABS(G12)>=10%,"关注",""))) | J12: 预收账款 | K12: =K11+1 -> 49 | M12: =IF(AND(L12<>0,$L$49<>0),L12/$L$49,"") | O12: =IF(AND(N12<>0,$N$49<>0),N12/$N$49,"") | P12: =IF(AND(M12="",O12=""),"",IF(M12="",O12,IF(O12="",-M12,O12-M12))) | Q12: =IF(P12="","",IF(ABS(P12)>=30%,"显著",IF(ABS(P12)>=10%,"关注","")))
A13: 其他应收款 | B13: =B12+1 -> 7 | D13: =IF(AND(C13<>0,$C$49<>0),C13/$C$49,"") | F13: =IF(AND(E13<>0,$E$49<>0),E13/$E$49,"") | G13: =IF(AND(D13="",F13=""),"",IF(D13="",F13,IF(F13="",-D13,F13-D13))) | H13: =IF(G13="","",IF(ABS(G13)>=30%,"显著",IF(ABS(G13)>=10%,"关注",""))) | J13: 应付职工薪酬 | K13: =K12+1 -> 50 | M13: =IF(AND(L13<>0,$L$49<>0),L13/$L$49,"") | O13: =IF(AND(N13<>0,$N$49<>0),N13/$N$49,"") | P13: =IF(AND(M13="",O13=""),"",IF(M13="",O13,IF(O13="",-M13,O13-M13))) | Q13: =IF(P13="","",IF(ABS(P13)>=30%,"显著",IF(ABS(P13)>=10%,"关注","")))
A14: 存货 | B14: =B13+1 -> 8 | D14: =IF(AND(C14<>0,$C$49<>0),C14/$C$49,"") | F14: =IF(AND(E14<>0,$E$49<>0),E14/$E$49,"") | G14: =IF(AND(D14="",F14=""),"",IF(D14="",F14,IF(F14="",-D14,F14-D14))) | H14: =IF(G14="","",IF(ABS(G14)>=30%,"显著",IF(ABS(G14)>=10%,"关注",""))) | J14: 应交税费 | K14: =K13+1 -> 51 | M14: =IF(AND(L14<>0,$L$49<>0),L14/$L$49,"") | O14: =IF(AND(N14<>0,$N$49<>0),N14/$N$49,"") | P14: =IF(AND(M14="",O14=""),"",IF(M14="",O14,IF(O14="",-M14,O14-M14))) | Q14: =IF(P14="","",IF(ABS(P14)>=30%,"显著",IF(ABS(P14)>=10%,"关注","")))
A15: 其中：原材料 | B15: =B14+1 -> 9 | D15: =IF(AND(C15<>0,$C$49<>0),C15/$C$49,"") | F15: =IF(AND(E15<>0,$E$49<>0),E15/$E$49,"") | G15: =IF(AND(D15="",F15=""),"",IF(D15="",F15,IF(F15="",-D15,F15-D15))) | H15: =IF(G15="","",IF(ABS(G15)>=30%,"显著",IF(ABS(G15)>=10%,"关注",""))) | J15: 其他应付款 | K15: =K14+1 -> 52 | M15: =IF(AND(L15<>0,$L$49<>0),L15/$L$49,"") | O15: =IF(AND(N15<>0,$N$49<>0),N15/$N$49,"") | P15: =IF(AND(M15="",O15=""),"",IF(M15="",O15,IF(O15="",-M15,O15-M15))) | Q15: =IF(P15="","",IF(ABS(P15)>=30%,"显著",IF(ABS(P15)>=10%,"关注","")))
A16: 库存商品（产成品） | B16: =B15+1 -> 10 | D16: =IF(AND(C16<>0,$C$49<>0),C16/$C$49,"") | F16: =IF(AND(E16<>0,$E$49<>0),E16/$E$49,"") | G16: =IF(AND(D16="",F16=""),"",IF(D16="",F16,IF(F16="",-D16,F16-D16))) | H16: =IF(G16="","",IF(ABS(G16)>=30%,"显著",IF(ABS(G16)>=10%,"关注",""))) | J16: 持有待售负债 | K16: =K15+1 -> 53 | M16: =IF(AND(L16<>0,$L$49<>0),L16/$L$49,"") | O16: =IF(AND(N16<>0,$N$49<>0),N16/$N$49,"") | P16: =IF(AND(M16="",O16=""),"",IF(M16="",O16,IF(O16="",-M16,O16-M16))) | Q16: =IF(P16="","",IF(ABS(P16)>=30%,"显著",IF(ABS(P16)>=10%,"关注","")))
A17: 持有待售资产 | B17: =B16+1 -> 11 | D17: =IF(AND(C17<>0,$C$49<>0),C17/$C$49,"") | F17: =IF(AND(E17<>0,$E$49<>0),E17/$E$49,"") | G17: =IF(AND(D17="",F17=""),"",IF(D17="",F17,IF(F17="",-D17,F17-D17))) | H17: =IF(G17="","",IF(ABS(G17)>=30%,"显著",IF(ABS(G17)>=10%,"关注",""))) | J17: 一年内到期的非流动负债 | K17: =K16+1 -> 54 | M17: =IF(AND(L17<>0,$L$49<>0),L17/$L$49,"") | O17: =IF(AND(N17<>0,$N$49<>0),N17/$N$49,"") | P17: =IF(AND(M17="",O17=""),"",IF(M17="",O17,IF(O17="",-M17,O17-M17))) | Q17: =IF(P17="","",IF(ABS(P17)>=30%,"显著",IF(ABS(P17)>=10%,"关注","")))
A18: 一年内到期的非流动资产 | B18: =B17+1 -> 12 | D18: =IF(AND(C18<>0,$C$49<>0),C18/$C$49,"") | F18: =IF(AND(E18<>0,$E$49<>0),E18/$E$49,"") | G18: =IF(AND(D18="",F18=""),"",IF(D18="",F18,IF(F18="",-D18,F18-D18))) | H18: =IF(G18="","",IF(ABS(G18)>=30%,"显著",IF(ABS(G18)>=10%,"关注",""))) | J18: 其他流动负债 | K18: =K17+1 -> 55 | M18: =IF(AND(L18<>0,$L$49<>0),L18/$L$49,"") | O18: =IF(AND(N18<>0,$N$49<>0),N18/$N$49,"") | P18: =IF(AND(M18="",O18=""),"",IF(M18="",O18,IF(O18="",-M18,O18-M18))) | Q18: =IF(P18="","",IF(ABS(P18)>=30%,"显著",IF(ABS(P18)>=10%,"关注","")))
A19: 其他流动资产 | B19: =B18+1 -> 13 | D19: =IF(AND(C19<>0,$C$49<>0),C19/$C$49,"") | F19: =IF(AND(E19<>0,$E$49<>0),E19/$E$49,"") | G19: =IF(AND(D19="",F19=""),"",IF(D19="",F19,IF(F19="",-D19,F19-D19))) | H19: =IF(G19="","",IF(ABS(G19)>=30%,"显著",IF(ABS(G19)>=10%,"关注",""))) | J19: 0 | K19: =K18+1 -> 56 | M19: =IF(AND(L19<>0,$L$49<>0),L19/$L$49,"") | O19: =IF(AND(N19<>0,$N$49<>0),N19/$N$49,"") | P19: =IF(AND(M19="",O19=""),"",IF(M19="",O19,IF(O19="",-M19,O19-M19))) | Q19: =IF(P19="","",IF(ABS(P19)>=30%,"显著",IF(ABS(P19)>=10%,"关注","")))
A20: 0 | B20: =B19+1 -> 14 | D20: =IF(AND(C20<>0,$C$49<>0),C20/$C$49,"") | F20: =IF(AND(E20<>0,$E$49<>0),E20/$E$49,"") | G20: =IF(AND(D20="",F20=""),"",IF(D20="",F20,IF(F20="",-D20,F20-D20))) | H20: =IF(G20="","",IF(ABS(G20)>=30%,"显著",IF(ABS(G20)>=10%,"关注",""))) | J20: 0 | K20: =K19+1 -> 57 | M20: =IF(AND(L20<>0,$L$49<>0),L20/$L$49,"") | O20: =IF(AND(N20<>0,$N$49<>0),N20/$N$49,"") | P20: =IF(AND(M20="",O20=""),"",IF(M20="",O20,IF(O20="",-M20,O20-M20))) | Q20: =IF(P20="","",IF(ABS(P20)>=30%,"显著",IF(ABS(P20)>=10%,"关注","")))
A21: 流动资产合计 | B21: =B20+1 -> 15 | C21: =SUM(C8:C20)-C15-C16 -> 0 | D21: =IF(AND(C21<>0,$C$49<>0),C21/$C$49,"") | E21: =SUM(E8:E20)-E15-E16 -> 0 | F21: =IF(AND(E21<>0,$E$49<>0),E21/$E$49,"") | G21: =IF(AND(D21="",F21=""),"",IF(D21="",F21,IF(F21="",-D21,F21-D21))) | H21: =IF(G21="","",IF(ABS(G21)>=30%,"显著",IF(ABS(G21)>=10%,"关注",""))) | J21: 流动负债合计 | K21: =K20+1 -> 58 | L21: =SUM(L8:L20) -> 0 | M21: =IF(AND(L21<>0,$L$49<>0),L21/$L$49,"") | N21: =SUM(N8:N20) -> 0 | O21: =IF(AND(N21<>0,$N$49<>0),N21/$N$49,"") | P21: =IF(AND(M21="",O21=""),"",IF(M21="",O21,IF(O21="",-M21,O21-M21))) | Q21: =IF(P21="","",IF(ABS(P21)>=30%,"显著",IF(ABS(P21)>=10%,"关注","")))
A22: 非流动资产: | B22: =B21+1 -> 16 | D22: =IF(AND(C22<>0,$C$49<>0),C22/$C$49,"") | F22: =IF(AND(E22<>0,$E$49<>0),E22/$E$49,"") | G22: =IF(AND(D22="",F22=""),"",IF(D22="",F22,IF(F22="",-D22,F22-D22))) | H22: =IF(G22="","",IF(ABS(G22)>=30%,"显著",IF(ABS(G22)>=10%,"关注",""))) | J22: 非流动负债: | K22: =K21+1 -> 59 | M22: =IF(AND(L22<>0,$L$49<>0),L22/$L$49,"") | O22: =IF(AND(N22<>0,$N$49<>0),N22/$N$49,"") | P22: =IF(AND(M22="",O22=""),"",IF(M22="",O22,IF(O22="",-M22,O22-M22))) | Q22: =IF(P22="","",IF(ABS(P22)>=30%,"显著",IF(ABS(P22)>=10%,"关注","")))
A23: 可供出售金融资产 | B23: =B22+1 -> 17 | D23: =IF(AND(C23<>0,$C$49<>0),C23/$C$49,"") | F23: =IF(AND(E23<>0,$E$49<>0),E23/$E$49,"") | G23: =IF(AND(D23="",F23=""),"",IF(D23="",F23,IF(F23="",-D23,F23-D23))) | H23: =IF(G23="","",IF(ABS(G23)>=30%,"显著",IF(ABS(G23)>=10%,"关注",""))) | J23: 长期借款 | K23: =K22+1 -> 60 | M23: =IF(AND(L23<>0,$L$49<>0),L23/$L$49,"") | O23: =IF(AND(N23<>0,$N$49<>0),N23/$N$49,"") | P23: =IF(AND(M23="",O23=""),"",IF(M23="",O23,IF(O23="",-M23,O23-M23))) | Q23: =IF(P23="","",IF(ABS(P23)>=30%,"显著",IF(ABS(P23)>=10%,"关注","")))
A24: 持有至到期投资 | B24: =B23+1 -> 18 | D24: =IF(AND(C24<>0,$C$49<>0),C24/$C$49,"") | F24: =IF(AND(E24<>0,$E$49<>0),E24/$E$49,"") | G24: =IF(AND(D24="",F24=""),"",IF(D24="",F24,IF(F24="",-D24,F24-D24))) | H24: =IF(G24="","",IF(ABS(G24)>=30%,"显著",IF(ABS(G24)>=10%,"关注",""))) | J24: 应付债券 | K24: =K23+1 -> 61 | M24: =IF(AND(L24<>0,$L$49<>0),L24/$L$49,"") | O24: =IF(AND(N24<>0,$N$49<>0),N24/$N$49,"") | P24: =IF(AND(M24="",O24=""),"",IF(M24="",O24,IF(O24="",-M24,O24-M24))) | Q24: =IF(P24="","",IF(ABS(P24)>=30%,"显著",IF(ABS(P24)>=10%,"关注","")))
A25: 长期应收款 | B25: =B24+1 -> 19 | D25: =IF(AND(C25<>0,$C$49<>0),C25/$C$49,"") | F25: =IF(AND(E25<>0,$E$49<>0),E25/$E$49,"") | G25: =IF(AND(D25="",F25=""),"",IF(D25="",F25,IF(F25="",-D25,F25-D25))) | H25: =IF(G25="","",IF(ABS(G25)>=30%,"显著",IF(ABS(G25)>=10%,"关注",""))) | J25: 其中：优先股 | K25: =K24+1 -> 62 | M25: =IF(AND(L25<>0,$L$49<>0),L25/$L$49,"") | O25: =IF(AND(N25<>0,$N$49<>0),N25/$N$49,"") | P25: =IF(AND(M25="",O25=""),"",IF(M25="",O25,IF(O25="",-M25,O25-M25))) | Q25: =IF(P25="","",IF(ABS(P25)>=30%,"显著",IF(ABS(P25)>=10%,"关注","")))
A26: 设定受益计划净资产 | B26: =B25+1 -> 20 | D26: =IF(AND(C26<>0,$C$49<>0),C26/$C$49,"") | F26: =IF(AND(E26<>0,$E$49<>0),E26/$E$49,"") | G26: =IF(AND(D26="",F26=""),"",IF(D26="",F26,IF(F26="",-D26,F26-D26))) | H26: =IF(G26="","",IF(ABS(G26)>=30%,"显著",IF(ABS(G26)>=10%,"关注",""))) | J26: 永续债 | K26: =K25+1 -> 63 | M26: =IF(AND(L26<>0,$L$49<>0),L26/$L$49,"") | O26: =IF(AND(N26<>0,$N$49<>0),N26/$N$49,"") | P26: =IF(AND(M26="",O26=""),"",IF(M26="",O26,IF(O26="",-M26,O26-M26))) | Q26: =IF(P26="","",IF(ABS(P26)>=30%,"显著",IF(ABS(P26)>=10%,"关注","")))
A27: 长期股权投资 | B27: =B26+1 -> 21 | D27: =IF(AND(C27<>0,$C$49<>0),C27/$C$49,"") | F27: =IF(AND(E27<>0,$E$49<>0),E27/$E$49,"") | G27: =IF(AND(D27="",F27=""),"",IF(D27="",F27,IF(F27="",-D27,F27-D27))) | H27: =IF(G27="","",IF(ABS(G27)>=30%,"显著",IF(ABS(G27)>=10%,"关注",""))) | J27: 长期应付款 | K27: =K26+1 -> 64 | M27: =IF(AND(L27<>0,$L$49<>0),L27/$L$49,"") | O27: =IF(AND(N27<>0,$N$49<>0),N27/$N$49,"") | P27: =IF(AND(M27="",O27=""),"",IF(M27="",O27,IF(O27="",-M27,O27-M27))) | Q27: =IF(P27="","",IF(ABS(P27)>=30%,"显著",IF(ABS(P27)>=10%,"关注","")))
A28: 投资性房地产 | B28: =B27+1 -> 22 | D28: =IF(AND(C28<>0,$C$49<>0),C28/$C$49,"") | F28: =IF(AND(E28<>0,$E$49<>0),E28/$E$49,"") | G28: =IF(AND(D28="",F28=""),"",IF(D28="",F28,IF(F28="",-D28,F28-D28))) | H28: =IF(G28="","",IF(ABS(G28)>=30%,"显著",IF(ABS(G28)>=10%,"关注",""))) | J28: 长期应付职工薪酬 | K28: =K27+1 -> 65 | M28: =IF(AND(L28<>0,$L$49<>0),L28/$L$49,"") | O28: =IF(AND(N28<>0,$N$49<>0),N28/$N$49,"") | P28: =IF(AND(M28="",O28=""),"",IF(M28="",O28,IF(O28="",-M28,O28-M28))) | Q28: =IF(P28="","",IF(ABS(P28)>=30%,"显著",IF(ABS(P28)>=10%,"关注","")))
A29: 固定资产 | B29: =B28+1 -> 23 | D29: =IF(AND(C29<>0,$C$49<>0),C29/$C$49,"") | F29: =IF(AND(E29<>0,$E$49<>0),E29/$E$49,"") | G29: =IF(AND(D29="",F29=""),"",IF(D29="",F29,IF(F29="",-D29,F29-D29))) | H29: =IF(G29="","",IF(ABS(G29)>=30%,"显著",IF(ABS(G29)>=10%,"关注",""))) | J29: 预计负债 | K29: =K28+1 -> 66 | M29: =IF(AND(L29<>0,$L$49<>0),L29/$L$49,"") | O29: =IF(AND(N29<>0,$N$49<>0),N29/$N$49,"") | P29: =IF(AND(M29="",O29=""),"",IF(M29="",O29,IF(O29="",-M29,O29-M29))) | Q29: =IF(P29="","",IF(ABS(P29)>=30%,"显著",IF(ABS(P29)>=10%,"关注","")))
A30: 在建工程 | B30: =B29+1 -> 24 | D30: =IF(AND(C30<>0,$C$49<>0),C30/$C$49,"") | F30: =IF(AND(E30<>0,$E$49<>0),E30/$E$49,"") | G30: =IF(AND(D30="",F30=""),"",IF(D30="",F30,IF(F30="",-D30,F30-D30))) | H30: =IF(G30="","",IF(ABS(G30)>=30%,"显著",IF(ABS(G30)>=10%,"关注",""))) | J30: 递延收益 | K30: =K29+1 -> 67
A31: 生产性生物资产 | B31: =B30+1 -> 25 | D31: =IF(AND(C31<>0,$C$49<>0),C31/$C$49,"") | F31: =IF(AND(E31<>0,$E$49<>0),E31/$E$49,"") | G31: =IF(AND(D31="",F31=""),"",IF(D31="",F31,IF(F31="",-D31,F31-D31))) | H31: =IF(G31="","",IF(ABS(G31)>=30%,"显著",IF(ABS(G31)>=10%,"关注",""))) | J31: 递延所得税负债 | K31: =K30+1 -> 68 | M31: =IF(AND(L31<>0,$L$49<>0),L31/$L$49,"") | O31: =IF(AND(N31<>0,$N$49<>0),N31/$N$49,"") | P31: =IF(AND(M31="",O31=""),"",IF(M31="",O31,IF(O31="",-M31,O31-M31))) | Q31: =IF(P31="","",IF(ABS(P31)>=30%,"显著",IF(ABS(P31)>=10%,"关注","")))
A32: 油气资产 | B32: =B31+1 -> 26 | D32: =IF(AND(C32<>0,$C$49<>0),C32/$C$49,"") | F32: =IF(AND(E32<>0,$E$49<>0),E32/$E$49,"") | G32: =IF(AND(D32="",F32=""),"",IF(D32="",F32,IF(F32="",-D32,F32-D32))) | H32: =IF(G32="","",IF(ABS(G32)>=30%,"显著",IF(ABS(G32)>=10%,"关注",""))) | J32: 其他非流动负债 | K32: =K31+1 -> 69 | M32: =IF(AND(L32<>0,$L$49<>0),L32/$L$49,"") | O32: =IF(AND(N32<>0,$N$49<>0),N32/$N$49,"") | P32: =IF(AND(M32="",O32=""),"",IF(M32="",O32,IF(O32="",-M32,O32-M32))) | Q32: =IF(P32="","",IF(ABS(P32)>=30%,"显著",IF(ABS(P32)>=10%,"关注","")))
A33: 无形资产 | B33: =B32+1 -> 27 | D33: =IF(AND(C33<>0,$C$49<>0),C33/$C$49,"") | F33: =IF(AND(E33<>0,$E$49<>0),E33/$E$49,"") | G33: =IF(AND(D33="",F33=""),"",IF(D33="",F33,IF(F33="",-D33,F33-D33))) | H33: =IF(G33="","",IF(ABS(G33)>=30%,"显著",IF(ABS(G33)>=10%,"关注",""))) | J33: 非流动负债合计 | K33: =K32+1 -> 70 | L33: =SUM(L23:L32)-L25-L26 -> 0 | M33: =IF(AND(L33<>0,$L$49<>0),L33/$L$49,"") | N33: =SUM(N23:N32)-N25-N26 -> 0 | O33: =IF(AND(N33<>0,$N$49<>0),N33/$N$49,"") | P33: =IF(AND(M33="",O33=""),"",IF(M33="",O33,IF(O33="",-M33,O33-M33))) | Q33: =IF(P33="","",IF(ABS(P33)>=30%,"显著",IF(ABS(P33)>=10%,"关注","")))
A34: 开发支出 | B34: =B33+1 -> 28 | D34: =IF(AND(C34<>0,$C$49<>0),C34/$C$49,"") | F34: =IF(AND(E34<>0,$E$49<>0),E34/$E$49,"") | G34: =IF(AND(D34="",F34=""),"",IF(D34="",F34,IF(F34="",-D34,F34-D34))) | H34: =IF(G34="","",IF(ABS(G34)>=30%,"显著",IF(ABS(G34)>=10%,"关注",""))) | J34: 负债合计 | K34: =K33+1 -> 71 | L34: =SUM(L21,L33) -> 0 | M34: =IF(AND(L34<>0,$L$49<>0),L34/$L$49,"") | N34: =SUM(N21,N33) -> 0 | O34: =IF(AND(N34<>0,$N$49<>0),N34/$N$49,"") | P34: =IF(AND(M34="",O34=""),"",IF(M34="",O34,IF(O34="",-M34,O34-M34))) | Q34: =IF(P34="","",IF(ABS(P34)>=30%,"显著",IF(ABS(P34)>=10%,"关注","")))
A35: 商誉 | B35: =B34+1 -> 29 | D35: =IF(AND(C35<>0,$C$49<>0),C35/$C$49,"") | F35: =IF(AND(E35<>0,$E$49<>0),E35/$E$49,"") | G35: =IF(AND(D35="",F35=""),"",IF(D35="",F35,IF(F35="",-D35,F35-D35))) | H35: =IF(G35="","",IF(ABS(G35)>=30%,"显著",IF(ABS(G35)>=10%,"关注",""))) | J35: 股东权益： | K35: =K34+1 -> 72 | M35: =IF(AND(L35<>0,$L$49<>0),L35/$L$49,"") | O35: =IF(AND(N35<>0,$N$49<>0),N35/$N$49,"") | P35: =IF(AND(M35="",O35=""),"",IF(M35="",O35,IF(O35="",-M35,O35-M35))) | Q35: =IF(P35="","",IF(ABS(P35)>=30%,"显著",IF(ABS(P35)>=10%,"关注","")))
A36: 长期待摊费用 | B36: =B35+1 -> 30 | D36: =IF(AND(C36<>0,$C$49<>0),C36/$C$49,"") | F36: =IF(AND(E36<>0,$E$49<>0),E36/$E$49,"") | G36: =IF(AND(D36="",F36=""),"",IF(D36="",F36,IF(F36="",-D36,F36-D36))) | H36: =IF(G36="","",IF(ABS(G36)>=30%,"显著",IF(ABS(G36)>=10%,"关注",""))) | J36: 股本 | K36: =K35+1 -> 73 | M36: =IF(AND(L36<>0,$L$49<>0),L36/$L$49,"") | O36: =IF(AND(N36<>0,$N$49<>0),N36/$N$49,"") | P36: =IF(AND(M36="",O36=""),"",IF(M36="",O36,IF(O36="",-M36,O36-M36))) | Q36: =IF(P36="","",IF(ABS(P36)>=30%,"显著",IF(ABS(P36)>=10%,"关注","")))
A37: 递延所得税资产 | B37: =B36+1 -> 31 | D37: =IF(AND(C37<>0,$C$49<>0),C37/$C$49,"") | F37: =IF(AND(E37<>0,$E$49<>0),E37/$E$49,"") | G37: =IF(AND(D37="",F37=""),"",IF(D37="",F37,IF(F37="",-D37,F37-D37))) | H37: =IF(G37="","",IF(ABS(G37)>=30%,"显著",IF(ABS(G37)>=10%,"关注",""))) | J37: 其他权益工具 | K37: =K36+1 -> 74 | M37: =IF(AND(L37<>0,$L$49<>0),L37/$L$49,"") | O37: =IF(AND(N37<>0,$N$49<>0),N37/$N$49,"") | P37: =IF(AND(M37="",O37=""),"",IF(M37="",O37,IF(O37="",-M37,O37-M37))) | Q37: =IF(P37="","",IF(ABS(P37)>=30%,"显著",IF(ABS(P37)>=10%,"关注","")))
A38: 其他非流动资产 | B38: =B37+1 -> 32 | D38: =IF(AND(C38<>0,$C$49<>0),C38/$C$49,"") | F38: =IF(AND(E38<>0,$E$49<>0),E38/$E$49,"") | G38: =IF(AND(D38="",F38=""),"",IF(D38="",F38,IF(F38="",-D38,F38-D38))) | H38: =IF(G38="","",IF(ABS(G38)>=30%,"显著",IF(ABS(G38)>=10%,"关注",""))) | J38: 其中：优先股 | K38: =K37+1 -> 75 | M38: =IF(AND(L38<>0,$L$49<>0),L38/$L$49,"") | O38: =IF(AND(N38<>0,$N$49<>0),N38/$N$49,"") | P38: =IF(AND(M38="",O38=""),"",IF(M38="",O38,IF(O38="",-M38,O38-M38))) | Q38: =IF(P38="","",IF(ABS(P38)>=30%,"显著",IF(ABS(P38)>=10%,"关注","")))
B39: =B38+1 -> 33 | D39: =IF(AND(C39<>0,$C$49<>0),C39/$C$49,"") | F39: =IF(AND(E39<>0,$E$49<>0),E39/$E$49,"") | G39: =IF(AND(D39="",F39=""),"",IF(D39="",F39,IF(F39="",-D39,F39-D39))) | H39: =IF(G39="","",IF(ABS(G39)>=30%,"显著",IF(ABS(G39)>=10%,"关注",""))) | J39: 永续债 | K39: =K38+1 -> 76 | M39: =IF(AND(L39<>0,$L$49<>0),L39/$L$49,"") | O39: =IF(AND(N39<>0,$N$49<>0),N39/$N$49,"") | P39: =IF(AND(M39="",O39=""),"",IF(M39="",O39,IF(O39="",-M39,O39-M39))) | Q39: =IF(P39="","",IF(ABS(P39)>=30%,"显著",IF(ABS(P39)>=10%,"关注","")))
B40: =B39+1 -> 34 | D40: =IF(AND(C40<>0,$C$49<>0),C40/$C$49,"") | F40: =IF(AND(E40<>0,$E$49<>0),E40/$E$49,"") | G40: =IF(AND(D40="",F40=""),"",IF(D40="",F40,IF(F40="",-D40,F40-D40))) | H40: =IF(G40="","",IF(ABS(G40)>=30%,"显著",IF(ABS(G40)>=10%,"关注",""))) | J40: 资本公积 | K40: =K39+1 -> 77 | M40: =IF(AND(L40<>0,$L$49<>0),L40/$L$49,"") | O40: =IF(AND(N40<>0,$N$49<>0),N40/$N$49,"") | P40: =IF(AND(M40="",O40=""),"",IF(M40="",O40,IF(O40="",-M40,O40-M40))) | Q40: =IF(P40="","",IF(ABS(P40)>=30%,"显著",IF(ABS(P40)>=10%,"关注","")))
...

Sheet 已审利润横向分析A1-14-3
A1: 已审利润表（合并）横向分析
A2: ='[31]已审资产负债纵向分析A1-13-2'!A2 -> 客户名称： | B2: ='[31]已审资产负债纵向分析A1-13-2'!E2 -> 编制人： | E2: ='[31]已审资产负债纵向分析A1-13-2'!G2 -> 日期： | H2: 索引：A1-13-3
A3: 会计期间：2017年度 | B3: ='[31]已审资产负债纵向分析A1-13-2'!E3 -> 复核人： | E3: ='[31]已审资产负债纵向分析A1-13-2'!G3 -> 日期： | H3: 页次：1
A4: 项目 | B4: 行次 | C4: 上年审定数 | D4: 本年审定数 | E4: 本年比上年增长 | G4: 变动状况（显著/关注) | H4: 显著变动原因分析；需进一步调查或解释的差异
E5: 变动额 | F5: 变动％
C6: ① | D6: ② | E6: ③=②-① | F6: ④=③/①
A7: 一、营业收入 | B7: 1 | E7: =D7-C7 -> 0 | F7: =IF(AND(C7=0,D7=0),"",IF(C7=0,100%,IF(D7=0,-100%,E7/C7))) | G7: =IF(F7="","",IF(OR(ABS(F7)>=30%,ABS(E7)>='[31]已审资产负债横向分析A1-13-1'!$D$51*5%,ABS(E7)>=$D$27*10%),"显著",IF(ABS(F7)>=10%,"关注","")))
A8: 其中：主营业务收入 | B8: 2 | E8: =D8-C8 -> 0 | F8: =IF(AND(C8=0,D8=0),"",IF(C8=0,100%,IF(D8=0,-100%,E8/C8))) | G8: =IF(F8="","",IF(OR(ABS(F8)>=30%,ABS(E8)>='[31]已审资产负债横向分析A1-13-1'!$D$51*5%,ABS(E8)>=$D$27*10%),"显著",IF(ABS(F8)>=10%,"关注","")))
A9: 其他业务收入 | B9: 3 | E9: =D9-C9 -> 0 | F9: =IF(AND(C9=0,D9=0),"",IF(C9=0,100%,IF(D9=0,-100%,E9/C9))) | G9: =IF(F9="","",IF(OR(ABS(F9)>=30%,ABS(E9)>='[31]已审资产负债横向分析A1-13-1'!$D$51*5%,ABS(E9)>=$D$27*10%),"显著",IF(ABS(F9)>=10%,"关注","")))
A10: 减：营业成本 | B10: 4 | E10: =D10-C10 -> 0 | F10: =IF(AND(C10=0,D10=0),"",IF(C10=0,100%,IF(D10=0,-100%,E10/C10))) | G10: =IF(F10="","",IF(OR(ABS(F10)>=30%,ABS(E10)>='[31]已审资产负债横向分析A1-13-1'!$D$51*5%,ABS(E10)>=$D$27*10%),"显著",IF(ABS(F10)>=10%,"关注","")))
A11: 其中：主营业务成本 | B11: 5 | E11: =D11-C11 -> 0 | F11: =IF(AND(C11=0,D11=0),"",IF(C11=0,100%,IF(D11=0,-100%,E11/C11))) | G11: =IF(F11="","",IF(OR(ABS(F11)>=30%,ABS(E11)>='[31]已审资产负债横向分析A1-13-1'!$D$51*5%,ABS(E11)>=$D$27*10%),"显著",IF(ABS(F11)>=10%,"关注","")))
A12: 其他业务成本 | B12: 6 | E12: =D12-C12 -> 0 | F12: =IF(AND(C12=0,D12=0),"",IF(C12=0,100%,IF(D12=0,-100%,E12/C12))) | G12: =IF(F12="","",IF(OR(ABS(F12)>=30%,ABS(E12)>='[31]已审资产负债横向分析A1-13-1'!$D$51*5%,ABS(E12)>=$D$27*10%),"显著",IF(ABS(F12)>=10%,"关注","")))
A13: 税金及附加 | B13: 7 | E13: =D13-C13 -> 0 | F13: =IF(AND(C13=0,D13=0),"",IF(C13=0,100%,IF(D13=0,-100%,E13/C13))) | G13: =IF(F13="","",IF(OR(ABS(F13)>=30%,ABS(E13)>='[31]已审资产负债横向分析A1-13-1'!$D$51*5%,ABS(E13)>=$D$27*10%),"显著",IF(ABS(F13)>=10%,"关注","")))
A14: 销售费用 | B14: 8 | E14: =D14-C14 -> 0 | F14: =IF(AND(C14=0,D14=0),"",IF(C14=0,100%,IF(D14=0,-100%,E14/C14))) | G14: =IF(F14="","",IF(OR(ABS(F14)>=30%,ABS(E14)>='[31]已审资产负债横向分析A1-13-1'!$D$51*5%,ABS(E14)>=$D$27*10%),"显著",IF(ABS(F14)>=10%,"关注","")))
A15: 管理费用 | B15: 9 | E15: =D15-C15 -> 0 | F15: =IF(AND(C15=0,D15=0),"",IF(C15=0,100%,IF(D15=0,-100%,E15/C15))) | G15: =IF(F15="","",IF(OR(ABS(F15)>=30%,ABS(E15)>='[31]已审资产负债横向分析A1-13-1'!$D$51*5%,ABS(E15)>=$D$27*10%),"显著",IF(ABS(F15)>=10%,"关注","")))
A16: 其中：业务招待费 | B16: 10 | E16: =D16-C16 -> 0 | F16: =IF(AND(C16=0,D16=0),"",IF(C16=0,100%,IF(D16=0,-100%,E16/C16))) | G16: =IF(F16="","",IF(OR(ABS(F16)>=30%,ABS(E16)>='[31]已审资产负债横向分析A1-13-1'!$D$51*5%,ABS(E16)>=$D$27*10%),"显著",IF(ABS(F16)>=10%,"关注","")))
A17: 研发费用 | B17: 11 | E17: =D17-C17 -> 0 | F17: =IF(AND(C17=0,D17=0),"",IF(C17=0,100%,IF(D17=0,-100%,E17/C17))) | G17: =IF(F17="","",IF(OR(ABS(F17)>=30%,ABS(E17)>='[31]已审资产负债横向分析A1-13-1'!$D$51*5%,ABS(E17)>=$D$27*10%),"显著",IF(ABS(F17)>=10%,"关注","")))
A18: 财务费用 | B18: 12 | E18: =D18-C18 -> 0 | F18: =IF(AND(C18=0,D18=0),"",IF(C18=0,100%,IF(D18=0,-100%,E18/C18))) | G18: =IF(F18="","",IF(OR(ABS(F18)>=30%,ABS(E18)>='[31]已审资产负债横向分析A1-13-1'!$D$51*5%,ABS(E18)>=$D$27*10%),"显著",IF(ABS(F18)>=10%,"关注","")))
... A24: 其中：对联营企业和合营企业的投资收益 | B24: 20 | E24: =D24-C24 -> 0 | F24: =IF(AND(C24=0,D24=0),"",IF(C24=0,100%,IF(D24=0,-100%,E24/C24))) | G24: =IF(F24="","",IF(OR(ABS(F24)>=30%,ABS(E24)>='[31]已审资产负债横向分析A1-13-1'!$D$51*5%,ABS(E24)>=$D$27*10%),"显著",IF(ABS(F24)>=10%,"关注","")))
A25: 公允价值变动收益(损失以“-”号填列） | B25: 21 | E25: =D25-C25 -> 0 | F25: =IF(AND(C25=0,D25=0),"",IF(C25=0,100%,IF(D25=0,-100%,E25/C25)))
A26: 资产处置收益(损失以“-”号填列） | B26: 22 | E26: =D26-C26 -> 0 | F26: =IF(AND(C26=0,D26=0),"",IF(C26=0,100%,IF(D26=0,-100%,E26/C26)))
A27: 二、营业利润（亏损以“－”号填列） | B27: 23 | C27: =SUM(C7)-SUM(C10,C13,C14,C15,C17,C18,C21)+SUM(C22,C23,C25,C26) -> 0 | D27: =SUM(D7)-SUM(D10,D13,D14,D15,D17,D18,D21)+SUM(D22,D23,D25,D26) -> 0 | E27: =D27-C27 -> 0 | F27: =IF(AND(C27=0,D27=0),"",IF(C27=0,100%,IF(D27=0,-100%,E27/C27))) | G27: =IF(F27="","",IF(OR(ABS(F27)>=30%,ABS(E27)>='[31]已审资产负债横向分析A1-13-1'!$D$51*5%,ABS(E27)>=$D$27*10%),"显著",IF(ABS(F27)>=10%,"关注","")))
A28: 加：营业外收入 | B28: 24 | E28: =D28-C28 -> 0 | F28: =IF(AND(C28=0,D28=0),"",IF(C28=0,100%,IF(D28=0,-100%,E28/C28))) | G28: =IF(F28="","",IF(OR(ABS(F28)>=30%,ABS(E28)>='[31]已审资产负债横向分析A1-13-1'!$D$51*5%,ABS(E28)>=$D$27*10%),"显著",IF(ABS(F28)>=10%,"关注","")))
A29: 减：营业外支出 | B29: 25 | E29: =D29-C29 -> 0 | F29: =IF(AND(C29=0,D29=0),"",IF(C29=0,100%,IF(D29=0,-100%,E29/C29))) | G29: =IF(F29="","",IF(OR(ABS(F29)>=30%,ABS(E29)>='[31]已审资产负债横向分析A1-13-1'!$D$51*5%,ABS(E29)>=$D$27*10%),"显著",IF(ABS(F29)>=10%,"关注","")))
A30: 三、利润总额（亏损总额以“－”号填列） | B30: 26 | C30: =SUM(C27)+SUM(C28)-SUM(C29) -> 0 | D30: =SUM(D27)+SUM(D28)-SUM(D29) -> 0 | E30: =D30-C30 -> 0 | F30: =IF(AND(C30=0,D30=0),"",IF(C30=0,100%,IF(D30=0,-100%,E30/C30))) | G30: =IF(F30="","",IF(OR(ABS(F30)>=30%,ABS(E30)>='[31]已审资产负债横向分析A1-13-1'!$D$51*5%,ABS(E30)>=$D$27*10%),"显著",IF(ABS(F30)>=10%,"关注","")))
A31: 减：所得税费用 | B31: 27 | E31: =D31-C31 -> 0 | F31: =IF(AND(C31=0,D31=0),"",IF(C31=0,100%,IF(D31=0,-100%,E31/C31))) | G31: =IF(F31="","",IF(OR(ABS(F31)>=30%,ABS(E31)>='[31]已审资产负债横向分析A1-13-1'!$D$51*5%,ABS(E31)>=$D$27*10%),"显著",IF(ABS(F31)>=10%,"关注","")))
A32: 0 | B32: 28 | E32: =D32-C32 -> 0 | F32: =IF(AND(C32=0,D32=0),"",IF(C32=0,100%,IF(D32=0,-100%,E32/C32))) | G32: =IF(F32="","",IF(OR(ABS(F32)>=30%,ABS(E32)>='[31]已审资产负债横向分析A1-13-1'!$D$51*5%,ABS(E32)>=$D$27*10%),"显著",IF(ABS(F32)>=10%,"关注","")))
A33: 四、净利润（净亏损以“－”号填列） | B33: 29 | C33: =C30-C31-C32 -> 0 | D33: =D30-D31-D32 -> 0 | E33: =D33-C33 -> 0 | F33: =IF(AND(C33=0,D33=0),"",IF(C33=0,100%,IF(D33=0,-100%,E33/C33))) | G33: =IF(F33="","",IF(OR(ABS(F33)>=30%,ABS(E33)>='[31]已审资产负债横向分析A1-13-1'!$D$51*5%,ABS(E33)>=$D$27*10%),"显著",IF(ABS(F33)>=10%,"关注","")))
A34: （一）按经营持续性分类 | B34: 30
A35: 1、持续经营净利润（净亏损以“-”号填列） | B35: 31 | E35: =D35-C35 -> 0 | F35: =IF(AND(C35=0,D35=0),"",IF(C35=0,100%,IF(D35=0,-100%,E35/C35)))
A36: 2、终止经营净利润（净亏损以“-”号填列） | B36: 32 | E36: =D36-C36 -> 0 | F36: =IF(AND(C36=0,D36=0),"",IF(C36=0,100%,IF(D36=0,-100%,E36/C36)))
A37: （二）按所有权归属分类 | B37: 33
A38: 1、归属于母公司股东的净利润 | B38: 34 | E38: =D38-C38 -> 0 | F38: =IF(AND(C38=0,D38=0),"",IF(C38=0,100%,IF(D38=0,-100%,E38/C38))) | G38: =IF(F38="","",IF(OR(ABS(F38)>=30%,ABS(E38)>='[31]已审资产负债横向分析A1-13-1'!$D$51*5%,ABS(E38)>=$D$27*10%),"显著",IF(ABS(F38)>=10%,"关注","")))
A39: 2、少数股东损益 | B39: 35 | E39: =D39-C39 -> 0 | F39: =IF(AND(C39=0,D39=0),"",IF(C39=0,100%,IF(D39=0,-100%,E39/C39))) | G39: =IF(F39="","",IF(OR(ABS(F39)>=30%,ABS(E39)>='[31]已审资产负债横向分析A1-13-1'!$D$51*5%,ABS(E39)>=$D$27*10%),"显著",IF(ABS(F39)>=10%,"关注","")))
A40: 五、其他综合收益税后净额 | B40: 36 | E40: =D40-C40 -> 0
A41: 归属于母公司股东的其他综合收益的税后净额 | B41: 37 | E41: =D41-C41 -> 0
A42: （一）以后不能重分类进损益的其他综合收益 | B42: 38 | E42: =D42-C42 -> 0
A43: 1、重新计量设定受益计划变动额 | B43: 39 | E43: =D43-C43 -> 0
A44: 2、权益法下不能转损益的其他综合收益 | B44: 40 | E44: =D44-C44 -> 0
A45: 3、其他（不适用的删除） | B45: 41 | E45: =D45-C45 -> 0
...

Sheet 已审利润纵向分析A1-14-4
A1: 已审利润表（合并）纵向分析
A2: ='[31]已审利润横向分析A1-13-3'!A2 -> 客户名称： | B2: ='[31]已审利润横向分析A1-13-3'!B2 -> 编制人： | F2: ='[31]已审利润横向分析A1-13-3'!E2 -> 日期： | I2: 索引：A1-13-4
A3: ='已审利润横向分析A1-14-3'!A3 -> 会计期间：2017年度 | B3: ='[31]已审利润横向分析A1-13-3'!B3 -> 复核人： | F3: ='[31]已审利润横向分析A1-13-3'!E3 -> 日期： | I3: 页次：1
A4: 项目 | B4: 行次 | C4: 上年审定数 | E4: 本年审定数 | G4: 本年比上年 增长差异 | H4: 变动状况（显著/关注) | I4: 显著变动原因分析；需进一步调查或解释的差异
C5: 已审数 | D5: 比重% | E5: 审定数 | F5: 比重%
C6: ① | D6: ② | E6: ③ | F6: ④ | G6: ⑤=④-②
A7: 一、营业收入 | B7: 1 | D7: =IF(AND(C7<>0,$C$7<>0),C7/$C$7,"") | F7: =IF(AND(E7<>0,$E$7<>0),E7/$E$7,"") | G7: =IF(AND(D7="",F7=""),"",IF(D7="",F7,IF(F7="",-D7,F7-D7))) | H7: =IF(G7="","",IF(ABS(G7)>=30%,"显著",IF(ABS(G7)>=10%,"关注",""))) | J7: 上市公司需填写信息：
A8: 其中：主营业务收入 | B8: 2 | D8: =IF(AND(C8<>0,$C$7<>0),C8/$C$7,"") | F8: =IF(AND(E8<>0,$E$7<>0),E8/$E$7,"") | G8: =IF(AND(D8="",F8=""),"",IF(D8="",F8,IF(F8="",-D8,F8-D8))) | H8: =IF(G8="","",IF(ABS(G8)>=30%,"显著",IF(ABS(G8)>=10%,"关注",""))) | J8: 上市板块
A9: 其他业务收入 | B9: 3 | D9: =IF(AND(C9<>0,$C$7<>0),C9/$C$7,"") | F9: =IF(AND(E9<>0,$E$7<>0),E9/$E$7,"") | G9: =IF(AND(D9="",F9=""),"",IF(D9="",F9,IF(F9="",-D9,F9-D9))) | H9: =IF(G9="","",IF(ABS(G9)>=30%,"显著",IF(ABS(G9)>=10%,"关注",""))) | J9: 扣除非经常性损益后的净利润
A10: 减：营业成本 | B10: 4 | D10: =IF(AND(C10<>0,$C$7<>0),C10/$C$7,"") | F10: =IF(AND(E10<>0,$E$7<>0),E10/$E$7,"") | G10: =IF(AND(D10="",F10=""),"",IF(D10="",F10,IF(F10="",-D10,F10-D10))) | H10: =IF(G10="","",IF(ABS(G10)>=30%,"显著",IF(ABS(G10)>=10%,"关注",""))) | J10: 是否需出具营业收入扣除情况说明专项核查报告 | L10: =IF((MIN(E30,E33,L9)<0),"是","否") -> 否
A11: 其中：主营业务成本 | B11: 5 | D11: =IF(AND(C11<>0,$C$7<>0),C11/$C$7,"") | F11: =IF(AND(E11<>0,$E$7<>0),E11/$E$7,"") | G11: =IF(AND(D11="",F11=""),"",IF(D11="",F11,IF(F11="",-D11,F11-D11))) | H11: =IF(G11="","",IF(ABS(G11)>=30%,"显著",IF(ABS(G11)>=10%,"关注","")))
A12: 其他业务成本 | B12: 6 | D12: =IF(AND(C12<>0,$C$7<>0),C12/$C$7,"") | F12: =IF(AND(E12<>0,$E$7<>0),E12/$E$7,"") | G12: =IF(AND(D12="",F12=""),"",IF(D12="",F12,IF(F12="",-D12,F12-D12))) | H12: =IF(G12="","",IF(ABS(G12)>=30%,"显著",IF(ABS(G12)>=10%,"关注",""))) | J12: 是否需出具非经常性损益专项核查报告 | L12: =IF(AND(OR(AND(L8="沪深主板",E7<300000000),AND(OR(L8="科创板",L8="创业板"),E7<100000000)),E30>0,E33>0,L9>0),"是","否") -> 否
A13: 税金及附加 | B13: 7 | D13: =IF(AND(C13<>0,$C$7<>0),C13/$C$7,"") | F13: =IF(AND(E13<>0,$E$7<>0),E13/$E$7,"") | G13: =IF(AND(D13="",F13=""),"",IF(D13="",F13,IF(F13="",-D13,F13-D13))) | H13: =IF(G13="","",IF(ABS(G13)>=30%,"显著",IF(ABS(G13)>=10%,"关注","")))
A14: 销售费用 | B14: 8 | D14: =IF(AND(C14<>0,$C$7<>0),C14/$C$7,"") | F14: =IF(AND(E14<>0,$E$7<>0),E14/$E$7,"") | G14: =IF(AND(D14="",F14=""),"",IF(D14="",F14,IF(F14="",-D14,F14-D14))) | H14: =IF(G14="","",IF(ABS(G14)>=30%,"显著",IF(ABS(G14)>=10%,"关注","")))
A15: 管理费用 | B15: 9 | D15: =IF(AND(C15<>0,$C$7<>0),C15/$C$7,"") | F15: =IF(AND(E15<>0,$E$7<>0),E15/$E$7,"") | G15: =IF(AND(D15="",F15=""),"",IF(D15="",F15,IF(F15="",-D15,F15-D15))) | H15: =IF(G15="","",IF(ABS(G15)>=30%,"显著",IF(ABS(G15)>=10%,"关注","")))
A16: 其中：业务招待费 | B16: 10 | D16: =IF(AND(C16<>0,$C$7<>0),C16/$C$7,"") | F16: =IF(AND(E16<>0,$E$7<>0),E16/$E$7,"") | G16: =IF(AND(D16="",F16=""),"",IF(D16="",F16,IF(F16="",-D16,F16-D16))) | H16: =IF(G16="","",IF(ABS(G16)>=30%,"显著",IF(ABS(G16)>=10%,"关注","")))
A17: 研发费用 | B17: 11 | D17: =IF(AND(C17<>0,$C$7<>0),C17/$C$7,"") | F17: =IF(AND(E17<>0,$E$7<>0),E17/$E$7,"") | G17: =IF(AND(D17="",F17=""),"",IF(D17="",F17,IF(F17="",-D17,F17-D17))) | H17: =IF(G17="","",IF(ABS(G17)>=30%,"显著",IF(ABS(G17)>=10%,"关注","")))
A18: 财务费用 | B18: 12 | D18: =IF(AND(C18<>0,$C$7<>0),C18/$C$7,"") | F18: =IF(AND(E18<>0,$E$7<>0),E18/$E$7,"") | G18: =IF(AND(D18="",F18=""),"",IF(D18="",F18,IF(F18="",-D18,F18-D18))) | H18: =IF(G18="","",IF(ABS(G18)>=30%,"显著",IF(ABS(G18)>=10%,"关注","")))
A19: 其中：利息费用 | B19: 13 | D19: =IF(AND(C19<>0,$C$7<>0),C19/$C$7,"") | F19: =IF(AND(E19<>0,$E$7<>0),E19/$E$7,"") | G19: =IF(AND(D19="",F19=""),"",IF(D19="",F19,IF(F19="",-D19,F19-D19))) | H19: =IF(G19="","",IF(ABS(G19)>=30%,"显著",IF(ABS(G19)>=10%,"关注","")))
A20: 利息收入 | B20: 14 | D20: =IF(AND(C20<>0,$C$7<>0),C20/$C$7,"") | F20: =IF(AND(E20<>0,$E$7<>0),E20/$E$7,"") | G20: =IF(AND(D20="",F20=""),"",IF(D20="",F20,IF(F20="",-D20,F20-D20))) | H20: =IF(G20="","",IF(ABS(G20)>=30%,"显著",IF(ABS(G20)>=10%,"关注","")))
A21: 资产减值损失 | B21: 16 | D21: =IF(AND(C21<>0,$C$7<>0),C21/$C$7,"") | F21: =IF(AND(E21<>0,$E$7<>0),E21/$E$7,"") | G21: =IF(AND(D21="",F21=""),"",IF(D21="",F21,IF(F21="",-D21,F21-D21))) | H21: =IF(G21="","",IF(ABS(G21)>=30%,"显著",IF(ABS(G21)>=10%,"关注","")))
A22: 加：其他收益 | B22: 18 | D22: =IF(AND(C22<>0,$C$7<>0),C22/$C$7,"") | F22: =IF(AND(E22<>0,$E$7<>0),E22/$E$7,"") | G22: =IF(AND(D22="",F22=""),"",IF(D22="",F22,IF(F22="",-D22,F22-D22))) | H22: =IF(G22="","",IF(ABS(G22)>=30%,"显著",IF(ABS(G22)>=10%,"关注","")))
A23: 投资收益（损失以“－”号填列） | B23: 19 | D23: =IF(AND(C23<>0,$C$7<>0),C23/$C$7,"") | F23: =IF(AND(E23<>0,$E$7<>0),E23/$E$7,"") | G23: =IF(AND(D23="",F23=""),"",IF(D23="",F23,IF(F23="",-D23,F23-D23))) | H23: =IF(G23="","",IF(ABS(G23)>=30%,"显著",IF(ABS(G23)>=10%,"关注","")))
A24: 其中：对联营企业和合营企业的投资收益 | B24: 20 | D24: =IF(AND(C24<>0,$C$7<>0),C24/$C$7,"") | F24: =IF(AND(E24<>0,$E$7<>0),E24/$E$7,"") | G24: =IF(AND(D24="",F24=""),"",IF(D24="",F24,IF(F24="",-D24,F24-D24))) | H24: =IF(G24="","",IF(ABS(G24)>=30%,"显著",IF(ABS(G24)>=10%,"关注","")))
A25: 公允价值变动收益(损失以“-”号填列） | B25: 21 | D25: =IF(AND(C25<>0,$C$7<>0),C25/$C$7,"") | F25: =IF(AND(E25<>0,$E$7<>0),E25/$E$7,"") | G25: =IF(AND(D25="",F25=""),"",IF(D25="",F25,IF(F25="",-D25,F25-D25)))
A26: 资产处置收益(损失以“-”号填列） | B26: 22 | D26: =IF(AND(C26<>0,$C$7<>0),C26/$C$7,"") | F26: =IF(AND(E26<>0,$E$7<>0),E26/$E$7,"") | G26: =IF(AND(D26="",F26=""),"",IF(D26="",F26,IF(F26="",-D26,F26-D26)))
A27: 二、营业利润（亏损以“－”号填列） | B27: 23 | C27: =SUM(C7)-SUM(C10,C13,C14,C15,C17,C18,C21)+SUM(C22,C23,C25,C26) -> 0 | D27: =IF(AND(C27<>0,$C$7<>0),C27/$C$7,"") | E27: =SUM(E7)-SUM(E10,E13,E14,E15,E17,E18,E21)+SUM(E22,E23,E25,E26) -> 0 | F27: =IF(AND(E27<>0,$E$7<>0),E27/$E$7,"") | G27: =IF(AND(D27="",F27=""),"",IF(D27="",F27,IF(F27="",-D27,F27-D27))) | H27: =IF(G27="","",IF(ABS(G27)>=30%,"显著",IF(ABS(G27)>=10%,"关注","")))
A28: 加：营业外收入 | B28: 24 | D28: =IF(AND(C28<>0,$C$7<>0),C28/$C$7,"") | F28: =IF(AND(E28<>0,$E$7<>0),E28/$E$7,"") | G28: =IF(AND(D28="",F28=""),"",IF(D28="",F28,IF(F28="",-D28,F28-D28))) | H28: =IF(G28="","",IF(ABS(G28)>=30%,"显著",IF(ABS(G28)>=10%,"关注","")))
A29: 减：营业外支出 | B29: 25 | D29: =IF(AND(C29<>0,$C$7<>0),C29/$C$7,"") | F29: =IF(AND(E29<>0,$E$7<>0),E29/$E$7,"") | G29: =IF(AND(D29="",F29=""),"",IF(D29="",F29,IF(F29="",-D29,F29-D29))) | H29: =IF(G29="","",IF(ABS(G29)>=30%,"显著",IF(ABS(G29)>=10%,"关注","")))
A30: 三、利润总额（亏损总额以“－”号填列） | B30: 26 | C30: =SUM(C27)+SUM(C28)-SUM(C29) -> 0 | D30: =IF(AND(C30<>0,$C$7<>0),C30/$C$7,"") | E30: =SUM(E27)+SUM(E28)-SUM(E29) -> 0 | F30: =IF(AND(E30<>0,$E$7<>0),E30/$E$7,"") | G30: =IF(AND(D30="",F30=""),"",IF(D30="",F30,IF(F30="",-D30,F30-D30))) | H30: =IF(G30="","",IF(ABS(G30)>=30%,"显著",IF(ABS(G30)>=10%,"关注","")))
A31: 减：所得税费用 | B31: 27 | D31: =IF(AND(C31<>0,$C$7<>0),C31/$C$7,"") | F31: =IF(AND(E31<>0,$E$7<>0),E31/$E$7,"") | G31: =IF(AND(D31="",F31=""),"",IF(D31="",F31,IF(F31="",-D31,F31-D31))) | H31: =IF(G31="","",IF(ABS(G31)>=30%,"显著",IF(ABS(G31)>=10%,"关注","")))
A32: 0 | B32: 28 | D32: =IF(AND(C32<>0,$C$7<>0),C32/$C$7,"") | F32: =IF(AND(E32<>0,$E$7<>0),E32/$E$7,"") | G32: =IF(AND(D32="",F32=""),"",IF(D32="",F32,IF(F32="",-D32,F32-D32))) | H32: =IF(G32="","",IF(ABS(G32)>=30%,"显著",IF(ABS(G32)>=10%,"关注","")))
A33: 四、净利润（净亏损以“－”号填列） | B33: 29 | C33: =C30-C31-C32 -> 0 | D33: =IF(AND(C33<>0,$C$7<>0),C33/$C$7,"") | E33: =E30-E31-E32 -> 0 | F33: =IF(AND(E33<>0,$E$7<>0),E33/$E$7,"") | G33: =IF(AND(D33="",F33=""),"",IF(D33="",F33,IF(F33="",-D33,F33-D33))) | H33: =IF(G33="","",IF(ABS(G33)>=30%,"显著",IF(ABS(G33)>=10%,"关注","")))
A34: （一）按经营持续性分类 | B34: 30
A35: 1、持续经营净利润（净亏损以“-”号填列） | B35: 31 | D35: =IF(AND(C35<>0,$C$7<>0),C35/$C$7,"") | F35: =IF(AND(E35<>0,$E$7<>0),E35/$E$7,"") | G35: =IF(AND(D35="",F35=""),"",IF(D35="",F35,IF(F35="",-D35,F35-D35)))
A36: 2、终止经营净利润（净亏损以“-”号填列） | B36: 32 | D36: =IF(AND(C36<>0,$C$7<>0),C36/$C$7,"") | F36: =IF(AND(E36<>0,$E$7<>0),E36/$E$7,"") | G36: =IF(AND(D36="",F36=""),"",IF(D36="",F36,IF(F36="",-D36,F36-D36)))
A37: （二）按所有权归属分类 | B37: 33
A38: 1、归属于母公司股东的净利润 | B38: 34 | D38: =IF(AND(C38<>0,$C$7<>0),C38/$C$7,"") | F38: =IF(AND(E38<>0,$E$7<>0),E38/$E$7,"") | G38: =IF(AND(D38="",F38=""),"",IF(D38="",F38,IF(F38="",-D38,F38-D38))) | H38: =IF(G38="","",IF(ABS(G38)>=30%,"显著",IF(ABS(G38)>=10%,"关注","")))
A39: 2、少数股东损益 | B39: 35 | D39: =IF(AND(C39<>0,$C$7<>0),C39/$C$7,"") | F39: =IF(AND(E39<>0,$E$7<>0),E39/$E$7,"") | G39: =IF(AND(D39="",F39=""),"",IF(D39="",F39,IF(F39="",-D39,F39-D39))) | H39: =IF(G39="","",IF(ABS(G39)>=30%,"显著",IF(ABS(G39)>=10%,"关注","")))
A40: 五、其他综合收益税后净额 | B40: 36 | E40: =D40-C40 -> 0
...

Sheet 已审报表比率分析A1-14-5
A1: 已审报表财务比率分析
A2: ='已审利润纵向分析A1-14-4'!A2 -> 客户名称： | C2: ='已审利润纵向分析A1-14-4'!B2 -> 编制人： | F2: ='已审利润纵向分析A1-14-4'!F2 -> 日期： | I2: 索引：A1-14-5
A3: ='已审利润纵向分析A1-14-4'!A3 -> 会计期间：2017年度 | C3: ='已审利润纵向分析A1-14-4'!B3 -> 复核人： | F3: ='已审利润纵向分析A1-14-4'!F3 -> 日期： | I3: 页次：1
A4: 指标名称 | B4: 计算公式 | C4: 上年审定数 | F4: 本年审定数 | I4: 增减 | J4: 结论
C5: 分子数值 | D5: 分母数值 | E5: 指标值 | F5: 分子数值 | G5: 分母数值 | H5: 指标值
A6: 一、获利能力分析
A7: 1、长期资本报酬率 | B7: （利润总额+利息支出净额）/（长期负债平均值+所有者权益平均值） | E7: =IF(D7=0,0,C7/D7) -> 0 | F7: =('已审利润纵向分析A1-14-4'!E30+'已审利润纵向分析A1-14-4'!E19-'已审利润纵向分析A1-14-4'!E20)/12*12 -> 0 | G7: =('已审资产负债纵向分析A1-14-2'!L33+'已审资产负债纵向分析A1-14-2'!N33)/2+('已审资产负债纵向分析A1-14-2'!L46+'已审资产负债纵向分析A1-14-2'!N46)/2 -> 0 | H7: =IF(G7=0,0,F7/G7) -> 0 | I7: =IF(E7=0,0,(H7-E7)/E7) -> 0 | J7: =IF(ABS(I7)<20%,"",IF(ABS(I7)<50%,"关注","显著"))
A8: 2、资本金收益率 | B8: 属于母公司所有者的净利润(annualized)/资本金总额 | E8: =IF(D8=0,0,C8/D8) -> 0 | F8: ='已审利润纵向分析A1-14-4'!E38/12*12 -> 0 | G8: ='已审资产负债纵向分析A1-14-2'!N36 -> 0 | H8: =IF(G8=0,0,F8/G8) -> 0 | I8: =IF(E8=0,0,(H8-E8)/E8) -> 0 | J8: =IF(ABS(I8)<20%,"",IF(ABS(I8)<50%,"关注","显著"))
A9: 3、股东权益报酬率 | B9: 净利润(annualized)/股东权益平均值 | E9: =IF(D9=0,0,C9/D9) -> 0 | F9: ='已审利润纵向分析A1-14-4'!E33/12*12 -> 0 | G9: =('已审资产负债纵向分析A1-14-2'!L48+'已审资产负债纵向分析A1-14-2'!N48)/2 -> 0 | H9: =IF(G9=0,0,F9/G9) -> 0 | I9: =IF(E9=0,0,(H9-E9)/E9) -> 0 | J9: =IF(ABS(I9)<20%,"",IF(ABS(I9)<50%,"关注","显著"))
A10: 4、总资产报酬率 | B10: （利润总额+利息支出净额）(annualized)/平均资产总值 | E10: =IF(D10=0,0,C10/D10) -> 0 | F10: =('已审利润纵向分析A1-14-4'!E30+'已审利润纵向分析A1-14-4'!E19-'已审利润纵向分析A1-14-4'!E20)/12*12 -> 0 | G10: =('已审资产负债纵向分析A1-14-2'!C49+'已审资产负债纵向分析A1-14-2'!E49)/2 -> 0 | H10: =IF(G10=0,0,F10/G10) -> 0 | I10: =IF(E10=0,0,(H10-E10)/E10) -> 0 | J10: =IF(ABS(I10)<20%,"",IF(ABS(I10)<50%,"关注","显著"))
A11: 5、毛利率 | B11: 毛利/营业收入净额 | E11: =IF(D11=0,0,C11/D11) -> 0 | F11: ='已审利润纵向分析A1-14-4'!E7-'已审利润纵向分析A1-14-4'!E10 -> 0 | G11: ='已审利润纵向分析A1-14-4'!E7 -> 0 | H11: =IF(G11=0,0,F11/G11) -> 0 | I11: =IF(E11=0,0,(H11-E11)/E11) -> 0 | J11: =IF(ABS(I11)<20%,"",IF(ABS(I11)<50%,"关注","显著"))
A12: 6、营业利润率 | B12: （营业利润+利息支出净额）/营业收入净额 | E12: =IF(D12=0,0,C12/D12) -> 0 | F12: ='已审利润纵向分析A1-14-4'!E27+'已审利润纵向分析A1-14-4'!E19-'已审利润纵向分析A1-14-4'!E20 -> 0 | G12: ='已审利润纵向分析A1-14-4'!E7 -> 0 | H12: =IF(G12=0,0,F12/G12) -> 0 | I12: =IF(E12=0,0,(H12-E12)/E12) -> 0 | J12: =IF(ABS(I12)<20%,"",IF(ABS(I12)<50%,"关注","显著"))
A13: 7、销售净利率 | B13: 净利润/营业收入净额 | E13: =IF(D13=0,0,C13/D13) -> 0 | F13: ='已审利润纵向分析A1-14-4'!E33 -> 0 | G13: ='已审利润纵向分析A1-14-4'!E7 -> 0 | H13: =IF(G13=0,0,F13/G13) -> 0 | I13: =IF(E13=0,0,(H13-E13)/E13) -> 0 | J13: =IF(ABS(I13)<20%,"",IF(ABS(I13)<50%,"关注","显著"))
A14: 8、成本费用利润率 | B14: 营业利润/（营业成本+销售费用+管理费用+财务费用+研发费用） | E14: =IF(D14=0,0,C14/D14) -> 0 | F14: ='已审利润纵向分析A1-14-4'!E27 -> 0 | G14: ='已审利润纵向分析A1-14-4'!E10+'已审利润纵向分析A1-14-4'!E14+'已审利润纵向分析A1-14-4'!E15+'已审利润纵向分析A1-14-4'!E18+'已审利润纵向分析A1-14-4'!E17 -> 0 | H14: =IF(G14=0,0,F14/G14) -> 0 | I14: =IF(E14=0,0,(H14-E14)/E14) -> 0 | J14: =IF(ABS(I14)<20%,"",IF(ABS(I14)<50%,"关注","显著"))
A15: 9、研究开发费用比例 | B15: 研究开发费用/主营业务收入 | E15: =IF(D15=0,0,C15/D15) -> 0 | F15: ='已审利润纵向分析A1-14-4'!E17 -> 0 | G15: ='已审利润纵向分析A1-14-4'!E8 -> 0 | H15: =IF(G15=0,0,F15/G15) -> 0
A16: 二、短期偿债能力分析
A17: 1、流动比率 | B17: 流动资产/流动负债 | E17: =IF(D17=0,0,C17/D17) -> 0 | F17: ='已审资产负债纵向分析A1-14-2'!E21 -> 0 | G17: ='已审资产负债纵向分析A1-14-2'!N21 -> 0 | H17: =IF(G17=0,0,F17/G17) -> 0 | I17: =IF(E17=0,0,(H17-E17)/E17) -> 0 | J17: =IF(AND(H17=0,I17=0),"",IF(AND(ABS(I17)<20%,H17>=1.6),"",IF(OR(ABS(I17)>=50%,H17<=1),"显著","关注")))
A18: 2、速动比率 | B18: 速动资产/流动负债 | E18: =IF(D18=0,0,C18/D18) -> 0 | F18: ='已审资产负债纵向分析A1-14-2'!E21-'已审资产负债纵向分析A1-14-2'!E14 -> 0 | G18: ='已审资产负债纵向分析A1-14-2'!N21 -> 0 | H18: =IF(G18=0,0,F18/G18) -> 0 | I18: =IF(E18=0,0,(H18-E18)/E18) -> 0 | J18: =IF(AND(H18=0,I18=0),"",IF(AND(ABS(I18)<20%,H18>=0.8),"",IF(OR(ABS(I18)>=50%,H18<=0.5),"显著","关注")))
A19: 3、现金比率 | B19: （货币资金+交易性金融资产）/流动负债 | E19: =IF(D19=0,0,C19/D19) -> 0 | F19: ='已审资产负债纵向分析A1-14-2'!E8+'已审资产负债纵向分析A1-14-2'!E9 -> 0 | G19: ='已审资产负债纵向分析A1-14-2'!N21 -> 0 | H19: =IF(G19=0,0,F19/G19) -> 0 | I19: =IF(E19=0,0,(H19-E19)/E19) -> 0 | J19: =IF(AND(H19=0,I19=0),"",IF(AND(ABS(I19)<20%,H19>=0.24),"",IF(OR(ABS(I19)>=50%,H19<=0.15),"显著","关注")))
A20: 三、长期偿债能力分析 | J20: =IF(ABS(I20)<20%,"",IF(ABS(I20)<50%,"关注","异常"))
A21: 1、资产负债比率 | B21: 负债总额/资产总额 | E21: =IF(D21=0,0,C21/D21) -> 0 | F21: ='已审资产负债纵向分析A1-14-2'!N34 -> 0 | G21: ='已审资产负债纵向分析A1-14-2'!E49 -> 0 | H21: =IF(G21=0,0,F21/G21) -> 0 | I21: =IF(E21=0,0,(H21-E21)/E21) -> 0 | J21: =IF(AND(ABS(I21)<20%,H21<=60%),"",IF(OR(ABS(I21)>=50%,H21>=90%),"显著","关注"))
A22: 2、产权比率 | B22: 负债总额/所有者权益总额 | E22: =IF(D22=0,0,C22/D22) -> 0 | F22: ='已审资产负债纵向分析A1-14-2'!N34 -> 0 | G22: ='已审资产负债纵向分析A1-14-2'!N48 -> 0 | H22: =IF(G22=0,0,F22/G22) -> 0 | I22: =IF(E22=0,0,(H22-E22)/E22) -> 0 | J22: =IF(AND(ABS(I22)<20%,H22<=100%),"",IF(OR(ABS(I22)>=50%,H22>=150%),"显著","关注"))
A23: 3、有形净值债务比率 | B23: 负债总额/（所有者权益-无形资产-开发支出-商誉-递延资产） | E23: =IF(D23=0,0,C23/D23) -> 0 | F23: ='已审资产负债纵向分析A1-14-2'!N34 -> 0 | G23: ='已审资产负债纵向分析A1-14-2'!N48-'已审资产负债纵向分析A1-14-2'!E33-'已审资产负债纵向分析A1-14-2'!E34-'已审资产负债纵向分析A1-14-2'!E35-'已审资产负债纵向分析A1-14-2'!E37 -> 0 | H23: =IF(G23=0,0,F23/G23) -> 0 | I23: =IF(E23=0,0,(H23-E23)/E23) -> 0 | J23: =IF(AND(ABS(I23)<20%,H23<=150%),"",IF(OR(ABS(I23)>=50%,H23>=200%),"显著","关注"))
A24: 4、利息保障倍数 | B24: （税前利润+利息支出净额）/利息支出净额 | E24: =IF(D24=0,0,C24/D24) -> 0 | F24: ='已审利润纵向分析A1-14-4'!E30+'已审利润纵向分析A1-14-4'!E19-'已审利润纵向分析A1-14-4'!E20 -> 0 | G24: ='已审利润纵向分析A1-14-4'!E19-'已审利润纵向分析A1-14-4'!E20 -> 0 | H24: =IF(G24=0,0,F24/G24) -> 0 | I24: =IF(E24=0,0,(H24-E24)/E24) -> 0 | J24: =IF(AND(H24=0,I24=0),"",IF(AND(ABS(I24)<20%,H24>=100%),"",IF(OR(ABS(I24)>=50%,H24<=50%),"显著","关注")))
A25: 5、营运资金长期负债比率 | B25: （流动资产-流动负债）/非流动负债 | E25: =IF(D25=0,0,C25/D25) -> 0 | F25: ='已审资产负债纵向分析A1-14-2'!E21-'已审资产负债纵向分析A1-14-2'!N21 -> 0 | G25: ='已审资产负债纵向分析A1-14-2'!N33 -> 0 | H25: =IF(G25=0,0,F25/G25) -> 0 | I25: =IF(E25=0,0,(H25-E25)/E25) -> 0 | J25: =IF(AND(H25=0,I25=0),"",IF(AND(ABS(I25)<20%,H25>=100%),"",IF(OR(ABS(I25)>=50%,H25<=50%),"显著","关注")))
A26: 6、长期负债比率 | B26: 非流动负债/负债总额 | E26: =IF(D26=0,0,C26/D26) -> 0 | F26: ='已审资产负债纵向分析A1-14-2'!N33 -> 0 | G26: ='已审资产负债纵向分析A1-14-2'!N34 -> 0 | H26: =IF(G26=0,0,F26/G26) -> 0 | I26: =IF(E26=0,0,(H26-E26)/E26) -> 0 | J26: =IF(ABS(I26)<20%,"",IF(ABS(I26)<50%,"关注","显著"))
A27: 7、融资结构弹性比率 | B27: 弹性融资（流动负债融资+未分配利润）/融资总量 | E27: =IF(D27=0,0,C27/D27) -> 0 | F27: ='已审资产负债纵向分析A1-14-2'!N21+'已审利润纵向分析A1-14-4'!E73 -> 0 | G27: ='已审资产负债纵向分析A1-14-2'!N34+'已审资产负债纵向分析A1-14-2'!N46 -> 0 | H27: =IF(G27=0,0,F27/G27) -> 0 | I27: =IF(E27=0,0,(H27-E27)/E27) -> 0 | J27: =IF(AND(H27=0,I27=0),"",IF(AND(ABS(I27)<20%,H27>=50%),"",IF(OR(ABS(I27)>=50%,H27<=30%),"显著","关注")))
A28: 四、资产管理效率分析
A29: 1、总资产周转率 | B29: 营业收入净额(annualized)/平均资产总额 | E29: =IF(D29=0,0,C29/D29) -> 0 | F29: ='已审利润纵向分析A1-14-4'!E7/12*12 -> 0 | G29: =('已审资产负债纵向分析A1-14-2'!C49+'已审资产负债纵向分析A1-14-2'!E49)/2 -> 0 | H29: =IF(G29=0,0,F29/G29) -> 0 | I29: =IF(E29=0,0,(H29-E29)/E29) -> 0 | J29: =IF(ABS(I29)<20%,"",IF(ABS(I29)<50%,"关注","显著"))
A30: 2、固定资产周转率 | B30: 营业收入净额(annualized)/固定资产平均净值 | E30: =IF(D30=0,0,C30/D30) -> 0 | F30: ='已审利润纵向分析A1-14-4'!E7/12*12 -> 0 | G30: =('已审资产负债纵向分析A1-14-2'!C29+'已审资产负债纵向分析A1-14-2'!E29)/2 -> 0 | H30: =IF(G30=0,0,F30/G30) -> 0 | I30: =IF(E30=0,0,(H30-E30)/E30) -> 0 | J30: =IF(ABS(I30)<20%,"",IF(ABS(I30)<50%,"关注","显著"))
A31: 3、流动资产周转率 | B31: 营业收入净额(annualized)/流动资产平均占用额 | E31: =IF(D31=0,0,C31/D31) -> 0 | F31: ='已审利润纵向分析A1-14-4'!E7/12*12 -> 0 | G31: =('已审资产负债纵向分析A1-14-2'!C21+'已审资产负债纵向分析A1-14-2'!E21)/2 -> 0 | H31: =IF(G31=0,0,F31/G31) -> 0 | I31: =IF(E31=0,0,(H31-E31)/E31) -> 0 | J31: =IF(ABS(I31)<20%,"",IF(ABS(I31)<50%,"关注","显著"))
A32: 4、应收账款周转率 | B32: 赊销收入净额(annualized)/应收账款平均余额 | E32: =IF(D32=0,0,C32/D32) -> 0 | F32: ='已审利润纵向分析A1-14-4'!E7/12*12 -> 0 | G32: =('已审资产负债纵向分析A1-14-2'!C11+'已审资产负债纵向分析A1-14-2'!E11)/2 -> 0 | H32: =IF(G32=0,0,F32/G32) -> 0 | I32: =IF(E32=0,0,(H32-E32)/E32) -> 0 | J32: =IF(ABS(I32)<20%,"",IF(ABS(I32)<50%,"关注","显著"))
A33: 5、存货周转率 | B33: 营业成本(annualized)/存货平均余额 | E33: =IF(D33=0,0,C33/D33) -> 0 | F33: ='已审利润纵向分析A1-14-4'!E10/12*12 -> 0 | G33: =('已审资产负债纵向分析A1-14-2'!C14+'已审资产负债纵向分析A1-14-2'!E14)/2 -> 0 | H33: =IF(G33=0,0,F33/G33) -> 0 | I33: =IF(E33=0,0,(H33-E33)/E33) -> 0 | J33: =IF(ABS(I33)<20%,"",IF(ABS(I33)<50%,"关注","显著"))
A34: 6、营业周期 | B34: 应收账款周转天数+存货周转天数 | E34: =SUM(C34:D34) -> 0 | F34: =IF(H32<>0,365/H32,) -> 0 | G34: =IF(H33<>0,365/H33,) -> 0 | H34: =SUM(F34:G34) -> 0 | I34: =IF(E34=0,0,(H34-E34)/E34) -> 0 | J34: =IF(ABS(I34)<20%,"",IF(ABS(I34)<50%,"关注","显著"))
A35: 五、资产管理效果分析
A36: 1、资本保值增值率 | B36: 期末所有者权益总额/期初所有者权益总额 | E36: =IF(D36=0,0,C36/D36) -> 0 | F36: ='已审资产负债纵向分析A1-14-2'!N48 -> 0 | G36: ='已审资产负债纵向分析A1-14-2'!L48 -> 0 | H36: =IF(G36=0,0,F36/G36) -> 0 | I36: =IF(E36=0,0,(H36-E36)/E36) -> 0 | J36: =IF(ABS(I36)<20%,"",IF(ABS(I36)<50%,"关注","显著"))
A37: 2、社会贡献率 | B37: 企业社会贡献总额(annualized)/平均资产总额 | E37: =IF(D37=0,0,C37/D37) -> 0 | G37: =('已审资产负债纵向分析A1-14-2'!C49+'已审资产负债纵向分析A1-14-2'!E49)/2 -> 0 | H37: =IF(G37=0,0,F37/G37) -> 0 | I37: =IF(E37=0,0,(H37-E37)/E37) -> 0 | J37: =IF(ABS(I37)<20%,"",IF(ABS(I37)<50%,"关注","显著"))
A38: 3、社会积累率 | B38: 上交国家财政总额/企业社会贡献总额 | E38: =IF(D38=0,0,C38/D38) -> 0 | G38: =F37 -> 0 | H38: =IF(G38=0,0,F38/G38) -> 0 | I38: =IF(E38=0,0,(H38-E38)/E38) -> 0 | J38: =IF(ABS(I38)<20%,"",IF(ABS(I38)<50%,"关注","显著"))
