Workbook
Name _DAT1: #REF!
Name _DAT1: #REF!
Name _DAT1: #REF!
Name _DAT1: #REF!
Name _DAT10: #REF!
Name _DAT10: #REF!
Name _DAT10: #REF!
Name _DAT10: #REF!
Name _DAT11: #REF!
Name _DAT11: #REF!
Name _DAT11: #REF!
Name _DAT11: #REF!
Name _DAT2: #REF!
Name _DAT2: #REF!
Name _DAT3: #REF!
Name _DAT3: #REF!
Name _DAT4: #REF!
Name _DAT4: #REF!
Name _DAT5: #REF!
Name _DAT5: #REF!
Name _DAT6: #REF!
Name _DAT6: #REF!
Name _DAT7: #REF!
Name _DAT7: #REF!
Name _DAT8: #REF!
Name _DAT8: #REF!
Name _DAT9: #REF!
Name _DAT9: #REF!
Name TEST1: #REF!
Name TEST1: #REF!
Name TESTHKEY: #REF!
Name TESTHKEY: #REF!
Name TESTKEYS: #REF!
Name TESTKEYS: #REF!
Name TESTVKEY: #REF!
Name TESTVKEY: #REF!
Name TextRefCopy1: #REF!
Name TextRefCopy1: #REF!
Name UFPrn20020120153922: #REF!
Name UFPrn20020120153922: #REF!
Name UFPrn20051027160140: #REF!
Name UFPrn20051027160140: #REF!
Name UFPrn20051027172739: #REF!
Name UFPrn20051027172739: #REF!
Name UFPrn20051103141418: #REF!
Name UFPrn20051103141418: #REF!
Name UFPrn20060721155740: #REF!
Name UFPrn20060721155740: #REF!
Name UFPrn20071205095615: #REF!
Name UFPrn20071205095615: #REF!
Name UFPrn20071205103259: #REF!
Name UFPrn20071205103259: #REF!
Name UFPrn20071205103331: #REF!
Name UFPrn20071205103331: #REF!
Name UFPrn20071205103404: #REF!
Name UFPrn20071205103404: #REF!
Name UFPrn20071205103449: #REF!
Name UFPrn20071205103449: #REF!
Name UFPrn20071205103544: #REF!
Name UFPrn20071205103544: #REF!

Sheet 表头
A1: 底稿开列时，可先在以下单元格填写有关内容，以便其他底稿引用有关数据：
A2: 客户名称：
A3: 会计期间：201X年度 | D3: 序号 | E3: 索引号 | F3: 内容
A4: 编制人： | D4: 1 | E4: H3 | F4: 审定表
A5: 日期： | D5: =D4+1 -> 2 | E5: H3-1 | F5: 附注披露信息（上市公司）
D6: =D5+1 -> 3 | E6: H3-1 | F6: 附注披露信息（国企）
A7: 关于工作底稿索引号的编制方法的说明 | D7: =D6+1 -> 4 | E7: H3-2 | F7: 明细分析表
A8: 1、 工作底稿的分类 | D8: =D7+1 -> 5 | E8: H3-3 | F8: 收益率分析表
D9: =D8+1 -> 6 | E9: H3-5 | F9: 检查表
A10: 作为具体审计程序的支持性工作底稿，共有三类，分别为审定表，明细表，检查表。
A11: 2、 工作底稿与审计程序的对应与索引
A12: 为提高工作底稿编制的针对性，各项目负责人提供的所有支持性工作底稿，均应当
A13: 按自然顺序依次编制索引号，并通过唯一的索引号将审计程序表中的特定程序与相关
A14: 支持性工作底稿进行一一对应。
A15: 3、 工作底稿索引号的编码规则（以销售循环为例，假设D为项目名称代码）
A16: 索引号的说明：实质性程序索引号从“D”到“N”,循环内账户以顺序号排列，如：销售循环的程序表即为D，D1为应收票据审定表，D1-1为附注披露信息，D1-2为明细表........

Sheet 审定表A5-4
A1: 致同会计师事务所
A2: 持续经营净利润和终止经营净利润审定表
A3: =表头!A2 -> 客户名称： | C3: =表头!A4 -> 编制人： | H3: =表头!A5 -> 日期： | N3: 索引：A5-4
A4: =表头!A3 -> 会计期间：201X年度 | C4: 复核人： | H4: 日期： | N4: 页次：
A5: 项目 | B5: 本期数 | F5: 上期数 | J5: 本期未审数与上期 未审数的比较 | L5: 本期审定数与上期 审定数的比较 | N5: 原因分析 | O5: 索引
B6: 本期未审数 | C6: 账项调整 | D6: 重分类调整 | E6: 本期审定数 | F6: 上期未审数 | G6: 账项调整 | H6: 重分类调整 | I6: 上期审定数 | J6: 变动额 | K6: 变动率 | L6: 变动额 | M6: 变动率
A7: 本年净利润(净亏损以“-”号填列） | B7: ='明细分析表A5-4-2'!C105 -> 0 | C7: ='明细分析表A5-4-2'!D105 -> —— | D7: ='明细分析表A5-4-2'!E105 -> —— | E7: ='明细分析表A5-4-2'!F105 -> 0 | F7: ='明细分析表A5-4-2'!J105 -> 0 | G7: ='明细分析表A5-4-2'!K105 -> —— | H7: ='明细分析表A5-4-2'!L105 -> —— | I7: ='明细分析表A5-4-2'!M105 -> 0 | J7: =B7-F7 -> 0 | K7: =ROUND(IF(AND(B7=0,F7=0),0,IF(AND(B7=0,F7>0),1,J7/F7)),4) -> 0 | L7: =E7-I7 -> 0 | M7: =ROUND(IF(AND(E7=0,I7=0),0,IF(AND(E7=0,I7>0),1,L7/I7)),4) -> 0
A8: （一）按经营持续性分类： | B8: ='明细分析表A5-4-2'!C106 -> —— | C8: ='明细分析表A5-4-2'!D106 -> —— | D8: ='明细分析表A5-4-2'!E106 -> —— | E8: ='明细分析表A5-4-2'!F106 -> —— | F8: ='明细分析表A5-4-2'!J106 -> —— | G8: ='明细分析表A5-4-2'!K106 -> —— | H8: ='明细分析表A5-4-2'!L106 -> —— | I8: ='明细分析表A5-4-2'!M106 -> —— | J8: ='明细分析表A5-4-2'!K106 -> —— | K8: ='明细分析表A5-4-2'!L106 -> —— | L8: ='明细分析表A5-4-2'!M106 -> —— | M8: ='明细分析表A5-4-2'!N106 -> ——
A9: 其中：持续经营净利润（净亏损以“-”号填列） | B9: ='明细分析表A5-4-2'!C107 -> 0 | C9: ='明细分析表A5-4-2'!D107 -> —— | D9: ='明细分析表A5-4-2'!E107 -> —— | E9: ='明细分析表A5-4-2'!F107 -> 0 | F9: ='明细分析表A5-4-2'!J107 -> 0 | G9: ='明细分析表A5-4-2'!K107 -> —— | H9: ='明细分析表A5-4-2'!L107 -> —— | I9: ='明细分析表A5-4-2'!M107 -> 0 | J9: =B9-F9 -> 0 | K9: =ROUND(IF(AND(B9=0,F9=0),0,IF(AND(B9=0,F9>0),1,J9/F9)),4) -> 0 | L9: =E9-I9 -> 0 | M9: =ROUND(IF(AND(E9=0,I9=0),0,IF(AND(E9=0,I9>0),1,L9/I9)),4) -> 0
A10: 终止经营净利润（净亏损以“-”号填列） | B10: ='明细分析表A5-4-2'!C108 -> 0 | C10: ='明细分析表A5-4-2'!D108 -> 0 | D10: ='明细分析表A5-4-2'!E108 -> 0 | E10: ='明细分析表A5-4-2'!F108 -> 0 | F10: ='明细分析表A5-4-2'!J108 -> 0 | G10: ='明细分析表A5-4-2'!K108 -> 0 | H10: ='明细分析表A5-4-2'!L108 -> 0 | I10: ='明细分析表A5-4-2'!M108 -> 0 | J10: =B10-F10 -> 0 | K10: =ROUND(IF(AND(B10=0,F10=0),0,IF(AND(B10=0,F10>0),1,J10/F10)),4) -> 0 | L10: =E10-I10 -> 0 | M10: =ROUND(IF(AND(E10=0,I10=0),0,IF(AND(E10=0,I10>0),1,L10/I10)),4) -> 0
A11: 终止经营收入 （A） | B11: ='明细分析表A5-4-2'!C20 -> 0 | C11: ='明细分析表A5-4-2'!D20 -> 0 | D11: ='明细分析表A5-4-2'!E20 -> 0 | E11: ='明细分析表A5-4-2'!F20 -> 0 | F11: ='明细分析表A5-4-2'!J20 -> 0 | G11: ='明细分析表A5-4-2'!K20 -> 0 | H11: ='明细分析表A5-4-2'!L20 -> 0 | I11: ='明细分析表A5-4-2'!M20 -> 0 | J11: =B11-F11 -> 0 | K11: =ROUND(IF(AND(B11=0,F11=0),0,IF(AND(B11=0,F11>0),1,J11/F11)),4) -> 0 | L11: =E11-I11 -> 0 | M11: =ROUND(IF(AND(E11=0,I11=0),0,IF(AND(E11=0,I11>0),1,L11/I11)),4) -> 0
A12: 减：终止经营费用（B） | B12: ='明细分析表A5-4-2'!C26 -> 0 | C12: ='明细分析表A5-4-2'!D26 -> 0 | D12: ='明细分析表A5-4-2'!E26 -> 0 | E12: ='明细分析表A5-4-2'!F26 -> 0 | F12: ='明细分析表A5-4-2'!J26 -> 0 | G12: ='明细分析表A5-4-2'!K26 -> 0 | H12: ='明细分析表A5-4-2'!L26 -> 0 | I12: ='明细分析表A5-4-2'!M26 -> 0 | J12: =B12-F12 -> 0 | K12: =ROUND(IF(AND(B12=0,F12=0),0,IF(AND(B12=0,F12>0),1,J12/F12)),4) -> 0 | L12: =E12-I12 -> 0 | M12: =ROUND(IF(AND(E12=0,I12=0),0,IF(AND(E12=0,I12>0),1,L12/I12)),4) -> 0
A13: 终止经营利润总额（C） | B13: ='明细分析表A5-4-2'!C32 -> 0 | C13: ='明细分析表A5-4-2'!D32 -> 0 | D13: ='明细分析表A5-4-2'!E32 -> 0 | E13: ='明细分析表A5-4-2'!F32 -> 0 | F13: ='明细分析表A5-4-2'!J32 -> 0 | G13: ='明细分析表A5-4-2'!K32 -> 0 | H13: ='明细分析表A5-4-2'!L32 -> 0 | I13: ='明细分析表A5-4-2'!M32 -> 0 | J13: =B13-F13 -> 0 | K13: =ROUND(IF(AND(B13=0,F13=0),0,IF(AND(B13=0,F13>0),1,J13/F13)),4) -> 0 | L13: =E13-I13 -> 0 | M13: =ROUND(IF(AND(E13=0,I13=0),0,IF(AND(E13=0,I13>0),1,L13/I13)),4) -> 0
A14: 减：终止经营所得税费用（D） | B14: ='明细分析表A5-4-2'!C38 -> 0 | C14: ='明细分析表A5-4-2'!D38 -> 0 | D14: ='明细分析表A5-4-2'!E38 -> 0 | E14: ='明细分析表A5-4-2'!F38 -> 0 | F14: ='明细分析表A5-4-2'!J38 -> 0 | G14: ='明细分析表A5-4-2'!K38 -> 0 | H14: ='明细分析表A5-4-2'!L38 -> 0 | I14: ='明细分析表A5-4-2'!M38 -> 0 | J14: =B14-F14 -> 0 | K14: =ROUND(IF(AND(B14=0,F14=0),0,IF(AND(B14=0,F14>0),1,J14/F14)),4) -> 0 | L14: =E14-I14 -> 0 | M14: =ROUND(IF(AND(E14=0,I14=0),0,IF(AND(E14=0,I14>0),1,L14/I14)),4) -> 0
A15: 经营活动净利润（E=C-D） | B15: ='明细分析表A5-4-2'!C44 -> 0 | C15: ='明细分析表A5-4-2'!D44 -> 0 | D15: ='明细分析表A5-4-2'!E44 -> 0 | E15: ='明细分析表A5-4-2'!F44 -> 0 | F15: ='明细分析表A5-4-2'!J44 -> 0 | G15: ='明细分析表A5-4-2'!K44 -> 0 | H15: ='明细分析表A5-4-2'!L44 -> 0 | I15: ='明细分析表A5-4-2'!M44 -> 0 | J15: =B15-F15 -> 0 | K15: =ROUND(IF(AND(B15=0,F15=0),0,IF(AND(B15=0,F15>0),1,J15/F15)),4) -> 0 | L15: =E15-I15 -> 0 | M15: =ROUND(IF(AND(E15=0,I15=0),0,IF(AND(E15=0,I15>0),1,L15/I15)),4) -> 0
A16: 资产减值损失/（转回）（F） | B16: ='明细分析表A5-4-2'!C50 -> 0 | C16: ='明细分析表A5-4-2'!D50 -> 0 | D16: ='明细分析表A5-4-2'!E50 -> 0 | E16: ='明细分析表A5-4-2'!F50 -> 0 | F16: ='明细分析表A5-4-2'!J50 -> 0 | G16: ='明细分析表A5-4-2'!K50 -> 0 | H16: ='明细分析表A5-4-2'!L50 -> 0 | I16: ='明细分析表A5-4-2'!M50 -> 0 | J16: =B16-F16 -> 0 | K16: =ROUND(IF(AND(B16=0,F16=0),0,IF(AND(B16=0,F16>0),1,J16/F16)),4) -> 0 | L16: =E16-I16 -> 0 | M16: =ROUND(IF(AND(E16=0,I16=0),0,IF(AND(E16=0,I16>0),1,L16/I16)),4) -> 0
A17: 处置收益总额（G） | B17: ='明细分析表A5-4-2'!C56 -> 0 | C17: ='明细分析表A5-4-2'!D56 -> 0 | D17: ='明细分析表A5-4-2'!E56 -> 0 | E17: ='明细分析表A5-4-2'!F56 -> 0 | F17: ='明细分析表A5-4-2'!J56 -> 0 | G17: ='明细分析表A5-4-2'!K56 -> 0 | H17: ='明细分析表A5-4-2'!L56 -> 0 | I17: ='明细分析表A5-4-2'!M56 -> 0 | J17: =B17-F17 -> 0 | K17: =ROUND(IF(AND(B17=0,F17=0),0,IF(AND(B17=0,F17>0),1,J17/F17)),4) -> 0 | L17: =E17-I17 -> 0 | M17: =ROUND(IF(AND(E17=0,I17=0),0,IF(AND(E17=0,I17>0),1,L17/I17)),4) -> 0
A18: 处置相关所得税费用（H） | B18: ='明细分析表A5-4-2'!C62 -> 0 | C18: ='明细分析表A5-4-2'!D62 -> 0 | D18: ='明细分析表A5-4-2'!E62 -> 0 | E18: ='明细分析表A5-4-2'!F62 -> 0 | F18: ='明细分析表A5-4-2'!J62 -> 0 | G18: ='明细分析表A5-4-2'!K62 -> 0 | H18: ='明细分析表A5-4-2'!L62 -> 0 | I18: ='明细分析表A5-4-2'!M62 -> 0 | J18: =B18-F18 -> 0 | K18: =ROUND(IF(AND(B18=0,F18=0),0,IF(AND(B18=0,F18>0),1,J18/F18)),4) -> 0 | L18: =E18-I18 -> 0 | M18: =ROUND(IF(AND(E18=0,I18=0),0,IF(AND(E18=0,I18>0),1,L18/I18)),4) -> 0
A19: 处置净利润（I=G-H） | B19: ='明细分析表A5-4-2'!C68 -> 0 | C19: ='明细分析表A5-4-2'!D68 -> 0 | D19: ='明细分析表A5-4-2'!E68 -> 0 | E19: ='明细分析表A5-4-2'!F68 -> 0 | F19: ='明细分析表A5-4-2'!J68 -> 0 | G19: ='明细分析表A5-4-2'!K68 -> 0 | H19: ='明细分析表A5-4-2'!L68 -> 0 | I19: ='明细分析表A5-4-2'!M68 -> 0 | J19: =B19-F19 -> 0 | K19: =ROUND(IF(AND(B19=0,F19=0),0,IF(AND(B19=0,F19>0),1,J19/F19)),4) -> 0 | L19: =E19-I19 -> 0 | M19: =ROUND(IF(AND(E19=0,I19=0),0,IF(AND(E19=0,I19>0),1,L19/I19)),4) -> 0
A20: 终止经营净利润（J=E+F+I） | B20: ='明细分析表A5-4-2'!C74 -> 0 | C20: ='明细分析表A5-4-2'!D74 -> 0 | D20: ='明细分析表A5-4-2'!E74 -> 0 | E20: ='明细分析表A5-4-2'!F74 -> 0 | F20: ='明细分析表A5-4-2'!J74 -> 0 | G20: ='明细分析表A5-4-2'!K74 -> 0 | H20: ='明细分析表A5-4-2'!L74 -> 0 | I20: ='明细分析表A5-4-2'!M74 -> 0 | J20: =B20-F20 -> 0 | K20: =ROUND(IF(AND(B20=0,F20=0),0,IF(AND(B20=0,F20>0),1,J20/F20)),4) -> 0 | L20: =E20-I20 -> 0 | M20: =ROUND(IF(AND(E20=0,I20=0),0,IF(AND(E20=0,I20>0),1,L20/I20)),4) -> 0
A21: 其中：归属于母公司股东的终止经营利润 | B21: ='明细分析表A5-4-2'!C80 -> 0 | C21: ='明细分析表A5-4-2'!D80 -> 0 | D21: ='明细分析表A5-4-2'!E80 -> 0 | E21: ='明细分析表A5-4-2'!F80 -> 0 | F21: ='明细分析表A5-4-2'!J80 -> 0 | G21: ='明细分析表A5-4-2'!K80 -> 0 | H21: ='明细分析表A5-4-2'!L80 -> 0 | I21: ='明细分析表A5-4-2'!M80 -> 0 | J21: =B21-F21 -> 0 | K21: =ROUND(IF(AND(B21=0,F21=0),0,IF(AND(B21=0,F21>0),1,J21/F21)),4) -> 0 | L21: =E21-I21 -> 0 | M21: =ROUND(IF(AND(E21=0,I21=0),0,IF(AND(E21=0,I21>0),1,L21/I21)),4) -> 0
A22: 归属于少数股东的终止经营利润 | B22: ='明细分析表A5-4-2'!C86 -> 0 | C22: ='明细分析表A5-4-2'!D86 -> 0 | D22: ='明细分析表A5-4-2'!E86 -> 0 | E22: ='明细分析表A5-4-2'!F86 -> 0 | F22: ='明细分析表A5-4-2'!J86 -> 0 | G22: ='明细分析表A5-4-2'!K86 -> 0 | H22: ='明细分析表A5-4-2'!L86 -> 0 | I22: ='明细分析表A5-4-2'!M86 -> 0 | J22: =B22-F22 -> 0 | K22: =ROUND(IF(AND(B22=0,F22=0),0,IF(AND(B22=0,F22>0),1,J22/F22)),4) -> 0 | L22: =E22-I22 -> 0 | M22: =ROUND(IF(AND(E22=0,I22=0),0,IF(AND(E22=0,I22>0),1,L22/I22)),4) -> 0
A23: 经营活动现金流量净额 | B23: ='明细分析表A5-4-2'!C92 -> 0 | C23: ='明细分析表A5-4-2'!D92 -> 0 | D23: ='明细分析表A5-4-2'!E92 -> 0 | E23: ='明细分析表A5-4-2'!F92 -> 0 | F23: ='明细分析表A5-4-2'!J92 -> 0 | G23: ='明细分析表A5-4-2'!K92 -> 0 | H23: ='明细分析表A5-4-2'!L92 -> 0 | I23: ='明细分析表A5-4-2'!M92 -> 0 | J23: =B23-F23 -> 0 | K23: =ROUND(IF(AND(B23=0,F23=0),0,IF(AND(B23=0,F23>0),1,J23/F23)),4) -> 0 | L23: =E23-I23 -> 0 | M23: =ROUND(IF(AND(E23=0,I23=0),0,IF(AND(E23=0,I23>0),1,L23/I23)),4) -> 0
A24: 投资活动现金流量净额 | B24: ='明细分析表A5-4-2'!C98 -> 0 | C24: ='明细分析表A5-4-2'!D98 -> 0 | D24: ='明细分析表A5-4-2'!E98 -> 0 | E24: ='明细分析表A5-4-2'!F98 -> 0 | F24: ='明细分析表A5-4-2'!J98 -> 0 | G24: ='明细分析表A5-4-2'!K98 -> 0 | H24: ='明细分析表A5-4-2'!L98 -> 0 | I24: ='明细分析表A5-4-2'!M98 -> 0 | J24: =B24-F24 -> 0 | K24: =ROUND(IF(AND(B24=0,F24=0),0,IF(AND(B24=0,F24>0),1,J24/F24)),4) -> 0 | L24: =E24-I24 -> 0 | M24: =ROUND(IF(AND(E24=0,I24=0),0,IF(AND(E24=0,I24>0),1,L24/I24)),4) -> 0
A25: 筹资活动现金流量净额 | B25: ='明细分析表A5-4-2'!C104 -> 0 | C25: ='明细分析表A5-4-2'!D104 -> 0 | D25: ='明细分析表A5-4-2'!E104 -> 0 | E25: ='明细分析表A5-4-2'!F104 -> 0 | F25: ='明细分析表A5-4-2'!J104 -> 0 | G25: ='明细分析表A5-4-2'!K104 -> 0 | H25: ='明细分析表A5-4-2'!L104 -> 0 | I25: ='明细分析表A5-4-2'!M104 -> 0 | J25: =B25-F25 -> 0 | K25: =ROUND(IF(AND(B25=0,F25=0),0,IF(AND(B25=0,F25>0),1,J25/F25)),4) -> 0 | L25: =E25-I25 -> 0 | M25: =ROUND(IF(AND(E25=0,I25=0),0,IF(AND(E25=0,I25>0),1,L25/I25)),4) -> 0
A26: 1、审计说明
A27: （1）大幅变动主要原因（比例超过30%的）：
A30: （2）情况说明。
A33: 2、审计结论

Sheet 附注披露信息（上市公司）A5-4-1
A1: 致同会计师事务所
A2: 附注披露信息（上市公司）
A3: =表头!A2 -> 客户名称： | B3: =表头!A4 -> 编制人： | C3: =表头!A5 -> 日期： | D3: 索引：A5-4-1
A4: =表头!A3 -> 会计期间：201X年度 | B4: 复核人： | C4: 日期： | D4: 页次：
A5: 附注披露信息
A6: 终止经营
A7: 项目 | B7: 本期发生额 | C7: 上期发生额
A8: 终止经营收入 （A） | B8: ='审定表A5-4'!E11 -> 0 | C8: ='审定表A5-4'!I11 -> 0
A9: 减：终止经营费用（B） | B9: ='审定表A5-4'!E12 -> 0 | C9: ='审定表A5-4'!I12 -> 0
A10: 终止经营利润总额（C） | B10: ='审定表A5-4'!E13 -> 0 | C10: ='审定表A5-4'!I13 -> 0
A11: 减：终止经营所得税费用（D） | B11: ='审定表A5-4'!E14 -> 0 | C11: ='审定表A5-4'!I14 -> 0
A12: 经营活动净利润（E=C-D） | B12: =B10-B11 -> 0 | C12: =C10-C11 -> 0
A13: 资产减值损失/（转回）（F） | B13: ='审定表A5-4'!E16 -> 0 | C13: ='审定表A5-4'!I16 -> 0
A14: 处置收益总额（G） | B14: ='审定表A5-4'!E17 -> 0 | C14: ='审定表A5-4'!I17 -> 0
A15: 处置相关所得税费用（H） | B15: ='审定表A5-4'!E18 -> 0 | C15: ='审定表A5-4'!I18 -> 0
A16: 处置净利润（I=G-H） | B16: =B14-B15 -> 0 | C16: =C14-C15 -> 0
A17: 终止经营净利润（J=E+F+I） | B17: =B12+B13+B16 -> 0 | C17: =C12+C13+C16 -> 0
A18: 其中：归属于母公司股东的终止经营利润 | B18: ='审定表A5-4'!E21 -> 0 | C18: ='审定表A5-4'!I21 -> 0
A19: 归属于少数股东的终止经营利润 | B19: ='审定表A5-4'!E22 -> 0 | C19: ='审定表A5-4'!I22 -> 0
A20: 经营活动现金流量净额 | B20: ='审定表A5-4'!E23 -> 0 | C20: ='审定表A5-4'!I23 -> 0
A21: 投资活动现金流量净额 | B21: ='审定表A5-4'!E24 -> 0 | C21: ='审定表A5-4'!I24 -> 0
A22: 筹资活动现金流量净额 | B22: ='审定表A5-4'!E25 -> 0 | C22: ='审定表A5-4'!I25 -> 0
A23: 说明：
A24: 1、本期实现的持续经营利润为XX，其中归属于母公司股东的持续经营利润为XX。
A25: 2、（企业终止经营的原因、内容、性质等。）
A26: （如果因出售对子公司的投资等原因导致丧失对子公司控制权，且该子公司符合终止经营定义的，应在合并利润表中列报相关终止经营损益，并需披露上述信息。）
A27: （如果对终止经营处置损益进行调整，需披露调整的性质和金额。例如：
A28: 本集团就[终止经营项目1]的最终处置条款与买方达成一致，[调整交易价格人民币XX元][向买方支付补偿金人民币XX元]。]）
A29: （不符合终止经营定义的持有待售的非流动资产或处置组，其减值损失和转回金额及处置损益应当作为持续经营损益列报；非流动资产或处置组不再继续划分为持有待售类别或非流动资产从持有待售的处置组中移除的，非流动资产或处置组的账面价值调整金额应当在当期利润表中作为持续经营损益列报；终止经营的减值损失和转回金额等经营损益、处置损益及其调整金额应当作为终止经营损益列报。）
A30: （3、对于当期列报的终止经营，企业应当在当期财务报表中，将原来作为持续经营损益列报的信息重新作为可比会计期间的终止经营损益列报，并披露以下可比会计期间的信息：
A31: A、终止经营的收入、费用、利润总额、所得税费用（收益）和净利润；
A32: B、终止经营的资产或处置组确认的减值损失及其转回金额；
A33: C、终止经营的经营活动、投资活动和筹资活动现金流量净额；
A34: D、归属于母公司所有者的持续经营损益和终止经营损益。）
... A50: (8、终止经营不再满足持有待售类别划分条件的，企业应当在当期财务报表中，将原来作为终止经营损益列报的信息重新作为可比会计期间的持续经营损益列报，并在附注中说明这一事实。)

Sheet 附注披露信息（国企）A5-4-1
A1: 致同会计师事务所
A2: 附注披露信息（国企）
A3: =表头!A2 -> 客户名称： | B3: =表头!A4 -> 编制人： | C3: =表头!A5 -> 日期： | D3: 索引：A5-4-1
A4: =表头!A3 -> 会计期间：201X年度 | B4: 复核人： | C4: 日期： | D4: 页次：
A5: 附注披露信息
A6: 终止经营
A7: 项目 | B7: 本期发生额 | C7: 上期发生额
A8: 一、终止经营收入
A9: 减：终止成本及经营费用
A10: 二、来自已终止经营的利润总额
A11: 减：终止经营所得税费用
A12: 三、终止经营净利润
A13: 其中：归属于母公司的终止经营净利润
A14: 加：处置业务的净收益（税后）
A15: 其中：处置损益总额
A16: 减：所得税费用（或收益）
A17: 四、来自已终止经营业务的净利润总计
A18: 其中：归属于母公司所有者的来自于已终止经营业务的净利润总计
A19: 五、终止经营的现金流量净额
... A25: 2、终止经营的项目或资产应逐一在报告中披露。

Sheet 明细分析表A5-4-2
A1: 致同会计师事务所
A2: 持续经营净利润和终止经营净利润明细分析表
A3: =表头!A2 -> 客户名称： | F3: =表头!A4 -> 编制人： | J3: 日期： | N3: 索引号： | O3: A5-4-2
A4: =表头!A3 -> 会计期间：201X年度 | F4: 复核人： | J4: 日期： | N4: 页次：
A5: 一、审计目标：
B6: 核对明细账、总账、报表、上年审计报告审定数金额是否相符，确定本期、上期金额是否正确。
A7: 二、审计过程
A8: 1 | B8: 获取或编制持有待售资产和负债的明细表，并完成以下工作：
A9: 1.1 | B9: 复核加计正确；
A10: 1.2 | B10: 复核当期首次符合终止经营定义的处置组在可比期间列报是否完整；
A11: 1.3 | B11: 将上期金额与上年度工作底稿或前期财务报表核对；
A12: 1.4 | B12: 将本期金额与与报表数、总账数和明细账合计数核对一致。
A13: 本期金额 | H13: 上期金额 | O13: 变动比例
A14: 项目 | C14: 本期未审数 | D14: 账项调整 | E14: 重分类调整 | F14: 本期审定数 | G14: 各项目占比 | H14: 项目 | J14: 上期未审数 | K14: 账项调整 | L14: 重分类调整 | M14: 上期审定数 | N14: 各项目占比
A15: 终止经营收入 （A） | H15: 终止经营收入 （A）
B16: 本期附合终止经营定义的处置组A | F16: =C16+D16+E16 -> 0 | G16: =ROUND(F16/F20,4) -> #DIV/0! | I16: 本期附合终止经营定义的处置组A | M16: =J16+K16+L16 -> 0 | N16: =ROUND(M16/M20,4) -> #DIV/0! | O16: ——
B17: 本期附合终止经营定义的处置组B | F17: =C17+D17+E17 -> 0 | G17: =ROUND(F17/F20,4) -> #DIV/0! | I17: 本期附合终止经营定义的处置组B | M17: =J17+K17+L17 -> 0 | N17: =ROUND(M17/M20,4) -> #DIV/0! | O17: ——
B18: …… | F18: =C18+D18+E18 -> 0 | G18: =ROUND(F18/F20,4) -> #DIV/0! | I18: 上期附合终止经营定义的处置组C | M18: =J18+K18+L18 -> 0 | N18: =ROUND(M18/M20,4) -> #DIV/0! | O18: ——
B19: …… | F19: =C19+D19+E19 -> 0 | G19: =ROUND(F19/F20,4) -> #DIV/0! | I19: …… | M19: =J19+K19+L19 -> 0 | N19: =ROUND(M19/M20,4) -> #DIV/0! | O19: ——
A20: 小计 | C20: =SUM(C16:C19) -> 0 | D20: =SUM(D16:D19) -> 0 | E20: =SUM(E16:E19) -> 0 | F20: =SUM(F16:F19) -> 0 | G20: =ROUND(SUM(G16:G19),4) -> #DIV/0! | H20: 小计 | J20: =SUM(J16:J19) -> 0 | K20: =SUM(K16:K19) -> 0 | L20: =SUM(L16:L19) -> 0 | M20: =SUM(M16:M19) -> 0 | N20: =ROUND(SUM(N16:N19),4) -> #DIV/0! | O20: =ROUND((F20-M20)/M20,4) -> #DIV/0!
A21: 减：终止经营费用（B） | H21: 减：终止经营费用（B）
B22: =$B$16 -> 本期附合终止经营定义的处置组A | F22: =C22+D22+E22 -> 0 | G22: =ROUND(F22/F26,4) -> #DIV/0! | I22: =$I$16 -> 本期附合终止经营定义的处置组A | M22: =J22+K22+L22 -> 0 | N22: =ROUND(M22/M26,4) -> #DIV/0! | O22: ——
B23: =$B$17 -> 本期附合终止经营定义的处置组B | F23: =C23+D23+E23 -> 0 | G23: =ROUND(F23/F26,4) -> #DIV/0! | I23: =$I$17 -> 本期附合终止经营定义的处置组B | M23: =J23+K23+L23 -> 0 | N23: =ROUND(M23/M26,4) -> #DIV/0! | O23: ——
B24: =$B$18 -> …… | F24: =C24+D24+E24 -> 0 | G24: =ROUND(F24/F26,4) -> #DIV/0! | I24: =$I$18 -> 上期附合终止经营定义的处置组C | M24: =J24+K24+L24 -> 0 | N24: =ROUND(M24/M26,4) -> #DIV/0! | O24: ——
B25: =$B$19 -> …… | F25: =C25+D25+E25 -> 0 | G25: =ROUND(F25/F26,4) -> #DIV/0! | I25: =$I$19 -> …… | M25: =J25+K25+L25 -> 0 | N25: =ROUND(M25/M26,4) -> #DIV/0! | O25: ——
A26: 小计 | B26: 小计 | C26: =SUM(C22:C25) -> 0 | D26: =SUM(D22:D25) -> 0 | E26: =SUM(E22:E25) -> 0 | F26: =C26+D26+E26 -> 0 | G26: =ROUND(SUM(G22:G25),4) -> #DIV/0! | H26: 小计 | I26: 小计 | J26: =SUM(J22:J25) -> 0 | K26: =SUM(K22:K25) -> 0 | L26: =SUM(L22:L25) -> 0 | M26: =J26+K26+L26 -> 0 | N26: =ROUND(SUM(N22:N25),4) -> #DIV/0! | O26: =ROUND((F26-M26)/M26,4) -> #DIV/0!
A27: 终止经营利润总额（C） | H27: 终止经营利润总额（C）
B28: =$B$16 -> 本期附合终止经营定义的处置组A | F28: =C28+D28+E28 -> 0 | G28: =ROUND(F28/F32,4) -> #DIV/0! | I28: =$I$16 -> 本期附合终止经营定义的处置组A | M28: =J28+K28+L28 -> 0 | N28: =ROUND(M28/M32,4) -> #DIV/0! | O28: ——
B29: =$B$17 -> 本期附合终止经营定义的处置组B | F29: =C29+D29+E29 -> 0 | G29: =ROUND(F29/F32,4) -> #DIV/0! | I29: =$I$17 -> 本期附合终止经营定义的处置组B | M29: =J29+K29+L29 -> 0 | N29: =ROUND(M29/M32,4) -> #DIV/0! | O29: ——
B30: =$B$18 -> …… | F30: =C30+D30+E30 -> 0 | G30: =ROUND(F30/F32,4) -> #DIV/0! | I30: =$I$18 -> 上期附合终止经营定义的处置组C | M30: =J30+K30+L30 -> 0 | N30: =ROUND(M30/M32,4) -> #DIV/0! | O30: ——
B31: =$B$19 -> …… | F31: =C31+D31+E31 -> 0 | G31: =ROUND(F31/F32,4) -> #DIV/0! | I31: =$I$19 -> …… | M31: =J31+K31+L31 -> 0 | N31: =ROUND(M31/M32,4) -> #DIV/0! | O31: ——
A32: 小计 | B32: 小计 | C32: =SUM(C28:C31) -> 0 | D32: =SUM(D28:D31) -> 0 | E32: =SUM(E28:E31) -> 0 | F32: =C32+D32+E32 -> 0 | G32: =ROUND(SUM(G28:G31),4) -> #DIV/0! | H32: 小计 | I32: 小计 | J32: =SUM(J28:J31) -> 0 | K32: =SUM(K28:K31) -> 0 | L32: =SUM(L28:L31) -> 0 | M32: =J32+K32+L32 -> 0 | N32: =ROUND(SUM(N28:N31),4) -> #DIV/0! | O32: =ROUND((F32-M32)/M32,4) -> #DIV/0!
A33: 减：终止经营所得税费用（D） | B33: 持有至到期投资持有期间取得的投资收益 | H33: 减：终止经营所得税费用（D） | I33: 持有至到期投资持有期间取得的投资收益
B34: =$B$16 -> 本期附合终止经营定义的处置组A | F34: =C34+D34+E34 -> 0 | G34: =ROUND(F34/F38,4) -> #DIV/0! | I34: =$I$16 -> 本期附合终止经营定义的处置组A | M34: =J34+K34+L34 -> 0 | N34: =ROUND(M34/M38,4) -> #DIV/0! | O34: ——
B35: =$B$17 -> 本期附合终止经营定义的处置组B | F35: =C35+D35+E35 -> 0 | G35: =ROUND(F35/F38,4) -> #DIV/0! | I35: =$I$17 -> 本期附合终止经营定义的处置组B | M35: =J35+K35+L35 -> 0 | N35: =ROUND(M35/M38,4) -> #DIV/0! | O35: ——
B36: =$B$18 -> …… | F36: =C36+D36+E36 -> 0 | G36: =ROUND(F36/F38,4) -> #DIV/0! | I36: =$I$18 -> 上期附合终止经营定义的处置组C | M36: =J36+K36+L36 -> 0 | N36: =ROUND(M36/M38,4) -> #DIV/0! | O36: ——
B37: =$B$19 -> …… | F37: =C37+D37+E37 -> 0 | G37: =ROUND(F37/F38,4) -> #DIV/0! | I37: =$I$19 -> …… | M37: =J37+K37+L37 -> 0 | N37: =ROUND(M37/M38,4) -> #DIV/0! | O37: ——
A38: 小计 | B38: 小计 | C38: =SUM(C34:C37) -> 0 | D38: =SUM(D34:D37) -> 0 | E38: =SUM(E34:E37) -> 0 | F38: =C38+D38+E38 -> 0 | G38: =ROUND(SUM(G34:G37),4) -> #DIV/0! | H38: 小计 | I38: 小计 | J38: =SUM(J34:J37) -> 0 | K38: =SUM(K34:K37) -> 0 | L38: =SUM(L34:L37) -> 0 | M38: =J38+K38+L38 -> 0 | N38: =ROUND(SUM(N34:N37),4) -> #DIV/0! | O38: =ROUND((F38-M38)/M38,4) -> #DIV/0!
A39: 经营活动净利润（E=C-D） | B39: 可供出售金融资产持有期间取得的投资收益 | H39: 经营活动净利润（E=C-D） | I39: 可供出售金融资产持有期间取得的投资收益
B40: =$B$16 -> 本期附合终止经营定义的处置组A | C40: =C28-C34 -> 0 | D40: =D28-D34 -> 0 | E40: =E28-E34 -> 0 | F40: =C40+D40+E40 -> 0 | G40: =ROUND(F40/F44,4) -> #DIV/0! | I40: =$I$16 -> 本期附合终止经营定义的处置组A | J40: =J28-J34 -> 0 | K40: =K28-K34 -> 0 | L40: =L28-L34 -> 0 | M40: =J40+K40+L40 -> 0 | N40: =ROUND(M40/M44,4) -> #DIV/0! | O40: ——
...

Sheet 检查表A5-4-3
A1: 致同会计师事务所
A2: 持续经营净利润和终止经营净利润检查表
A3: =表头!A2 -> 客户名称： | C3: =表头!A4 -> 编制人： | E3: =表头!A5 -> 日期： | G3: 索引号：A5-4-3
A4: =表头!A3 -> 会计期间：201X年度 | C4: 复核人： | E4: 日期： | G4: 页次：
A5: 一、审计目标：
B6: 本期转入终止经营净利润金额是否正确合理。
A7: 二、审计过程
A8: 1 | B8: 询问被审计单位管理层处置的原因，并获取被审计单位就处置该非流动资产或处置组作出的决议、转让协议、评估报告等相关支持性证据，检查确认为终止经营净利润是否合理，金额是否正确。
A9: 2 | B9: 检查终止经营相关损益核算是否完整、准确。
A10: 项目 | B10: 对方单位 | C10: 合同/协议内容 | D10: 合同执行日期 | E10: 本期应计损益 | F10: 本期已计损益 | G10: 差异 | H10: 合同索引 | I10: 凭证检查索引 | J10: 审计结论
A11: 附合终止经营定义的处置组A | E11: =B30 -> 0 | F11: =B41 -> 0 | G11: =F11-E11 -> 0
A12: 附合终止经营定义的处置组B | E12: =C30 -> 0 | F12: =C41 -> 0 | G12: =F12-E12 -> 0
A13: 附合终止经营定义的处置组C | E13: =D30 -> 0 | F13: =D41 -> 0 | G13: =F13-E13 -> 0
A14: 附合终止经营定义的处置组D | E14: =E30 -> 0 | F14: =E41 -> 0 | G14: =F14-E14 -> 0
A15: 附合终止经营定义的处置组E | E15: =F30 -> 0 | F15: =F41 -> 0 | G15: =F15-E15 -> 0
A16: …… | E16: =G30 -> 0 | F16: =G41 -> 0 | G16: =F16-E16 -> 0
A18: 其中：
A19: 项目 | B19: 附合终止经营定义的处置组A | C19: 附合终止经营定义的处置组B | D19: 附合终止经营定义的处置组C | E19: 附合终止经营定义的处置组D | F19: 附合终止经营定义的处置组E | G19: ……
A20: 本期应计损益：
A21: A、终止经营的经营活动收入；
A22: B、终止经营的经营活动成本；
A23: C、终止经营的经营活动费用；
A24: D、账面价值高于其公允价值减去出售费用后的净额而确认的资产减值损失；
A25: E、恢复以前减记的金额而转回的资产减值损失；
A26: F、终止经营的处置损益；
A27: G、增量费用
A28: H、其他损益（可明细列示）；
A29: ……
A30: 小计 | B30: =B21-B22-B23-B24-B25-B26-B27-B28 -> 0 | C30: =C21-C22-C23-C24-C25-C26-C27-C28 -> 0 | D30: =D21-D22-D23-D24-D25-D26-D27-D28 -> 0 | E30: =E21-E22-E23-E24-E25-E26-E27-E28 -> 0 | F30: =F21-F22-F23-F24-F25-F26-F27-F28 -> 0 | G30: =G21-G22-G23-G24-G25-G26-G27-G28 -> 0
A31: 账面已计损益：
A32: =A21 -> A、终止经营的经营活动收入；
A33: =A22 -> B、终止经营的经营活动成本；
A34: =A23 -> C、终止经营的经营活动费用；
A35: =A24 -> D、账面价值高于其公允价值减去出售费用后的净额而确认的资产减值损失；
A36: =A25 -> E、恢复以前减记的金额而转回的资产减值损失；
A37: =A26 -> F、终止经营的处置损益；
A38: =A27 -> G、增量费用
A39: =A28 -> H、其他损益（可明细列示）；
A40: =A29 -> ……
A41: 小计 | B41: =B32-B33-B34-B35-B36-B37-B38-B39 -> 0 | C41: =C32-C33-C34-C35-C36-C37-C38-C39 -> 0 | D41: =D32-D33-D34-D35-D36-D37-D38-D39 -> 0 | E41: =E32-E33-E34-E35-E36-E37-E38-E39 -> 0 | F41: =F32-F33-F34-F35-F36-F37-F38-F39 -> 0 | G41: =G32-G33-G34-G35-G36-G37-G38-G39 -> 0
...
