Workbook

Sheet GC生产经营能力及规模调查封面
A2: 生产经营能力及规模调查——程序表
A4: 被审计单位： | E4: 编制人： | H4: 日期： | I4: 2018.XX.XX | J4: 索引号： | K4: GC
A5: 会计期间： | E5: 复核人： | H5: 日期： | I5: 2018.XX.XX | J5: 页次：
A7: 一、审计目标与认定对应关系表：
F8: 财务报表认定
A9: 审计目标 | F9: a | G9: b | H9: c | I9: d | J9: e
F10: 存在性 | G10: 完整性 | H10: 准确性 | I10: 计价 | J10: 列报
A11: A | B11: 调查企业生产经营能力及规模。 | F11: √
A12: B | B12: 确定收入的合理性及可信度。 | G12: √
A14: 二、审计目标与审计计划的衔接：
A15: 项 目 | G15: 财务报表认定
G16: 存在性 | H16: 完整性 | I16: 准确性 | J16: 计价 | K16: 列报
B17: 评估的重大错报风险水平（注：“显著”或“普通”，结果取自该项目所属业务循环工作底稿）
B18: 控制测试结果是否支持风险评估结论（注：结果取自该项目所属业务循环内部控制测试工作底稿）
B19: 需从实质性程序获取的保证程度（注：结果取自该项目所属循环了解内部控制中的审计应对措施工作底稿）
A21: 三、审计目标与审计程序对应关系表：
A22: 审计目标 | B22: 内 容 | I22: 是否计划实施（√） | J22: 与认定的对应关系 | K22: 索引号
B23: 1.了解和询问企业产品生产的主要生产过程
B24: 2.获取企业近三年来营业收入有关数据，比较差异，确定主要产品有关数据资料。
B25: 3.获取企业人员的实际记录等原始记录
B26: 4.获取企业单台设备、车辆等营运能力的定额指标，并根据设备、车辆等总量进行框算，确定企业生产经营能力及规模的上限。
B27: 5.获取企业生产产量或其他工作量等原始记录
B28: 6.现场观察企业的生产情况，并作出观察记录和小结
B29: 7.根据了解和询问情况，说明对关键生产控制点的合理判断的理由和结论
B30: 8.根据对企业生产能力的调查问卷，以及对生产能力的现场观察，对企业生产产量进行合理推算。
B31: 9.根据实际的物耗、，对企业生产产量进行合理推算。
A34: 四、需说明的事项
B36: =IF(J47="√","本科目无需调整事项","调整分录详见后附页") -> 本科目无需调整事项
A41: 五、发生额：
C42: 上年发生额 | G42: 本年发生额
C43: 上年审定数（或未审数） | E43: 本期审定数 | G43: 未审数 | I43: 本期审定数
A46: 六、审计结论：
A47: 1、 经审核，本期收入应在生产经营能力范围内，可信度较高： | J47: =IF(AND(C47-E47=0,G47-I47=0),"√",0) -> √
A49: 2、 本期收入似超越了生产能力许可范围： | J49: 0
A51: 3、 按生产能力估计，本期收入有明显高估的可能：

Sheet GC-1生产能力调查问卷
A1: 生产经营能力及规模调查——生产能力调查问卷
A3: 被审计单位： | B3: =GC生产经营能力及规模调查封面!B4 -> 0 | C3: 编制人： | D3: =GC生产经营能力及规模调查封面!F4 -> 0 | E3: 日期： | F3: =GC生产经营能力及规模调查封面!I4 -> 2018.XX.XX | G3: 索引号： | H3: GC-1
A4: 会计期间： | B4: =GC生产经营能力及规模调查封面!B5 -> 0 | C4: 复核人： | D4: =GC生产经营能力及规模调查封面!F5 -> 0 | E4: 日期： | F4: =GC生产经营能力及规模调查封面!I5 -> 2018.XX.XX | G4: 页次：
A5: （本底稿根据企业实际特点，可进行适当修改或另行设计）
A7: 1、向财务部门询问近3年销售量和比重？询问和了解企业生产的主要产品是什么？报告期内实际产量多少？
B8: 20XX年度：
B9: 主要产品名称 | C9: 规格 | D9: 计量单位 （如：重量/工时/件/条等） | E9: 销售数量 | F9: 销售金额（万元） | G9: 销售金额比例 | H9: 产量
B16: 20XX-1年度：
B17: 主要产品名称 | C17: 规格 | D17: 计量单位 （如：重量/工时/件/条等） | E17: 销售数量 | F17: 销售金额（万元） | G17: 销售金额比例 | H17: 产量
B24: 20XX-2年度：
B25: 主要产品名称 | C25: 规格 | D25: 计量单位 （如：重量/工时/件/条等） | E25: 销售数量 | F25: 销售金额（万元） | G25: 销售金额比例 | H25: 产量
A36: 2、向设计部门询问与了解产品主要是依赖于设备生产能力还是依赖于生产人员数量？
B37: 主要依赖于设备的生产能力 | C37: ( )
B38: 主要依赖于生产人员的数量 | C38: （ ）
A39: 3、向设计部门询问和了解主要产品生产的主要工艺过程。（以图示法表达）工艺设计的生产能力？哪个生产阶段是主要产品必须经过的？（如：生产工艺中的关键设备和关键工艺及其产量）
A40: （1）生产工艺过程（以图示法表达）
A42: （2）工艺设计的生产能力
B43: 生产过程中的关键设备和关键工艺 | C43: 主要产品名称 | D43: 规格 | E43: 计量单位（如：重量/工时/件/条等） | F43: 产量
A49: （3）主要产品的生产过程中必须经过的关键设备是 ，其产量是______________________
A51: 4、向设备管理部门询问和了解产品生产的主要的关键设备（注：制约产量的设备）或生产流水线数量？这些设备设计能力？设备需要配备的相关人员数量？（主要适用产品产量依赖于设备生产能力）
A52: （1）关键设备的数量 台，生产线有 条
A54: （2）生产设备需要配备的生产人员的数量 个
A56: 5、向设备管理部门询问和了解企业的能源（例如电力、煤等）消耗和水资源消耗上年情况和本年消耗情况？了解和询问主要产品设计能源及水资源消耗量？（适用于主要产品生产依赖于能源的消耗数量或水资源消耗的企业）
A57: （1）企业生产主要的生产能源是 ，每年消耗 ，水每年消耗 吨
A59: （2）产品设计的能源消耗和水资源
B60: 主要产品名称 | C60: 规格 | D60: 计量单位 （如：重量/工时/件/条等）
A66: 6、向人事部门询问和了解目前企业各生产部门的人员数量？生产人员产量考核办法？
A67: （1）企业各生产部门的人员数量
A69: （2）生产人员产量考核办法是
A72: 7、主要材料投放是一次投料还是多次投料？多次投料是在哪个生产阶段完成的？投入产出比例是多少？
B73: 主要材料的投料方式是 ：
B75: 材料全部投入完成的生产阶段是：
B77: 投入产出比：
B78: 主要产品名称 | C78: 产量 | D78: 耗用总量 | E78: 单耗
A81: 8、企业的生产场地的面积是多少？设备需要占用的面积多少?
B82: 企业的总建筑面积 生产建筑面积 设备占用面积 ______________________
A86: 9、需询问和了解到其他事项（影响产能的其他因素，如季节性因素、停工检修、运输能力、产品保质期等）
D93: 被调查人员签字：
D100: 调查时间： 年 月 日

Sheet GC-2生产能力调查表
A1: 生产经营能力及规模调查——生产能力调查表
A3: 被审计单位： | B3: =GC生产经营能力及规模调查封面!B4 -> 0 | C3: 编制人： | E3: 日期： | F3: =GC生产经营能力及规模调查封面!I4 -> 2018.XX.XX | G3: 索引号： | H3: GC-2
A4: 会计期间： | B4: =GC生产经营能力及规模调查封面!B5 -> 0 | C4: 复核人： | E4: 日期： | F4: =GC生产经营能力及规模调查封面!I5 -> 2018.XX.XX | G4: 页次：
A6: 1、取得设计部门的工艺设计的生产能力
B7: 主要产品名称 | C7: 规格 | D7: 数量 | E7: 金额 | F7: 折合标准（如：重量/工时/件/条等）
A15: 2、根据被审计单位生产部门产量统计实际产量
B16: 主要产品名称 | C16: 规格 | D16: 计量单位 | E16: 数量 | F16: 备注
A24: 3、根据对被审计单位的财务账面取得的主要产品产量
B25: 主要产品名称 | C25: 规格 | D25: 计量单位 | E25: 数量 | F25: 备注
A33: 4、差异原因的分析

Sheet GC-3生产能力现场观察
H1: 索引： | I1: GC-3
A2: 生产经营能力及规模调查——对生产能力调查的现场观察
A3: （根据企业特点可参考本底稿的内容自行设计）
A4: =GC生产经营能力及规模调查封面!A4&GC生产经营能力及规模调查封面!B4 -> 被审计单位：
A5: 一、调查日期：________________________________
A6: 二、调查记录
A7: （一）产品名称 规格
A8: 调查地点：________________________________
A9: 生产人员：__________________________________
A10: 生产记录员：_________________________________
A11: 生产人员考核指标：___________________ 生产人员实际完成考核指标：___________________
A12: 设备（或流水线）名称：
A13: 记录观察的耗用时间 观察期间生产数量：
A14: （二）产品名称 规格
A15: 调查地点：________________________________
A16: 生产人员：__________________________________
... A40: 复核人员签字：

Sheet GC-4生产能力测算
A1: 生产能力测算
A3: 被审计单位： | B3: =[1]设定!$C$6 -> XXX有限公司 | C3: 编制人： | D3: =GC生产经营能力及规模调查封面!F4 -> 0 | E3: 日期： | F3: =GC生产经营能力及规模调查封面!I4 -> 2018.XX.XX | G3: 索引号： | H3: GC-4
A4: 会计期间： | B4: =GC生产经营能力及规模调查封面!D5 -> 0 | C4: 复核人： | D4: =GC生产经营能力及规模调查封面!F5 -> 0 | E4: 日期： | F4: =GC生产经营能力及规模调查封面!I5 -> 2018.XX.XX | G4: 页次：
A6: 1、生产能力合理性说明（针对调查问卷和现场观察情况）
A13: 2、根据了解和观察结果，合理推算企业的生产能力（以下表格提供的方法仅供参考）
B14: 主要产品名称 | C14: 主要设备或流水线的名称 | D14: 关键的生产工序的名称 | E14: 设计生产率（件/小时） | F14: 计划生产班次数 | G14: 设计生产量 | H14: 备注
B22: 主要产品名称 | C22: 主要设备或流水线的名称 | D22: 关键的生产工序的名称 | E22: 现场记录生产率（件/小时） | F22: 实际生产班次数 | G22: 实际产量 | H22: 本期计划生产班次数 | I22: 按照现场记录生产率计算的本期可生产产量
A30: 3、合理推算的结果与调查结果的比较（提示：说明差异的原因），确定销售能力是否可信

Sheet temp
B1: SM生产经营能力及规模调查封面 | C1: SM-1生产能力调查问卷
C2: SM-2生产能力调查表
C3: SM-3生产能力现场观察
C4: SM-4生产能力测算
C5: SM-5生产能力与资源耗用分析
A6: temp

Sheet GC-5生产能力与资源耗用分析
A1: 生产能力与资源耗用分析
A2: 被审计单位： | B2: =[1]设定!$C$6 -> XXX有限公司 | C2: 编制人： | F2: 日期： | G2: =GC生产经营能力及规模调查封面!I4 -> 2018.XX.XX | I2: 索引号： | J2: GC-5
A3: 会计期间： | B3: =GC生产经营能力及规模调查封面!D5 -> 0 | C3: 复核人： | F3: 日期： | G3: =GC生产经营能力及规模调查封面!I5 -> 2018.XX.XX | I3: 页次：
A5: 一、固定资产原值与产品产量的比例分析
A6: 项目 | C6: 年 | D6: 年 | E6: 年 | F6: 备注
A7: 固定资产原值与X产品产量的比例
A8: 固定资产原值与X产品产量的比例
A12: 二、主要资源耗用数量与产品产量分析
A13: （提示：以下为示例。在实务中，应根据所了解的被审计单位生产工艺流程，从实际已经发生的物料/主要材料的数量、人工/工时数量、消耗电力/水/煤/气/热等的数量，分析生产能力的合理性。）
A14: 示例： 从实际的物料消耗、人工及耗电量分析生产能力的合理性。
A15: X产品和Y产品产量
A16: 单位：吨
A17: 月份 | B17: X产品 | D17: Y产品 | G17: 合计产量
A18: 一月
A19: 二月
A20: 三月
A21: 四月
A22: 五月
A23: 六月
A24: 七月
A25: 八月
A26: 九月
A27: 十月
A28: 十一月
A29: 十二月
... A34: 审计获取20XX年1-12月M料发出资料（详见原材料计价测试底稿），与当月的产量进行配比，分析XY产品每吨耗用M料（吨料）波动的情况。
A36: 月份 | B36: X产品的M料耗用量 | D36: Y产品的M料耗用量 | F36: 生产领用量合计 | G36: 吨耗比 | H36: 与平均吨耗差异率
A37: 一月
A38: 二月
A39: 三月
A40: 四月
A41: 五月
A42: 六月
A43: 七月
A44: 八月
A45: 九月
A46: 十月
A47: 十一月
A48: 十二月
... A51: 2.直接人工-产量工资分析
...
