Workbook
Name _13102: #REF!
Name _13102: #REF!
Name _13302: #REF!
Name _13302: #REF!
Name _13398: #REF!
Name _13398: #REF!
Name _18102: #REF!
Name _18102: #REF!
Name _18198: #REF!
Name _18198: #REF!
Name _1其他资产_开办费除外_明细表: #REF!
Name _2003附注: [1]附注汇总!$C$5:$AY$646
Name _2其他资产_开办费除外_明细表: #REF!
Name _scn11: #REF!
Name _scn11: #REF!
Name _scn15: #REF!
Name _scn15: #REF!
Name _scn16: #REF!
Name _scn16: #REF!
Name _scn17: #REF!
Name _scn17: #REF!
Name _scn19: #REF!
Name _scn19: #REF!
Name _scn2: #REF!
Name _scn2: #REF!
Name _scn20: #REF!
Name _scn20: #REF!
Name _scn3: #REF!
Name _scn3: #REF!
Name _scn4: #REF!
Name _scn4: #REF!
Name _scn5: #REF!
Name _scn5: #REF!
Name _scn6: #REF!
Name _scn6: #REF!
Name _scn7: #REF!
Name _scn7: #REF!
Name _scn8: #REF!
Name _scn8: #REF!
Name _scn9: #REF!
Name _scn9: #REF!
Name _scq1: #REF!
Name _scq1: #REF!
Name _scq11: #REF!
Name _scq11: #REF!
Name _scq15: #REF!
Name _scq15: #REF!
Name _scq16: #REF!
Name _scq16: #REF!
Name _scq17: #REF!
Name _scq17: #REF!
Name _scq19: #REF!
Name _scq19: #REF!
Name _scq2: #REF!
Name _scq2: #REF!
Name _scq20: #REF!
Name _scq20: #REF!
Name _scq3: #REF!
Name _scq3: #REF!
Name _scq4: #REF!

Sheet temp_temp__
AI36: =SUM(AI26)+SUM(AI27)-SUM(AI32) -> 0

Sheet 说明
B2: 使用说明： | L2: 序号 | M2: 目录
L3: 1 | M3: 说明
B4: 1 | C4: 本工作簿用于合并会计报表审计调整、试算平衡；审定报表的横向、纵向、比率分析。 | L4: 2 | M4: TEST
L5: 3 | M5: 报表格式
B6: 2 | C6: 本工作簿没有颜色的单元格可以根据需要进行修改， | L6: 4 | M6: 年初BS审定
C7: 修改时，请在拟修改的单元格直接输入新的内容，请不要使用剪切或拖拽填充功能。 | L7: 5 | M7: 上年PL审定
L8: 6 | M8: 期初核对BS
B9: 3 | C9: 请在 | D9: “基本参数” | E9: 中没有颜色的单元格中输入项目基本情况，其他工作表相应区域会随之改变。 | L9: 7 | M9: 期初核对PL
L10: 8 | M10: 母公司BS原报汇总
B11: 4 | C11: 未审报表、试算平衡表（TB）、审定报表、比较分析表的格式由 | G11: “报表格式” | H11: 链接控制； | L11: 9 | M11: 母公司PL原报汇总
C12: 如需修改报表科目，请在 | E12: “报表格式” | F12: 中没有颜色的单元格区域修改，其他报表会相应改变。 | L12: 10 | M12: 母公司CF原报汇总
L13: 11 | M13: 母公司汇总抵销
B14: 5 | C14: “权益抵销” | D14: “往来交易抵销” | E14: 可以根据需要插入行，请勿删除行；调整金额会自动链接到试算平衡表， | L14: 12 | M14: 母公司账项调整
C15: 若调整未全部链入试算平衡表，请检查调整分录的借贷方科目是否为报表科目。若需添加或更改报表科目， | L15: 13 | M15: 母公司报表调整
C16: 请在 | D16: “报表格式” | E16: 中没有颜色的单元格区域进行修改，并相应修改 | H16: “报表格式AA列” | L16: 14 | M16: 母公司TB资产
L17: 15 | M17: 母公司TB负债
L18: 16 | M18: 母公司TB损益
L19: 17 | M19: TB母公司CF
L20: 18 | M20: 合并BS汇总
C21: 基本参数： | L21: 19 | M21: 合并PL汇总
C22: 项 目 | E22: 参 数 | G22: 参考格式 | L22: 20 | M22: 合并CF汇总
C23: 客户情况 | D23: 单位名称： | G23: 北京二锅头有限责任公司 | L23: 21 | M23: 权益抵销
D24: 法定代表人： | G24: 张一二 | L24: 22 | M24: 往来交易抵销
D25: 财务负责人： | G25: 陈一二 | L25: 23 | M25: 合并报表调整
D26: 会计主管： | G26: 王一二 | L26: 24 | M26: 合并TB资产
L27: 25 | M27: 合并TB负债
C28: 会计报表 | D28: 报表类型 | E28: 股份有限公司 | G28: 股份有限公司或一般企业(执行统一会计制度) | J28: 股份有限公司 | L28: 26 | M28: 合并TB损益
D29: 会计年度（上期）： | E29: 2018年度 | G29: 1999年度 或 1997年10月20日～1998年8月10日 | J29: 非股份有限公司 | L29: 27 | M29: TB合并CF
D30: 会计年度（本期）： | E30: 2019年度 | G30: 2000年度 或 1998年8月10日～2000年10月20日 | L30: 28 | M30: 审定合并BS
D31: 会计截止（上期）： | E31: 43465 | G31: 1999年12月31日 或 1998年8月10日 | J31: =MONTH(E31) -> 12 | L31: 29 | M31: 审定合并PL
D32: 会计截止（本期）： | E32: 43830 | G32: 2000年12月31日 或 2000年10月20日 | J32: =MONTH(E32) -> 12 | L32: 30 | M32: 审定合并CF
D33: 金额单位： | E33: 人民币元 | G33: 人民币元 | L33: 31 | M33: 已审横向BS
C34: NB： | D34: 本表没有颜色的单元格可以根据需要进行修改 | L34: 32 | M34: 已审横向PL
L35: 33 | M35: 已审纵向BS
L36: 34 | M36: 已审纵向PL
L37: 35 | M37: 已审比率分析
L38: 36 | M38: EPS-ROE计算
L39: 37 | M39: 母已审横向BS
L40: 38 | M40: 母已审横向PL
L41: 39 | M41: 母已审纵向BS
...

Sheet TEST
B3: 报表勾稽关系审核表
B4: No. | C4: 勾稽审核内容 | D4: 审核结果 | E4: 不符原因
B5: 1 | C5: 期末资产总计＝期末负债和股东权益总计 | D5: =IF(ABS(审定合并BS!C59-审定合并BS!C122)<0.01,TRUE,FALSE) -> TRUE | E5: =IF(D5=TRUE,"","期末资产负债表不平")
B6: 2 | C6: 期初资产总计＝期初负债和股东权益总计 | D6: =IF(ABS(审定合并BS!E59-审定合并BS!E122)<0.01,TRUE,FALSE) -> TRUE | E6: =IF(D6=TRUE,"","期初资产负债表不平")
B7: 3 | C7: B/S期末未分配利润＝P/L期末未分配利润 | D7: =IF(ABS(审定合并BS!C118-审定合并PL!C89)<0.01,TRUE,FALSE) -> TRUE | E7: =IF(D7=TRUE,"","期末利润分配表与资产负债表未分配利润勾稽不对")
B8: 4 | C8: B/S期初未分配利润＝P/L期初未分配利润 | D8: =IF(ABS(审定合并BS!E116-审定合并PL!E71)<0.01,TRUE,FALSE) -> TRUE | E8: =IF(D8=TRUE,"","期初利润分配表与资产负债表未分配利润勾稽不对")
B9: 5 | C9: 期末年初未分配利润＝期初未分配利润 | D9: =IF(ABS(审定合并PL!C79-审定合并PL!E89)<0.01,TRUE,FALSE) -> TRUE | E9: =IF(D9=TRUE,"","利润及利润分配表年初未分配利润与上期勾稽不对")
B10: 6 | C10: B/S期末货币资金＝Cashflow期末货币资金 | D10: =IF(ABS(审定合并BS!C7-审定合并CF!C64)<0.01,TRUE,FALSE) -> TRUE | E10: =IF(D10=TRUE,"","现金流量表与资产负债表期末货币资金勾稽不对")
B11: 7 | C11: B/S期初货币资金＝Cashflow期初货币资金 | D11: =IF(ABS(审定合并BS!E7-审定合并CF!C63)<0.01,TRUE,FALSE) -> TRUE | E11: =IF(D11=TRUE,"","现金流量表与资产负债表期初货币资金勾稽不对")
B12: 8 | C12: 直接法OperatingCF＝间接法OperatingCF | D12: =IF(ABS(审定合并CF!C31-审定合并CF!C91)<0.01,TRUE,FALSE) -> TRUE | E12: =IF(D12=TRUE,"","现金流量表主表与附表勾稽不对-经营活动现金净增加额")
B13: 9 | C13: 直接法NetCashflow＝间接法NetCashflow | D13: =IF(ABS(审定合并CF!C103-审定合并CF!C62)<0.01,TRUE,FALSE) -> TRUE | E13: =IF(D13=TRUE,"","现金流量表主表与附表勾稽不对-现金净增加额")
B14: 10 | C14: P/L净利润＝Cashflow间接法净利润 | D14: =IF(ABS(审定合并CF!C75-审定合并PL!C44)<0.01,TRUE,FALSE) -> TRUE | E14: =IF(D14=TRUE,"","现金流量表与利润表勾稽不对-净利润")
B15: 11 | C15: Cashflow存货的减少＝B/S存货的减少 | D15: =IF(ABS(审定合并CF!C87-(审定合并BS!E24-审定合并BS!C24))<0.01,TRUE,FALSE) -> TRUE | E15: =IF(D15=TRUE,"","现金流量表存货与资产负债表勾稽不对")
B16: 12 | C16: Cashflow投资收益＝P/L投资收益 | D16: =IF(ABS(审定合并CF!C84+审定合并PL!C33)<0.01,TRUE,FALSE) -> TRUE | E16: =IF(D16=TRUE,"","利润分配表与现金流量表投资收益勾稽不对")
B17: 13 | C17: 按净利润的10%提取法定盈余公积 | D17: =IF(ABS(审定合并PL!C53-审定合并PL!H45*0.1)<0.01,TRUE,FALSE) -> TRUE | E17: =IF(D17=TRUE,"","按照公司政策，公司提取的法定盈余公积不符")
B18: 14
B19: 15
B20: 16
B21: 17

Sheet 报表格式
A1: 会计报表格式及科目名称 | Q1: 会计报表格式及科目名称 | Z1: code | AA1: 报表项目
B2: 本表没有颜色的单元格可以根据需要进行修改，本系统的其它表格将随之改变。比如，可将“存货”改为“存货1”。正确的修改方法，是在拟修改的单元格直接输入新的内容，请不要使用剪切或拖拽功能。
B3: 资 产 类 | G3: 负债及所有者权益类 | L3: 损 益 类 | Q3: 现金流量表类 | U3: 现金流量表类
B4: 报表项目 | C4: 行 | D4: 调整年末科目名称 | E4: 调整年初科目名称 | G4: 报表项目 | H4: 行 | I4: 调整年末科目名称 | J4: 调整年初科目名称 | L4: 报表项目 | M4: 行 | N4: 调整本期科目名称 | O4: 调整上期科目名称 | Q4: 报表项目 | R4: 行 | S4: 科目名称 | U4: 补充资料 | V4: 行 | W4: 科目名称
B5: 流动资产： | C5: 1 | G5: 流动负债： | H5: =C58+1 -> 55 | L5: 一、营业收入 | M5: 1 | N5: 主营业务收入 | O5: =IF(N5="",0,CONCATENATE("上年",N5)) -> 上年主营业务收入 | Q5: 一、经营活动产生的现金流量 | R5: 1 | U5: 1、将净利润调节为经营活动现金流量： | V5: =R70+1 -> 1 | AA5: 流动资产：
B6: 货币资金 | C6: 2 | D6: 货币资金 | E6: =IF(D6="",0,CONCATENATE("年初",D6)) -> 年初货币资金 | G6: 短期借款 | H6: =H5+1 -> 56 | I6: 短期借款 | J6: =IF(I6="",0,CONCATENATE("年初",I6)) -> 年初短期借款 | L6: 其中：主营业务收入 | M6: 2 | Q6: 销售商品、提供劳务收到的现金 | R6: 2 | S6: 销售商品、提供劳务收到的现金 | U6: 净利润 | V6: =V5+1 -> 2 | W6: 净利润 | Z6: D1 | AA6: =B6 -> 货币资金
B7: 结算备付金 | C7: 3 | D7: 短期投资 | E7: =IF(D7="",0,CONCATENATE("年初",D7)) -> 年初短期投资 | G7: 向中央银行借款 | H7: =H6+1 -> 57 | I7: 应付票据 | J7: =IF(I7="",0,CONCATENATE("年初",I7)) -> 年初应付票据 | L7: 利息收入 | M7: 3 | Q7: 客户存款和同业存放款项净增加额 | R7: 3 | S7: 收到的税费返还 | V7: =V6+1 -> 3 | W7: 少数股东损益 | Z7: D41 | AA7: =B7 -> 结算备付金
B8: 拆出资金 | C8: 4 | D8: 应收票据 | E8: =IF(D8="",0,CONCATENATE("年初",D8)) -> 年初应收票据 | G8: 吸收存款及同业存放 | H8: =H7+1 -> 58 | I8: 应付账款 | J8: =IF(I8="",0,CONCATENATE("年初",I8)) -> 年初应付账款 | L8: 已赚保费 | M8: 4 | N8: 折扣与折让 | O8: =IF(N8="",0,CONCATENATE("上年",N8)) -> 上年折扣与折让 | Q8: 向中央银行借款净增加额 | R8: 4 | S8: 收到的其他与经营活动有关的现金 | V8: =V7+1 -> 4 | W8: 未确认的投资损失 | Z8: D42 | AA8: =B8 -> 拆出资金
B9: 交易性金融资产 | C9: 5 | D9: 应收股利 | E9: =IF(D9="",0,CONCATENATE("年初",D9)) -> 年初应收股利 | G9: 拆入资金 | H9: =H8+1 -> 59 | I9: 预收账款 | J9: =IF(I9="",0,CONCATENATE("年初",I9)) -> 年初预收账款 | L9: 手续费及佣金收入 | M9: 5 | Q9: 向其他金融机构拆入资金净增加额 | R9: 5 | U9: 加：资产减值损失 | V9: =V8+1 -> 5 | W9: 计提的资产减值准备 | Z9: D2 | AA9: =B9 -> 交易性金融资产
B10: 以公允价值计量且其变动计入当期损益的金融资产 | C10: 6 | D10: 应收利息 | E10: =IF(D10="",0,CONCATENATE("年初",D10)) -> 年初应收利息 | G10: 交易性金融负债 | H10: =H9+1 -> 60 | I10: 应付工资 | J10: =IF(I10="",0,CONCATENATE("年初",I10)) -> 年初应付工资 | L10: 其他业务收入 | M10: 6 | N10: 主营业务成本 | O10: =IF(N10="",0,CONCATENATE("上年",N10)) -> 上年主营业务成本 | Q10: 收到原保险合同保费取得的现金 | R10: 6 | U10: 信用减值损失 | V10: =V9+1 -> 6 | W10: 固定资产折旧 | Z10: D3 | AA10: =B10 -> 以公允价值计量且其变动计入当期损益的金融资产
B11: 衍生金融资产 | C11: 7 | D11: 应收账款 | E11: =IF(D11="",0,CONCATENATE("年初",D11)) -> 年初应收账款 | G11: 以公允价值计量且其变动计入当期损益的金融负债 | H11: =H10+1 -> 61 | I11: 应付福利费 | J11: =IF(I11="",0,CONCATENATE("年初",I11)) -> 年初应付福利费 | L11: 减：营业成本 | M11: 7 | Q11: 收到再保险业务现金净额 | R11: 7 | S11: 购买商品、接受劳务支付的现金 | U11: 固定资产折旧、油气资产折耗、生产性生物资产折旧 | V11: =V10+1 -> 7 | W11: 无形资产摊销 | Z11: D4 | AA11: =B11 -> 衍生金融资产
B12: 应收票据 | C12: 8 | D12: 其他应收款 | E12: =IF(D12="",0,CONCATENATE("年初",D12)) -> 年初其他应收款 | G12: 衍生金融负债 | H12: =H11+1 -> 62 | I12: 应付股利 | J12: =IF(I12="",0,CONCATENATE("年初",I12)) -> 年初应付股利 | L12: 其中：主营业务成本 | M12: 8 | N12: 主营业务税金及附加 | O12: =IF(N12="",0,CONCATENATE("上年",N12)) -> 上年主营业务税金及附加 | Q12: 保户储金及投资款净增加额 | R12: 8 | S12: 支付给职工以及为职工支付的现金 | U12: 无形资产摊销 | V12: =V11+1 -> 8 | W12: 长期待摊费用摊销 | Z12: D5 | AA12: =B12 -> 应收票据
B13: 应收账款 | C13: 9 | D13: 预付账款 | E13: =IF(D13="",0,CONCATENATE("年初",D13)) -> 年初预付账款 | G13: 应付票据 | H13: =H12+1 -> 63 | I13: 应交税金 | J13: =IF(I13="",0,CONCATENATE("年初",I13)) -> 年初应交税金 | L13: 利息支出 | M13: 9 | N13: 经营费用 | O13: =IF(N13="",0,CONCATENATE("上年",N13)) -> 上年经营费用 | Q13: 收取利息、手续费及佣金的现金 | R13: 9 | S13: 支付各项税费 | U13: 长期待摊费用摊销 | V13: =V12+1 -> 9 | W13: 待摊费用的减少（减：增加） | Z13: D6 | AA13: =B13 -> 应收账款
B14: 应收款项融资 | C14: 10 | D14: 期货保证金 | E14: =IF(D14="",0,CONCATENATE("年初",D14)) -> 年初期货保证金 | G14: 应付账款 | H14: =H13+1 -> 64 | I14: 其他未交款 | J14: =IF(I14="",0,CONCATENATE("年初",I14)) -> 年初其他未交款 | L14: 手续费及佣金支出 | M14: 10 | N14: 其他 | O14: =IF(N14="",0,CONCATENATE("上年",N14)) -> 上年其他 | Q14: 拆入资金净增加额 | R14: 10 | S14: 支付的其他与经营活动有关的现金 | U14: 处置固定资产、无形资产和其他长期资产的损失（收益以“－”号填列） | V14: =V13+1 -> 10 | W14: 预提费用的增加（减：减少） | Z14: D7 | AA14: =B14 -> 应收款项融资
B15: 预付款项 | C15: 11 | D15: 应收补贴款 | E15: =IF(D15="",0,CONCATENATE("年初",D15)) -> 年初应收补贴款 | G15: 预收款项 | H15: =H14+1 -> 65 | I15: 其他应付款 | J15: =IF(I15="",0,CONCATENATE("年初",I15)) -> 年初其他应付款 | L15: 退保金 | M15: 11 | N15: 递延收益 | O15: =IF(N15="",0,CONCATENATE("上年",N15)) -> 上年递延收益 | Q15: 回购业务资金净增加额 | R15: 11 | U15: 固定资产报废损失（收益以“－”号填列） | V15: =V14+1 -> 11 | W15: 处置固定资产、无形资产和其他长期资产的损失（减：收益） | Z15: D8 | AA15: =B15 -> 预付款项
B16: 应收保费 | C16: 12 | D16: 应收出口退税 | E16: =IF(D16="",0,CONCATENATE("年初",D16)) -> 年初应收出口退税 | G16: 卖出回购金融资产款 | H16: =H15+1 -> 66 | I16: 预提费用 | J16: =IF(I16="",0,CONCATENATE("年初",I16)) -> 年初预提费用 | L16: 赔付支出净额 | M16: 12 | N16: 代购代销收入 | O16: =IF(N16="",0,CONCATENATE("上年",N16)) -> 上年代购代销收入 | Q16: 收到的税费返还 | R16: 12 | U16: 公允价值变动损失（收益以“－”号填列） | V16: =V15+1 -> 12 | W16: 固定资产报废损失 | Z16: D43 | AA16: =B16 -> 应收保费
B17: 应收分保账款 | C17: 13 | D17: 存货 | E17: =IF(D17="",0,CONCATENATE("年初",D17)) -> 年初存货 | G17: 应付手续费及佣金 | H17: =H16+1 -> 67 | I17: 预计负债 | J17: =IF(I17="",0,CONCATENATE("年初",I17)) -> 年初预计负债 | L17: 提取保险合同准备金净额 | M17: 13 | N17: 其他 | O17: =IF(N17="",0,CONCATENATE("上年",N17)) -> 上年其他 | Q17: 收到的其他与经营活动有关的现金 | R17: 13 | U17: 财务费用（收益以“－”号填列） | V17: =V16+1 -> 13 | W17: 财务费用 | Z17: D44 | AA17: =B17 -> 应收分保账款
B18: 应收分保准备金 | C18: 14 | D18: 其中：原材料 | G18: 合同负债 | H18: =H17+1 -> 68 | I18: 一年内到期的长期负债 | J18: =IF(I18="",0,CONCATENATE("年初",I18)) -> 年初一年内到期的长期负债 | L18: 保单红利支出 | M18: 14 | O18: =IF(N18="",0,CONCATENATE("上年",N18)) -> 0 | R18: 14 | U18: 投资损失（收益以“－”号填列） | V18: =V17+1 -> 14 | Z18: D45 | AA18: =B18 -> 应收分保准备金
B19: 其他应收款 | C19: 15 | D19: 库存商品（产成品） | G19: 应付职工薪酬 | H19: =H18+1 -> 69 | I19: 其他流动负债 | J19: =IF(I19="",0,CONCATENATE("年初",I19)) -> 年初其他流动负债 | L19: 分保费用 | M19: 15 | N19: 其他业务利润 | O19: =IF(N19="",0,CONCATENATE("上年",N19)) -> 上年其他业务利润 | R19: 15 | U19: 递延所得税资产减少（增加以“－”号填列） | V19: =V18+1 -> 15 | Z19: D9 | AA19: =B19 -> 其他应收款
B20: 其中：应收利息 | C20: 16 | D20: 待摊费用 | E20: =IF(D20="",0,CONCATENATE("年初",D20)) -> 年初待摊费用 | G20: 应交税费 | H20: =H19+1 -> 70 | L20: 其他业务成本 | M20: 16 | N20: 营业费用 | O20: =IF(N20="",0,CONCATENATE("上年",N20)) -> 上年营业费用 | Q20: 经营活动现金流入小计 | R20: 16 | U20: 递延所得税负债增加（减少以“－”号填列） | V20: =V19+1 -> 16 | W20: 投资损失（减：收益） | AA20: =B20 -> 其中：应收利息
B21: 应收股利 | C21: 17 | D21: 待处理流动资产净损失 | E21: =IF(D21="",0,CONCATENATE("年初",D21)) -> 年初待处理流动资产净损失 | G21: 其他应付款 | H21: =H20+1 -> 71 | J21: =IF(I21="",0,CONCATENATE("年初",I21)) -> 0 | L21: 税金及附加 | M21: 17 | N21: 管理费用 | O21: =IF(N21="",0,CONCATENATE("上年",N21)) -> 上年管理费用 | Q21: 购买商品、接受劳务支付的现金 | R21: 17 | S21: 收回投资所收到的现金 | U21: 存货的减少（增加以“－”号填列） | V21: =V20+1 -> 17 | W21: 递延税款贷项（减：借项） | AA21: =B21 -> 应收股利
B22: 买入返售金融资产 | C22: 18 | D22: 一年内到期的长期债权投资 | E22: =IF(D22="",0,CONCATENATE("年初",D22)) -> 年初一年内到期的长期债权投资 | G22: 其中：应付利息 | H22: =H21+1 -> 72 | J22: =IF(I22="",0,CONCATENATE("年初",I22)) -> 0 | L22: 销售费用 | M22: 18 | N22: 财务费用 | O22: =IF(N22="",0,CONCATENATE("上年",N22)) -> 上年财务费用 | Q22: 客户贷款及垫款净增加额 | R22: 18 | U22: 经营性应收项目的减少（增加以“－”号填列） | V22: =V21+1 -> 18 | W22: 存货的减少（减：增加） | Z22: D46 | AA22: =B22 -> 买入返售金融资产
B23: 存货 | C23: 19 | D23: 其他流动资产 | E23: =IF(D23="",0,CONCATENATE("年初",D23)) -> 年初其他流动资产 | G23: 应付股利 | H23: =H22+1 -> 73 | J23: =IF(I23="",0,CONCATENATE("年初",I23)) -> 0 | L23: 管理费用 | M23: 19 | Q23: 存放中央银行和同业款项净增加额 | R23: 19 | S23: 取得投资收益所收到的现金 | U23: 经营性应付项目的增加（减少以“－”号填列） | V23: =V22+1 -> 19 | W23: 经营性应收项目的减少（减：增加） | Z23: D10 | AA23: =B23 -> 存货
B24: 合同资产 | C24: 20 | E24: =IF(D24="",0,CONCATENATE("年初",D24)) -> 0 | G24: 应付分保账款 | H24: =H23+1 -> 74 | J24: =IF(I24="",0,CONCATENATE("年初",I24)) -> 0 | L24: 研发费用 | M24: 20 | Q24: 支付原保险合同赔付款项的现金 | R24: 20 | S24: 处置固定资产、无形资产和其他长期资产所收回的现金净额 | U24: 其他 | V24: =V23+1 -> 20 | W24: 经营性应付项目的增加（减：减少） | Z24: D11 | AA24: =B24 -> 合同资产
B25: 持有待售资产 | C25: 21 | E25: =IF(D25="",0,CONCATENATE("年初",D25)) -> 0 | G25: 保险合同准备金 | H25: =H24+1 -> 75 | I25: 长期借款 | J25: =IF(I25="",0,CONCATENATE("年初",I25)) -> 年初长期借款 | L25: 财务费用 | M25: 21 | O25: =IF(N25="",0,CONCATENATE("上年",N25)) -> 0 | Q25: 支付利息、手续费及佣金的现金 | R25: 21 | S25: 收到的其他与投资活动有关的现金 | V25: =V24+1 -> 21 | W25: 其他 | Z25: D12 | AA25: =B25 -> 持有待售资产
B26: 一年内到期的非流动资产 | C26: 22 | E26: =IF(D26="",0,CONCATENATE("年初",D26)) -> 0 | G26: 代理买卖证券款 | H26: =H25+1 -> 76 | I26: 应付债券 | J26: =IF(I26="",0,CONCATENATE("年初",I26)) -> 年初应付债券 | L26: 其中：利息费用 | M26: 22 | N26: 其他 | O26: =IF(N26="",0,CONCATENATE("上年",N26)) -> 上年其他 | Q26: 支付保单红利的现金 | R26: 22 | U26: 经营活动产生的现金流量净额 | V26: =V25+1 -> 22 | Z26: D13 | AA26: =B26 -> 一年内到期的非流动资产
B27: 其他流动资产 | C27: 23 | E27: =IF(D27="",0,CONCATENATE("年初",D27)) -> 0 | G27: 代理承销证券款 | H27: =H26+1 -> 77 | I27: 长期应付款 | J27: =IF(I27="",0,CONCATENATE("年初",I27)) -> 年初长期应付款 | L27: 利息收入 | M27: 23 | O27: =IF(N27="",0,CONCATENATE("上年",N27)) -> 0 | Q27: 支付给职工以及为职工支付的现金 | R27: 23 | V27: =V26+1 -> 23 | Z27: D14 | AA27: =B27 -> 其他流动资产
C28: 24 | E28: =IF(D28="",0,CONCATENATE("年初",D28)) -> 0 | G28: 持有待售负债 | H28: =H27+1 -> 78 | I28: 专项应付款 | J28: =IF(I28="",0,CONCATENATE("年初",I28)) -> 年初专项应付款 | L28: 加：其他收益 | M28: 24 | N28: 投资收益 | O28: =IF(N28="",0,CONCATENATE("上年",N28)) -> 上年投资收益 | Q28: 支付各项税费 | R28: 24 | S28: 购置固定资产、无形资产和其他长期资产所支付的现金 | U28: 2、不涉及现金收支的投资和筹资活动： | V28: =V27+1 -> 24 | Z28: D15 | AA28: =B28 -> 0
C29: 25 | D29: 长期股权投资 | E29: =IF(D29="",0,CONCATENATE("年初",D29)) -> 年初长期股权投资 | G29: 一年内到期的非流动负债 | H29: =H28+1 -> 79 | I29: 其他长期负债 | J29: =IF(I29="",0,CONCATENATE("年初",I29)) -> 年初其他长期负债 | L29: 投资收益（损失以“－”号填列） | M29: 25 | N29: 期货收益 | Q29: 支付的其他与经营活动有关的现金 | R29: 25 | S29: 投资所支付的现金 | U29: 债务转为资本 | V29: =V28+1 -> 25 | Z29: D16 | AA29: =B29 -> 0
B30: 流动资产合计 | C30: 26 | D30: 长期债权投资 | E30: =IF(D30="",0,CONCATENATE("年初",D30)) -> 年初长期债权投资 | G30: 其他流动负债 | H30: =H29+1 -> 80 | I30: 其中：特准储备资金 | L30: 其中：对联营企业和合营企业的投资收益 | M30: 26 | N30: 补贴收入 | R30: 26 | U30: 一年内到期的可转换公司债券 | V30: =V29+1 -> 26 | AA30: =B30 -> 流动资产合计
B31: 非流动资产: | C31: 27 | D31: 合并价差 | E31: =IF(D31="",0,CONCATENATE("年初",D31)) -> 年初合并价差 | G31: 流动负债合计 | H31: =H30+1 -> 81 | L31: 以摊余成本计量的金融资产终止确认收益（损失以“-”号填列） | M31: 27 | Q31: 经营活动现金流出小计 | R31: 27 | S31: 支付的其他与投资活动有关的现金 | U31: 融资租入固定资产 | V31: =V30+1 -> 27 | W31: 债务转为资本 | AA31: =B31 -> 非流动资产:
B32: 发放贷款及垫款 | C32: 28 | G32: 非流动负债: | H32: =H31+1 -> 82 | J32: =IF(I32="",0,CONCATENATE("年初",I32)) -> 0 | L32: 净敞口套期收益（损失以“-”号填列） | M32: 28 | N32: 营业外收入 | O32: =IF(N32="",0,CONCATENATE("上年",N32)) -> 上年营业外收入 | Q32: 经营活动产生的现金流量净额 | R32: 28 | U32: 其他 | V32: =V31+1 -> 28 | W32: 一年内到期的可转换公司债券 | Z32: D47 | AA32: =B32 -> 发放贷款及垫款
B33: 债权投资 | C33: 29 | G33: 长期借款 | H33: =H32+1 -> 83 | J33: =IF(I33="",0,CONCATENATE("年初",I33)) -> 0 | L33: 公允价值变动收益（损失以“－”号填列） | M33: 29 | Q33: 二、投资活动产生的现金流量 | R33: 29 | V33: =V32+1 -> 29 | W33: 融资租入固定资产 | Z33: D17 | AA33: =B33 -> 债权投资
B34: 可供出售金融资产 | C34: 30 | E34: =IF(D34="",0,CONCATENATE("年初",D34)) -> 0 | G34: 应付债券 | H34: =H33+1 -> 84 | J34: =IF(I34="",0,CONCATENATE("年初",I34)) -> 0 | L34: 信用减值损失(损失以“-”号填列） | M34: 30 | Q34: 收回投资所收到的现金 | R34: 30 | V34: =V33+1 -> 30 | W34: 其他 | Z34: D18 | AA34: =B34 -> 可供出售金融资产
B35: 其他债权投资 | C35: 31 | E35: =IF(D35="",0,CONCATENATE("年初",D35)) -> 0 | G35: 其中：优先股 | H35: =H34+1 -> 85 | J35: =IF(I35="",0,CONCATENATE("年初",I35)) -> 0 | L35: 资产减值损失(损失以“-”号填列） | M35: 31 | Q35: 取得投资收益所收到的现金 | R35: 31 | U35: 3、现金及现金等价物净变动情况： | V35: =V34+1 -> 31 | Z35: D19 | AA35: =B35 -> 其他债权投资
B36: 持有至到期投资 | C36: 32 | E36: =IF(D36="",0,CONCATENATE("年初",D36)) -> 0 | G36: 永续债 | H36: =H35+1 -> 86 | I36: 递延税款贷项 | J36: =IF(I36="",0,CONCATENATE("年初",I36)) -> 年初递延税款贷项 | L36: 资产处置收益(损失以“-”号填列） | M36: 32 | Q36: 处置固定资产、无形资产和其他长期资产而收到的现金净额 | R36: 32 | S36: 吸收投资所收到的现金 | U36: 现金的期末余额 | V36: =V35+1 -> 32 | Z36: D20 | AA36: =B36 -> 持有至到期投资
B37: 长期应收款 | C37: 33 | D37: 固定资产 | E37: =IF(D37="",0,CONCATENATE("年初",D37)) -> 年初固定资产 | G37: 租赁负债 | H37: =H36+1 -> 87 | J37: =IF(I37="",0,CONCATENATE("年初",I37)) -> 0 | L37: 二、营业利润（亏损以“－”号填列） | M37: 33 | Q37: 处置子公司及其他营业单位收到的现金净额 | R37: 33 | S37: 取得借款所收到的现金 | U37: 减：现金的期初余额 | V37: =V36+1 -> 33 | W37: 现金的期末余额 | Z37: D21 | AA37: =B37 -> 长期应收款
B38: 设定受益计划净资产 | C38: 34 | D38: 累计折旧 | E38: =IF(D38="",0,CONCATENATE("年初",D38)) -> 年初累计折旧 | G38: 长期应付款 | H38: =H37+1 -> 88 | J38: =IF(I38="",0,CONCATENATE("年初",I38)) -> 0 | L38: 加：营业外收入 | M38: 34 | Q38: 收到其他与投资活动有关的现金 | R38: 34 | S38: 收到的其他与筹资活动有关的现金 | U38: 加：现金等价物的期末余额 | V38: =V37+1 -> 34 | W38: 现金的期初余额 | Z38: D22 | AA38: =B38 -> 设定受益计划净资产
B39: 长期股权投资 | C39: 35 | E39: =IF(D39="",0,CONCATENATE("年初",D39)) -> 0 | G39: 长期应付职工薪酬 | H39: =H38+1 -> 89 | J39: =IF(I39="",0,CONCATENATE("年初",I39)) -> 0 | L39: 减：营业外支出 | M39: 35 | O39: =IF(N39="",0,CONCATENATE("上年",N39)) -> 0 | R39: 35 | U39: 减：现金等价物的期初余额 | V39: =V38+1 -> 35 | W39: 现金等价物的期末余额 | Z39: D23 | AA39: =B39 -> 长期股权投资
B40: 其他权益工具投资 | C40: 36 | D40: 固定资产减值准备 | E40: =IF(D40="",0,CONCATENATE("年初",D40)) -> 年初固定资产减值准备 | G40: 预计负债 | H40: =H39+1 -> 90 | I40: 少数股东权益 | J40: =IF(I40="",0,CONCATENATE("年初",I40)) -> 年初少数股东权益 | L40: 三、利润总额（亏损总额以“－”号填列） | M40: 36 | N40: 营业外支出 | O40: =IF(N40="",0,CONCATENATE("上年",N40)) -> 上年营业外支出 | Q40: 投资活动现金流入小计 | R40: 36 | V40: =V39+1 -> 36 | W40: 现金等价物的期初余额 | Z40: D24 | AA40: =B40 -> 其他权益工具投资
...

Sheet 年初BS审定
A1: 年初资产负债表（审定数）
A2: =CONCATENATE("客户名称：",说明!E23) -> 客户名称：
A3: =CONCATENATE("会计时点：",TEXT(说明!E31+1,"yyyy.mm.dd")) -> 会计时点：2019.01.01
X4: 1 | Y4: 2 | Z4: 3 | AA4: 4 | AB4: 5 | AC4: 6 | AD4: 7 | AE4: 8 | AF4: 9 | AG4: 10 | AI4: XX
A5: =报表格式!B4 -> 报表项目 | B5: 合并审定数 | C5: 合并报表调整 | D5: 合并抵销 | E5: 合并汇总 | F5: 母公司审定数 | G5: 母公司报表调整 | H5: 母公司账项调整 | I5: 母公司汇总抵销 | J5: 母公司汇总 | K5: 母公司本部 | L5: 1分公司 | M5: 2分公司 | N5: 3分公司 | O5: 4分公司 | P5: 5分公司 | Q5: 6分公司 | R5: 7分公司 | S5: 8分公司 | T5: 9分公司 | U5: 10分公司 | W5: XX分公司 | X5: 子公司1 | Y5: 子公司2 | Z5: 子公司3 | AA5: 子公司4 | AB5: 子公司5 | AC5: 子公司6 | AD5: 子公司7 | AE5: 子公司8 | AF5: 子公司9 | AG5: 子公司10 | AI5: 子公司XX
A6: =报表格式!B5 -> 流动资产：
A7: =报表格式!B6 -> 货币资金 | B7: =SUM(C7:E7) -> 0 | E7: =SUM(F7,X7:AI7) -> 0 | F7: =SUM(G7:J7) -> 0 | J7: =SUM(K7:W7) -> 0
A8: =报表格式!B7 -> 结算备付金 | B8: =SUM(C8:E8) -> 0 | E8: =SUM(F8,X8:AI8) -> 0 | F8: =SUM(G8:J8) -> 0 | J8: =SUM(K8:W8) -> 0
A9: =报表格式!B8 -> 拆出资金 | B9: =SUM(C9:E9) -> 0 | E9: =SUM(F9,X9:AI9) -> 0 | F9: =SUM(G9:J9) -> 0 | J9: =SUM(K9:W9) -> 0
A10: =报表格式!B9 -> 交易性金融资产 | B10: =SUM(C10:E10) -> 0 | E10: =SUM(F10,X10:AI10) -> 0 | F10: =SUM(G10:J10) -> 0 | J10: =SUM(K10:W10) -> 0
A11: =报表格式!B10 -> 以公允价值计量且其变动计入当期损益的金融资产 | B11: =SUM(C11:E11) -> 0 | E11: =SUM(F11,X11:AI11) -> 0 | F11: =SUM(G11:J11) -> 0 | J11: =SUM(K11:W11) -> 0
A12: =报表格式!B11 -> 衍生金融资产 | B12: =SUM(C12:E12) -> 0 | E12: =SUM(F12,X12:AI12) -> 0 | F12: =SUM(G12:J12) -> 0 | J12: =SUM(K12:W12) -> 0
A13: =报表格式!B12 -> 应收票据 | B13: =SUM(C13:E13) -> 0 | E13: =SUM(F13,X13:AI13) -> 0 | F13: =SUM(G13:J13) -> 0 | J13: =SUM(K13:W13) -> 0
A14: =报表格式!B13 -> 应收账款 | B14: =SUM(C14:E14) -> 0 | E14: =SUM(F14,X14:AI14) -> 0 | F14: =SUM(G14:J14) -> 0 | J14: =SUM(K14:W14) -> 0
A15: =报表格式!B14 -> 应收款项融资 | B15: =SUM(C15:E15) -> 0 | E15: =SUM(F15,X15:AI15) -> 0 | F15: =SUM(G15:J15) -> 0 | J15: =SUM(K15:W15) -> 0
A16: =报表格式!B15 -> 预付款项 | B16: =SUM(C16:E16) -> 0 | E16: =SUM(F16,X16:AI16) -> 0 | F16: =SUM(G16:J16) -> 0 | J16: =SUM(K16:W16) -> 0
A17: =报表格式!B16 -> 应收保费 | B17: =SUM(C17:E17) -> 0 | E17: =SUM(F17,X17:AI17) -> 0 | F17: =SUM(G17:J17) -> 0 | J17: =SUM(K17:W17) -> 0
A18: =报表格式!B17 -> 应收分保账款 | B18: =SUM(C18:E18) -> 0 | E18: =SUM(F18,X18:AI18) -> 0 | F18: =SUM(G18:J18) -> 0 | J18: =SUM(K18:W18) -> 0
... A30: =报表格式!B29 -> 0 | B30: =SUM(C30:E30) -> 0 | E30: =SUM(F30,X30:AI30) -> 0 | F30: =SUM(G30:J30) -> 0 | J30: =SUM(K30:W30) -> 0
A31: =报表格式!B30 -> 流动资产合计 | B31: =SUM(C31:E31) -> 0 | C31: =SUM(C7:C30)-C21-C22 -> 0 | D31: =SUM(D7:D30)-D21-D22 -> 0 | E31: =SUM(F31,X31:AI31) -> 0 | F31: =SUM(G31:J31) -> 0 | G31: =SUM(G7:G30)-G21-G22 -> 0 | H31: =SUM(H7:H30)-H21-H22 -> 0 | I31: =SUM(I7:I30)-I21-I22 -> 0 | J31: =SUM(K31:W31) -> 0 | K31: =SUM(K7:K30)-K21-K22 -> 0 | L31: =SUM(L7:L30)-L21-L22 -> 0 | M31: =SUM(M7:M30)-M21-M22 -> 0 | N31: =SUM(N7:N30)-N21-N22 -> 0 | O31: =SUM(O7:O30)-O21-O22 -> 0 | P31: =SUM(P7:P30)-P21-P22 -> 0 | Q31: =SUM(Q7:Q30)-Q21-Q22 -> 0 | R31: =SUM(R7:R30)-R21-R22 -> 0 | ... AI31: =SUM(AI7:AI30)-AI21-AI22 -> 0
A32: =报表格式!B31 -> 非流动资产:
A33: =报表格式!B32 -> 发放贷款及垫款 | B33: =SUM(C33:E33) -> 0 | E33: =SUM(F33,X33:AI33) -> 0 | F33: =SUM(G33:J33) -> 0 | J33: =SUM(K33:W33) -> 0
A34: =报表格式!B33 -> 债权投资 | B34: =SUM(C34:E34) -> 0 | E34: =SUM(F34,X34:AI34) -> 0 | F34: =SUM(G34:J34) -> 0 | J34: =SUM(K34:W34) -> 0
A35: =报表格式!B34 -> 可供出售金融资产 | B35: =SUM(C35:E35) -> 0 | E35: =SUM(F35,X35:AI35) -> 0 | F35: =SUM(G35:J35) -> 0 | J35: =SUM(K35:W35) -> 0
A36: =报表格式!B35 -> 其他债权投资 | B36: =SUM(C36:E36) -> 0 | E36: =SUM(F36,X36:AI36) -> 0 | F36: =SUM(G36:J36) -> 0 | J36: =SUM(K36:W36) -> 0
A37: =报表格式!B36 -> 持有至到期投资 | B37: =SUM(C37:E37) -> 0 | E37: =SUM(F37,X37:AI37) -> 0 | F37: =SUM(G37:J37) -> 0 | J37: =SUM(K37:W37) -> 0
A38: =报表格式!B37 -> 长期应收款 | B38: =SUM(C38:E38) -> 0 | E38: =SUM(F38,X38:AI38) -> 0 | F38: =SUM(G38:J38) -> 0 | J38: =SUM(K38:W38) -> 0
A39: =报表格式!B38 -> 设定受益计划净资产 | B39: =SUM(C39:E39) -> 0 | E39: =SUM(F39,X39:AI39) -> 0 | F39: =SUM(G39:J39) -> 0 | J39: =SUM(K39:W39) -> 0
A40: =报表格式!B39 -> 长期股权投资 | B40: =SUM(C40:E40) -> 0 | E40: =SUM(F40,X40:AI40) -> 0 | F40: =SUM(G40:J40) -> 0 | J40: =SUM(K40:W40) -> 0
A41: =报表格式!B40 -> 其他权益工具投资 | B41: =SUM(C41:E41) -> 0 | E41: =SUM(F41,X41:AI41) -> 0 | F41: =SUM(G41:J41) -> 0 | J41: =SUM(K41:W41) -> 0
A42: =报表格式!B41 -> 其他非流动金融资产 | B42: =SUM(C42:E42) -> 0 | E42: =SUM(F42,X42:AI42) -> 0 | F42: =SUM(G42:J42) -> 0 | J42: =SUM(K42:W42) -> 0
A43: =报表格式!B42 -> 投资性房地产 | B43: =SUM(C43:E43) -> 0 | E43: =SUM(F43,X43:AI43) -> 0 | F43: =SUM(G43:J43) -> 0 | J43: =SUM(K43:W43) -> 0
A44: =报表格式!B43 -> 固定资产 | B44: =SUM(C44:E44) -> 0 | E44: =SUM(F44,X44:AI44) -> 0 | F44: =SUM(G44:J44) -> 0 | J44: =SUM(K44:W44) -> 0
... A57: =报表格式!B56 -> 0 | B57: =SUM(C57:E57) -> 0 | E57: =SUM(F57,X57:AI57) -> 0 | F57: =SUM(G57:J57) -> 0 | J57: =SUM(K57:W57) -> 0
A58: =报表格式!B57 -> 非流动资产合计 | B58: =SUM(C58:E58) -> 0 | C58: =SUM(C33:C57) -> 0 | D58: =SUM(D33:D57) -> 0 | E58: =SUM(F58,X58:AI58) -> 0 | F58: =SUM(F33:F57) -> 0 | G58: =SUM(G33:G57) -> 0 | H58: =SUM(H33:H57) -> 0 | I58: =SUM(I33:I57) -> 0 | J58: =SUM(J33:J57) -> 0 | K58: =SUM(K33:K57) -> 0 | L58: =SUM(L33:L57) -> 0 | M58: =SUM(M33:M57) -> 0 | ... AI58: =SUM(AI33:AI57) -> 0
A59: =报表格式!B58 -> 资 产 总 计 | B59: =SUM(C59:E59) -> 0 | C59: =SUM(C31,C58) -> 0 | D59: =SUM(D31,D58) -> 0 | E59: =SUM(E31,E58) -> 0 | F59: =SUM(F31,F58) -> 0 | G59: =SUM(G31,G58) -> 0 | H59: =SUM(H31,H58) -> 0 | I59: =SUM(I31,I58) -> 0 | J59: =SUM(J31,J58) -> 0 | ... AI59: =SUM(AI31,AI58) -> 0
J60: =SUM(K60:W60) -> 0
A61: =报表格式!G5 -> 流动负债：
A62: =报表格式!G6 -> 短期借款 | B62: =SUM(C62:E62) -> 0 | E62: =SUM(F62,X62:AI62) -> 0 | F62: =SUM(G62:J62) -> 0 | J62: =SUM(K62:W62) -> 0
A63: =报表格式!G7 -> 向中央银行借款 | B63: =SUM(C63:E63) -> 0 | E63: =SUM(F63,X63:AI63) -> 0 | F63: =SUM(G63:J63) -> 0 | J63: =SUM(K63:W63) -> 0
...

Sheet 上年PL审定
A1: 上年利润及利润分配表（审定数）
A2: =CONCATENATE("客户名称：",说明!E23) -> 客户名称：
A3: =CONCATENATE("会计期间：",说明!E29) -> 会计期间：2018年度
X4: 1 | Y4: 2 | Z4: 3 | AA4: 4 | AB4: 5 | AC4: 6 | AD4: 7 | AE4: 8 | AF4: 9 | AG4: 10 | AI4: XX
A5: =报表格式!L4 -> 报表项目 | B5: 合并审定数 | C5: 合并报表调整 | D5: 合并抵销 | E5: 合并汇总 | F5: 母公司审定数 | G5: 母公司报表调整 | H5: 母公司账项调整 | I5: 母公司汇总抵销 | J5: 母公司汇总 | K5: 母公司本部 | L5: 1分公司 | M5: 2分公司 | N5: 3分公司 | O5: 4分公司 | P5: 5分公司 | Q5: 6分公司 | R5: 7分公司 | S5: 8分公司 | T5: 9分公司 | U5: 10分公司 | W5: XX分公司 | X5: 子公司1 | Y5: 子公司2 | Z5: 子公司3 | AA5: 子公司4 | AB5: 子公司5 | AC5: 子公司6 | AD5: 子公司7 | AE5: 子公司8 | AF5: 子公司9 | AG5: 子公司10 | AI5: 子公司XX
A6: =报表格式!L5 -> 一、营业收入 | B6: =SUM(C6:E6) -> 0 | E6: =SUM(F6,X6:AI6) -> 0 | F6: =SUM(G6:J6) -> 0 | J6: =SUM(K6:W6) -> 0
A7: =报表格式!L6 -> 其中：主营业务收入 | B7: =SUM(C7:E7) -> 0 | E7: =SUM(F7,X7:AI7) -> 0 | F7: =SUM(G7:J7) -> 0 | J7: =SUM(K7:W7) -> 0
A8: =报表格式!L7 -> 利息收入 | B8: =SUM(C8:E8) -> 0 | E8: =SUM(F8,X8:AI8) -> 0 | F8: =SUM(G8:J8) -> 0 | J8: =SUM(K8:W8) -> 0
A9: =报表格式!L8 -> 已赚保费 | B9: =SUM(C9:E9) -> 0 | E9: =SUM(F9,X9:AI9) -> 0 | F9: =SUM(G9:J9) -> 0 | J9: =SUM(K9:W9) -> 0
A10: =报表格式!L9 -> 手续费及佣金收入 | B10: =SUM(C10:E10) -> 0 | E10: =SUM(F10,X10:AI10) -> 0 | F10: =SUM(G10:J10) -> 0 | J10: =SUM(K10:W10) -> 0
A11: =报表格式!L10 -> 其他业务收入 | B11: =SUM(C11:E11) -> 0 | E11: =SUM(F11,X11:AI11) -> 0 | F11: =SUM(G11:J11) -> 0 | J11: =SUM(K11:W11) -> 0
A12: =报表格式!L11 -> 减：营业成本 | B12: =SUM(C12:E12) -> 0 | E12: =SUM(F12,X12:AI12) -> 0 | F12: =SUM(G12:J12) -> 0 | J12: =SUM(K12:W12) -> 0
A13: =报表格式!L12 -> 其中：主营业务成本 | B13: =SUM(C13:E13) -> 0 | E13: =SUM(F13,X13:AI13) -> 0 | F13: =SUM(G13:J13) -> 0 | J13: =SUM(K13:W13) -> 0
A14: =报表格式!L13 -> 利息支出 | B14: =SUM(C14:E14) -> 0 | E14: =SUM(F14,X14:AI14) -> 0 | F14: =SUM(G14:J14) -> 0 | J14: =SUM(K14:W14) -> 0
A15: =报表格式!L14 -> 手续费及佣金支出 | B15: =SUM(C15:E15) -> 0 | E15: =SUM(F15,X15:AI15) -> 0 | F15: =SUM(G15:J15) -> 0 | J15: =SUM(K15:W15) -> 0
A16: =报表格式!L15 -> 退保金 | B16: =SUM(C16:E16) -> 0 | E16: =SUM(F16,X16:AI16) -> 0 | F16: =SUM(G16:J16) -> 0 | J16: =SUM(K16:W16) -> 0
A17: =报表格式!L16 -> 赔付支出净额 | B17: =SUM(C17:E17) -> 0 | E17: =SUM(F17,X17:AI17) -> 0 | F17: =SUM(G17:J17) -> 0 | J17: =SUM(K17:W17) -> 0
... A37: =报表格式!L36 -> 资产处置收益(损失以“-”号填列） | B37: =SUM(C37:E37) -> 0 | E37: =SUM(F37,X37:AI37) -> 0 | F37: =SUM(G37:J37) -> 0 | J37: =SUM(K37:W37) -> 0
A38: =报表格式!L37 -> 二、营业利润（亏损以“－”号填列） | B38: =SUM(C38:E38) -> 0 | C38: =SUM(C6)-SUM(C12,C22:C26)+SUM(C29,C30)+SUM(C33:C37) -> 0 | D38: =SUM(D6)-SUM(D12,D22:D26)+SUM(D29,D30)+SUM(D33:D37) -> 0 | E38: =SUM(F38,X38:AI38) -> 0 | F38: =SUM(F6)-SUM(F12,F22:F26)+SUM(F29,F30)+SUM(F33:F37) -> 0 | G38: =SUM(G6)-SUM(G12,G22:G26)+SUM(G29,G30)+SUM(G33:G37) -> 0 | H38: =SUM(H6)-SUM(H12,H22:H26)+SUM(H29,H30)+SUM(H33:H37) -> 0 | I38: =SUM(I6)-SUM(I12,I22:I26)+SUM(I29,I30)+SUM(I33:I37) -> 0 | J38: =SUM(J6)-SUM(J12,J22:J26)+SUM(J29,J30)+SUM(J33:J37) -> 0 | K38: =SUM(K6)-SUM(K12,K22:K26)+SUM(K29,K30)+SUM(K33:K37) -> 0 | L38: =SUM(L6)-SUM(L12,L22:L26)+SUM(L29,L30)+SUM(L33:L37) -> 0 | M38: =SUM(M6)-SUM(M12,M22:M26)+SUM(M29,M30)+SUM(M33:M37) -> 0 | ... AI38: =SUM(AI6)-SUM(AI12,AI22:AI26)+SUM(AI29,AI30)+SUM(AI33:AI37) -> 0
A39: =报表格式!L38 -> 加：营业外收入 | B39: =SUM(C39:E39) -> 0 | E39: =SUM(F39,X39:AI39) -> 0 | F39: =SUM(G39:J39) -> 0 | J39: =SUM(K39:W39) -> 0
A40: =报表格式!L39 -> 减：营业外支出 | B40: =SUM(C40:E40) -> 0 | E40: =SUM(F40,X40:AI40) -> 0 | F40: =SUM(G40:J40) -> 0 | J40: =SUM(K40:W40) -> 0
A41: =报表格式!L40 -> 三、利润总额（亏损总额以“－”号填列） | B41: =SUM(C41:E41) -> 0 | C41: =SUM(C38)+SUM(C39)-SUM(C40) -> 0 | D41: =SUM(D38)+SUM(D39)-SUM(D40) -> 0 | E41: =SUM(F41,X41:AI41) -> 0 | F41: =SUM(F38)+SUM(F39)-SUM(F40) -> 0 | G41: =SUM(G38)+SUM(G39)-SUM(G40) -> 0 | H41: =SUM(H38)+SUM(H39)-SUM(H40) -> 0 | I41: =SUM(I38)+SUM(I39)-SUM(I40) -> 0 | J41: =SUM(J38)+SUM(J39)-SUM(J40) -> 0 | K41: =SUM(K38)+SUM(K39)-SUM(K40) -> 0 | L41: =SUM(L38)+SUM(L39)-SUM(L40) -> 0 | M41: =SUM(M38)+SUM(M39)-SUM(M40) -> 0 | ... AI41: =SUM(AI38)+SUM(AI39)-SUM(AI40) -> 0
A42: =报表格式!L41 -> 减：所得税费用 | B42: =SUM(C42:E42) -> 0 | E42: =SUM(F42,X42:AI42) -> 0 | F42: =SUM(G42:J42) -> 0 | J42: =SUM(K42:W42) -> 0
A43: =报表格式!L42 -> 0 | B43: =SUM(C43:E43) -> 0 | E43: =SUM(F43,X43:AI43) -> 0 | F43: =SUM(G43:J43) -> 0 | J43: =SUM(K43:W43) -> 0
A44: =报表格式!L43 -> 四、净利润（净亏损以“－”号填列） | B44: =SUM(C44:E44) -> 0 | C44: =C41-C42-C43 -> 0 | D44: =D41-D42-D43 -> 0 | E44: =SUM(F44,X44:AI44) -> 0 | F44: =F41-F42-F43 -> 0 | G44: =G41-G42-G43 -> 0 | H44: =H41-H42-H43 -> 0 | I44: =I41-I42-I43 -> 0 | J44: =J41-J42-J43 -> 0 | K44: =K41-K42-K43 -> 0 | L44: =L41-L42-L43 -> 0 | M44: =M41-M42-M43 -> 0 | ... AI44: =AI41-AI42-AI43 -> 0
A45: =报表格式!L44 -> （一）按经营持续性分类 | E45: =SUM(F45,X45:AI45) -> 0
A46: =报表格式!L45 -> 其中：持续经营净利润（净亏损以“-”号填列） | B46: =SUM(C46:E46) -> 0 | E46: =SUM(F46,X46:AI46) -> 0 | F46: =SUM(G46:J46) -> 0 | J46: =SUM(K46:W46) -> 0
A47: =报表格式!L46 -> 终止经营净利润（净亏损以“-”号填列） | B47: =SUM(C47:E47) -> 0 | E47: =SUM(F47,X47:AI47) -> 0 | F47: =SUM(G47:J47) -> 0 | J47: =SUM(K47:W47) -> 0
A48: =报表格式!L47 -> （二）按所有权归属分类 | E48: =SUM(F48,X48:AI48) -> 0
A49: =报表格式!L48 -> 其中：归属于母公司股东的净利润（净亏损以“-”号填列） | B49: =SUM(C49:E49) -> 0 | C49: =C44-C50 -> 0 | D49: =D44-D50 -> 0 | E49: =SUM(F49,X49:AI49) -> 0 | F49: =SUM(G49:J49) -> 0 | G49: =G44-G50 -> 0 | H49: =H44-H50 -> 0 | I49: =I44-I50 -> 0 | J49: =SUM(K49:W49) -> 0 | K49: =K44-K50 -> 0 | L49: =L44-L50 -> 0 | M49: =M44-M50 -> 0 | N49: =N44-N50 -> 0 | O49: =O44-O50 -> 0 | P49: =P44-P50 -> 0 | Q49: =Q44-Q50 -> 0 | R49: =R44-R50 -> 0 | ... AI49: =AI44-AI50 -> 0
A50: =报表格式!L49 -> 少数股东损益（净亏损以“-”号填列） | B50: =SUM(C50:E50) -> 0 | E50: =SUM(F50,X50:AI50) -> 0 | F50: =SUM(G50:J50) -> 0 | J50: =SUM(K50:W50) -> 0
A51: =报表格式!L50 -> 五、其他综合收益的税后净额 | B51: =SUM(C51:E51) -> 0 | C51: =C52+C59 -> 0 | D51: =D52+D59 -> 0 | E51: =SUM(F51,X51:AI51) -> 0 | F51: =SUM(G51:J51) -> 0 | G51: =G52+G71 -> 0 | H51: =H52+H71 -> 0 | I51: =I52+I71 -> 0 | J51: =SUM(K51:W51) -> 0 | K51: =K52+K71 -> 0 | L51: =L52+L71 -> 0 | M51: =M52+M71 -> 0 | N51: =N52+N71 -> 0 | O51: =O52+O71 -> 0 | P51: =P52+P71 -> 0 | Q51: =Q52+Q71 -> 0 | R51: =R52+R71 -> 0 | ... AI51: =AI52+AI71 -> 0
A52: =报表格式!L51 -> 归属于母公司股东的其他综合收益的税后净额 | B52: =SUM(C52:E52) -> 0 | C52: =C53+C59 -> 0 | D52: =D53+D59 -> 0 | E52: =SUM(F52,X52:AI52) -> 0 | F52: =SUM(G52:J52) -> 0 | G52: =G53+G59 -> 0 | H52: =H53+H59 -> 0 | I52: =I53+I59 -> 0 | J52: =SUM(K52:W52) -> 0 | K52: =K53+K59 -> 0 | L52: =L53+L59 -> 0 | M52: =M53+M59 -> 0 | N52: =N53+N59 -> 0 | O52: =O53+O59 -> 0 | P52: =P53+P59 -> 0 | Q52: =Q53+Q59 -> 0 | R52: =R53+R59 -> 0 | ... AI52: =AI53+AI59 -> 0
A53: =报表格式!L52 -> （一）不能重分类进损益的其他综合收益 | B53: =SUM(C53:E53) -> 0 | C53: =SUM(C54:C58) -> 0 | D53: =SUM(D54:D58) -> 0 | E53: =SUM(F53,X53:AI53) -> 0 | F53: =SUM(G53:J53) -> 0 | G53: =SUM(G54:G58) -> 0 | H53: =SUM(H54:H58) -> 0 | I53: =SUM(I54:I58) -> 0 | J53: =SUM(K53:W53) -> 0 | K53: =SUM(K54:K58) -> 0 | L53: =SUM(L54:L58) -> 0 | M53: =SUM(M54:M58) -> 0 | N53: =SUM(N54:N58) -> 0 | O53: =SUM(O54:O58) -> 0 | P53: =SUM(P54:P58) -> 0 | Q53: =SUM(Q54:Q58) -> 0 | R53: =SUM(R54:R58) -> 0 | ... AI53: =SUM(AI54:AI58) -> 0
A54: =报表格式!L53 -> 1.重新计量设定受益计划变动额 | B54: =SUM(C54:E54) -> 0 | E54: =SUM(F54,X54:AI54) -> 0 | F54: =SUM(G54:J54) -> 0 | J54: =SUM(K54:W54) -> 0
A55: =报表格式!L54 -> 2.权益法下不能转损益的其他综合收益 | B55: =SUM(C55:E55) -> 0 | E55: =SUM(F55,X55:AI55) -> 0 | F55: =SUM(G55:J55) -> 0 | J55: =SUM(K55:W55) -> 0
A56: =报表格式!L55 -> 3.其他权益工具投资公允价值变动 | B56: =SUM(C56:E56) -> 0 | E56: =SUM(F56,X56:AI56) -> 0 | F56: =SUM(G56:J56) -> 0 | J56: =SUM(K56:W56) -> 0
A57: =报表格式!L56 -> 4.企业自身信用风险公允价值变动 | B57: =SUM(C57:E57) -> 0 | E57: =SUM(F57,X57:AI57) -> 0 | F57: =SUM(G57:J57) -> 0 | J57: =SUM(K57:W57) -> 0
A58: =报表格式!L57 -> 5.其他 | B58: =SUM(C58:E58) -> 0 | E58: =SUM(F58,X58:AI58) -> 0 | F58: =SUM(G58:J58) -> 0 | J58: =SUM(K58:W58) -> 0
A59: =报表格式!L58 -> （二）将重分类进损益的其他综合收益 | B59: =SUM(C59:E59) -> 0 | C59: =SUM(C60:C70) -> 0 | D59: =SUM(D60:D70) -> 0 | E59: =SUM(F59,X59:AI59) -> 0 | F59: =SUM(G59:J59) -> 0 | G59: =SUM(G60:G70) -> 0 | H59: =SUM(H60:H70) -> 0 | I59: =SUM(I60:I70) -> 0 | J59: =SUM(K59:W59) -> 0 | K59: =SUM(K60:K70) -> 0 | L59: =SUM(L60:L70) -> 0 | M59: =SUM(M60:M70) -> 0 | N59: =SUM(N60:N70) -> 0 | O59: =SUM(O60:O70) -> 0 | P59: =SUM(P60:P70) -> 0 | Q59: =SUM(Q60:Q70) -> 0 | R59: =SUM(R60:R70) -> 0 | ... AI59: =SUM(AI60:AI70) -> 0
...

Sheet 期初核对BS
A1: =IF(AND(ABS(F60)<0.005,ABS(F119)<0.005),"期初合并金额核对一致","期初合并金额核对不符！") -> 期初合并金额核对一致 | G1: =IF(AND(ABS(J60)<0.005,ABS(J119)<0.005),"期初母公司金额核对一致","期初母公司金额核对不符！") -> 期初母公司金额核对一致
A2: 资产负债表期初核对
C3: =说明!$E$32 -> 43830
A4: =IF(报表格式!G58=""," 对不起，请到参数表中确定报表类型！",CONCATENATE(" 客户名称：",说明!E23)) -> 客户名称： | H4: =CONCATENATE("金额单位：",说明!$E$33) -> 金额单位：人民币元
A5: =IF(E60<=0.005,"资 产","资产明细核对不符！") -> 资 产 | B5: 行次 | C5: 合并数 | G5: 母公司数
C6: 本年期初数 ① | D6: 上期审定数 ② | E6: 辅助列 | F6: 差异 ①-② | G6: 本年期初数 ① | H6: 上期审定数 ② | I6: 辅助列 | J6: 差异 ①-②
A7: =报表格式!B5 -> 流动资产： | B7: 1
A8: =报表格式!B6 -> 货币资金 | B8: =B7+1 -> 2 | D8: =年初BS审定!B7 -> 0 | E8: =ABS(F8) -> 0 | F8: =C8-D8 -> 0 | H8: =年初BS审定!F7 -> 0 | I8: =ABS(J8) -> 0 | J8: =G8-H8 -> 0
A9: =报表格式!B7 -> 结算备付金 | B9: =B8+1 -> 3 | D9: =年初BS审定!B8 -> 0 | E9: =ABS(F9) -> 0 | F9: =C9-D9 -> 0 | H9: =年初BS审定!F8 -> 0 | I9: =ABS(J9) -> 0 | J9: =G9-H9 -> 0
A10: =报表格式!B8 -> 拆出资金 | B10: =B9+1 -> 4 | D10: =年初BS审定!B9 -> 0 | E10: =ABS(F10) -> 0 | F10: =C10-D10 -> 0 | H10: =年初BS审定!F9 -> 0 | I10: =ABS(J10) -> 0 | J10: =G10-H10 -> 0
A11: =报表格式!B9 -> 交易性金融资产 | B11: =B10+1 -> 5 | D11: =年初BS审定!B10 -> 0 | E11: =ABS(F11) -> 0 | F11: =C11-D11 -> 0 | H11: =年初BS审定!F10 -> 0 | I11: =ABS(J11) -> 0 | J11: =G11-H11 -> 0
A12: =报表格式!B10 -> 以公允价值计量且其变动计入当期损益的金融资产 | B12: =B11+1 -> 6 | D12: =年初BS审定!B11 -> 0 | E12: =ABS(F12) -> 0 | F12: =C12-D12 -> 0 | H12: =年初BS审定!F11 -> 0 | I12: =ABS(J12) -> 0 | J12: =G12-H12 -> 0
A13: =报表格式!B11 -> 衍生金融资产 | B13: =B12+1 -> 7 | D13: =年初BS审定!B12 -> 0 | E13: =ABS(F13) -> 0 | F13: =C13-D13 -> 0 | H13: =年初BS审定!F12 -> 0 | I13: =ABS(J13) -> 0 | J13: =G13-H13 -> 0
A14: =报表格式!B12 -> 应收票据 | B14: =B13+1 -> 8 | D14: =年初BS审定!B13 -> 0 | E14: =ABS(F14) -> 0 | F14: =C14-D14 -> 0 | H14: =年初BS审定!F13 -> 0 | I14: =ABS(J14) -> 0 | J14: =G14-H14 -> 0
A15: =报表格式!B13 -> 应收账款 | B15: =B14+1 -> 9 | D15: =年初BS审定!B14 -> 0 | E15: =ABS(F15) -> 0 | F15: =C15-D15 -> 0 | H15: =年初BS审定!F14 -> 0 | I15: =ABS(J15) -> 0 | J15: =G15-H15 -> 0
A16: =报表格式!B14 -> 应收款项融资 | B16: =B15+1 -> 10 | D16: =年初BS审定!B15 -> 0 | E16: =ABS(F16) -> 0 | F16: =C16-D16 -> 0 | H16: =年初BS审定!F15 -> 0 | I16: =ABS(J16) -> 0 | J16: =G16-H16 -> 0
A17: =报表格式!B15 -> 预付款项 | B17: =B16+1 -> 11 | D17: =年初BS审定!B16 -> 0 | E17: =ABS(F17) -> 0 | F17: =C17-D17 -> 0 | H17: =年初BS审定!F16 -> 0 | I17: =ABS(J17) -> 0 | J17: =G17-H17 -> 0
A18: =报表格式!B16 -> 应收保费 | B18: =B17+1 -> 12 | D18: =年初BS审定!B17 -> 0 | E18: =ABS(F18) -> 0 | F18: =C18-D18 -> 0 | H18: =年初BS审定!F17 -> 0 | I18: =ABS(J18) -> 0 | J18: =G18-H18 -> 0
A19: =报表格式!B17 -> 应收分保账款 | B19: =B18+1 -> 13 | D19: =年初BS审定!B18 -> 0 | E19: =ABS(F19) -> 0 | F19: =C19-D19 -> 0 | H19: =年初BS审定!F18 -> 0 | I19: =ABS(J19) -> 0 | J19: =G19-H19 -> 0
... A31: =报表格式!B29 -> 0 | B31: =B30+1 -> 25 | D31: =年初BS审定!B30 -> 0 | E31: =ABS(F31) -> 0 | F31: =C31-D31 -> 0 | H31: =年初BS审定!F30 -> 0 | I31: =ABS(J31) -> 0 | J31: =G31-H31 -> 0
A32: =报表格式!B30 -> 流动资产合计 | B32: =B31+1 -> 26 | C32: =SUM(C8:C31)-C22-C23 -> 0 | D32: =SUM(D8:D31)-D22-D23 -> 0 | E32: =ABS(F32) -> 0 | F32: =C32-D32 -> 0 | G32: =SUM(G8:G31)-G22-G23 -> 0 | H32: =SUM(H8:H31)-H22-H23 -> 0 | I32: =ABS(J32) -> 0 | J32: =G32-H32 -> 0
A33: =报表格式!B31 -> 非流动资产: | B33: =B32+1 -> 27
A34: =报表格式!B32 -> 发放贷款及垫款 | B34: =B33+1 -> 28 | D34: =年初BS审定!B33 -> 0 | E34: =ABS(F34) -> 0 | F34: =C34-D34 -> 0 | H34: =年初BS审定!F33 -> 0 | I34: =ABS(J34) -> 0 | J34: =G34-H34 -> 0
A35: =报表格式!B33 -> 债权投资 | B35: =B34+1 -> 29 | D35: =年初BS审定!B34 -> 0 | E35: =ABS(F35) -> 0 | F35: =C35-D35 -> 0 | H35: =年初BS审定!F34 -> 0 | I35: =ABS(J35) -> 0 | J35: =G35-H35 -> 0
A36: =报表格式!B34 -> 可供出售金融资产 | B36: =B35+1 -> 30 | D36: =年初BS审定!B35 -> 0 | E36: =ABS(F36) -> 0 | F36: =C36-D36 -> 0 | H36: =年初BS审定!F35 -> 0 | I36: =ABS(J36) -> 0 | J36: =G36-H36 -> 0
A37: =报表格式!B35 -> 其他债权投资 | B37: =B36+1 -> 31 | D37: =年初BS审定!B36 -> 0 | E37: =ABS(F37) -> 0 | F37: =C37-D37 -> 0 | H37: =年初BS审定!F36 -> 0 | I37: =ABS(J37) -> 0 | J37: =G37-H37 -> 0
A38: =报表格式!B36 -> 持有至到期投资 | B38: =B37+1 -> 32 | D38: =年初BS审定!B37 -> 0 | E38: =ABS(F38) -> 0 | F38: =C38-D38 -> 0 | H38: =年初BS审定!F37 -> 0 | I38: =ABS(J38) -> 0 | J38: =G38-H38 -> 0
A39: =报表格式!B37 -> 长期应收款 | B39: =B38+1 -> 33 | D39: =年初BS审定!B38 -> 0 | E39: =ABS(F39) -> 0 | F39: =C39-D39 -> 0 | H39: =年初BS审定!F38 -> 0 | I39: =ABS(J39) -> 0 | J39: =G39-H39 -> 0
A40: =报表格式!B38 -> 设定受益计划净资产 | B40: =B39+1 -> 34 | D40: =年初BS审定!B39 -> 0 | E40: =ABS(F40) -> 0 | F40: =C40-D40 -> 0 | H40: =年初BS审定!F39 -> 0 | I40: =ABS(J40) -> 0 | J40: =G40-H40 -> 0
A41: =报表格式!B39 -> 长期股权投资 | B41: =B40+1 -> 35 | D41: =年初BS审定!B40 -> 0 | E41: =ABS(F41) -> 0 | F41: =C41-D41 -> 0 | H41: =年初BS审定!F40 -> 0 | I41: =ABS(J41) -> 0 | J41: =G41-H41 -> 0
A42: =报表格式!B40 -> 其他权益工具投资 | B42: =B41+1 -> 36 | D42: =年初BS审定!B41 -> 0 | E42: =ABS(F42) -> 0 | F42: =C42-D42 -> 0 | H42: =年初BS审定!F41 -> 0 | I42: =ABS(J42) -> 0 | J42: =G42-H42 -> 0
A43: =报表格式!B41 -> 其他非流动金融资产 | B43: =B42+1 -> 37 | D43: =年初BS审定!B42 -> 0 | E43: =ABS(F43) -> 0 | F43: =C43-D43 -> 0 | H43: =年初BS审定!F42 -> 0 | I43: =ABS(J43) -> 0 | J43: =G43-H43 -> 0
A44: =报表格式!B42 -> 投资性房地产 | B44: =B43+1 -> 38 | D44: =年初BS审定!B43 -> 0 | E44: =ABS(F44) -> 0 | F44: =C44-D44 -> 0 | H44: =年初BS审定!F43 -> 0 | I44: =ABS(J44) -> 0 | J44: =G44-H44 -> 0
A45: =报表格式!B43 -> 固定资产 | B45: =B44+1 -> 39 | D45: =年初BS审定!B44 -> 0 | E45: =ABS(F45) -> 0 | F45: =C45-D45 -> 0 | H45: =年初BS审定!F44 -> 0 | I45: =ABS(J45) -> 0 | J45: =G45-H45 -> 0
... A58: =报表格式!B56 -> 0 | B58: =B57+1 -> 52 | D58: =年初BS审定!B57 -> 0 | E58: =ABS(F58) -> 0 | F58: =C58-D58 -> 0 | H58: =年初BS审定!F57 -> 0 | I58: =ABS(J58) -> 0 | J58: =G58-H58 -> 0
A59: =报表格式!B57 -> 非流动资产合计 | B59: =B58+1 -> 53 | C59: =SUM(C35:C58) -> 0 | D59: =SUM(D34:D58) -> 0 | E59: =ABS(F59) -> 0 | F59: =C59-D59 -> 0 | G59: =SUM(G35:G58) -> 0 | H59: =SUM(H34:H58) -> 0 | I59: =ABS(J59) -> 0 | J59: =G59-H59 -> 0
A60: =报表格式!B58 -> 资 产 总 计 | B60: =B59+1 -> 54 | C60: =SUM(C32,C59) -> 0 | D60: =SUM(D32,D59) -> 0 | E60: =ABS(F60) -> 0 | F60: =C60-D60 -> 0 | G60: =SUM(G32,G59) -> 0 | H60: =SUM(H32,H59) -> 0 | I60: =ABS(J60) -> 0 | J60: =G60-H60 -> 0
A61: =IF(E119<=0.005,IF(说明!E28="一般企业（执行统一会计制度）","负债及所有者权益","负债及股东权益"),"负债明细核对不符！") -> 负债及股东权益 | B61: 行次 | C61: 合并数 | G61: 母公司数
C62: 本年期初数 ① | D62: 上期审定数 ② | E62: 辅助列 | F62: 差异 ①-② | G62: 本年期初数 ① | H62: 上期审定数 ② | I62: 辅助列 | J62: 差异 ①-②
A63: =报表格式!G5 -> 流动负债： | B63: =B60+1 -> 55
...

Sheet 期初核对PL
A1: =IF(AND(ABS(F72)<0.005,ABS(F89)<0.005),"期初合并金额核对一致","期初合并金额核对不符！") -> 期初合并金额核对一致 | C1: =IF(AND(ABS(F161)<0.005,ABS(F178)<0.005),"期初母公司金额核对一致","期初母公司金额核对不符！") -> 期初母公司金额核对一致
A2: 利润及利润分配表期初核对－合并
A4: =IF(报表格式!G58=""," 对不起，请到参数表中确定报表类型！",CONCATENATE(" 客户名称：",说明!E23)) -> 客户名称： | B4: =说明!$E$30 -> 2019年度 | F4: =CONCATENATE("金额单位：",说明!$E$33) -> 金额单位：人民币元
A5: =IF(AND(E69<0.005,E70<0.005),"项 目","合并明细项目不符！") -> 项 目 | B5: 行次 | C5: 本年上期数 ① | D5: 上期审定数 ② | E5: 辅助列 | F5: 差异 ①-②
A6: =报表格式!L5 -> 一、营业收入 | B6: 1 | D6: =上年PL审定!B6 -> 0 | E6: =ABS(F6) -> 0 | F6: =C6-D6 -> 0
A7: =报表格式!L6 -> 其中：主营业务收入 | B7: 2 | D7: =上年PL审定!B7 -> 0 | E7: =ABS(F7) -> 0 | F7: =C7-D7 -> 0
A8: =报表格式!L7 -> 利息收入 | B8: 3 | D8: =上年PL审定!B8 -> 0 | E8: =ABS(F8) -> 0 | F8: =C8-D8 -> 0
A9: =报表格式!L8 -> 已赚保费 | B9: 4 | D9: =上年PL审定!B9 -> 0 | E9: =ABS(F9) -> 0 | F9: =C9-D9 -> 0
A10: =报表格式!L9 -> 手续费及佣金收入 | B10: 5 | D10: =上年PL审定!B10 -> 0 | E10: =ABS(F10) -> 0 | F10: =C10-D10 -> 0
A11: =报表格式!L10 -> 其他业务收入 | B11: 6 | D11: =上年PL审定!B11 -> 0 | E11: =ABS(F11) -> 0 | F11: =C11-D11 -> 0
A12: =报表格式!L11 -> 减：营业成本 | B12: 7 | D12: =上年PL审定!B12 -> 0 | E12: =ABS(F12) -> 0 | F12: =C12-D12 -> 0
A13: =报表格式!L12 -> 其中：主营业务成本 | B13: 8 | D13: =上年PL审定!B13 -> 0 | E13: =ABS(F13) -> 0 | F13: =C13-D13 -> 0
A14: =报表格式!L13 -> 利息支出 | B14: 9 | D14: =上年PL审定!B14 -> 0 | E14: =ABS(F14) -> 0 | F14: =C14-D14 -> 0
A15: =报表格式!L14 -> 手续费及佣金支出 | B15: 10 | D15: =上年PL审定!B15 -> 0 | E15: =ABS(F15) -> 0 | F15: =C15-D15 -> 0
A16: =报表格式!L15 -> 退保金 | B16: 11 | D16: =上年PL审定!B16 -> 0 | E16: =ABS(F16) -> 0 | F16: =C16-D16 -> 0
A17: =报表格式!L16 -> 赔付支出净额 | B17: 12 | D17: =上年PL审定!B17 -> 0 | E17: =ABS(F17) -> 0 | F17: =C17-D17 -> 0
... A37: =报表格式!L36 -> 资产处置收益(损失以“-”号填列） | B37: 32 | D37: =上年PL审定!B37 -> 0 | E37: =ABS(F37) -> 0 | F37: =C37-D37 -> 0
A38: =报表格式!L37 -> 二、营业利润（亏损以“－”号填列） | B38: 33 | C38: =SUM(C6)-SUM(C12,C22:C26)+SUM(C29:C30)+SUM(C33:C37) -> 0 | D38: =SUM(D6)-SUM(D12,D22:D26)+SUM(D29:D30)+SUM(D33:D37) -> 0 | E38: =SUM(E6)-SUM(E12,E22:E26)+SUM(E29:E30)+SUM(E33:E37) -> 0 | F38: =SUM(F6)-SUM(F12,F22:F26)+SUM(F29:F30)+SUM(F33:F37) -> 0
A39: =报表格式!L38 -> 加：营业外收入 | B39: 34 | D39: =上年PL审定!B39 -> 0 | E39: =ABS(F39) -> 0 | F39: =C39-D39 -> 0
A40: =报表格式!L39 -> 减：营业外支出 | B40: 35 | D40: =上年PL审定!B40 -> 0 | E40: =ABS(F40) -> 0 | F40: =C40-D40 -> 0
A41: =报表格式!L40 -> 三、利润总额（亏损总额以“－”号填列） | B41: 36 | C41: =SUM(C38)+SUM(C39)-SUM(C40) -> 0 | D41: =SUM(D38)+SUM(D39)-SUM(D40) -> 0 | E41: =ABS(F41) -> 0 | F41: =C41-D41 -> 0
A42: =报表格式!L41 -> 减：所得税费用 | B42: 37 | D42: =上年PL审定!B42 -> 0 | E42: =ABS(F42) -> 0 | F42: =C42-D42 -> 0
A43: =报表格式!L42 -> 0 | B43: 38 | D43: =上年PL审定!B43 -> 0 | E43: =ABS(F43) -> 0 | F43: =C43-D43 -> 0
A44: =报表格式!L43 -> 四、净利润（净亏损以“－”号填列） | B44: 39 | C44: =C41-C42-C43 -> 0 | D44: =D41-D42-D43 -> 0 | E44: =ABS(F44) -> 0 | F44: =C44-D44 -> 0
A45: =报表格式!L44 -> （一）按经营持续性分类 | B45: 40
A46: =报表格式!L45 -> 其中：持续经营净利润（净亏损以“-”号填列） | B46: 41 | D46: =上年PL审定!B46 -> 0 | E46: =ABS(F46) -> 0 | F46: =C46-D46 -> 0
A47: =报表格式!L46 -> 终止经营净利润（净亏损以“-”号填列） | B47: 42 | D47: =上年PL审定!B47 -> 0 | E47: =ABS(F47) -> 0 | F47: =C47-D47 -> 0
A48: =报表格式!L47 -> （二）按所有权归属分类 | B48: 43
A49: =报表格式!L48 -> 其中：归属于母公司股东的净利润（净亏损以“-”号填列） | B49: 44 | C49: =C44-C50 -> 0 | D49: =上年PL审定!B49 -> 0 | E49: =ABS(F49) -> 0 | F49: =C49-D49 -> 0
A50: =报表格式!L49 -> 少数股东损益（净亏损以“-”号填列） | B50: 45 | D50: =上年PL审定!B50 -> 0 | E50: =ABS(F50) -> 0 | F50: =C50-D50 -> 0
A51: =报表格式!L50 -> 五、其他综合收益的税后净额 | B51: 46 | C51: =C52+C71 -> 0 | D51: =D52+D71 -> 0 | F51: =C51-D51 -> 0
A52: =报表格式!L51 -> 归属于母公司股东的其他综合收益的税后净额 | B52: 47 | C52: =C53+C59 -> 0 | D52: =D53+D59 -> 0 | E52: =ABS(F52) -> 0 | F52: =C52-D52 -> 0
A53: =报表格式!L52 -> （一）不能重分类进损益的其他综合收益 | B53: 48 | C53: =SUM(C54:C58) -> 0 | D53: =SUM(D54:D58) -> 0 | E53: =ABS(F53) -> 0 | F53: =C53-D53 -> 0
A54: =报表格式!L53 -> 1.重新计量设定受益计划变动额 | B54: 49 | D54: =上年PL审定!B54 -> 0 | E54: =ABS(F54) -> 0 | F54: =C54-D54 -> 0
A55: =报表格式!L54 -> 2.权益法下不能转损益的其他综合收益 | B55: 50 | D55: =上年PL审定!B55 -> 0 | E55: =ABS(F55) -> 0 | F55: =C55-D55 -> 0
A56: =报表格式!L55 -> 3.其他权益工具投资公允价值变动 | B56: 51 | D56: =上年PL审定!B56 -> 0 | E56: =ABS(F56) -> 0 | F56: =C56-D56 -> 0
A57: =报表格式!L56 -> 4.企业自身信用风险公允价值变动 | B57: 52 | D57: =上年PL审定!B57 -> 0 | E57: =ABS(F57) -> 0 | F57: =C57-D57 -> 0
A58: =报表格式!L57 -> 5.其他 | B58: 53 | D58: =上年PL审定!B58 -> 0 | E58: =ABS(F58) -> 0 | F58: =C58-D58 -> 0
A59: =报表格式!L58 -> （二）将重分类进损益的其他综合收益 | B59: 54 | C59: =SUM(C60:C70) -> 0 | D59: =SUM(D60:D70) -> 0 | E59: =ABS(F59) -> 0 | F59: =C59-D59 -> 0
A60: =报表格式!L59 -> 1.权益法下可转损益的其他综合收益 | B60: 55 | D60: =上年PL审定!B60 -> 0 | E60: =ABS(F60) -> 0 | F60: =C60-D60 -> 0
...

Sheet 母公司BS汇总
A1: 母公司资产负债表汇总（审定数）
A2: =CONCATENATE("客户名称：",说明!E23) -> 客户名称：
A3: =CONCATENATE("会计时点：",TEXT(说明!E32,"yyyy.mm.dd")) -> 会计时点：2019.12.31
D4: 1 | E4: 2 | F4: 3 | G4: 4 | H4: 5 | I4: 6 | J4: 7 | K4: 8 | L4: 9 | M4: 10
A5: =报表格式!B4 -> 报表项目 | B5: 母公司汇总 | C5: 母公司本部 | D5: 1分公司 | E5: 2分公司 | F5: 3分公司 | G5: 4分公司 | H5: 5分公司 | I5: 6分公司 | J5: 7分公司 | K5: 8分公司 | L5: 9分公司 | M5: 10分公司 | O5: XX分公司
A6: =报表格式!B5 -> 流动资产：
A7: =报表格式!B6 -> 货币资金 | B7: =SUM(C7:O7) -> 0
A8: =报表格式!B7 -> 结算备付金 | B8: =SUM(C8:O8) -> 0
A9: =报表格式!B8 -> 拆出资金 | B9: =SUM(C9:O9) -> 0
A10: =报表格式!B9 -> 交易性金融资产 | B10: =SUM(C10:O10) -> 0
A11: =报表格式!B10 -> 以公允价值计量且其变动计入当期损益的金融资产 | B11: =SUM(C11:O11) -> 0
A12: =报表格式!B11 -> 衍生金融资产 | B12: =SUM(C12:O12) -> 0
A13: =报表格式!B12 -> 应收票据 | B13: =SUM(C13:O13) -> 0
A14: =报表格式!B13 -> 应收账款 | B14: =SUM(C14:O14) -> 0
A15: =报表格式!B14 -> 应收款项融资 | B15: =SUM(C15:O15) -> 0
A16: =报表格式!B15 -> 预付款项 | B16: =SUM(C16:O16) -> 0
A17: =报表格式!B16 -> 应收保费 | B17: =SUM(C17:O17) -> 0
A18: =报表格式!B17 -> 应收分保账款 | B18: =SUM(C18:O18) -> 0
... A30: =报表格式!B29 -> 0 | B30: =SUM(C30:O30) -> 0
A31: =报表格式!B30 -> 流动资产合计 | B31: =SUM(C31:O31) -> 0 | C31: =SUM(C7:C30)-C21-C22 -> 0 | D31: =SUM(D7:D29)-D21-D22 -> 0 | E31: =SUM(E7:E29)-E21-E22 -> 0 | F31: =SUM(F7:F29)-F21-F22 -> 0 | G31: =SUM(G7:G29)-G21-G22 -> 0 | H31: =SUM(H7:H29)-H21-H22 -> 0 | I31: =SUM(I7:I29)-I21-I22 -> 0 | J31: =SUM(J7:J29)-J21-J22 -> 0 | K31: =SUM(K7:K29)-K21-K22 -> 0 | ... O31: =SUM(O7:O29)-O21-O22 -> 0
A32: =报表格式!B31 -> 非流动资产:
A33: =报表格式!B32 -> 发放贷款及垫款 | B33: =SUM(C33:O33) -> 0
A34: =报表格式!B33 -> 债权投资 | B34: =SUM(C34:O34) -> 0
A35: =报表格式!B34 -> 可供出售金融资产 | B35: =SUM(C35:O35) -> 0
A36: =报表格式!B35 -> 其他债权投资 | B36: =SUM(C36:O36) -> 0
A37: =报表格式!B36 -> 持有至到期投资 | B37: =SUM(C37:O37) -> 0
A38: =报表格式!B37 -> 长期应收款 | B38: =SUM(C38:O38) -> 0
A39: =报表格式!B38 -> 设定受益计划净资产 | B39: =SUM(C39:O39) -> 0
A40: =报表格式!B39 -> 长期股权投资 | B40: =SUM(C40:O40) -> 0
A41: =报表格式!B40 -> 其他权益工具投资 | B41: =SUM(C41:O41) -> 0
A42: =报表格式!B41 -> 其他非流动金融资产 | B42: =SUM(C42:O42) -> 0
A43: =报表格式!B42 -> 投资性房地产 | B43: =SUM(C43:O43) -> 0
A44: =报表格式!B43 -> 固定资产 | B44: =SUM(C44:O44) -> 0
... A57: =报表格式!B56 -> 0 | B57: =SUM(C57:O57) -> 0
A58: =报表格式!B57 -> 非流动资产合计 | B58: =SUM(C58:O58) -> 0 | C58: =SUM(C33:C57) -> 0 | D58: =SUM(D34:D57) -> 0 | E58: =SUM(E34:E57) -> 0 | F58: =SUM(F34:F57) -> 0 | G58: =SUM(G34:G57) -> 0 | H58: =SUM(H34:H57) -> 0 | I58: =SUM(I34:I57) -> 0 | J58: =SUM(J34:J57) -> 0 | K58: =SUM(K34:K57) -> 0 | ... O58: =SUM(O34:O57) -> 0
A59: =报表格式!B58 -> 资 产 总 计 | B59: =SUM(C59:O59) -> 0 | C59: =SUM(C31,C58) -> 0 | D59: =SUM(D31,D58) -> 0 | E59: =SUM(E31,E58) -> 0 | F59: =SUM(F31,F58) -> 0 | G59: =SUM(G31,G58) -> 0 | H59: =SUM(H31,H58) -> 0 | I59: =SUM(I31,I58) -> 0 | J59: =SUM(J31,J58) -> 0 | ... O59: =SUM(O31,O58) -> 0
A61: =报表格式!G5 -> 流动负债：
A62: =报表格式!G6 -> 短期借款 | B62: =SUM(C62:O62) -> 0
A63: =报表格式!G7 -> 向中央银行借款 | B63: =SUM(C63:O63) -> 0
A64: =报表格式!G8 -> 吸收存款及同业存放 | B64: =SUM(C64:O64) -> 0
...

Sheet 母公司PL汇总
A1: 母公司利润及利润分配表汇总（审定数）
A2: =CONCATENATE("客户名称：",说明!E23) -> 客户名称：
A3: =CONCATENATE("会计期间：",说明!E30) -> 会计期间：2019年度
D4: 1 | E4: 2 | F4: 3 | G4: 4 | H4: 5 | I4: 6 | J4: 7 | K4: 8 | L4: 9 | M4: 10
A5: =报表格式!L4 -> 报表项目 | B5: 母公司汇总 | C5: 母公司本部 | D5: 1分公司 | E5: 2分公司 | F5: 3分公司 | G5: 4分公司 | H5: 5分公司 | I5: 6分公司 | J5: 7分公司 | K5: 8分公司 | L5: 9分公司 | M5: 10分公司 | O5: XX分公司
A6: =报表格式!L5 -> 一、营业收入 | B6: =SUM(C6:O6) -> 0
A7: =报表格式!L6 -> 其中：主营业务收入 | B7: =SUM(C7:O7) -> 0
A8: =报表格式!L7 -> 利息收入 | B8: =SUM(C8:O8) -> 0
A9: =报表格式!L8 -> 已赚保费 | B9: =SUM(C9:O9) -> 0
A10: =报表格式!L9 -> 手续费及佣金收入 | B10: =SUM(C10:O10) -> 0
A11: =报表格式!L10 -> 其他业务收入 | B11: =SUM(C11:O11) -> 0
A12: =报表格式!L11 -> 减：营业成本 | B12: =SUM(C12:O12) -> 0
A13: =报表格式!L12 -> 其中：主营业务成本 | B13: =SUM(C13:O13) -> 0
A14: =报表格式!L13 -> 利息支出 | B14: =SUM(C14:O14) -> 0
A15: =报表格式!L14 -> 手续费及佣金支出 | B15: =SUM(C15:O15) -> 0
A16: =报表格式!L15 -> 退保金 | B16: =SUM(C16:O16) -> 0
A17: =报表格式!L16 -> 赔付支出净额 | B17: =SUM(C17:O17) -> 0
... A37: =报表格式!L36 -> 资产处置收益(损失以“-”号填列） | B37: =SUM(C37:O37) -> 0
A38: =报表格式!L37 -> 二、营业利润（亏损以“－”号填列） | B38: =SUM(C38:O38) -> 0 | C38: =SUM(C6)-SUM(C12,C22:C26)+SUM(C29:C30,C33:C37) -> 0 | D38: =SUM(D6)-SUM(D12,D22:D26)+SUM(D29:D30,D33:D37) -> 0 | E38: =SUM(E6)-SUM(E12,E22:E26)+SUM(E29:E30,E33:E37) -> 0 | F38: =SUM(F6)-SUM(F12,F22:F26)+SUM(F29:F30,F33:F37) -> 0 | G38: =SUM(G6)-SUM(G12,G22:G26)+SUM(G29:G30,G33:G37) -> 0 | H38: =SUM(H6)-SUM(H12,H22:H26)+SUM(H29:H30,H33:H37) -> 0 | I38: =SUM(I6)-SUM(I12,I22:I26)+SUM(I29:I30,I33:I37) -> 0 | J38: =SUM(J6)-SUM(J12,J22:J26)+SUM(J29:J30,J33:J37) -> 0 | ... O38: =SUM(O6)-SUM(O12,O22:O26)+SUM(O29:O30,O33:O37) -> 0
A39: =报表格式!L38 -> 加：营业外收入 | B39: =SUM(C39:O39) -> 0
A40: =报表格式!L39 -> 减：营业外支出 | B40: =SUM(C40:O40) -> 0
A41: =报表格式!L40 -> 三、利润总额（亏损总额以“－”号填列） | B41: =SUM(C41:O41) -> 0 | C41: =SUM(C38)+SUM(C39)-SUM(C40) -> 0 | D41: =SUM(D38)+SUM(D39)-SUM(D40) -> 0 | E41: =SUM(E38)+SUM(E39)-SUM(E40) -> 0 | F41: =SUM(F38)+SUM(F39)-SUM(F40) -> 0 | G41: =SUM(G38)+SUM(G39)-SUM(G40) -> 0 | H41: =SUM(H38)+SUM(H39)-SUM(H40) -> 0 | I41: =SUM(I38)+SUM(I39)-SUM(I40) -> 0 | J41: =SUM(J38)+SUM(J39)-SUM(J40) -> 0 | ... O41: =SUM(O38)+SUM(O39)-SUM(O40) -> 0
A42: =报表格式!L41 -> 减：所得税费用 | B42: =SUM(C42:O42) -> 0
A43: =报表格式!L42 -> 0 | B43: =SUM(C43:O43) -> 0
A44: =报表格式!L43 -> 四、净利润（净亏损以“－”号填列） | B44: =SUM(C44:O44) -> 0 | C44: =C41-C42-C43 -> 0 | D44: =D41-D42-D43 -> 0 | E44: =E41-E42-E43 -> 0 | F44: =F41-F42-F43 -> 0 | G44: =G41-G42-G43 -> 0 | H44: =H41-H42-H43 -> 0 | I44: =I41-I42-I43 -> 0 | J44: =J41-J42-J43 -> 0 | ... O44: =O41-O42-O43 -> 0
A45: =报表格式!L44 -> （一）按经营持续性分类 | B45: =SUM(C45:O45) -> 0
A46: =报表格式!L45 -> 其中：持续经营净利润（净亏损以“-”号填列） | B46: =SUM(C46:O46) -> 0
A47: =报表格式!L46 -> 终止经营净利润（净亏损以“-”号填列） | B47: =SUM(C47:O47) -> 0
A48: =报表格式!L47 -> （二）按所有权归属分类 | B48: =SUM(C48:O48) -> 0
A49: =报表格式!L48 -> 其中：归属于母公司股东的净利润（净亏损以“-”号填列） | B49: =SUM(C49:O49) -> 0 | C49: =C44-C50 -> 0 | D49: =D44-D50 -> 0 | E49: =E44-E50 -> 0 | F49: =F44-F50 -> 0 | G49: =G44-G50 -> 0 | H49: =H44-H50 -> 0 | I49: =I44-I50 -> 0 | J49: =J44-J50 -> 0 | ... O49: =O44-O50 -> 0
A50: =报表格式!L49 -> 少数股东损益（净亏损以“-”号填列） | B50: =SUM(C50:O50) -> 0
A51: =报表格式!L50 -> 五、其他综合收益的税后净额 | B51: =SUM(C51:O51) -> 0 | C51: =C52+C71 -> 0 | D51: =D52+D71 -> 0 | E51: =E52+E71 -> 0 | F51: =F52+F71 -> 0 | G51: =G52+G71 -> 0 | H51: =H52+H71 -> 0 | I51: =I52+I71 -> 0 | J51: =J52+J71 -> 0 | ... O51: =O52+O71 -> 0
A52: =报表格式!L51 -> 归属于母公司股东的其他综合收益的税后净额 | B52: =SUM(C52:O52) -> 0 | C52: =C53+C59 -> 0 | D52: =D53+D59 -> 0 | E52: =E53+E59 -> 0 | F52: =F53+F59 -> 0 | G52: =G53+G59 -> 0 | H52: =H53+H59 -> 0 | I52: =I53+I59 -> 0 | J52: =J53+J59 -> 0 | ... O52: =O53+O59 -> 0
A53: =报表格式!L52 -> （一）不能重分类进损益的其他综合收益 | B53: =SUM(C53:O53) -> 0 | C53: =SUM(C54:C58) -> 0 | D53: =SUM(D54:D58) -> 0 | E53: =SUM(E54:E58) -> 0 | F53: =SUM(F54:F58) -> 0 | G53: =SUM(G54:G58) -> 0 | H53: =SUM(H54:H58) -> 0 | I53: =SUM(I54:I58) -> 0 | J53: =SUM(J54:J58) -> 0 | ... O53: =SUM(O54:O58) -> 0
A54: =报表格式!L53 -> 1.重新计量设定受益计划变动额 | B54: =SUM(C54:O54) -> 0
A55: =报表格式!L54 -> 2.权益法下不能转损益的其他综合收益 | B55: =SUM(C55:O55) -> 0
A56: =报表格式!L55 -> 3.其他权益工具投资公允价值变动 | B56: =SUM(C56:O56) -> 0
A57: =报表格式!L56 -> 4.企业自身信用风险公允价值变动 | B57: =SUM(C57:O57) -> 0
A58: =报表格式!L57 -> 5.其他 | B58: =SUM(C58:O58) -> 0
A59: =报表格式!L58 -> （二）将重分类进损益的其他综合收益 | B59: =SUM(C59:O59) -> 0 | C59: =SUM(C60:C70) -> 0 | D59: =SUM(D60:D70) -> 0 | E59: =SUM(E60:E70) -> 0 | F59: =SUM(F60:F70) -> 0 | G59: =SUM(G60:G70) -> 0 | H59: =SUM(H60:H70) -> 0 | I59: =SUM(I60:I70) -> 0 | J59: =SUM(J60:J70) -> 0 | ... O59: =SUM(O60:O70) -> 0
...

Sheet 母公司CF汇总
A1: 母公司现金流量表汇总（审定数）
A2: =CONCATENATE("客户名称：",说明!E23) -> 客户名称：
A3: =CONCATENATE("会计期间：",说明!E30) -> 会计期间：2019年度
D4: 1 | E4: 2 | F4: 3 | G4: 4 | H4: 5 | I4: 6 | J4: 7 | K4: 8 | L4: 9 | M4: 10
A5: =报表格式!Q4 -> 报表项目 | B5: 母公司汇总 | C5: 母公司本部 | D5: 1分公司 | E5: 2分公司 | F5: 3分公司 | G5: 4分公司 | H5: 5分公司 | I5: 6分公司 | J5: 7分公司 | K5: 8分公司 | L5: 9分公司 | M5: 10分公司 | O5: XX分公司
A6: =报表格式!Q5 -> 一、经营活动产生的现金流量
A7: =报表格式!Q6 -> 销售商品、提供劳务收到的现金 | B7: =SUM(C7:O7) -> 0
A8: =报表格式!Q7 -> 客户存款和同业存放款项净增加额 | B8: =SUM(C8:O8) -> 0
A9: =报表格式!Q8 -> 向中央银行借款净增加额 | B9: =SUM(C9:O9) -> 0
A10: =报表格式!Q9 -> 向其他金融机构拆入资金净增加额 | B10: =SUM(C10:O10) -> 0
A11: =报表格式!Q10 -> 收到原保险合同保费取得的现金 | B11: =SUM(C11:O11) -> 0
A12: =报表格式!Q11 -> 收到再保险业务现金净额 | B12: =SUM(C12:O12) -> 0
A13: =报表格式!Q12 -> 保户储金及投资款净增加额 | B13: =SUM(C13:O13) -> 0
A14: =报表格式!Q13 -> 收取利息、手续费及佣金的现金 | B14: =SUM(C14:O14) -> 0
A15: =报表格式!Q14 -> 拆入资金净增加额 | B15: =SUM(C15:O15) -> 0
A16: =报表格式!Q15 -> 回购业务资金净增加额 | B16: =SUM(C16:O16) -> 0
A17: =报表格式!Q16 -> 收到的税费返还 | B17: =SUM(C17:O17) -> 0
A18: =报表格式!Q17 -> 收到的其他与经营活动有关的现金 | B18: =SUM(C18:O18) -> 0
A19: =报表格式!Q18 -> 0 | B19: =SUM(C19:O19) -> 0
A20: =报表格式!Q20 -> 经营活动现金流入小计 | B20: =SUM(C20:O20) -> 0 | C20: =SUM(C7:C19) -> 0 | D20: =SUM(D7:D19) -> 0 | E20: =SUM(E7:E19) -> 0 | F20: =SUM(F7:F19) -> 0 | G20: =SUM(G7:G19) -> 0 | H20: =SUM(H7:H19) -> 0 | I20: =SUM(I7:I19) -> 0 | J20: =SUM(J7:J19) -> 0 | ... O20: =SUM(O7:O19) -> 0
A21: =报表格式!Q21 -> 购买商品、接受劳务支付的现金 | B21: =SUM(C21:O21) -> 0
A22: =报表格式!Q22 -> 客户贷款及垫款净增加额 | B22: =SUM(C22:O22) -> 0
A23: =报表格式!Q23 -> 存放中央银行和同业款项净增加额 | B23: =SUM(C23:O23) -> 0
A24: =报表格式!Q24 -> 支付原保险合同赔付款项的现金 | B24: =SUM(C24:O24) -> 0
A25: =报表格式!Q25 -> 支付利息、手续费及佣金的现金 | B25: =SUM(C25:O25) -> 0
A26: =报表格式!Q26 -> 支付保单红利的现金 | B26: =SUM(C26:O26) -> 0
A27: =报表格式!Q27 -> 支付给职工以及为职工支付的现金 | B27: =SUM(C27:O27) -> 0
A28: =报表格式!Q28 -> 支付各项税费 | B28: =SUM(C28:O28) -> 0
A29: =报表格式!Q29 -> 支付的其他与经营活动有关的现金 | B29: =SUM(C29:O29) -> 0
A30: =报表格式!Q31 -> 经营活动现金流出小计 | B30: =SUM(C30:O30) -> 0 | C30: =SUM(C21:C29) -> 0 | D30: =SUM(D21:D29) -> 0 | E30: =SUM(E21:E29) -> 0 | F30: =SUM(F21:F29) -> 0 | G30: =SUM(G21:G29) -> 0 | H30: =SUM(H21:H29) -> 0 | I30: =SUM(I21:I29) -> 0 | J30: =SUM(J21:J29) -> 0 | ... O30: =SUM(O21:O29) -> 0
A31: =报表格式!Q32 -> 经营活动产生的现金流量净额 | B31: =SUM(C31:O31) -> 0 | C31: =C20-C30 -> 0 | D31: =D20-D30 -> 0 | E31: =E20-E30 -> 0 | F31: =F20-F30 -> 0 | G31: =G20-G30 -> 0 | H31: =H20-H30 -> 0 | I31: =I20-I30 -> 0 | J31: =J20-J30 -> 0 | ... O31: =O20-O30 -> 0
A32: =报表格式!Q33 -> 二、投资活动产生的现金流量
A33: =报表格式!Q34 -> 收回投资所收到的现金 | B33: =SUM(C33:O33) -> 0
A34: =报表格式!Q35 -> 取得投资收益所收到的现金 | B34: =SUM(C34:O34) -> 0
A35: =报表格式!Q36 -> 处置固定资产、无形资产和其他长期资产而收到的现金净额 | B35: =SUM(C35:O35) -> 0
A36: =报表格式!Q37 -> 处置子公司及其他营业单位收到的现金净额 | B36: =SUM(C36:O36) -> 0
A37: =报表格式!Q38 -> 收到其他与投资活动有关的现金 | B37: =SUM(C37:O37) -> 0
A38: =报表格式!Q40 -> 投资活动现金流入小计 | B38: =SUM(B33:B37) -> 0 | C38: =SUM(C33:C37) -> 0 | D38: =SUM(D33:D37) -> 0 | E38: =SUM(E33:E37) -> 0 | F38: =SUM(F33:F37) -> 0 | G38: =SUM(G33:G37) -> 0 | H38: =SUM(H33:H37) -> 0 | I38: =SUM(I33:I37) -> 0 | ... O38: =SUM(O33:O37) -> 0
A39: =报表格式!Q41 -> 购置固定资产、无形资产和其他长期资产所支付现金 | B39: =SUM(C39:O39) -> 0
A40: =报表格式!Q42 -> 投资所支付的现金 | B40: =SUM(C40:O40) -> 0
...

Sheet 母公司汇总抵销
A1: =IF((L2-(母公司TB资产!C60+母公司TB负债!C63+母公司TB损益!C90)-IF(COUNTIF(E5:E668,"未分配利润")>=1,VLOOKUP("未分配利润",E5:J668,6,0),0))<0.005,"母公司汇总抵销","调整事项未全部链入试算平衡表，请检查调整科目是否为报表项目!") -> 母公司汇总抵销 | K1: =SUM(L2:L3) -> 0 | N1: code | O1: 报表项目
A2: =CONCATENATE("客户名称：",说明!E23) -> 客户名称： | E2: =CONCATENATE("编制人：",说明!E36) -> 编制人： | H2: =CONCATENATE("日期：",TEXT(NOW(),"yyyy.mm.dd")) -> 日期：2019.12.31 | J2: 索引： | K2: 借方调整累计 | L2: =SUMIF(E5:E65538,"?*",J5:J65538) -> 0
A3: =CONCATENATE("会计期间：",说明!E30) -> 会计期间：2019年度 | E3: =CONCATENATE("复核人：",说明!E37) -> 复核人： | H3: 日期： | J3: 页码： | K3: 贷方调整累计 | L3: =SUMIF(H5:H65538,"?*",J5:J65538) -> 0
A4: 序号 | B4: 索引号 | C4: 抵销说明 | D4: code | E4: 借方科目 | F4: 二级科目 | G4: code | H4: 贷方科目 | I4: 二级科目 | J4: 金额 | L4: =L2-L3 -> 0
A5: 1 | E5: =IF(D5=0,"",VLOOKUP(D5,$N:$O,2,0)) | H5: =IF(G5=0,"",VLOOKUP(G5,$N:$O,2,0)) | K5: 本表可根据需要插入行， | N5: =报表格式!Z5 -> 0 | O5: =IF(OR(MID(TRIM(报表格式!AA5),2,1)="：",MID(TRIM(报表格式!AA5),2,1)="、"),REPLACEB(TRIM(报表格式!AA5),1,4,""),TRIM(报表格式!AA5)) -> 流动资产：
E6: =IF(D6=0,"",VLOOKUP(D6,$N:$O,2,0)) | H6: =IF(G6=0,"",VLOOKUP(G6,$N:$O,2,0)) | K6: 请勿删除行。 | N6: =报表格式!Z6 -> D1 | O6: =IF(OR(MID(TRIM(报表格式!AA6),2,1)="：",MID(TRIM(报表格式!AA6),2,1)="、"),REPLACEB(TRIM(报表格式!AA6),1,4,""),TRIM(报表格式!AA6)) -> 货币资金
E7: =IF(D7=0,"",VLOOKUP(D7,$N:$O,2,0)) | H7: =IF(G7=0,"",VLOOKUP(G7,$N:$O,2,0)) | N7: =报表格式!Z7 -> D41 | O7: =IF(OR(MID(TRIM(报表格式!AA7),2,1)="：",MID(TRIM(报表格式!AA7),2,1)="、"),REPLACEB(TRIM(报表格式!AA7),1,4,""),TRIM(报表格式!AA7)) -> 结算备付金
E8: =IF(D8=0,"",VLOOKUP(D8,$N:$O,2,0)) | H8: =IF(G8=0,"",VLOOKUP(G8,$N:$O,2,0)) | N8: =报表格式!Z8 -> D42 | O8: =IF(OR(MID(TRIM(报表格式!AA8),2,1)="：",MID(TRIM(报表格式!AA8),2,1)="、"),REPLACEB(TRIM(报表格式!AA8),1,4,""),TRIM(报表格式!AA8)) -> 拆出资金
E9: =IF(D9=0,"",VLOOKUP(D9,$N:$O,2,0)) | H9: =IF(G9=0,"",VLOOKUP(G9,$N:$O,2,0)) | N9: =报表格式!Z9 -> D2 | O9: =IF(OR(MID(TRIM(报表格式!AA9),2,1)="：",MID(TRIM(报表格式!AA9),2,1)="、"),REPLACEB(TRIM(报表格式!AA9),1,4,""),TRIM(报表格式!AA9)) -> 交易性金融资产
E10: =IF(D10=0,"",VLOOKUP(D10,$N:$O,2,0)) | H10: =IF(G10=0,"",VLOOKUP(G10,$N:$O,2,0)) | N10: =报表格式!Z10 -> D3 | O10: =IF(OR(MID(TRIM(报表格式!AA10),2,1)="：",MID(TRIM(报表格式!AA10),2,1)="、"),REPLACEB(TRIM(报表格式!AA10),1,4,""),TRIM(报表格式!AA10)) -> 以公允价值计量且其变动计入当期损益的金融资产
E11: =IF(D11=0,"",VLOOKUP(D11,$N:$O,2,0)) | H11: =IF(G11=0,"",VLOOKUP(G11,$N:$O,2,0)) | N11: =报表格式!Z11 -> D4 | O11: =IF(OR(MID(TRIM(报表格式!AA11),2,1)="：",MID(TRIM(报表格式!AA11),2,1)="、"),REPLACEB(TRIM(报表格式!AA11),1,4,""),TRIM(报表格式!AA11)) -> 衍生金融资产
E12: =IF(D12=0,"",VLOOKUP(D12,$N:$O,2,0)) | H12: =IF(G12=0,"",VLOOKUP(G12,$N:$O,2,0)) | N12: =报表格式!Z12 -> D5 | O12: =IF(OR(MID(TRIM(报表格式!AA12),2,1)="：",MID(TRIM(报表格式!AA12),2,1)="、"),REPLACEB(TRIM(报表格式!AA12),1,4,""),TRIM(报表格式!AA12)) -> 应收票据
J13: =IF(ABS((SUMIF(E5:E12,"?*",J5:J12)-SUMIF(H5:H12,"?*",J5:J12)))<0.005,"","借贷不等") | N13: =报表格式!Z13 -> D6 | O13: =IF(OR(MID(TRIM(报表格式!AA13),2,1)="：",MID(TRIM(报表格式!AA13),2,1)="、"),REPLACEB(TRIM(报表格式!AA13),1,4,""),TRIM(报表格式!AA13)) -> 应收账款
A14: 2 | E14: =IF(D14=0,"",VLOOKUP(D14,$N:$O,2,0)) | H14: =IF(G14=0,"",VLOOKUP(G14,$N:$O,2,0)) | N14: =报表格式!Z14 -> D7 | O14: =IF(OR(MID(TRIM(报表格式!AA14),2,1)="：",MID(TRIM(报表格式!AA14),2,1)="、"),REPLACEB(TRIM(报表格式!AA14),1,4,""),TRIM(报表格式!AA14)) -> 应收款项融资
E15: =IF(D15=0,"",VLOOKUP(D15,$N:$O,2,0)) | H15: =IF(G15=0,"",VLOOKUP(G15,$N:$O,2,0)) | N15: =报表格式!Z15 -> D8 | O15: =IF(OR(MID(TRIM(报表格式!AA15),2,1)="：",MID(TRIM(报表格式!AA15),2,1)="、"),REPLACEB(TRIM(报表格式!AA15),1,4,""),TRIM(报表格式!AA15)) -> 预付款项
E16: =IF(D16=0,"",VLOOKUP(D16,$N:$O,2,0)) | H16: =IF(G16=0,"",VLOOKUP(G16,$N:$O,2,0)) | N16: =报表格式!Z16 -> D43 | O16: =IF(OR(MID(TRIM(报表格式!AA16),2,1)="：",MID(TRIM(报表格式!AA16),2,1)="、"),REPLACEB(TRIM(报表格式!AA16),1,4,""),TRIM(报表格式!AA16)) -> 应收保费
E17: =IF(D17=0,"",VLOOKUP(D17,$N:$O,2,0)) | H17: =IF(G17=0,"",VLOOKUP(G17,$N:$O,2,0)) | N17: =报表格式!Z17 -> D44 | O17: =IF(OR(MID(TRIM(报表格式!AA17),2,1)="：",MID(TRIM(报表格式!AA17),2,1)="、"),REPLACEB(TRIM(报表格式!AA17),1,4,""),TRIM(报表格式!AA17)) -> 应收分保账款
E18: =IF(D18=0,"",VLOOKUP(D18,$N:$O,2,0)) | H18: =IF(G18=0,"",VLOOKUP(G18,$N:$O,2,0)) | N18: =报表格式!Z18 -> D45 | O18: =IF(OR(MID(TRIM(报表格式!AA18),2,1)="：",MID(TRIM(报表格式!AA18),2,1)="、"),REPLACEB(TRIM(报表格式!AA18),1,4,""),TRIM(报表格式!AA18)) -> 应收分保准备金
E19: =IF(D19=0,"",VLOOKUP(D19,$N:$O,2,0)) | H19: =IF(G19=0,"",VLOOKUP(G19,$N:$O,2,0)) | N19: =报表格式!Z19 -> D9 | O19: =IF(OR(MID(TRIM(报表格式!AA19),2,1)="：",MID(TRIM(报表格式!AA19),2,1)="、"),REPLACEB(TRIM(报表格式!AA19),1,4,""),TRIM(报表格式!AA19)) -> 其他应收款
J20: =IF(ABS((SUMIF(E14:E19,"?*",J14:J19)-SUMIF(H14:H19,"?*",J14:J19)))<0.005,"","借贷不等") | N20: =报表格式!Z20 -> 0 | O20: =IF(OR(MID(TRIM(报表格式!AA20),3,1)="：",MID(TRIM(报表格式!AA20),2,1)="、"),REPLACEB(TRIM(报表格式!AA20),1,6,""),TRIM(报表格式!AA20)) -> 应收利息
A21: 3 | E21: =IF(D21=0,"",VLOOKUP(D21,$N:$O,2,0)) | H21: =IF(G21=0,"",VLOOKUP(G21,$N:$O,2,0)) | N21: =报表格式!Z21 -> 0 | O21: =IF(OR(MID(TRIM(报表格式!AA21),2,1)="：",MID(TRIM(报表格式!AA21),2,1)="、"),REPLACEB(TRIM(报表格式!AA21),1,4,""),TRIM(报表格式!AA21)) -> 应收股利
E22: =IF(D22=0,"",VLOOKUP(D22,$N:$O,2,0)) | H22: =IF(G22=0,"",VLOOKUP(G22,$N:$O,2,0)) | N22: =报表格式!Z22 -> D46 | O22: =IF(OR(MID(TRIM(报表格式!AA22),2,1)="：",MID(TRIM(报表格式!AA22),2,1)="、"),REPLACEB(TRIM(报表格式!AA22),1,4,""),TRIM(报表格式!AA22)) -> 买入返售金融资产
E23: =IF(D23=0,"",VLOOKUP(D23,$N:$O,2,0)) | H23: =IF(G23=0,"",VLOOKUP(G23,$N:$O,2,0)) | N23: =报表格式!Z23 -> D10 | O23: =IF(OR(MID(TRIM(报表格式!AA23),2,1)="：",MID(TRIM(报表格式!AA23),2,1)="、"),REPLACEB(TRIM(报表格式!AA23),1,4,""),TRIM(报表格式!AA23)) -> 存货
E24: =IF(D24=0,"",VLOOKUP(D24,$N:$O,2,0)) | H24: =IF(G24=0,"",VLOOKUP(G24,$N:$O,2,0)) | N24: =报表格式!Z24 -> D11 | O24: =IF(OR(MID(TRIM(报表格式!AA24),3,1)="：",MID(TRIM(报表格式!AA24),2,1)="、"),REPLACEB(TRIM(报表格式!AA24),1,6,""),TRIM(报表格式!AA24)) -> 合同资产
E25: =IF(D25=0,"",VLOOKUP(D25,$N:$O,2,0)) | H25: =IF(G25=0,"",VLOOKUP(G25,$N:$O,2,0)) | N25: =报表格式!Z25 -> D12 | O25: =IF(OR(MID(TRIM(报表格式!AA25),2,1)="：",MID(TRIM(报表格式!AA25),2,1)="、"),REPLACEB(TRIM(报表格式!AA25),1,4,""),TRIM(报表格式!AA25)) -> 持有待售资产
E26: =IF(D26=0,"",VLOOKUP(D26,$N:$O,2,0)) | H26: =IF(G26=0,"",VLOOKUP(G26,$N:$O,2,0)) | N26: =报表格式!Z26 -> D13 | O26: =IF(OR(MID(TRIM(报表格式!AA26),2,1)="：",MID(TRIM(报表格式!AA26),2,1)="、"),REPLACEB(TRIM(报表格式!AA26),1,4,""),TRIM(报表格式!AA26)) -> 一年内到期的非流动资产
J27: =IF(ABS((SUMIF(E21:E26,"?*",J21:J26)-SUMIF(H21:H26,"?*",J21:J26)))<0.005,"","借贷不等") | N27: =报表格式!Z27 -> D14 | O27: =IF(OR(MID(TRIM(报表格式!AA27),2,1)="：",MID(TRIM(报表格式!AA27),2,1)="、"),REPLACEB(TRIM(报表格式!AA27),1,4,""),TRIM(报表格式!AA27)) -> 其他流动资产
