Workbook
Name _1、: #REF!
Name _1、受本循环影响的相关交易和账户余额: #REF!
Name _2、主要业务活动: #REF!
Name _2、注册会计师通常应在本循环中了解与上述业务活动相关的内部控制_如果计划在其他业务循环中对上述: #REF!
Name _DAT1: #REF!
Name _DAT1: #REF!
Name _DAT10: #REF!
Name _DAT10: #REF!
Name _DAT11: #REF!
Name _DAT11: #REF!
Name _DAT2: #REF!
Name _DAT3: #REF!
Name _DAT4: #REF!
Name _DAT5: #REF!
Name _DAT6: #REF!
Name _DAT7: #REF!
Name _DAT8: #REF!
Name _DAT9: #REF!
Name AS2DocOpenMode: "AS2DocumentEdit"
Name CarryKnown: #REF!
Name CarryKnown: #REF!
Name CarryKnownTable: #REF!
Name CarryKnownTable: #REF!
Name CarryLikely: #REF!
Name CarryLikely: #REF!
Name CarryLikelyTable: #REF!
Name CarryLikelyTable: #REF!
Name Carryover_Effect_of_Prior_Year: #REF!
Name Carryover_Effect_of_Prior_Year: #REF!
Name CarryoverTitle: #REF!
Name CarryoverTitle: #REF!
Name CC_Instruction: #REF!
Name CC_Instruction: #REF!
Name CE_CarryKnownProtection: #REF!
Name CE_CarryKnownProtection: #REF!
Name CE_CarryKnownTable: #REF!
Name CE_CarryKnownTable: #REF!
Name CE_CarryLikely1Protection: #REF!
Name CE_CarryLikely1Protection: #REF!
Name CE_CarryLikely1Table: #REF!
Name CE_CarryLikely1Table: #REF!
Name CE_CarryLikely2Protection: #REF!
Name CE_CarryLikely2Protection: #REF!
Name CE_CarryLikely2Table: #REF!
Name CE_CarryLikely2Table: #REF!
Name CE_CarryTaxable: #REF!
Name CE_CarryTaxable: #REF!
Name CE_Desc: #REF!
Name CE_Desc: #REF!
Name CE_Income: #REF!
Name CE_Income: #REF!
Name CE_KeepFormat: #REF!
Name CE_KeepFormat: #REF!
Name CE_KnownChange: #REF!
Name CE_KnownChange: #REF!
Name CE_KnownFormulaProtection: #REF!
Name CE_KnownFormulaProtection: #REF!
Name CE_KnownImpact: #REF!
Name CE_KnownImpact: #REF!
Name CE_Likely1Change: #REF!

Sheet 底稿目录
A1: 底稿开列时，可先在以下单元格填写有关内容，以便其他底稿引用有关数据： | B1: 目录
A2: 被审计单位：
A3: 截止日：202X年12月31日 | B3: 序号 | C3: 内容 | D3: 索引号 | E3: 备注
A4: 编制人： | C4: 其他非流动资产实质性程序 | D4: I5A
A5: 编制日期： | B5: 1 | C5: 其他非流动资产审定表 | D5: I5-1
A6: 复核人： | B6: 2 | C6: 其他非流动资产附注披露表（上市公司）
A7: 复核日期： | B7: 3 | C7: 其他非流动资产附注披露表（国有企业）
B8: 4 | C8: 其他非流动资产明细表 | D8: I5-2
A9: 关于工作底稿与审计程序索引号对应的说明 | B9: 5 | C9: 调整分录汇总 | D9: I5-3 | E9: 备选
A10: 1.编制的审计工作底稿应与审计程序对应。审计项目组应根据被审计单位实际情况和风险评估情况在实质性程序表中裁剪、修改或增加审计程序，根据实际执行的审计程序完成相应审计工作底稿，编制的工作底稿中应按自然顺序依次编制索引号，并通过唯一的索引号将与实质性程序表中的程序对应关联（即将工作底稿的索引号填入实质性程序表中的底稿索引号列）。 | B10: 6 | C10: 其他非流动资产检查表 | D10: I5-4
A14: 2.获取的支持性证据应与审计底稿或程序对应。审计项目组在完成底稿时获取的支持性证据应根据底稿索引号编制下一级按自然顺序排序的索引号（如D1-2-1、D1-2-2、……），并在底稿中说明引用的支持性证据、关联索引号。
A17: 3.工作底稿索引号的编码规则：实质性程序索引号按循环从“D”到“N”,循环内账户以顺序号排列，模板中底稿索引号按账户顺序+自然数顺序（即模板中索引号按二级自然顺序排列，如D1-1、D1-2、D1-3、……D1-N）。

Sheet 其他非流动资产实质性程序 I5A
A1: 致同会计师事务所
A2: 其他非流动资产程序表
A3: =底稿目录!A2 -> 被审计单位： | C3: =底稿目录!A4 -> 编制人： | F3: =底稿目录!A5 -> 编制日期： | H3: 索引号： | I3: I5A
A4: =底稿目录!A3 -> 截止日：202X年12月31日 | C4: =底稿目录!A6 -> 复核人： | F4: =底稿目录!A7 -> 复核日期： | H4: 页次：
A5: 一、本账户涉及的科目
A6: 其他非流动资产
A7: 二、审计目标与认定的对应关系
A8: 审计目标 | G8: 财务报表的认定
A9: A. 资产负债表中记录的其他非流动资产是存在的，且已经记录在恰当的账户中 | G9: 存在
A10: B. 所有应记录的其他非流动资产均已记录，所有应当包括在财务报表中的相关披露均已包括 | G10: 完整性
A11: C. 记录的其他非流动资产由被审计单位拥有或控制 | G11: 权利和义务
A12: D. 其他非流动资产以恰当的金额包括在财务报表中，与之相关的计价或分摊调整已恰当记录，相关披露已得到恰当计量和描述 | G12: 准确性、计价和分摊
A13: E. 其他非流动资产已被恰当地汇总或分解且表述清楚，相关披露在按照企业会计准则的编制基础下是相关的、可理解的 | G13: 列报
A14: 三、计划实施的实质性程序
A15: 序号 | B15: 审计程序 | C15: 程序分类 | D15: 财务报表的认定 | I15: 底稿索引号
D16: 存在 | E16: 完整性 | F16: 权利和 义务 | G16: 准确性、计价和分摊 | H16: 列报 | J16: 根据被审计单位实际情况和风险评估情况裁剪、修改或增加审计程序
A17: 1 | B17: 获取或编制其他非流动资产的明细表，复核加计是否正确，与总账、明细账合计数核对是否相符，期初余额与上期审定期末余额是否相符，并编制审定表。 | C17: 常规★ | D17: √ | E17: √ | G17: √ | I17: I5-1 /I5-2
A18: 2 | B18: 在使用手工编制、自定义信息报告、系统生成的非固定格式报告等由被审计单位生成的信息时，测试有关信息准确性和完整性，并考虑针对编制和维护由被审计单位生成的信息的相关控制实施控制测试，以评价该信息是否能够为实现审计目的提供基础。 | C18: 常规★ | E18: √ | G18: √ | I18: T1 / | J18: 可参见《审计手册》4.2.6，由被审计单位生成的信息可能是由系统生成的、或手工编制的、或二者兼而有之的方式生成的。例如，由被审计单位生成的信息可能包括： • 不涉及自定义的、由系统生成的报告（如，固定格式报告）； • 可能通过人工自定义的、由系统生成的报告，例如，（计算机）查询信息或特别定制的报告； • 手工编制的信息，例如，汇总信息的电子表格或用以支持分配、计算以及调节的电子表格； • 其他系统生成或手工编制的信息，例如，由被审计单位编制的客户发票； • 通过影印、拍摄、扫描或其他方式转换成电子形式的文件记录。
A19: 3 | B19: 对期初余额的审计，取得其他非流动资产期初余额明细表复核加计是否正确，与总账、明细账合计数是否相符，检查上期其他非流动资产在本期减少情况以及其他必要追加的审计程序。（适用于首次承接） | C19: 备选 | D19: √ | E19: √ | F19: √ | G19: √ | J19: 由被审计单位生成的信息不包括： • 总分类账或明细分类账、试算平衡表、或经审计的财务报表； • 第三方（除了服务机构）的报表或报告，例如，原始银行对账单，或函证的回函； • 外部数据（例如，第三方发布的数据，如，定价来源）。
A20: 4 | B20: 关注会计政策、会计估计合理性、一贯性，关注其是否利用会计政策和会计估计及其变更操纵利润。 | C20: 常规★ | D20: √ | E20: √ | G20: √ | I20: I5-1 /I5-2
A21: 5 | B21: 对于本期新增的其他非流动资产，根据具体情况，需要检查的支持性文件包括但不限于： （1）获取有关合同、协议等资料，检查其他非流动资产的构成内容、性质、计价依据，其所有权是否归被审计单位拥有和控制； （2）抽查重要的原始凭证，检查其他非流动资产的合法性和真实性，查阅有关合同、协议和原始凭证，是否经授权批准，会计处理是否正确。 | C21: 常规★ | D21: √ | F21: √ | G21: √ | I21: I5-4
A22: 6 | B22: 对于本期减少的其他非流动资产，根据具体情况，需要检查的支持性文件包括但不限于： （1）检查与资产处置相关的合同、发票及其他文件。 （2）重新计算相关的利得或损失。 （3）确定会计处理是否恰当。 | C22: 常规★ | D22: √ | E22: √ | G22: √ | I22: I5-4
A23: 7 | B23: 针对存在减值迹象的其他非流动资产，考虑执行下列程序： （1）获取其他非流动资产的减值明细表； （2）记录对其他非流动资产可能造成减值的事件或环境变化； （3）复核用于减值测试的资产分组的合理性； （4）关注并复核公司确定的减值测试方法与模型是否恰当；关注并复核公司进行减值测试所依据的基础数据是否准确、所选取的关键参数是否恰当，评价所采用的关键假设、所作出的重大估计和判断、所选取的价值类型是否合理，分析减值测试方法与价值类型是否匹配； （5）取得相关的资产现金流分析。确定相关资产的预测的未来现金流量是合理的；如果现金流量预测表明，资产的账面价值无法收回，获得企业对资产组的公允价值的分析；评价每个评估专家的资质和工作（是否第三方或客户员工），并对完成“专家资质”和“专家工作”的审计程序。确定是否需要在审计项目组中增加一个估值专家，以帮助对公允价值/可收回金额的计算进行评价。 （6）比预期所估计减值准备和已记录的金额，调查所有重大差异； （7）确定潜在减值是否恰当。 （8）确定上期确认的长期资产减值准备在本期的变动是否适当。 | C23: 备选 | G23: √
A24: 8 | B24: 根据评估的舞弊风险等因素增加的审计程序。 | C24: IPO/上市/新三板/重组/舞弊应对
A25: 9 | B25: 检查其他非流动资产是否已按企业会计准则或其他适用的规定在财务报表中做出恰当列报和披露。 | C25: 常规★ | H25: √ | I25: A1-1/A1-15 /A1-16

Sheet 审定表I5-1
A1: 致同会计师事务所
A2: 其他非流动资产审定表
A3: =底稿目录!A2 -> 被审计单位： | D3: =底稿目录!A4 -> 编制人： | H3: =底稿目录!A5 -> 编制日期： | J3: 索引号： | K3: I5-1
A4: =底稿目录!A3 -> 截止日：202X年12月31日 | D4: =底稿目录!A6 -> 复核人： | H4: =底稿目录!A7 -> 复核日期： | J4: 页次：
A5: 项目 | B5: 期初数 | F5: 期末数 | J5: 本期审定数与上期 审定数的比较
B6: 未审数 | C6: 账项调整 | D6: 重分类调整 | E6: 审定数 | F6: 未审数 | G6: 账项调整 | H6: 重分类调整 | I6: 审定数 | J6: 变动额 | K6: 变动率
A7: 其他非流动资产原值：
A8: ='明细表I5-2'!A11 -> 预付土地出让金 | B8: ='明细表I5-2'!B11 -> 0 | C8: ='明细表I5-2'!F11 -> 0 | D8: ='明细表I5-2'!G11 -> 0 | E8: ='明细表I5-2'!L11 -> 0 | F8: ='明细表I5-2'!E11 -> 0 | G8: ='明细表I5-2'!F11+'明细表I5-2'!H11-'明细表I5-2'!I11 -> 0 | H8: ='明细表I5-2'!G11+'明细表I5-2'!J11-'明细表I5-2'!K11 -> 0 | I8: ='明细表I5-2'!O11 -> 0 | J8: =I8-E8 -> 0 | K8: =IF(AND(E8=0,J8=0),0,IF(AND(E8=0,J8>0),1,J8/E8)) -> 0
A9: ='明细表I5-2'!A12 -> 预付工程款 | B9: ='明细表I5-2'!B12 -> 0 | C9: ='明细表I5-2'!F12 -> 0 | D9: ='明细表I5-2'!G12 -> 0 | E9: ='明细表I5-2'!L12 -> 0 | F9: ='明细表I5-2'!E12 -> 0 | G9: ='明细表I5-2'!F12+'明细表I5-2'!H12-'明细表I5-2'!I12 -> 0 | H9: ='明细表I5-2'!G12+'明细表I5-2'!J12-'明细表I5-2'!K12 -> 0 | I9: ='明细表I5-2'!O12 -> 0 | J9: =I9-E9 -> 0 | K9: =IF(AND(E9=0,J9=0),0,IF(AND(E9=0,J9>0),1,J9/E9)) -> 0
A10: ='明细表I5-2'!A13 -> 预付房屋、设备款 | B10: ='明细表I5-2'!B13 -> 0 | C10: ='明细表I5-2'!F13 -> 0 | D10: ='明细表I5-2'!G13 -> 0 | E10: ='明细表I5-2'!L13 -> 0 | F10: ='明细表I5-2'!E13 -> 0 | G10: ='明细表I5-2'!F13+'明细表I5-2'!H13-'明细表I5-2'!I13 -> 0 | H10: ='明细表I5-2'!G13+'明细表I5-2'!J13-'明细表I5-2'!K13 -> 0 | I10: ='明细表I5-2'!O13 -> 0 | J10: =I10-E10 -> 0 | K10: =IF(AND(E10=0,J10=0),0,IF(AND(E10=0,J10>0),1,J10/E10)) -> 0
A11: ='明细表I5-2'!A14 -> 无形资产预付款 | B11: ='明细表I5-2'!B14 -> 0 | C11: ='明细表I5-2'!F14 -> 0 | D11: ='明细表I5-2'!G14 -> 0 | E11: ='明细表I5-2'!L14 -> 0 | F11: ='明细表I5-2'!E14 -> 0 | G11: ='明细表I5-2'!F14+'明细表I5-2'!H14-'明细表I5-2'!I14 -> 0 | H11: ='明细表I5-2'!G14+'明细表I5-2'!J14-'明细表I5-2'!K14 -> 0 | I11: ='明细表I5-2'!O14 -> 0 | J11: =I11-E11 -> 0 | K11: =IF(AND(E11=0,J11=0),0,IF(AND(E11=0,J11>0),1,J11/E11)) -> 0
A12: ='明细表I5-2'!A15 -> 预付投资款 | B12: ='明细表I5-2'!B15 -> 0 | C12: ='明细表I5-2'!F15 -> 0 | D12: ='明细表I5-2'!G15 -> 0 | E12: ='明细表I5-2'!L15 -> 0 | F12: ='明细表I5-2'!E15 -> 0 | G12: ='明细表I5-2'!F15+'明细表I5-2'!H15-'明细表I5-2'!I15 -> 0 | H12: ='明细表I5-2'!G15+'明细表I5-2'!J15-'明细表I5-2'!K15 -> 0 | I12: ='明细表I5-2'!O15 -> 0 | J12: =I12-E12 -> 0 | K12: =IF(AND(E12=0,J12=0),0,IF(AND(E12=0,J12>0),1,J12/E12)) -> 0
A13: ='明细表I5-2'!A16 -> 委托贷款 | B13: ='明细表I5-2'!B16 -> 0 | C13: ='明细表I5-2'!F16 -> 0 | D13: ='明细表I5-2'!G16 -> 0 | E13: ='明细表I5-2'!L16 -> 0 | F13: ='明细表I5-2'!E16 -> 0 | G13: ='明细表I5-2'!F16+'明细表I5-2'!H16-'明细表I5-2'!I16 -> 0 | H13: ='明细表I5-2'!G16+'明细表I5-2'!J16-'明细表I5-2'!K16 -> 0 | I13: ='明细表I5-2'!O16 -> 0 | J13: =I13-E13 -> 0 | K13: =IF(AND(E13=0,J13=0),0,IF(AND(E13=0,J13>0),1,J13/E13)) -> 0
A14: ='明细表I5-2'!A17 -> 合同资产 | B14: ='明细表I5-2'!B17 -> 0 | C14: ='明细表I5-2'!F17 -> 0 | D14: ='明细表I5-2'!G17 -> 0 | E14: ='明细表I5-2'!L17 -> 0 | F14: ='明细表I5-2'!E17 -> 0 | G14: ='明细表I5-2'!F17+'明细表I5-2'!H17-'明细表I5-2'!I17 -> 0 | H14: ='明细表I5-2'!G17+'明细表I5-2'!J17-'明细表I5-2'!K17 -> 0 | I14: ='明细表I5-2'!O17 -> 0 | J14: =I14-E14 -> 0 | K14: =IF(AND(E14=0,J14=0),0,IF(AND(E14=0,J14>0),1,J14/E14)) -> 0
A15: ='明细表I5-2'!A18 -> 合同取得成本 | B15: ='明细表I5-2'!B18 -> 0 | C15: ='明细表I5-2'!F18 -> 0 | D15: ='明细表I5-2'!G18 -> 0 | E15: ='明细表I5-2'!L18 -> 0 | F15: ='明细表I5-2'!E18 -> 0 | G15: ='明细表I5-2'!F18+'明细表I5-2'!H18-'明细表I5-2'!I18 -> 0 | H15: ='明细表I5-2'!G18+'明细表I5-2'!J18-'明细表I5-2'!K18 -> 0 | I15: ='明细表I5-2'!O18 -> 0 | J15: =I15-E15 -> 0 | K15: =IF(AND(E15=0,J15=0),0,IF(AND(E15=0,J15>0),1,J15/E15)) -> 0
A16: ='明细表I5-2'!A19 -> 合同履约成本 | B16: ='明细表I5-2'!B19 -> 0 | C16: ='明细表I5-2'!F19 -> 0 | D16: ='明细表I5-2'!G19 -> 0 | E16: ='明细表I5-2'!L19 -> 0 | F16: ='明细表I5-2'!E19 -> 0 | G16: ='明细表I5-2'!F19+'明细表I5-2'!H19-'明细表I5-2'!I19 -> 0 | H16: ='明细表I5-2'!G19+'明细表I5-2'!J19-'明细表I5-2'!K19 -> 0 | I16: ='明细表I5-2'!O19 -> 0 | J16: =I16-E16 -> 0 | K16: =IF(AND(E16=0,J16=0),0,IF(AND(E16=0,J16>0),1,J16/E16)) -> 0
A17: ='明细表I5-2'!A20 -> 应收退货成本 | B17: ='明细表I5-2'!B20 -> 0 | C17: ='明细表I5-2'!F20 -> 0 | D17: ='明细表I5-2'!G20 -> 0 | E17: ='明细表I5-2'!L20 -> 0 | F17: ='明细表I5-2'!E20 -> 0 | G17: ='明细表I5-2'!F20+'明细表I5-2'!H20-'明细表I5-2'!I20 -> 0 | H17: ='明细表I5-2'!G20+'明细表I5-2'!J20-'明细表I5-2'!K20 -> 0 | I17: ='明细表I5-2'!O20 -> 0 | J17: =I17-E17 -> 0 | K17: =IF(AND(E17=0,J17=0),0,IF(AND(E17=0,J17>0),1,J17/E17)) -> 0
A18: ='明细表I5-2'!A21 -> …… | B18: ='明细表I5-2'!B21 -> 0 | C18: ='明细表I5-2'!F21 -> 0 | D18: ='明细表I5-2'!G21 -> 0 | E18: ='明细表I5-2'!L21 -> 0 | F18: ='明细表I5-2'!E21 -> 0 | G18: ='明细表I5-2'!F21+'明细表I5-2'!H21-'明细表I5-2'!I21 -> 0 | H18: ='明细表I5-2'!G21+'明细表I5-2'!J21-'明细表I5-2'!K21 -> 0 | I18: ='明细表I5-2'!O21 -> 0 | J18: =I18-E18 -> 0 | K18: =IF(AND(E18=0,J18=0),0,IF(AND(E18=0,J18>0),1,J18/E18)) -> 0
A19: 合计 | B19: =SUM(B8:B18) -> 0 | C19: =SUM(C8:C18) -> 0 | D19: =SUM(D8:D18) -> 0 | E19: =SUM(E8:E18) -> 0 | F19: =SUM(F8:F18) -> 0 | G19: =SUM(G8:G18) -> 0 | H19: =SUM(H8:H18) -> 0 | I19: =SUM(I8:I18) -> 0 | J19: =I19-E19 -> 0 | K19: =IF(AND(E19=0,J19=0),0,IF(AND(E19=0,J19>0),1,J19/E19)) -> 0
A20: 减值准备：
A21: =A8 -> 预付土地出让金 | B21: ='明细表I5-2'!B24 -> 0 | C21: ='明细表I5-2'!F24 -> 0 | D21: ='明细表I5-2'!G24 -> 0 | E21: ='明细表I5-2'!L24 -> 0 | F21: ='明细表I5-2'!E24 -> 0 | G21: ='明细表I5-2'!F24+'明细表I5-2'!H24-'明细表I5-2'!I24 -> 0 | H21: ='明细表I5-2'!G24+'明细表I5-2'!J24-'明细表I5-2'!K24 -> 0 | I21: ='明细表I5-2'!O24 -> 0 | J21: =I21-E21 -> 0 | K21: =IF(AND(E21=0,J21=0),0,IF(AND(E21=0,J21>0),1,J21/E21)) -> 0
A22: =A9 -> 预付工程款 | B22: ='明细表I5-2'!B25 -> 0 | C22: ='明细表I5-2'!F25 -> 0 | D22: ='明细表I5-2'!G25 -> 0 | E22: ='明细表I5-2'!L25 -> 0 | F22: ='明细表I5-2'!E25 -> 0 | G22: ='明细表I5-2'!F25+'明细表I5-2'!H25-'明细表I5-2'!I25 -> 0 | H22: ='明细表I5-2'!G25+'明细表I5-2'!J25-'明细表I5-2'!K25 -> 0 | I22: ='明细表I5-2'!O25 -> 0 | J22: =I22-E22 -> 0 | K22: =IF(AND(E22=0,J22=0),0,IF(AND(E22=0,J22>0),1,J22/E22)) -> 0
A23: =A10 -> 预付房屋、设备款 | B23: ='明细表I5-2'!B26 -> 0 | C23: ='明细表I5-2'!F26 -> 0 | D23: ='明细表I5-2'!G26 -> 0 | E23: ='明细表I5-2'!L26 -> 0 | F23: ='明细表I5-2'!E26 -> 0 | G23: ='明细表I5-2'!F26+'明细表I5-2'!H26-'明细表I5-2'!I26 -> 0 | H23: ='明细表I5-2'!G26+'明细表I5-2'!J26-'明细表I5-2'!K26 -> 0 | I23: ='明细表I5-2'!O26 -> 0 | J23: =I23-E23 -> 0 | K23: =IF(AND(E23=0,J23=0),0,IF(AND(E23=0,J23>0),1,J23/E23)) -> 0
A24: =A11 -> 无形资产预付款 | B24: ='明细表I5-2'!B27 -> 0 | C24: ='明细表I5-2'!F27 -> 0 | D24: ='明细表I5-2'!G27 -> 0 | E24: ='明细表I5-2'!L27 -> 0 | F24: ='明细表I5-2'!E27 -> 0 | G24: ='明细表I5-2'!F27+'明细表I5-2'!H27-'明细表I5-2'!I27 -> 0 | H24: ='明细表I5-2'!G27+'明细表I5-2'!J27-'明细表I5-2'!K27 -> 0 | I24: ='明细表I5-2'!O27 -> 0 | J24: =I24-E24 -> 0 | K24: =IF(AND(E24=0,J24=0),0,IF(AND(E24=0,J24>0),1,J24/E24)) -> 0
A25: =A12 -> 预付投资款 | B25: ='明细表I5-2'!B28 -> 0 | C25: ='明细表I5-2'!F28 -> 0 | D25: ='明细表I5-2'!G28 -> 0 | E25: ='明细表I5-2'!L28 -> 0 | F25: ='明细表I5-2'!E28 -> 0 | G25: ='明细表I5-2'!F28+'明细表I5-2'!H28-'明细表I5-2'!I28 -> 0 | H25: ='明细表I5-2'!G28+'明细表I5-2'!J28-'明细表I5-2'!K28 -> 0 | I25: ='明细表I5-2'!O28 -> 0 | J25: =I25-E25 -> 0 | K25: =IF(AND(E25=0,J25=0),0,IF(AND(E25=0,J25>0),1,J25/E25)) -> 0
A26: =A13 -> 委托贷款 | B26: ='明细表I5-2'!B29 -> 0 | C26: ='明细表I5-2'!F29 -> 0 | D26: ='明细表I5-2'!G29 -> 0 | E26: ='明细表I5-2'!L29 -> 0 | F26: ='明细表I5-2'!E29 -> 0 | G26: ='明细表I5-2'!F29+'明细表I5-2'!H29-'明细表I5-2'!I29 -> 0 | H26: ='明细表I5-2'!G29+'明细表I5-2'!J29-'明细表I5-2'!K29 -> 0 | I26: ='明细表I5-2'!O29 -> 0 | J26: =I26-E26 -> 0 | K26: =IF(AND(E26=0,J26=0),0,IF(AND(E26=0,J26>0),1,J26/E26)) -> 0
A27: =A14 -> 合同资产 | B27: ='明细表I5-2'!B30 -> 0 | C27: ='明细表I5-2'!F30 -> 0 | D27: ='明细表I5-2'!G30 -> 0 | E27: ='明细表I5-2'!L30 -> 0 | F27: ='明细表I5-2'!E30 -> 0 | G27: ='明细表I5-2'!F30+'明细表I5-2'!H30-'明细表I5-2'!I30 -> 0 | H27: ='明细表I5-2'!G30+'明细表I5-2'!J30-'明细表I5-2'!K30 -> 0 | I27: ='明细表I5-2'!O30 -> 0 | J27: =I27-E27 -> 0 | K27: =IF(AND(E27=0,J27=0),0,IF(AND(E27=0,J27>0),1,J27/E27)) -> 0
A28: =A15 -> 合同取得成本 | B28: ='明细表I5-2'!B31 -> 0 | C28: ='明细表I5-2'!F31 -> 0 | D28: ='明细表I5-2'!G31 -> 0 | E28: ='明细表I5-2'!L31 -> 0 | F28: ='明细表I5-2'!E31 -> 0 | G28: ='明细表I5-2'!F31+'明细表I5-2'!H31-'明细表I5-2'!I31 -> 0 | H28: ='明细表I5-2'!G31+'明细表I5-2'!J31-'明细表I5-2'!K31 -> 0 | I28: ='明细表I5-2'!O31 -> 0 | J28: =I28-E28 -> 0 | K28: =IF(AND(E28=0,J28=0),0,IF(AND(E28=0,J28>0),1,J28/E28)) -> 0
A29: =A16 -> 合同履约成本 | B29: ='明细表I5-2'!B32 -> 0 | C29: ='明细表I5-2'!F32 -> 0 | D29: ='明细表I5-2'!G32 -> 0 | E29: ='明细表I5-2'!L32 -> 0 | F29: ='明细表I5-2'!E32 -> 0 | G29: ='明细表I5-2'!F32+'明细表I5-2'!H32-'明细表I5-2'!I32 -> 0 | H29: ='明细表I5-2'!G32+'明细表I5-2'!J32-'明细表I5-2'!K32 -> 0 | I29: ='明细表I5-2'!O32 -> 0 | J29: =I29-E29 -> 0 | K29: =IF(AND(E29=0,J29=0),0,IF(AND(E29=0,J29>0),1,J29/E29)) -> 0
A30: =A17 -> 应收退货成本 | B30: ='明细表I5-2'!B33 -> 0 | C30: ='明细表I5-2'!F33 -> 0 | D30: ='明细表I5-2'!G33 -> 0 | E30: ='明细表I5-2'!L33 -> 0 | F30: ='明细表I5-2'!E33 -> 0 | G30: ='明细表I5-2'!F33+'明细表I5-2'!H33-'明细表I5-2'!I33 -> 0 | H30: ='明细表I5-2'!G33+'明细表I5-2'!J33-'明细表I5-2'!K33 -> 0 | I30: ='明细表I5-2'!O33 -> 0 | J30: =I30-E30 -> 0 | K30: =IF(AND(E30=0,J30=0),0,IF(AND(E30=0,J30>0),1,J30/E30)) -> 0
A31: =A18 -> …… | B31: ='明细表I5-2'!B34 -> 0 | C31: ='明细表I5-2'!F34 -> 0 | D31: ='明细表I5-2'!G34 -> 0 | E31: ='明细表I5-2'!L34 -> 0 | F31: ='明细表I5-2'!E34 -> 0 | G31: ='明细表I5-2'!F34+'明细表I5-2'!H34-'明细表I5-2'!I34 -> 0 | H31: ='明细表I5-2'!G34+'明细表I5-2'!J34-'明细表I5-2'!K34 -> 0 | I31: ='明细表I5-2'!O34 -> 0 | J31: =I31-E31 -> 0 | K31: =IF(AND(E31=0,J31=0),0,IF(AND(E31=0,J31>0),1,J31/E31)) -> 0
A32: 合计 | B32: =SUM(B21:B31) -> 0 | C32: =SUM(C21:C31) -> 0 | D32: =SUM(D21:D31) -> 0 | E32: =SUM(E21:E31) -> 0 | F32: =SUM(F21:F31) -> 0 | G32: =SUM(G21:G31) -> 0 | H32: =SUM(H21:H31) -> 0 | I32: =SUM(I21:I31) -> 0 | J32: =I32-E32 -> 0 | K32: =IF(AND(E32=0,J32=0),0,IF(AND(E32=0,J32>0),1,J32/E32)) -> 0
A33: 净值：
A34: =A21 -> 预付土地出让金 | B34: =B8-B21 -> 0 | C34: =C8-C21 -> 0 | D34: =D8-D21 -> 0 | E34: =E8-E21 -> 0 | F34: =F8-F21 -> 0 | G34: =G8-G21 -> 0 | H34: =H8-H21 -> 0 | I34: =I8-I21 -> 0 | ... K34: =K8-K21 -> 0
A35: =A22 -> 预付工程款 | B35: =B9-B22 -> 0 | C35: =C9-C22 -> 0 | D35: =D9-D22 -> 0 | E35: =E9-E22 -> 0 | F35: =F9-F22 -> 0 | G35: =G9-G22 -> 0 | H35: =H9-H22 -> 0 | I35: =I9-I22 -> 0 | ... K35: =K9-K22 -> 0
A36: =A23 -> 预付房屋、设备款 | B36: =B10-B23 -> 0 | C36: =C10-C23 -> 0 | D36: =D10-D23 -> 0 | E36: =E10-E23 -> 0 | F36: =F10-F23 -> 0 | G36: =G10-G23 -> 0 | H36: =H10-H23 -> 0 | I36: =I10-I23 -> 0 | ... K36: =K10-K23 -> 0
A37: =A24 -> 无形资产预付款 | B37: =B11-B24 -> 0 | C37: =C11-C24 -> 0 | D37: =D11-D24 -> 0 | E37: =E11-E24 -> 0 | F37: =F11-F24 -> 0 | G37: =G11-G24 -> 0 | H37: =H11-H24 -> 0 | I37: =I11-I24 -> 0 | ... K37: =K11-K24 -> 0
A38: =A25 -> 预付投资款 | B38: =B12-B25 -> 0 | C38: =C12-C25 -> 0 | D38: =D12-D25 -> 0 | E38: =E12-E25 -> 0 | F38: =F12-F25 -> 0 | G38: =G12-G25 -> 0 | H38: =H12-H25 -> 0 | I38: =I12-I25 -> 0 | ... K38: =K12-K25 -> 0
A39: =A26 -> 委托贷款 | B39: =B13-B26 -> 0 | C39: =C13-C26 -> 0 | D39: =D13-D26 -> 0 | E39: =E13-E26 -> 0 | F39: =F13-F26 -> 0 | G39: =G13-G26 -> 0 | H39: =H13-H26 -> 0 | I39: =I13-I26 -> 0 | ... K39: =K13-K26 -> 0
A40: =A27 -> 合同资产 | B40: =B14-B27 -> 0 | C40: =C14-C27 -> 0 | D40: =D14-D27 -> 0 | E40: =E14-E27 -> 0 | F40: =F14-F27 -> 0 | G40: =G14-G27 -> 0 | H40: =H14-H27 -> 0 | I40: =I14-I27 -> 0 | ... K40: =K14-K27 -> 0
...

Sheet 附注披露（上市公司）
A1: 致同会计师事务所
A2: 其他非流动资产附注披露表（上市公司）
A3: =底稿目录!A2 -> 被审计单位： | B3: =底稿目录!A4 -> 编制人： | D3: =底稿目录!A5 -> 编制日期： | F3: 索引号：
A4: =底稿目录!A3 -> 截止日：202X年12月31日 | B4: =底稿目录!A6 -> 复核人： | D4: =底稿目录!A7 -> 复核日期： | F4: 页次：
A5: 其他非流动资产（注：根据实际情况列示；不存在的项目请删除）
A6: 项 目 | B6: 期末数 | E6: 上年年末数
B7: 账面余额 | C7: 减值准备 | D7: 账面价值 | E7: 账面余额 | F7: 减值准备 | G7: 账面价值
A8: ='明细表I5-2'!A11 -> 预付土地出让金 | B8: =SUMIF('明细表I5-2'!$A$10:$A$22,$A8,'明细表I5-2'!$O$10:$O$22) -> 0 | C8: =SUMIF('明细表I5-2'!$A$23:$A$35,$A8,'明细表I5-2'!$O$23:$O$35) -> 0 | D8: =B8-C8 -> 0 | E8: =SUMIF('明细表I5-2'!$A$10:$A$22,$A8,'明细表I5-2'!$L$10:$L$22) -> 0 | F8: =SUMIF('明细表I5-2'!$A$23:$A$35,$A8,'明细表I5-2'!$L$23:$L$35) -> 0 | G8: =E8-F8 -> 0
A9: ='明细表I5-2'!A12 -> 预付工程款 | B9: =SUMIF('明细表I5-2'!$A$10:$A$22,$A9,'明细表I5-2'!$O$10:$O$22) -> 0 | C9: =SUMIF('明细表I5-2'!$A$23:$A$35,$A9,'明细表I5-2'!$O$23:$O$35) -> 0 | D9: =B9-C9 -> 0 | E9: =SUMIF('明细表I5-2'!$A$10:$A$22,$A9,'明细表I5-2'!$L$10:$L$22) -> 0 | F9: =SUMIF('明细表I5-2'!$A$23:$A$35,$A9,'明细表I5-2'!$L$23:$L$35) -> 0 | G9: =E9-F9 -> 0
A10: ='明细表I5-2'!A13 -> 预付房屋、设备款 | B10: =SUMIF('明细表I5-2'!$A$10:$A$22,$A10,'明细表I5-2'!$O$10:$O$22) -> 0 | C10: =SUMIF('明细表I5-2'!$A$23:$A$35,$A10,'明细表I5-2'!$O$23:$O$35) -> 0 | D10: =B10-C10 -> 0 | E10: =SUMIF('明细表I5-2'!$A$10:$A$22,$A10,'明细表I5-2'!$L$10:$L$22) -> 0 | F10: =SUMIF('明细表I5-2'!$A$23:$A$35,$A10,'明细表I5-2'!$L$23:$L$35) -> 0 | G10: =E10-F10 -> 0
A11: ='明细表I5-2'!A14 -> 无形资产预付款 | B11: =SUMIF('明细表I5-2'!$A$10:$A$22,$A11,'明细表I5-2'!$O$10:$O$22) -> 0 | C11: =SUMIF('明细表I5-2'!$A$23:$A$35,$A11,'明细表I5-2'!$O$23:$O$35) -> 0 | D11: =B11-C11 -> 0 | E11: =SUMIF('明细表I5-2'!$A$10:$A$22,$A11,'明细表I5-2'!$L$10:$L$22) -> 0 | F11: =SUMIF('明细表I5-2'!$A$23:$A$35,$A11,'明细表I5-2'!$L$23:$L$35) -> 0 | G11: =E11-F11 -> 0
A12: ='明细表I5-2'!A15 -> 预付投资款 | B12: =SUMIF('明细表I5-2'!$A$10:$A$22,$A12,'明细表I5-2'!$O$10:$O$22) -> 0 | C12: =SUMIF('明细表I5-2'!$A$23:$A$35,$A12,'明细表I5-2'!$O$23:$O$35) -> 0 | D12: =B12-C12 -> 0 | E12: =SUMIF('明细表I5-2'!$A$10:$A$22,$A12,'明细表I5-2'!$L$10:$L$22) -> 0 | F12: =SUMIF('明细表I5-2'!$A$23:$A$35,$A12,'明细表I5-2'!$L$23:$L$35) -> 0 | G12: =E12-F12 -> 0
A13: ='明细表I5-2'!A16 -> 委托贷款 | B13: =SUMIF('明细表I5-2'!$A$10:$A$22,$A13,'明细表I5-2'!$O$10:$O$22) -> 0 | C13: =SUMIF('明细表I5-2'!$A$23:$A$35,$A13,'明细表I5-2'!$O$23:$O$35) -> 0 | D13: =B13-C13 -> 0 | E13: =SUMIF('明细表I5-2'!$A$10:$A$22,$A13,'明细表I5-2'!$L$10:$L$22) -> 0 | F13: =SUMIF('明细表I5-2'!$A$23:$A$35,$A13,'明细表I5-2'!$L$23:$L$35) -> 0 | G13: =E13-F13 -> 0
A14: ='明细表I5-2'!A17 -> 合同资产 | B14: =SUMIF('明细表I5-2'!$A$10:$A$22,$A14,'明细表I5-2'!$O$10:$O$22) -> 0 | C14: =SUMIF('明细表I5-2'!$A$23:$A$35,$A14,'明细表I5-2'!$O$23:$O$35) -> 0 | D14: =B14-C14 -> 0 | E14: =SUMIF('明细表I5-2'!$A$10:$A$22,$A14,'明细表I5-2'!$L$10:$L$22) -> 0 | F14: =SUMIF('明细表I5-2'!$A$23:$A$35,$A14,'明细表I5-2'!$L$23:$L$35) -> 0 | G14: =E14-F14 -> 0
A15: ='明细表I5-2'!A18 -> 合同取得成本 | B15: =SUMIF('明细表I5-2'!$A$10:$A$22,$A15,'明细表I5-2'!$O$10:$O$22) -> 0 | C15: =SUMIF('明细表I5-2'!$A$23:$A$35,$A15,'明细表I5-2'!$O$23:$O$35) -> 0 | D15: =B15-C15 -> 0 | E15: =SUMIF('明细表I5-2'!$A$10:$A$22,$A15,'明细表I5-2'!$L$10:$L$22) -> 0 | F15: =SUMIF('明细表I5-2'!$A$23:$A$35,$A15,'明细表I5-2'!$L$23:$L$35) -> 0 | G15: =E15-F15 -> 0
A16: ='明细表I5-2'!A19 -> 合同履约成本 | B16: =SUMIF('明细表I5-2'!$A$10:$A$22,$A16,'明细表I5-2'!$O$10:$O$22) -> 0 | C16: =SUMIF('明细表I5-2'!$A$23:$A$35,$A16,'明细表I5-2'!$O$23:$O$35) -> 0 | D16: =B16-C16 -> 0 | E16: =SUMIF('明细表I5-2'!$A$10:$A$22,$A16,'明细表I5-2'!$L$10:$L$22) -> 0 | F16: =SUMIF('明细表I5-2'!$A$23:$A$35,$A16,'明细表I5-2'!$L$23:$L$35) -> 0 | G16: =E16-F16 -> 0
A17: ='明细表I5-2'!A20 -> 应收退货成本 | B17: =SUMIF('明细表I5-2'!$A$10:$A$22,$A17,'明细表I5-2'!$O$10:$O$22) -> 0 | C17: =SUMIF('明细表I5-2'!$A$23:$A$35,$A17,'明细表I5-2'!$O$23:$O$35) -> 0 | D17: =B17-C17 -> 0 | E17: =SUMIF('明细表I5-2'!$A$10:$A$22,$A17,'明细表I5-2'!$L$10:$L$22) -> 0 | F17: =SUMIF('明细表I5-2'!$A$23:$A$35,$A17,'明细表I5-2'!$L$23:$L$35) -> 0 | G17: =E17-F17 -> 0
A18: ='明细表I5-2'!A21 -> …… | B18: =SUMIF('明细表I5-2'!$A$10:$A$22,$A18,'明细表I5-2'!$O$10:$O$22) -> 0 | C18: =SUMIF('明细表I5-2'!$A$23:$A$35,$A18,'明细表I5-2'!$O$23:$O$35) -> 0 | D18: =B18-C18 -> 0 | E18: =SUMIF('明细表I5-2'!$A$10:$A$22,$A18,'明细表I5-2'!$L$10:$L$22) -> 0 | F18: =SUMIF('明细表I5-2'!$A$23:$A$35,$A18,'明细表I5-2'!$L$23:$L$35) -> 0 | G18: =E18-F18 -> 0
A19: 合 计 | B19: =SUM(B8:B18) -> 0 | C19: =SUM(C8:C18) -> 0 | D19: =SUM(D8:D18) -> 0 | E19: =SUM(E8:E18) -> 0 | F19: =SUM(F8:F18) -> 0 | G19: =SUM(G8:G18) -> 0
A20: 说明：

Sheet 附注披露（国有企业）
A1: 致同会计师事务所
A2: 其他非流动资产附注披露表（国有企业）
A3: =底稿目录!A2 -> 被审计单位： | B3: =底稿目录!A4 -> 编制人： | C3: =底稿目录!A5 -> 编制日期： | D3: 索引号：
A4: =底稿目录!A3 -> 截止日：202X年12月31日 | B4: 复核人： | C4: =底稿目录!A7 -> 复核日期： | D4: 页次：
A5: 其他非流动资产
A6: 项 目 | B6: 期末余额 | C6: 年初余额
A7: ='明细表I5-2'!A11 -> 预付土地出让金 | B7: =SUMIF('明细表I5-2'!$A$36:$A$48,$A7,'明细表I5-2'!$O$36:$O$48) -> 0 | C7: =SUMIF('明细表I5-2'!$A$36:$A$48,$A7,'明细表I5-2'!$L$36:$L$48) -> 0
A8: ='明细表I5-2'!A12 -> 预付工程款 | B8: =SUMIF('明细表I5-2'!$A$36:$A$48,$A8,'明细表I5-2'!$O$36:$O$48) -> 0 | C8: =SUMIF('明细表I5-2'!$A$36:$A$48,$A8,'明细表I5-2'!$L$36:$L$48) -> 0
A9: ='明细表I5-2'!A13 -> 预付房屋、设备款 | B9: =SUMIF('明细表I5-2'!$A$36:$A$48,$A9,'明细表I5-2'!$O$36:$O$48) -> 0 | C9: =SUMIF('明细表I5-2'!$A$36:$A$48,$A9,'明细表I5-2'!$L$36:$L$48) -> 0
A10: ='明细表I5-2'!A14 -> 无形资产预付款 | B10: =SUMIF('明细表I5-2'!$A$36:$A$48,$A10,'明细表I5-2'!$O$36:$O$48) -> 0 | C10: =SUMIF('明细表I5-2'!$A$36:$A$48,$A10,'明细表I5-2'!$L$36:$L$48) -> 0
A11: ='明细表I5-2'!A15 -> 预付投资款 | B11: =SUMIF('明细表I5-2'!$A$36:$A$48,$A11,'明细表I5-2'!$O$36:$O$48) -> 0 | C11: =SUMIF('明细表I5-2'!$A$36:$A$48,$A11,'明细表I5-2'!$L$36:$L$48) -> 0
A12: ='明细表I5-2'!A16 -> 委托贷款 | B12: =SUMIF('明细表I5-2'!$A$36:$A$48,$A12,'明细表I5-2'!$O$36:$O$48) -> 0 | C12: =SUMIF('明细表I5-2'!$A$36:$A$48,$A12,'明细表I5-2'!$L$36:$L$48) -> 0
A13: ='明细表I5-2'!A17 -> 合同资产 | B13: =SUMIF('明细表I5-2'!$A$36:$A$48,$A13,'明细表I5-2'!$O$36:$O$48) -> 0 | C13: =SUMIF('明细表I5-2'!$A$36:$A$48,$A13,'明细表I5-2'!$L$36:$L$48) -> 0
A14: ='明细表I5-2'!A18 -> 合同取得成本 | B14: =SUMIF('明细表I5-2'!$A$36:$A$48,$A14,'明细表I5-2'!$O$36:$O$48) -> 0 | C14: =SUMIF('明细表I5-2'!$A$36:$A$48,$A14,'明细表I5-2'!$L$36:$L$48) -> 0
A15: ='明细表I5-2'!A19 -> 合同履约成本 | B15: =SUMIF('明细表I5-2'!$A$36:$A$48,$A15,'明细表I5-2'!$O$36:$O$48) -> 0 | C15: =SUMIF('明细表I5-2'!$A$36:$A$48,$A15,'明细表I5-2'!$L$36:$L$48) -> 0
A16: ='明细表I5-2'!A20 -> 应收退货成本 | B16: =SUMIF('明细表I5-2'!$A$36:$A$48,$A16,'明细表I5-2'!$O$36:$O$48) -> 0 | C16: =SUMIF('明细表I5-2'!$A$36:$A$48,$A16,'明细表I5-2'!$L$36:$L$48) -> 0
A17: ='明细表I5-2'!A21 -> …… | B17: =SUMIF('明细表I5-2'!$A$36:$A$48,$A17,'明细表I5-2'!$O$36:$O$48) -> 0 | C17: =SUMIF('明细表I5-2'!$A$36:$A$48,$A17,'明细表I5-2'!$L$36:$L$48) -> 0
A18: 合 计 | B18: =SUM(B7:B17) -> 0 | C18: =SUM(C7:C17) -> 0

Sheet 明细表I5-2
A1: 致同会计师事务所
A2: 其他非流动资产明细表
A3: =底稿目录!A2 -> 被审计单位： | E3: =底稿目录!A4 -> 编制人： | K3: =底稿目录!A5 -> 编制日期： | O3: 索引号： | P3: I5-2
A4: =底稿目录!A3 -> 截止日：202X年12月31日 | E4: =底稿目录!A6 -> 复核人： | K4: =底稿目录!A7 -> 复核日期： | O4: 页次：
A5: 一、审计目标:
A6: 复核其他非流动资产确认和会计处理的正确性。
A7: 二、审计过程：
A8: 项目 | B8: 未审数 | F8: 期初调整 | H8: 账项调整 | J8: 重分类调整 | L8: 审定数 | P8: 备注
B9: 期初数 | C9: 本期增加 | D9: 本期减少 | E9: 期末数 | F9: 账项调整 | G9: 重分类调整 | H9: 本期增加 | I9: 本期减少 | J9: 本期增加 | K9: 本期减少 | L9: 期初数 | M9: 本期增加 | N9: 本期减少 | O9: 期末数
A10: 其他非流动资产原值：
A11: 预付土地出让金 | E11: =SUM(B11:C11)-D11 -> 0 | L11: =B11+F11+G11 -> 0 | M11: =C11+H11+J11 -> 0 | N11: =D11+I11+K11 -> 0 | O11: =L11+M11-N11 -> 0
A12: 预付工程款 | E12: =SUM(B12:C12)-D12 -> 0 | L12: =B12+F12+G12 -> 0 | M12: =C12+H12+J12 -> 0 | N12: =D12+I12+K12 -> 0 | O12: =L12+M12-N12 -> 0
A13: 预付房屋、设备款 | E13: =SUM(B13:C13)-D13 -> 0 | L13: =B13+F13+G13 -> 0 | M13: =C13+H13+J13 -> 0 | N13: =D13+I13+K13 -> 0 | O13: =L13+M13-N13 -> 0
A14: 无形资产预付款 | E14: =SUM(B14:C14)-D14 -> 0 | L14: =B14+F14+G14 -> 0 | M14: =C14+H14+J14 -> 0 | N14: =D14+I14+K14 -> 0 | O14: =L14+M14-N14 -> 0
A15: 预付投资款 | E15: =SUM(B15:C15)-D15 -> 0 | L15: =B15+F15+G15 -> 0 | M15: =C15+H15+J15 -> 0 | N15: =D15+I15+K15 -> 0 | O15: =L15+M15-N15 -> 0
A16: 委托贷款 | E16: =SUM(B16:C16)-D16 -> 0 | L16: =B16+F16+G16 -> 0 | M16: =C16+H16+J16 -> 0 | N16: =D16+I16+K16 -> 0 | O16: =L16+M16-N16 -> 0
A17: 合同资产 | E17: =SUM(B17:C17)-D17 -> 0 | L17: =B17+F17+G17 -> 0 | M17: =C17+H17+J17 -> 0 | N17: =D17+I17+K17 -> 0 | O17: =L17+M17-N17 -> 0 | Q17: 相关内容索引至D7 合同资产
A18: 合同取得成本 | E18: =SUM(B18:C18)-D18 -> 0 | L18: =B18+F18+G18 -> 0 | M18: =C18+H18+J18 -> 0 | N18: =D18+I18+K18 -> 0 | O18: =L18+M18-N18 -> 0 | Q18: 相关内容索引至M12 合同取得成本及减值准备
A19: 合同履约成本 | E19: =SUM(B19:C19)-D19 -> 0 | L19: =B19+F19+G19 -> 0 | M19: =C19+H19+J19 -> 0 | N19: =D19+I19+K19 -> 0 | O19: =L19+M19-N19 -> 0 | Q19: 相关内容索引至G2-13 合同履约成本
A20: 应收退货成本 | E20: =SUM(B20:C20)-D20 -> 0 | L20: =B20+F20+G20 -> 0 | M20: =C20+H20+J20 -> 0 | N20: =D20+I20+K20 -> 0 | O20: =L20+M20-N20 -> 0
A21: …… | E21: =SUM(B21:C21)-D21 -> 0 | L21: =B21+F21+G21 -> 0 | M21: =C21+H21+J21 -> 0 | N21: =D21+I21+K21 -> 0 | O21: =L21+M21-N21 -> 0
A22: 合计 | B22: =SUM(B11:B21) -> 0 | C22: =SUM(C11:C21) -> 0 | D22: =SUM(D11:D21) -> 0 | E22: =SUM(E11:E21) -> 0 | F22: =SUM(F11:F21) -> 0 | G22: =SUM(G11:G21) -> 0 | H22: =SUM(H11:H21) -> 0 | I22: =SUM(I11:I21) -> 0 | ... O22: =SUM(O11:O21) -> 0
A23: 减值准备：
A24: =A11 -> 预付土地出让金 | E24: =SUM(B24:C24)-D24 -> 0 | L24: =B24+F24+G24 -> 0 | M24: =C24+H24+J24 -> 0 | N24: =D24+I24+K24 -> 0 | O24: =L24+M24-N24 -> 0
A25: =A12 -> 预付工程款 | E25: =SUM(B25:C25)-D25 -> 0 | L25: =B25+F25+G25 -> 0 | M25: =C25+H25+J25 -> 0 | N25: =D25+I25+K25 -> 0 | O25: =L25+M25-N25 -> 0
A26: =A13 -> 预付房屋、设备款 | E26: =SUM(B26:C26)-D26 -> 0 | L26: =B26+F26+G26 -> 0 | M26: =C26+H26+J26 -> 0 | N26: =D26+I26+K26 -> 0 | O26: =L26+M26-N26 -> 0
A27: =A14 -> 无形资产预付款 | E27: =SUM(B27:C27)-D27 -> 0 | L27: =B27+F27+G27 -> 0 | M27: =C27+H27+J27 -> 0 | N27: =D27+I27+K27 -> 0 | O27: =L27+M27-N27 -> 0
A28: =A15 -> 预付投资款 | E28: =SUM(B28:C28)-D28 -> 0 | L28: =B28+F28+G28 -> 0 | M28: =C28+H28+J28 -> 0 | N28: =D28+I28+K28 -> 0 | O28: =L28+M28-N28 -> 0
A29: =A16 -> 委托贷款 | E29: =SUM(B29:C29)-D29 -> 0 | L29: =B29+F29+G29 -> 0 | M29: =C29+H29+J29 -> 0 | N29: =D29+I29+K29 -> 0 | O29: =L29+M29-N29 -> 0
A30: =A17 -> 合同资产 | E30: =SUM(B30:C30)-D30 -> 0 | L30: =B30+F30+G30 -> 0 | M30: =C30+H30+J30 -> 0 | N30: =D30+I30+K30 -> 0 | O30: =L30+M30-N30 -> 0
A31: =A18 -> 合同取得成本 | E31: =SUM(B31:C31)-D31 -> 0 | L31: =B31+F31+G31 -> 0 | M31: =C31+H31+J31 -> 0 | N31: =D31+I31+K31 -> 0 | O31: =L31+M31-N31 -> 0
A32: =A19 -> 合同履约成本 | E32: =SUM(B32:C32)-D32 -> 0 | L32: =B32+F32+G32 -> 0 | M32: =C32+H32+J32 -> 0 | N32: =D32+I32+K32 -> 0 | O32: =L32+M32-N32 -> 0
A33: =A20 -> 应收退货成本 | E33: =SUM(B33:C33)-D33 -> 0 | L33: =B33+F33+G33 -> 0 | M33: =C33+H33+J33 -> 0 | N33: =D33+I33+K33 -> 0 | O33: =L33+M33-N33 -> 0
A34: =A21 -> …… | E34: =SUM(B34:C34)-D34 -> 0 | L34: =B34+F34+G34 -> 0 | M34: =C34+H34+J34 -> 0 | N34: =D34+I34+K34 -> 0 | O34: =L34+M34-N34 -> 0
A35: 合计 | B35: =SUM(B24:B34) -> 0 | C35: =SUM(C24:C34) -> 0 | D35: =SUM(D24:D34) -> 0 | E35: =SUM(E24:E34) -> 0 | F35: =SUM(F24:F34) -> 0 | G35: =SUM(G24:G34) -> 0 | H35: =SUM(H24:H34) -> 0 | I35: =SUM(I24:I34) -> 0 | ... O35: =SUM(O24:O34) -> 0
A36: 净值：
A37: =A24 -> 预付土地出让金 | B37: =B11-B24 -> 0 | C37: =C11-C24 -> 0 | D37: =D11-D24 -> 0 | E37: =E11-E24 -> 0 | F37: =F11-F24 -> 0 | G37: =G11-G24 -> 0 | H37: =H11-H24 -> 0 | I37: =I11-I24 -> 0 | ... O37: =O11-O24 -> 0
A38: =A25 -> 预付工程款 | B38: =B12-B25 -> 0 | C38: =C12-C25 -> 0 | D38: =D12-D25 -> 0 | E38: =E12-E25 -> 0 | F38: =F12-F25 -> 0 | G38: =G12-G25 -> 0 | H38: =H12-H25 -> 0 | I38: =I12-I25 -> 0 | ... O38: =O12-O25 -> 0
A39: =A26 -> 预付房屋、设备款 | B39: =B13-B26 -> 0 | C39: =C13-C26 -> 0 | D39: =D13-D26 -> 0 | E39: =E13-E26 -> 0 | F39: =F13-F26 -> 0 | G39: =G13-G26 -> 0 | H39: =H13-H26 -> 0 | I39: =I13-I26 -> 0 | ... O39: =O13-O26 -> 0
A40: =A27 -> 无形资产预付款 | B40: =B14-B27 -> 0 | C40: =C14-C27 -> 0 | D40: =D14-D27 -> 0 | E40: =E14-E27 -> 0 | F40: =F14-F27 -> 0 | G40: =G14-G27 -> 0 | H40: =H14-H27 -> 0 | I40: =I14-I27 -> 0 | ... O40: =O14-O27 -> 0
...

Sheet 调整分录汇总I5-3
A1: 致同会计师事务所
A2: 其他非流动资产调整分录汇总表
A3: =底稿目录!A2 -> 被审计单位： | D3: =底稿目录!A4 -> 编制人： | F3: =底稿目录!A5 -> 编制日期： | I3: 索引号： | J3: I5-3
A4: =底稿目录!A3 -> 截止日：202X年12月31日 | D4: =底稿目录!A6 -> 复核人： | F4: =底稿目录!A7 -> 复核日期： | I4: 页次：
A5: 调整事项说明 | B5: 类别（报表调整/账项调整/其他） | C5: 报表项目 | D5: 科目名称 | E5: 附注项目 | F5: …… | G5: 借方调整金额 | H5: 贷方调整金额 | I5: 索引 | J5: 备注
A21: 【注：本底稿适用于调整分录较多、较复杂的项目，且仅列示与本报表项目相关的审计调整。项目组可根据项目实际情况选择是否使用该底稿。】

Sheet 针对性检查表I5-4
A1: 致同会计师事务所
A2: 其他非流动资产针对性检查表
A3: =底稿目录!A2 -> 被审计单位： | D3: =底稿目录!A4 -> 编制人： | F3: =底稿目录!A5 -> 编制日期： | P3: 索引号： | Q3: I5-4
A4: =底稿目录!A3 -> 截止日：202X年12月31日 | D4: =底稿目录!A6 -> 复核人： | F4: =底稿目录!A7 -> 复核日期： | P4: 页次：
A5: 一、测试目标：
A6: 检查其他非流动资产的存在/发生、计价和分摊。
A7: 二、样本选取标准与规模：
A8: 测试总体： | B8: 如贷方发生额所有凭证共XX笔金额XX | G8: 特定样本： | H8: XX金额以上（大额）、关联方/关联交易形成的款项、XX异常款项全部测试，共XX笔
A9: 抽样总体： | B9: 测试总体扣除特定样本以外的样本，共XX笔、金额XX | G9: 确定的抽样样本量： | I9: 抽取XX笔 | J9: （如果使用了样本计算器计算样本量，样本量计算过程见<XX>底稿）
A10: 抽样方法： | B10: 随机选样/系统选样/货币单元抽样/随意选样（非统计抽样适用） | G10: 抽样过程： | H10: 使用IDEA（XX抽样工具）选择XX数量、金额XX的样本进行测试，抽样工具中的样本选择过程和结果见<XX>底稿
A11: 三、测试：
A12: 测试内容说明：1.原始凭证是否齐全； 2.记账凭证与原始凭证是否相符；3.账务处理是否正确；4.是否记录于恰当的会计期间；5.……
A13: 记账凭证 | I13: 支持性文件 | J13: 核对内容 | O13: 索引号 | P13: 是否异常 | Q13: 备注说明
A14: 名称 | B14: 日期 | C14: 凭证编号 | D14: 业务内容 | E14: 对方科目 | F14: 对方明细科目 | G14: 借方金额 | H14: 贷方金额 | J14: 1 | K14: 2 | L14: 3 | M14: 4 | N14: 5
A26: 四、审计说明：
A29: 五、审计结论：
A31: 编制说明：
A32: 参考结论：
A33: A、 | B33: 未见异常。
A34: B、 | B34: 除以下重大不符事项应当作为调整事项予以调整外，其余未见异常。
A35: C、 | B35: 由于存在以下重大未调整事项（或审计范围受到限制无法获取充分、适当证据），不可确认。

Sheet GT_Custom
A1: C1 | B1: Custom 1
A2: C2 | B2: Custom 2
A3: C3 | B3: Custom 3
A4: C4 | B4: Custom 4
A5: C5 | B5: Custom 5
A6: C6 | B6: Custom 6
A7: C7 | B7: Custom 7
A8: C8 | B8: Custom 8
