Workbook
Name _13102: #REF!
Name _13302: #REF!
Name _13398: #REF!
Name _18102: #REF!
Name _18198: #REF!
Name _1其他资产_开办费除外_明细表: #REF!
Name _scn11: #REF!
Name _scn15: #REF!
Name _scn16: #REF!
Name _scn17: #REF!
Name _scn19: #REF!
Name _scn2: #REF!
Name _scn20: #REF!
Name _scn3: #REF!
Name _scn4: #REF!
Name _scn5: #REF!
Name _scn6: #REF!
Name _scn7: #REF!
Name _scn8: #REF!
Name _scn9: #REF!
Name _scq1: #REF!
Name _scq11: #REF!
Name _scq15: #REF!
Name _scq16: #REF!
Name _scq17: #REF!
Name _scq19: #REF!
Name _scq2: #REF!
Name _scq20: #REF!
Name _scq3: #REF!
Name _scq4: #REF!
Name _scq5: #REF!
Name _scq6: #REF!
Name _scq7: #REF!
Name _scq8: #REF!
Name _scq9: #REF!
Name hv: #REF!
Name scn: #REF!
Name scq: #REF!
Name ss: #REF!
Name TextRefCopy1: #REF!
Name TextRefCopy10: #REF!
Name TextRefCopy100: #REF!
Name TextRefCopy101: #REF!
Name TextRefCopy102: #REF!
Name TextRefCopy103: #REF!
Name TextRefCopy104: #REF!
Name TextRefCopy105: #REF!
Name TextRefCopy106: #REF!
Name TextRefCopy107: #REF!
Name TextRefCopy108: #REF!
Name TextRefCopy109: #REF!
Name TextRefCopy11: #REF!
Name TextRefCopy12: #REF!
Name TextRefCopy120: #REF!
Name TextRefCopy121: #REF!
Name TextRefCopy122: #REF!
Name TextRefCopy123: #REF!
Name TextRefCopy124: #REF!
Name TextRefCopy125: #REF!
Name TextRefCopy126: #REF!

Sheet 表头（请先填写）
A1: 底稿开列时，可先在以下单元格填写有关内容，以便其他底稿引用有关数据：
A2: 客户名称： | D2: 序号 | E2: 内 容 | F2: 性质
A3: 会计期间：2023年度 | D3: 1 | E3: 审计程序S15 | F3: 审计程序
A4: 编制人： | D4: 2 | E4: 审定表S15-1 | F4: 审定表
A5: 日期： | D5: 3 | E5: 基本每股收益计算表S15-2 | F5: 计算表
D6: 4 | E6: 稀释每股收益计算表S15-3 | F6: 计算表
D7: 5 | E7: 净资产收益率计算S15-4 | F7: 计算表
A9: 关于工作底稿索引号的编制方法的说明
A10: 1、 工作底稿的分类
A12: 作为具体审计程序的支持性工作底稿，共有三类，分别为审定表，明细表，检查表。
A13: 2、 工作底稿与审计程序的对应与索引
A14: 为提高工作底稿编制的针对性，各项目负责人提供的所有支持性工作底稿，均应当
A15: 按自然顺序依次编制索引号，并通过唯一的索引号将审计程序表中的特定程序与相关
A16: 支持性工作底稿进行一一对应。
A17: 3、 工作底稿索引号的编码规则（以销售循环为例，假设D为项目名称代码）
A18: 索引号的说明：实质性程序索引号从“D”到“N”,循环内账户以顺序号排列，如：销售循环的程序表即为D，D1为应收票据审定表，D1-1为附注披露信息，D1-2为明细表........

Sheet 审计程序S15
A1: 致同会计师事务所
A2: 每股收益
A3: ='表头（请先填写）'!A2 -> 客户名称： | C3: ='表头（请先填写）'!A4 -> 编制人： | E3: ='表头（请先填写）'!A5 -> 日期： | G3: 索引号： | H3: S15
A4: ='表头（请先填写）'!A3 -> 会计期间：2023年度 | C4: 复核人： | E4: 日期： | G4: 页 次：
A6: 一、审计目标
A7: 1.每股收益的计算和披露是否符合中国证券监督管理委员会发布的《公开发行证券公司信息披露编报规则第9号―净资产收益率和每股收益的计算及披露》的规定；
A8: 2.每股收益的计算和披露是否符合《企业会计准则第34号-每股收益》的规定。
A10: 二、审计程序 | G10: 执行人 | H10: 索引号
A11: 1.获取每股收益的计算方法 | H11: S15-2
A12: 1.1 确认计算的准确性
A13: 1.2 从财务报表中追踪金额和股数
A14: 2. 考虑可能的稀释性效应，例如：可转换优先股，假如适用，获取稀释股收益的计算方法 | H14: S15-3
A15: 3. 确定计算的准确性
A16: 3.1 已发行普通股的加权平均
A17: 3.2 已发行普通股的稀释加权平均
A18: 3.3 基本每股收益 | H18: S15-2
A19: 3.4 如适用，稀释的每股收益 | H19: S15-3

Sheet 审定表S15-1
A1: 致同会计师事务所
A2: 每股收益审定表
A3: ='表头（请先填写）'!A2 -> 客户名称： | B3: ='表头（请先填写）'!A4 -> 编制人： | C3: ='表头（请先填写）'!A5 -> 日期： | E3: 索引号： | F3: S26-1
A4: ='表头（请先填写）'!A3 -> 会计期间：2023年度 | B4: 复核人： | C4: 日期： | E4: 页 次：
A5: 报告期利润 | C5: 每股收益
C6: 基本每股收益 | E6: 稀释每股收益
C7: 2018年度 | D7: 2017年度 | E7: 2018年度 | F7: 2017年度
A8: 归属于公司普通股股东的净利润
A9: 扣除非经常性损益后归属于公司普通股股东的净利润

Sheet 基本每股收益计算表S15-2
A1: 致同会计师事务所
A2: 基本每股收益计算表
A3: ='表头（请先填写）'!A2 -> 客户名称： | B3: ='表头（请先填写）'!A4 -> 编制人： | D3: ='表头（请先填写）'!A5 -> 日期： | F3: 索引号： | G3: S15-2
A4: ='表头（请先填写）'!A3 -> 会计期间：2023年度 | B4: 复核人： | D4: 日期： | F4: 页 次：
A5: 每股收益的计算 | C5: 计算 | D5: 2021年度 | F5: 2020年度
A6: 1.归属于母公司普通股股东的净利润 | C6: a1
A7: 2.扣除非经常性损益后归属于母公司普通股股东的净利润 | C7: a2
A8: 3.母公司发行在外普通股的加权平均数 | C8: b=b0+b1+b2-b3-b4 | D8: =D9+D10+D11-D18-D21 -> 0 | F8: =F9+F10+F11-F18-F21 -> 0
A9: 3.1期初股份总数 | C9: b0
A10: 3.2报告期因公积金转增股本或股票股利分配等增加股份数 | C10: b1
A11: 3.3报告期因发行新股或债转股等增加股份的加权平均数 | C11: b2
A12: 3.3.1发行新股增加股份的加权平均数 | C12: c=c1*c2/m0
A13: 3.3.1.1发行新股增加的股份数 | C13: c1
A14: 3.3.1.2发行新股下一月份起至报告期期末的月份数 | C14: c2
A15: 3.3.2债转股增加股份的加权平均数 | C15: d=d1*d2/m0
A16: 3.3.2.1债转股增加的股份数 | C16: d1
A17: 3.3.2.2债转股下一月份起至报告期末的月份数 | C17: d2
A18: 3.4报告期因回购等减少股份的加权平均数 | C18: b3=e1*e2/mo
A19: 3.4.1回购股份数 | C19: e1
A20: 3.4.2回购股份下一月份起至报告期期末的月份数 | C20: e2
... A24: 6.基本每股收益（扣除非经常性损益） | C24: a2/b
A25: 7.配股对基本每股收益的调整
A26: 7.1配股情况下，发行在外普通股的加权平均数 | C26: f
A27: 7.2基本每股收益 | C27: a1/f
A28: 7.3基本每股收益（扣除非经常性损益） | C28: a2/f
A29: 计算说明： 1、报告期内，企业发生派发股票股利、公积金转增资本、拆股或并股等事项，为保持会计指标的前后期可比性，应按调整后的股数重新计算各列报期间的每股收益 2、企业当期发生配股的情况下，计算基本每股收益时，应考虑配股中包含的送股因素，据以调整各列报期间发行在外普通股的加权平均数。计算公式如下： 每股理论除权价格＝（行权前发行在外普通股的公允价值＋配股收到的款项）÷行权后发行在外的普通股股数 调整系数=行权前每股公允价值÷每股理论除权价格 因配股重新计算的上年度基本每股收益=上年度基本每股收益÷调整系数 本年度基本每股收益=归属于普通股股东的当期净利润÷（行权前发行在外普通股股数×调整系数×行权前普通股发行在外的时间权数＋行权后发行在外普通股加权平均数）

Sheet 稀释每股收益计算表S15-3
A1: 致同会计师事务所
A2: 稀释每股收益计算表
A3: ='表头（请先填写）'!A2 -> 客户名称： | B3: ='表头（请先填写）'!A4 -> 编制人： | D3: ='表头（请先填写）'!A5 -> 日期： | E3: 索引号：S15-3
A4: ='表头（请先填写）'!A3 -> 会计期间：2023年度 | B4: 复核人： | D4: 日期： | E4: 页 次：
A6: 表一、假设潜在普通股转换为普通股，计算增量股每股收益并排序
A7: 稀释性潜在普通股 | B7: 净利润增加① | C7: 股数增加② | D7: 增量股的每股收益③=①/② | E7: 顺序④
A8: 股份期权
A9: 认股权证
A10: 可转换公司债券
A11: 股份回购
A13: ①净利润增加=（已确认为费用的稀释性潜在普通股利息－转换费用）×（1-所得税率）
A14: ②认股权证和股份期权增加的普通股股数＝拟行权时转换的普通股股数－行权价格×拟行权时转换的普通股股数÷当期普通股平均市场价格
A15: 可转换公司债券增加的普通股股数=可转换公司债券总额/转股价格
A16: 股份回购增加的普通股股数＝回购价格×承诺回购的普通股股数÷当期普通股平均市场价格－承诺回购的普通股股数
A17: ③按照增量股的每股收益由低至高的顺序排序
A19: 表二、分步计算稀释每股收益
A20: 项目① | B20: 净利润② | C20: 股数③ | D20: 每股收益④=②/③ | E20: 稀释性
A21: 基本每股收益A
A22: 股份期权
A23: 小计
A24: 认股权证
A25: 小计
A26: 可转换公司债券
A27: 小计
A28: 股份回购
A29: 小计
A30: 稀释每股收益B
A32: 计算说明： 1、项目①按照表一的排序依次填写； 2、表二应分别按照归属于母公司普通股股东的净利润a1、扣除非经常性损益后归属于母公司普通股股东的净利润a2，计算两次； 3、基本每股收益A引自基本每股收益计算表G20-2； 4、稀释每股收益B为每股收益④中最小值；

Sheet 净资产收益率计算S15-4
B2: 2021年 | C2: 净资产收益率 | F2: 每股收益
C3: 全面摊薄 | D3: 加权平均 | F3: 基本每股收益 | G3: 稀释每股收益
B4: 归属于公司普通股股东的净利润 | C4: =C11/$C$18 -> #DIV/0! | D4: =C11/$C$26 -> #DIV/0! | F4: =C11/$C$36 -> #DIV/0! | G4: =(C11+(F11-F13)*(1-F15))/($C$36+F31*F32/C19) -> #DIV/0!
B5: 扣除非经常性损益后归属于公司普通股股东的净利润 | C5: =C12/$C$18 -> #DIV/0! | D5: =C12/$C$26 -> #DIV/0! | F5: =C12/$C$36 -> #DIV/0! | G5: =(C12+(F11-F13)*(1-F15))/($C$36+F31*F32/C19) -> #DIV/0!
B8: 项目 | C8: 本年数据 | D8: 上年数据 | F8: 本年数据 | G8: 上年数据
B9: 归属于母公司股东的净利润
B10: 减项 | F10: 已确认为费用的稀释性潜在普通股利息
B11: 归属于公司普通股股东的净利润NP | C11: =C9-C10 -> 0 | D11: =D9-D10 -> 0
B12: 扣除非经常性损益后归属于公司普通股股东的净利润P | C12: =C11-C13 -> 0 | D12: =D11-D13 -> 0 | F12: 转换费用
B13: 非经常性损益（母＋子公司中母普通股股东所占份额）
F14: 所得税率
B15: 归属于公司普通股股东的期初净资产E0 | C15: =D18 -> 0 | F15: 0.25 | G15: 0.33
B16: 期末净资产
B17: 少数股东权益
B18: 归属于公司普通股股东的期末净资产E | C18: =C16-C17 -> 0 | D18: =D16-D17 -> 0
B19: 报告期月份数M0 | C19: 12 | D19: 12
B20: 发行新股或债转股等新增的、归属于公司普通股股东的净资产Ei | F20: 全面摊薄净资产收益率＝P÷E
B21: 新增净资产下一个月份至报告期期末的月份Mi
B22: 回购或现金分红等减少的、归属于公司普通股股东的净资产Ej | F22: 加权平均净资产收益率：
B23: 减少净资产下一个月份至报告期期末的月份Mj | F23: P
B24: 其他交易或事项引起的净资产增减变动Ek | F24: ROE = ——————————————————
B25: 发生其他净资产增减变动下一月份起至报告期期末的月份数Mk | F25: E0 + NP÷2 + Ei×Mi÷M0 - Ej×Mj÷M0±Ek×Mk÷M0
B26: 加权平均净资产测算 | C26: =C15+C11/2+C20*C21/C19-C22*C23/C19+C24*C25/C19 -> 0 | D26: =D15+D11/2+D20*D21/D19-D22*D23/D19+D24*D25/D19 -> 0
B28: 期初股份总数S0 | C28: =D29 -> 0
B29: 期末股份总数
B30: 公积金转增股本或股票股利分配等增加股份数S1 | D30: =C30/C28*D28 -> #DIV/0! | F30: 稀释性普通股
B31: 发行新股或债转股等增加股份数Si
B32: 增加股份下一月份起至报告期期末的月份数Mi
B33: 回购或缩股等减少股份数Sj
B34: 减少股份下一月份起至报告期期末的月份数Mj
B35: 为报告期缩股数Sk
B36: 发行在外的普通股加权平均数S | C36: =C28+C30+C31*C32/C19-C33*C34/C19-C35 -> 0 | D36: =D28+D30+D31*D32/D19-D33*D34/D19-D35 -> #DIV/0!
B37: 稀释每股收益：
B38: P+（已确认为费用的稀释性潜在普通股利息－转换费用）×（1－所得税率） | F38: 基本每股收益＝P÷S
B39: DEPS = ——————————————————————————————————————————— | F39: S＝S0＋S1＋Si×Mi÷M0－Sj×Mj÷M0－Sk
B40: S0＋S1＋Si×Mi÷M0－Sj×Mj÷M0－Sk＋认股权证、股份期权、可转换债券等增加的普通股加权平均数
B43: 2021年 | C43: 净资产收益率 | F43: 每股收益
C44: 全面摊薄 | D44: 加权平均 | F44: 基本每股收益 | G44: 稀释每股收益
B45: 归属于公司普通股股东的净利润 | C45: =D11/$D$18 -> #DIV/0! | D45: =D11/$D$26 -> #DIV/0! | F45: =D11/$D$36 -> #DIV/0! | G45: =(D11+(G11-G13)*(1-G15))/($D$36+G31*G32/D19) -> #DIV/0!
B46: 扣除非经常性损益后归属于公司普通股股东的净利润 | C46: =D12/$D$18 -> #DIV/0! | D46: =D12/$D$26 -> #DIV/0! | F46: =D12/$D$36 -> #DIV/0! | G46: =(D12+(G11-G13)*(1-G15))/($D$36+G31*G32/D19) -> #DIV/0!
...
