Workbook
Name _1、: #REF!
Name _1、: #REF!
Name _1、受本循环影响的相关交易和账户余额: #REF!
Name _1、受本循环影响的相关交易和账户余额: #REF!
Name _2、主要业务活动: #REF!
Name _2、主要业务活动: #REF!
Name _2、注册会计师通常应在本循环中了解与上述业务活动相关的内部控制_如果计划在其他业务循环中对上述: #REF!
Name _2、注册会计师通常应在本循环中了解与上述业务活动相关的内部控制_如果计划在其他业务循环中对上述: #REF!
Name _DAT1: #REF!
Name _DAT1: #REF!
Name _DAT10: #REF!
Name _DAT10: #REF!
Name _DAT11: #REF!
Name _DAT11: #REF!
Name _DAT2: #REF!
Name _DAT2: #REF!
Name _DAT3: #REF!
Name _DAT3: #REF!
Name _DAT4: #REF!
Name _DAT4: #REF!
Name _DAT5: #REF!
Name _DAT5: #REF!
Name _DAT6: #REF!
Name _DAT6: #REF!
Name _DAT7: #REF!
Name _DAT7: #REF!
Name _DAT8: #REF!
Name _DAT8: #REF!
Name _DAT9: #REF!
Name _DAT9: #REF!
Name _Hlk174523187: '开发支出资本化分析表S21-2'!$A$40
Name a暗暗: [2]企业表一!$F$20
Name bbkm: [3]W!$B$2:$B$65
Name bbxml: #REF!
Name bbxml: #REF!
Name bbxml: #REF!
Name bbxml: #REF!
Name CarryKnown: #REF!
Name CarryKnown: #REF!
Name CarryKnown: #REF!
Name CarryKnown: #REF!
Name CarryKnown: #REF!
Name CarryKnownTable: #REF!
Name CarryKnownTable: #REF!
Name CarryKnownTable: #REF!
Name CarryKnownTable: #REF!
Name CarryKnownTable: #REF!
Name CarryLikely: #REF!
Name CarryLikely: #REF!
Name CarryLikely: #REF!
Name CarryLikely: #REF!
Name CarryLikely: #REF!
Name CarryLikelyTable: #REF!
Name CarryLikelyTable: #REF!
Name CarryLikelyTable: #REF!
Name CarryLikelyTable: #REF!
Name CarryLikelyTable: #REF!
Name Carryover_Effect_of_Prior_Year: #REF!
Name Carryover_Effect_of_Prior_Year: #REF!
Name Carryover_Effect_of_Prior_Year: #REF!

Sheet 表头（请先填写）
A1: 底稿开列时，可先在以下单元格填写有关内容，以便其他底稿引用有关数据：
A2: 客户名称： | D2: 序号 | E2: 内 容
A3: 截止日：2024年12月31日 | D3: 1 | E3: 表头（请先填写）
A4: 编制人： | D4: 2 | E4: 数据资源S21
A5: 编制日期： | D5: 3 | E5: 数据资产的基本情况S21-1
A6: 复核人： | D6: 4 | E6: 开发支出资本化分析表S21-2
A7: 复核日期： | D7: 5 | E7: 成本归集与分摊检查表S21-3
D8: 6 | E8: 摊销减值政策检查表S21-4
A9: 关于工作底稿索引号的编制方法的说明
A10: 1、 工作底稿的分类
A12: 作为具体审计程序的支持性工作底稿，共有三类，分别为审定表，明细表，检查表。
A13: 2、 工作底稿与审计程序的对应与索引
A14: 为提高工作底稿编制的针对性，各项目负责人提供的所有支持性工作底稿，均应当
A15: 按自然顺序依次编制索引号，并通过唯一的索引号将审计程序表中的特定程序与相关
A16: 支持性工作底稿进行一一对应。
A17: 3、 工作底稿索引号的编码规则（以销售循环为例，假设D为项目名称代码）
A18: 索引号的说明：实质性程序索引号从“D”到“N”,循环内账户以顺序号排列，如：销售循环的程序表即为D，D1为应收票据审定表，D1-1为附注披露信息，D1-2为明细表........

Sheet 数据资产S21
A1: 致同会计师事务所
A2: 数据资产
A3: 客户名称： | C3: 编制人： | D3: 日期： | E3: 索引号： | F3: S21
A4: ='表头（请先填写）'!A3 -> 截止日：2024年12月31日 | C4: 复核人： | D4: 日期： | E4: 页 次： | F4: 1
A6: 一、审计目标
A7: 存在：资产负债表中记录的数据资产是否存在
A8: 完整性：属于被审计单位的数据资产是否均已记录入账
A9: 分类：数据资源分类是否合理
A10: 权利和义务：确定记录的数据资产是否属于被审计单位
A11: 准确性、计价和分摊：数据资产的成本计量是否准确
A12: 列报：确定数据资产是否已按照企业会计准则的规定在财务报表中作出恰当列报
A13: 二、审计程序
A14: 序号 | B14: 审计程序 | E14: 执行人 | F14: 索引号
A15: 1 | B15: 风险评估
A16: 1.1 | B16: 了解被审计单位的数据资源分类框架标准，了解被审计单位根据相关法律法规要求或行业指引，如何基于不同的数据属性对相关数据资源进行分类，例如，业务类相关的数据资源和技术类数据资源等不同的数据资源细分；
A17: 1.2 | B17: 了解被审计单位形成数据资源的来源、规模、应用场景或业务模式、对被审计单位创造价值的影响方式，以及与数据资源应用场景相关的宏观经济和行业领域前景等信息；
A18: 1.3 | B18: 了解被审计单位与数据资源管理体系、组织架构、职责分工的相关管理流程。重点关注被审计单位是否已经建立与数据资源的生命周期相关的管理流程（例如，数据采集、数据传输、数据存储、数据使用、数据交易、以及数据的删除和销毁等周期重要节点），相关部门的部门职责和人员分配，以及被审计单位如何在不同周期节点对相关数据资源进行成本归集和管理、如何入账（包括何时可达到资本化时点）；
A19: 1.4 | B19: 了解被审计单位与数据资源相关的清查管理制度，例如，管理层用以记录和控制数据资源清查的指令和程序（包括清查的范围、计划、时间表和记录等），并观察管理层对制定的数据资源清查程序的执行情况；
A20: 1.5 | B20: 基于被审计单位数据资源形成的方式（例如，外部采购、自行开发和通过其他方式取得）以及入表的数据资源类型（例如，无形资产、存货和其他资产），询问被审计单位管理层和相关财务人员，了解其对与不同数据资源相关的会计准则要求和具体会计处理方法的理解，是否与会计准则的相关要求保持一致；
A21: 1.6 | B21: 获取被审计单位董事会就数据资源外购或研发流程相关事项形成的会议纪要，并查看相关信息；
A22: 1.7 | B22: 针对被审计单位与形成数据资源相关的研发项目，获取管理层编制的研究开发支出按项目列示的清单，并且：
A23: 1.7.1 | B23: 询问管理层各项目的性质以及研发流程（包括所使用的信息系统），了解项目立项、项目预算、项目投入、项目进度、研发成果等基本情况；
A24: 1.7.2 | B24: 获取并检查管理层当期正在进行或已完成的数据资源项目研究开发支出明细表（按项目列示，包括研究阶段产生的费用和开发阶段的支出），以识别是否存在与注册会计师通过上述询问所获取的信息存在重大不一致的情况；
A25: 1.7.3 | B25: 询问并了解管理层对研发人员的界定及人工成本的归集和分配情况，以及其他费用（包括直接费用和间接费用）的性质、范围、归集和核算方法，分析记入与形成入表数据资源的开发支出金额的合理性，关注是否存在将不属于开发支出性质的支出计入开发支出的情况；
A26: 1.7.4 | B26: 对于履行定制化产品客户合同过程中发生的研发支出，了解被审计单位相应的会计政策，区分属于研发项目还是销售项目，判断其会计处理是否合理。
A27: 1.8 | B27: 了解被审计单位与数据资产相关的信息技术环境及控制体系，进一步识别运用信息技术导致的相关风险，以及被审计单位用于应对这些风险的信息技术一般控制。
A28: 2 | B28: 控制测试 | F28: C5/C9
A29: 2.1 | B29: 了解公司数据资源相关的业务流程及其内部控制制度，识别关键的内部控制活动，必要时评价内部控制活动的设计是否有效以及是否得到执行。
A30: 2.2 | B30: 在评价被审计单位与数据资源相关的业务流程以及内部控制设计并确定其是否得到执行时，注册会计师通常关注的与数据资源计量和列报相关的内部控制活动主要包括：
A31: 2.2.1 | B31: 与评估是否满足资本化条件相关的控制活动，是否按照企业会计准则所要求的资本化条件逐条分析并记录审议结果：针对内部研究开发形成无形资产的数据资源，获取其项目资料，检查研究阶段和开发阶段是否以合理的依据清晰划分；检查资本化条件和时点的评估是否基于适当的文件记录（包括但不限于：技术可行性报告、项目产出的数据资源成果及预计使用方式介绍、现有商机/合同/其他证明其经济利益流入的材料等）进行评价，并经过适当审批；
A32: 2.2.2 | B32: 与数据资产形成相关的成本归集与分摊相关的控制活动：询问数据资产的成本结构及归集和分摊的方法，例如：针对外购数据，了解其是否存在同一批外购数据复用于多项数据资产的情况，如有，外购成本如何在各项数据资产之间分摊，其检查是否选择了合理适当的分摊方法；了解从基础数据到形成数据资产的业务流程及控制，评估其控制是否能保证直接归属于使该项无形资产达到预定用途所发生的数据脱敏、清洗、标注、整合、分析、可视化等加工过程所发生的有关支出等，以及数据权属鉴证、质量评估、登记结算、安全管理等费用能够完整归集；针对自行研究开发形成的无形资产，了解其自立项至结项所有相关投入及分摊方法，检查成本的归集和分摊方式是否恰当（例如：人工成本按照项目产出分别记录的工时、服务器等软硬件成本按照容量占用分摊或其他合理的分摊方式），分摊过程是否经过适当的复核等；
A33: 2.2.3 | B33: 与形成无形资产的数据资源的摊销年限和摊销方法确定相关的控制活动：询问并检查形成无形资产的数据资源摊销方法选择及摊销年限确定依据（例如：数据的权利限制、基于数据应用场景分析并记录的数据预计使用年限、类似业务模式下数据迭代更新频率的历史数据、同行业可比公司类似数据的使用年限等）的充分性和适当性，数据资源的应用场景不同对数据的时效性要求迥异，在评价与确定摊销年限和摊销方法相关的控制活动设计和执行的有效性时，注册会计师应当关注企业的数据资源应用场景是否是多样的，如是，企业是否已经按照应用场景和数据资产的类型（数据库/数据模型/数据集等）分别评估其摊销年限；检查该会计估计的确定是否经过适当的复核以及是否定期评估并更新；
A34: 2.2.4 | B34: 与数据资产（包括形成存货和形成无形资产的数据资源）盘点相关的控制活动：询问并了解数据资产盘点的管理制度（时间、频率、参与人员及各自职责等）和技术方法及工具；
A35: 2.2.5 | B35: 与数据资产减值测试相关的控制活动：询问了解公司对数据资产减值测试流程及其内部控制流程，获取并检查公司对数据资产（包括形成存货的数据资源和形成无形资产的数据资源）识别减值迹象并执行减值测试的文件记录。 如果管理层进行减值测试时涉及利用专家的工作，注册会计师需评价公司与利用专家工作相关内控的设计和执行情况:与数据资产失效的识别与评估以及终止确认相关的控制活动;与数据资源披露信息收集整理相关的控制活动；
A36: 2.3 | B36: 了解信息技术环境： 包括IT应用程序（如名称、开发人、基本架构、主要功能、应用方式）、IT基础设施（网络、操作系统、数据库及相关的硬件和软件）和IT控制流程
A37: 2.4 | B37: 信息技术一般控制测试: 评价相关控制的设计是否有效，即这些控制能否应对认定层次重大错报风险或为其他控制的运行提供支持；询问被审计单位内部人员，并实施其他风险评估程序，以确定控制是否得到执行；例如： | F37: C22
A38: 2.4.1 | B38: 环境访问权限、程序更改、信息技术环境变化以及信息技术运行的流程；
A39: 2.4.2 | B39: 检查是否存在过度授权,是否存在录入信息系统数据层数据或篡改信息系统后台数据库等数据造假舞弊的风险,是否发生过导致数据异常的重大事件；
A40: 2.4.3 | B40: 获取并检查数据资产全流程数据安全管理机制，了解被审计单位数据资产分类分级原则、网络安全管理、数据资产泄露、损毁、丢失、篡改等预警和应急管理措施；
A41: 2.4.4 | B41: 询问并了解企业使用第三方来存储、处理、维护其数据资产的情况，评估第三方服务的安全性、可靠性和合规性，并确保企业与其之间的合作协议包含了足够的数据保护和隐私条款。
...

Sheet 数据资产的基本情况S21-1
A1: 致同会计师事务所
A2: 数据资产的基本情况
A3: ='表头（请先填写）'!A2 -> 客户名称： | E3: ='表头（请先填写）'!A4 -> 编制人： | I3: ='表头（请先填写）'!A5 -> 编制日期： | O3: 索引号： | P3: S21-1
A4: ='表头（请先填写）'!A3 -> 截止日：2024年12月31日 | E4: ='表头（请先填写）'!A6 -> 复核人： | I4: ='表头（请先填写）'!A7 -> 复核日期： | O4: 页 次： | P4: 1
A6: 项目 | B6: 数据的相关信息 | G6: 元数据层的关键字段 | H6: 数据资源内容 （或数据产品名称等） | I6: 数据资源的应用场景 | J6: 数据资源的业务模式 | K6: 加工维护、更新情况 | L6: 权利限制 | M6: 相关登记证书 （数据知识产权登记/数据产品登记等） | N6: 减值迹象
B7: 数据的类型 （数字/文字/图像/视频/视频/多种格式组合等） | C7: 数据来源 （外购/经营产生/公开信息采集/数据置换/政府开放平台/政府授权/其他授权/其他 | D7: 数据存储方式 （数据库存储/文件存储/对象存储等） | E7: 数据存放的物理位置 | F7: 数据大小 （MB、GB、TB、...） | N7: 数据资产质量下降 | O7: 市场需求减少 | P7: 存在数据安全风险 | Q7: ......

Sheet 开发支出资本化分析表S21-2
A1: 致同会计师事务所
A2: 开发支出资本化分析表
A3: ='表头（请先填写）'!A2 -> 客户名称： | D3: ='表头（请先填写）'!A4 -> 编制人： | I3: ='表头（请先填写）'!A5 -> 编制日期： | N3: 索引号： | O3: S21-2
A4: ='表头（请先填写）'!A3 -> 截止日：2024年12月31日 | D4: ='表头（请先填写）'!A6 -> 复核人： | I4: ='表头（请先填写）'!A7 -> 复核日期： | N4: 页 次： | O4: 1
A6: （一）资本化时点的判断
A7: 项目名称 | B7: 数据资源内容 （或数据产品名称等） | C7: 分析过程 | E7: 确认为无形资产金额 | F7: 具体研究内容 | G7: 资本化开始的时点 | H7: 资本化的具体依据 | I7: 开发阶段支出资本化确认为无形资产，必须同时满足下列条件 | N7: 截至期末的研发进度 | O7: 索引
C8: 开发支出总额 | I8: 使用和出售在技术上的可行性 | J8: 是否存在使用和出售该资产的意图 | K8: 是否存在市场和内部使用需求 | L8: 是否有足够的技术、财力支持完成无形资产的开发 | M8: 无形资产的开发支出是否单独核算并可靠计量
C9: 研究阶段支出 | D9: 开发阶段支出
A15: 合计 | B15: =SUM(C10:C14) -> 0 | C15: =SUM(D10:D14) -> 0 | D15: =SUM(E10:E14) -> 0
A16: （二）资本化金额的确认（按项目）
A17: 项目 | B17: 1月 | C17: 2月 | D17: 3月 | E17: 4月 | F17: 5月 | G17: 6月 | H17: 7月 | I17: 8月 | J17: 9月 | K17: 10月 | L17: 11月 | M17: 12月 | N17: 本期未审合计 | O17: 各项目占比
A18: 采购成本 | N18: =SUM(B18:M18) -> 0 | O18: =N18/$N$40 -> #DIV/0!
A19: 人工成本 | N19: =SUM(B19:M19) -> 0 | O19: =N19/$N$40 -> #DIV/0!
A20: 其他数据脱敏、清洗、标注、整合、分析支出 | N20: =SUM(B20:M20) -> 0 | O20: =N20/$N$40 -> #DIV/0!
A21: 数据权属鉴证费
A22: 质量评估费
A23: 登记结算费
A24: 安全管理费
A25: … | N25: =SUM(B25:M25) -> 0 | O25: =N25/$N$40 -> #DIV/0!
A26: 合计 | B26: =SUM(B18:B25) -> 0 | C26: =SUM(C18:C25) -> 0 | D26: =SUM(D18:D25) -> 0 | E26: =SUM(E18:E25) -> 0 | F26: =SUM(F18:F25) -> 0 | G26: =SUM(G18:G25) -> 0 | H26: =SUM(H18:H25) -> 0 | I26: =SUM(I18:I25) -> 0 | ... M26: =SUM(M18:M25) -> 0 | N26: =SUM(B26:M26) -> 0 | O26: =N26/$N$40 -> #DIV/0!
A27: 各月比例 | B27: =B26/$N$40 -> #DIV/0! | C27: =C26/$N$40 -> #DIV/0! | D27: =D26/$N$40 -> #DIV/0! | E27: =E26/$N$40 -> #DIV/0! | F27: =F26/$N$40 -> #DIV/0! | G27: =G26/$N$40 -> #DIV/0! | H27: =H26/$N$40 -> #DIV/0! | I27: =I26/$N$40 -> #DIV/0! | ... M27: =M26/$N$40 -> #DIV/0!
A28: 审计说明：
A30: 审计结论：
A33: 提示：（供参考）
A34: 1、完成该数据资源无形资产以使其能够使用或出售在技术上具有可行性。
A35: 这一条件通常包括： | B35: （1）企业应当在项目研发前，经过规划、设计和可行性分析，形成可行性分析报告，并按照企业内外部要求进行了相应审批。
B36: （2）企业应当具备数据资源开发所需的相关技术条件，如数据采集技术、数据整合技术、数据存储技术、数据分析技术、数据挖掘技术、数据安全与隐私保护技术等。
B37: （3）企业应当有详细的开发计划、技术路线图、技术文档、技术专家评估报告或评估意见等，表明项目能够按照预定的技术路径完成。
B38: （4）企业应当形成技术验证报告，证明数据资源已经通过了相关的技术测试和验证，确保其功能和技术性能符合预期，不存在技术上的障碍或其他技术不确定性。同行业企业已有同类数据资产的，一般认为不存在技术上的障碍或其他技术不确定性。
B39: （5）数据资源开发应当已经达到一定的成熟度，形成数据资源技术成熟度和可靠性的分析，以证明其可以在商业环境中稳定运行，不会频繁出现技术故障。
A40: 2、具有完成该数据资源无形资产并使用或出售的意图。
A41: 这一条件通常包括： | B41: （1）企业应当有经批准的数据资源开发立项相关书面决策文件（如开发计划书、立项决议等），内容一般应涵盖数据资源的开发目标、开发必要性、开发可行性、开发总体计划、预期成果、项目时间表、需要的各项资源等。
B42: （2）企业应当能够说明其开发数据资源的目的、数据资源使用的业务模式、应用场景。如，将数据资源与企业其他资源相结合使用，从而服务、支持生产经营或管理活动，实现降本增效等目的；运用数据资源为其他主体提供有关服务，赚取收入等。
B43: （3）开发活动应当有固定的开发团队和明确的预算安排。
A44: 3、数据资源无形资产产生经济利益的方式，包括能够证明运用该数据资源无形资产生产的产品存在市场或无形资产自身存在市场，数据资源无形资产将在内部使用的，应当证明其有用性。
A45: 这一条件通常包括： | B45: （1）该数据资源无形资产形成后主要用于生产产品或提供服务的，企业应当对运用该数据资源生产的产品或服务的市场情况进行预计，能够证明所生产的产品或提供的服务存在市场，有明确的市场需求，能够为企业带来稳定收入。
B46: （2）该数据资源无形资产形成后主要用于非排他的对外出售或授权使用的，应当能够证明市场上存在对该类数据资源的需求，开发以后存在外在的市场可以出售或授权，并带来经济利益流入。
B47: （3）该数据资源无形资产形成后主要用于企业内部赋能的，应当能够对数据资源在降低成本、节约工时、减少风险损失等方面的情况进行定量分析，证明在降低成本、节约工时、减少风险损失等方面的收益合理预计将大于研发支出概算。
A48: 4、有足够的技术、财务资源和其他资源支持，以完成该数据资源无形资产的开发，并有能力使用或出售该数据资源无形资产。
A49: 这一条件通常包括： | B49: （1）企业应当具备开发数据资源所需的技术团队，能够保证团队投入必要的开发时间，从而有确凿证据证明企业继续开发该项数据资源无形资产有足够的技术支持和技术能力。
...

Sheet 成本归集与分摊检查表S21-3
A1: 致同会计师事务所
A2: 成本归集与分摊检查表
A3: ='表头（请先填写）'!A2 -> 客户名称： | D3: ='表头（请先填写）'!A4 -> 编制人： | H3: ='表头（请先填写）'!A5 -> 编制日期： | R3: 索引号： | S3: S21-3
A4: ='表头（请先填写）'!A3 -> 截止日：2024年12月31日 | D4: ='表头（请先填写）'!A6 -> 复核人： | H4: ='表头（请先填写）'!A7 -> 复核日期： | R4: 页次： | S4: 1
A5: 成本构成（按项目）
A6: 数据资源内容 （或数据产品名称等） | B6: 采购成本 | F6: 人工成本 | J6: 服务器等软硬件可计入数据资源成本的费用 | N6: 其他数据脱敏、清洗、标注、整合、分析支出 | O6: 数据权属鉴证费 | P6: 质量评估费 | Q6: 登记结算费 | R6: 安全管理费 | S6: 其他可归属的费用
B7: 金额 | C7: 是否存在同一批外购数据复用于多项数据资产的情况 | D7: 分摊方法 | E7: 评价分摊方法的适当性，并说明理由 | F7: 金额 | G7: 参与人数 | H7: 是否存在兼职其他数据资源项目或经营生产的人员 | I7: 工时 | J7: 金额 | K7: 是否存在其他数据资产或生产共用的情况 | L7: 分摊方法 | M7: 评价分摊方法的适当性，并说明理由
A18: 审计说明：
A20: 审计结论：

Sheet 摊销政策检查表S21-4
A1: 致同会计师事务所
A2: 摊销政策检查表
A3: ='表头（请先填写）'!A2 -> 客户名称： | F3: ='表头（请先填写）'!A4 -> 编制人： | K3: ='表头（请先填写）'!A5 -> 编制日期： | O3: 索引号： | P3: S21-4
A4: ='表头（请先填写）'!A3 -> 截止日：2024年12月31日 | F4: ='表头（请先填写）'!A6 -> 复核人： | K4: ='表头（请先填写）'!A7 -> 复核日期： | O4: 页次： | P4: 1
B5: 无形资产-数据资源摊销政策：
A6: 序号 | B6: 数据资源内容 （或数据产品名称等） | C6: 使用寿命 | D6: 数据安全和个人信息保护的相关法律法规对数据资源的权利限制 | E6: 是否与基于数据应用场景分析并记录的数据预计使用年限一致 | F6: 是否考虑了数据的调用频率、更新频率和时效性 | G6: 是否考虑了有关产品或技术迭代、同类竞品的因素 | H6: 类似业务模式下数据迭代更新频率的历史数据 | I6: 同行业可比公司类似数据的使用年限等 | J6: 摊销方法 | K6: 是否符合实际经营情况和会计准则的要求 | L6: 是否与相关资产所包含的经济利益预期实现方式相一致 | M6: 与同行业公司相比，会计政策是否合理 | N6: 是否存在会计政策/会计估计变更 | O6: 会计政策/会计估计变更是否合理 | P6: 备注
A7: 1
A8: 2
A9: 3
A10: 4
A11: 5
A12: 6
A13: 7
A14: 8
A15: 9
A16: 10
A17: 审计说明：
A19: 审计结论：
