Workbook
Name _1、: #REF!
Name _1、: #REF!
Name _1、受本循环影响的相关交易和账户余额: #REF!
Name _1、受本循环影响的相关交易和账户余额: #REF!
Name _2、主要业务活动: #REF!
Name _2、主要业务活动: #REF!
Name _2、注册会计师通常应在本循环中了解与上述业务活动相关的内部控制_如果计划在其他业务循环中对上述: #REF!
Name _2、注册会计师通常应在本循环中了解与上述业务活动相关的内部控制_如果计划在其他业务循环中对上述: #REF!
Name a暗暗: [1]企业表一!$F$20
Name CarryKnown: #REF!
Name CarryKnown: #REF!
Name CarryKnown: #REF!
Name CarryKnown: #REF!
Name CarryKnownTable: #REF!
Name CarryKnownTable: #REF!
Name CarryKnownTable: #REF!
Name CarryKnownTable: #REF!
Name CarryLikely: #REF!
Name CarryLikely: #REF!
Name CarryLikely: #REF!
Name CarryLikely: #REF!
Name CarryLikelyTable: #REF!
Name CarryLikelyTable: #REF!
Name CarryLikelyTable: #REF!
Name CarryLikelyTable: #REF!
Name Carryover_Effect_of_Prior_Year: #REF!
Name Carryover_Effect_of_Prior_Year: #REF!
Name Carryover_Effect_of_Prior_Year: #REF!
Name Carryover_Effect_of_Prior_Year: #REF!
Name CarryoverTitle: #REF!
Name CarryoverTitle: #REF!
Name CarryoverTitle: #REF!
Name CarryoverTitle: #REF!
Name CC_Instruction: #REF!
Name CC_Instruction: #REF!
Name CC_Instruction: #REF!
Name CC_Instruction: #REF!
Name CE_CarryKnownProtection: #REF!
Name CE_CarryKnownProtection: #REF!
Name CE_CarryKnownProtection: #REF!
Name CE_CarryKnownProtection: #REF!
Name CE_CarryKnownTable: #REF!
Name CE_CarryKnownTable: #REF!
Name CE_CarryKnownTable: #REF!
Name CE_CarryKnownTable: #REF!
Name CE_CarryLikely1Protection: #REF!
Name CE_CarryLikely1Protection: #REF!
Name CE_CarryLikely1Protection: #REF!
Name CE_CarryLikely1Protection: #REF!
Name CE_CarryLikely1Table: #REF!
Name CE_CarryLikely1Table: #REF!
Name CE_CarryLikely1Table: #REF!
Name CE_CarryLikely1Table: #REF!
Name CE_CarryLikely2Protection: #REF!
Name CE_CarryLikely2Protection: #REF!
Name CE_CarryLikely2Protection: #REF!
Name CE_CarryLikely2Protection: #REF!
Name CE_CarryLikely2Table: #REF!
Name CE_CarryLikely2Table: #REF!
Name CE_CarryLikely2Table: #REF!

Sheet 表头（请先填写）
A1: 底稿开列时，可先在以下单元格填写有关内容，以便其他底稿引用有关数据： | B1: 序号 | C1: 目录
A2: 客户名称： | B2: 1 | C2: B23-3了解货币资金循环流程和内部控制记录表
A3: 会计期间：2013年度 | B3: 2 | C3: B23-3-1链接-企业对财务报表风险的应对
A4: 编制人： | B4: 3 | C4: B23-3-2穿行测试
A5: 日 期： | B5: 4 | C5: B23-3-3关键控制点选择表（财报审计适用）
B6: 5 | C6: B23-3-4关键控制点选择表（整合审计适用）
A8: 附录、关于工作底稿索引号的编制方法
A9: 1、 工作底稿与审计程序的对应与索引
A10: 为提高工作底稿编制的针对性，各项目负责人提供的所有支持性工作底稿，均应当按自然顺序依次编制索引号，并通过唯一的索引号将审计程序表中的特定程序与相关支持性工作底稿进行一一对应。
A11: 2、 工作底稿索引号的编码规则
A12: （1）索引号的结构：包括三要素，即“项目名称代码”、“—”和“索引顺序号”，如“B23-1”、“B23-2”、........
A13: （2）索引顺序号的分层：可分为多层，如“B23-1-1”；“B23-1-2”；........

Sheet B23-3了解货币资金循环流程和内部控制记录表
A1: 致同会计师事务所
A2: 了解货币资金循环流程和内部控制记录表
A3: ='表头（请先填写）'!A2 -> 客户名称： | C3: ='表头（请先填写）'!A4 -> 编制人： | D3: ='表头（请先填写）'!A5 -> 日 期： | E3: 索引号：B23-3
A4: ='表头（请先填写）'!A3 -> 会计期间：2013年度 | C4: 复核人： | D4: 日期： | E4: 页 次：
A6: 一、本循环涉及的交易、账户及相关业务活动
A7: 1、受本循环影响的相关交易和账户余额
A8: 现金、银行存款、其他货币资金
A9: 2、本循环涉及的主要业务活动
A10: 序号 | B10: 主要业务活动 | C10: 是否在本循环中进行了解 | D10: 未了解的原因
A11: 1 | B11: 与现金有关的调整Cash-related adjustments | C11: 是 | D11: N/A
A12: 2 | B12: 货币资金维护Cash maintenance | C12: 是 | D12: N/A
B13: ……
A15: 二、本循环业务涉及的主要人员及其职责
A16: 层级或部门 | B16: 姓名 | C16: 职务 | D16: 职责及权限 | E16: 备注
A17: 治理层
A21: 高级管理层
A25: 财务人员
A29: 相关职能部门人员
A34: 二、主要业务活动介绍/货币资金流程图（需标注容易出错的领域）
A35: 1、与现金有关的调整Cash-related adjustments
A38: 2、货币资金维护Cash maintenance

Sheet B23-3-1链接-企业对财务报表风险的应对
A1: 致同会计师事务所
A2: 链接-企业对财务报表风险的应对
A3: ='表头（请先填写）'!A2 -> 客户名称： | B3: ='表头（请先填写）'!A4 -> 编制人： | C3: ='表头（请先填写）'!A5 -> 日 期： | E3: 索引号：B23-3-1
A4: ='表头（请先填写）'!A3 -> 会计期间：2013年度 | B4: 复核人： | C4: 日期： | E4: 页次：
A5: 认定 | B5: 风险（来自于B22-1/B22-2） | C5: 是否适用 | D5: 应对风险的活动 | E5: 应对风险的控制
A6: 存在/发生 Existence/Occurrence | B6: 无效的已记录现金余额 Recorded cash in bank not valid （V4Recorded cash balance not valid） | D6: 1.**** | E6: 1.**** 2.****
D7: 2.****
A8: 存在/发生 Existence/Occurrence | B8: 未对账的库存现金 Recorded cash on hand not valid （V4Cash on hand not reconciled）
A9: 价值-毛值 Valuation - Gross | B9: 未恰当计量的现金账户 Cash accounts denominated in foreign currencies not measured properly （V4Cash accounts not measured properly）
A10: 价值-净值 Valuation - Net | B10: 非流动现金的存放 Cash repositories not solvent （V4Cash repositories not liquid）
A13: 编制说明：
A14: 1、该底稿用于判断选取与风险相关的控制。
A15: 2、加黑的流程为特定风险下推荐的必选流程。如审计项目组认为还有其他的流程需要进一步选择，请打开组合“+”进行选取。
A16: 3、底稿模板中列示的为全部建议风险及流程，如果某些风险被审计单位不适用，请删除该风险及相关控制。
A17: 4、对于适用的流程，请在G列选择“√”。
A27: √
A28: ×

Sheet B23-3-2穿行测试
A1: 致同会计师事务所
A2: 穿行测试（货币资金循环）
A3: ='表头（请先填写）'!A2 -> 客户名称： | E3: ='表头（请先填写）'!A4 -> 编制人： | G3: ='表头（请先填写）'!A5 -> 日 期： | J3: 索引号：B23-3-2
A4: ='表头（请先填写）'!A3 -> 会计期间：2013年度 | E4: 复核人： | G4: 日 期： | J4: 页次：
A5: 活动 | B5: 控制 | D5: 穿行测试方法 （检查/观察） | E5: 所检查（取得）文件名称 | F5: 所检查（取得）文件索引号 | G5: 简述如何执行 | H5: 是否得到执行，未得到执行请解释 | I5: 是否为偏差 并解释原因 （是/否/N/A） | J5: 缺陷评价 索引号
A6: 与现金有关的调整Cash-related adjustments
B7: 1
B8: 2
B9: 3
B10: ……
A12: 货币资金维护Cash maintenance
B13: 1
B14: 2
B15: 3
B16: ……
A22: 编制说明：
A23: 1、根据对被审计单位的了解，选择检查或观察的方法，选取1个样本，填写穿行测试获得的结果。审计人员应该对之前了解的相关内控中企业已有的控制点执行穿行测试。
A24: 2、根据穿行测试的结果判断是否得到执行，如果未得到执行，说明原因，并判断是否为偏差。如果确定为偏差，应对缺陷进行评价，并索引内控缺陷评价表。
A25: 3、穿行测试的方法分为观察和检查。
A26: （1）观察：观察所执行的控制，并确定控制已得到执行。
A27: （2）检查：检查原始文件、单据，提出探求性问题，并确定控制得到执行。
A28: （3）选择穿行测试方法时的考虑因素：
A29: 观察
A30: 通常是无文件证明的控制；
A31: 自动化控制；
A32: 固有风险越低；
A83: 检查
A84: 观察

Sheet B23-3-3关键控制点选择表（财报审计适用）
A1: 致同会计师事务所
A2: 关键控制点选择（货币资金循环）
A3: ='B23-3了解货币资金循环流程和内部控制记录表'!A3 -> 客户名称： | C3: ='B23-3了解货币资金循环流程和内部控制记录表'!C3 -> 编制人： | E3: ='B23-3了解货币资金循环流程和内部控制记录表'!D3 -> 日 期： | I3: 索引号：B23-3-3
A4: ='B23-3了解货币资金循环流程和内部控制记录表'!A4 -> 会计期间：2013年度 | C4: 复核人： | E4: 日 期： | I4: 页次：
A6: 风险、相关的“流程”和“活动”须根据具体情况分析填列，下表列示内容不适用须删除。
A7: 认定 | B7: 风险 | C7: 与风险相关的活动 | D7: 拟测试的控制 | F7: 关键控制点数量（D=A+B+C） | G7: 直接测试方法（询问观察/CAAT/抽样（检查）/重新执行)-A | H7: 管理层-重新执行-B | I7: 管理层-仅复核-C
A8: 存在/发生 Existence/Occurrence
B9: 无效的已记录现金余额 Recorded cash in bank not valid （V4Recorded cash balance not valid） | D9: 1 | F9: =IF(OR(G9<>0,H9<>0,I9<>0),1,0) -> 0
D10: 2 | F10: =IF(OR(G10<>0,H10<>0,I10<>0),1,0) -> 0
D11: …… | F11: =IF(OR(G11<>0,H11<>0,I11<>0),1,0) -> 0
B12: 未对账的库存现金 Recorded cash on hand not valid （V4Cash on hand not reconciled） | F12: =IF(OR(G12<>0,H12<>0,I12<>0),1,0) -> 0
F13: =IF(OR(G13<>0,H13<>0,I13<>0),1,0) -> 0
A14: 价值-毛值 Valuation - Gross | F14: =IF(OR(G14<>0,H14<>0,I14<>0),1,0) -> 0
B15: 未恰当计量的现金账户 Cash accounts denominated in foreign currencies not measured properly （V4Cash accounts not measured properly） | F15: =IF(OR(G15<>0,H15<>0,I15<>0),1,0) -> 0
F16: =IF(OR(G16<>0,H16<>0,I16<>0),1,0) -> 0
A17: 价值-净值 Valuation - Net | F17: =IF(OR(G17<>0,H17<>0,I17<>0),1,0) -> 0
B18: 非流动现金的存放 Cash repositories not solvent （V4Cash repositories not liquid） | F18: =IF(OR(G18<>0,H18<>0,I18<>0),1,0) -> 0
F19: =IF(OR(G19<>0,H19<>0,I19<>0),1,0) -> 0
F20: =IF(OR(G20<>0,H20<>0,I20<>0),1,0) -> 0
C21: 合计 | F21: =SUM(F9:F20) -> 0 | G21: =COUNTA(G9:G20) -> 0 | H21: =COUNTA(H9:H20) -> 0 | I21: =COUNTA(I9:I20) -> 0
G22: =G21/F21 -> #DIV/0! | H22: =H21/F21 -> #DIV/0! | I22: =I21/F21 -> #DIV/0!
F23: 各种测试方法所占比例 | G23: 50-70 | H23: 20-50 | I23: 0-30
A24: 编制说明：
A25: 1、审计人员应根据风险评估的结果（B22-1）确定是否进行控制测试。
A26: 2、选择关键控制点
A27: a.关键控制点的特点：
A28: （1）和将减少测试范围的实质性审计程序强调的风险相同―如果控制有效运行，将减少一些实质性审计程序的范围。如许多被审计单位针对定期存货盘点制定了有效的控制程序，这些控制程序可以直接减少该项目记录在存在性方面发生错误的可能性。相应地，通过控制测试可减少实质程序（存货实地观察）的使用；
A29: （2）设计目的是防止或发现财务报表具体的重大错报风险（旨在实现该目标的控制会因业务性质的不同而不同）；
A30: （3）证据有书面记录；可以通过询问、观察、抽样、重新执行或使用计算机辅助审计技术进行测试；
A31: （4） 包含适当的属性（自动或人工、预防性或检查性、操作性或基础性、有文件记录或无文件记录）以便进行最有效率和效果的测试。
A32: b.关键控制点主要选择原则如下：
A33: （1）对于采用综合性方案以应对的风险，应确保每个风险都有效率并能达到效果的控制点进行测试；
A34: （2）对于每个非常重要的流程，都应当选择关键控制点进行控制测试；
A35: （3）并不一定必须对每一个“比较重要”的流程都进行控制测试，但对于“比较重要”的流程，都不选择关键控制点进行控制测试的情况也是比较罕见。
... A42: 对应关系表如下：
A43: 序号 | B43: PRC
A44: 1 | B44: 询问
A45: 2 | B45: 观察
A46: 3 | B46: 检查
A47: 4 | B47: 重新执行
...

Sheet B23-3-4关键控制点选择表（整合审计适用）
A1: 致同会计师事务所
A2: 关键控制点选择（货币资金循环）
A3: ='B23-3了解货币资金循环流程和内部控制记录表'!A3 -> 客户名称： | E3: ='B23-3了解货币资金循环流程和内部控制记录表'!C3 -> 编制人： | G3: ='B23-3了解货币资金循环流程和内部控制记录表'!D3 -> 日 期： | K3: 索引号：B23-3-4
A4: ='B23-3了解货币资金循环流程和内部控制记录表'!A4 -> 会计期间：2013年度 | E4: 复核人： | G4: 日 期： | K4: 页次：
A6: 风险、相关的“流程”和“活动”须根据具体情况分析填列，下表列示内容不适用须删除。
A7: 认定 | B7: 风险 | C7: 是否进行控制测试 | D7: 原 因 | E7: 与风险相关的活动 | F7: 拟测试的控制 | H7: 关键控制点数量（D=A+B+C） | I7: 直接测试方法（询问观察/CAAT/抽样（检查）/重新执行)-A | J7: 管理层-重新执行-B | K7: 管理层-仅复核-C
A8: 存在合理可能的重大错报 Reasonably Possisble
A9: 存在/发生 Existence/Occurrence
B10: 无效的已记录现金余额 Recorded cash in bank not valid （V4Recorded cash balance not valid） | F10: 1 | H10: =IF(OR(I10<>0,J10<>0,K10<>0),1,0) -> 0
F11: 2 | H11: =IF(OR(I11<>0,J11<>0,K11<>0),1,0) -> 0
F12: …… | H12: =IF(OR(I12<>0,J12<>0,K12<>0),1,0) -> 0
B13: 未对账的库存现金 Recorded cash on hand not valid （V4Cash on hand not reconciled） | H13: =IF(OR(I13<>0,J13<>0,K13<>0),1,0) -> 0
H14: =IF(OR(I14<>0,J14<>0,K14<>0),1,0) -> 0
A15: 价值-毛值 Valuation - Gross | H15: =IF(OR(I15<>0,J15<>0,K15<>0),1,0) -> 0
B16: 未恰当计量的现金账户 Cash accounts denominated in foreign currencies not measured properly （V4Cash accounts not measured properly） | H16: =IF(OR(I16<>0,J16<>0,K16<>0),1,0) -> 0
H17: =IF(OR(I17<>0,J17<>0,K17<>0),1,0) -> 0
A18: 价值-净值 Valuation - Net | H18: =IF(OR(I18<>0,J18<>0,K18<>0),1,0) -> 0
B19: 非流动现金的存放 Cash repositories not solvent （V4Cash repositories not liquid） | H19: =IF(OR(I19<>0,J19<>0,K19<>0),1,0) -> 0
H20: =IF(OR(I20<>0,J20<>0,K20<>0),1,0) -> 0
H21: =IF(OR(I21<>0,J21<>0,K21<>0),1,0) -> 0
E22: 合计 | H22: =SUM(H10:H21) -> 0 | I22: =COUNTA(I10:I21) -> 0 | J22: =COUNTA(J10:J21) -> 0 | K22: =COUNTA(K10:K21) -> 0
I23: =I22/H22 -> #DIV/0! | J23: =J22/H22 -> #DIV/0! | K23: =K22/H22 -> #DIV/0!
H24: 各种测试方法所占比例 | I24: 50-70 | J24: 20-50 | K24: 0-30
A25: 不存在合理可能的重大错报 Reasonably Possisble
A26: 存在/发生 Existence/Occurrence
B27: 无效的已记录现金余额 Recorded cash in bank not valid （V4Recorded cash balance not valid） | F27: 1 | H27: =IF(OR(I27<>0,J27<>0,K27<>0),1,0) -> 0
F28: 2 | H28: =IF(OR(I28<>0,J28<>0,K28<>0),1,0) -> 0
F29: …… | H29: =IF(OR(I29<>0,J29<>0,K29<>0),1,0) -> 0
B30: 未对账的库存现金 Recorded cash on hand not valid （V4Cash on hand not reconciled） | H30: =IF(OR(I30<>0,J30<>0,K30<>0),1,0) -> 0
H31: =IF(OR(I31<>0,J31<>0,K31<>0),1,0) -> 0
A32: 价值-毛值 Valuation - Gross | H32: =IF(OR(I32<>0,J32<>0,K32<>0),1,0) -> 0
B33: 未恰当计量的现金账户 Cash accounts denominated in foreign currencies not measured properly （V4Cash accounts not measured properly） | H33: =IF(OR(I33<>0,J33<>0,K33<>0),1,0) -> 0
H34: =IF(OR(I34<>0,J34<>0,K34<>0),1,0) -> 0
A35: 价值-净值 Valuation - Net | H35: =IF(OR(I35<>0,J35<>0,K35<>0),1,0) -> 0
B36: 非流动现金的存放 Cash repositories not solvent （V4Cash repositories not liquid） | H36: =IF(OR(I36<>0,J36<>0,K36<>0),1,0) -> 0
H37: =IF(OR(I37<>0,J37<>0,K37<>0),1,0) -> 0
H38: =IF(OR(I38<>0,J38<>0,K38<>0),1,0) -> 0
E39: 合计 | H39: =SUM(H27:H38) -> 0 | I39: =COUNTA(I27:I38) -> 0 | J39: =COUNTA(J27:J38) -> 0 | K39: =COUNTA(K27:K38) -> 0
I40: =I39/H39 -> #DIV/0! | J40: =J39/H39 -> #DIV/0! | K40: =K39/H39 -> #DIV/0!
H41: 各种测试方法所占比例 | I41: 0-50 | J41: 0-50 | K41: 0-50
...
