Workbook
Name _1、: #REF!
Name _1、: #REF!
Name _1、受本循环影响的相关交易和账户余额: #REF!
Name _1、受本循环影响的相关交易和账户余额: #REF!
Name _2、主要业务活动: #REF!
Name _2、主要业务活动: #REF!
Name _2、注册会计师通常应在本循环中了解与上述业务活动相关的内部控制_如果计划在其他业务循环中对上述: #REF!
Name _2、注册会计师通常应在本循环中了解与上述业务活动相关的内部控制_如果计划在其他业务循环中对上述: #REF!
Name a暗暗: [1]企业表一!$F$20
Name CarryKnown: #REF!
Name CarryKnown: #REF!
Name CarryKnown: #REF!
Name CarryKnown: #REF!
Name CarryKnownTable: #REF!
Name CarryKnownTable: #REF!
Name CarryKnownTable: #REF!
Name CarryKnownTable: #REF!
Name CarryLikely: #REF!
Name CarryLikely: #REF!
Name CarryLikely: #REF!
Name CarryLikely: #REF!
Name CarryLikelyTable: #REF!
Name CarryLikelyTable: #REF!
Name CarryLikelyTable: #REF!
Name CarryLikelyTable: #REF!
Name Carryover_Effect_of_Prior_Year: #REF!
Name Carryover_Effect_of_Prior_Year: #REF!
Name Carryover_Effect_of_Prior_Year: #REF!
Name Carryover_Effect_of_Prior_Year: #REF!
Name CarryoverTitle: #REF!
Name CarryoverTitle: #REF!
Name CarryoverTitle: #REF!
Name CarryoverTitle: #REF!
Name CC_Instruction: #REF!
Name CC_Instruction: #REF!
Name CC_Instruction: #REF!
Name CC_Instruction: #REF!
Name CE_CarryKnownProtection: #REF!
Name CE_CarryKnownProtection: #REF!
Name CE_CarryKnownProtection: #REF!
Name CE_CarryKnownProtection: #REF!
Name CE_CarryKnownTable: #REF!
Name CE_CarryKnownTable: #REF!
Name CE_CarryKnownTable: #REF!
Name CE_CarryKnownTable: #REF!
Name CE_CarryLikely1Protection: #REF!
Name CE_CarryLikely1Protection: #REF!
Name CE_CarryLikely1Protection: #REF!
Name CE_CarryLikely1Protection: #REF!
Name CE_CarryLikely1Table: #REF!
Name CE_CarryLikely1Table: #REF!
Name CE_CarryLikely1Table: #REF!
Name CE_CarryLikely1Table: #REF!
Name CE_CarryLikely2Protection: #REF!
Name CE_CarryLikely2Protection: #REF!
Name CE_CarryLikely2Protection: #REF!
Name CE_CarryLikely2Protection: #REF!
Name CE_CarryLikely2Table: #REF!
Name CE_CarryLikely2Table: #REF!
Name CE_CarryLikely2Table: #REF!

Sheet 表头（请先填写）
A1: 底稿开列时，可先在以下单元格填写有关内容，以便其他底稿引用有关数据： | B1: 序号 | C1: 目录
A2: 客户名称： | B2: 1 | C2: B23-1了解收入循环流程和内部控制记录表
A3: 会计期间：2013年度 | B3: 2 | C3: B23-1-1链接-企业对财务报表风险的应对
A4: 编制人： | B4: 3 | C4: B23-1-2穿行测试
A5: 日 期： | B5: 4 | C5: B23-1-3关键控制点选择表（财报审计适用）
B6: 5 | C6: B23-1-4关键控制点选择表（整合审计适用）
A8: 附录、关于工作底稿索引号的编制方法
A9: 1、 工作底稿与审计程序的对应与索引
A10: 为提高工作底稿编制的针对性，各项目负责人提供的所有支持性工作底稿，均应当按自然顺序依次编制索引号，并通过唯一的索引号将审计程序表中的特定程序与相关支持性工作底稿进行一一对应。
A11: 2、 工作底稿索引号的编码规则
A12: （1）索引号的结构：包括三要素，即“项目名称代码”、“—”和“索引顺序号”，如“B23-1”、“B23-2”、........
A13: （2）索引顺序号的分层：可分为多层，如“B23-1-1”；“B23-1-2”；........

Sheet B23-1了解收入循环流程和内部控制记录表
A1: 致同会计师事务所
A2: 了解收入循环流程和内部控制记录表
A3: ='表头（请先填写）'!A2 -> 客户名称： | C3: ='表头（请先填写）'!A4 -> 编制人： | D3: ='表头（请先填写）'!A5 -> 日 期： | E3: 索引号：B23-1
A4: ='表头（请先填写）'!A3 -> 会计期间：2013年度 | C4: 复核人： | D4: 日期： | E4: 页 次：
A6: 一、本循环涉及的交易、账户及相关业务活动
A7: 1、受本循环影响的相关交易和账户余额
A8: 应收票据及坏账准备、应收账款及坏账准备、预收款项、主营业务收入
A9: 2、本循环涉及的主要业务活动
A10: 序号 | B10: 主要业务活动 | C10: 是否在本循环中进行了解 | D10: 未了解的原因
A11: 1 | B11: 新合约/变更订单 New contract/change orders | C11: 是 | D11: N/A
A12: 2 | B12: 销售订单 Sales order | C12: 是 | D12: N/A
A13: 3 | B13: 开具发票 Invoicing | C13: 是 | D13: N/A
A14: 4 | B14: 对客户的收款 Customer collections | C14: 是 | D14: N/A
A15: 5 | B15: 嵌入式衍生工具 Embedded derivatives | C15: 是 | D15: N/A
A16: 6 | B16: 与销售相关的调整、准备 Sales-related adjustments and allowances | C16: 是 | D16: N/A
B17: ……
A19: 二、本循环业务涉及的主要人员及其职责
A20: 层级或部门 | B20: 姓名 | C20: 职务 | D20: 职责及权限 | E20: 备注
A21: 治理层
A25: 高级管理层
A29: 财务人员
A33: 相关职能部门人员
A38: 三、主要业务活动介绍/销售业务流程图（需标注容易出错的领域）
A39: 1、新合约/变更单 New contract/change orders
A42: 2、销售订单 Sales order
A45: 3、开具发票 Invoicing
A49: 4、收款 Customer collections
A52: 5、嵌入式衍生工具 Embedded derivatives
A55: 6、与销售相关的调整、准备 Sales-related adjustments and allowances
A60: 参考事例：

Sheet B23-1-1链接-企业对财务报表风险的应对
A1: 致同会计师事务所
A2: 链接-企业对财务报表风险的应对
A3: ='表头（请先填写）'!A2 -> 客户名称： | B3: ='表头（请先填写）'!A4 -> 编制人： | C3: ='表头（请先填写）'!A5 -> 日 期： | E3: 索引号：B23-1-1
A4: ='表头（请先填写）'!A3 -> 会计期间：2013年度 | B4: 复核人： | C4: 日期： | E4: 页次：
A5: 认定 | B5: 风险（来自于B22-1/B22-2） | C5: 是否适用 | D5: 应对风险的活动 | E5: 应对风险的控制
A6: 完整性 Completeness | B6: 未记录的收入交易 Revenue transactions not recorded | D6: 1.**** | E6: 1.**** 2.****
D7: 2.****
A8: 完整性 Completeness | B8: 协议包含未识别的嵌入衍生工具。Agreements contain unidentified embedded derivatives
A9: 完整性 Completeness | B9: 通过增加客户信用及应收款项的方式隐藏从客户那里收回的款项，从而进行盗窃。 Theft of customer collections concealed by issuing credits
A10: 截止 Cutoff | B10: 未正确计入恰当期间的收入 Revenue not recorded in correct period
A11: 截止 Cutoff | B11: 无效的已接单但未出货的收入 Bill and hold revenue not valid
A12: 存在和发生 Existence/Occurrence | B12: 已记录应收款项不存在 Recorded receivables not valid
A13: 存在和发生 Existence/Occurrence | B13: 为隐藏舞弊而虚构客户 Fictitious customers created to conceal fraud；包括舞弊交易的销售 Revenues fraudulently recognized
A14: 存在和发生 Existence/Occurrence | B14: 包括舞弊交易的销售 Revenues fraudulently recognized
A15: 存在和发生 Existence/Occurrence | B15: 挪用客户收款 Customer collections misappropriated；
A16: 存在和发生 Existence/Occurrence | B16: 未记录的现销 Cash sales not recorded
A17: 存在和发生 Existence/Occurrence | B17: 对于合同的会计记录不符合合同条款 Contract accounting not consistent with terms
A18: 价值-毛值 Valuation - Gross | B18: 错误定价 Products sold not priced correctly
A19: 价值-毛值 Valuation - Gross | B19: 外币计量不恰当 Foreign currency measurements not proper
... A26: 权利/义务 Rights/Obligations | B26: 已完成合同的担保或持续性义务未得到适当的会计处理 Warranties or continuing obligations on completed contracts not accounted for properly
A29: 编制说明：
A30: 1、该底稿用于判断选取与风险相关的控制。
A31: 2、加黑的流程为特定风险下推荐的必选流程。如审计项目组认为还有其他的流程需要进一步选择，请打开组合“+”进行选取。
A32: 3、底稿模板中列示的为全部建议风险及流程，如果某些风险被审计单位不适用，请删除该风险及相关控制。
A33: 4、对于适用的流程，请在G列选择“√”。
A43: √
A44: ×

Sheet B23-1-2穿行测试
A1: 致同会计师事务所
A2: 穿行测试（收入循环）
A3: ='表头（请先填写）'!A2 -> 客户名称： | E3: ='表头（请先填写）'!A4 -> 编制人： | G3: ='表头（请先填写）'!A5 -> 日 期： | J3: 索引号：B23-1-2
A4: ='表头（请先填写）'!A3 -> 会计期间：2013年度 | E4: 复核人： | G4: 日 期： | J4: 页次：
A5: 活动 | B5: 控制 | D5: 穿行测试方法 （检查/观察） | E5: 所检查（取得）文件名称 | F5: 所检查（取得）文件索引号 | G5: 简述如何执行 | H5: 是否得到执行，未得到执行请解释 | I5: 是否为偏差 并解释原因 （是/否/N/A） | J5: 缺陷评价 索引号
A6: 新合约/变更单 New contract/change orders
B7: 1
B8: 2
B9: 3
B10: ……
A12: 销售订单 Sales order
B13: 1
B14: 2
B15: 3
B16: ……
A18: 开具发票 Invoicing
B19: 1
B20: 2
B21: 3
B22: ……
A24: 收款 Customer collections
B25: 1
B26: 2
B27: 3
B28: ……
A30: 嵌入式衍生工具 Embedded derivatives
B31: 1
B32: 2
B33: 3
B34: ……
A36: 与销售相关的调整、准备 Sales-related adjustments and allowances
B37: 1
B38: 2
B39: 3
B40: ……
A45: 编制说明：
A46: 1、根据对被审计单位的了解，选择检查或观察的方法，选取1个样本，填写穿行测试获得的结果。审计人员应该对之前了解的相关内控中企业已有的控制点执行穿行测试。
A47: 2、根据穿行测试的结果判断是否得到执行，如果未得到执行，说明原因，并判断是否为偏差。如果确定为偏差，应对缺陷进行评价，并索引内控缺陷评价表。
A48: 3、穿行测试的方法分为观察和检查。
A49: （1）观察：观察所执行的控制，并确定控制已得到执行。
...

Sheet B23-1-3关键控制点选择表（财报审计适用）
A1: 致同会计师事务所
A2: 关键控制点选择（收入循环）
A3: ='B23-1了解收入循环流程和内部控制记录表'!A3 -> 客户名称： | C3: ='B23-1了解收入循环流程和内部控制记录表'!C3 -> 编制人： | F3: ='B23-1了解收入循环流程和内部控制记录表'!D3 -> 日 期： | I3: 索引号：B23-1-3
A4: ='B23-1了解收入循环流程和内部控制记录表'!A4 -> 会计期间：2013年度 | C4: 复核人： | F4: 日 期： | I4: 页次：
A6: 风险、相关的“流程”和“活动”须根据具体情况分析填列，下表列示内容不适用须删除。
A7: 认定 | B7: 风险 | C7: 与风险相关的活动 | D7: 拟测试的控制 | F7: 关键控制点数量（D=A+B+C） | G7: 直接测试方法（询问观察/CAAT/抽样（检查）/重新执行)-A | H7: 管理层-重新执行-B | I7: 管理层-仅复核-C
A8: 截止性 Cutoff
B9: 未正确计入恰当期间的收入 Revenue not recorded in correct period | D9: 1 | F9: =IF(OR(G9<>0,H9<>0,I9<>0),1,0) -> 1 | G9: 抽样
D10: 2 | F10: =IF(OR(G10<>0,H10<>0,I10<>0),1,0) -> 0
D11: …… | F11: =IF(OR(G11<>0,H11<>0,I11<>0),1,0) -> 0
B12: 无效的已接单但未出货的收入 Bill and hold revenue not valid | F12: =IF(OR(G12<>0,H12<>0,I12<>0),1,0) -> 1 | G12: CAAT
A13: 存在和发生 Existence/Occurrence | F13: =IF(OR(G13<>0,H13<>0,I13<>0),1,0) -> 0
B14: 虚构客户以隐藏舞弊动机 Fictitious customers created to conceal fraud | D14: 1 | E14: 客户主文档是否定期复核，相关事项得到适当审批 | F14: =IF(OR(G14<>0,H14<>0,I14<>0),1,0) -> 1 | G14: 重新执行
D15: 2 | E15: 在客户主文档中新增项目时，录入信息恰当的与原始资料核对 | F15: =IF(OR(G15<>0,H15<>0,I15<>0),1,0) -> 1 | G15: 抽样
F16: =IF(OR(G16<>0,H16<>0,I16<>0),1,0) -> 0
B17: 包括舞弊交易的销售 Revenues fraudulently recognized | F17: =IF(OR(G17<>0,H17<>0,I17<>0),1,0) -> 0
B18: 挪用客户收款 Customer collections misappropriated | F18: =IF(OR(G18<>0,H18<>0,I18<>0),1,0) -> 0
B19: 已记录应收款项不存在 Recorded receivables not valid | F19: =IF(OR(G19<>0,H19<>0,I19<>0),1,0) -> 0
B20: 未记录的现销 Cash sales not recorded | F20: =IF(OR(G20<>0,H20<>0,I20<>0),1,0) -> 0
B21: 对于合同的会计记录不符合合同条款 Contract accounting not consistent with terms | F21: =IF(OR(G21<>0,H21<>0,I21<>0),1,0) -> 0
F22: =IF(OR(G22<>0,H22<>0,I22<>0),1,0) -> 0
A23: 准确性 - 净值 Valuation - Net | F23: =IF(OR(G23<>0,H23<>0,I23<>0),1,0) -> 0
B24: 坏账准备计提不充分 Allowance for doubtful accounts not adequate | F24: =IF(OR(G24<>0,H24<>0,I24<>0),1,0) -> 0
B25: 退货和客户索赔负债不足够 Goods returned and customer claims liabilities not adequate | F25: =IF(OR(G25<>0,H25<>0,I25<>0),1,0) -> 0
B26: 不恰当的利息计算 Imputed interest not proper | F26: =IF(OR(G26<>0,H26<>0,I26<>0),1,0) -> 0
F27: =IF(OR(G27<>0,H27<>0,I27<>0),1,0) -> 0
A28: 准确性 - 毛值 Valuation - Gross | F28: =IF(OR(G28<>0,H28<>0,I28<>0),1,0) -> 0
B29: 计价不正确 Pricing not correct | F29: =IF(OR(G29<>0,H29<>0,I29<>0),1,0) -> 0
B30: 估计的合同收入不准确 Contract estimates not accurate | F30: =IF(OR(G30<>0,H30<>0,I30<>0),1,0) -> 0
B31: 外币计量不恰当 Foreign currency measurements not proper | F31: =IF(OR(G31<>0,H31<>0,I31<>0),1,0) -> 0
B32: 多重要素安排会计核算不恰当 Multiple-element arrangements not accounted for properly | F32: =IF(OR(G32<>0,H32<>0,I32<>0),1,0) -> 0
F33: =IF(OR(G33<>0,H33<>0,I33<>0),1,0) -> 0
A34: 完整性 Completeness | F34: =IF(OR(G34<>0,H34<>0,I34<>0),1,0) -> 0
B35: 收入记录不完整 Revenue transactions not recorded | F35: =IF(OR(G35<>0,H35<>0,I35<>0),1,0) -> 0
B36: 协议包含未识别的嵌入衍生工具 Agreements contain unidentified embedded derivatives | F36: =IF(OR(G36<>0,H36<>0,I36<>0),1,0) -> 0
B37: 通过操纵客户信用额度，盗用客户收款 Theft of customer collections concealed by issuing credits | F37: =IF(OR(G37<>0,H37<>0,I37<>0),1,0) -> 0
F38: =IF(OR(G38<>0,H38<>0,I38<>0),1,0) -> 0
A39: 权利/义务 Rights/Obligations | F39: =IF(OR(G39<>0,H39<>0,I39<>0),1,0) -> 0
B40: 应收帐款销售和折扣记录不恰当 Receivables discounted or sold not accounted for properly | F40: =IF(OR(G40<>0,H40<>0,I40<>0),1,0) -> 0
B41: 已完成合同的担保或持续性义务未得到适当的会计处理 Warranties or continuing obligations on completed contracts not accounted for properly | F41: =IF(OR(G41<>0,H41<>0,I41<>0),1,0) -> 0
...

Sheet B23-1-4关键控制点选择表（整合审计适用）
A1: 致同会计师事务所
A2: 关键控制点选择（收入循环）
A3: ='B23-1了解收入循环流程和内部控制记录表'!A3 -> 客户名称： | C3: ='B23-1了解收入循环流程和内部控制记录表'!C3 -> 编制人： | F3: ='B23-1了解收入循环流程和内部控制记录表'!D3 -> 日 期： | I3: 索引号：B23-1-4
A4: ='B23-1了解收入循环流程和内部控制记录表'!A4 -> 会计期间：2013年度 | C4: 复核人： | F4: 日 期： | I4: 页次：
A6: 风险、相关的“流程”和“活动”须根据具体情况分析填列，下表列示内容不适用须删除。
A7: 认定 | B7: 风险 | C7: 与风险相关的活动 | D7: 拟测试的控制 | F7: 关键控制点数量（D=A+B+C） | G7: 直接测试方法（询问观察/CAAT/抽样（检查）/重新执行)-A | H7: 管理层-重新执行-B | I7: 管理层-仅复核-C
A8: 存在合理可能的重大错报 Reasonably Possisble
A9: 截止性 Cutoff
B10: 未正确计入恰当期间的收入 Revenue not recorded in correct period | D10: 1 | F10: =IF(OR(G10<>0,H10<>0,I10<>0),1,0) -> 0
D11: 2 | F11: =IF(OR(G11<>0,H11<>0,I11<>0),1,0) -> 0
D12: …… | F12: =IF(OR(G12<>0,H12<>0,I12<>0),1,0) -> 0
B13: 无效的已接单但未出货的收入 Bill and hold revenue not valid | F13: =IF(OR(G13<>0,H13<>0,I13<>0),1,0) -> 0
A14: 存在和发生 Existence/Occurrence | F14: =IF(OR(G14<>0,H14<>0,I14<>0),1,0) -> 0
B15: 虚构客户以隐藏舞弊动机 Fictitious customers created to conceal fraud | D15: 1 | F15: =IF(OR(G15<>0,H15<>0,I15<>0),1,0) -> 0
D16: 2 | F16: =IF(OR(G16<>0,H16<>0,I16<>0),1,0) -> 0
F17: =IF(OR(G17<>0,H17<>0,I17<>0),1,0) -> 0
B18: 包括舞弊交易的销售 Revenues fraudulently recognized | F18: =IF(OR(G18<>0,H18<>0,I18<>0),1,0) -> 0
B19: 挪用客户收款 Customer collections misappropriated | F19: =IF(OR(G19<>0,H19<>0,I19<>0),1,0) -> 0
B20: 已记录应收款项不存在 Recorded receivables not valid | F20: =IF(OR(G20<>0,H20<>0,I20<>0),1,0) -> 0
B21: 未记录的现销 Cash sales not recorded | F21: =IF(OR(G21<>0,H21<>0,I21<>0),1,0) -> 0
B22: 对于合同的会计记录不符合合同条款 Contract accounting not consistent with terms | F22: =IF(OR(G22<>0,H22<>0,I22<>0),1,0) -> 0
F23: =IF(OR(G23<>0,H23<>0,I23<>0),1,0) -> 0
A24: 准确性 - 净值 Valuation - Net | F24: =IF(OR(G24<>0,H24<>0,I24<>0),1,0) -> 0
B25: 坏账准备计提不充分 Allowance for doubtful accounts not adequate | F25: =IF(OR(G25<>0,H25<>0,I25<>0),1,0) -> 0
B26: 退货和客户索赔负债不足够 Goods returned and customer claims liabilities not adequate | F26: =IF(OR(G26<>0,H26<>0,I26<>0),1,0) -> 0
B27: 不恰当的利息计算 Imputed interest not proper | F27: =IF(OR(G27<>0,H27<>0,I27<>0),1,0) -> 0
F28: =IF(OR(G28<>0,H28<>0,I28<>0),1,0) -> 0
A29: 准确性 - 毛值 Valuation - Gross | F29: =IF(OR(G29<>0,H29<>0,I29<>0),1,0) -> 0
B30: 计价不正确 Pricing not correct | F30: =IF(OR(G30<>0,H30<>0,I30<>0),1,0) -> 0
B31: 估计的合同收入不准确 Contract estimates not accurate | F31: =IF(OR(G31<>0,H31<>0,I31<>0),1,0) -> 0
B32: 外币计量不恰当 Foreign currency measurements not proper | F32: =IF(OR(G32<>0,H32<>0,I32<>0),1,0) -> 0
B33: 多重要素安排会计核算不恰当 Multiple-element arrangements not accounted for properly | F33: =IF(OR(G33<>0,H33<>0,I33<>0),1,0) -> 0
F34: =IF(OR(G34<>0,H34<>0,I34<>0),1,0) -> 0
A35: 完整性 Completeness | F35: =IF(OR(G35<>0,H35<>0,I35<>0),1,0) -> 0
B36: 收入记录不完整 Revenue transactions not recorded | F36: =IF(OR(G36<>0,H36<>0,I36<>0),1,0) -> 0
B37: 协议包含未识别的嵌入衍生工具 Agreements contain unidentified embedded derivatives | F37: =IF(OR(G37<>0,H37<>0,I37<>0),1,0) -> 0
B38: 通过操纵客户信用额度，盗用客户收款 Theft of customer collections concealed by issuing credits | F38: =IF(OR(G38<>0,H38<>0,I38<>0),1,0) -> 0
F39: =IF(OR(G39<>0,H39<>0,I39<>0),1,0) -> 0
A40: 权利/义务 Rights/Obligations | F40: =IF(OR(G40<>0,H40<>0,I40<>0),1,0) -> 0
B41: 应收帐款销售和折扣记录不恰当 Receivables discounted or sold not accounted for properly | F41: =IF(OR(G41<>0,H41<>0,I41<>0),1,0) -> 0
...
