Workbook
Name bs: {#N/A,#N/A,FALSE,"BBPREP"}
Name bs: {#N/A,#N/A,FALSE,"BBPREP"}
Name bs_1: {#N/A,#N/A,FALSE,"BBPREP"}
Name bs_1: {#N/A,#N/A,FALSE,"BBPREP"}
Name OLE_LINK1: '附注披露信息核对（上市公司）'!$A$44

Sheet 底稿目录
A1: 底稿开列时，可先在以下单元格填写有关内容，以便其他底稿引用有关数据：
A2: 被审计单位： | D2: 序号 | E2: 内容 | F2: 索引号
A3: 截止日：202X年12月31日 | D3: 1 | E3: 应付债券实质性程序表 | F3: L4A
A4: 编制人： | D4: 2 | E4: 应付债券审定表 | F4: L4-1
A5: 编制日期： | D5: 3 | E5: 附注披露信息(上市公司) | G5: 无需打印
A6: 复核人： | D6: 4 | E6: 附注披露信息(国企) | G6: 无需打印
A7: 复核日期： | D7: 5 | E7: 应付债券明细表 | F7: L4-2
D8: 6 | E8: 划分为金融负债的其他金融工具明细表 | F8: L4-3
A9: 关于工作底稿与审计程序索引号对应的说明 | D9: 7 | E9: 调整分录汇总 | F9: L4-4
A10: 1.编制的审计工作底稿应与审计程序对应。审计项目组应根据被审计单位实际情况和风险评估情况在实质性程序表中裁剪、修改或增加审计程序，根据实际执行的审计程序完成相应审计工作底稿，编制的工作底稿中应按自然顺序依次编制索引号，并通过唯一的索引号将与实质性程序表中的程序对应关联（即将工作底稿的索引号填入实质性程序表中的底稿索引号列）。 | D10: 8 | E10: 权益与负债划分检查表 | F10: L4-5
D11: 9 | E11: 应付债券初始计量 | F11: L4-6
D12: 10 | E12: 应付债券后续计量(到期一次还本付息) | F12: L4-7
D13: 11 | E13: 应付债券后续计量(分期付息到期一次还本) | F13: L4-7
A14: 2.获取的支持性证据应与审计底稿或程序对应。审计项目组在完成底稿时获取的支持性证据应根据底稿索引号编制下一级按自然顺序排序的索引号（如D1-2-1、D1-2-2、……），并在底稿中说明引用的支持性证据、关联索引号。 | D14: 12 | E14: 应付债券账面核对(到期一次还本付息) | F14: L4-8
D15: 13 | E15: 应付债券账面核对(分期付息到期一次还本) | F15: L4-8
D16: 14 | E16: ='应付债券检查表L4-9'!A2 -> 应付债券检查底稿 | F16: L4-9
A17: 3.工作底稿索引号的编码规则：实质性程序索引号按循环从“D”到“N”,循环内账户以顺序号排列，模板中底稿索引号按账户顺序+自然数顺序（即模板中索引号按二级自然顺序排列，如D1-1、D1-2、D1-3、……D1-N）。

Sheet 应付债券实质性程序表L4A 
A1: 致同会计师事务所
A2: 应付债券实质性程序
A3: =底稿目录!A2 -> 被审计单位： | C3: =底稿目录!A4 -> 编制人： | E3: =底稿目录!A5 -> 编制日期： | H3: 索引号： | I3: L4A
A4: =底稿目录!A3 -> 截止日：202X年12月31日 | C4: =底稿目录!A6 -> 复核人： | E4: =底稿目录!A7 -> 复核日期： | H4: 页 次：
A5: 一、本账户涉及的科目
A6: 应付债券
A7: 二、审计目标与认定的对应关系
A8: 审计目标 | G8: 财务报表的认定
A9: A. 资产负债表中记录的应付债券是存在的，且已记录于恰当的账户 | G9: 存在
A10: B. 所有应记录的应付债券均已记录，所有应当包括在财务报表中的相关披露均已包括 | G10: 完整性
A11: C. 记录的应付债券是被审计单位应当履行的偿还义务 | G11: 权利和义务
A12: D. 应付债券以恰当的金额包括在财务报表中，与之相关的计价或分摊调整已恰当记录，相关披露已得到恰当计量和描述 | G12: 准确性、计价和分摊
A13: E. 应付债券已被恰当地汇总或分解且表述清楚，相关披露在按照企业会计准则的编制基础下是相关的、可理解的 | G13: 列报
A14: 三、计划实施的实质性程序
A15: 序号 | B15: 审计程序 | C15: 程序分类 | D15: 财务报表的认定 | I15: 底稿索引号
D16: 存在 | E16: 完整性 | F16: 权利和 义务 | G16: 准确性、计价和分摊 | H16: 列报 | J16: 根据被审计单位实际情况和风险评估情况裁剪、修改或增加审计程序
A17: 1 | B17: 获取或编制应付债券的明细表，完成以下工作，并编制审定表 （1）复核加计是否正确，与总账、明细账合计数核对是否相符； （2）检查非记账本位币债务的折算汇率及折算金额是否正确，折算方法是否前后期一致； （3）确定流动负债和非流动负债的划分是否正确。 | C17: 常规★ | D17: √ | E17: √ | G17: √ | I17: L4-1 /L4-2 /L4-3
A18: 2 | B18: 在使用手工编制、自定义信息报告、系统生成的非固定格式报告等由被审计单位生成的信息时，测试有关信息准确性和完整性，并针对编制和维护由被审计单位生成的信息的相关控制实施控制测试，以评价该信息是否能够为实现审计目的提供基础。 | C18: 常规★ | E18: √ | G18: √ | I18: T1 / | J18: 可参见《审计手册》4.2.6，由被审计单位生成的信息可能是由系统生成的、或手工编制的、或二者兼而有之的方式生成的。例如，由被审计单位生成的信息可能包括： • 不涉及自定义的、由系统生成的报告（如，固定格式报告）； • 可能通过人工自定义的、由系统生成的报告，例如，（计算机）查询信息或特别定制的报告； • 手工编制的信息，例如，汇总信息的电子表格或用以支持分配、计算以及调节的电子表格； • 其他系统生成或手工编制的信息，例如，由被审计单位编制的客户发票； • 通过影印、拍摄、扫描或其他方式转换成电子形式的文件记录。
A19: 3 | B19: 对期初余额的审计，取得应付债券期初余额明细表复核加计是否正确，与总账、明细账合计数是否相符，检查上期应付债券在本期转销情况，函证期初余额以及其他必要追加的审计程序。（适用于首次承接） | C19: 备选 | D19: √ | E19: √ | F19: √ | G19: √ | J19: 由被审计单位生成的信息不包括： • 总分类账或明细分类账、试算平衡表、或经审计的财务报表； • 第三方（除了服务机构）的报表或报告，例如，原始银行对账单，或函证的回函； • 外部数据（例如，第三方发布的数据，如，定价来源）。
A20: 4 | B20: 检查本期发行的债券： （1）对于本期发行的应付债券，检查债券发行申请和审批文件、银行单证、协议、募集说明书等支持性文件，确认发行的合法性、合规性及审批流程是否完整； （2）复核面值、利息、到期日、抵押、规定的付息日及债务契约等关键或重要信息，确定债券的初始确认金额是否正确、会计处理是否正确。 | C20: 常规★ | D20: √ | E20: √ | F20: √ | G20: √ | I20: L4-6
A21: 5 | B21: 后续计量： （1）重新计算应付债券溢折价摊销、利息费用计提和债权余额，与账面金额进行核对，检查会计处理是否正确； （2）结合存货、固定资产等循环审计，关注借款费用资本化是否恰当，资本化的处理是否符合规定，确认全部利息费用已正确区分为资本性支出和收益性支出，并已正确入账。 | C21: 常规★ | G21: √ | I21: L4-7 /L4-8
A22: 6 | B22: 检查应付债券记账凭证与相关的支持性文件，确定原始凭证是否齐全、记账凭证与原始凭证是否相符以及账务处理是否正确。 | C22: 常规★ | D22: √ | E22: √ | F22: √ | G22: √ | I22: L4-9
A23: 7 | B23: 考虑通过执行下列程序，关注是否存在违反债务协议条款或条件的情况： （1）检查债务协议是否存在限定性或者违约条款； （2）检查函证的回函是否有存在不履约的证据，复核贷款信息的信函，诸如更改、免除及重要事件的通知； （3）如果存在有违反债务协议约定或者条款的情况：确定和记录任何额外执行的程序、违反相关协议的影响、违约行为是否影响我们对持续经营评价。 | C23: 常规★ | F23: √ | G23: √
A24: 9 | B24: 对于可转换公司债券： （1）获取发行文件，梳理对发行人的全部合同义务的约定条款； （2）检查可转换公司债券的负债和权益成份分拆的会计处理是否正确，可转换公司债券持有人行使转换权利，将其持有的债券转为股票时其会计处理是否正确。 （3）根据或有结算条款和结算选择权、可回售工具或清算产生的义务等因素，判断被审计单位选取的会计分类是否符合企业会计准则的要求。 | C24: 备选 | D24: √ | F24: √ | G24: √ | I24: L5 /
A25: 10 | B25: 必要时对应付债券向证券承销商、包销商或债券登记机构实施函证程序： （1）以积极方式对应付债券进行函证，设计询证函、发函前核实被函证单位信息； （2）注册会计师独立收发询证函； （3）编制函证结果汇总表，检查发函、回函物流信息和轨迹、比对回函印章和签字等以核实回函的真实性，检查回函是否相符，对不符事项查明原因确定是否存在错报； （4）如果未收到回函，应当考虑与被询证者联系，要求对方作出回应或再次寄发询证函，无法收到的回函实施替代程序； （5）如果管理层不允许寄发询证函的，询问管理层不允许寄发的原因，并就其原因的正当、合理性收集证据；考虑实施替代审计程序以获取相关、可靠的审计证据； （6）如果管理层不允许寄发询证函的原因不合理、或者认为回函不可靠，评价对评估的重大错报风险以及其他审计程序的性质、时间安排和范围的影响，并确定其对审计工作和审计意见的影响。 | C25: 备选 | D25: √ | E25: √ | F25: √ | G25: √ | I25: L0
A26: 11 | B26: 根据评估的舞弊风险等因素增加的审计程序。 | C26: IPO/上市/新三板/重组/舞弊应对
A27: 12 | B27: 检查应付债券是否已按企业会计准则或其他适用的规定在财务报表中做出恰当列报和披露。 | C27: 常规★ | H27: √ | I27: A1-1/A1-15 /A1-16

Sheet 审定表L4-1
A1: 致同会计师事务所
A2: 应付债券审定表
A3: =底稿目录!A2 -> 被审计单位： | F3: =底稿目录!A4 -> 编制人： | L3: =底稿目录!A5 -> 编制日期： | Q3: 索引： | R3: =底稿目录!F4 -> L4-1
A4: =底稿目录!A3 -> 截止日：202X年12月31日 | F4: =底稿目录!A6 -> 复核人： | L4: =底稿目录!A7 -> 复核日期： | Q4: 页次：
A5: 项目 | B5: 期初数 | H5: 期末数 | N5: 本期未审数与上期 审定数的比较 | P5: 本期审定数与上期 审定数的比较 | R5: 原因分析
B6: 未审数 | C6: 账项调整 | D6: 重分类调整 | E6: 审定数 | F6: 减：一年内到期的应付债券 | G6: 最终审定数 | H6: 未审数 | I6: 账项调整 | J6: 重分类调整 | K6: 审定数 | L6: 减：一年内到期的应付债券 | M6: 最终审定数 | N6: 变动额 | O6: 变动率 | P6: 变动额 | Q6: 变动率
A7: (一)普通应付债券
A8: （1）成本 | B8: ='应付债券明细表L4-2'!M17 -> 0 | C8: ='应付债券明细表L4-2'!AJ17 -> 0 | D8: ='应付债券明细表L4-2'!AN17 -> 0 | E8: =SUM(B8:D8) -> 0 | H8: ='应付债券明细表L4-2'!AE17 -> 0 | I8: ='应付债券明细表L4-2'!AJ17+'应付债券明细表L4-2'!AR17-'应付债券明细表L4-2'!AZ17 -> 0 | J8: ='应付债券明细表L4-2'!AN17+'应付债券明细表L4-2'!AV17-'应付债券明细表L4-2'!BD17 -> 0 | K8: =SUM(H8:J8) -> 0 | N8: =H8-B8 -> 0 | O8: =IF(AND(B8=0,N8=0),0,IF(AND(B8=0,N8>0),1,N8/B8)) -> 0 | P8: =K8-E8 -> 0 | Q8: =IF(AND(E8=0,P8=0),0,IF(AND(E8=0,P8>0),1,P8/E8)) -> 0
A9: （2）利息调整 | B9: ='应付债券明细表L4-2'!N17 -> 0 | C9: ='应付债券明细表L4-2'!AK17 -> 0 | D9: ='应付债券明细表L4-2'!AO17 -> 0 | E9: =SUM(B9:D9) -> 0 | H9: ='应付债券明细表L4-2'!AF17 -> 0 | I9: ='应付债券明细表L4-2'!AK17+'应付债券明细表L4-2'!AS17-'应付债券明细表L4-2'!BA17 -> 0 | J9: ='应付债券明细表L4-2'!AO17+'应付债券明细表L4-2'!AW17-'应付债券明细表L4-2'!BE17 -> 0 | K9: =SUM(H9:J9) -> 0 | N9: =H9-B9 -> 0 | O9: =IF(AND(B9=0,N9=0),0,IF(AND(B9=0,N9>0),1,N9/B9)) -> 0 | P9: =K9-E9 -> 0 | Q9: =IF(AND(E9=0,P9=0),0,IF(AND(E9=0,P9>0),1,P9/E9)) -> 0
A10: （3）应计利息 | B10: ='应付债券明细表L4-2'!O17 -> 0 | C10: ='应付债券明细表L4-2'!AL17 -> 0 | D10: ='应付债券明细表L4-2'!AP17 -> 0 | E10: =SUM(B10:D10) -> 0 | H10: ='应付债券明细表L4-2'!AG17 -> 0 | I10: ='应付债券明细表L4-2'!AL17+'应付债券明细表L4-2'!AT17-'应付债券明细表L4-2'!BB17 -> 0 | J10: ='应付债券明细表L4-2'!AP17+'应付债券明细表L4-2'!AX17-'应付债券明细表L4-2'!BF17 -> 0 | K10: =SUM(H10:J10) -> 0 | N10: =H10-B10 -> 0 | O10: =IF(AND(B10=0,N10=0),0,IF(AND(B10=0,N10>0),1,N10/B10)) -> 0 | P10: =K10-E10 -> 0 | Q10: =IF(AND(E10=0,P10=0),0,IF(AND(E10=0,P10>0),1,P10/E10)) -> 0
A11: 小计 | B11: =SUM(B8:B10) -> 0 | C11: =SUM(C8:C10) -> 0 | D11: =SUM(D8:D10) -> 0 | E11: =SUM(E8:E10) -> 0 | F11: ='应付债券明细表L4-2'!BM17 -> 0 | G11: =E11-F11 -> 0 | H11: =SUM(H8:H10) -> 0 | I11: =SUM(I8:I10) -> 0 | J11: =SUM(J8:J10) -> 0 | K11: =SUM(K8:K10) -> 0 | L11: ='应付债券明细表L4-2'!CG17 -> 0 | M11: =K11-L11 -> 0 | N11: =H11-B11 -> 0 | O11: =IF(AND(B11=0,N11=0),0,IF(AND(B11=0,N11>0),1,N11/B11)) -> 0 | P11: =K11-E11 -> 0 | Q11: =IF(AND(E11=0,P11=0),0,IF(AND(E11=0,P11>0),1,P11/E11)) -> 0
A12: （二）可转换公司债券
A13: （1）成本 | B13: ='应付债券明细表L4-2'!M21 -> 0 | C13: ='应付债券明细表L4-2'!AJ21 -> 0 | D13: ='应付债券明细表L4-2'!AN21 -> 0 | E13: =SUM(B13:D13) -> 0 | H13: ='应付债券明细表L4-2'!AE21 -> 0 | I13: ='应付债券明细表L4-2'!AJ21+'应付债券明细表L4-2'!AR21-'应付债券明细表L4-2'!AZ21 -> 0 | J13: ='应付债券明细表L4-2'!AN21+'应付债券明细表L4-2'!AV21-'应付债券明细表L4-2'!BD21 -> 0 | K13: =SUM(H13:J13) -> 0 | N13: =H13-B13 -> 0 | O13: =IF(AND(B13=0,N13=0),0,IF(AND(B13=0,N13>0),1,N13/B13)) -> 0 | P13: =K13-E13 -> 0 | Q13: =IF(AND(E13=0,P13=0),0,IF(AND(E13=0,P13>0),1,P13/E13)) -> 0
A14: （2）利息调整 | B14: ='应付债券明细表L4-2'!N21 -> 0 | C14: ='应付债券明细表L4-2'!AK21 -> 0 | D14: ='应付债券明细表L4-2'!AO21 -> 0 | E14: =SUM(B14:D14) -> 0 | H14: ='应付债券明细表L4-2'!AF21 -> 0 | I14: ='应付债券明细表L4-2'!AK21+'应付债券明细表L4-2'!AS21-'应付债券明细表L4-2'!BA21 -> 0 | J14: ='应付债券明细表L4-2'!AO21+'应付债券明细表L4-2'!AW21-'应付债券明细表L4-2'!BE21 -> 0 | K14: =SUM(H14:J14) -> 0 | N14: =H14-B14 -> 0 | O14: =IF(AND(B14=0,N14=0),0,IF(AND(B14=0,N14>0),1,N14/B14)) -> 0 | P14: =K14-E14 -> 0 | Q14: =IF(AND(E14=0,P14=0),0,IF(AND(E14=0,P14>0),1,P14/E14)) -> 0
A15: （3）应计利息 | B15: ='应付债券明细表L4-2'!O21 -> 0 | C15: ='应付债券明细表L4-2'!AL21 -> 0 | D15: ='应付债券明细表L4-2'!AP21 -> 0 | E15: =SUM(B15:D15) -> 0 | H15: ='应付债券明细表L4-2'!AG21 -> 0 | I15: ='应付债券明细表L4-2'!AL21+'应付债券明细表L4-2'!AT21-'应付债券明细表L4-2'!BB21 -> 0 | J15: ='应付债券明细表L4-2'!AP21+'应付债券明细表L4-2'!AX21-'应付债券明细表L4-2'!BF21 -> 0 | K15: =SUM(H15:J15) -> 0 | N15: =H15-B15 -> 0 | O15: =IF(AND(B15=0,N15=0),0,IF(AND(B15=0,N15>0),1,N15/B15)) -> 0 | P15: =K15-E15 -> 0 | Q15: =IF(AND(E15=0,P15=0),0,IF(AND(E15=0,P15>0),1,P15/E15)) -> 0
A16: 小计 | B16: =SUM(B13:B15) -> 0 | C16: =SUM(C13:C15) -> 0 | D16: =SUM(D13:D15) -> 0 | E16: =SUM(E13:E15) -> 0 | F16: ='应付债券明细表L4-2'!BM21 -> 0 | G16: =E16-F16 -> 0 | H16: =SUM(H13:H15) -> 0 | I16: =SUM(I13:I15) -> 0 | J16: =SUM(J13:J15) -> 0 | K16: =SUM(K13:K15) -> 0 | L16: ='应付债券明细表L4-2'!CG21 -> 0 | M16: =K16-L16 -> 0 | N16: =H16-B16 -> 0 | O16: =IF(AND(B16=0,N16=0),0,IF(AND(B16=0,N16>0),1,N16/B16)) -> 0 | P16: =K16-E16 -> 0 | Q16: =IF(AND(E16=0,P16=0),0,IF(AND(E16=0,P16>0),1,P16/E16)) -> 0
A17: 划分为金融负债的其他金融工具 | B17: ='划分为金融负债的其他金融工具明细表L4-3'!M18 -> 0 | C17: ='划分为金融负债的其他金融工具明细表L4-3'!U18 -> 0 | D17: ='划分为金融负债的其他金融工具明细表L4-3'!W18 -> 0 | E17: =B17+C17+D17 -> 0 | H17: ='划分为金融负债的其他金融工具明细表L4-3'!S18 -> 0 | I17: ='划分为金融负债的其他金融工具明细表L4-3'!U18+'划分为金融负债的其他金融工具明细表L4-3'!Y18-'划分为金融负债的其他金融工具明细表L4-3'!AA18 -> 0 | J17: ='划分为金融负债的其他金融工具明细表L4-3'!W18+'划分为金融负债的其他金融工具明细表L4-3'!AC18-'划分为金融负债的其他金融工具明细表L4-3'!AE18 -> 0 | K17: =H17+I17+J17 -> 0 | M17: =K17-L17 -> 0 | N17: =H17-B17 -> 0 | O17: =IF(AND(B17=0,N17=0),0,IF(AND(B17=0,N17>0),1,N17/B17)) -> 0 | P17: =K17-E17 -> 0 | Q17: =IF(AND(E17=0,P17=0),0,IF(AND(E17=0,P17>0),1,P17/E17)) -> 0
A18: 合计 | B18: =B11+B16+B17 -> 0 | C18: =C11+C16+C17 -> 0 | D18: =D11+D16+D17 -> 0 | E18: =E11+E16+E17 -> 0 | F18: =F11+F16+F17 -> 0 | G18: =G11+G16+G17 -> 0 | H18: =H11+H16+H17 -> 0 | I18: =I11+I16+I17 -> 0 | ... N18: =N11+N16+N17 -> 0 | O18: =IF(AND(B18=0,N18=0),0,IF(AND(B18=0,N18>0),1,N18/B18)) -> 0 | P18: =P11+P16+P17 -> 0 | Q18: =IF(AND(E18=0,P18=0),0,IF(AND(E18=0,P18>0),1,P18/E18)) -> 0
A19: 1、审计说明：
A22: 2、审计结论：

Sheet 附注披露信息核对（上市公司）
A1: 致同会计师事务所
A2: 应付债券附注披露信息 | K2: 返回目录
A3: =底稿目录!A2 -> 被审计单位： | D3: =底稿目录!A4 -> 编制人： | G3: =底稿目录!A5 -> 编制日期： | I3: 索引号：
A4: =底稿目录!A3 -> 截止日：202X年12月31日 | D4: =底稿目录!A6 -> 复核人： | G4: =底稿目录!A7 -> 复核日期： | I4: 页次：
A5: 附注披露信息（上市公司）
A6: 项 目 | B6: 期末余额 | C6: 上年年末余额
A7: ='应付债券明细表L4-2'!B15 -> 0 | B7: ='应付债券明细表L4-2'!CH15 -> 0 | C7: ='应付债券明细表L4-2'!BN15 -> 0
A8: ='应付债券明细表L4-2'!B16 -> 0 | B8: ='应付债券明细表L4-2'!CH16 -> 0 | C8: ='应付债券明细表L4-2'!BN16 -> 0
A9: ='应付债券明细表L4-2'!B19 -> 0 | B9: ='应付债券明细表L4-2'!CH19 -> 0 | C9: ='应付债券明细表L4-2'!BN19 -> 0
A10: ='应付债券明细表L4-2'!B20 -> 0 | B10: ='应付债券明细表L4-2'!CH20 -> 0 | C10: ='应付债券明细表L4-2'!BN20 -> 0
A11: ='划分为金融负债的其他金融工具明细表L4-3'!A13 -> 0 | B11: ='划分为金融负债的其他金融工具明细表L4-3'!AM13 -> 0 | C11: ='划分为金融负债的其他金融工具明细表L4-3'!AG13 -> 0
A12: ='划分为金融负债的其他金融工具明细表L4-3'!A14 -> 0 | B12: ='划分为金融负债的其他金融工具明细表L4-3'!AM14 -> 0 | C12: ='划分为金融负债的其他金融工具明细表L4-3'!AG14 -> 0
A13: ='划分为金融负债的其他金融工具明细表L4-3'!A15 -> 0 | B13: ='划分为金融负债的其他金融工具明细表L4-3'!AM15 -> 0 | C13: ='划分为金融负债的其他金融工具明细表L4-3'!AG15 -> 0
A14: ='划分为金融负债的其他金融工具明细表L4-3'!A16 -> 0 | B14: ='划分为金融负债的其他金融工具明细表L4-3'!AM16 -> 0 | C14: ='划分为金融负债的其他金融工具明细表L4-3'!AG16 -> 0
A15: ='划分为金融负债的其他金融工具明细表L4-3'!A17 -> 0 | B15: ='划分为金融负债的其他金融工具明细表L4-3'!AM17 -> 0 | C15: ='划分为金融负债的其他金融工具明细表L4-3'!AG17 -> 0
A16: 合 计 | B16: =SUM(B7:B15) -> 0 | C16: =SUM(C7:C15) -> 0
A17: （1）应付债券的增减变动（不包括划分为金融负债的优先股、永续债等其他金融工具）
A18: 债券名称 | B18: 面值 | C18: 票面利率 | D18: 发行日期 | E18: 债券期限 | F18: 发行金额
A19: ='应付债券明细表L4-2'!B15 -> 0 | B19: ='应付债券明细表L4-2'!G15 -> 0 | C19: ='应付债券明细表L4-2'!F15 -> 0 | D19: ='应付债券明细表L4-2'!C15 -> 0 | E19: ='应付债券明细表L4-2'!E15 -> 0 | F19: ='应付债券明细表L4-2'!H15 -> 0
A20: ='应付债券明细表L4-2'!B16 -> 0 | B20: ='应付债券明细表L4-2'!G16 -> 0 | C20: ='应付债券明细表L4-2'!F16 -> 0 | D20: ='应付债券明细表L4-2'!C16 -> 0 | E20: ='应付债券明细表L4-2'!E16 -> 0 | F20: ='应付债券明细表L4-2'!H16 -> 0
A21: ='应付债券明细表L4-2'!B17 -> 0 | B21: ='应付债券明细表L4-2'!G17 -> 0 | C21: ='应付债券明细表L4-2'!F17 -> 0 | D21: ='应付债券明细表L4-2'!C17 -> 0 | E21: ='应付债券明细表L4-2'!E17 -> 0 | F21: ='应付债券明细表L4-2'!H17 -> 0
A22: ='应付债券明细表L4-2'!B18 -> 0 | B22: ='应付债券明细表L4-2'!G18 -> 0 | C22: ='应付债券明细表L4-2'!F18 -> 0 | D22: ='应付债券明细表L4-2'!C18 -> 0 | E22: ='应付债券明细表L4-2'!E18 -> 0 | F22: ='应付债券明细表L4-2'!H18 -> 0
A23: ='应付债券明细表L4-2'!B19 -> 0 | B23: ='应付债券明细表L4-2'!G19 -> 0 | C23: ='应付债券明细表L4-2'!F19 -> 0 | D23: ='应付债券明细表L4-2'!C19 -> 0 | E23: ='应付债券明细表L4-2'!E19 -> 0 | F23: ='应付债券明细表L4-2'!H19 -> 0
A24: ='应付债券明细表L4-2'!B20 -> 0 | B24: ='应付债券明细表L4-2'!G20 -> 0 | C24: ='应付债券明细表L4-2'!F20 -> 0 | D24: ='应付债券明细表L4-2'!C20 -> 0 | E24: ='应付债券明细表L4-2'!E20 -> 0 | F24: ='应付债券明细表L4-2'!H20 -> 0
A25: 小 计 | B25: =SUM(B19:B24) -> 0 | F25: =SUM(F19:F24) -> 0
A26: 应付债券（续）
A27: 债券名称 | B27: 期初余额 | C27: 本期发行 | D27: 按面值计提利息 | E27: 溢折价摊销 | F27: 本期偿还 | G27: 期末余额 | H27: 是否违约
A28: ='应付债券明细表L4-2'!B15 -> 0 | B28: ='应付债券明细表L4-2'!BN15 -> 0 | C28: ='应付债券明细表L4-2'!BQ15 -> 0 | D28: ='应付债券明细表L4-2'!BS15 -> 0 | E28: ='应付债券明细表L4-2'!BR15-'应付债券明细表L4-2'!BX15 -> 0 | F28: ='应付债券明细表L4-2'!BW15+'应付债券明细表L4-2'!BY15 -> 0 | G28: =B28+C28+D28+E28-F28 -> 0 | H28: ='应付债券明细表L4-2'!I15 -> 0
A29: ='应付债券明细表L4-2'!B16 -> 0 | B29: ='应付债券明细表L4-2'!BN16 -> 0 | C29: ='应付债券明细表L4-2'!BQ16 -> 0 | D29: ='应付债券明细表L4-2'!BS16 -> 0 | E29: ='应付债券明细表L4-2'!BR16-'应付债券明细表L4-2'!BX16 -> 0 | F29: ='应付债券明细表L4-2'!BW16+'应付债券明细表L4-2'!BY16 -> 0 | G29: =B29+C29+D29+E29-F29 -> 0 | H29: ='应付债券明细表L4-2'!I16 -> 0
A30: ='应付债券明细表L4-2'!B19 -> 0 | B30: ='应付债券明细表L4-2'!BN19 -> 0 | C30: ='应付债券明细表L4-2'!BQ19 -> 0 | D30: ='应付债券明细表L4-2'!BS19 -> 0 | E30: ='应付债券明细表L4-2'!BR19-'应付债券明细表L4-2'!BX19 -> 0 | F30: ='应付债券明细表L4-2'!BW19+'应付债券明细表L4-2'!BY19 -> 0 | G30: =B30+C30+D30+E30-F30 -> 0 | H30: ='应付债券明细表L4-2'!I19 -> 0
A31: ='应付债券明细表L4-2'!B20 -> 0 | B31: ='应付债券明细表L4-2'!BN20 -> 0 | C31: ='应付债券明细表L4-2'!BQ20 -> 0 | D31: ='应付债券明细表L4-2'!BS20 -> 0 | E31: ='应付债券明细表L4-2'!BR20-'应付债券明细表L4-2'!BX20 -> 0 | F31: ='应付债券明细表L4-2'!BW20+'应付债券明细表L4-2'!BY20 -> 0 | G31: =B31+C31+D31+E31-F31 -> 0 | H31: ='应付债券明细表L4-2'!I20 -> 0
A32: 小 计 | B32: =SUM(B28:B31) -> 0 | C32: =SUM(C28:C31) -> 0 | D32: =SUM(D28:D31) -> 0 | E32: =SUM(E28:E31) -> 0 | F32: =SUM(F28:F31) -> 0 | G32: =SUM(G28:G31) -> 0
A33: 减：一年内到期的应付债券 | B33: ='应付债券明细表L4-2'!BM22 -> 0 | G33: ='应付债券明细表L4-2'!CG22 -> 0
A34: 合 计 | B34: =B32-B33 -> 0 | G34: =G32-G33 -> 0
A35: （2）可转换公司债券
A36: 说明：（披露可转换公司债券的转股条件、转股时间、转股权会计处理及相关判断依据等。（15号文第二十条（十））
A37: 根据中国证券监督管理委员会证监发行字[201x]XX号核准，本公司于202X年X月X日至202X年X月X日公开发行XX份可转换公司债券，每份面值100元，发行总额XXX元，债券期限为X年。
A38: 本公司发行的可转换公司债券的票面利率为X%，利息按季支付，202X年X月X日为第一次派息日。转股期自发行之日起(202X年X月X日)X个月后的第一个交易日(202X年X月X日)起(含当日)，至可转换公司债券到期日(202X年X月X日)前一个交易日止(含当日)。持有人可在转股期内申请转股。该转股权符合《企业会计准则第37号——金融工具列报》有关权益工具的定义，即满足“固定换固定”原则，本公司将其确认为一项权益工具（其他权益工具），并以发行价格减去不附认股权且其他条件相同的公司债券公允价值后的净额进行计量。
A39: 可转换公司债券发行时的初始转股价格为每股X元，本公司在202X年X月X日实施202X年度每股派发现金股息X元及用资本公积每十股转增X股的方案后，可转债初始转股价格相应调整为每股X元。
A40: （3）划分为金融负债的其他金融工具
...

Sheet 附注披露信息核对（国企）
A1: 致同会计师事务所
A2: 应付债券附注披露信息 | K2: 返回目录
A3: =底稿目录!A2 -> 被审计单位： | D3: =底稿目录!A4 -> 编制人： | G3: =底稿目录!A5 -> 编制日期： | J3: 索引号：
A4: =底稿目录!A3 -> 截止日：202X年12月31日 | D4: =底稿目录!A6 -> 复核人： | G4: =底稿目录!A7 -> 复核日期： | J4: 页次：
A5: 附注披露信息（国企）
A6: 项 目 | B6: 期末余额 | C6: 期初余额
A7: ='应付债券明细表L4-2'!B15 -> 0 | B7: ='应付债券明细表L4-2'!CH15 -> 0 | C7: ='应付债券明细表L4-2'!BN15 -> 0
A8: ='应付债券明细表L4-2'!B16 -> 0 | B8: ='应付债券明细表L4-2'!CH16 -> 0 | C8: ='应付债券明细表L4-2'!BN16 -> 0
A9: ='应付债券明细表L4-2'!B19 -> 0 | B9: ='应付债券明细表L4-2'!CH19 -> 0 | C9: ='应付债券明细表L4-2'!BN19 -> 0
A10: ='应付债券明细表L4-2'!B20 -> 0 | B10: ='应付债券明细表L4-2'!CH20 -> 0 | C10: ='应付债券明细表L4-2'!BN20 -> 0
A11: ='划分为金融负债的其他金融工具明细表L4-3'!A13 -> 0 | B11: ='划分为金融负债的其他金融工具明细表L4-3'!AM13 -> 0 | C11: ='划分为金融负债的其他金融工具明细表L4-3'!AG13 -> 0
A12: ='划分为金融负债的其他金融工具明细表L4-3'!A14 -> 0 | B12: ='划分为金融负债的其他金融工具明细表L4-3'!AM14 -> 0 | C12: ='划分为金融负债的其他金融工具明细表L4-3'!AG14 -> 0
A13: ='划分为金融负债的其他金融工具明细表L4-3'!A15 -> 0 | B13: ='划分为金融负债的其他金融工具明细表L4-3'!AM15 -> 0 | C13: ='划分为金融负债的其他金融工具明细表L4-3'!AG15 -> 0
A14: ='划分为金融负债的其他金融工具明细表L4-3'!A16 -> 0 | B14: ='划分为金融负债的其他金融工具明细表L4-3'!AM16 -> 0 | C14: ='划分为金融负债的其他金融工具明细表L4-3'!AG16 -> 0
A15: ='划分为金融负债的其他金融工具明细表L4-3'!A17 -> 0 | B15: ='划分为金融负债的其他金融工具明细表L4-3'!AM17 -> 0 | C15: ='划分为金融负债的其他金融工具明细表L4-3'!AG17 -> 0
A16: 合 计 | B16: =SUM(B7:B15) -> 0 | C16: =SUM(C7:C15) -> 0
A17: 债券名称 | B17: 面值 | C17: 发行日期 | D17: 债券期限 | E17: 发行金额 | F17: 年初应付利息 | G17: 本期应计利息 | H17: 本期已付利息 | I17: 期末应付利息 | J17: 期末余额
A18: ='应付债券明细表L4-2'!B15 -> 0 | B18: ='应付债券明细表L4-2'!G15 -> 0 | C18: ='应付债券明细表L4-2'!C15 -> 0 | D18: ='应付债券明细表L4-2'!E15 -> 0 | E18: ='应付债券明细表L4-2'!H15 -> 0 | F18: ='应付债券明细表L4-2'!BK15 -> 0 | G18: ='应付债券明细表L4-2'!BS15 -> 0 | H18: ='应付债券明细表L4-2'!BY15 -> 0 | I18: ='应付债券明细表L4-2'!CE15 -> 0 | J18: ='应付债券明细表L4-2'!CF15 -> 0
A19: ='应付债券明细表L4-2'!B16 -> 0 | B19: ='应付债券明细表L4-2'!G16 -> 0 | C19: ='应付债券明细表L4-2'!C16 -> 0 | D19: ='应付债券明细表L4-2'!E16 -> 0 | E19: ='应付债券明细表L4-2'!H16 -> 0 | F19: ='应付债券明细表L4-2'!BK16 -> 0 | G19: ='应付债券明细表L4-2'!BS16 -> 0 | H19: ='应付债券明细表L4-2'!BY16 -> 0 | I19: ='应付债券明细表L4-2'!CE16 -> 0 | J19: ='应付债券明细表L4-2'!CF16 -> 0
A20: ='应付债券明细表L4-2'!B19 -> 0 | B20: ='应付债券明细表L4-2'!G19 -> 0 | C20: ='应付债券明细表L4-2'!C19 -> 0 | D20: ='应付债券明细表L4-2'!E19 -> 0 | E20: ='应付债券明细表L4-2'!H19 -> 0 | F20: ='应付债券明细表L4-2'!BK19 -> 0 | G20: ='应付债券明细表L4-2'!BS19 -> 0 | H20: ='应付债券明细表L4-2'!BY19 -> 0 | I20: ='应付债券明细表L4-2'!CE19 -> 0 | J20: ='应付债券明细表L4-2'!CF19 -> 0
A21: ='应付债券明细表L4-2'!B20 -> 0 | B21: ='应付债券明细表L4-2'!G20 -> 0 | C21: ='应付债券明细表L4-2'!C20 -> 0 | D21: ='应付债券明细表L4-2'!E20 -> 0 | E21: ='应付债券明细表L4-2'!H20 -> 0 | F21: ='应付债券明细表L4-2'!BK20 -> 0 | G21: ='应付债券明细表L4-2'!BS20 -> 0 | H21: ='应付债券明细表L4-2'!BY20 -> 0 | I21: ='应付债券明细表L4-2'!CE20 -> 0 | J21: ='应付债券明细表L4-2'!CF20 -> 0
A22: 小计 | B22: — | C22: — | D22: — | E22: — | J22: =SUM(J18:J21) -> 0
A23: 减：一年内到期的应付债券 | J23: ='应付债券明细表L4-2'!CG22 -> 0
A24: 合计 | B24: — | C24: — | D24: — | E24: — | J24: =J22-J23 -> 0
A25: 注：企业需说明可转换公司债券的转股条件、转股时间等情况。
A26: 【根据中国证券监督管理委员会证监发行字[200x]XX号核准，本公司于200X年X月X日至200X年X月X日公开发行XX份可转换公司债券，每份面值100元，发行总额XXX元，债券期限为X年。
A27: 本公司发行的可转换公司债券的票面利率为X%，利息按季支付，200X年X月X日为第一次派息日。转股期自发行之日起(200X年X月X日)X个月后的第一个交易日(200X年X月X日)起(含当日)，至可转换公司债券到期日(200X年X月X日)前一个交易日止(含当日)。持有人可在转股期内申请转股。
A28: 可转换公司债券发行时的初始转股价格为每股人民币X元，本公司在200X年X月X日实施200X年度每股派发现金股息人民币X元及用资本公积每十股转增X股的方案后，可转债初始转股价格相应调整为每股人民币X元。】
A29: （3）划分为金融负债的其他金融工具
A30: 【公司发行其他金融工具并划分为金融负债的，应分项披露其基本情况、期初余额、期末余额和本期增减变动情况，以及划分至金融负债的依据。】
A31: 期末发行在外的优先股、永续债等其他金融工具的基本情况：
A32: 参考披露格式：
A33: 发行在外的金融工具 | B33: 发行时间 | C33: 会计分类 | D33: 股利率或利息率 | E33: 发行价格 | F33: 数量 | G33: 金额 | H33: 到期日或续期情况 | I33: 转股条件 | J33: 转换情况
A34: ='划分为金融负债的其他金融工具明细表L4-3'!A13 -> 0 | B34: ='划分为金融负债的其他金融工具明细表L4-3'!C13 -> 0 | C34: ='划分为金融负债的其他金融工具明细表L4-3'!D13 -> 0 | D34: ='划分为金融负债的其他金融工具明细表L4-3'!E13 -> 0 | E34: ='划分为金融负债的其他金融工具明细表L4-3'!F13 -> 0 | F34: ='划分为金融负债的其他金融工具明细表L4-3'!G13 -> 0 | G34: ='划分为金融负债的其他金融工具明细表L4-3'!H13 -> 0 | H34: ='划分为金融负债的其他金融工具明细表L4-3'!I13 -> 0 | I34: ='划分为金融负债的其他金融工具明细表L4-3'!J13 -> 0 | J34: ='划分为金融负债的其他金融工具明细表L4-3'!K13 -> 0
A35: ='划分为金融负债的其他金融工具明细表L4-3'!A14 -> 0 | B35: ='划分为金融负债的其他金融工具明细表L4-3'!C14 -> 0 | C35: ='划分为金融负债的其他金融工具明细表L4-3'!D14 -> 0 | D35: ='划分为金融负债的其他金融工具明细表L4-3'!E14 -> 0 | E35: ='划分为金融负债的其他金融工具明细表L4-3'!F14 -> 0 | F35: ='划分为金融负债的其他金融工具明细表L4-3'!G14 -> 0 | G35: ='划分为金融负债的其他金融工具明细表L4-3'!H14 -> 0 | H35: ='划分为金融负债的其他金融工具明细表L4-3'!I14 -> 0 | I35: ='划分为金融负债的其他金融工具明细表L4-3'!J14 -> 0 | J35: ='划分为金融负债的其他金融工具明细表L4-3'!K14 -> 0
A36: ='划分为金融负债的其他金融工具明细表L4-3'!A15 -> 0 | B36: ='划分为金融负债的其他金融工具明细表L4-3'!C15 -> 0 | C36: ='划分为金融负债的其他金融工具明细表L4-3'!D15 -> 0 | D36: ='划分为金融负债的其他金融工具明细表L4-3'!E15 -> 0 | E36: ='划分为金融负债的其他金融工具明细表L4-3'!F15 -> 0 | F36: ='划分为金融负债的其他金融工具明细表L4-3'!G15 -> 0 | G36: ='划分为金融负债的其他金融工具明细表L4-3'!H15 -> 0 | H36: ='划分为金融负债的其他金融工具明细表L4-3'!I15 -> 0 | I36: ='划分为金融负债的其他金融工具明细表L4-3'!J15 -> 0 | J36: ='划分为金融负债的其他金融工具明细表L4-3'!K15 -> 0
A37: ='划分为金融负债的其他金融工具明细表L4-3'!A16 -> 0 | B37: ='划分为金融负债的其他金融工具明细表L4-3'!C16 -> 0 | C37: ='划分为金融负债的其他金融工具明细表L4-3'!D16 -> 0 | D37: ='划分为金融负债的其他金融工具明细表L4-3'!E16 -> 0 | E37: ='划分为金融负债的其他金融工具明细表L4-3'!F16 -> 0 | F37: ='划分为金融负债的其他金融工具明细表L4-3'!G16 -> 0 | G37: ='划分为金融负债的其他金融工具明细表L4-3'!H16 -> 0 | H37: ='划分为金融负债的其他金融工具明细表L4-3'!I16 -> 0 | I37: ='划分为金融负债的其他金融工具明细表L4-3'!J16 -> 0 | J37: ='划分为金融负债的其他金融工具明细表L4-3'!K16 -> 0
A38: ='划分为金融负债的其他金融工具明细表L4-3'!A17 -> 0 | B38: ='划分为金融负债的其他金融工具明细表L4-3'!C17 -> 0 | C38: ='划分为金融负债的其他金融工具明细表L4-3'!D17 -> 0 | D38: ='划分为金融负债的其他金融工具明细表L4-3'!E17 -> 0 | E38: ='划分为金融负债的其他金融工具明细表L4-3'!F17 -> 0 | F38: ='划分为金融负债的其他金融工具明细表L4-3'!G17 -> 0 | G38: ='划分为金融负债的其他金融工具明细表L4-3'!H17 -> 0 | H38: ='划分为金融负债的其他金融工具明细表L4-3'!I17 -> 0 | I38: ='划分为金融负债的其他金融工具明细表L4-3'!J17 -> 0 | J38: ='划分为金融负债的其他金融工具明细表L4-3'!K17 -> 0
A39: 可无限加行
A40: 合计 | G40: =SUM(G34:G39) -> 0
...

Sheet 应付债券明细表L4-2
A1: 致同会计师事务所 | AI1: 致同会计师事务所 | BG1: 致同会计师事务所
A2: 应付债券明细表(未审数) | AI2: 应付债券明细表(审计调整) | BG2: 应付债券明细表(审定数)
A3: =底稿目录!A2 -> 被审计单位： | K3: =底稿目录!A4 -> 编制人： | W3: =底稿目录!A5 -> 编制日期： | AG3: 索引号： | AH3: =底稿目录!F7 -> L4-2 | AR3: =底稿目录!A4 -> 编制人： | AZ3: =底稿目录!A5 -> 编制日期： | BE3: 索引号： | BF3: =底稿目录!F7 -> L4-2 | BR3: =底稿目录!A4 -> 编制人： | BZ3: =底稿目录!A5 -> 编制日期： | CI3: 索引号： | CJ3: =底稿目录!F7 -> L4-2
A4: =底稿目录!A3 -> 截止日：202X年12月31日 | K4: =底稿目录!A6 -> 复核人： | W4: =底稿目录!A7 -> 复核日期： | AG4: 页次： | AR4: 复核人： | AZ4: =底稿目录!A7 -> 复核日期： | BE4: 页次： | BR4: 复核人： | BZ4: =底稿目录!A7 -> 复核日期： | CI4: 页次：
C5: 一、审计目标:
C6: 1.资产负债表中记录的应付债券是存在的，且已经记录在恰当的账户中；
C7: 2. 所有应记录的短期借款均已记录，所有应当包括在财务报表中的相关披露均已包括；
C8: 3.应付债券以恰当的金额包括在财务报表中，与之相关的计价或分摊调整已恰当记录，相关披露已得到恰当计量和描述
C9: 二、审计过程：
C10: 获取发行文件，梳理对发行人的全部合同义务的约定条款；根据或有结算条款和结算选择权、可回售工具或清算产生的义务等因素，判断被审计单位选取的会计分类是否符合企业会计准则的要求；考虑是否需要对复合型金融产品各成分的拆分；如果发现会计分类方面的重大差异，应与管理层沟通，并执行其他补充审计程序。
A11: 序号 | B11: 债券名称 | C11: 债券期限 | F11: 票面利率 | G11: 面值 | H11: 发行金额 | I11: 是否违约 | J11: 初始溢(折)价额 | K11: 未审数 | AI11: 期初调整 | AQ11: 本期增加调整 | AY11: 本期减少调整 | BG11: 审定数 | CI11: 可转换公司债券
C12: 起息日 | D12: 到期日 | E12: 期限 | K12: 期初余额 | Q12: 本期增加 | W12: 本期减少 | AC12: 期末余额 | AI12: 账项调整 | AM12: 重分类调整 | AQ12: 账项调整 | AU12: 重分类调整 | AY12: 账项调整 | BC12: 重分类调整 | BG12: 期初余额 | BO12: 本期增加 | BU12: 本期减少 | CA12: 期末余额 | CI12: 转股条件 | CJ12: 转股时间
K13: 单位面值(净值) | L13: 数量 | M13: 面值 | N13: 利息调整 | O13: 应计利息 | P13: 合计 | Q13: 单位面值(净值) | R13: 数量 | S13: 面值 | T13: 利息调整 | U13: 应计利息 | V13: 合计 | W13: 单位面值(净值) | X13: 数量 | Y13: 面值 | Z13: 利息调整 | AA13: 应计利息 | AB13: 合计 | AC13: 单位面值(净值) | AD13: 数量 | AE13: 面值 | AF13: 利息调整 | AG13: 应计利息 | AH13: 合计 | AI13: 数量 | AJ13: 面值 | AK13: 利息调整 | AL13: 应计利息 | AM13: 数量 | AN13: 面值 | AO13: 利息调整 | AP13: 应计利息 | AQ13: 数量 | AR13: 面值 | AS13: 利息调整 | AT13: 应计利息 | AU13: 数量 | AV13: 面值 | AW13: 利息调整 | AX13: 应计利息 | AY13: 数量 | AZ13: 面值 | BA13: 利息调整 | BB13: 应计利息 | BC13: 数量 | BD13: 面值 | BE13: 利息调整 | BF13: 应计利息 | BG13: 单位面值(净值) | BH13: 数量 | BI13: 面值 | BJ13: 利息调整 | BK13: 应计利息 | BL13: 合计 | BM13: 减：一年内到期的应付债券 | BN13: 最终审定数 | BO13: 单位面值(净值) | BP13: 数量 | BQ13: 面值 | BR13: 利息调整 | BS13: 应计利息 | BT13: 合计 | BU13: 单位面值(净值) | BV13: 数量 | BW13: 面值 | BX13: 利息调整 | BY13: 应计利息 | BZ13: 合计 | CA13: 单位面值(净值) | CB13: 数量 | CC13: 面值 | CD13: 利息调整 | CE13: 应计利息 | CF13: 合计 | CG13: 减：一年内到期的应付债券 | CH13: 最终审定数
A14: （一）普通应付债券
K15: =IF(L15=0,0,P15/L15) -> 0 | P15: =SUM(M15:O15) -> 0 | Q15: =IF(R15=0,0,V15/R15) -> 0 | V15: =SUM(S15:U15) -> 0 | W15: =IF(X15=0,0,AB15/X15) -> 0 | AB15: =SUM(Y15:AA15) -> 0 | AC15: =IF(AD15=0,0,AH15/AD15) -> 0 | AD15: =L15+R15-X15 -> 0 | AE15: =M15+S15-Y15 -> 0 | AF15: =N15+T15-Z15 -> 0 | AG15: =O15+U15-AA15 -> 0 | AH15: =SUM(AE15:AG15) -> 0 | BG15: =IF(BH15=0,0,BL15/BH15) -> 0 | BH15: =L15+AM15+AI15 -> 0 | BI15: =M15+AN15+AJ15 -> 0 | BJ15: =N15+AO15+AK15 -> 0 | BK15: =O15+AP15+AL15 -> 0 | BL15: =SUM(BI15:BK15) -> 0 | BN15: =BL15-BM15 -> 0 | BO15: =IF(BP15=0,0,BT15/BP15) -> 0 | BP15: =R15+AQ15+AU15 -> 0 | BQ15: =S15+AR15+AV15 -> 0 | BR15: =T15+AS15+AW15 -> 0 | BS15: =U15+AT15+AX15 -> 0 | BT15: =SUM(BQ15:BS15) -> 0 | BU15: =IF(BV15=0,0,BZ15/BV15) -> 0 | BV15: =X15+AY15+BC15 -> 0 | BW15: =Y15+AZ15+BD15 -> 0 | BX15: =Z15+BA15+BE15 -> 0 | BY15: =AA15+BB15+BF15 -> 0 | BZ15: =SUM(BW15:BY15) -> 0 | CA15: =IF(CB15=0,0,CF15/CB15) -> 0 | CB15: =BH15+BP15-BV15 -> 0 | CC15: =BI15+BQ15-BW15 -> 0 | CD15: =BJ15+BR15-BX15 -> 0 | CE15: =BK15+BS15-BY15 -> 0 | CF15: =SUM(CC15:CE15) -> 0 | CH15: =CF15-CG15 -> 0
K16: =IF(L16=0,0,P16/L16) -> 0 | P16: =SUM(M16:O16) -> 0 | Q16: =IF(R16=0,0,V16/R16) -> 0 | V16: =SUM(S16:U16) -> 0 | W16: =IF(X16=0,0,AB16/X16) -> 0 | AB16: =SUM(Y16:AA16) -> 0 | AC16: =IF(AD16=0,0,AH16/AD16) -> 0 | AD16: =L16+R16-X16 -> 0 | AE16: =M16+S16-Y16 -> 0 | AF16: =N16+T16-Z16 -> 0 | AG16: =O16+U16-AA16 -> 0 | AH16: =SUM(AE16:AG16) -> 0 | BG16: =IF(BH16=0,0,BL16/BH16) -> 0 | BH16: =L16+AM16+AI16 -> 0 | BI16: =M16+AN16+AJ16 -> 0 | BJ16: =N16+AO16+AK16 -> 0 | BK16: =O16+AP16+AL16 -> 0 | BL16: =SUM(BI16:BK16) -> 0 | BN16: =BL16-BM16 -> 0 | BO16: =IF(BP16=0,0,BT16/BP16) -> 0 | BP16: =R16+AQ16+AU16 -> 0 | BQ16: =S16+AR16+AV16 -> 0 | BR16: =T16+AS16+AW16 -> 0 | BS16: =U16+AT16+AX16 -> 0 | BT16: =SUM(BQ16:BS16) -> 0 | BU16: =IF(BV16=0,0,BZ16/BV16) -> 0 | BV16: =X16+AY16+BC16 -> 0 | BW16: =Y16+AZ16+BD16 -> 0 | BX16: =Z16+BA16+BE16 -> 0 | BY16: =AA16+BB16+BF16 -> 0 | BZ16: =SUM(BW16:BY16) -> 0 | CA16: =IF(CB16=0,0,CF16/CB16) -> 0 | CB16: =BH16+BP16-BV16 -> 0 | CC16: =BI16+BQ16-BW16 -> 0 | CD16: =BJ16+BR16-BX16 -> 0 | CE16: =BK16+BS16-BY16 -> 0 | CF16: =SUM(CC16:CE16) -> 0 | CH16: =CF16-CG16 -> 0
A17: 小计 | K17: -- | L17: =SUM(L15:L16) -> 0 | M17: =SUM(M15:M16) -> 0 | N17: =SUM(N15:N16) -> 0 | O17: =SUM(O15:O16) -> 0 | P17: =SUM(P15:P16) -> 0 | Q17: -- | R17: =SUM(R15:R16) -> 0 | S17: =SUM(S15:S16) -> 0 | T17: =SUM(T15:T16) -> 0 | U17: =SUM(U15:U16) -> 0 | V17: =SUM(S17:U17) -> 0 | W17: -- | X17: =SUM(X15:X16) -> 0 | Y17: =SUM(Y15:Y16) -> 0 | Z17: =SUM(Z15:Z16) -> 0 | AA17: =SUM(AA15:AA16) -> 0 | AB17: =SUM(Y17:AA17) -> 0 | AC17: -- | AD17: =SUM(AD15:AD16) -> 0 | AE17: =SUM(AE15:AE16) -> 0 | AF17: =SUM(AF15:AF16) -> 0 | AG17: =SUM(AG15:AG16) -> 0 | AH17: =SUM(AE17:AG17) -> 0 | AI17: =SUM(AI15:AI16) -> 0 | AJ17: =SUM(AJ15:AJ16) -> 0 | AK17: =SUM(AK15:AK16) -> 0 | AL17: =SUM(AL15:AL16) -> 0 | AM17: =SUM(AM15:AM16) -> 0 | AN17: =SUM(AN15:AN16) -> 0 | AO17: =SUM(AO15:AO16) -> 0 | AP17: =SUM(AP15:AP16) -> 0 | ... BF17: =SUM(BF15:BF16) -> 0 | BG17: -- | BH17: =SUM(BH15:BH16) -> 0 | BI17: =SUM(BI15:BI16) -> 0 | BJ17: =SUM(BJ15:BJ16) -> 0 | BK17: =SUM(BK15:BK16) -> 0 | BL17: =SUM(BL15:BL16) -> 0 | BM17: =SUM(BM15:BM16) -> 0 | BN17: =SUM(BN15:BN16) -> 0 | BO17: -- | BP17: =SUM(BP15:BP16) -> 0 | BQ17: =SUM(BQ15:BQ16) -> 0 | BR17: =SUM(BR15:BR16) -> 0 | BS17: =SUM(BS15:BS16) -> 0 | BT17: =SUM(BT15:BT16) -> 0 | BU17: -- | BV17: =SUM(BV15:BV16) -> 0 | BW17: =SUM(BW15:BW16) -> 0 | BX17: =SUM(BX15:BX16) -> 0 | BY17: =SUM(BY15:BY16) -> 0 | BZ17: =SUM(BZ15:BZ16) -> 0 | CA17: =SUM(CA15:CA16) -> 0 | CB17: =SUM(CB15:CB16) -> 0 | CC17: =SUM(CC15:CC16) -> 0 | ... CH17: =SUM(CH15:CH16) -> 0
A18: （二）可转换/可交换公司债券
K19: =IF(L19=0,0,P19/L19) -> 0 | P19: =SUM(M19:O19) -> 0 | Q19: =IF(R19=0,0,V19/R19) -> 0 | V19: =SUM(S19:U19) -> 0 | W19: =IF(X19=0,0,AB19/X19) -> 0 | AB19: =SUM(Y19:AA19) -> 0 | AC19: =IF(AD19=0,0,AH19/AD19) -> 0 | AD19: =L19+R19-X19 -> 0 | AE19: =M19+S19-Y19 -> 0 | AF19: =N19+T19-Z19 -> 0 | AG19: =O19+U19-AA19 -> 0 | AH19: =SUM(AE19:AG19) -> 0 | BG19: =IF(BH19=0,0,BL19/BH19) -> 0 | BH19: =L19+AM19+AI19 -> 0 | BI19: =M19+AN19+AJ19 -> 0 | BJ19: =N19+AO19+AK19 -> 0 | BK19: =O19+AP19+AL19 -> 0 | BL19: =SUM(BI19:BK19) -> 0 | BN19: =BL19-BM19 -> 0 | BO19: =IF(BP19=0,0,BT19/BP19) -> 0 | BP19: =R19+AQ19+AU19 -> 0 | BQ19: =S19+AR19+AV19 -> 0 | BR19: =T19+AS19+AW19 -> 0 | BS19: =U19+AT19+AX19 -> 0 | BT19: =SUM(BQ19:BS19) -> 0 | BU19: =IF(BV19=0,0,BZ19/BV19) -> 0 | BV19: =X19+AY19+BC19 -> 0 | BW19: =Y19+AZ19+BD19 -> 0 | BX19: =Z19+BA19+BE19 -> 0 | BY19: =AA19+BB19+BF19 -> 0 | BZ19: =SUM(BW19:BY19) -> 0 | CA19: =IF(CB19=0,0,CF19/CB19) -> 0 | CB19: =BH19+BP19-BV19 -> 0 | CC19: =BI19+BQ19-BW19 -> 0 | CD19: =BJ19+BR19-BX19 -> 0 | CE19: =BK19+BS19-BY19 -> 0 | CF19: =SUM(CC19:CE19) -> 0 | CH19: =CF19-CG19 -> 0
K20: =IF(L20=0,0,P20/L20) -> 0 | P20: =SUM(M20:O20) -> 0 | Q20: =IF(R20=0,0,V20/R20) -> 0 | V20: =SUM(S20:U20) -> 0 | W20: =IF(X20=0,0,AB20/X20) -> 0 | AB20: =SUM(Y20:AA20) -> 0 | AC20: =IF(AD20=0,0,AH20/AD20) -> 0 | AD20: =L20+R20-X20 -> 0 | AE20: =M20+S20-Y20 -> 0 | AF20: =N20+T20-Z20 -> 0 | AG20: =O20+U20-AA20 -> 0 | AH20: =SUM(AE20:AG20) -> 0 | BG20: =IF(BH20=0,0,BL20/BH20) -> 0 | BH20: =L20+AM20+AI20 -> 0 | BI20: =M20+AN20+AJ20 -> 0 | BJ20: =N20+AO20+AK20 -> 0 | BK20: =O20+AP20+AL20 -> 0 | BL20: =SUM(BI20:BK20) -> 0 | BN20: =BL20-BM20 -> 0 | BO20: =IF(BP20=0,0,BT20/BP20) -> 0 | BP20: =R20+AQ20+AU20 -> 0 | BQ20: =S20+AR20+AV20 -> 0 | BR20: =T20+AS20+AW20 -> 0 | BS20: =U20+AT20+AX20 -> 0 | BT20: =SUM(BQ20:BS20) -> 0 | BU20: =IF(BV20=0,0,BZ20/BV20) -> 0 | BV20: =X20+AY20+BC20 -> 0 | BW20: =Y20+AZ20+BD20 -> 0 | BX20: =Z20+BA20+BE20 -> 0 | BY20: =AA20+BB20+BF20 -> 0 | BZ20: =SUM(BW20:BY20) -> 0 | CA20: =IF(CB20=0,0,CF20/CB20) -> 0 | CB20: =BH20+BP20-BV20 -> 0 | CC20: =BI20+BQ20-BW20 -> 0 | CD20: =BJ20+BR20-BX20 -> 0 | CE20: =BK20+BS20-BY20 -> 0 | CF20: =SUM(CC20:CE20) -> 0 | CH20: =CF20-CG20 -> 0
A21: 小计 | K21: -- | L21: =SUM(L19:L20) -> 0 | M21: =SUM(M19:M20) -> 0 | N21: =SUM(N19:N20) -> 0 | O21: =SUM(O19:O20) -> 0 | P21: =SUM(P19:P20) -> 0 | Q21: -- | R21: =SUM(R19:R20) -> 0 | S21: =SUM(S19:S20) -> 0 | T21: =SUM(T19:T20) -> 0 | U21: =SUM(U19:U20) -> 0 | V21: =SUM(S21:U21) -> 0 | W21: -- | X21: =SUM(X19:X20) -> 0 | Y21: =SUM(Y19:Y20) -> 0 | Z21: =SUM(Z19:Z20) -> 0 | AA21: =SUM(AA19:AA20) -> 0 | AB21: =SUM(Y21:AA21) -> 0 | AC21: -- | AD21: =SUM(AD19:AD20) -> 0 | AE21: =SUM(AE19:AE20) -> 0 | AF21: =SUM(AF19:AF20) -> 0 | AG21: =SUM(AG19:AG20) -> 0 | AH21: =SUM(AE21:AG21) -> 0 | AI21: =SUM(AI19:AI20) -> 0 | AJ21: =SUM(AJ19:AJ20) -> 0 | AK21: =SUM(AK19:AK20) -> 0 | AL21: =SUM(AL19:AL20) -> 0 | AM21: =SUM(AM19:AM20) -> 0 | AN21: =SUM(AN19:AN20) -> 0 | AO21: =SUM(AO19:AO20) -> 0 | AP21: =SUM(AP19:AP20) -> 0 | ... BF21: =SUM(BF19:BF20) -> 0 | BG21: -- | BH21: =SUM(BH19:BH20) -> 0 | BI21: =SUM(BI19:BI20) -> 0 | BJ21: =SUM(BJ19:BJ20) -> 0 | BK21: =SUM(BK19:BK20) -> 0 | BL21: =SUM(BL19:BL20) -> 0 | BM21: =SUM(BM19:BM20) -> 0 | BN21: =SUM(BN19:BN20) -> 0 | BO21: -- | BP21: =SUM(BP19:BP20) -> 0 | BQ21: =SUM(BQ19:BQ20) -> 0 | BR21: =SUM(BR19:BR20) -> 0 | BS21: =SUM(BS19:BS20) -> 0 | BT21: =SUM(BT19:BT20) -> 0 | BU21: -- | BV21: =SUM(BV19:BV20) -> 0 | BW21: =SUM(BW19:BW20) -> 0 | BX21: =SUM(BX19:BX20) -> 0 | BY21: =SUM(BY19:BY20) -> 0 | BZ21: =SUM(BZ19:BZ20) -> 0 | CA21: =SUM(CA19:CA20) -> 0 | CB21: =SUM(CB19:CB20) -> 0 | CC21: =SUM(CC19:CC20) -> 0 | ... CH21: =SUM(CH19:CH20) -> 0
A22: 合计 | K22: -- | L22: =L17+L21 -> 0 | M22: =M17+M21 -> 0 | N22: =N17+N21 -> 0 | O22: =O17+O21 -> 0 | P22: =P17+P21 -> 0 | Q22: -- | R22: =R17+R21 -> 0 | S22: =S17+S21 -> 0 | T22: =T17+T21 -> 0 | U22: =U17+U21 -> 0 | V22: =V17+V21 -> 0 | W22: -- | X22: =X17+X21 -> 0 | Y22: =Y17+Y21 -> 0 | Z22: =Z17+Z21 -> 0 | AA22: =AA17+AA21 -> 0 | AB22: =AB17+AB21 -> 0 | AC22: -- | AD22: =AD17+AD21 -> 0 | AE22: =AE17+AE21 -> 0 | AF22: =AF17+AF21 -> 0 | AG22: =AG17+AG21 -> 0 | AH22: =AH17+AH21 -> 0 | AI22: =AI17+AI21 -> 0 | AJ22: =AJ17+AJ21 -> 0 | AK22: =AK17+AK21 -> 0 | ... BF22: =BF17+BF21 -> 0 | BG22: -- | BH22: =BH17+BH21 -> 0 | BI22: =BI17+BI21 -> 0 | BJ22: =BJ17+BJ21 -> 0 | BK22: =BK17+BK21 -> 0 | BL22: =BL17+BL21 -> 0 | BM22: =BM17+BM21 -> 0 | BN22: =BN17+BN21 -> 0 | BO22: -- | BP22: =BP17+BP21 -> 0 | BQ22: =BQ17+BQ21 -> 0 | BR22: =BR17+BR21 -> 0 | BS22: =BS17+BS21 -> 0 | BT22: =BT17+BT21 -> 0 | BU22: -- | BV22: =BV17+BV21 -> 0 | BW22: =BW17+BW21 -> 0 | BX22: =BX17+BX21 -> 0 | BY22: =BY17+BY21 -> 0 | BZ22: =BZ17+BZ21 -> 0 | CA22: =CA17+CA21 -> 0 | CB22: =CB17+CB21 -> 0 | CC22: =CC17+CC21 -> 0 | ... CH22: =CH17+CH21 -> 0
C23: 三、审计说明：
C27: 四、审计结论：
A30: 提示：
A31: 1、本科目核算企业为筹集（长期）资金而发行债券的本金和利息。企业发行的可转换公司债券，应将负债和权益成份进行分拆。分拆后形成的负债成份在本科目核算。
A32: 2、含一年内到期的应付债券。
A33: 3、如新发行债券，应在“备注”栏中说明证券主管部门批准文号，发行日期、付息日期等内容。
A34: 4.审计说明可以概述：（1）程序的测试情况、结果；（2）拟调整事项及其调整分录、未调整事项及其影响，审计范围受到限制情况及其影响。
A35: 5.审计结论可参考：A、未见异常。 B、除上述重大不符事项应当作为调整事项予以调整外，其余未见异常。 C、由于存在以下重大未调整事项（或审计范围受到限制无法获取充分、适当证据），不可确认。

Sheet 划分为金融负债的其他金融工具明细表L4-3
A1: 致同会计师事务所 | T1: 致同会计师事务所
A2: 应付债券明细表-划分为金融负债的其他金融工具（未审数） | T2: 应付债券明细表（审计调整+审定数） | AN2: 返回目录
A3: =底稿目录!A2 -> 被审计单位： | H3: =底稿目录!A4 -> 编制人： | L3: =底稿目录!A5 -> 编制日期： | R3: 索引号： | S3: =底稿目录!F8 -> L4-3 | Z3: =底稿目录!A4 -> 编制人： | AF3: =底稿目录!A5 -> 编制日期： | AL3: 索引号： | AM3: L4-3
A4: =底稿目录!A3 -> 截止日：202X年12月31日 | H4: =底稿目录!A6 -> 复核人： | L4: =底稿目录!A7 -> 复核日期： | R4: 页次： | Z4: 复核人： | AF4: =底稿目录!A7 -> 复核日期： | AL4: 页次：
C5: 一、审计目标:
C6: 1.资产负债表中记录的应付债券是存在的，且已经记录在恰当的账户中；
C7: 2. 所有应记录的短期借款均已记录，所有应当包括在财务报表中的相关披露均已包括；
C8: 3.应付债券以恰当的金额包括在财务报表中，与之相关的计价或分摊调整已恰当记录，相关披露已得到恰当计量和描述
C9: 二、审计过程：
A10: 发行在外的金融工具 | C10: 发行时间 | D10: 会计分类 | E10: 股利率或利息率 | F10: 发行价格 | G10: 数量 | H10: 金额 | I10: 到期日或续期情况 | J10: 转股条件 | K10: 转换情况 | L10: 未审数 | T10: 期初调整 | X10: 账项调整 | AB10: 重分类调整 | AF10: 审定数
L11: 期初余额 | N11: 本期增加 | P11: 本期减少 | R11: 期末余额 | T11: 账项调整 | V11: 重分类调整 | X11: 本期增加 | Z11: 本期减少 | AB11: 本期增加 | AD11: 本期减少 | AF11: 期初余额 | AH11: 本期增加 | AJ11: 本期减少 | AL11: 期末余额
L12: 数量 | M12: 金额 | N12: 数量 | O12: 金额 | P12: 数量 | Q12: 金额 | R12: 数量 | S12: 金额 | T12: 数量 | U12: 金额 | V12: 数量 | W12: 金额 | X12: 数量 | Y12: 金额 | Z12: 数量 | AA12: 金额 | AB12: 数量 | AC12: 金额 | AD12: 数量 | AE12: 金额 | AF12: 数量 | AG12: 金额 | AH12: 数量 | AI12: 金额 | AJ12: 数量 | AK12: 金额 | AL12: 数量 | AM12: 金额
R13: =L13+N13-P13 -> 0 | S13: =M13+O13-Q13 -> 0 | AF13: =L13+T13+V13 -> 0 | AG13: =M13+U13+W13 -> 0 | AH13: =N13+X13+AB13 -> 0 | AI13: =O13+Y13+AC13 -> 0 | AJ13: =P13+Z13+AD13 -> 0 | AK13: =Q13+AA13+AE13 -> 0 | AL13: =AF13+AH13-AJ13 -> 0 | AM13: =AG13+AI13-AK13 -> 0
R14: =L14+N14-P14 -> 0 | S14: =M14+O14-Q14 -> 0 | AF14: =L14+T14+V14 -> 0 | AG14: =M14+U14+W14 -> 0 | AH14: =N14+X14+AB14 -> 0 | AI14: =O14+Y14+AC14 -> 0 | AJ14: =P14+Z14+AD14 -> 0 | AK14: =Q14+AA14+AE14 -> 0 | AL14: =AF14+AH14-AJ14 -> 0 | AM14: =AG14+AI14-AK14 -> 0
R15: =L15+N15-P15 -> 0 | S15: =M15+O15-Q15 -> 0 | AF15: =L15+T15+V15 -> 0 | AG15: =M15+U15+W15 -> 0 | AH15: =N15+X15+AB15 -> 0 | AI15: =O15+Y15+AC15 -> 0 | AJ15: =P15+Z15+AD15 -> 0 | AK15: =Q15+AA15+AE15 -> 0 | AL15: =AF15+AH15-AJ15 -> 0 | AM15: =AG15+AI15-AK15 -> 0
R16: =L16+N16-P16 -> 0 | S16: =M16+O16-Q16 -> 0 | AF16: =L16+T16+V16 -> 0 | AG16: =M16+U16+W16 -> 0 | AH16: =N16+X16+AB16 -> 0 | AI16: =O16+Y16+AC16 -> 0 | AJ16: =P16+Z16+AD16 -> 0 | AK16: =Q16+AA16+AE16 -> 0 | AL16: =AF16+AH16-AJ16 -> 0 | AM16: =AG16+AI16-AK16 -> 0
R17: =L17+N17-P17 -> 0 | S17: =M17+O17-Q17 -> 0 | AF17: =L17+T17+V17 -> 0 | AG17: =M17+U17+W17 -> 0 | AH17: =N17+X17+AB17 -> 0 | AI17: =O17+Y17+AC17 -> 0 | AJ17: =P17+Z17+AD17 -> 0 | AK17: =Q17+AA17+AE17 -> 0 | AL17: =AF17+AH17-AJ17 -> 0 | AM17: =AG17+AI17-AK17 -> 0
A18: 合计 | L18: =SUM(L13:L17) -> 0 | M18: =SUM(M13:M17) -> 0 | N18: =SUM(N13:N17) -> 0 | O18: =SUM(O13:O17) -> 0 | P18: =SUM(P13:P17) -> 0 | Q18: =SUM(Q13:Q17) -> 0 | R18: =L18+N18-P18 -> 0 | S18: =M18+O18-Q18 -> 0 | T18: =SUM(T13:T17) -> 0 | U18: =SUM(U13:U17) -> 0 | V18: =SUM(V13:V17) -> 0 | W18: =SUM(W13:W17) -> 0 | X18: =SUM(X13:X17) -> 0 | Y18: =SUM(Y13:Y17) -> 0 | Z18: =SUM(Z13:Z17) -> 0 | AA18: =SUM(AA13:AA17) -> 0 | ... AK18: =SUM(AK13:AK17) -> 0 | AL18: =AF18+AH18-AJ18 -> 0 | AM18: =AG18+AI18-AK18 -> 0
C19: 三、审计说明：
C22: 四、审计结论：
A24: 提示：
A25: 1、本科目核算企业为筹集（长期）资金而发行债券的本金和利息。企业发行的可转换公司债券，应将负债和权益成份进行分拆，分拆后形成的负债成份在本科目核算。
A26: 2.审计说明可以概述：（1）程序的测试情况、结果；（2）拟调整事项及其调整分录、未调整事项及其影响，审计范围受到限制情况及其影响。
A27: 3.审计结论可参考：A、未见异常。 B、除上述重大不符事项应当作为调整事项予以调整外，其余未见异常。 C、由于存在以下重大未调整事项（或审计范围受到限制无法获取充分、适当证据），不可确认。

Sheet 调整分录汇总L4-4
A1: 致同会计师事务所
A2: 应付债券调整分录汇总表
A3: =底稿目录!A2 -> 被审计单位： | C3: =底稿目录!A4 -> 编制人： | G3: =底稿目录!A5 -> 编制日期： | I3: 索引： | J3: =底稿目录!F9 -> L4-4
A4: =底稿目录!A3 -> 截止日：202X年12月31日 | C4: =底稿目录!A6 -> 复核人： | G4: =底稿目录!A7 -> 复核日期： | I4: 页次：
A5: 调整事项说明 | B5: 类别（报表调整/账项调整/其他） | C5: 报表项目 | D5: 科目名称 | E5: 附注项目 | F5: …… | G5: 借方调整金额 | H5: 贷方调整金额 | I5: 索引 | J5: 备注
A23: 注：本底稿适用于调整分录较多、较复杂的项目，且仅列示与本报表项目相关的审计调整。项目组可根据项目实际情况选择是否使用该底稿。

Sheet 权益与负债划分检查表L4-5
A1: 致同会计师事务所
A2: 权益与负债划分检查表
A3: =底稿目录!A2 -> 被审计单位： | F3: =底稿目录!A4 -> 编制人： | I3: =底稿目录!A5 -> 编制日期： | M3: 索引号： | N3: =底稿目录!F10 -> L4-5
A4: =底稿目录!A3 -> 截止日：202X年12月31日 | F4: =底稿目录!A6 -> 复核人： | I4: =底稿目录!A7 -> 复核日期： | M4: 页次：
A5: 一、审计目标
A6: 1.资产负债表中记录的应付债券是存在的，且已经记录在恰当的账户中；2.应付债券以恰当的金额包括在财务报表中，与之相关的计价或分摊调整已恰当记录，相关披露已得到恰当计量和描述
A7: 二、审计过程
A8: 发行在外的金融工具 | B8: 发行时间 | C8: 期末账面价值 | D8: 发行方的合同义务 | J8: 其他相关因素 | K8: 关于会计分类的结论 | L8: 是否存在差异 | M8: 备注 | N8: 发行文件索引号
D9: 关于本金的赎回约定 | E9: 或有支付义务、或有结算条款、结算选择权 | F9: 转股条件 | G9: 股息支付条款（强制付息条件） | H9: 赎回选择权 | I9: 剩余利润分配的条款
A20: 合计 | C20: =SUM(C10:C19) -> 0
A22: 三、审计说明：
A25: 四、审计结论
A28: 提示：
A29: 1
A30: 项目 | B30: 优先股条款 | C30: 倾向性分类
A31: 本金的赎回 | B31: 本金无需赎回，或发行方可自主决定是否赎回 | C31: 可能表明具有权益特征，但须分析股息的支付机制。若必须支付股息，则负债部分等于支付的永续股利的现值；若自主决定是否支付股息，则属于权益。
C32: 若发行方可自行选择在某一未来日期赎回，则发行方以现金赎回股票的看涨期权是一项嵌入衍生工具（资产）。
B33: 需在某固定或未来日期按照固定或可确定的金额强制赎回 | C33: 负债，还需分析股息的支付机制。若必须支付股息，则整体为负债；若自主决定是否支付股息，则负债部分等于赎回金额的现值，权益部分等于发行收入减去负债部分。
A34: 股息支付 | B34: 发行方可自主决定是否支付或无限期地递延股息而无任何支付义务（即使股息可累积） | C34: 可能表明具有权益特征，还需分析本金的赎回机制。若本金无需赎回或发行方可自主决定是否赎回，则属于权益；若本金需强制赎回，则负债部分等于赎回金额的现值，权益部分等于发行收入减去负债部分。
B35: 强制付息——固定股息，发行方不能递延支付 | C35: 负债。若本金无需赎回或发行方可自主决定是否赎回，则负债部分等于支付的永续股利的现值；若本金需强制赎回，则整体为负债。
B36: 强制付息——浮动股息 | C36: 负债。若本金无需赎回或发行方可自主决定是否赎回，则负债部分等于支付的永续股利的现值；若本金需强制赎回，则整体为负债。
C37: 应分析浮动机制是否构成一项嵌入衍生工具并评估其是否与主合同紧密相关。
B38: 股息支付与另一项强制付息的金融工具相关联 | C38: 若优先股的股息支付与另一项强制付息的金融工具相关联，即支付另一关联工具的利息时，就必须支付该优先股股息，则仍然形成了支付该优先股股息的合同义务。
A39: 赎回选择权 | B39: 需在某固定或未来日期按照固定或可确定的金额强制赎回 | C39: 若必须支付股息，则整体为负债；若自主决定是否支付股息，则负债部分等于赎回金额的现值，权益部分等于发行收入减去负债部分，但若赎回时需支付的金额还包括未支付的股利，则整体上为负债。
B40: 仅发行方有权选择赎回 | C40: 可能不影响其分类。
C41: 若必须支付股息，则负债部分等于支付的永续股利的现值, 且发行方以现金赎回股票的看涨期权是一项嵌入衍生工具（资产）；若自主决定是否支付股息，则属于权益。
B42: 投资方有权选择赎回 | C42: 负债，还需分析股息的支付机制。若必须支付股息，则整体上为负债，且以现金赎回股票的嵌入看跌期权是一项嵌入衍生工具；若自主决定是否支付股息，则负债部分等于赎回金额的现值，权益部分等于发行收入减去负债部分，但若赎回时需支付的金额还包括未支付的股利，则整体上为负债。
A43: 剩余利润分配 | B43: 无权同普通股股东一起参加剩余利润分配 | C43: 通常不影响根据其他条款划分的类别
B44: 有权同普通股股东一起参加剩余利润分配 | C44: 通常表明存在权益成分（享有剩余收益），若其他条款表明该优先股需要拆分为负债、权益，则此条款可能影响其负债和权益成分的拆分比例
A45: 转股权条款 | B45: 固定金额转换固定数量的股份 | C45: 该转股权具有权益特征，通常需要拆分（满足“固定换固定”的要求）
B46: 固定金额转换可变数量的股份 | C46: 该转股权具有负债特征，需要判断是否需要拆分（不满足“固定换固定”的要求）
A48: 2.优先股划分为权益工具需满足的条件（须同时满足）： （1）不构成支付义务，即发行方能够无条件避免支付。为满足这一条件，发行方需（不限于）：无需或自主决定分红付息、不存在或有支付义务、不存在或有结算条款、不存在结算选择权。 （2）转股条件（如有）符合“固定换固定”的标准。 （3）仅发行方持有回购权（如有）。
A53: 3.将一项优先股划分为权益还是金融负债，还需要考虑的其他因素： （1）以前期间股利发放情况，例如历史上每年均支付自主决定的股利； （2）未来发放股利的意向，例如持有方合理预期发行方将发放股利； （3）没有发放优先股股利对发行方普通股的价格可能产生的负面影响，比如因为未向优先股支付股利限制了向普通股支付股利，从而导致普通股价值下跌； （4）发行方发放股利的或赎回的能力，如亏损或留存收益的金额不足； （5）发行方对某一期间损益的预期； （6）发行方影响当期损益的能力。
A61: 4.会计提示第78号—优先股永续债可转换公司债券 | D61: https://www.gt-china.com.cn/article_view.php?id=5951

Sheet 应付债券初始计量L4-6
A1: 致同会计师事务所
A2: 应付债券初始计量
A3: =底稿目录!A2 -> 被审计单位： | C3: =底稿目录!A4 -> 编制人： | E3: =底稿目录!A5 -> 编制日期： | F3: 索引号： | G3: =底稿目录!F11 -> L4-6
A4: =底稿目录!A3 -> 截止日：202X年12月31日 | C4: =底稿目录!A6 -> 复核人： | E4: =底稿目录!A7 -> 复核日期： | F4: 页次：
A5: 一、审计目标:
A6: 1. 所有应记录的应付债券均已记录，所有应当包括在财务报表中的相关披露均已包括；
A7: 2.应付债券以恰当的金额包括在财务报表中，与之相关的计价或分摊调整已恰当记录，相关披露已得到恰当计量和描述
A8: 二、审计过程：
A9: 计息期初： | C9: 计息期末：
A10: 利息费用测算：
A11: 项目 | B11: 应付债券1 | C11: 应付债券2 | D11: 应付债券3 | E11: 应付债券4 | F11: 合计 | G11: 备注
A12: 后续计量方式 | F12: ——
A13: 债券种类
A14: 债券名称 | F14: ——
A15: 债权期限 | F15: ——
A16: 计息基数-面值/本金 | F16: =SUM(B16:E16) -> 0
A17: 合同利率 | F17: ——
A18: 发行价格 | F18: =SUM(B18:E18) -> 0
A19: 发行费用 | F19: =SUM(B19:E19) -> 0
A20: 利息调整初始确认金额 | B20: =B18-B16-B19 -> 0 | C20: =C18-C16-C19 -> 0 | D20: =D18-D16-D19 -> 0 | E20: =E18-E16-E19 -> 0 | F20: =SUM(B20:E20) -> 0
A21: 起息日 | F21: ——
A22: 到期日 | F22: ——
A23: 本期计息天数 | B23: =IFERROR(IF(B21=0,0,IF(AND(B21<$B$9,B22>$D$9),VALUE(DATEDIF($B$9,$D$9,"d")+1),IF(AND(B21<$B$9,B22<=$D$9),VALUE(DATEDIF($B$9,B22,"d")+1),IF(AND(B21>=$B$9,B22>$D$9),VALUE(DATEDIF(B21,$D$9,"d")+1),IF(AND(B21>=$B$9,B22<=$D$9),VALUE(DATEDIF(B21,B22,"d")+1),))))),0) -> 0 | C23: =IF(C21=0,0,IF(AND(C21<$B$9,C22>$D$9),VALUE(DATEDIF($B$9,$D$9,"d")),IF(AND(C21<$B$9,C22<=$D$9),VALUE(DATEDIF($B$9,C22,"d")+1),IF(AND(C21>=$B$9,C22>$D$9),VALUE(DATEDIF(C21,$D$9,"d")),IF(AND(C21>=$B$9,C22<=$D$9),VALUE(DATEDIF(C21,C22,"d")+1),))))) -> 0 | D23: =IF(D21=0,0,IF(AND(D21<$B$9,D22>$D$9),VALUE(DATEDIF($B$9,$D$9,"d")),IF(AND(D21<$B$9,D22<=$D$9),VALUE(DATEDIF($B$9,D22,"d")+1),IF(AND(D21>=$B$9,D22>$D$9),VALUE(DATEDIF(D21,$D$9,"d")),IF(AND(D21>=$B$9,D22<=$D$9),VALUE(DATEDIF(D21,D22,"d")+1),))))) -> 0 | E23: =IF(I2=0,0,IF(AND(I2<$B$9,E22>$D$9),VALUE(DATEDIF($B$9,$D$9,"d")),IF(AND(I2<$B$9,E22<=$D$9),VALUE(DATEDIF($B$9,E22,"d")+1),IF(AND(I2>=$B$9,E22>$D$9),VALUE(DATEDIF(I2,$D$9,"d")),IF(AND(I2>=$B$9,E22<=$D$9),VALUE(DATEDIF(I2,E22,"d")+1),))))) -> 0 | F23: ——
A24: 实际利率 | B24: =B32 -> 0 | C24: =C32 -> 0 | D24: =D32 -> 0 | E24: =E32 -> 0 | F24: ——
A25: 按合同利率计算的应付利息 | B25: =B16*B17/365*B23 -> 0 | C25: =C16*C17/365*C23 -> 0 | D25: =D16*D17/365*D23 -> 0 | E25: =E16*E17/365*E23 -> 0 | F25: =SUM(B25:E25) -> 0 | G25: “应付利息”
A26: 期初应付本金余额 | B26: =B18-B19 -> 0 | C26: =C18-C19 -> 0 | D26: =D18-D19 -> 0 | E26: =E18-E19 -> 0 | F26: =SUM(B26:E26) -> 0
A27: 期末应付本金余额 | B27: =B26-B29 -> 0 | C27: =C26-C29 -> 0 | D27: =D26-D29 -> 0 | E27: =E26-E29 -> 0 | F27: =F26-F29 -> 0
A28: 确认的利息费用 | B28: =B26*B24/365*B23 -> 0 | F28: =SUM(B28:E28) -> 0 | G28: 利息费用
A29: 应付本金减少 | B29: =B25-B28 -> 0 | C29: =C25-C28 -> 0 | D29: =D25-D28 -> 0 | E29: =E25-E28 -> 0 | F29: =F25-F28 -> 0
A30: —利息调整 | B30: =B29 -> 0 | C30: =C29 -> 0 | D30: =D29 -> 0 | E30: =E29 -> 0 | F30: =F29 -> 0
A31: 实际利率测算：
A32: 实际利率（插值） | B32: =IF(B39=0,0,B33+(B36-B33)*(B39-B34)/(B37-B34)) -> 0 | C32: =IF(C39=0,0,C33+(C36-C33)*(C39-C34)/(C37-C34)) -> 0 | D32: =IF(D39=0,0,D33+(D36-D33)*(D39-D34)/(D37-D34)) -> 0 | E32: =IF(E39=0,0,E33+(E36-E33)*(E39-E34)/(E37-E34)) -> 0 | F32: ——
A33: 实际利率（测试1）-较小 | F33: ——
A34: 利息现值（测试1） | B34: =B40/(1+$B$33)^1+B41/(1+$B$33)^2+B42/(1+$B$33)^3+B43/(1+$B$33)^4+B44/(1+$B$33)^5+B16/(1+$B$33)^B45 -> 0 | C34: =C40/(1+$B$33)^1+C41/(1+$B$33)^2+C42/(1+$B$33)^3+C43/(1+$B$33)^4+C44/(1+$B$33)^5+C45/(1+$B$33)^6+C16/(1+$B$33)^C45 -> 0 | D34: =D40/(1+$B$33)^1+D41/(1+$B$33)^2+D42/(1+$B$33)^3+D43/(1+$B$33)^4+D44/(1+$B$33)^5+D45/(1+$B$33)^6+D16/(1+$B$33)^D45 -> 0 | E34: =E40/(1+$B$33)^1+E41/(1+$B$33)^2+E42/(1+$B$33)^3+E43/(1+$B$33)^4+E44/(1+$B$33)^5+E45/(1+$B$33)^6+E16/(1+$B$33)^E45 -> 0 | F34: =SUM(B34:E34) -> 0
A35: 现值差异（测试1） | B35: =IF((B34-B39)>=0,(B34-B39),"利率太大") -> 0 | C35: =IF((C34-C39)>=0,(C34-C39),"利率太大") -> 0 | D35: =IF((D34-D39)>=0,(D34-D39),"利率太大") -> 0 | E35: =IF((E34-E39)>=0,(E34-E39),"利率太大") -> 0 | F35: =SUM(B35:E35) -> 0
A36: 实际利率（测试2）-较大 | F36: ——
A37: 利息现值（测试2） | B37: =B40/(1+$B$36)^1+B41/(1+$B$36)^2+B42/(1+$B$36)^3+B43/(1+$B$36)^4+B44/(1+$B$36)^5+B16/(1+$B$36)^B45 -> 0 | C37: =C40/(1+$B$36)^1+C41/(1+$B$36)^2+C42/(1+$B$36)^3+C43/(1+$B$36)^4+C44/(1+$B$36)^5+C45/(1+$B$36)^6+C16/(1+$B$36)^C45 -> 0 | D37: =D40/(1+$B$36)^1+D41/(1+$B$36)^2+D42/(1+$B$36)^3+D43/(1+$B$36)^4+D44/(1+$B$36)^5+D45/(1+$B$36)^6+D16/(1+$B$36)^D45 -> 0 | E37: =E40/(1+$B$36)^1+E41/(1+$B$36)^2+E42/(1+$B$36)^3+E43/(1+$B$36)^4+E44/(1+$B$36)^5+E45/(1+$B$36)^6+E16/(1+$B$36)^E45 -> 0 | F37: =SUM(B37:E37) -> 0
A38: 现值差异（测试2） | B38: =IF((B39-B37)>=0,(B39-B37),"利率太小") -> 0 | C38: =IF((C39-C37)>=0,(C39-C37),"利率太小") -> 0 | D38: =IF((D39-D37)>=0,(D39-D37),"利率太小") -> 0 | E38: =IF((E39-E37)>=0,(E39-E37),"利率太小") -> 0 | F38: =SUM(B38:E38) -> 0
A39: 债务现值 | B39: =B18-B19 -> 0 | C39: =C18-C19 -> 0 | D39: =D18-D19 -> 0 | E39: =E18-E19 -> 0 | F39: =SUM(B39:E39) -> 0
A40: 按合同利率计算的应付利息(1) | F40: =SUM(B40:E40) -> 0
...

Sheet 应付债券后续计量(到期一次还本付息)L4-7
A1: 致同会计师事务所
A2: 应付债券后续计量(到期一次还本付息)
A3: =底稿目录!A2 -> 被审计单位： | D3: =底稿目录!A4 -> 编制人： | H3: =底稿目录!A5 -> 编制日期： | K3: 索引号： | L3: =底稿目录!F12 -> L4-7
A4: =底稿目录!A3 -> 截止日：202X年12月31日 | D4: =底稿目录!A6 -> 复核人： | H4: =底稿目录!A7 -> 复核日期： | K4: 页次：
A5: 一、审计目标:
A6: 1.资产负债表中记录的应付债券是存在的，且已经记录在恰当的账户中；
A7: 2.所有应记录的应付债券均已记录，所有应当包括在财务报表中的相关披露均已包括；
A8: 3.应付债券以恰当的金额包括在财务报表中，与之相关的计价或分摊调整已恰当记录，相关披露已得到恰当计量和描述
A9: 二、审计过程： | B9: 到期一次还本付息后续计量测算
A10: 1、债券信息
A11: 计息期初： | B11: ='应付债券初始计量L4-6'!B9 -> 0 | C11: 计息期末： | D11: ='应付债券初始计量L4-6'!D9 -> 0
A12: 序号： | B12: 债券种类： | C12: 债券名称： | D12: 债券期限： | E12: 实际利率： | F12: 面值 | G12: 票面利率 | H12: 发行价格 | I12: 发行费用 | J12: 利息调整初始确认金额 | K12: 起息日 | L12: 到期日
B13: ='应付债券初始计量L4-6'!B12 -> 0 | C13: ='应付债券初始计量L4-6'!B14 -> 0 | D13: ='应付债券初始计量L4-6'!B15 -> 0 | E13: ='应付债券初始计量L4-6'!B24 -> 0 | F13: ='应付债券初始计量L4-6'!B16 -> 0 | G13: ='应付债券初始计量L4-6'!B17 -> 0 | H13: ='应付债券初始计量L4-6'!B18 -> 0 | J13: =H13-F13-I13 -> 0 | K13: ='应付债券初始计量L4-6'!B21 -> 0 | L13: ='应付债券初始计量L4-6'!B22 -> 0
A15: 2、后续计量过程
A16: 期间 | B16: 截止日 | C16: 适用到期一次还本付息： | L16: 审计结论
C17: 期初账面价值 | D17: 利息费用 | E17: 应计利息 | F17: 期末“利息调整” | G17: “利息调整”摊销 | H17: 本期已付利息 | I17: 期末账面价值 | J17: 面值归还 | K17: 期末余额
A18: 第一期 | C18: =H13-I13 -> 0 | D18: =C18*$E$13 -> 0 | E18: =$F$13*$G$13 -> 0 | F18: =C18-$F$13 -> 0 | G18: =D18-E18 -> 0 | H18: —— | I18: =C18+D18 -> 0 | K18: =I18-J18 -> 0
A19: 第二期 | C19: =I18 -> 0 | D19: =C19*$E$13 -> 0 | E19: =$F$13*$G$13 -> 0 | F19: =C19-$F$13 -> 0 | G19: =D19-E19 -> 0 | H19: —— | I19: =C19+D19 -> 0 | K19: =I19-J19 -> 0
A20: 最后一期 | C20: =I19 -> 0 | D20: =I20-C20 -> 0 | E20: =$F$13*$G$13 -> 0 | F20: =C20-$F$13 -> 0 | G20: =D20-E20 -> 0 | H20: —— | I20: =F13+E18+E19+E20 -> 0 | K20: =I20-J20 -> 0
A21: 三、审计说明：
A22: 1.利息费用计入财务费用XX元、计入在建工程XX元，计入存货XX元，……
A25: 四、审计结论：

Sheet 应付债券后续计量(分期付息到期一次还本)L4-7
A1: 致同会计师事务所
A2: 应付债券后续计量(分期付息到期一次还本) | X2: 2、本期利息计提情况
A3: =底稿目录!A2 -> 被审计单位： | F3: =底稿目录!A4 -> 编制人： | H3: =底稿目录!A5 -> 编制日期： | K3: 索引号： | L3: =底稿目录!F13 -> L4-7 | X3: 债券名称 | Y3: 票面金额 | Z3: 票面年利率 | AA3: 开始日期 | AB3: 结束日期 | AC3: 计息天数 | AD3: 应计利息 | AE3: 已计利息 | AF3: 差异 | AG3: 差异原因 | AH3: 备注
A4: =底稿目录!A3 -> 截止日：202X年12月31日 | F4: =底稿目录!A6 -> 复核人： | H4: =底稿目录!A7 -> 复核日期： | K4: 页次： | AC4: =IF(DATEDIF(AA4,AB4,"d"),DATEDIF(AA4,AB4,"d")+1,0) -> 0 | AD4: =ROUND(Y4*Z4/365*AC4,2) -> 0 | AF4: =AD4-AE4 -> 0
A5: 一、审计目标: | AC5: =IF(DATEDIF(AA5,AB5,"d"),DATEDIF(AA5,AB5,"d")+1,0) -> 0 | AD5: =ROUND(Y5*Z5/360*AC5,2) -> 0 | AF5: =AD5-AE5 -> 0
A6: 1.资产负债表中记录的应付债券是存在的，且已经记录在恰当的账户中；
A7: 2.所有应记录的应付债券均已记录，所有应当包括在财务报表中的相关披露均已包括；
A8: 3.应付债券以恰当的金额包括在财务报表中，与之相关的计价或分摊调整已恰当记录，相关披露已得到恰当计量和描述
A9: 二、审计过程： | B9: 分期付息，到期一次还本 后续计量测算 | AC9: =IF(DATEDIF(AA9,AB9,"d"),DATEDIF(AA9,AB9,"d")+1,0) -> 0 | AD9: =ROUND(Y9*Z9/360*AC9,2) -> 0 | AF9: =AD9-AE9 -> 0
A10: 1、债券信息
A11: 计息期初： | B11: ='应付债券初始计量L4-6'!B9 -> 0 | C11: 计息期末： | D11: ='应付债券初始计量L4-6'!D9 -> 0
A12: 序号： | B12: 债券种类： | C12: 债券名称： | D12: 债券期限： | E12: 实际利率： | F12: 面值 | G12: 票面利率 | H12: 发行价格 | I12: 发行费用 | J12: 利息调整初始确认金额 | K12: 起息日 | L12: 到期日
B13: ='应付债券初始计量L4-6'!B12 -> 0 | C13: ='应付债券初始计量L4-6'!B14 -> 0 | D13: ='应付债券初始计量L4-6'!B15 -> 0 | E13: ='应付债券初始计量L4-6'!B24 -> 0 | F13: ='应付债券初始计量L4-6'!B16 -> 0 | G13: ='应付债券初始计量L4-6'!B17 -> 0 | H13: ='应付债券初始计量L4-6'!B18 -> 0 | J13: =H13-F13-I13 -> 0 | K13: ='应付债券初始计量L4-6'!B21 -> 0 | L13: ='应付债券初始计量L4-6'!B22 -> 0
A14: 2、后续计量过程
A15: 期间 | B15: 截止日 | C15: 适用分期付息，到期一次还本 | L15: 审计结论
C16: 期初账面价值 | D16: 利息费用 | E16: 应付利息 | F16: “利息调整”摊销 | G16: “利息调整”余额 | H16: 本期已付利息 | I16: 期末账面价值 | J16: 面值归还 | K16: 期末余额
A17: 初始计量 | G17: =C18-$F$13 -> 0
A18: 第一期 | C18: =H13-I13 -> 0 | D18: =ROUND(C18*$E$13,2) -> 0 | E18: =ROUND($F$13*$G$13,2) -> 0 | F18: =D18-E18 -> 0 | G18: =C19-$F$13 -> 0 | H18: =E18 -> 0 | I18: =C18+D18-H18 -> 0 | K18: =I18-J18 -> 0
A19: 第二期 | C19: =I18 -> 0 | D19: =ROUND(C19*$E$13,2) -> 0 | E19: =ROUND($F$13*$G$13,2) -> 0 | F19: =D19-E19 -> 0 | G19: =C20-$F$13 -> 0 | H19: =E19 -> 0 | I19: =C19+D19-H19 -> 0 | K19: =I19-J19 -> 0
A20: 最后一期 | C20: =I19 -> 0 | D20: =E20+F20 -> 0 | E20: =ROUND($F$13*$G$13,2) -> 0 | F20: =-G19 -> 0 | H20: =E20 -> 0 | I20: =$F$13 -> 0 | K20: =I20-J20 -> 0
A21: 三、审计说明：
A22: 1.利息费用计入财务费用XX元、计入在建工程XX元，计入存货XX元，……
A24: 四、审计结论：

Sheet 应付债券账面核对(到期一次还本付息)L4-8
A1: 致同会计师事务所
A2: 应付债券账面核对(到期一次还本付息)
A3: =底稿目录!A2 -> 被审计单位： | D3: =底稿目录!A4 -> 编制人： | H3: =底稿目录!A5 -> 编制日期： | K3: 索引号： | L3: =底稿目录!F14 -> L4-8
A4: =底稿目录!A3 -> 截止日：202X年12月31日 | D4: =底稿目录!A6 -> 复核人： | H4: =底稿目录!A7 -> 复核日期： | K4: 页次：
A5: 一、审计目标:
A6: 1.资产负债表中记录的应付债券是存在的，且已经记录在恰当的账户中；
A7: 2.所有应记录的应付债券均已记录，所有应当包括在财务报表中的相关披露均已包括；
A8: 3.应付债券以恰当的金额包括在财务报表中，与之相关的计价或分摊调整已恰当记录，相关披露已得到恰当计量和描述
A9: 二、审计过程：
A10: 1、期末余额测算
A11: 序号 | B11: 债券名称 | C11: 本期截止日 | D11: 期数 | E11: 期末账面价值
E12: 测算数 | F12: 应计利息 | G12: 测算期末数 | H12: 账面数 | I12: 差异 | J12: 是否调整
A13: 1 | C13: ='应付债券后续计量(到期一次还本付息)L4-7'!B18 -> 0 | D13: ='应付债券后续计量(到期一次还本付息)L4-7'!A18 -> 第一期 | E13: ='应付债券后续计量(到期一次还本付息)L4-7'!K18 -> 0 | F13: =I19 -> 0 | G13: =E13+I19 -> 0 | H13: ='应付债券明细表L4-2'!AH15 -> 0 | I13: =E13-H13 -> 0 | J13: 是
A14: 2
A15: 3
A16: 2、利息测算
A17: 序号 | B17: 债券名称 | C17: 利息调整 | G17: 应计利息
C18: 测算数 | D18: 账面数 | E18: 差异 | F18: 是否调整 | G18: 最近一次付息日 | H18: 计息天数 | I18: 应计利息 | J18: 账面数 | K18: 差异 | L18: 是否调整
A19: 1 | B19: =B13 -> 0 | C19: ='应付债券后续计量(到期一次还本付息)L4-7'!F18 -> 0 | D19: ='应付债券明细表L4-2'!AF15 -> 0 | E19: =C19-D19 -> 0 | G19: —— | H19: =IFERROR(IF(DATEDIF('应付债券后续计量(到期一次还本付息)L4-7'!K13,MIN('应付债券后续计量(到期一次还本付息)L4-7'!L13,'应付债券后续计量(到期一次还本付息)L4-7'!D11),"d"),DATEDIF('应付债券后续计量(到期一次还本付息)L4-7'!K13,MIN('应付债券后续计量(到期一次还本付息)L4-7'!L13,'应付债券后续计量(到期一次还本付息)L4-7'!D11),"d")+1,0),0) -> 0 | I19: =ROUND('应付债券后续计量(到期一次还本付息)L4-7'!$F$13*'应付债券后续计量(到期一次还本付息)L4-7'!$G$13/365*H19,2) -> 0 | J19: ='应付债券明细表L4-2'!AG15 -> 0 | K19: =F13-J19 -> 0 | L19: 是
A20: 2 | B20: =B14 -> 0
A21: 3 | B21: =B15 -> 0
A22: 3、“利息调整”摊销分配测算
A23: 序号 | B23: 债券名称 | C23: 债权期数 | D23: “利息调整”摊销 | E23: 利息分配数测算 | J23: 差异
E24: 财务费用 | F24: 存货 | G24: 长期资产 | H24: … | I24: 合计
C25: 第一期 | D25: ='应付债券后续计量(到期一次还本付息)L4-7'!G18 -> 0 | I25: =SUM(E25:H25) -> 0 | J25: =D25-I25 -> 0
C26: 第二期 | D26: ='应付债券后续计量(到期一次还本付息)L4-7'!G19 -> 0 | I26: =SUM(E26:H26) -> 0 | J26: =D26-I26 -> 0
C27: 最后一期 | D27: ='应付债券后续计量(到期一次还本付息)L4-7'!G20 -> 0 | I27: =SUM(E27:H27) -> 0 | J27: =D27-I27 -> 0
A29: 序号 | B29: 债券名称 | C29: 债权期数 | D29: “利息调整”摊销 | E29: 利息分配数测算 | J29: 差异
E30: 财务费用 | F30: 存货 | G30: 长期资产 | H30: … | I30: 合计
C31: 第一期 | I31: =SUM(E31:H31) -> 0 | J31: =D31-I31 -> 0
C32: 第二期 | I32: =SUM(E32:H32) -> 0 | J32: =D32-I32 -> 0
C33: 最后一期 | I33: =SUM(E33:H33) -> 0 | J33: =D33-I33 -> 0
A34: 三、审计说明：
A36: 四、审计结论：

Sheet 应付债券账面核对(分期付息到期一次还本) L4-8
A1: 致同会计师事务所
A2: 应付债券账面核对(分期付息到期一次还本)
A3: =底稿目录!A2 -> 被审计单位： | D3: =底稿目录!A4 -> 编制人： | G3: =底稿目录!A5 -> 编制日期： | K3: 索引号： | L3: =底稿目录!F15 -> L4-8
A4: =底稿目录!A3 -> 截止日：202X年12月31日 | D4: =底稿目录!A6 -> 复核人： | G4: =底稿目录!A7 -> 复核日期： | K4: 页次：
A5: 一、审计目标:
A6: 1.资产负债表中记录的应付债券是存在的，且已经记录在恰当的账户中；
A7: 2.所有应记录的应付债券均已记录，所有应当包括在财务报表中的相关披露均已包括；
A8: 3.应付债券以恰当的金额包括在财务报表中，与之相关的计价或分摊调整已恰当记录，相关披露已得到恰当计量和描述
A9: 二、审计过程：
A10: 1、期末余额测算
A11: 序号 | B11: 债券名称 | C11: 本期截止日 | D11: 期数 | E11: 期末账面价值
E12: 后续计量测算期末余额 | F12: 应计利息 | G12: 测算期末数 | H12: 账面数 | I12: 差异 | J12: 是否调整
A13: 1 | C13: ='应付债券后续计量(分期付息到期一次还本)L4-7'!B18 -> 0 | D13: ='应付债券后续计量(分期付息到期一次还本)L4-7'!A18 -> 第一期 | E13: ='应付债券后续计量(分期付息到期一次还本)L4-7'!K18 -> 0 | F13: =I19 -> 0 | G13: =E13+F13 -> 0 | H13: ='应付债券明细表L4-2'!AH15 -> 0 | I13: =G13-H13 -> 0
A14: 2
A15: 3
A16: 2、利息测算
A17: 序号 | B17: 债券名称 | C17: 利息调整 | G17: 应计利息
C18: 测算数 | D18: 账面数 | E18: 差异 | F18: 是否调整 | G18: 最近一次付息日 | H18: 计息天数 | I18: 测算数 | J18: 账面数 | K18: 差异 | L18: 是否调整
A19: 1 | B19: =B13 -> 0 | C19: ='应付债券后续计量(分期付息到期一次还本)L4-7'!G17 -> 0 | D19: ='应付债券明细表L4-2'!AF15 -> 0 | E19: =C19-D19 -> 0 | H19: =IFERROR(IF(DATEDIF(MAX(G19+1,'应付债券后续计量(分期付息到期一次还本)L4-7'!B11),MIN('应付债券后续计量(分期付息到期一次还本)L4-7'!L13,'应付债券后续计量(分期付息到期一次还本)L4-7'!D11),"d"),DATEDIF(MAX(G19+1,'应付债券后续计量(分期付息到期一次还本)L4-7'!B11),MIN('应付债券后续计量(分期付息到期一次还本)L4-7'!L13,'应付债券后续计量(分期付息到期一次还本)L4-7'!D11),"d")+1,0),0) -> 0 | I19: =ROUND('应付债券后续计量(分期付息到期一次还本)L4-7'!$F$13*'应付债券后续计量(分期付息到期一次还本)L4-7'!$G$13/365*H19,2) -> 0 | J19: ='应付债券明细表L4-2'!AG15 -> 0 | K19: =I19-J19 -> 0
A20: 2 | B20: =B14 -> 0
A21: 3 | B21: =B15 -> 0
A22: 3、“利息调整”摊销分配测算
A23: 序号 | B23: 债券名称 | C23: 债权期数 | D23: “利息调整”摊销 | E23: 利息分配数测算 | J23: 差异
E24: 财务费用 | F24: 存货 | G24: 长期资产 | H24: … | I24: 合计
D25: ='应付债券后续计量(分期付息到期一次还本)L4-7'!F18 -> 0 | I25: =SUM(E25:H25) -> 0 | J25: =D25-I25 -> 0
D26: ='应付债券后续计量(分期付息到期一次还本)L4-7'!F19 -> 0 | I26: =SUM(E26:H26) -> 0 | J26: =D26-I26 -> 0
D27: ='应付债券后续计量(分期付息到期一次还本)L4-7'!F20 -> 0 | I27: =SUM(E27:H27) -> 0 | J27: =D27-I27 -> 0
A29: 序号 | B29: 债券名称 | C29: 债权期数 | D29: “利息调整”摊销 | E29: 利息分配数测算 | J29: 差异
E30: 财务费用 | F30: 存货 | G30: 长期资产 | H30: … | I30: 合计
I31: =SUM(E31:H31) -> 0 | J31: =D31-I31 -> 0
I32: =SUM(E32:H32) -> 0 | J32: =D32-I32 -> 0
I33: =SUM(E33:H33) -> 0 | J33: =D33-I33 -> 0
A34: 三、审计说明：
A36: 四、审计结论：

Sheet 应付债券检查表L4-9
A1: 致同会计师事务所
A2: 应付债券检查底稿
A3: =底稿目录!A2 -> 被审计单位： | E3: =底稿目录!A4 -> 编制人： | H3: =底稿目录!A5 -> 编制日期： | O3: 索引号： | P3: =底稿目录!F16 -> L4-9
A4: =底稿目录!A3 -> 截止日：202X年12月31日 | E4: =底稿目录!A6 -> 复核人： | H4: =底稿目录!A7 -> 复核日期： | O4: 页次：
A5: 一、审计目标:
A6: 1.资产负债表中记录的应付债券是存在的，且已经记录在恰当的账户中； 2.记录的应付债券由被审计单位拥有或控制；
A7: 3.应付债券以恰当的金额包括在财务报表中，与之相关的计价或分摊调整已恰当记录，相关披露已得到恰当计量和描述
A8: 二、测试： | C8: 测试原因：大额（）关联方（）大额交易频繁（）异常（）其他（）
A9: 测试内容说明：1.原始凭证是否齐全； 2.记账凭证与原始凭证是否相符；3.账务处理是否正确；4.是否记录于恰当的会计期间；5.……
A10: 记账凭证 | H10: 支持性文件 | I10: 核对内容 | N10: 索引号 | O10: 是否异常 | P10: 备注说明
A11: 日期 | B11: 凭证编号 | C11: 业务内容 | D11: 对方科目 | E11: 对方明细科目 | F11: 借方金额 | G11: 贷方金额 | I11: 1 | J11: 2 | K11: 3 | L11: 4 | M11: 5
A22: 合计 | F22: =SUM(F12:F21) -> 0 | G22: =SUM(G12:G21) -> 0
A23: 本期发生额 | F23: ='应付债券明细表L4-2'!BZ22 -> 0 | G23: ='应付债券明细表L4-2'!BT22 -> 0
A24: 检查比例 | F24: =F22/F23 -> #DIV/0! | G24: =G22/G23 -> #DIV/0!
A25: 三、审计说明：
A30: 四、审计结论：

Sheet GT_Custom
A1: C1 | B1: Custom 1
A2: C2 | B2: Custom 2
A3: C3 | B3: Custom 3
A4: C4 | B4: Custom 4
A5: C5 | B5: Custom 5
A6: C6 | B6: Custom 6
A7: C7 | B7: Custom 7
A8: C8 | B8: Custom 8
