Workbook

Sheet 底稿目录
A1: 底稿开列时，可先在以下单元格填写有关内容，以便其他底稿引用有关数据：
A2: 被审计单位：
A3: 截止日：202X年12月31日 | D3: 序号 | E3: 内容 | F3: 索引号 | G3: 备注
A4: 编制人： | D4: 1 | E4: 未分配利润实质性程序表 | F4: M6A
A5: 编制日期： | D5: 2 | E5: 审定表 | F5: M6-1
A6: 复核人： | D6: 3 | E6: 附注披露信息(上市公司) | H6: 无需打印
A7: 复核日期： | D7: 4 | E7: 附注披露信息(国企) | H7: 无需打印
D8: 5 | E8: 明细表 | F8: M6-2
A9: 关于工作底稿与审计程序索引号对应的说明 | D9: 6 | E9: 调整分录汇总 | F9: M6-3
A10: 1.编制的审计工作底稿应与审计程序对应。审计项目组应根据被审计单位实际情况和风险评估情况在实质性程序表中裁剪、修改或增加审计程序，根据实际执行的审计程序完成相应审计工作底稿，编制的工作底稿中应按自然顺序依次编制索引号，并通过唯一的索引号将与实质性程序表中的程序对应关联（即将工作底稿的索引号填入实质性程序表中的底稿索引号列）。 | D10: 7 | E10: 未分配利润检查表 | F10: M6-4
A14: 2.获取的支持性证据应与审计底稿或程序对应。审计项目组在完成底稿时获取的支持性证据应根据底稿索引号编制下一级按自然顺序排序的索引号（如D1-2-1、D1-2-2、……），并在底稿中说明引用的支持性证据、关联索引号。
A17: 3.工作底稿索引号的编码规则：实质性程序索引号按循环从“D”到“N”,循环内账户以顺序号排列，模板中底稿索引号按账户顺序+自然数顺序（即模板中索引号按二级自然顺序排列，如D1-1、D1-2、D1-3、……D1-N）。

Sheet 未分配利润实质性程序表 M6A 
A1: 致同会计师事务所
A2: 未分配利润实质性程序
A3: =底稿目录!A2 | C3: =底稿目录!A4 | E3: =底稿目录!A5 | H3: 索引号： | I3: =底稿目录!F4
A4: =底稿目录!A3 | C4: =底稿目录!A6 | E4: =底稿目录!A7 | H4: 页 次：
A5: 一、本账户涉及的科目
A6: 未分配利润
A7: 二、审计目标与认定的对应关系
A8: 审计目标 | G8: 财务报表的认定
A9: A. 资产负债表中记录的资本公积是存在的，且已经记录在恰当的账户中 | G9: 存在
A10: B. 所有应记录的资本公积均已记录，所有应当包括在财务报表中的相关披露均已包括 | G10: 完整性
A11: C. 记录的资本公积由被审计单位拥有或控制 | G11: 权利和义务
A12: D. 资本公积以恰当的金额包括在财务报表中，与之相关的计价或分摊调整已恰当记录，相关披露已得到恰当计量和描述 | G12: 准确性、计价和分摊
A13: E. 资本公积已被恰当地汇总或分解且表述清楚，相关披露在按照企业会计准则的编制基础下是相关的、可理解的 | G13: 列报
A14: 三、计划实施的实质性程序
A15: 序号 | B15: 审计程序 | C15: 程序分类 | D15: 财务报表的认定 | I15: 底稿索引号
D16: 存在 | E16: 完整性 | F16: 权利和 义务 | G16: 准确性、计价和分摊 | H16: 列报 | J16: 根据被审计单位实际情况和风险评估情况裁剪、修改或增加审计程序
A17: 1 | B17: 获取或编制实收资本（股本）明细表，完成以下工作，并编制审定表 复核加计是否正确，与总账、明细账合计数核对是否相符，期初余额与上期审定期末余额是否相符； | C17: 常规★ | D17: √ | E17: √ | G17: √ | I17: M6-1 /M6-2
A18: 2 | B18: 在使用手工编制、自定义信息报告、系统生成的非固定格式报告等由被审计单位生成的信息时，测试有关信息准确性和完整性，并考虑针对编制和维护由被审计单位生成的信息的相关控制实施控制测试，以评价该信息是否能够为实现审计目的提供基础。 | C18: 常规★ | E18: √ | G18: √ | I18: T1/ | J18: 可参见《审计手册》4.2.6，由被审计单位生成的信息可能是由系统生成的、或手工编制的、或二者兼而有之的方式生成的。例如，由被审计单位生成的信息可能包括： • 不涉及自定义的、由系统生成的报告（如，固定格式报告）； • 可能通过人工自定义的、由系统生成的报告，例如，（计算机）查询信息或特别定制的报告； • 手工编制的信息，例如，汇总信息的电子表格或用以支持分配、计算以及调节的电子表格； • 其他系统生成或手工编制的信息，例如，由被审计单位编制的客户发票； • 通过影印、拍摄、扫描或其他方式转换成电子形式的文件记录。
A19: 3 | B19: 对于上期资本的期末余额，核对期初未分配利润是否正确，检查上期利润分配相关文件以及在本期支付情况。（适用于首次承接） | C19: 备选 | D19: √ | E19: √ | F19: √ | G19: √ | I19: M6- | J19: 由被审计单位生成的信息不包括： • 总分类账或明细分类账、试算平衡表、或经审计的财务报表； • 第三方（除了服务机构）的报表或报告，例如，原始银行对账单，或函证的回函； • 外部数据（例如，第三方发布的数据，如，定价来源）。
A20: 4 | B20: 针对本期利润分配： （1）了解本年利润弥补以前年度亏损的情况； （2）检查公司章程、股东大会和董事会会议纪要中有关股利的规定，了解股利分配标准和发放方式是否符合有关规定并经法定程序批准； （3）检查董事会会议纪要、股东会（或股东大会）决议、利润分配方案等资料，对照有关规定确认利润分配的合法性；复核应付股利金额和会计处理是否正确； （4）结合应付股利检查现金股利是否按公告规定的时间、金额予以发放。 | C20: 备选 | D20: √ | E20: √ | F20: √ | I20: M6-2 /M6-4
A21: 5 | B21: 如果存在未分配利润弥补以前年度亏损的情况，检查有关公司章程、董事会/股东会决议、政府批准文件等，确认未分配利润弥补的合法性，检查会计处理是否正确。 | C21: 常规★ | D21: √ | E21: √ | F21: √ | I21: M6-2
A22: 6 | B22: 如果存在除净利润转入以外的未分配利润其他变动，结合所获取的文件资料以及其他相关科目的审计，判断其分类为未分配利润是否恰当，确定其会计处理是否正确。 | C22: 备选 | D22: √ | E22: √ | F22: √ | I22: M6-2
A23: 7 | B23: 检查未分配利润是否已按企业会计准则或其他适用的规定在财务报表中做出恰当列报和披露。 | C23: 常规★ | H23: √ | I23: A1-1/A1-15 /A1-16

Sheet 未分配利润实质性程序表 Q6A  (修订前)
A1: 致同会计师事务所
A2: 未分配利润实质性程序
A3: =底稿目录!A2 | C3: =底稿目录!A4 | F3: =底稿目录!A5 | I3: 索引号： | J3: QA
A4: =底稿目录!A3 | C4: =底稿目录!A6 | F4: =底稿目录!A7 | I4: 页 次：
A5: 一、本账户涉及的科目
A6: 未分配利润
A7: 二、重大错报风险需从实质性程序获取的保证程度
A8: 审计目标与认定对应关系 | C8: 财务报表的认定 | H8: 信赖/不信赖/不适用 | I8: 索引号
C9: 存在 | D9: 完整性 | E9: 权利和义务 | F9: 计价和分摊 | G9: 列报与披露
A10: A. 资产负债表中记录的专项储备是存在的。 | C10: √
A11: B. 所有应记录的专项储备均已记录，专项储备的增减变动符合法律、法规和合同、章程的规定。 | D11: √
A12: C. 专项储备以恰当的金额包括在财务报表中。 | F12: √
A13: D. 专项储备已按照企业会计准则的规定在财务报表中作出恰当列报和披露。 | G13: √
A15: 三、计划实施的实质性程序
A16: 序号 | B16: 审计程序 | D16: 程序分类 | E16: 对应的认定/风险 | I16: 执行情况说明 （含底稿索引）
A17: （一） | B17: 编制审定表 | D17: 常规★ | E17: B | I17: Q6 | K17: 整合 | L17: 获取或编制实收资本（股本）明细表，完成以下工作，并编制审定表 复核加计是否正确，与总账、明细账合计数核对是否相符，期初余额与上期审定期末余额是否相符；
A18: （二） | B18: 获取或编制未分配利润、其他综合收益明细表，并完成以下工作： | D18: 常规★ | E18: C | I18: Q6-1 | K18: 整合
A19: 1 | B19: 复核加计正确 。 | D19: 常规★ | E19: C | K19: 整合
A20: 2 | B20: 将总金额与总账核对。 | D20: 常规★ | E20: C | K20: 整合
A21: 3 | B21: 确定计算的准确性。 | D21: 常规 | E21: C | K21: 整合
A22: 4 | B22: 将期初额与上年度工作底稿或前期财务报表核对。 | D22: 常规 | E22: C | K22: 整合
A23: 5 | B23: 将期末余额与总分类账核对一致。 | D23: 常规 | E23: C | K23: 整合
A24: 6 | B24: 以非记账本位币出资的，检查其折算汇率是否符合规定，折算差额的会计处理是否正确。 | D24: 常规★ | E24: C | K24: 整合
A25: （三） | B25: 在使用被审计单位生成的信息（IPE）时，应当评价该信息对实现审计目的是否足够可靠，包括根据具体情况在必要时实施下列程序： | D25: 常规★ | E25: B | I25: T1 | K25: 整合 | L25: 在使用手工编制、自定义信息报告、系统生成的非固定格式报告等由被审计单位生成的信息时，测试有关信息准确性和完整性，并考虑针对编制和维护由被审计单位生成的信息的相关控制实施控制测试，以评价该信息是否能够为实现审计目的提供基础。
A26: 1 | B26: 获取有关信息准确性和完整性的审计证据。 | K26: 整合
A27: 2 | B27: 评价信息对实现审计目的是否足够准确和详细。 | K27: 整合
A28: （四） | B28: 对于上期未分配利润账户的期末余额（适用于首次承接时对期初余额的审计）： | D28: 备选 | E28: AB | I28: Q6-1 | K28: 修改 | L28: 对于上期资本的期末余额，核对期初未分配利润是否正确，检查上期利润分配相关文件以及在本期支付情况。（适用于首次承接）
A29: 1 | B29: 取得企业成立时的文件、合伙协议等并摘录相关章节。 | D29: 备选 | E29: AB | K29: 修改
A30: 2 | B30: 向证券结算中介机构并与股票登记簿核对，或向每位合伙人函证以确认股本账户期初金额。 | D30: 备选 | E30: AB | K30: 修改
A31: （五） | B31: 获取董事会/股东会会议记录，执行下列审计程序。 | D31: 常规 | E31: AB | I31: Q6-2 | K31: 删除
A32: 1 | B32: 确定会议纪要是否包含权益交易。包括：现金股利、股票股利、股票分割；权益回购；已出售的权益性工具。 | D32: 常规 | E32: AB | K32: 删除
A33: 2 | B33: 对于识别出的交易，确认交易是否经过授权并且得到适当会计处理。 | D33: 常规 | E33: AB | K33: 删除
A34: （六） | B34: 取得未分配利润账户当期交易活动的明细表，检查增减变动的原因，对每一项增加或减少，关注有关交易的性质，检查法律性文件是否齐全，相关的手续是否办理，以及其会计处理是否正确： | D34: 常规★ | E34: AB | I34: Q6-2 | K34: 整合 | L34: 针对本期利润分配： （1）了解本年利润弥补以前年度亏损的情况； （2）审阅公司章程、股东大会和董事会会议纪要中有关股利的规定，了解股利分配标准和发放方式是否符合有关规定并经法定程序批准； （3）检查董事会会议纪要、股东会（或股东大会）决议、利润分配方案等资料，对照有关规定确认利润分配的合法性；复核应付股利金额和会计处理是否正确； （4）结合应付股利检查现金股利是否按公告规定的时间、金额予以发放。
A35: 1 | B35: 对于每一增减变动，确定交易的是否恰当，会计处理是否正确。 | D35: 常规★ | E35: AB | K35: 整合
A36: 2 | B36: 通过查阅上述会议记录，确定每笔交易是否都已通过授权。 | D36: 常规 | E36: AB | K36: 整合
A37: 3 | B37: 审阅公司章程、股东（大）会、董事会会议记录中相关规定。收集与所有者权益账户变动有关的董股东（大）会决议、事会会议纪要、合同、协议、公司章程及营业执照，公司设立批文、验资报告以及政府主管部门、财政部门批复、资产评估报告等文件资料，并更新永久性档案。 | D37: 常规★ | E37: AB | K37: 整合
A38: 4 | B38: 针对利润分配的审计程序： | D38: 常规 | E38: AB | I38: Q6-2 | K38: 整合
A39: （1） | B39: 了解本年利润弥补以前年度亏损的情况，确定本期末未弥补亏损金额。 | D39: 常规 | E39: AB | K39: 整合
A40: （2） | B40: 审阅公司章程、股东大会和董事会会议纪要中有关股利的规定，了解股利分配标准和发放方式是否符合有关规定并经法定程序批准。 | D40: 常规 | E40: AB | K40: 整合
A41: （3） | B41: 检查董事会会议纪要、股东会（或股东大会）决议、利润分配方案等资料，对照有关规定确认利润分配的合法性。 | D41: 常规 | E41: AB | K41: 整合
...

Sheet 审定表M6-1
A1: 致同会计师事务所
A2: 未分配利润审定表
A3: =底稿目录!A2 | D3: =底稿目录!A4 | I3: =底稿目录!A5 | K3: 索引号： | L3: =底稿目录!F5
A4: =底稿目录!A3 | D4: =底稿目录!A6 | I4: =底稿目录!A7 | K4: 页 次：
A5: 项目名称 | B5: 本期数 | F5: 上期数 | J5: 本期审定数与上期 审定数的比较 | L5: 原因分析
B6: 未审数 | C6: 账项调整 | D6: 重分类调整 | E6: 审定数 | F6: 未审数 | G6: 账项调整 | H6: 重分类调整 | I6: 审定数 | J6: 变动额 | K6: 变动率
A7: 未分配利润 | B7: ='明细表M6-2'!B25 | C7: ='明细表M6-2'!C25 | D7: ='明细表M6-2'!D25 | E7: ='明细表M6-2'!E25 | F7: ='明细表M6-2'!F25 | G7: ='明细表M6-2'!G25 | H7: ='明细表M6-2'!H25 | I7: ='明细表M6-2'!I25 | J7: =E7-I7 | K7: =IF(AND(E7=0,J7=0),0,IF(AND(E7=0,J7>0),1,J7/E7))
J8: =E8-I8 | K8: =IF(AND(E8=0,J8=0),0,IF(AND(E8=0,J8>0),1,J8/E8))
J9: =E9-I9 | K9: =IF(AND(E9=0,J9=0),0,IF(AND(E9=0,J9>0),1,J9/E9))
A10: 合计 | B10: =SUM(B7:B9) | C10: =SUM(C7:C9) | D10: =SUM(D7:D9) | E10: =SUM(E7:E9) | F10: =SUM(F7:F9) | G10: =SUM(G7:G9) | H10: =SUM(H7:H9) | I10: =SUM(I7:I9) | J10: =E10-I10 | K10: =IF(AND(E10=0,J10=0),0,IF(AND(E10=0,J10>0),1,J10/E10))
A11: 试算平衡表数
A12: 差异数 | E12: =E10-E11 | I12: =I10-I11
A13: 1、审计说明
A14: （1）期末余额较期初余额增加（负数为减少）：
A15: 主要原因（比例超过30%的）：
A18: （2）利润分配情况及当年利润分配预案情况说明。
A22: 2、审计结论

Sheet 附注披露信息（上市公司）
A1: 致同会计师事务所
A2: 未分配利润附注披露信息（上市公司）
A3: =底稿目录!A2 | B3: =底稿目录!A4 | C3: =底稿目录!A5 | E3: 索引号：
A4: =底稿目录!A3 | B4: =底稿目录!A6 | C4: =底稿目录!A7 | E4: 页次：
A5: 未分配利润
A6: 项 目 | B6: 本期发生额 | C6: 上期发生额 | D6: 提取或分配比例
A7: 调整前 上期末未分配利润 | B7: ='明细表M6-2'!E10 | C7: ='明细表M6-2'!I10 | D7: --
A8: 调整 期初未分配利润合计数（调增+，调减-） | B8: ='明细表M6-2'!E11+'明细表M6-2'!E12 | C8: ='明细表M6-2'!I11+'明细表M6-2'!I12 | D8: --
A9: 调整后 期初未分配利润 | B9: =B7+B8 | C9: =C7+C8
A10: 加：本期归属于母公司所有者的净利润 | B10: ='明细表M6-2'!E15 | C10: ='明细表M6-2'!I15 | D10: --
A11: 其他（例如：盈余公积弥补亏损） | B11: ='明细表M6-2'!E14 | C11: ='明细表M6-2'!I14
A12: 减：提取法定盈余公积 | B12: ='明细表M6-2'!E17 | C12: ='明细表M6-2'!I17
A13: 提取任意盈余公积 | B13: ='明细表M6-2'!E18 | C13: ='明细表M6-2'!I18
A14: 提取一般风险准备
A15: 应付普通股股利 | B15: ='明细表M6-2'!E19 | C15: ='明细表M6-2'!I19
A16: 应付其他权益持有者的股利
A17: 转作股本的普通股股利 | B17: ='明细表M6-2'!E20 | C17: ='明细表M6-2'!I20
A18: 其他
A19: 期末未分配利润 | B19: =B9+B10+B11-SUM(B12:B17) | C19: =C9+C10+C11-SUM(C12:C17)
A20: 其中：子公司当年提取的盈余公积归属于母公司的金额
A21: 说明：（对期初未分配利润进行调整的，各项调整原因及金额。）
A22: 调整本期期初未分配利润明细：
A23: （1）由于《企业会计准则》及其相关新规定进行追溯调整，影响期初未分配利润XX元。
A24: （2）由于会计政策变更，影响期初未分配利润XX元。
A25: （3）由于重大会计差错更正，影响期初未分配利润XX元。
A26: （4）由于同一控制导致的合并范围变更，影响期初未分配利润XX元。
A27: （5）其他调整合计影响期初未分配利润XX元。
A28: 会计政策变更对期初未分配利润的影响参见附注二、38；前期差错更正对期初未分配利润的影响参见附注十四、1。
A29: 根据[XX文件]及公司章程的规定，本公司可供股东分配利润为按中国会计准则编制的报表数与按国际财务报告准则编制报表数两者孰低的金额。(请列明利润分配依据。)
A30: (对于首次公开发行证券的公司，如果发行前的滚存利润经股东大会决议由新老股东共同享有，应明确予以说明。如果发行前的滚存利润经股东大会决议在发行前进行分配并由老股东享有，公司应明确披露应付股利项目中列示的老股东享有的经审计的利润数。)

Sheet 附注披露信息（国有企业）
A1: 致同会计师事务所
A2: 未分配利润附注披露信息（国有企业）
A3: =底稿目录!A2 | B3: =底稿目录!A4 | C3: =底稿目录!A5 | D3: 索引号：
A4: =底稿目录!A3 | B4: =底稿目录!A6 | C4: =底稿目录!A7 | D4: 页次：
A5: 未分配利润
A6: 项 目 | B6: 本期金额 | C6: 上期金额
A7: 上年年末余额 | B7: ='明细表M6-2'!E10 | C7: ='明细表M6-2'!I10
A8: 期初调整金额 | B8: ='明细表M6-2'!E12+'明细表M6-2'!E11 | C8: ='明细表M6-2'!I12+'明细表M6-2'!I11
A9: 本期年初余额 | B9: ='明细表M6-2'!E13 | C9: ='明细表M6-2'!I13
A10: 本期增加额 | B10: ='明细表M6-2'!E15+'明细表M6-2'!E14 | C10: ='明细表M6-2'!I15+'明细表M6-2'!I14
A11: 其中：本期净利润转入 | B11: ='明细表M6-2'!E15 | C11: ='明细表M6-2'!I15
A12: 其他调整因素
A13: 本期减少额 | B13: ='明细表M6-2'!E16 | C13: ='明细表M6-2'!I16
A14: 其中：本期提取盈余公积数 | B14: ='明细表M6-2'!E17+'明细表M6-2'!E18 | C14: ='明细表M6-2'!I17+'明细表M6-2'!I18
A15: 本期提取一般风险准备
A16: 本期分配现金股利数 | B16: ='明细表M6-2'!E19 | C16: ='明细表M6-2'!I19
A17: 转增资本 | B17: ='明细表M6-2'!E20 | C17: ='明细表M6-2'!I20
A18: 其他减少
A19: 本期期末余额 | B19: =B9+B10-B13 | C19: =C9+C10-C13

Sheet 明细表M6-2
A1: 致同会计师事务所
A2: 未分配利润明细表
A3: =底稿目录!A2 | C3: =底稿目录!A4 | G3: =底稿目录!A5 | J3: 索引号： | K3: =底稿目录!F8
A4: =底稿目录!A3 | C4: =底稿目录!A6 | G4: =底稿目录!A7 | J4: 页 次：
A5: 一、审计目标:
A6: 1.资本公积已被恰当地汇总或分解且表述清楚，相关披露在按照企业会计准则的编制基础下是相关的、可理解的。
A7: 二、审计过程：
A8: 内容 | B8: 本期数 | F8: 上期数 | J8: 索引号 | K8: 备注
B9: 未审数 | C9: 账项调整 | D9: 重分类调整 | E9: 审定数 | F9: 未审数 | G9: 账项调整 | H9: 重分类调整 | I9: 审定数
A10: 一、上年年末余额 | E10: =B10+C10+D10 | I10: =F10+G10+H10
A11: 加：会计政策变更 | E11: =B11+C11+D11 | I11: =F11+G11+H11
A12: 前期差错更正 | E12: =B12+C12+D12 | I12: =F12+G12+H12
A13: 二、本年年初余额 | B13: =B10+B11+B12 | C13: =C10+C11+C12 | D13: =D10+D11+D12 | E13: =E10+E11+E12 | F13: =F10+F11+F12 | G13: =G10+G11+G12 | H13: =H10+H11+H12 | I13: =F13+G13+H13
A14: 三、盈余公积补亏 | E14: =B14+C14+D14 | I14: =F14+G14+H14
A15: 四、本期净利润 | E15: =B15+C15+D15 | I15: =F15+G15+H15
A16: 五、利润分配 | B16: =SUM(B17:B21) | C16: =SUM(C17:C21) | D16: =SUM(D17:D21) | E16: =SUM(E17:E21) | F16: =SUM(F17:F21) | G16: =SUM(G17:G21) | H16: =SUM(H17:H21) | I16: =F16+G16+H16
A17: 1、提取法定盈余公积 | E17: =B17+C17+D17 | I17: =F17+G17+H17
A18: 2、提取任意盈余公积 | E18: =B18+C18+D18 | I18: =F18+G18+H18
A19: 3、应付现金股利 | E19: =B19+C19+D19 | I19: =F19+G19+H19
A20: 4、转作股本的股利 | E20: =B20+C20+D20 | I20: =F20+G20+H20
A21: 5、其他 | E21: =B21+C21+D21 | I21: =F21+G21+H21
A22: 六、所有者权益内部结转 | B22: =SUM(B23:B24) | C22: =SUM(C23:C24) | D22: =SUM(D23:D24) | E22: =SUM(E23:E24) | F22: =SUM(F23:F24) | G22: =SUM(G23:G24) | H22: =SUM(H23:H24) | I22: =F22+G22+H22
A23: 1、盈余公积弥补亏损 | E23: =B23+C23+D23 | I23: =F23+G23+H23
A24: 2、其他 | E24: =B24+C24+D24 | I24: =F24+G24+H24
A25: 七、本年年末余额 | B25: =B13+B14+B15-B16 | C25: =C13+C14+C15-C16 | D25: =D13+D14+D15-D16 | E25: =E13+E14+E15-E16 | F25: =F13+F14+F15-F16 | G25: =G13+G14+G15-G16 | H25: =H13+H14+H15-H16 | I25: =F25+G25+H25
A26: 三、审计说明：
A29: 四、审计结论：
A31: 1、审计说明可以概述：（1）程序的测试情况、结果；（2）拟调整事项及其调整分录、未调整事项及其影响，审计范围受到限制情况及其影响。
A32: 2、审计结论可参考：A、未见异常。B、除上述重大不符事项应当作为调整事项予以调整外，其余未见异常。C、由于存在以下重大未调整事项(或审计范围受到限制无法获取充分、适当证据），不可确认。

Sheet 调整分录汇总M6-3
A1: 致同会计师事务所
A2: 未分配利润调整分录汇总表
A3: =底稿目录!A2 | D3: =底稿目录!A4 | F3: =底稿目录!A5 | I3: 索引号： | J3: =底稿目录!F9
A4: =底稿目录!A3 | D4: =底稿目录!A6 | F4: =底稿目录!A7 | I4: 页 次：
A5: 调整事项说明 | B5: 类别（报表调整/账项调整/其他） | C5: 报表项目 | D5: 科目名称 | E5: 附注项目 | F5: …… | G5: 借方调整金额 | H5: 贷方调整金额 | I5: 索引 | J5: 备注

Sheet 未分配利润检查表M6-4
A1: 致同会计师事务所
A2: 未分配利润检查表
A3: =底稿目录!A2 | E3: =底稿目录!A4 | I3: =底稿目录!A5 | O3: 索引号： | P3: =底稿目录!F10
A4: =底稿目录!A3 | E4: =底稿目录!A6 | I4: =底稿目录!A7 | O4: 页 次：
A5: 一、测试目标：
A6: 通过凭证抽查，验证未分配利润业务的存在/发生、计价和分摊。
A7: 二、测试：
A8: 测试内容说明：1.原始凭证是否齐全； 2.记账凭证与原始凭证是否相符；3.账务处理是否正确；4.是否记录于恰当的会计期间；5.……
A9: 记账凭证 | H9: 支持性文件 | I9: 核对内容 | N9: 索引号 | O9: 是否异常 | P9: 备注说明
A10: 日期 | B10: 凭证编号 | C10: 业务内容 | D10: 对方科目 | E10: 对方明细科目 | F10: 借方金额 | G10: 贷方金额 | I10: 1 | J10: 2 | K10: 3 | L10: 4 | M10: 5
A17: 四、审计说明：
A22: 五、审计结论：

Sheet GT_Custom
A1: C1 | B1: Custom 1
A2: C2 | B2: Custom 2
A3: C3 | B3: Custom 3
A4: C4 | B4: Custom 4
A5: C5 | B5: Custom 5
A6: C6 | B6: Custom 6
A7: C7 | B7: Custom 7
A8: C8 | B8: Custom 8
