Workbook
Name _.dbf: #REF!
Name _00510: #REF!
Name _1、: #REF!
Name _1、受本循环影响的相关交易和账户余额: #REF!
Name _13: #REF!
Name _1w6_: #REF!
Name _1固定资产数据库_筛选打印: #REF!
Name _2、主要业务活动: #REF!
Name _2、注册会计师通常应在本循环中了解与上述业务活动相关的内部控制_如果计划在其他业务循环中对上述: #REF!
Name _2其他资产_开办费除外_明细表: #REF!
Name _3余额表_一级_.dbf: #REF!
Name _DAT1: #REF!
Name _DAT10: #REF!
Name _DAT11: #REF!
Name _DAT2: #REF!
Name _DAT3: #REF!
Name _DAT4: #REF!
Name _DAT5: #REF!
Name _DAT6: #REF!
Name _DAT7: #REF!
Name _DAT8: #REF!
Name _DAT9: #REF!
Name _YE1: #REF!
Name _YS1: #REF!
Name _YS2: '[1]YS02-02'!#REF!
Name a: #REF!
Name a1c1: #REF!,#REF!
Name aa: #REF!
Name aaa: #REF!
Name agmmt: #REF!
Name agmt: #REF!
Name agmt1: #REF!
Name al: #REF!
Name avg_days: [3]Sheet3!$A$2
Name a暗暗: [4]企业表一!$F$20
Name b: #REF!
Name BD: #REF!
Name beg_day: #REF!
Name beg_day1: #REF!
Name CarryKnown: #REF!
Name CarryKnownTable: #REF!
Name CarryLikely: #REF!
Name CarryLikelyTable: #REF!
Name Carryover_Effect_of_Prior_Year: #REF!
Name CarryoverTitle: #REF!
Name CC_Instruction: #REF!
Name CE_CarryKnownProtection: #REF!
Name CE_CarryKnownTable: #REF!
Name CE_CarryLikely1Protection: #REF!
Name CE_CarryLikely1Table: #REF!
Name CE_CarryLikely2Protection: #REF!
Name CE_CarryLikely2Table: #REF!
Name CE_CarryTaxable: #REF!
Name CE_Desc: #REF!
Name CE_Income: #REF!
Name CE_KeepFormat: #REF!
Name CE_KnownChange: #REF!
Name CE_KnownFormulaProtection: #REF!
Name CE_KnownImpact: #REF!
Name CE_Likely1Change: #REF!

Sheet 底稿目录
A1: 底稿开列时，可先在以下单元格填写有关内容，以便其他底稿引用有关数据：
A2: 被审计单位：
A3: 截止日：202X年12月31日 | D3: 序号 | E3: 内容 | F3: 索引号 | G3: 备注
A4: 编制人： | D4: 1 | E4: 其他综合收益实质性程序表 | F4: M9A
A5: 编制日期： | D5: 2 | E5: 审定表 | F5: M9-1
A6: 复核人： | D6: 3 | E6: 附注披露信息(上市公司) | H6: 无需打印
A7: 复核日期： | D7: 4 | E7: 附注披露信息(国企) | H7: 无需打印
D8: 5 | E8: 明细表 | F8: M9-2
A9: 关于工作底稿与审计程序索引号对应的说明 | D9: 6 | E9: 调整分录汇总 | F9: M9-3
A10: 1.编制的审计工作底稿应与审计程序对应。审计项目组应根据被审计单位实际情况和风险评估情况在实质性程序表中裁剪、修改或增加审计程序，根据实际执行的审计程序完成相应审计工作底稿，编制的工作底稿中应按自然顺序依次编制索引号，并通过唯一的索引号将与实质性程序表中的程序对应关联（即将工作底稿的索引号填入实质性程序表中的底稿索引号列）。 | D10: 7 | E10: 其他综合收益核对表 | F10: M9-4
A14: 2.获取的支持性证据应与审计底稿或程序对应。审计项目组在完成底稿时获取的支持性证据应根据底稿索引号编制下一级按自然顺序排序的索引号（如D1-2-1、D1-2-2、……），并在底稿中说明引用的支持性证据、关联索引号。
A17: 3.工作底稿索引号的编码规则：实质性程序索引号按循环从“D”到“N”,循环内账户以顺序号排列，模板中底稿索引号按账户顺序+自然数顺序（即模板中索引号按二级自然顺序排列，如D1-1、D1-2、D1-3、……D1-N）。

Sheet 其他综合收益实质性程序表 M9A
A1: 致同会计师事务所
A2: 其他综合收益实质性程序
A3: =底稿目录!A2 -> 被审计单位： | C3: =底稿目录!A4 -> 编制人： | E3: =底稿目录!A5 -> 编制日期： | H3: 索引号： | I3: =底稿目录!F4 -> M9A
A4: =底稿目录!A3 -> 截止日：202X年12月31日 | C4: =底稿目录!A6 -> 复核人： | E4: =底稿目录!A7 -> 复核日期： | H4: 页 次：
A5: 一、本账户涉及的科目
A6: 其他综合收益
A7: 二、审计目标与认定的对应关系
A8: 审计目标 | G8: 财务报表的认定
A9: A. 资产负债表中记录的其他综合收益是存在的，且已经记录在恰当的账户中 | G9: 存在
A10: B. 所有应记录的其他综合收益均已记录，所有应当包括在财务报表中的相关披露均已包括 | G10: 完整性
A11: C. 记录的其他综合收益由被审计单位拥有或控制 | G11: 权利和义务
A12: D. 其他综合收益以恰当的金额包括在财务报表中，与之相关的计价或分摊调整已恰当记录，相关披露已得到恰当计量和描述 | G12: 准确性、计价和分摊
A13: E. 其他综合收益已被恰当地汇总或分解且表述清楚，相关披露在按照企业会计准则的编制基础下是相关的、可理解的 | G13: 列报
A14: 三、计划实施的实质性程序
A15: 序号 | B15: 审计程序 | C15: 程序分类 | D15: 财务报表的认定 | I15: 底稿索引号
D16: 存在 | E16: 完整性 | F16: 权利和 义务 | G16: 准确性、计价和分摊 | H16: 列报
A17: 1 | B17: 获取或编制专项储备明细表，完成以下工作，并编制审定表 复核加计是否正确，与总账、明细账合计数核对是否相符，期初余额与上期审定期末余额是否相符； | C17: 常规★ | D17: √ | E17: √ | G17: √ | I17: M9-1 /M9-2
A18: 2 | B18: 在使用手工编制、自定义信息报告、系统生成的非固定格式报告等由被审计单位生成的信息时，测试有关信息准确性和完整性，并考虑针对编制和维护由被审计单位生成的信息的相关控制实施控制测试，以评价该信息是否能够为实现审计目的提供基础。 | C18: 常规★ | E18: √ | G18: √ | I18: T1/ | J18: 可参见《审计手册》4.2.6，由被审计单位生成的信息可能是由系统生成的、或手工编制的、或二者兼而有之的方式生成的。例如，由被审计单位生成的信息可能包括： • 不涉及自定义的、由系统生成的报告（如，固定格式报告）； • 可能通过人工自定义的、由系统生成的报告，例如，（计算机）查询信息或特别定制的报告； • 手工编制的信息，例如，汇总信息的电子表格或用以支持分配、计算以及调节的电子表格； • 其他系统生成或手工编制的信息，例如，由被审计单位编制的客户发票； • 通过影印、拍摄、扫描或其他方式转换成电子形式的文件记录。
A19: 3 | B19: 对于上期其他综合收益末余额，取得一般风险储备明细表复核加计是否正确，与总账、明细账合计数是否相符，检查其他综合收益形成原因、依据是否充分、分类是否正确。（适用于首次承接） | C19: 备选 | D19: √ | E19: √ | F19: √ | G19: √ | J19: 由被审计单位生成的信息不包括： • 总分类账或明细分类账、试算平衡表、或经审计的财务报表； • 第三方（除了服务机构）的报表或报告，例如，原始银行对账单，或函证的回函； • 外部数据（例如，第三方发布的数据，如，定价来源）。
A20: 4 | B20: 针对其他综合收益明细项目，结合长期股权投资、应付职工薪酬等其他科目的审计，检查会计处理是否正确： （1）检查其他综合收益的分类是否准确完整。是否按照企业会计准则的规定分类为“以后会计期间不能重分类进损益”和“以后期间将重分类进损益”两类列报； （2）检查当期重分类（原计入其他综合收益，本期入损益）事项，重新计算重分类的金额是否正确； （3）检查不能重分类进损益的其他综合收益在当期权益内部结转事项，是否符合企业会计准则的规定以及管理层的相关文件规定。 （4）考虑所得税影响，检查其他综合收益税后净额计算是否正确。 | C20: 常规 | D20: √ | E20: √ | F20: √ | G20: √ | H20: √ | I20: M9-2 /M9-2
A21: 5 | B21: 检查其他综合收益、其他综合收益税后净额是否已按企业会计准则或其他适用的规定在财务报表中做出恰当列报和披露。 | C21: 常规★ | H21: √ | I21: A1-1/A1-15 /A1-16

Sheet 审定表M9-1
A1: 致同会计师事务所
A2: 其他综合收益审定表
A3: =底稿目录!A2 -> 被审计单位： | D3: =底稿目录!A4 -> 编制人： | H3: =底稿目录!A5 -> 编制日期： | K3: 索引号： | L3: =底稿目录!F5 -> M9-1
A4: =底稿目录!A3 -> 截止日：202X年12月31日 | D4: =底稿目录!A6 -> 复核人： | H4: =底稿目录!A7 -> 复核日期： | K4: 页 次：
A5: 项目名称 | B5: 期初数 | F5: 期末数 | J5: 本期审定数与上期 审定数的比较 | L5: 原因分析
B6: 未审数 | C6: 账项调整 | D6: 重分类调整 | E6: 审定数 | F6: 未审数 | G6: 账项调整 | H6: 重分类调整 | I6: 审定数 | J6: 变动额 | K6: 变动率
A7: 一、以后不能重分类进损益的其他综合收益 | B7: ='明细表M9-2'!C10 -> 0 | C7: ='明细表M9-2'!H10 -> 0 | D7: ='明细表M9-2'!I10 -> 0 | E7: ='明细表M9-2'!P10 -> 0 | F7: ='明细表M9-2'!G10 -> 0 | G7: ='明细表M9-2'!H10+'明细表M9-2'!J10-'明细表M9-2'!K10-'明细表M9-2'!L10 -> 0 | H7: ='明细表M9-2'!I10+'明细表M9-2'!M10-'明细表M9-2'!N10-'明细表M9-2'!O10 -> 0 | I7: ='明细表M9-2'!T10 -> 0 | J7: =I7-E7 -> 0 | K7: =IF(AND(E7=0,J7=0),0,IF(AND(E7=0,J7>0),1,J7/E7)) -> 0
A8: 二、以后能重分类进损益的其他综合收益 | B8: ='明细表M9-2'!C16 -> 0 | C8: ='明细表M9-2'!H16 -> 0 | D8: ='明细表M9-2'!I16 -> 0 | E8: ='明细表M9-2'!P16 -> 0 | F8: ='明细表M9-2'!G16 -> 0 | G8: ='明细表M9-2'!H16+'明细表M9-2'!J16-'明细表M9-2'!K16-'明细表M9-2'!L16 -> 0 | H8: ='明细表M9-2'!I16+'明细表M9-2'!M16-'明细表M9-2'!N16-'明细表M9-2'!O16 -> 0 | I8: ='明细表M9-2'!T16 -> 0 | J8: =I8-E8 -> 0 | K8: =IF(AND(E8=0,J8=0),0,IF(AND(E8=0,J8>0),1,J8/E8)) -> 0
J9: =I9-E9 -> 0 | K9: =IF(AND(E9=0,J9=0),0,IF(AND(E9=0,J9>0),1,J9/E9)) -> 0
A10: 合计 | B10: =SUM(B7:B9) -> 0 | C10: =SUM(C7:C9) -> 0 | D10: =SUM(D7:D9) -> 0 | E10: =SUM(E7:E9) -> 0 | F10: =SUM(F7:F9) -> 0 | G10: =SUM(G7:G9) -> 0 | H10: =SUM(H7:H9) -> 0 | I10: =SUM(I7:I9) -> 0 | J10: =I10-E10 -> 0 | K10: =IF(AND(E10=0,J10=0),0,IF(AND(E10=0,J10>0),1,J10/E10)) -> 0
A11: 试算平衡表数
A12: 差异数 | E12: =E10-E11 -> 0 | I12: =I10-I11 -> 0
A13: 1、审计说明
A14: （1）期末余额较期初余额增加（负数为减少）：
A15: 主要原因（比例超过30%的）：
A18: （2）其他综合收益变动的原因、依据。
A22: 2、审计结论

Sheet 附注披露信息（上市公司）
A1: 致同会计师事务所
A2: 其他综合收益附注披露信息（上市公司）
A3: =底稿目录!A2 -> 被审计单位： | C3: =底稿目录!A4 -> 编制人： | D3: =底稿目录!A5 -> 编制日期： | G3: 索引号：
A4: =底稿目录!A3 -> 截止日：202X年12月31日 | C4: =底稿目录!A6 -> 复核人： | D4: =底稿目录!A7 -> 复核日期： | G4: 页 次：
A5: 其他综合收益
A6: 项 目 | B6: 期初余额 | C6: 本期发生金额 | H6: 期末余额
B7: （1） | C7: 本期所得税前发生额 | D7: 减：前期计入其他综合收益当期转入损益 | E7: 减：所得税费用 | F7: 税后归属于母公司（2） | G7: 税后归属于少数股东 | H7: （3）=（1）+（2）
A8: 一、以后不能重分类进损益的其他综合收益 | B8: ='明细表M9-2'!P10 -> 0 | C8: ='明细表M9-2'!Q10 -> 0 | E8: ='明细表M9-2'!S10 -> 0 | H8: =B8+F8 -> 0
A9: 1.重新计量设定受益计划变动额 | B9: ='明细表M9-2'!P11 -> 0 | C9: ='明细表M9-2'!Q11 -> 0 | E9: ='明细表M9-2'!S11 -> 0 | H9: =B9+F9 -> 0
A10: 2.权益法下不能转损益的其他综合收益 | B10: ='明细表M9-2'!P12 -> 0 | C10: ='明细表M9-2'!Q12 -> 0 | E10: ='明细表M9-2'!S12 -> 0 | H10: =B10+F10 -> 0
A11: 3.其他权益工具投资公允价值变动 | B11: ='明细表M9-2'!P13 -> 0 | C11: ='明细表M9-2'!Q13 -> 0 | E11: ='明细表M9-2'!S13 -> 0
A12: 4.企业自身信用风险公允价值变动 | B12: ='明细表M9-2'!P14 -> 0 | C12: ='明细表M9-2'!Q14 -> 0 | E12: ='明细表M9-2'!S14 -> 0
A13: 可无限量添加行 | H13: =B13+F13 -> 0
A14: 二、以后将重分类进损益的其他综合收益 | B14: ='明细表M9-2'!P16 -> 0 | C14: ='明细表M9-2'!Q16 -> 0 | D14: ='明细表M9-2'!R16 -> 0 | E14: ='明细表M9-2'!S16 -> 0 | H14: =B14+F14 -> 0
A15: 1.权益法下可转损益的其他综合收益 | B15: ='明细表M9-2'!P17 -> 0 | C15: ='明细表M9-2'!Q17 -> 0 | D15: ='明细表M9-2'!R17 -> 0 | E15: ='明细表M9-2'!S17 -> 0 | H15: =B15+F15 -> 0
A16: 2.其他债权投资公允价值变动 | B16: ='明细表M9-2'!P18 -> 0 | C16: ='明细表M9-2'!Q18 -> 0 | D16: ='明细表M9-2'!R18 -> 0 | E16: ='明细表M9-2'!S18 -> 0 | H16: =B16+F16 -> 0
A17: 3.金融资产重分类计入其他综合收益的金额 | B17: ='明细表M9-2'!P19 -> 0 | C17: ='明细表M9-2'!Q19 -> 0 | D17: ='明细表M9-2'!R19 -> 0 | E17: ='明细表M9-2'!S19 -> 0 | H17: =B17+F17 -> 0
A18: 4.其他债权投资信用减值准备 | B18: ='明细表M9-2'!P20 -> 0 | C18: ='明细表M9-2'!Q20 -> 0 | D18: ='明细表M9-2'!R20 -> 0 | E18: ='明细表M9-2'!S20 -> 0 | H18: =B18+F18 -> 0
A19: 5.现金流量套期储备 | B19: ='明细表M9-2'!P21 -> 0 | C19: ='明细表M9-2'!Q21 -> 0 | D19: ='明细表M9-2'!R21 -> 0 | E19: ='明细表M9-2'!S21 -> 0 | H19: =B19+F19 -> 0
A20: 6.外币财务报表折算差额 | B20: ='明细表M9-2'!P22 -> 0 | C20: ='明细表M9-2'!Q22 -> 0 | D20: ='明细表M9-2'!R22 -> 0 | E20: ='明细表M9-2'!S22 -> 0 | H20: =B20+F20 -> 0
H21: =B21+F21 -> 0
A23: 可无限量添加行 | B23: ='明细表M9-2'!P25 -> 0 | C23: ='明细表M9-2'!Q25 -> 0 | D23: ='明细表M9-2'!R25 -> 0 | E23: ='明细表M9-2'!S25 -> 0 | H23: =B23+F23 -> 0
A24: 其他综合收益合计 | B24: =B8+B14 -> 0 | C24: =C8+C14 -> 0 | D24: =D8+D14 -> 0 | E24: =E8+E14 -> 0 | H24: =H8+H14 -> 0
A25: 说明：其他综合收益的税后净额本期发生额为XXXX。其中，归属于母公司股东的其他综合收益的税后净额本期发生额为XXXX；归属于少数股东的其他综合收益的税后净额的本期发生额为XXXXX。
A26: （说明对现金流量套期损益的有效部分转为被套期项目初始确认金额调整等）
A27: 【提示：
A28: （1）上表中，期初数合计、期末数合计分别对应资产负债表中权益项下的其他综合收益，为归属于母公司的其他综合收益期初、期末余额。
A29: 税后归属于母公司合计数=利润表中归属于母公司所有者的其他综合收益的税后净额本期发生额；
A30: 税后归属于少数股东合计数=利润表中归属于少数股东的其他综合收益的税后净额本期发生额；】

Sheet 附注披露信息（国有企业）
A1: 致同会计师事务所
A2: 其他综合收益附注披露信息（国有企业）
A3: =底稿目录!A2 -> 被审计单位： | C3: =底稿目录!A4 -> 编制人： | G3: =底稿目录!A5 -> 编制日期： | K3: 索引号： | L3: M9-1
A4: =底稿目录!A3 -> 截止日：202X年12月31日 | C4: =底稿目录!A6 -> 复核人： | G4: =底稿目录!A7 -> 复核日期： | K4: 页 次：
A5: 附注披露信息（国企）
A6: 其他综合收益
A7: （1）其他综合收益各项目及其所得税影响和转入损益情况
A8: 项 目 | B8: 本期发生额 | H8: 上期发生额
B9: 税前金额 | D9: 所得税 | F9: 税后净额 | H9: 税前金额 | J9: 所得税 | L9: 税后净额 | O9: 项 目 | P9: 本期发生额 | S9: 上期发生额
A10: 一、以后不能重分类进损益的其他综合收益 | B10: =SUM(B11:C15) -> 0 | D10: =SUM(D11:E15) -> 0 | F10: =SUM(F11:G15) -> 0 | H10: =SUM(H11:I15) -> 0 | J10: =SUM(J11:K15) -> 0 | L10: =SUM(L11:M15) -> 0 | P10: 税前金额 | Q10: 所得税 | R10: 税后净额 | S10: 税前金额 | T10: 所得税 | U10: 税后净额
A11: 1、重新计量设定受益计划变动额 | B11: ='明细表M9-2'!Q11-'明细表M9-2'!R11 -> 0 | D11: ='明细表M9-2'!S11 -> 0 | F11: =B11-D11 -> 0 | L11: =H11-J11 -> 0 | O11: 一、以后不能重分类进损益的其他综合收益
A12: 2、权益法下不能转损益的其他综合收益 | B12: ='明细表M9-2'!Q12-'明细表M9-2'!R12 -> 0 | D12: ='明细表M9-2'!S12 -> 0 | F12: =B12-D12 -> 0 | L12: =H12-J12 -> 0 | O12: 1、重新计量设定受益计划净负债或净资产的变动
A13: 3、其他权益工具投资公允价值变动 | B13: ='明细表M9-2'!Q13-'明细表M9-2'!R13 -> 0 | D13: ='明细表M9-2'!S13 -> 0 | F13: =B13-D13 -> 0
A14: 4、企业自身信用风险公允价值变动 | B14: ='明细表M9-2'!Q14-'明细表M9-2'!R14 -> 0 | D14: ='明细表M9-2'!S14 -> 0 | F14: =B14-D14 -> 0
A15: 5、不能转损益的保险合同金融变动（金融企业适用） | F15: =B15-D15 -> 0 | L15: =H15-J15 -> 0 | O15: 2、权益法下在被投资单位不能重分类进损益的其他综合收益中享有的份额
A16: 二、以后将重分类进损益的其他综合收益 | B16: =B19+B22+B25+B28+B32+B35+B38+B41+B44+B47+B50 -> 0 | D16: =D19+D22+D25+D28+D32+D35+D38+D41+D44+D47+D50 -> 0 | F16: =F19+F22+F25+F28+F32+F35+F38+F41+F44+F47+F50 -> 0 | H16: =H19+H22+H25+H28+H32+H35+H38+H41+H44+H47+H50 -> 0 | J16: =J19+J22+J25+J28+J32+J35+J38+J41+J44+J47+J50 -> 0 | L16: =L19+L22+L25+L28+L32+L35+L38+L41+L44+L47+L50 -> 0 | O16: 3、其他权益工具投资公允价值变动 | P16: —— | Q16: —— | R16: ——
A17: 1、权益法下可转损益的其他综合收益 | B17: ='明细表M9-2'!Q17 -> 0 | F17: =B17-D17 -> 0 | L17: =H17-J17 -> 0 | O17: 4、企业自身信用风险公允价值变动 | P17: —— | Q17: —— | R17: ——
A18: 减：前期计入其他综合收益当期转入损益 | B18: ='明细表M9-2'!R17 -> 0 | F18: =B18-D18 -> 0 | L18: =H18-J18 -> 0 | O18: 5、其他
A19: 小 计 | B19: =B17-B18 -> 0 | D19: =D17-D18 -> 0 | F19: =F17-F18 -> 0 | H19: =H17-H18 -> 0 | J19: =J17-J18 -> 0 | L19: =L17-L18 -> 0 | O19: 二、以后将重分类进损益的其他综合收益
A20: 2、其他债权投资公允价值变动
A21: 减：前期计入其他综合收益当期转入损益
A22: 小 计 | B22: =B20-B21 -> 0 | D22: =D20-D21 -> 0 | F22: =F20-F21 -> 0 | H22: =H20-H21 -> 0 | J22: =J20-J21 -> 0 | L22: =L20-L21 -> 0
A23: 3、金融工具重分类计入其他综合收益的金额
A24: 减：前期计入其他综合收益当期转入损益
A25: 小 计 | B25: =B23-B24 -> 0 | D25: =D23-D24 -> 0 | F25: =F23-F24 -> 0 | H25: =H23-H24 -> 0 | J25: =J23-J24 -> 0 | L25: =L23-L24 -> 0
A26: 4、其他债权投资信用减值准备 | O26: 2、其他债权投资公允价值变动 | P26: —— | Q26: —— | R26: ——
A27: 减：前期计入其他综合收益当期转入损益 | O27: 减：前期计入其他综合收益当期转入损益 | P27: —— | Q27: —— | R27: ——
A28: 小 计 | B28: =B26-B27 -> 0 | D28: =D26-D27 -> 0 | F28: =F26-F27 -> 0 | H28: =H26-H27 -> 0 | J28: =J26-J27 -> 0 | L28: =L26-L27 -> 0 | O28: 小 计 | P28: —— | Q28: —— | R28: ——
A29: 5、现金流量套期储备（现金流量套期损益的有效部分） | B29: ='明细表M9-2'!Q21 -> 0 | F29: =B29-D29 -> 0 | L29: =H29-J29 -> 0 | O29: 3、可供出售金融资产公允价值变动损益 | P29: —— | Q29: —— | R29: ——
A30: 减：转为被套期项目初始确认金额的调整额 | B30: ='明细表M9-2'!R21 -> 0 | F30: =B30-D30 -> 0 | L30: =H30-J30 -> 0 | O30: 减：前期计入其他综合收益当期转入损益 | P30: —— | Q30: —— | R30: ——
A31: 前期计入其他综合收益当期转入损益 | F31: =B31-D31 -> 0 | L31: =H31-J31 -> 0 | O31: 小 计 | P31: —— | Q31: —— | R31: ——
A32: 小 计 | B32: =B29-B30-B31 -> 0 | D32: =D29-D30-D31 -> 0 | F32: =F29-F30-F31 -> 0 | H32: =H29-H30-H31 -> 0 | J32: =J29-J30-J31 -> 0 | L32: =L29-L30-L31 -> 0 | O32: 4、金融工具重分类计入其他综合收益的金额 | S32: —— | T32: —— | U32: ——
A33: 6、外币财务报表折算差额 | B33: ='明细表M9-2'!Q22 -> 0 | F33: =B33-D33 -> 0 | L33: =H33-J33 -> 0 | O33: 减：前期计入其他综合收益当期转入损益 | S33: —— | T33: —— | U33: ——
A34: 减：前期计入其他综合收益当期转入损益 | B34: ='明细表M9-2'!R22 -> 0 | F34: =B34-D34 -> 0 | L34: =H34-J34 -> 0 | O34: 小 计 | S34: —— | U34: ——
A35: 小 计 | B35: =B33-B34 -> 0 | D35: =D33-D34 -> 0 | F35: =F33-F34 -> 0 | H35: =H33-H34 -> 0 | J35: =J33-J34 -> 0 | L35: =L33-L34 -> 0 | O35: 5、持有至到期投资重分类为可供出售金融资产损益 | P35: —— | Q35: —— | R35: ——
A36: 7、可转损益的保险合同金融变动（金融企业适用）
A37: 减：前期计入其他综合收益当期转入损益
A38: 小 计 | B38: =B36-B37 -> 0 | D38: =D36-D37 -> 0 | F38: =F36-F37 -> 0 | H38: =H36-H37 -> 0 | J38: =J36-J37 -> 0 | L38: =L36-L37 -> 0
A39: 8、可转损益的分出再保险合同金融变动（金融企业适用）
A40: 减：前期计入其他综合收益当期转入损益
...

Sheet 明细表M9-2
A1: 致同会计师事务所
A2: 其他综合收益明细表
A3: =底稿目录!A2 -> 被审计单位： | E3: =底稿目录!A4 -> 编制人： | L3: =底稿目录!A5 -> 编制日期： | T3: 索引号： | U3: =底稿目录!F8 -> M9-2
A4: =底稿目录!A3 -> 截止日：202X年12月31日 | E4: =底稿目录!A6 -> 复核人： | L4: =底稿目录!A7 -> 复核日期： | T4: 页 次：
A5: 一、审计目标:
A6: 其他综合收益以恰当的金额包括在财务报表中，与之相关的计价或分摊调整已恰当记录，相关披露已得到恰当计量和描述。
A7: 二、审计过程：
A8: 项目类别 | C8: 未审数 | H8: 期初调整 | J8: 账项调整 | M8: 重分类调整 | P8: 审定数 | U8: 备注
C9: 期初数 | D9: 本期所得税前发生额 | E9: 减：前期计入其他综合收益当期转入损益/留存收益 | F9: 减：所得税费用 | G9: 期末数 | H9: 账项调整 | I9: 重分类调整 | J9: 本期所得税前发生额 | K9: 减：前期计入其他综合收益当期转入损益/留存收益 | L9: 减：所得税费用 | M9: 本期所得税前发生额 | N9: 减：前期计入其他综合收益当期转入损益/留存收益 | O9: 减：所得税费用 | P9: 期初数 | Q9: 本期所得税前发生额 | R9: 减：前期计入其他综合收益当期转入损益/留存收益 | S9: 减：所得税费用 | T9: 期末数
A10: 1、以后不能重分类进损益的其他综合收益 | C10: =SUM(C11:C15) -> 0 | D10: =SUM(D11:D15) -> 0 | E10: =SUM(E11:E15) -> 0 | F10: =SUM(F11:F15) -> 0 | G10: =C10+D10-E10-F10 -> 0 | H10: =SUM(H11:H15) -> 0 | I10: =SUM(I11:I15) -> 0 | J10: =SUM(J11:J15) -> 0 | K10: =SUM(K11:K15) -> 0 | L10: =SUM(L11:L15) -> 0 | M10: =SUM(M11:M15) -> 0 | N10: =SUM(N11:N15) -> 0 | O10: =SUM(O11:O15) -> 0 | ... Q10: =SUM(Q11:Q15) -> 0 | S10: =SUM(S11:S15) -> 0 | T10: =SUM(T11:T15) -> 0
A11: （1）重新计量设定受益计划变动额； | G11: =C11+D11-E11-F11 -> 0 | P11: =C11+H11+I11 -> 0 | Q11: =D11+J11+M11 -> 0 | S11: =F11+L11+O11 -> 0 | T11: =P11+Q11-R11-S11 -> 0
A12: （2）权益法下不能转损益的其他综合收益； | G12: =C12+D12-E12-F12 -> 0 | P12: =C12+H12+I12 -> 0 | Q12: =D12+J12+M12 -> 0 | S12: =F12+L12+O12 -> 0 | T12: =P12+Q12-R12-S12 -> 0
A13: （3）其他权益工具投资公允价值变动； | G13: =C13+D13-E13-F13 -> 0 | P13: =C13+H13+I13 -> 0 | Q13: =D13+J13+M13 -> 0 | S13: =F13+L13+O13 -> 0 | T13: =P13+Q13-R13-S13 -> 0
A14: （4）企业自身信用风险公允价值变动； | G14: =C14+D14-E14-F14 -> 0 | P14: =C14+H14+I14 -> 0 | Q14: =D14+J14+M14 -> 0 | S14: =F14+L14+O14 -> 0 | T14: =P14+Q14-R14-S14 -> 0
A15: … | G15: =C15+D15-E15-F15 -> 0 | P15: =C15+H15+I15 -> 0 | Q15: =D15+J15+M15 -> 0 | S15: =F15+L15+O15 -> 0 | T15: =P15+Q15-R15-S15 -> 0
A16: 2、以后将重分类进损益的其他综合收益 | C16: =SUM(C17:C26) -> 0 | D16: =SUM(D17:D26) -> 0 | E16: =SUM(E17:E26) -> 0 | F16: =SUM(F17:F26) -> 0 | G16: =SUM(G17:G26) -> 0 | H16: =SUM(H17:H26) -> 0 | I16: =SUM(I17:I26) -> 0 | J16: =SUM(J17:J26) -> 0 | ... T16: =SUM(T17:T26) -> 0
A17: （1）权益法下可转损益的其他综合收益； | G17: =C17+D17-E17-F17 -> 0 | P17: =C17+H17+I17 -> 0 | Q17: =D17+J17+M17 -> 0 | R17: =E17+K17+N17 -> 0 | S17: =F17+L17+O17 -> 0 | T17: =P17+Q17-R17-S17 -> 0
A18: （2）其他债权投资公允价值变动； | G18: =C18+D18-E18-F18 -> 0 | P18: =C18+H18+I18 -> 0 | Q18: =D18+J18+M18 -> 0 | R18: =E18+K18+N18 -> 0 | S18: =F18+L18+O18 -> 0 | T18: =P18+Q18-R18-S18 -> 0
A19: （3）金融资产重分类计入其他综合收益的金额； | G19: =C19+D19-E19-F19 -> 0 | P19: =C19+H19+I19 -> 0 | Q19: =D19+J19+M19 -> 0 | R19: =E19+K19+N19 -> 0 | S19: =F19+L19+O19 -> 0 | T19: =P19+Q19-R19-S19 -> 0
A20: （4）其他债权投资信用减值准备； | G20: =C20+D20-E20-F20 -> 0 | P20: =C20+H20+I20 -> 0 | Q20: =D20+J20+M20 -> 0 | R20: =E20+K20+N20 -> 0 | S20: =F20+L20+O20 -> 0 | T20: =P20+Q20-R20-S20 -> 0
A21: （5）现金流量套期储备； | G21: =C21+D21-E21-F21 -> 0 | P21: =C21+H21+I21 -> 0 | Q21: =D21+J21+M21 -> 0 | R21: =E21+K21+N21 -> 0 | S21: =F21+L21+O21 -> 0 | T21: =P21+Q21-R21-S21 -> 0
A22: （6）外币报表折算差额； | G22: =C22+D22-E22-F22 -> 0 | P22: =C22+H22+I22 -> 0 | Q22: =D22+J22+M22 -> 0 | R22: =E22+K22+N22 -> 0 | S22: =F22+L22+O22 -> 0 | T22: =P22+Q22-R22-S22 -> 0
A23: （7）自用房地产或作为存货的房地产转换为以公允价值计量的投资性房地产在转换日公允价值大于账面价值部分； | G23: =C23+D23-E23-F23 -> 0 | P23: =C23+H23+I23 -> 0 | Q23: =D23+J23+M23 -> 0 | R23: =E23+K23+N23 -> 0 | S23: =F23+L23+O23 -> 0 | T23: =P23+Q23-R23-S23 -> 0
A24: （8）多次交易分步处置子公司股权构成一揽子交易的，丧失控制权之前各次交易处置价款与对应净资产账面价值份额的差额； | G24: =C24+D24-E24-F24 -> 0 | P24: =C24+H24+I24 -> 0 | Q24: =D24+J24+M24 -> 0 | R24: =E24+K24+N24 -> 0 | S24: =F24+L24+O24 -> 0 | T24: =P24+Q24-R24-S24 -> 0
A25: … | G25: =C25+D25-E25-F25 -> 0 | P25: =C25+H25+I25 -> 0 | Q25: =D25+J25+M25 -> 0 | R25: =E25+K25+N25 -> 0 | S25: =F25+L25+O25 -> 0 | T25: =P25+Q25-R25-S25 -> 0
G26: =C26+D26-E26-F26 -> 0 | P26: =C26+H26+I26 -> 0 | Q26: =D26+J26+M26 -> 0 | R26: =E26+K26+N26 -> 0 | S26: =F26+L26+O26 -> 0 | T26: =P26+Q26-R26-S26 -> 0
A27: 合计 | C27: =C10+C16 -> 0 | D27: =D10+D16 -> 0 | E27: =E10+E16 -> 0 | F27: =F10+F16 -> 0 | G27: =G10+G16 -> 0 | H27: =H10+H16 -> 0 | I27: =I10+I16 -> 0 | J27: =J10+J16 -> 0 | ... T27: =T10+T16 -> 0
A28: 三、审计说明：
A31: 四、审计结论：

Sheet 调整分录汇总M9-3
A1: 致同会计师事务所
A2: 其他综合收益调整分录汇总表
A3: =底稿目录!A2 -> 被审计单位： | D3: =底稿目录!A4 -> 编制人： | F3: =底稿目录!A5 -> 编制日期： | I3: 索引号： | J3: =底稿目录!F9 -> M9-3
A4: =底稿目录!A3 -> 截止日：202X年12月31日 | D4: =底稿目录!A6 -> 复核人： | F4: =底稿目录!A7 -> 复核日期： | I4: 页 次：
A5: 调整事项说明 | B5: 类别（报表调整/账项调整/其他） | C5: 报表项目 | D5: 科目名称 | E5: 附注项目 | F5: …… | G5: 借方调整金额 | H5: 贷方调整金额 | I5: 索引 | J5: 备注
A24: 【注：本底稿适用于调整分录较多、较复杂的项目，且仅列示与本报表项目相关的审计调整。项目组可根据项目实际情况选择是否使用该底稿。】

Sheet 其他综合收益核对表M9-4
A1: 致同会计师事务所
A2: 其他综合收益核对表
A3: =底稿目录!A2 -> 被审计单位： | C3: =底稿目录!A4 -> 编制人： | F3: =底稿目录!A5 -> 编制日期： | H3: 索引号： | I3: =底稿目录!F10 -> M9-4
A4: =底稿目录!A3 -> 截止日：202X年12月31日 | C4: =底稿目录!A4 -> 编制人： | F4: =底稿目录!A7 -> 复核日期： | H4: 页 次：
A5: 一、审计目标:
A6: 1.所有应记录的其他综合收益的税后净额均已记录，所有应当包括在财务报表中的相关披露均已包括；
A7: 2.其他综合收益的税后净额以恰当的金额包括在财务报表中，与之相关的计价或分摊调整已恰当记录，相关披露已得到恰当计量和描述。
A8: 二、审计过程：
A9: 项目 | B9: 本期数 | F9: 对应科目 | H9: 核对 | I9: 索引号
B10: 未审数 | C10: 账项调整 | D10: 重分类调整 | E10: 审定数 | F10: 科目 | G10: 金额
A11: 其他综合收益税后净额：
A12: 1、不能重分类进损益的其他综合收益 | B12: =SUM(B13:B17) -> 0 | C12: =SUM(C13:C17) -> 0 | D12: =SUM(D13:D17) -> 0 | E12: =B12+C12+D12 -> 0 | G12: =SUM(G13:G17) -> 0 | H12: =E12=G12 -> TRUE
A13: （1）重新计量设定受益计划变动额 | E13: =B13+C13+D13 -> 0 | F13: 应付职工薪酬-设定受益计划义务 | H13: =E13=G13 -> TRUE
A14: （2）权益法下不能转损益的其他综合收益 | E14: =B14+C14+D14 -> 0 | F14: 长期股权投资-其他综合收益 | H14: =E14=G14 -> TRUE
A15: （3）其他权益工具投资公允价值变动 | E15: =B15+C15+D15 -> 0 | F15: 其他权益工具投资-公允价值变动 | H15: =E15=G15 -> TRUE
A16: （4）企业自身信用风险公允价值变动 | E16: =B16+C16+D16 -> 0 | F16: 交易性负债-公允价值变动 | H16: =E16=G16 -> TRUE
A17: …… | E17: =B17+C17+D17 -> 0 | H17: =E17=G17 -> TRUE
A18: 2、将重分类进损益的其他综合收益 | B18: =SUM(B19:B27) -> 0 | C18: =SUM(C19:C27) -> 0 | D18: =SUM(D19:D27) -> 0 | E18: =B18+C18+D18 -> 0 | G18: =SUM(G19:G27) -> 0 | H18: =E18=G18 -> TRUE
A19: （1）权益法下可转损益的其他综合收益 | E19: =B19+C19+D19 -> 0 | F19: 长期股权投资-其他综合收益 | H19: =E19=G19 -> TRUE
A20: （2）其他债权投资公允价值变动 | E20: =B20+C20+D20 -> 0 | F20: 其他债权投资-公允价值变动 | H20: =E20=G20 -> TRUE
A21: （3）金融资产重分类计入其他综合收益的金额 | E21: =B21+C21+D21 -> 0 | F21: 债权投资 | H21: =E21=G21 -> TRUE
A22: （4）其他债权投资信用减值准备 | E22: =B22+C22+D22 -> 0 | F22: 信用减值损失-其他权益工具投资 | H22: =E22=G22 -> TRUE
A23: （5）现金流量套期储备 | E23: =B23+C23+D23 -> 0 | F23: 套期工具 | H23: =E23=G23 -> TRUE
A24: （6）外币财务报表折算差额 | E24: =B24+C24+D24 -> 0 | H24: =E24=G24 -> TRUE
A25: （7）自用房地产或作为存货的房地产转换为以公允价值计量的投资性房地产在转换日公允价值大于账面价值部分 | H25: =E25=G25 -> TRUE
A26: （8）多次交易分步处置子公司股权构成一揽子交易的，丧失控制权之前各次交易处置价款与对应净资产账面价值份额的差额 | H26: =E26=G26 -> TRUE
A27: …… | E27: =B27+C27+D27 -> 0 | H27: =E27=G27 -> TRUE
A28: 合计 | B28: =SUM(B12,B18) -> 0 | C28: =SUM(C12,C18) -> 0 | D28: =SUM(D12,D18) -> 0 | E28: =SUM(E12,E18) -> 0 | G28: =SUM(G12,G18) -> 0 | H28: =E28=G28 -> TRUE
A29: 三、审计说明：
A32: 四、审计结论：

Sheet GT_Custom
A1: C1 | B1: Custom 1
A2: C2 | B2: Custom 2
A3: C3 | B3: Custom 3
A4: C4 | B4: Custom 4
A5: C5 | B5: Custom 5
A6: C6 | B6: Custom 6
A7: C7 | B7: Custom 7
A8: C8 | B8: Custom 8
