Workbook
Name _WPE_GuideTable1: 'B10-4-1 了解薪酬政策'!$A$6

Sheet 相关资源
B3: 相关资源 <AE3.3 了解被审计单位及其环境>（审计手册摘选，完全内容请参考审计手册原文） 项目组应当了解相关行业状况、法律环境和监管环境以及其他外部因素，包括财务报告编制基础。[ISA 315.11(a)][CSA 1211.14] 项目组应当了解被审计单位的性质，包括： a. 经营活动； b. 所有权和治理机构； c. 正在实施和计划实施的投资类型，包括对特殊目的实体的投资； d. 组织结构和筹资方式； 以使项目组了解预期在财务报表中反映的特定类别的交易、账户余额和披露。[ISA 315.11(b)] 项目组应当了解被审计单位对会计政策的选择和运用，包括变更会计政策的原因。项目组应当根据被审计单位的经营活动，评估其会计政策是否适当，与财务报告编制基础和相关行业运用的会计政策是否一致。 [ISA 315.11(c)][CSA 1211.14] 项目组应当了解被审计单位的目标、战略和可能导致重大错报风险的相关经营风险。[ISA 315.11(d)][CSA 1211.14] 项目组应当了解被审计单位对财务业绩的衡量和评价。 [ISA 315.11(e)][CSA 1211.14]
B5: 相关资源 <QRG 3 - 20 了解被审计单位 - 概览> <QRG 3 - 21 对被审计单位财务业绩的衡量和评价>

Sheet 底稿目录
A1: 底稿开列时，可先在以下单元格填写有关内容，以便其他底稿引用有关数据：
A2: 被审计单位：ABC公司 | D2: 序号 | E2: 内容 | F2: 索引号
A3: 编制人：张三 | D3: 1 | E3: 了解被审计单位及其所处环境和适用的财务报告编制基程序表 | F3: B10
A4: 编制日期：2025.X.X | D4: =D3+1 -> 2 | E4: 被审计单位组织结构、所有权结构和治理结构 | F4: B10-1
A5: 复核人：李四 | D5: =D4+1 -> 3 | E5: 了解被审计单位的业务模式 | F5: B10-2
A6: 复核日期：2025.X.X | D6: =D5+1 -> 4 | E6: 了解行业形势、法律环境、监管环境和其他外部因素 | F6: B10-3
A7: 会计期间：202X年度 | D7: =D6+1 -> 5 | E7: 法律监管附表 | F7: B10-3-1
D8: =D7+1 -> 6 | E8: 了解业绩衡量 | F8: B10-4
D9: =D8+1 -> 7 | E9: 了解薪酬政策 | F9: B10-4-1
D10: =D9+1 -> 8 | E10: 了解会计政策 | F10: B10-5
D11: =D10+1 -> 9 | E11: 了解收入 | F11: B10-5-1

Sheet B10 了解被审计单位及其所处环境和适用的财务报告编制基程序表
A1: 致同会计师事务所
A2: 了解被审计单位及其环境和适用的财务报告编制基础程序表
A3: =底稿目录!A2 -> 被审计单位：ABC公司 | C3: =底稿目录!A3 -> 编制人：张三 | D3: =底稿目录!A4 -> 编制日期：2025.X.X | G3: 索引号： | H3: B10
A4: =底稿目录!A7 -> 会计期间：202X年度 | C4: =底稿目录!A6 -> 复核日期：2025.X.X | D4: =底稿目录!A6 -> 复核日期：2025.X.X
A5: 序号 | B5: 程序 | E5: 是否适用 | F5: 执行人 | G5: 执行情况说明 | H5: 索引号
A6: 一 | B6: 通过检查相关资料（内部或外部）、获取的其他信息，实施分析程序以及询问相关人员（包括内部和外部）了解被审计单位及其环境和适用的财务报告编制基础：
A7: （一） | B7: 了解被审计单位及其环境所执行的主要手段 | H7: B11、B12、B13
A8: 1 | B8: 检查、观察和询问相关人员的记录
A9: 2 | B9: 对未审财务报表执行分析程序，计算主要财务报表比率，并解释异常变动
A10: （二） | B10: 了解被审计单位的组织结构、所有权结构和治理结构 | H10: B10-1 | I10: B16
A11: 1 | B11: 获取或编制被审计单位组织结构图，考虑被审计单位组织结构的复杂程度，适当可能导致存在风险因素。
A12: 2 | B12: 了解或编制被审计单位所有权机构，及所有者与其他成员或实体之间的关系，所有者、治理层、管理层之间的分离情况
A13: 3 | B13: 获取或编制被审计单位治理结构图，考虑是否可能表明内部控制体系存在缺陷。
A14: 4 | B14: 了解被审计单位信息技术环境的组织结构和复杂程度，了解服务机构；
A15: （1） | B15: 了解被审计单位是否在不同的业务中拥有多个旧版信息技术系统，以及这些系统是否可以很好地集成整合。 | H15: B22A-4
A16: （2） | B16: 收集或更新在“组织架构”工具中服务机构的信息，并记录： 服务机构名称 、服务内容、涉及的业务循环、与服务机构的其他关系 ； 检查服务合同，了解业务关系的性质，并核实已记录信息的准确性; 评价并记录被审计单位与服务机构的沟通情况。 | I16: B14
A17: （三） | B17: 了解被审计单位的被审计单位的业务模式，包括：
A18: 1 | B18: 了解被审计单位的筹融资活动。 | H18: B10-2
A19: 2 | B19: 了解被审计单位的目标、战略以及可能导致重大错报风险的相关经营风险。 | H19: B10-3
A20: 3 | B20: 了解不同业务模式下被审计单位对信息技术的使用和依赖程度。 | H20: B22A-4
A21: （四） | B21: 了解被审计单位行业状况、法律环境和监管环境以及其他外部因素 | H21: B10-4
A22: 1 | B22: 了解被审计单位所处的行业状况，包括： （1）所在行业的市场供求与竞争; （2）生产经营的季节性和周期性； （3）与被审计单位产品相关的生产技术； （4）能源供应与成本；
A23: 2 | B23: 了解被审计单位所处的法律环境及监管环境，包括： （1）受管制行业的法规框架，如与审慎监管相关的监管框架，包括相关披露； （2）对被审计单位经营活动产生重大影响的法律法规，如劳动法和相关法规； （3）税收相关法律法规； （4）目前对被审计单位开展经营活动产生影响的政府政策，如货币政策（包括外汇管制）； （5）财政政策、关税或贸易限制政策等； 6、影响行业和被审计单位经营活动的环保要求。
A24: 3 | B24: 了解被审计单位的其他外部因素，包括：总体经济情况、利率、融资的可获得性、通货膨胀水平或币值变动等
A25: （五） | B25: 了解评价被审计单位财务业绩的衡量标准，包括： | H25: B10-5
A26: 1 | B26: 关键业绩指标（财务或非财务的）、关键比率、趋势和经营统计数据。 | H26: B13
A27: 2 | B27: 同期财务业绩比较分析。
A28: 3 | B28: 预测、预算和差异分析。
A29: 4 | B29: 员工业绩考核与激励性报酬政策。
A30: 5 | B30: 被审计单位与竞争对手的业绩比较。
A31: 6 | B31: 外部机构提供的报告。 | H31: B11-3
A32: （六） | B32: 了解被审计单位适用的财务报告编制基础 | H32: B10-6
A33: 1 | B33: 了解被审计单位与适用的财务报告编制基础相关的财务报告实务，包括： （1）会计政策和行业特定惯例，包括特定行业财务报表中的相关交易类别、账户余额和披露（如银行业的贷款和投资、医药行业的研究与开发活动）； （2）收入确认； （3）金融工具以及相关信用损失的会计处理； （4）外币资产、负债与交易； （5）异常或复杂交易（包括在有争议或新兴领域的交易）的会计处理（如对加密货币的会计处理）
A34: 2 | B34: 了解被审计单位对会计政策的选择和运用（包括发生的变化以及变化的原因）: （1）被审计单位用于确认、计量和列报（包括披露）重大和异常交易的方法； （2）在缺乏权威性标准或共识的争议或新兴领域采用重要会计政策产生的影响； （3）环境变化，例如适用的财务报告编制基础的变化或税制改革可能导致被审计单位的会计政策变更； （4）新颁布的财务报告准则、法律法规，被审计单位采用的时间以及如何采用或遵守这些规定。
A35: 二 | B35: 基于上述了解汇总识别出的风险因素和控制缺陷。
A36: 1 | B36: 基于对上述了解，评价固有风险因素如何影响各项认定易于发生错报的可能性以及影响的程度。 | H36: B50-1
A37: 2 | B37: 基于对上述了解，汇总识别出的内部控制体系缺陷，并评价其影响程度。
A83: 是
A84: 否

Sheet B10-1被审计单位组织结构、所有权结构和治理结构
A1: 致 同 会 计 师 事 务 所
A2: 组织架构、所有权结构和治理结构
A3: =底稿目录!A2 -> 被审计单位：ABC公司 | C3: =底稿目录!A3 -> 编制人：张三 | E3: =底稿目录!A4 -> 编制日期：2025.X.X | G3: 索引号： | H3: B10-1
A4: =底稿目录!A7 -> 会计期间：202X年度 | C4: =底稿目录!A5 -> 复核人：李四 | E4: =底稿目录!A6 -> 复核日期：2025.X.X
A5: 编制说明： 在进行了解时，应考虑下列表格中列示的项目，但考虑内容不限于这些内容。在记录了解的内容时，如果涉及到多个项目，可以综合考虑并予以记录． | K5: 项目组可通过查询企业官网、查看公开文件（例如年报、招股说明书）、以前年度底稿（保持业务）、取得组织结构图和所有权结构图（如有）、询问被审计单位相关人员、查看会议纪要等了解被审计单位组织结构、所有权结构和治理结构
A6: 提示： 在记录了解的内容及评估的风险时，应注明访谈人员姓名、职位、检查文件名称，如相关内容来源其他工作底稿，则说明相关工作底稿（若有）索引，一般情况下B11 检查相关信息或文件记录程序表和B12 与相关人员访谈程序及记录中会涉及相关内容。
A7: 一、被审计单位-综合问题
A8: 企业类型 | B8: 有限责任公司 | C8: 是否有国外经营分部 | D8: √ | E8: 行业类型 | F8: 制造业
A9: 是否上市公司 | B9: √ | C9: 是否有内审部门 | D9: √ | E9: 地址
A10: 是否首年审计 | B10: × | C10: 是否有外部审计师加入审计团队 | D10: √ | E10: 电话
A11: 是否整合审计 | B11: √ | C11: 是否有重大的财务职能外包 | D11: × | E11: 联系人
A12: 是否存在子公司、分公司、分部、多地点经营等业务单元 | B12: √ | C12: 是否存在需披露的经营分部信息 | D12: √ | E12: 网址
A14: 二、组织结构 | B14: =IF(B12="√","请填写","不需要填写") -> 请填写
A15: 组成部分类型 | B15: 组成部分名称 | C15: 企业类型 | D15: 注册地址 | E15: 主营业务 | F15: 是否由本所审计
A20: 提示：通常来说，组织结构越复杂，越容易出现导致重大错报风险的可能性有所增加的因素。相关问题可能包括对商誉、合营企业、投资或特殊目的实体的会计处理是否恰当，以及财务报表是否已对这些事项作出充分披露
A21: 三、所有权结构（股东基本信息)
A22: 姓名/公司名称 | B22: 出资额 | C22: 持股比例 | D22: 投资性质 | E22: 是否同时为管理层或治理层
A23: A | E23: 请选择
A24: B | E24: 请选择
A25: C | E25: 请选择
A26: D | E26: 请选择
A27: E | E27: 请选择
A28: 提示：了解这些方面有助于注册会计师确定关联方交易是否已得到恰当识别和处理，并在财务报表中得到充分披露
A29: 四、治理结构
A30: 姓名 | B30: 出资额 | C30: 持股比例 | D30: 是否同时为管理层 | E30: 是否财务专家 | F30: 是否在组成部分任职 | G30: 是否批准财务报表 | H30: 是否下设专门机构，如审计委员会及其责任
A31: A | D31: 请选择 | E31: 请选择 | F31: 请选择
A32: B | D32: 请选择 | E32: 请选择 | F32: 请选择
A33: C | D33: 请选择 | E33: 请选择 | F33: 请选择
A34: D | D34: 请选择 | E34: 请选择 | F34: 请选择
A35: E | D35: 请选择 | E35: 请选择 | F35: 请选择
A37: 六、管理层基本信息
A38: 姓名 | B38: 职务 | C38: 持股比例 | D38: 是否财务经验 | E38: 是否同时为治理层
A39: A | D39: 请选择 | E39: 请选择
A40: B | D40: 请选择 | E40: 请选择
A41: C | D41: 请选择 | E41: 请选择
A42: D | D42: 请选择 | E42: 请选择
D43: 请选择 | E43: 请选择
A44: 七、内外部顾问基本信息
A45: 类别 | B45: 所在公司名称 | C45: 姓名 | D45: 电话 | E45: 电子邮件
A49: 八、内审部门基本信息 | B49: =IF(D9="√","请填写","不需要填写") -> 请填写
...

Sheet B10-2业务模式（被审计单位筹融资活动） (2)
A1: 致同会计师事务所
A2: 了解被审计单位的经营活动
A3: =底稿目录!A2 -> 被审计单位：ABC公司 | D3: =底稿目录!A3 -> 编制人：张三 | F3: =底稿目录!A4 -> 编制日期：2025.X.X | H3: 索引号： | K3: B10-2
A4: =底稿目录!A7 -> 会计期间：202X年度 | D4: =底稿目录!A5 -> 复核人：李四 | F4: =底稿目录!A6 -> 复核日期：2025.X.X | H4: 页 次：
A5: 编制说明：在进行了解时，应考虑下列表格中列示的项目，但考虑内容不限于这些内容。在记录了解的内容时，如果涉及到多个项目，可以综合考虑并予以记录．
A6: 提示：在记录了解的内容及评估的风险时，应注明被调查人姓名、职位、相关的信息来源及相关工作底稿（若有）索引。
A7: （一）经营活动
A8: 了解的项目 | G8: 了解的内容和评估的风险 | I8: 是否识别出风险因素 | J8: 描述识别出的风险因素 | K8: 索引号或信息来源
A9: 1.业务开展情况，如业务分部的设立情况、产品和服务的交付情况等。
A10: 2.联盟、合营与外包情况。
A11: 3.从事电子商务的情况，如是否通过互联网从事营销活动。
A12: 4.业务的地域分布情况。
A13: 5.重要供应商及对关键供应商的依赖程度。
A14: 6.雇员数量、薪酬水平。
A15: 7.劳动力供应、劳动法规对被审计单位的影响。
A16: 8.被审计单位为雇员缴纳社会保险的情况。
A17: 9.被审计单位重大的研究开发活动及其影响。
A18: 10.人员与生产、销售、研发工作的匹配程度。
A19: （二）投资活动
A20: 了解的项目 | G20: 了解的内容和评估的风险 | I20: 是否识别出风险因素 | J20: 描述识别出的风险因素 | K20: 索引号或信息来源
A21: 1.被审计单位的投资活动，如证券投资、债权投资、股权投资、其他投资及投资的处置情况。
A22: 2.被审计单位重大的资本性开支及计划情况。
A23: 3.被审计单位未纳入合并范围的投资。
A24: （三）筹资活动
A25: 了解的项目 | G25: 了解的内容和评估的风险 | I25: 是否识别出风险因素 | J25: 描述识别出的风险因素 | K25: 索引号或信息来源
A26: 1.被审计单位的筹资活动，如银行借款、关联方借款、经营租赁、融资租赁、票据贴现等。
A27: 2.筹资活动导致的抵押、质押等担保情况。
A28: 3.被审计单位的筹资合同中的限制性条款及其影响。
A29: 4.被审计单位的出资人与实际受益人是否一致。
A30: 【提示：根据《会计监管风险提示第6号——新三板挂牌公司审计》，为新三板挂牌公司提供的年报审计服务和为被审计单位申请挂牌提供的相关审计服务时，对被审计单位的性质性质，应关注包括是否存在特殊的业务模式、所有权和治理结构是否明晰、筹资和投资活动是否存在重大限制、是否存在超出被审计单位正常经营过程的重大关联方交易及资金占用情况等。
A31: 【提示：根据《会计监管风险提示第6号——新三板挂牌公司审计》，为新三板挂牌公司提供的年报审计服务和为被审计单位申请挂牌提供的相关审计服务时，在了解经营风险时，应关注成立时间较短、处于发展或成长期的被审计单位，可能存在开发新产品或提供新服务失败或者业务扩张失败等导致的经营风险。
A32: 【被审计单位性质方面的风险因素举例：以下是可能表明被审计单位性质方面存在重大错报风险的情况和事项的示例。这些情况和事项涵盖范围广泛，然而，并非所有的情况和事项都与每项审计业务相关，下面所列情况和事项也不一定完整。 （1）持续经营和资产流动性出现问题，包括重要客户流失； （2）供应链发生变化； （3）开辟新的经营场所； （4）被审计单位发生重大收购、重组或其他异常的事项； （5）计划处置产品线或业务线，拟出售分支机构或业务分部； （6）存在复杂的联营或合资企业； （7）从事重大的关联方交易； （8）发生大额非常规或非系统性交易（包括公司间的交易和在期末发生大量收入的交易）； （9）安装新的重要的IT 系统。】

Sheet B10-2 了解被审计单位的业务模式
A1: 致同会计师事务所
A2: 了解被审计单位业务模式
A3: =底稿目录!A2 -> 被审计单位：ABC公司 | D3: =底稿目录!A3 -> 编制人：张三 | F3: =底稿目录!A4 -> 编制日期：2025.X.X | J3: 索引号： | K3: B10-2
A4: =底稿目录!A7 -> 会计期间：202X年度 | D4: =底稿目录!A5 -> 复核人：李四 | F4: =底稿目录!A6 -> 复核日期：2025.X.X
A5: 编制说明：在进行了解时，应考虑下列表格中列示的项目，但考虑内容不限于这些内容。在记录了解的内容时，如果涉及到多个项目，可以综合考虑并予以记录．
A6: 提示： 在记录了解的内容及评估的风险时，应注明访谈人员姓名、职位、检查文件名称，如相关内容来源其他工作底稿，则说明相关工作底稿（若有）索引，一般情况下B11检查相关信息或文件记录程序表和B12与相关人员访谈程序及记录中会涉及相关内容。
A7: 一、了解事项
A8: 了解的项目 | G8: 了解的内容 | I8: 是否识别出风险因素 | J8: 描述识别出的风险因素 | K8: 索引号或信息来源
A9: 1.行业发展，例如，缺乏足以应对行业变化的人力资源和业务专长；
A10: 2.开发新产品或提供新服务，这可能导致被审计单位的产品责任增加；
A11: 3.被审计单位的业务扩张，被审计单位对市场需求的估计可能不准确
A12: 4.新的会计政策要求，被审计单位可能对其未完全执行或执行不当；
A13: 5.本期及未来的融资条件，例如被审计单位由于无法满足融资条件而失去融资机会；
A14: 6.信息技术的运用，例如，新的信息技术系统的实施将影响经营和财务报告；
A15: 7.信息技术的运用，例如，新的信息技术系统的实施将影响经营和财务报告；
A16: 8.实施战略的影响，特别是由此产生的需要运用新的会计政策要求的影响；
A17: 二、了解的活动
A18: （一）经营活动
A19: 了解的项目 | G19: 了解的内容 | I19: 是否识别出风险因素 | J19: 描述识别出的风险因素 | K19: 索引号或信息来源
A20: 1.业务开展情况，如生产阶段与生产方法，易受环境风险影响的活动。
A21: 2.收入来源、产品或服务以及市场的性质（包括电子商务，如网上销售和营销活动）；
A22: 3.联盟、合营与外包情况。
A23: 4.地区分布和行业细分
A24: 5.生产设施、仓库和办公室的地理位置
A25: 6.存货存放地点和数量
A26: 7.关键客户及对重要客户的依赖程度
A27: 8.重要供应商及对关键供应商的依赖程度。
A28: 9.劳动用工安排（包括是否存在退休金和其他退休福利、股票期权或激励性奖金安排以及与劳动用工事项相关的政府法规）；
A29: 10.研究与开发活动及其支出。
A30: 11.关联方交易。
A31: （二）投资活动
A32: 了解的项目 | G32: 了解的内容 | I32: 是否识别出风险因素 | J32: 描述识别出的风险因素 | K32: 索引号或信息来源
A33: 1.计划实施或近期已实施的并购或资产处置。
A34: 2.证券与贷款的投资和处置。
A35: 3.资本性投资活动
A36: 4.未纳入合并范围的实体的投资，包括非控制合伙企业、合营企业和非控制特殊目的实体。
A37: （三）筹资活动
A38: 了解的项目 | G38: 了解的内容 | I38: 是否识别出风险因素 | J38: 描述识别出的风险因素 | K38: 索引号或信息来源
A39: 1.主要子公司和联营企业（无论是否纳入合并范围）的所有权结构；
A40: 2.债务结构和相关条款，包括资产负债表外融资和租赁安排。
...

Sheet B10-3了解行业形势、法律环境、监管环境和其他外部因素
A1: 致同会计师事务所
A2: 了解被审计单位行业形势、法律环境、监管环境和其他外部因素
A3: =底稿目录!A2 -> 被审计单位：ABC公司 | D3: =底稿目录!A3 -> 编制人：张三 | F3: =底稿目录!A4 -> 编制日期：2025.X.X | I3: 索引号： | J3: B10-3
A4: =底稿目录!A7 -> 会计期间：202X年度 | D4: =底稿目录!A5 -> 复核人：李四 | F4: =底稿目录!A6 -> 复核日期：2025.X.X
A5: 编制说明：在进行了解时，应考虑下列表格中列示的项目，但考虑内容不限于这些内容。在记录了解的内容时，如果涉及到多个项目，可以综合考虑并予以记录．
A6: 提示： 在记录了解的内容及评估的风险时，应注明访谈人员姓名、职位、检查文件名称，如相关内容来源其他工作底稿，则说明相关工作底稿（若有）索引，一般情况下B11 检查相关信息或文件记录程序表和B12 与相关人员访谈程序及记录中会涉及相关内容。
A7: 一、行业状况、法律环境与监管环境以及其他外部因素
A8: （一）行业状况
A9: 了解的项目 | G9: 了解的内容 | H9: 是否识别出风险因素 | I9: 描述识别出的风险因素 | J9: 索引号或信息来源
A10: 1.行业的总体发展趋势（如起步、快速增长、成熟、停滞、萎缩）。如果行业发展处于停滞及萎缩阶段，应说明对被审计单位的影响。
A11: 2.行业的竞争情况。被审计单位在行业中所处的地位以及在行业中有无竞争优势。
A12: 3.行业是否受经济周期的影响？影响程度如何？如果行业受经济周期的影响程度较大，应说明对被审计单位的影响。
A13: 4．行业生产经营和销售是否受季节影响？如果受季节影响，每年的销售旺季和淡季是什么时间？对业务影响程度如何？是否会导致重大风险？
A14: 5．行业是否受特定生产技术的影响？如是，应具体说明对被审计单位的影响。
A15: 6．行业是否对能源有较高的依赖程度？如是，能源消耗在成本中所占比重是多少？能源价格变化对被审计单位成本的影响如何？
A16: 7．行业是否有特定的关键指标？如有，被审计单位的关键指标是否与行业的平均水平存在显著差异？
A17: 【提示：根据《会计监管风险提示第6号——新三板挂牌公司审计》，为新三板挂牌公司提供的年报审计服务和为被审计单位申请挂牌提供的相关审计服务时，了解相关行业状况和监管环境时，对属于新兴高新技术行业的被审计单位，除了需要了解行业的基本情况和发展现状以外，还应重点关注行业的稳定性、发展趋势、竞争程度和特有风险（如政策风险等）。】
A18: （二）法律环境及监管环境
A19: 了解的项目 | G19: 了解的内容 | H19: 是否识别出风险因素 | I19: 描述识别出的风险因素 | J19: 索引号或 信息来源
A20: 1.受管制行业的法规框架，如与审慎监管相关的监管框架，包括相关披露
A21: 2.对被审计单位经营活动产生重大影响的法律法规，如劳动法和相关法规
A22: 3.影响行业和被审计单位经营活动的环保要求
A23: 4.目前对被审计单位开展经营活动产生影响的政府政策，如货币政策、财政政策、关税和贸易限制等？
A24: 5.被审计单位所涉及的主要税种有哪些？税率如何？
A25: 6.被审计单位是否享有税收优惠政策？如是，说明具体的税收优惠政策，并考虑相关的风险。
A26: 7.税务部门、行业主管部门等有关部门近期是否对被审计单位进行检查？如是，说明检查结果，并考虑相关的风险。
A28: （三）其他外部因素
A29: 了解的项目 | G29: 了解的内容 | H29: 是否识别出风险因素 | I29: 描述识别出的风险因素 | J29: 索引号或 信息来源
A30: 1.宏观经济景气度对被审计单位所处行业及其经营活动产生的重大影响。
A31: 2.当前的利率水平对被审计单位的经营活动、投资活动及筹资活动产生的重大影响。
A32: 3.当期的通货膨胀水平对被审计单位的销售和采购价格产生的影响。
A33: 4.汇率波动对被审计单位生产经营的影响。
A34: 【被审计单位法律及监管环境方面的风险因素举例：以下是可能表明被审计单位法律及监管环境方面存在重大错报风险的情况和事项的示例。这些情况和事项涵盖范围广泛，然而，并非所有的情况和事项都与每项审计业务相关，下面所列情况和事项也不一定完整。 （1）在经济不稳定（如货币发生重大贬值或经济发生严重通货膨胀）的国家或地区开展业务； （2）在高度波动的市场开展业务（如期货交易）； （3）在高度复杂的监管环境中开展业务； （4）被审计单位经营所处的行业发生变化； （5）经营活动或财务业绩受到监管机构或政府机构的调查； （6）控制环境无效或缺乏职责分离； （7）由于大量企业倒闭，行业呈下降趋势。】

Sheet B10-3-1 法律监管附表
A1: 致同会计师事务所
A2: 法律环境与监管环境附表
A3: =底稿目录!A2 -> 被审计单位：ABC公司 | D3: =底稿目录!A3 -> 编制人：张三 | F3: =底稿目录!A4 -> 编制日期：2025.X.X | G3: 索引号 ： B10-4-1 | H3: 其他了解内容的附表使用本表头，并修改了解的内容标题，索引号顺延。
A4: =底稿目录!A7 -> 会计期间：202X年度 | D4: =底稿目录!A5 -> 复核人：李四 | F4: =底稿目录!A6 -> 复核日期：2025.X.X
A5: 主要适用的准则、制度、法规、行业惯例名称 | C5: 最后一次修改日期或颁布日期 | E5: 影响本公司的主要条款内容概述 | F5: 具体影响情况（有利或不利影响）描述 | G5: 可能产生的风险
A6: 《关于调整煤炭生产安全费用提取标准、加强煤炭生产安全费用使用管理与监督的通知》(财建[2005]168号) | C6: 38450 | E6: 调整安全费用提取标准：45户重点监控煤炭生产企业吨煤不低于15元 | F6: 公司属于45户名单内的单位，2005年5月开始提高安全费计提比例为15元/吨 | G6: 吨煤成本增加，公司利润压力增大
A12: 填表说明：
A13: 1、查阅相关资料或向被审计单位了解其适用的主要会计准则、行业惯例、法律法规列示其名称
A14: 2、关注其是否近期被修改
A15: 3、关注影响公司的关键条款并简述其内容
A16: 4、分析说明关键条款对公司的相关影响情况
A17: 5、如果公司为简单的小企业没有特殊相关的法规、制度则直接在前面的了解表中描述即可，无需单独填列此表
A19: 请重点关注：
A20: 1、该行业的行政监管要求变化（如：产品质量、销售业务、金融业务等）
A21: 2、该行业的环保监管要求变化
A22: 3、其他特殊监管要求以及对公司影响重大的监管要求
B33: 了解被审计单位与适用的财务报告编制基础相关的财务报告实务，包括： 1、会计政策和行业特定惯例，包括特定行业财务报表中的相关交易类别、账户余额和披露（如银行业的贷款和投资、医药行业的研究与开发活动）； 2、收入确认； 3、金融工具以及相关信用损失的会计处理； 4、外币资产、负债与交易； 5、异常或复杂交易（包括在有争议或新兴领域的交易）的会计处理（如对加密货币的会计处理）

Sheet B10-4 了解业绩衡量
A1: 致同会计师事务所
A2: 了解被审计单位的财务业绩的衡量和评价
A3: =底稿目录!A2 -> 被审计单位：ABC公司 | C3: =底稿目录!A3 -> 编制人：张三 | E3: =底稿目录!A4 -> 编制日期：2025.X.X | G3: 索引号： | H3: B10-4
A4: =底稿目录!A7 -> 会计期间：202X年度 | C4: =底稿目录!A5 -> 复核人：李四 | E4: =底稿目录!A6 -> 复核日期：2025.X.X
A6: 一、了解的内容（下列内容系提示，根据客户实际情况及了解的内容增加修改，可分项纪录或汇总纪录） | H6: 索引号
A7: (一)关键业绩指标（财务或非财务的）、关键比率、趋势和经营统计数据
A8: 了解的内容
A10: (二)同期财务业绩比较分析 | H10: B13
A13: (三)预算、预测、差异分析，分部信息与分部、部门或其他不同层次的业绩报告
A14: 了解的内容
A16: (四)员工业绩考核与激励性报酬政策
A17: 了解的内容
A19: (五)与竞争对手的业绩比较
A20: 了解的内容
A22: (六)外部机构提出的报告
A23: 例如：外部分析师报告、信用评级机构的报告，这些报告通常可以从被审计单位获取；
A24: 了解的内容
A26: (七)对小型被审计单位的特殊考虑
A27: 例如：小型被审计单位通常没有正式的财务业绩衡量和评价程序，管理层往往依据特定关键指标评价财务业绩和采取适当行动，注册会计师应当了解管理层使用的关键指标；若询问结果表明被审计单位不存在业绩衡量和评价，则尚未发现和更正的错报风险可能增加
A28: 了解的内容
A31: 二、汇总识别出的风险因素 | H31: B50-1
A34: 【被审计单位的财务业绩的衡量和评价方面的风险因素举例：以下是可能表明被审计单位的财务业绩的衡量和评价方面存在重大错报风险的情况和事项的示例。这些情况和事项涵盖范围广泛，然而，并非所有的情况和事项都与每项审计业务相关，下面所列情况和事项也不一定完整。 （1）安装新的与财务报告有关的重大信息技术系统； （2）以往发生的错报或错误，或者在本期期末出现重大会计调整； （3）按照管理层特定意图记录的交易（如债务重组、资产出售和交易性债券的分类）。】 【对于被审计单位财务业绩指标的具体考虑因素，可参考致同审计手册QRG3-21的相关内容。】

Sheet B10-4-1 了解薪酬政策
A1: 致同会计师事务所
A2: 了解薪酬政策
A3: =底稿目录!A2 -> 被审计单位：ABC公司 | D3: =底稿目录!A3 -> 编制人：张三 | G3: =底稿目录!A4 -> 编制日期：2025.X.X | J3: 索引号： | K3: B10-4-1
A4: =底稿目录!A7 -> 会计期间：202X年度 | D4: =底稿目录!A5 -> 复核人：李四 | G4: =底稿目录!A6 -> 复核日期：2025.X.X
A5: 一、询问：
A6: 被询问人姓名： | E6: 职务： | I6: 询问日期：
A7: 1.激励性方案：
A10: 2.变更或调整
A13: 3.特别奖金
A16: 二、检查文件或记录
A17: 文件名称 | C17: 文件编号 | E17: 主要内容 | K17: 索引号
A24: 编制说明：
A25: 1．在了解高层管理人员的薪酬政策时，项目组了解的内容包括：
A26: ·激励性方案
A27: ·变更或调整
A28: ·特别奖金
A29: 2．项目组可以通过询问或检查文件记录等方式获取了解。
B33: 了解被审计单位与适用的财务报告编制基础相关的财务报告实务，包括： 1、会计政策和行业特定惯例，包括特定行业财务报表中的相关交易类别、账户余额和披露（如银行业的贷款和投资、医药行业的研究与开发活动）； 2、收入确认； 3、金融工具以及相关信用损失的会计处理； 4、外币资产、负债与交易； 5、异常或复杂交易（包括在有争议或新兴领域的交易）的会计处理（如对加密货币的会计处理）

Sheet B10-5 了解会计政策
A1: 致 同 会 计 师 事 务 所
A2: 了解被审计单位对会计政策的选择和运用
A3: =底稿目录!A2 -> 被审计单位：ABC公司 | F3: =底稿目录!A3 -> 编制人：张三 | J3: =底稿目录!A4 -> 编制日期：2025.X.X | L3: 索引号： | M3: B10-5
A4: =底稿目录!A7 -> 会计期间：202X年度 | F4: =底稿目录!A5 -> 复核人：李四 | J4: =底稿目录!A6 -> 复核日期：2025.X.X
A6: 一、被审计单位选择和运用的会计政策
B7: 重要的会计政策 | F7: 被审计单位选择和 运用的会计政策 | J7: 对会计政策选择和 运用的评价
B9: 发出存货成本的计量
B10: 长期股权投资的后续计量
B11: 固定资产的初始计量
B12: 无形资产的确定
B13: 非货币性资产交换的计量
B14: 收入的确认
B15: 借款费用的处理
B16: 合并政策
B17: ……
A19: 二、会计政策变更的情况
B20: 原会计政策 | D20: 变更后会计政策 | F20: 变更日期 | H20: 变更原因 | J20: 对变更的处理（调整、列报等） 对变更的评价 | L20: 对变更的评价
A26: 三、对重大和异常交易的会计处理方法
A36: 四、对缺乏权威性标准或共识的争议或新兴领域采用重要会计政策
A45: 五、新颁布的会计准则、法律法规，以及被审计单位何时采用、如何采用这些规定。
A55: 六、披露
B57: 例如：  被审计单位是否按照适用的财务报告编制基础对会计政策的选择和运用进行了恰当的披露
A65: 七、汇总识别出风险因素
B74: 【被审计单位对会计政策的选择和运用方面的风险因素举例：以下是可能表明被审计单位对会计政策的选择和运用方面存在重大错报风险的情况和事项的示例。这些情况和事项涵盖范围广泛，然而，并非所有的情况和事项都与每项审计业务相关，下面所列情况和事项也不一定完整。 （1）缺乏具备会计和财务报告技能的员工； （2）采用新的会计准则（例如与收入确认相关的新的复杂的会计准则）； （3）涉及复杂过程的会计计量； （4）涉及重大计量不确定性（包括会计估计）的事项或交易； （5）存在未决诉讼和或有负债（如售后质量保证、财务担保和环境补救）。】
B75: 编制说明：
B76: 1、如果为首次承接业务，建议获取管理层编制的重要会计政策和会计估计说明，并加盖公司印鉴；
B77: 2、如果为连续审计业务，建议将上年度财务报表附注中有关重要会计政策和会计估计的相关内容作为底稿附件，如本年度发生会计政策或会计估计变更，应取得相关批准文件。

Sheet B10-5-1 了解收入
A1: 致 同 会 计 师 事 务 所
A2: 了解收入
A3: =底稿目录!A2 -> 被审计单位：ABC公司 | F3: =底稿目录!A3 -> 编制人：张三 | H3: =底稿目录!A4 -> 编制日期：2025.X.X | K3: 索引号： | L3: B10-5-1
A4: =底稿目录!A7 -> 会计期间：202X年度 | F4: =底稿目录!A5 -> 复核人：李四 | H4: =底稿目录!A6 -> 复核日期：2025.X.X
A5: 序号 | B5: 收入来源 | C5: 收入占比 | D5: 简单描述收入的来源和性质 | E5: 客户类型 | F5: 收入销售模式 | H5: 收入确认政策 | J5: 收入确认依据 | K5: 是否涉及贸易业务 | L5: 非经常性或特殊的会计处理方法（如有）
F6: 直销 | G6: 经销 | H6: 时段法（投入法/产出法） | I6: 时点法
A7: 1 | B7: 产品销售收入 | C7: 0.7 | D7: 产品销售收入主要来源于销售主要产品A、B的收入 | E7: 销售对象主要为众多的小客户/少量的大客户
A8: 2 | B8: 租金收入 | C8: 0.3 | D8: 来源于出租公司位于XXX地的房屋收入。
A9: 3
A10: 4
A11: 5
