Workbook

Sheet 底稿目录
A1: 底稿开列时，可先在以下单元格填写有关内容，以便其他底稿引用有关数据：
A2: 被审计单位：ABC有限公司
A3: 会计期间：202X年度 | D3: 序号 | E3: 内容 | F3: 索引号
A4: 评价基准日：202X年X月X日 | D4: 1 | E4: 检查相关信息程序表 | F4: B11
A5: 编制人：张XX | D5: =D4+1 -> 2 | E5: 股东大会、董事会等会议记录的摘录 | F5: B11-1
A6: 编制日期：2025-X-X | D6: =D5+1 -> 3 | E6: 评价企业内部控制评价报告 | F6: B11-2
A7: 复核人：李XX | D7: =D6+1 -> 4 | E7: 自我评价报告参考格式
A8: 复核日期：2025-X-X | D8: =D7+1 -> 5 | E8: 被审计单位的公开信息记录 | F8: B11-3

Sheet B11检查相关信息程序表
A1: 致同会计师事务所
A2: 检查相关信息或文件记录程序表
A3: =底稿目录!A2 -> 被审计单位：ABC有限公司 | C3: =底稿目录!A5 -> 编制人：张XX | D3: =底稿目录!A6 -> 编制日期：2025-X-X | G3: 索引号： | H3: B11
A4: =底稿目录!A3 -> 会计期间：202X年度 | C4: =底稿目录!A7 -> 复核人：李XX | D4: =底稿目录!A8 -> 复核日期：2025-X-X | G4: 页 次：
A5: 序号 | B5: 程序 | E5: 是否适用 | F5: 执行人 | G5: 执行情况说明 | H5: 索引号
A6: 一 | B6: 阅读过去两年已审计财务报表、内部控制报告、监管机构报告和提交的其他文件。（适用于首次审计）
A7: 二 | B7: 获取对执行分析性复核和询问程序有帮助的管理层报告。（适用于首次审计）
A8: 三 | B8: 获取并查阅：（适用于内部控制审计）
A9: 1 | B9: 管理层有关内部控制的文件（如内部控制制度或手册等。
A10: 2 | B10: 与内部控制有关的内审报告（以及企业内部控制自我评价报告等） ，评价自我评价报告。 | H10: B11-2
A11: 3 | B11: 关于重要缺陷和重大缺陷的报告 。
A12: 4 | B12: 监管机构对企业内部控制的报告，如有 。
A13: 四 | B13: 查阅上年报告，包括财务报表和管理建议书。
A14: 五 | B14: 与向该客户提供其他服务的事务所内的其他人员（如咨询或税务）讨论影响审计的事项，并与他们讨论重点关注问题。
A15: 六 | B15: 查看以前年度和本年度档案资料中的背景资料，并考虑可能影响审计的重要事项。
A16: 七 | B16: 确定以前年度所有调整分录是否已入账。
A17: 八 | B17: 查阅政府和监管机构发布的审计和会计的相关法规以及事务所技术提示。
A18: 九 | B18: 查阅股东会、董事会、审计委员会和其他委员会的会议记录： | H18: B11-1
A19: 1 | B19: 了解所有商业和非商业活动。
A20: 2 | B20: 识别此前未披露的关联方。
A21: 十 | B21: 查阅该企业与其外部法律顾问之间的信函。
A22: 十一 | B22: 查阅该企业与其外部法律顾问之间的信函。 | H22: B11-3
A23: 1 | B23: 公开财务报告信息
A24: 2 | B24: 对分析师和投资者的解释说明
A25: 3 | B25: 分析师报告
A26: 4 | B26: 业绩公告或业绩发布会记录
A27: 5 | B27: 获得与投资者或评级机构的其他会议记录
A28: 十二 | B28: 汇总识别出的风险因素。 | H28: B50-1
A57: 是
A58: 否

Sheet B11-1股东大会、董事会等会议记录的摘录
A1: 致同会计师事务所
A2: 股东大会、董事会等会议记录的摘录
A3: =底稿目录!A2 -> 被审计单位：ABC有限公司 | D3: =底稿目录!A5 -> 编制人：张XX | G3: =底稿目录!A6 -> 编制日期：2025-X-X | J3: 索引号： | K3: B11-1
A4: =底稿目录!A3 -> 会计期间：202X年度 | D4: =底稿目录!A8 -> 复核日期：2025-X-X | G4: =底稿目录!A8 -> 复核日期：2025-X-X | J4: 页 次：
A5: 程序：
A6: 查阅股东会、董事会、审计委员会和其他委员会的会议记录：
A7: （1）了解所有商业和非商业活动
A8: （2）识别此前未披露的关联方。
A10: 工作记录：
A11: 请选择
A13: 一、股东会
A14: 会议编号 | B14: 会议日期 | C14: 会议讨论的可能影响财务报表的重要事项 | J14: 是否存在未披露的关联方 | K14: 说明
A19: 二、董事会
A20: 会议编号 | B20: 会议日期 | C20: 会议讨论的可能影响财务报表的重要事项 | J20: 是否存在未披露的关联方 | K20: 说明
A25: 三、审计委员会
A26: 会议编号 | B26: 会议日期 | C26: 会议讨论的可能影响财务报表的重要事项 | J26: 是否存在未披露的关联方 | K26: 说明
A31: 四、其他委员会
A32: 会议编号 | B32: 会议日期 | C32: 会议讨论的可能影响财务报表的重要事项 | J32: 是否存在未披露的关联方 | K32: 说明
A37: 编制说明：
A38: 项目组需要阅读股东会、董事会、审计委员会和其他委员会的会议记录，以了解所有商业和非商业活动，识别此前未披露的关联方。
A39: 项目组需要记录会议讨论的、可能影响到财务报表的重要事项。

Sheet B11-2评价企业内部控制评价报告
A1: 致同会计师事务所
A2: 评价企业内部控制评价报告及涉及内部控制的其他报告
A3: =底稿目录!A2 -> 被审计单位：ABC有限公司 | B3: =底稿目录!A5 -> 编制人：张XX | C3: =底稿目录!A6 -> 编制日期：2025-X-X | D3: 索引号： | E3: B11-2
A4: =底稿目录!A4 -> 评价基准日：202X年X月X日 | B4: =底稿目录!A7 -> 复核人：李XX | C4: =底稿目录!A8 -> 复核日期：2025-X-X | D4: 页次：
A5: 内部控制评价报告应包含的内容 | D5: 是否包含 | E5: 备 注
A6: 明确内部控制评价报告的基准日 | E6: 年度内部控制评价报告的基准日为12月31日。
A7: 公司董事会关于建立健全和有效实施财务报告内部控制是公司董事会的责任，并就公司财务报告内部控制评价报告真实性作出的声明。 | E7: 董事会全体成员保证本报告内容真实、准确和完整，没有虚假记载、误导性陈述或者重大遗漏。
A8: 内部控制评价工作的总体情况。
A9: 内部控制评价的依据。 | E9: 《企业内部控制基本规范》、《企业内部控制应用指引》、《企业内部控制评价指引》
A10: 内部控制评价的范围。
A11: 内部控制评价的程序和方法。
A12: 内部控制缺陷及其认定情况。
A13: 内部控制缺陷的整改情况及重大缺陷拟采取的整改措施。
A14: 对上一年度内部控制缺陷的整改情况（如适用）
A15: 公司董事会对评价基准日财务报告内部控制有效性的自我评价结论。
A16: 在财务报告内部控制自我评价过程中关注到的非财务报告内部控制重大缺陷情况。
A17: 董事长签名、公司盖章。 | E17: 建立健全和有效实施财务报告内部控制是公司董事会的责任。
A19: 企业涉及内部控制的内部审计报告或类似报告所列控制缺陷 （缺陷类型及评价为缺陷的原因） | D19: 评价报告中指出的控制缺陷 | E19: 对内部控制审计的影响
A27: 说明：
A28: 根据《企业内部控制审计指引》的规定，注册会计师无需对企业内部控制评价报告发表意见。在内部控制审计中，注册会计师对企业内部控制评价开展的工作主要包括：
A29: 1）注册会计师应当对企业内部控制自我评价工作进行评估，判断是否利用企业内部审计人员、内部控制评价人员和其他相关人员的工作以及可利用的程度，相应减少可能本应由注册会计师执行的工作；（底稿参见B11-2，如内控评价人员与内审人员相同，完成-了解和利用内部审计工作B20/C27）
A30: 2）注册会计师应当识别、了解和测试对内部控制有效性具有重要影响的企业层面控制。企业内部控制自我评价，是企业层面控制的重要组成部分，与控制环境、对控制的监督这两项要素相关，注册会计师应将包括在企业层面控制的范围进行考虑。
A31: 3）在形成审计意见时，注册会计师应当查阅从各种来源获取的审计证据，包括企业本年度涉及内部控制的内部审计报告或类似报告，并评价这些报告中指出的控制缺陷（底稿参见B11-2）
A32: 《上市公司实施企业内部控制规范体系监管问题解答》（2011年第1期，总第1期）
A33: 公开发行证券的公司在年度报告中应披露的财务报告内部控制评价报告应包括以下内容：
A34: （一）公司董事会关于建立健全和有效实施财务报告内部控制是公司董事会的责任，并就公司财务报告内部控制评价报告真实性作出的声明。
A35: （二）财务报告内部控制评价的依据。
A36: （三）根据自我评价情况，认定于评价基准日存在的财务报告内部控制重大缺陷情况。
A37: （四）对发现的重大缺陷已采取或拟采取的整改措施的说明。
A38: （五）公司董事会对评价基准日财务报告内部控制有效性的自我评价结论。
... A53: 企业应当以12月31日作为年度内部控制评价报告的基准日。
A56: 具体内容 | E56: 涉及法规
A57: （一）董事会对内部控制报告真实性的声明。 | E57: 《评价指引》
A58: （一）公司董事会关于建立健全和有效实施财务报告内部控制是公司董事会的责任，并就公司财务报告内部控制评价报告真实性作出的声明。 | E58: 《监管问题解答》（2011年第1期，总第1期）
A59: （二）内部控制评价工作的总体情况。 | E59: 《评价指引》
A60: （一）对照本指引及有关规定，说明公司内部控制制度是否建立健全和有效运行，是否存在缺陷。 | E60: 《深交所主板上市公司规范运作指引》2010-9-1
A61: （二）说明本指引重点关注的控制活动的自查和评估情况。
A62: （一）内控制度是否建立健全；（二）内控制度是否有效实施；（三）内部控制检查监督工作的情况；（五）对本年度内部控制检查监督工作计划完成情况的评价。 | E62: 《上交所上市公司内部控制指引》2006-7-1
A63: （三）内部控制评价的依据。 | E63: 《评价指引》
A64: （二）财务报告内部控制评价的依据。 | E64: 《监管问题解答》（2011年第1期，总第1期）
...

Sheet 自我评价报告参考格式
A1: 被审计单位：ABC有限公司
A3: xx公司全体股东：
A4: 根据《企业内部控制基本规范》及其配套指引的规定和要求，结合本公司(以下简称公司)内部控制制度和评价办法，在内部控制日常监督和专项监督的基础上，我们对公司内部控制的有效性进行了自我评价。
A5: 一、董事会声明
A6: 公司董事会及全体董事保证本报告内容不存在任何虚假记载、误导性陈述或重大遗漏，并对报告内容的真实性、准确性和完整性承担个别及连带责任。
A7: 建立健全并有效实施内部控制是公司董事会的责任；监事会对董事会建立与实施内部控制进行监督；经理层负责组织领导公司内部控制的日常运行。
A8: 公司内部控制的目标是：[一般包括合理保证经营合法合规、资产安全、财务报告及相关信息真实完整，提高经营效率和效果，促进实现发展战略]。由于内部控制存在固有局限性，故仅能对实现上述目标提供合理保证。
A9: 二、内部控制评价工作的总体情况
A10: 公司董事会授权内部审计机构[或其他专门机构]负责内部控制评价的具体组织实施工作，对纳入评价范围的高风险领域和单位进行评价[描述评价工作的组织领导体制，一般包括评价工作组织结构图、主要负责人及汇报途径等]。
A11: 公司[是/否]聘请了专业机构[中介机构名称]提供内部控制咨询服务；公司[是/否]聘请了专业机构[中介机构名称]协助开展内部控制评价工作；公司[是/否]聘请会计师事务所[会计师事务所名称]对公司内部控制进行独立审计。
A12: 三、内部控制评价的范围
A13: 内部控制评价的范围涵盖了公司及其所属单位的主要业务和事项[列明评价范围占公司总资产比例或占公司收入比例等]，重点关注下列高风险领域：
... A58: 20xx年xx月xx日

Sheet B11-3被审计单位的公开信息记录
A1: 致同会计师事务所
A2: 被审计单位的公开信息记录
A3: =底稿目录!A2 -> 被审计单位：ABC有限公司 | D3: =底稿目录!A5 -> 编制人：张XX | G3: =底稿目录!A6 -> 编制日期：2025-X-X | J3: 索引号： | K3: B11-3
A4: =底稿目录!A3 -> 会计期间：202X年度 | D4: =底稿目录!A7 -> 复核人：李XX | G4: =底稿目录!A8 -> 复核日期：2025-X-X | J4: 页 次：
A5: 程序：
A6: 了解企业的公开信息，考虑以下几点： （适用于上市实体）
A7: *公开财务报告信息
A8: *对分析师和投资者的解释说明
A9: *分析师报告
A10: *业绩公告或业绩发布会记录
A11: *获得与投资者或评级机构的其他会议记录
A12: 记录：
A13: 名称 | C13: 信息编号 | D13: 主要内容
A14: 关于为**公司银行授信担保的公告 | C14: 临时公告2013-044 | D14: 为**公司向银行申请的银行授信额度提供担保总额为人民币 78,000 万元，本次担保方式为连带责任保证，本次对外担保不构成关联交易
