Workbook
Name _13102: #REF!
Name _13302: #REF!
Name _13398: #REF!
Name _18102: #REF!
Name _18198: #REF!
Name a: #REF!
Name as: #REF!
Name b: #REF!
Name bv: #REF!
Name d: #REF!
Name df: #REF!
Name dfs: #REF!
Name e: #REF!
Name er: #REF!
Name f: #REF!
Name fg: #REF!
Name fgd: #REF!
Name fgh: #REF!
Name g: #REF!
Name h: #REF!
Name hv: #REF!
Name i: #REF!
Name jk: #REF!
Name k: #REF!
Name kj: #REF!
Name kl: #REF!
Name KMDM: #REF!
Name l: #REF!
Name lk: #REF!
Name m: #REF!
Name mn: #REF!
Name n: #REF!
Name nm: #REF!
Name o: #REF!
Name op: #REF!
Name p: #REF!
Name q: #REF!
Name rt: #REF!
Name rty: #REF!
Name s: #REF!
Name sa: #REF!
Name scn: #REF!
Name _scn11: #REF!
Name _scn15: #REF!
Name _scn16: #REF!
Name _scn17: #REF!
Name _scn19: #REF!
Name _scn2: #REF!
Name _scn20: #REF!
Name _scn3: #REF!
Name _scn4: #REF!
Name _scn5: #REF!
Name _scn6: #REF!
Name _scn7: #REF!
Name _scn8: #REF!
Name _scn9: #REF!
Name scq: #REF!
Name _scq1: #REF!
Name _scq11: #REF!
Name _scq15: #REF!

Sheet temp_temp__
C5: 38717

Sheet 说明
B2: 使用说明： | L2: 序号 | M2: 目录
L3: 1 | M3: 说明
B4: 1 | C4: 本工作簿用于单项会计报表审计调整、试算平衡；未审报表及审定报表的横向、纵向、比率分析。 | L4: 2 | M4: 参数
L5: 3 | M5: 报表格式
B6: 2 | C6: 本工作簿没有颜色的单元格可以根据需要进行修改， | L6: 4 | M6: 未审BS
C7: 修改时，请在拟修改的单元格直接输入新的内容，请不要使用剪切或拖拽填充功能。 | L7: 5 | M7: 未审PL
L8: 6 | M8: 未审CF
B9: 3 | C9: 请在 | D9: “参数表” | E9: 中没有颜色的单元格中输入项目基本情况，其他工作表相应区域会随之改变。 | L9: 7 | M9: 期初核对BS
L10: 8 | M10: 期初核对PL
B11: 4 | C11: 未审报表、试算平衡表（TB）、审定报表、比较分析表的格式由 | G11: “报表格式” | H11: 链接控制； | L11: 9 | M11: 账项调整
C12: 如需修改报表科目，请在 | E12: “报表格式” | F12: 中没有颜色的单元格区域修改，其他报表会相应改变。 | L12: 10 | M12: 报表调整
L13: 11 | M13: CF调整
B14: 5 | C14: “账项调整”、 | D14: “报表调整” | E14: 可以根据需要插入行，请勿删除行；调整金额会自动链接到试算平衡表， | L14: 12 | M14: TB资产
C15: 若调整未全部链入试算平衡表，请检查调整分录的借贷方科目是否为报表科目。若需添加或更改报表科目， | L15: 13 | M15: TB负债
C16: 请在 | D16: “报表格式” | E16: 中没有颜色的单元格区域进行修改，并相应修改 | H16: “报表格式AA列” | L16: 14 | M16: TB损益
L17: 15 | M17: 审定BS
L18: 16 | M18: 审定PL
L19: 17 | M19: 审定CF
L20: 18 | M20: 未审横向BS
L21: 19 | M21: 未审横向PL
L22: 20 | M22: 未审纵向BS
L23: 21 | M23: 未审纵向PL
L24: 22 | M24: 未审比率分析
L25: 23 | M25: 已审横向BS
L26: 24 | M26: 已审横向PL
L27: 25 | M27: 已审纵向BS
L28: 26 | M28: 已审纵向PL
... L37: 35 | M37: 审定CF(上期)

Sheet 参数
B2: 项 目 | D2: 参 数 | E2: 参考格式
B3: 客户情况 | C3: 单位名称： | E3: 北京二锅头有限责任公司
C4: 法定代表人： | E4: 张一二
C5: 财务负责人： | E5: 陈一二
C6: 会计主管： | E6: 王一二
B8: 会计报表 | C8: 报表类型 | D8: 一般企业（执行统一会计制度） | E8: 股份有限公司或一般企业(执行统一会计制度)
C9: 会计年度（上期）： | D9: 2006年度 | E9: 1999年度 或 1997年10月20日～1998年8月10日 | H9: 股份有限公司
C10: 会计年度（本期）： | D10: 2007年度 | E10: 2000年度 或 1998年8月10日～2000年10月20日 | H10: 一般企业（执行统一会计制度）
C11: 会计截止（上期）： | D11: 39082 | E11: 1999年12月31日 或 1998年8月10日 | I11: =MONTH(D11) -> 12
C12: 会计截止（本期）： | D12: 39447 | E12: 2000年12月31日 或 2000年10月20日 | I12: =MONTH(D12) -> 12
C13: 金额单位： | D13: 人民币元 | E13: 人民币元
B15: 审计单位 | C15: 审计单位名称： | D15: 北京京都会计师事务所 | E15: 北京京都会计师事务所
C16: 项目负责人：
C17: 底稿编制人： | E17: 刘一二
C18: 底稿复核人： | E18: 周一二
B20: NB | C20: 本表没有颜色的单元格可以根据需要进行修改
B24: 报表勾稽关系审核表
B25: No. | C25: 勾稽审核内容 | D25: 审核结果 | E25: 不符原因
B26: 1 | C26: 期末资产总计＝期末负债和股东权益总计 | D26: =IF(ABS(审定BS!C62-审定BS!C125)<0.01,TRUE,FALSE) -> TRUE | E26: =IF(D26=TRUE,"","期末资产负债表不平")
B27: 2 | C27: 期初资产总计＝期初负债和股东权益总计 | D27: =IF(ABS(审定BS!E62-审定BS!E125)<0.01,TRUE,FALSE) -> TRUE | E27: =IF(D27=TRUE,"","期初资产负债表不平")
B28: 3 | C28: B/S期末未分配利润＝P/L期末未分配利润 | D28: =IF(ABS(审定BS!C118-审定PL!C73)<0.01,TRUE,FALSE) -> TRUE | E28: =IF(D28=TRUE,"","期末利润分配表与资产负债表未分配利润勾稽不对")
B29: 4 | C29: B/S期初未分配利润＝P/L期初未分配利润 | D29: =IF(ABS(审定BS!E118-审定PL!E73)<0.01,TRUE,FALSE) -> TRUE | E29: =IF(D29=TRUE,"","期初利润分配表与资产负债表未分配利润勾稽不对")
B30: 5 | C30: 期末年初未分配利润＝期初未分配利润 | D30: =IF(ABS(审定PL!C54-审定PL!E73)<0.01,TRUE,FALSE) -> TRUE | E30: =IF(D30=TRUE,"","利润及利润分配表年初未分配利润与上期勾稽不对")
B31: 6 | C31: B/S期末货币资金＝Cashflow期末货币资金 | D31: =IF(ABS(审定BS!C7-审定CF!C82)<0.01,TRUE,FALSE) -> TRUE | E31: =IF(D31=TRUE,"","现金流量表与资产负债表期末货币资金勾稽不对")
B32: 7 | C32: B/S期初货币资金＝Cashflow期初货币资金 | D32: =IF(ABS(审定BS!E7-审定CF!C83)<0.01,TRUE,FALSE) -> TRUE | E32: =IF(D32=TRUE,"","现金流量表与资产负债表期初货币资金勾稽不对")
B33: 8 | C33: 直接法OperatingCF＝间接法OperatingCF | D33: =IF(ABS(审定CF!C16-审定CF!C74)<0.01,TRUE,FALSE) -> TRUE | E33: =IF(D33=TRUE,"","现金流量表主表与附表勾稽不对-经营活动现金净增加额")
B34: 9 | C34: 直接法NetCashflow＝间接法NetCashflow | D34: =IF(ABS(审定CF!C45-审定CF!C86)<0.01,TRUE,FALSE) -> TRUE | E34: =IF(D34=TRUE,"","现金流量表主表与附表勾稽不对-现金净增加额")
B35: 10 | C35: P/L净利润＝Cashflow间接法净利润 | D35: =IF(ABS(审定PL!C53-审定CF!C56)<0.01,TRUE,FALSE) -> TRUE | E35: =IF(D35=TRUE,"","现金流量表与利润表勾稽不对-净利润")
B36: 11 | C36: Cashflow待摊费用减少＝B/S待摊费用减少 | D36: =IF(ABS(审定CF!C63-(审定BS!E21-审定BS!C21))<0.01,TRUE,FALSE) -> TRUE | E36: =IF(D36=TRUE,"","现金流量表待摊费用与资产负债表勾稽不对")
B37: 12 | C37: Cashflow预提费用增加＝B/S预提费用增加 | D37: =IF(ABS(审定CF!C64-(审定BS!C81-审定BS!E81))<0.01,TRUE,FALSE) -> TRUE | E37: =IF(D37=TRUE,"","现金流量表预提费用与资产负债表勾稽不对")
B38: 13 | C38: Cashflow存货的减少＝B/S存货的减少 | D38: =IF(ABS(审定CF!C70-(审定BS!E18-审定BS!C18))<0.01,TRUE,FALSE) -> TRUE | E38: =IF(D38=TRUE,"","现金流量表存货与资产负债表勾稽不对")
B39: 14 | C39: Cashflow投资收益＝P/L投资收益 | D39: =IF(ABS(审定CF!C68+审定PL!C31)<0.01,TRUE,FALSE) -> TRUE | E39: =IF(D39=TRUE,"","2005年利润分配表与现金流量表投资收益勾稽不对")
B40: 15 | C40: Cashflow少数股东损益＝P/L少数股东损益 | D40: =IF(ABS(审定CF!C57-审定PL!C51)<0.01,TRUE,FALSE) -> TRUE | E40: =IF(D40=TRUE,"","利润分配表与现金流量表少数股东损益勾稽不对")
B41: 16 | C41: 按净利润的10%提取法定盈余公积 | D41: =IF(ABS(审定PL!C58-审定PL!C53*0.1)<0.01,TRUE,FALSE) -> TRUE | E41: =IF(D41=TRUE,"","按照公司政策，公司提取的法定盈余公积不符")
B42: 17 | C42: 法定公益金余额结转盈余公积后余额为零 | D42: =IF(审定BS!C116=0,TRUE,FALSE) -> TRUE | E42: =IF(D42=TRUE,"","法定公益金结转盈余公积后无余额")
B43: 18
B44: 19
B45: 20 | C45: 待处理流动资产净损益科目年末余额为零 | D45: =IF(审定BS!C22=0,TRUE,FALSE) -> TRUE | E45: =IF(D45=TRUE,"","按照新制度规定，待处理流动资产净损益科目年末不应有余额")
B46: 21 | C46: 待处理固定资产净损益科目年末余额为零 | D46: =IF(审定BS!C44=0,TRUE,FALSE) -> TRUE | E46: =IF(D46=TRUE,"","按照新制度规定，待处理固定资产净损益科目年末不应有余额")

Sheet 报表格式
A1: 会计报表格式及科目名称 | Q1: 会计报表格式及科目名称 | Z1: code | AA1: 报表项目
B2: 本表没有颜色的单元格可以根据需要进行修改，本系统的其它表格将随之改变。比如，可将“存货”改为“存货1”。正确的修改方法，是在拟修改的单元格直接输入新的内容，请不要使用剪切或拖拽功能。
B3: 资 产 类 | G3: 负债及所有者权益类 | L3: 损 益 类 | Q3: 现金流量表类 | U3: 现金流量表类
B4: 报表项目 | C4: 行 | D4: 调整年末科目名称 | E4: 调整年初科目名称 | G4: 报表项目 | H4: 行 | I4: 调整年末科目名称 | J4: 调整年初科目名称 | L4: 报表项目 | M4: 行 | N4: 调整本期科目名称 | O4: 调整上期科目名称 | Q4: 报表项目 | R4: 行 | S4: 科目名称 | U4: 补充资料 | V4: 行 | W4: 科目名称
B5: 流动资产： | C5: 1 | G5: 流动负债： | H5: =C72+1 -> 58 | L5: 一、主营业务收入 | M5: 1 | N5: 主营业务收入 | O5: =IF(N5="",0,CONCATENATE("上年",N5)) -> 上年主营业务收入 | Q5: 一、经营活动产生的现金流量 | R5: 1 | U5: 1、将净利润调节为经营活动现金流量 | V5: =R78+1 -> 1 | AA5: 流动资产：
B6: 货币资金 | C6: 2 | D6: 货币资金 | E6: =IF(D6="",0,CONCATENATE("年初",D6)) -> 年初货币资金 | G6: 短期借款 | H6: =H5+1 -> 59 | I6: 短期借款 | J6: =IF(I6="",0,CONCATENATE("年初",I6)) -> 年初短期借款 | L6: 其中：进口产品（商品）销售收入 | M6: 2 | Q6: 销售商品、提供劳务收到的现金 | R6: 2 | S6: 销售商品、提供劳务收到的现金 | U6: 净利润 | V6: =V5+1 -> 2 | W6: 净利润 | Z6: G123 | AA6: =B6 -> 货币资金
B7: 短期投资 | C7: 3 | D7: 短期投资 | E7: =IF(D7="",0,CONCATENATE("年初",D7)) -> 年初短期投资 | G7: 应付票据 | H7: =H6+1 -> 60 | I7: 应付票据 | J7: =IF(I7="",0,CONCATENATE("年初",I7)) -> 年初应付票据 | L7: 出口产品（商品）销售收入 | M7: 3 | Q7: 收到的税费返还 | R7: 3 | S7: 收到的税费返还 | U7: 加：*少数股东损益 | V7: =V6+1 -> 3 | W7: 少数股东损益 | Z7: F1 | AA7: =B7 -> 短期投资
B8: 应收票据 | C8: 4 | D8: 应收票据 | E8: =IF(D8="",0,CONCATENATE("年初",D8)) -> 年初应收票据 | G8: 应付账款 | H8: =H7+1 -> 61 | I8: 应付账款 | J8: =IF(I8="",0,CONCATENATE("年初",I8)) -> 年初应付账款 | L8: 减：折扣与折让 | M8: 4 | N8: 折扣与折让 | O8: =IF(N8="",0,CONCATENATE("上年",N8)) -> 上年折扣与折让 | Q8: 收到的其他与经营活动有关的现金 | R8: 4 | S8: 收到的其他与经营活动有关的现金 | U8: 减：*未确认的投资损失 | V8: =V7+1 -> 4 | W8: 未确认的投资损失 | Z8: D3 | AA8: =B8 -> 应收票据
B9: 应收股利 | C9: 5 | D9: 应收股利 | E9: =IF(D9="",0,CONCATENATE("年初",D9)) -> 年初应收股利 | G9: 预收账款 | H9: =H8+1 -> 62 | I9: 预收账款 | J9: =IF(I9="",0,CONCATENATE("年初",I9)) -> 年初预收账款 | L9: 二、主营业务收入净额 | M9: 5 | R9: 5 | U9: 加：计提的资产减值准备 | V9: =V8+1 -> 5 | W9: 计提的资产减值准备 | Z9: F5 | AA9: =B9 -> 应收股利
B10: 应收利息 | C10: 6 | D10: 应收利息 | E10: =IF(D10="",0,CONCATENATE("年初",D10)) -> 年初应收利息 | G10: 应付工资 | H10: =H9+1 -> 63 | I10: 应付工资 | J10: =IF(I10="",0,CONCATENATE("年初",I10)) -> 年初应付工资 | L10: 减：（一）主营业务成本 | M10: 6 | N10: 主营业务成本 | O10: =IF(N10="",0,CONCATENATE("上年",N10)) -> 上年主营业务成本 | Q10: 现金流入小计 | R10: 6 | U10: 固定资产折旧 | V10: =V9+1 -> 6 | W10: 固定资产折旧 | Z10: F6 | AA10: =B10 -> 应收利息
B11: 应收账款 | C11: 7 | D11: 应收账款 | E11: =IF(D11="",0,CONCATENATE("年初",D11)) -> 年初应收账款 | G11: 应付福利费 | H11: =H10+1 -> 64 | I11: 应付福利费 | J11: =IF(I11="",0,CONCATENATE("年初",I11)) -> 年初应付福利费 | L11: 其中：出口产品（商品）销售成本 | M11: 7 | Q11: 购买商品、接受劳务支付的现金 | R11: 7 | S11: 购买商品、接受劳务支付的现金 | U11: 无形资产摊销 | V11: =V10+1 -> 7 | W11: 无形资产摊销 | Z11: D1 | AA11: =B11 -> 应收账款
B12: 其他应收款 | C12: 8 | D12: 其他应收款 | E12: =IF(D12="",0,CONCATENATE("年初",D12)) -> 年初其他应收款 | G12: 应付股利（利润） | H12: =H11+1 -> 65 | I12: 应付股利 | J12: =IF(I12="",0,CONCATENATE("年初",I12)) -> 年初应付股利 | L12: （二）主营业务税金及附加 | M12: 8 | N12: 主营业务税金及附加 | O12: =IF(N12="",0,CONCATENATE("上年",N12)) -> 上年主营业务税金及附加 | Q12: 支付给职工以及为职工支付的现金 | R12: 8 | S12: 支付给职工以及为职工支付的现金 | U12: 长期待摊费用摊销 | V12: =V11+1 -> 8 | W12: 长期待摊费用摊销 | Z12: G4 | AA12: =B12 -> 其他应收款
B13: 预付账款 | C13: 9 | D13: 预付账款 | E13: =IF(D13="",0,CONCATENATE("年初",D13)) -> 年初预付账款 | G13: 应付利息 | H13: =H12+1 -> 66 | I13: 应交税金 | J13: =IF(I13="",0,CONCATENATE("年初",I13)) -> 年初应交税金 | L13: （三）经营费用 | M13: 9 | N13: 经营费用 | O13: =IF(N13="",0,CONCATENATE("上年",N13)) -> 上年经营费用 | Q13: 支付各项税费 | R13: 9 | S13: 支付各项税费 | U13: 待摊费用的减少（减：增加） | V13: =V12+1 -> 9 | W13: 待摊费用的减少（减：增加） | Z13: E3 | AA13: =B13 -> 预付账款
B14: 期货保证金 | C14: 10 | D14: 期货保证金 | E14: =IF(D14="",0,CONCATENATE("年初",D14)) -> 年初期货保证金 | G14: 应交税金 | H14: =H13+1 -> 67 | I14: 其他未交款 | J14: =IF(I14="",0,CONCATENATE("年初",I14)) -> 年初其他未交款 | L14: （四）其他 | M14: 10 | N14: 其他 | O14: =IF(N14="",0,CONCATENATE("上年",N14)) -> 上年其他 | Q14: 支付的其他与经营活动有关的现金 | R14: 10 | S14: 支付的其他与经营活动有关的现金 | U14: 预提费用的增加（减：减少） | V14: =V13+1 -> 10 | W14: 预提费用的增加（减：减少） | AA14: =B14 -> 期货保证金
B15: 应收补贴款 | C15: 11 | D15: 应收补贴款 | E15: =IF(D15="",0,CONCATENATE("年初",D15)) -> 年初应收补贴款 | G15: 其他应交款 | H15: =H14+1 -> 68 | I15: 其他应付款 | J15: =IF(I15="",0,CONCATENATE("年初",I15)) -> 年初其他应付款 | L15: 加：（一）递延收益 | M15: 11 | N15: 递延收益 | O15: =IF(N15="",0,CONCATENATE("上年",N15)) -> 上年递延收益 | R15: 11 | U15: 处置固定资产、无形资产和其他长期资产的损失（减：收益） | V15: =V14+1 -> 11 | W15: 处置固定资产、无形资产和其他长期资产的损失（减：收益） | Z15: I1 | AA15: =B15 -> 应收补贴款
B16: 应收出口退税 | C16: 12 | D16: 应收出口退税 | E16: =IF(D16="",0,CONCATENATE("年初",D16)) -> 年初应收出口退税 | G16: 其他应付款 | H16: =H15+1 -> 69 | I16: 预提费用 | J16: =IF(I16="",0,CONCATENATE("年初",I16)) -> 年初预提费用 | L16: （二）代购代销收入 | M16: 12 | N16: 代购代销收入 | O16: =IF(N16="",0,CONCATENATE("上年",N16)) -> 上年代购代销收入 | R16: 12 | U16: 固定资产报废损失 | V16: =V15+1 -> 12 | W16: 固定资产报废损失 | AA16: =B16 -> 应收出口退税
B17: 存货 | C17: 13 | D17: 存货 | E17: =IF(D17="",0,CONCATENATE("年初",D17)) -> 年初存货 | G17: 预提费用 | H17: =H16+1 -> 70 | I17: 预计负债 | J17: =IF(I17="",0,CONCATENATE("年初",I17)) -> 年初预计负债 | L17: （三）其他 | M17: 13 | N17: 其他 | O17: =IF(N17="",0,CONCATENATE("上年",N17)) -> 上年其他 | R17: 13 | U17: 财务费用 | V17: =V16+1 -> 13 | W17: 财务费用 | Z17: E1 | AA17: =B17 -> 存货
B18: 其中：原材料 | C18: 14 | D18: 其中：原材料 | G18: 预计负债 | H18: =H17+1 -> 71 | I18: 一年内到期的长期负债 | J18: =IF(I18="",0,CONCATENATE("年初",I18)) -> 年初一年内到期的长期负债 | L18: 三、主营业务利润 | M18: 14 | O18: =IF(N18="",0,CONCATENATE("上年",N18)) -> 0 | Q18: 现金流出小计 | R18: 14 | U18: 投资损失（减：收益） | V18: =V17+1 -> 14
B19: 库存商品（产成品） | C19: 15 | D19: 库存商品（产成品） | G19: 递延收益 | H19: =H18+1 -> 72 | I19: 其他流动负债 | J19: =IF(I19="",0,CONCATENATE("年初",I19)) -> 年初其他流动负债 | L19: 加：其他业务利润 | M19: 15 | N19: 其他业务利润 | O19: =IF(N19="",0,CONCATENATE("上年",N19)) -> 上年其他业务利润 | Q19: 经营活动产生的现金流量净额 | R19: 15 | U19: 递延税款贷项（减：借项） | V19: =V18+1 -> 15
B20: 待摊费用 | C20: 16 | D20: 待摊费用 | E20: =IF(D20="",0,CONCATENATE("年初",D20)) -> 年初待摊费用 | G20: 一年内到期的长期负债 | H20: =H19+1 -> 73 | L20: 减：（一）营业费用 | M20: 16 | N20: 营业费用 | O20: =IF(N20="",0,CONCATENATE("上年",N20)) -> 上年营业费用 | Q20: 二、投资活动产生的现金流量 | R20: 16 | U20: 存货的减少（减：增加） | V20: =V19+1 -> 16 | W20: 投资损失（减：收益） | Z20: I4 | AA20: =B20 -> 待摊费用
B21: 待处理流动资产净损失 | C21: 17 | D21: 待处理流动资产净损失 | E21: =IF(D21="",0,CONCATENATE("年初",D21)) -> 年初待处理流动资产净损失 | G21: 应付权证 | H21: =H20+1 -> 74 | J21: =IF(I21="",0,CONCATENATE("年初",I21)) -> 0 | L21: （二）管理费用 | M21: 17 | N21: 管理费用 | O21: =IF(N21="",0,CONCATENATE("上年",N21)) -> 上年管理费用 | Q21: 收回投资所收到的现金 | R21: 17 | S21: 收回投资所收到的现金 | U21: 经营性应收项目的减少（减：增加） | V21: =V20+1 -> 17 | W21: 递延税款贷项（减：借项） | Z21: I6 | AA21: =B21 -> 待处理流动资产净损失
B22: 一年内到期的长期债权投资 | C22: 18 | D22: 一年内到期的长期债权投资 | E22: =IF(D22="",0,CONCATENATE("年初",D22)) -> 年初一年内到期的长期债权投资 | G22: 其他流动负债 | H22: =H21+1 -> 75 | J22: =IF(I22="",0,CONCATENATE("年初",I22)) -> 0 | L22: 其中：业务招待费 | M22: 18 | N22: 财务费用 | O22: =IF(N22="",0,CONCATENATE("上年",N22)) -> 上年财务费用 | Q22: 其中：出售子公司所收到的现金 | R22: 18 | U22: 经营性应付项目的增加（减：减少） | V22: =V21+1 -> 18 | W22: 存货的减少（减：增加） | AA22: =B22 -> 一年内到期的长期债权投资
B23: 其他流动资产 | C23: 19 | D23: 其他流动资产 | E23: =IF(D23="",0,CONCATENATE("年初",D23)) -> 年初其他流动资产 | H23: =H22+1 -> 76 | J23: =IF(I23="",0,CONCATENATE("年初",I23)) -> 0 | L23: 研究与开发费 | M23: 19 | Q23: 取得投资收益所收到的现金 | R23: 19 | S23: 取得投资收益所收到的现金 | U23: 其他 | V23: =V22+1 -> 19 | W23: 经营性应收项目的减少（减：增加） | AA23: =B23 -> 其他流动资产
C24: 20 | E24: =IF(D24="",0,CONCATENATE("年初",D24)) -> 0 | H24: =H23+1 -> 77 | J24: =IF(I24="",0,CONCATENATE("年初",I24)) -> 0 | L24: （三）财务费用 | M24: 20 | Q24: 处置固定资产、无形资产和其他长期资产所收回的现金净额 | R24: 20 | S24: 处置固定资产、无形资产和其他长期资产所收回的现金净额 | V24: =V23+1 -> 20 | W24: 经营性应付项目的增加（减：减少） | AA24: =B24 -> 0
C25: 21 | E25: =IF(D25="",0,CONCATENATE("年初",D25)) -> 0 | G25: 流动负债合计 | H25: =H24+1 -> 78 | I25: 长期借款 | J25: =IF(I25="",0,CONCATENATE("年初",I25)) -> 年初长期借款 | L25: 其中：利息支出 | M25: 21 | O25: =IF(N25="",0,CONCATENATE("上年",N25)) -> 0 | Q25: 收到的其他与投资活动有关的现金 | R25: 21 | S25: 收到的其他与投资活动有关的现金 | V25: =V24+1 -> 21 | W25: 其他 | AA25: =B25 -> 0
B26: 流动资产合计 | C26: 22 | E26: =IF(D26="",0,CONCATENATE("年初",D26)) -> 0 | G26: 长期负债： | H26: =H25+1 -> 79 | I26: 应付债券 | J26: =IF(I26="",0,CONCATENATE("年初",I26)) -> 年初应付债券 | L26: 利息收入 | M26: 22 | N26: 其他 | O26: =IF(N26="",0,CONCATENATE("上年",N26)) -> 上年其他 | R26: 22 | U26: 经营活动产生的现金流量净额 | V26: =V25+1 -> 22 | AA26: 流动资产合计
B27: 长期投资 | C27: 23 | E27: =IF(D27="",0,CONCATENATE("年初",D27)) -> 0 | G27: 长期借款 | H27: =H26+1 -> 80 | I27: 长期应付款 | J27: =IF(I27="",0,CONCATENATE("年初",I27)) -> 年初长期应付款 | L27: 汇兑净损失 | M27: 23 | O27: =IF(N27="",0,CONCATENATE("上年",N27)) -> 0 | Q27: 现金流入小计 | R27: 23 | V27: =V26+1 -> 23
B28: 其中：长期股权投资 | C28: 24 | E28: =IF(D28="",0,CONCATENATE("年初",D28)) -> 0 | G28: 应付债券 | H28: =H27+1 -> 81 | I28: 专项应付款 | J28: =IF(I28="",0,CONCATENATE("年初",I28)) -> 年初专项应付款 | L28: （四）其他 | M28: 24 | N28: 投资收益 | O28: =IF(N28="",0,CONCATENATE("上年",N28)) -> 上年投资收益 | Q28: 购置固定资产、无形资产和其他长期资产所支付的现金 | R28: 24 | S28: 购置固定资产、无形资产和其他长期资产所支付的现金 | U28: 2、不涉及现金收支的投资和筹资活动 | V28: =V27+1 -> 24 | AA28: 长期投资：
B29: 长期债权投资 | C29: 25 | D29: 长期股权投资 | E29: =IF(D29="",0,CONCATENATE("年初",D29)) -> 年初长期股权投资 | G29: 长期应付款 | H29: =H28+1 -> 82 | I29: 其他长期负债 | J29: =IF(I29="",0,CONCATENATE("年初",I29)) -> 年初其他长期负债 | L29: 四、营业利润 | M29: 25 | N29: 期货收益 | Q29: 投资所支付的现金 | R29: 25 | S29: 投资所支付的现金 | U29: 债务转为资本 | V29: =V28+1 -> 25 | Z29: F2 | AA29: 长期股权投资
B30: *合并价差 | C30: 26 | D30: 长期债权投资 | E30: =IF(D30="",0,CONCATENATE("年初",D30)) -> 年初长期债权投资 | G30: 专项应付款 | H30: =H29+1 -> 83 | I30: 其中：特准储备资金 | L30: 加：（一）投资收益 | M30: 26 | N30: 补贴收入 | Q30: 其中：购买子公司所支付的现金 | R30: 26 | U30: 一年内到期的可转换公司债券 | V30: =V29+1 -> 26 | Z30: F3 | AA30: 长期债权投资
C31: 27 | D31: 合并价差 | E31: =IF(D31="",0,CONCATENATE("年初",D31)) -> 年初合并价差 | G31: 其他长期负债 | H31: =H30+1 -> 84 | L31: （二）期货收益 | M31: 27 | Q31: 支付的其他与投资活动有关的现金 | R31: 27 | S31: 支付的其他与投资活动有关的现金 | U31: 融资租入固定资产 | V31: =V30+1 -> 27 | W31: 债务转为资本 | AA31: 合并价差
C32: 28 | G32: 其中：特准储备资金 | H32: =H31+1 -> 85 | J32: =IF(I32="",0,CONCATENATE("年初",I32)) -> 0 | L32: （三）补贴收入 | M32: 28 | N32: 营业外收入 | O32: =IF(N32="",0,CONCATENATE("上年",N32)) -> 上年营业外收入 | R32: 28 | U32: 其他 | V32: =V31+1 -> 28 | W32: 一年内到期的可转换公司债券 | AA32: =B31 -> 0
B33: 长期投资合计 | C33: 29 | H33: =H32+1 -> 86 | J33: =IF(I33="",0,CONCATENATE("年初",I33)) -> 0 | L33: 其中：补贴前亏损的企业补贴收入 | M33: 29 | Q33: 现金流出小计 | R33: 29 | V33: =V32+1 -> 29 | W33: 融资租入固定资产 | AA33: =B32 -> 0
B34: 固定资产： | C34: 30 | E34: =IF(D34="",0,CONCATENATE("年初",D34)) -> 0 | H34: =H33+1 -> 87 | J34: =IF(I34="",0,CONCATENATE("年初",I34)) -> 0 | L34: （四）营业外收入 | M34: 30 | Q34: 投资活动产生的现金流量净额 | R34: 30 | U34: 3、现金及现金等价物净增加情况 | V34: =V33+1 -> 30 | W34: 其他 | AA34: 长期投资合计
B35: 固定资产原价 | C35: 31 | E35: =IF(D35="",0,CONCATENATE("年初",D35)) -> 0 | G35: 长期负债合计 | H35: =H34+1 -> 88 | J35: =IF(I35="",0,CONCATENATE("年初",I35)) -> 0 | L35: 其中：处置固定资产净收益 | M35: 31 | Q35: 三、筹资活动产生的现金流量 | R35: 31 | U35: 现金的期末余额 | V35: =V34+1 -> 31
B36: 减：累计折旧 | C36: 32 | E36: =IF(D36="",0,CONCATENATE("年初",D36)) -> 0 | G36: 递延税项： | H36: =H35+1 -> 89 | I36: 递延税款贷项 | J36: =IF(I36="",0,CONCATENATE("年初",I36)) -> 年初递延税款贷项 | L36: 非货币性交易收益 | M36: 32 | Q36: 吸收投资所收到的现金 | R36: 32 | S36: 吸收投资所收到的现金 | U36: 减：现金的期初余额 | V36: =V35+1 -> 32 | AA36: 固定资产：
B37: 固定资产净值 | C37: 33 | D37: 固定资产 | E37: =IF(D37="",0,CONCATENATE("年初",D37)) -> 年初固定资产 | G37: 递延税款贷项 | H37: =H36+1 -> 90 | J37: =IF(I37="",0,CONCATENATE("年初",I37)) -> 0 | L37: 出售无形资产收益 | M37: 33 | Q37: 取得借款所收到的现金 | R37: 33 | S37: 取得借款所收到的现金 | U37: 加：现金等价物的期末余额 | V37: =V36+1 -> 33 | W37: 现金的期末余额 | Z37: H1 | AA37: 固定资产原价
B38: 减：固定资产减值准备 | C38: 34 | D38: 累计折旧 | E38: =IF(D38="",0,CONCATENATE("年初",D38)) -> 年初累计折旧 | G38: 负 债 合 计 | H38: =H37+1 -> 91 | J38: =IF(I38="",0,CONCATENATE("年初",I38)) -> 0 | L38: 罚款净收入 | M38: 34 | Q38: 收到的其他与筹资活动有关的现金 | R38: 34 | S38: 收到的其他与筹资活动有关的现金 | U38: 减：现金等价物的期初余额 | V38: =V37+1 -> 34 | W38: 现金的期初余额 | Z38: H2 | AA38: 累计折旧
B39: 固定资产净额 | C39: 35 | E39: =IF(D39="",0,CONCATENATE("年初",D39)) -> 0 | G39: *少数股东权益 | H39: =H38+1 -> 92 | J39: =IF(I39="",0,CONCATENATE("年初",I39)) -> 0 | L39: （五）其他 | M39: 35 | O39: =IF(N39="",0,CONCATENATE("上年",N39)) -> 0 | R39: 35 | V39: =V38+1 -> 35 | W39: 现金等价物的期末余额
B40: 工程物资 | C40: 36 | D40: 固定资产减值准备 | E40: =IF(D40="",0,CONCATENATE("年初",D40)) -> 年初固定资产减值准备 | H40: =H39+1 -> 93 | I40: 少数股东权益 | J40: =IF(I40="",0,CONCATENATE("年初",I40)) -> 年初少数股东权益 | L40: 其中：用以前年度含量工资结余弥补利润 | M40: 36 | N40: 营业外支出 | O40: =IF(N40="",0,CONCATENATE("上年",N40)) -> 上年营业外支出 | Q40: 现金流入小计 | R40: 36 | V40: =V39+1 -> 36 | W40: 现金等价物的期初余额 | Z40: H3 | AA40: 固定资产减值准备
...

Sheet 未审BS
A1: =IF(ABS(G55-未审PL!C73)<0.005,"","年初未分配利润勾稽有误！") | C1: =IF(ABS(H55-未审PL!D73)<0.005,"","年末未分配利润勾稽有误！") | F1: 索引号： | H1: 页次：
A2: 资产负债表
A3: =IF(ABS(C62-G62)<0.005,0,"年初数不平，差额为：") -> 0 | C3: =IF(ABS(C62-G62)<0.005,0,C62-G62) -> 0 | E3: =IF(ABS(D62-H62)<0.005,0,"年末数不平，差额为：") -> 0 | G3: =IF(ABS(D62-H62)<0.005," 财企01表",D62-H62) -> 财企01表
A4: =IF(报表格式!G41=""," 对不起，请到参数表中确定报表类型！",CONCATENATE(" 编制单位：",参数!D3)) -> 编制单位： | D4: =参数!$D$12 -> 39447 | G4: =CONCATENATE("金额单位：",参数!$D$13) -> 金额单位：人民币元
A5: 资 产 | B5: 行次 | C5: =参数!D11 -> 39082 | D5: =参数!D12 -> 39447 | E5: =IF(参数!D8="一般企业（执行统一会计制度）","负债及所有者权益","负债及股东权益") -> 负债及所有者权益 | F5: 行次 | G5: =C5 -> 39082 | H5: =D5 -> 39447
A6: =报表格式!B5 -> 流动资产： | B6: 1 | E6: =报表格式!G5 -> 流动负债： | F6: =B62+1 -> 58
A7: =报表格式!B6 -> 货币资金 | B7: 2 | E7: =报表格式!G6 -> 短期借款 | F7: =F6+1 -> 59
A8: =报表格式!B7 -> 短期投资 | B8: 3 | E8: =报表格式!G7 -> 应付票据 | F8: =F7+1 -> 60
A9: =报表格式!B8 -> 应收票据 | B9: 4 | E9: =报表格式!G8 -> 应付账款 | F9: =F8+1 -> 61
A10: =报表格式!B9 -> 应收股利 | B10: 5 | E10: =报表格式!G9 -> 预收账款 | F10: =F9+1 -> 62
A11: =报表格式!B10 -> 应收利息 | B11: 6 | E11: =报表格式!G10 -> 应付工资 | F11: =F10+1 -> 63
A12: =报表格式!B11 -> 应收账款 | B12: 7 | E12: =报表格式!G11 -> 应付福利费 | F12: =F11+1 -> 64
A13: =报表格式!B12 -> 其他应收款 | B13: 8 | E13: =报表格式!G12 -> 应付股利（利润） | F13: =F12+1 -> 65
A14: =报表格式!B13 -> 预付账款 | B14: 9 | E14: =报表格式!G13 -> 应付利息 | F14: =F13+1 -> 66
A15: =报表格式!B14 -> 期货保证金 | B15: 10 | E15: =报表格式!G14 -> 应交税金 | F15: =F14+1 -> 67
A16: =报表格式!B15 -> 应收补贴款 | B16: 11 | E16: =报表格式!G15 -> 其他应交款 | F16: =F15+1 -> 68
A17: =报表格式!B16 -> 应收出口退税 | B17: 12 | E17: =报表格式!G16 -> 其他应付款 | F17: =F16+1 -> 69
A18: =报表格式!B17 -> 存货 | B18: 13 | E18: =报表格式!G17 -> 预提费用 | F18: =F17+1 -> 70
... A25: =报表格式!B24 -> 0 | B25: 20 | E25: =报表格式!G24 -> 0 | F25: =F24+1 -> 77
A26: =报表格式!B25 -> 0 | B26: 21 | E26: =报表格式!G25 -> 流动负债合计 | F26: =F25+1 -> 78 | G26: =SUM(G7:G25) -> 0 | H26: =SUM(H7:H25) -> 0
A27: =报表格式!B26 -> 流动资产合计 | B27: 22 | C27: =SUM(C7:C26)-C19-C20 -> 0 | D27: =SUM(D7:D26)-D19-D20 -> 0 | E27: =报表格式!G26 -> 长期负债： | F27: =F26+1 -> 79
A28: =报表格式!B27 -> 长期投资 | B28: 23 | C28: =SUM(C29:C30) -> 0 | D28: =SUM(D29:D30) -> 0 | E28: =报表格式!G27 -> 长期借款 | F28: =F27+1 -> 80
A29: =报表格式!B28 -> 其中：长期股权投资 | B29: 24 | E29: =报表格式!G28 -> 应付债券 | F29: =F28+1 -> 81
A30: =报表格式!B29 -> 长期债权投资 | B30: 25 | E30: =报表格式!G29 -> 长期应付款 | F30: =F29+1 -> 82
A31: =报表格式!B30 -> *合并价差 | B31: 26 | E31: =报表格式!G30 -> 专项应付款 | F31: =F30+1 -> 83
A32: =报表格式!B31 -> 0 | B32: 27 | E32: =报表格式!G31 -> 其他长期负债 | F32: =F31+1 -> 84
A33: =报表格式!B32 -> 0 | B33: 28 | E33: =报表格式!G32 -> 其中：特准储备资金 | F33: =F32+1 -> 85
A34: =报表格式!B33 -> 长期投资合计 | B34: 29 | C34: =SUM(C28,C31:C33) -> 0 | D34: =SUM(D28,D31:D33) -> 0 | E34: =报表格式!G33 -> 0 | F34: =F33+1 -> 86
A35: =报表格式!B34 -> 固定资产： | B35: 30 | E35: =报表格式!G34 -> 0 | F35: =F34+1 -> 87
A36: =报表格式!B35 -> 固定资产原价 | B36: 31 | E36: =报表格式!G35 -> 长期负债合计 | F36: =F35+1 -> 88 | G36: =SUM(G28:G32,G34:G35) -> 0 | H36: =SUM(H28:H32,H34:H35) -> 0
A37: =报表格式!B36 -> 减：累计折旧 | B37: 32 | E37: =报表格式!G36 -> 递延税项： | F37: =F36+1 -> 89
A38: =报表格式!B37 -> 固定资产净值 | B38: 33 | C38: =C36-C37 -> 0 | D38: =D36-D37 -> 0 | E38: =报表格式!G37 -> 递延税款贷项 | F38: =F37+1 -> 90
A39: =报表格式!B38 -> 减：固定资产减值准备 | B39: 34 | E39: =报表格式!G38 -> 负 债 合 计 | F39: =F38+1 -> 91 | G39: =SUM(G26,G36,G38:G38) -> 0 | H39: =SUM(H26,H36,H38:H38) -> 0
A40: =报表格式!B39 -> 固定资产净额 | B40: 35 | C40: =C38-C39 -> 0 | D40: =D38-D39 -> 0 | E40: =报表格式!G39 -> *少数股东权益 | F40: =F39+1 -> 92
A41: =报表格式!B40 -> 工程物资 | B41: 36 | E41: =报表格式!G40 -> 0 | F41: =F40+1 -> 93
A42: =报表格式!B41 -> 在建工程 | B42: 37 | E42: =报表格式!G41 -> 所有者权益： | F42: =F41+1 -> 94
A43: =报表格式!B42 -> 固定资产清理 | B43: 38 | E43: =报表格式!G42 -> 实收资本 | F43: =F42+1 -> 95
A44: =报表格式!B43 -> 待处理固定资产净损失 | B44: 39 | E44: =报表格式!G43 -> 国家资本 | F44: =F43+1 -> 96
A45: =报表格式!B44 -> 0 | B45: 40 | E45: =报表格式!G44 -> 集体资本 | F45: =F44+1 -> 97
A46: =报表格式!B45 -> 0 | B46: 41 | E46: =报表格式!G45 -> 法人资本 | F46: =F45+1 -> 98
...

Sheet 未审PL
A1: =IF(ABS(C73-D54)<0.005,"","年初未分配利润勾稽有误！") | D1: 索引号： 页次：
A2: 利润表及利润分配表
A3: =IF(ABS(C73-未审BS!G55)<0.005,IF(ABS(D73-未审BS!H55)<0.005,0,"“未分配利润”栏与资产负债表不平,差额为:"),"“未分配利润”栏与资产负债表不平,差额为:") -> 0 | C3: =IF(ABS(C73-未审BS!G55)<0.005,0,C73-未审BS!G55) -> 0 | D3: =IF(ABS(D73-未审BS!H55)<0.005," 财企02表",D73-未审BS!H55) -> 财企02表
A4: =IF(报表格式!G41=""," 对不起，请到参数表中确定报表类型！",CONCATENATE(" 编制单位：",参数!D3)) -> 编制单位： | B4: =参数!$D$10 -> 2007年度 | D4: =CONCATENATE("金额单位：",参数!$D$13) -> 金额单位：人民币元
A5: 项 目 | B5: 行次 | C5: =参数!D9 -> 2006年度 | D5: =参数!D10 -> 2007年度
A6: =报表格式!L5 -> 一、主营业务收入 | B6: 1
A7: =报表格式!L6 -> 其中：进口产品（商品）销售收入 | B7: 2
A8: =报表格式!L7 -> 出口产品（商品）销售收入 | B8: 3
A9: =报表格式!L8 -> 减：折扣与折让 | B9: 4
A10: =报表格式!L9 -> 二、主营业务收入净额 | B10: 5 | C10: =C6-C9 -> 0 | D10: =D6-D9 -> 0
A11: =报表格式!L10 -> 减：（一）主营业务成本 | B11: 6
A12: =报表格式!L11 -> 其中：出口产品（商品）销售成本 | B12: 7
A13: =报表格式!L12 -> （二）主营业务税金及附加 | B13: 8
A14: =报表格式!L13 -> （三）经营费用 | B14: 9
A15: =报表格式!L14 -> （四）其他 | B15: 10
A16: =报表格式!L15 -> 加：（一）递延收益 | B16: 11
A17: =报表格式!L16 -> （二）代购代销收入 | B17: 12
A18: =报表格式!L17 -> （三）其他 | B18: 13
A19: =报表格式!L18 -> 三、主营业务利润 | B19: 14 | C19: =C10-C11-C13-C14-C15+C16+C17+C18 -> 0 | D19: =D10-D11-D13-D14-D15+D16+D17+D18 -> 0
A20: =报表格式!L19 -> 加：其他业务利润 | B20: 15
A21: =报表格式!L20 -> 减：（一）营业费用 | B21: 16
A22: =报表格式!L21 -> （二）管理费用 | B22: 17
A23: =报表格式!L22 -> 其中：业务招待费 | B23: 18
A24: =报表格式!L23 -> 研究与开发费 | B24: 19
A25: =报表格式!L24 -> （三）财务费用 | B25: 20
A26: =报表格式!L25 -> 其中：利息支出 | B26: 21
A27: =报表格式!L26 -> 利息收入 | B27: 22
A28: =报表格式!L27 -> 汇兑净损失 | B28: 23
A29: =报表格式!L28 -> （四）其他 | B29: 24
A30: =报表格式!L29 -> 四、营业利润 | B30: 25 | C30: =C19+C20-C21-C22-C25-C29 -> 0 | D30: =D19+D20-D21-D22-D25-D29 -> 0
A31: =报表格式!L30 -> 加：（一）投资收益 | B31: 26
A32: =报表格式!L31 -> （二）期货收益 | B32: 27
A33: =报表格式!L32 -> （三）补贴收入 | B33: 28
A34: =报表格式!L33 -> 其中：补贴前亏损的企业补贴收入 | B34: 29
A35: =报表格式!L34 -> （四）营业外收入 | B35: 30
A36: =报表格式!L35 -> 其中：处置固定资产净收益 | B36: 31
A37: =报表格式!L36 -> 非货币性交易收益 | B37: 32
A38: =报表格式!L37 -> 出售无形资产收益 | B38: 33
A39: =报表格式!L38 -> 罚款净收入 | B39: 34
A40: =报表格式!L39 -> （五）其他 | B40: 35
...

Sheet 未审CF
A1: =IF(AND(ABS(C18-F27)<0.005,ABS(C47-F47)<0.005),"","未审现金流量表不平！") | D1: 索引号： | F1: 页次：
A2: 现 金 流 量 表
A3: =IF(ABS(C18-F27)<0.005,0,"“经营活动产生的现金流量”左右不平，差额为:") -> 0 | C3: =IF(ABS(C18-F27)<0.005,0,C18-F27) -> 0 | D3: =IF(ABS(C47-F47)<0.005,0,"“现金及现金等价物净增加额”左右不平，差额为：") -> 0 | F3: =IF(ABS(C47-F47)<0.005," 财企03表",C47-F47) -> 财企03表
A4: =IF(报表格式!G41=""," 对不起，请到参数表中确定报表类型！",CONCATENATE(" 编制单位：",参数!D3)) -> 编制单位： | C4: =参数!$D$10 -> 2007年度 | E4: =CONCATENATE("金额单位：",参数!$D$13) -> 金额单位：人民币元
A5: 报 表 项 目 | B5: 行次 | C5: 金 额 | D5: 补 充 资 料 | E5: 行次 | F5: 金 额
A6: =报表格式!Q5 -> 一、经营活动产生的现金流量 | B6: 1 | D6: =报表格式!U5 -> 1、将净利润调节为经营活动现金流量 | E6: 1
A7: =报表格式!Q6 -> 销售商品、提供劳务收到的现金 | B7: 2 | D7: =报表格式!U6 -> 净利润 | E7: 2 | F7: =未审PL!D53 -> 0
A8: =报表格式!Q7 -> 收到的税费返还 | B8: 3 | D8: =报表格式!U7 -> 加：*少数股东损益 | E8: 3
A9: =报表格式!Q8 -> 收到的其他与经营活动有关的现金 | B9: 4 | D9: =报表格式!U8 -> 减：*未确认的投资损失 | E9: 4
A10: =报表格式!Q9 -> 0 | B10: 5 | D10: =报表格式!U9 -> 加：计提的资产减值准备 | E10: 5
A11: =报表格式!Q10 -> 现金流入小计 | B11: 6 | C11: =SUM(C7:C10) -> 0 | D11: =报表格式!U10 -> 固定资产折旧 | E11: 6
A12: =报表格式!Q11 -> 购买商品、接受劳务支付的现金 | B12: 7 | D12: =报表格式!U11 -> 无形资产摊销 | E12: 7
A13: =报表格式!Q12 -> 支付给职工以及为职工支付的现金 | B13: 8 | D13: =报表格式!U12 -> 长期待摊费用摊销 | E13: 8
A14: =报表格式!Q13 -> 支付各项税费 | B14: 9 | D14: =报表格式!U13 -> 待摊费用的减少（减：增加） | E14: 9
A15: =报表格式!Q14 -> 支付的其他与经营活动有关的现金 | B15: 10 | D15: =报表格式!U14 -> 预提费用的增加（减：减少） | E15: 10
A16: =报表格式!Q15 -> 0 | B16: 11 | D16: =报表格式!U15 -> 处置固定资产、无形资产和其他长期资产的损失（减：收益） | E16: 11
A17: =报表格式!Q18 -> 现金流出小计 | B17: 12 | C17: =SUM(C12:C16) -> 0 | D17: =报表格式!U16 -> 固定资产报废损失 | E17: 12
A18: =报表格式!Q19 -> 经营活动产生的现金流量净额 | B18: 13 | C18: =C11-C17 -> 0 | D18: =报表格式!U17 -> 财务费用 | E18: 13
A19: =报表格式!Q20 -> 二、投资活动产生的现金流量 | B19: 14 | D19: =报表格式!U18 -> 投资损失（减：收益） | E19: 14
A20: =报表格式!Q21 -> 收回投资所收到的现金 | B20: 15 | D20: =报表格式!U19 -> 递延税款贷项（减：借项） | E20: 15
A21: =报表格式!Q22 -> 其中：出售子公司所收到的现金 | B21: 16 | D21: =报表格式!U20 -> 存货的减少（减：增加） | E21: 16
A22: =报表格式!Q23 -> 取得投资收益所收到的现金 | B22: 17 | D22: =报表格式!U21 -> 经营性应收项目的减少（减：增加） | E22: 17
A23: =报表格式!Q24 -> 处置固定资产、无形资产和其他长期资产所收回的现金净额 | B23: 18 | D23: =报表格式!U22 -> 经营性应付项目的增加（减：减少） | E23: 18
A24: =报表格式!Q25 -> 收到的其他与投资活动有关的现金 | B24: 19 | D24: =报表格式!U23 -> 其他 | E24: 19
A25: =报表格式!Q26 -> 0 | B25: 20 | D25: =报表格式!U24 -> 0 | E25: 20
A26: =报表格式!Q27 -> 现金流入小计 | B26: 21 | C26: =SUM(C20:C25)-C21 -> 0 | D26: =报表格式!U25 -> 0 | E26: 21
A27: =报表格式!Q28 -> 购置固定资产、无形资产和其他长期资产所支付的现金 | B27: 22 | D27: =报表格式!U26 -> 经营活动产生的现金流量净额 | E27: 22 | F27: =SUM(F7:F8,F10:F26)-F9 -> 0
A28: =报表格式!Q29 -> 投资所支付的现金 | B28: 23 | D28: =IF(报表格式!U27="","",报表格式!U27) | E28: 23
A29: =报表格式!Q30 -> 其中：购买子公司所支付的现金 | B29: 24 | D29: =报表格式!U28 -> 2、不涉及现金收支的投资和筹资活动 | E29: 24
A30: =报表格式!Q31 -> 支付的其他与投资活动有关的现金 | B30: 25 | D30: =报表格式!U29 -> 债务转为资本 | E30: 25
A31: =报表格式!Q32 -> 0 | B31: 26 | D31: =报表格式!U30 -> 一年内到期的可转换公司债券 | E31: 26
A32: =报表格式!Q33 -> 现金流出小计 | B32: 27 | C32: =SUM(C27:C31)-C29 -> 0 | D32: =报表格式!U31 -> 融资租入固定资产 | E32: 27
A33: =报表格式!Q34 -> 投资活动产生的现金流量净额 | B33: 28 | C33: =C26-C32 -> 0 | D33: =报表格式!U32 -> 其他 | E33: 28
A34: =报表格式!Q35 -> 三、筹资活动产生的现金流量 | B34: 29 | D34: =报表格式!U33 -> 0 | E34: 29
A35: =报表格式!Q36 -> 吸收投资所收到的现金 | B35: 30 | D35: =报表格式!U34 -> 3、现金及现金等价物净增加情况 | E35: 30
A36: =报表格式!Q37 -> 取得借款所收到的现金 | B36: 31 | D36: =报表格式!U35 -> 现金的期末余额 | E36: 31 | F36: =未审BS!D7 -> 0
A37: =报表格式!Q38 -> 收到的其他与筹资活动有关的现金 | B37: 32 | D37: =报表格式!U36 -> 减：现金的期初余额 | E37: 32 | F37: =未审BS!C7 -> 0
A38: =报表格式!Q39 -> 0 | B38: 33 | D38: =报表格式!U37 -> 加：现金等价物的期末余额 | E38: 33
A39: =报表格式!Q40 -> 现金流入小计 | B39: 34 | C39: =SUM(C35:C38) -> 0 | D39: =报表格式!U38 -> 减：现金等价物的期初余额 | E39: 34
A40: =报表格式!Q41 -> 偿还债务所支付的现金 | B40: 35 | D40: =IF(报表格式!U39="","",报表格式!U39) | E40: 35
...

Sheet 期初核对BS
A1: =IF(AND(ABS(F62)<0.005,ABS(L62)<0.005),"期初金额核对一致","期初金额核对不符！") -> 期初金额核对一致
A2: 资产负债表期初核对
A4: =IF(报表格式!G41=""," 对不起，请到参数表中确定报表类型！",CONCATENATE(" 客户名称：",参数!D3)) -> 客户名称： | D4: =参数!$D$12 -> 39447 | J4: =CONCATENATE("金额单位：",参数!$D$13) -> 金额单位：人民币元
A5: =IF(E62<=0.005,"资 产","资产明细核对不符！") -> 资 产 | B5: 行次 | C5: 上期审定数 ① | D5: 本年期初数 ② | E5: 辅助列 | F5: 差异 ①-② | G5: =IF(K62<=0.005,IF(参数!D8="一般企业（执行统一会计制度）","负债及所有者权益","负债及股东权益"),"负债明细核对不符！") -> 负债及所有者权益 | H5: 行次 | I5: 上期审定数 ① | J5: 本年期初数 ② | K5: 辅助列 | L5: 差异 ①-②
A6: =报表格式!B5 -> 流动资产： | B6: 1 | G6: =报表格式!G5 -> 流动负债： | H6: =B62+1 -> 58
A7: =报表格式!B6 -> 货币资金 | B7: 2 | D7: =未审BS!C7 -> 0 | E7: =ABS(F7) -> 0 | F7: =C7-D7 -> 0 | G7: =报表格式!G6 -> 短期借款 | H7: =H6+1 -> 59 | J7: =未审BS!G7 -> 0 | K7: =ABS(L7) -> 0 | L7: =I7-J7 -> 0
A8: =报表格式!B7 -> 短期投资 | B8: 3 | D8: =未审BS!C8 -> 0 | E8: =ABS(F8) -> 0 | F8: =C8-D8 -> 0 | G8: =报表格式!G7 -> 应付票据 | H8: =H7+1 -> 60 | J8: =未审BS!G8 -> 0 | K8: =ABS(L8) -> 0 | L8: =I8-J8 -> 0
A9: =报表格式!B8 -> 应收票据 | B9: 4 | D9: =未审BS!C9 -> 0 | E9: =ABS(F9) -> 0 | F9: =C9-D9 -> 0 | G9: =报表格式!G8 -> 应付账款 | H9: =H8+1 -> 61 | J9: =未审BS!G9 -> 0 | K9: =ABS(L9) -> 0 | L9: =I9-J9 -> 0
A10: =报表格式!B9 -> 应收股利 | B10: 5 | D10: =未审BS!C10 -> 0 | E10: =ABS(F10) -> 0 | F10: =C10-D10 -> 0 | G10: =报表格式!G9 -> 预收账款 | H10: =H9+1 -> 62 | J10: =未审BS!G10 -> 0 | K10: =ABS(L10) -> 0 | L10: =I10-J10 -> 0
A11: =报表格式!B10 -> 应收利息 | B11: 6 | D11: =未审BS!C11 -> 0 | E11: =ABS(F11) -> 0 | F11: =C11-D11 -> 0 | G11: =报表格式!G10 -> 应付工资 | H11: =H10+1 -> 63 | J11: =未审BS!G11 -> 0 | K11: =ABS(L11) -> 0 | L11: =I11-J11 -> 0
A12: =报表格式!B11 -> 应收账款 | B12: 7 | D12: =未审BS!C12 -> 0 | E12: =ABS(F12) -> 0 | F12: =C12-D12 -> 0 | G12: =报表格式!G11 -> 应付福利费 | H12: =H11+1 -> 64 | J12: =未审BS!G12 -> 0 | K12: =ABS(L12) -> 0 | L12: =I12-J12 -> 0
A13: =报表格式!B12 -> 其他应收款 | B13: 8 | D13: =未审BS!C13 -> 0 | E13: =ABS(F13) -> 0 | F13: =C13-D13 -> 0 | G13: =报表格式!G12 -> 应付股利（利润） | H13: =H12+1 -> 65 | J13: =未审BS!G13 -> 0 | K13: =ABS(L13) -> 0 | L13: =I13-J13 -> 0
A14: =报表格式!B13 -> 预付账款 | B14: 9 | D14: =未审BS!C14 -> 0 | E14: =ABS(F14) -> 0 | F14: =C14-D14 -> 0 | G14: =报表格式!G13 -> 应付利息 | H14: =H13+1 -> 66 | J14: =未审BS!G14 -> 0 | K14: =ABS(L14) -> 0 | L14: =I14-J14 -> 0
A15: =报表格式!B14 -> 期货保证金 | B15: 10 | D15: =未审BS!C15 -> 0 | E15: =ABS(F15) -> 0 | F15: =C15-D15 -> 0 | G15: =报表格式!G14 -> 应交税金 | H15: =H14+1 -> 67 | J15: =未审BS!G15 -> 0 | K15: =ABS(L15) -> 0 | L15: =I15-J15 -> 0
A16: =报表格式!B15 -> 应收补贴款 | B16: 11 | D16: =未审BS!C16 -> 0 | E16: =ABS(F16) -> 0 | F16: =C16-D16 -> 0 | G16: =报表格式!G15 -> 其他应交款 | H16: =H15+1 -> 68 | J16: =未审BS!G16 -> 0 | K16: =ABS(L16) -> 0 | L16: =I16-J16 -> 0
A17: =报表格式!B16 -> 应收出口退税 | B17: 12 | D17: =未审BS!C17 -> 0 | E17: =ABS(F17) -> 0 | F17: =C17-D17 -> 0 | G17: =报表格式!G16 -> 其他应付款 | H17: =H16+1 -> 69 | J17: =未审BS!G17 -> 0 | K17: =ABS(L17) -> 0 | L17: =I17-J17 -> 0
A18: =报表格式!B17 -> 存货 | B18: 13 | D18: =未审BS!C18 -> 0 | E18: =ABS(F18) -> 0 | F18: =C18-D18 -> 0 | G18: =报表格式!G17 -> 预提费用 | H18: =H17+1 -> 70 | J18: =未审BS!G18 -> 0 | K18: =ABS(L18) -> 0 | L18: =I18-J18 -> 0
... A25: =报表格式!B24 -> 0 | B25: 20 | D25: =未审BS!C25 -> 0 | E25: =ABS(F25) -> 0 | F25: =C25-D25 -> 0 | G25: =报表格式!G24 -> 0 | H25: =H24+1 -> 77 | J25: =未审BS!G25 -> 0 | K25: =ABS(L25) -> 0 | L25: =I25-J25 -> 0
A26: =报表格式!B25 -> 0 | B26: 21 | D26: =未审BS!C26 -> 0 | E26: =ABS(F26) -> 0 | F26: =C26-D26 -> 0 | G26: =报表格式!G25 -> 流动负债合计 | H26: =H25+1 -> 78 | I26: =SUM(I7:I25) -> 0 | J26: =SUM(J7:J25) -> 0 | K26: =SUM(K7:K25) -> 0 | L26: =I26-J26 -> 0
A27: =报表格式!B26 -> 流动资产合计 | B27: 22 | C27: =SUM(C7:C26)-C19-C20 -> 0 | D27: =SUM(D7:D26)-D19-D20 -> 0 | E27: =SUM(E7:E26)-E19-E20 -> 0 | F27: =C27-D27 -> 0 | G27: =报表格式!G26 -> 长期负债： | H27: =H26+1 -> 79 | K27: =ABS(L27) -> 0
A28: =报表格式!B27 -> 长期投资 | B28: 23 | C28: =SUM(C29:C30) -> 0 | D28: =SUM(D29:D30) -> 0 | E28: =ABS(F28) -> 0 | F28: =C28-D28 -> 0 | G28: =报表格式!G27 -> 长期借款 | H28: =H27+1 -> 80 | J28: =未审BS!G28 -> 0 | K28: =ABS(L28) -> 0 | L28: =I28-J28 -> 0
A29: =报表格式!B28 -> 其中：长期股权投资 | B29: 24 | D29: =未审BS!C29 -> 0 | E29: =ABS(F29) -> 0 | F29: =C29-D29 -> 0 | G29: =报表格式!G28 -> 应付债券 | H29: =H28+1 -> 81 | J29: =未审BS!G29 -> 0 | K29: =ABS(L29) -> 0 | L29: =I29-J29 -> 0
A30: =报表格式!B29 -> 长期债权投资 | B30: 25 | D30: =未审BS!C30 -> 0 | E30: =ABS(F30) -> 0 | F30: =C30-D30 -> 0 | G30: =报表格式!G29 -> 长期应付款 | H30: =H29+1 -> 82 | J30: =未审BS!G30 -> 0 | K30: =ABS(L30) -> 0 | L30: =I30-J30 -> 0
A31: =报表格式!B30 -> *合并价差 | B31: 26 | D31: =未审BS!C31 -> 0 | E31: =ABS(F31) -> 0 | F31: =C31-D31 -> 0 | G31: =报表格式!G30 -> 专项应付款 | H31: =H30+1 -> 83 | J31: =未审BS!G31 -> 0 | K31: =ABS(L31) -> 0 | L31: =I31-J31 -> 0
A32: =报表格式!B31 -> 0 | B32: 27 | D32: =未审BS!C32 -> 0 | E32: =ABS(F32) -> 0 | F32: =C32-D32 -> 0 | G32: =报表格式!G31 -> 其他长期负债 | H32: =H31+1 -> 84 | J32: =未审BS!G32 -> 0 | K32: =ABS(L32) -> 0 | L32: =I32-J32 -> 0
A33: =报表格式!B32 -> 0 | B33: 28 | D33: =未审BS!C33 -> 0 | E33: =ABS(F33) -> 0 | F33: =C33-D33 -> 0 | G33: =报表格式!G32 -> 其中：特准储备资金 | H33: =H32+1 -> 85 | J33: =未审BS!G33 -> 0 | K33: =ABS(L33) -> 0 | L33: =I33-J33 -> 0
A34: =报表格式!B33 -> 长期投资合计 | B34: 29 | C34: =SUM(C28,C31:C33) -> 0 | D34: =SUM(D28,D31:D33) -> 0 | E34: =SUM(E29:E33) -> 0 | F34: =C34-D34 -> 0 | G34: =报表格式!G33 -> 0 | H34: =H33+1 -> 86 | J34: =未审BS!G34 -> 0 | K34: =ABS(L34) -> 0 | L34: =I34-J34 -> 0
A35: =报表格式!B34 -> 固定资产： | B35: 30 | E35: =ABS(F35) -> 0 | G35: =报表格式!G34 -> 0 | H35: =H34+1 -> 87 | J35: =未审BS!G35 -> 0 | K35: =ABS(L35) -> 0 | L35: =I35-J35 -> 0
A36: =报表格式!B35 -> 固定资产原价 | B36: 31 | D36: =未审BS!C36 -> 0 | E36: =ABS(F36) -> 0 | F36: =C36-D36 -> 0 | G36: =报表格式!G35 -> 长期负债合计 | H36: =H35+1 -> 88 | I36: =SUM(I28:I33)-I33+SUM(I34:I35) -> 0 | J36: =SUM(J28:J33)-J33+SUM(J34:J35) -> 0 | K36: =SUM(K28:K33)-K33+SUM(K34:K35) -> 0 | L36: =I36-J36 -> 0
A37: =报表格式!B36 -> 减：累计折旧 | B37: 32 | D37: =未审BS!C37 -> 0 | E37: =ABS(F37) -> 0 | F37: =C37-D37 -> 0 | G37: =报表格式!G36 -> 递延税项： | H37: =H36+1 -> 89 | K37: =ABS(L37) -> 0
A38: =报表格式!B37 -> 固定资产净值 | B38: 33 | C38: =C36-C37 -> 0 | D38: =D36-D37 -> 0 | E38: =ABS(F38) -> 0 | F38: =C38-D38 -> 0 | G38: =报表格式!G37 -> 递延税款贷项 | H38: =H37+1 -> 90 | J38: =未审BS!G38 -> 0 | K38: =ABS(L38) -> 0 | L38: =I38-J38 -> 0
A39: =报表格式!B38 -> 减：固定资产减值准备 | B39: 34 | D39: =未审BS!C39 -> 0 | E39: =ABS(F39) -> 0 | F39: =C39-D39 -> 0 | G39: =报表格式!G38 -> 负 债 合 计 | H39: =H38+1 -> 91 | I39: =I26+I36+I38 -> 0 | J39: =J26+J36+J38 -> 0 | K39: =K26+K36+K38 -> 0 | L39: =I39-J39 -> 0
A40: =报表格式!B39 -> 固定资产净额 | B40: 35 | C40: =C38-C39 -> 0 | D40: =D38-D39 -> 0 | E40: =ABS(F40) -> 0 | F40: =C40-D40 -> 0 | G40: =报表格式!G39 -> *少数股东权益 | H40: =H39+1 -> 92 | J40: =未审BS!G40 -> 0 | K40: =ABS(L40) -> 0 | L40: =I40-J40 -> 0
A41: =报表格式!B40 -> 工程物资 | B41: 36 | D41: =未审BS!C41 -> 0 | E41: =ABS(F41) -> 0 | F41: =C41-D41 -> 0 | G41: =报表格式!G40 -> 0 | H41: =H40+1 -> 93 | K41: =ABS(L41) -> 0 | L41: =I41-J41 -> 0
A42: =报表格式!B41 -> 在建工程 | B42: 37 | D42: =未审BS!C42 -> 0 | E42: =ABS(F42) -> 0 | F42: =C42-D42 -> 0 | G42: =报表格式!G41 -> 所有者权益： | H42: =H41+1 -> 94 | K42: =ABS(L42) -> 0
A43: =报表格式!B42 -> 固定资产清理 | B43: 38 | D43: =未审BS!C43 -> 0 | E43: =ABS(F43) -> 0 | F43: =C43-D43 -> 0 | G43: =报表格式!G42 -> 实收资本 | H43: =H42+1 -> 95 | J43: =未审BS!G43 -> 0 | K43: =ABS(L43) -> 0 | L43: =I43-J43 -> 0
A44: =报表格式!B43 -> 待处理固定资产净损失 | B44: 39 | D44: =未审BS!C44 -> 0 | E44: =ABS(F44) -> 0 | F44: =C44-D44 -> 0 | G44: =报表格式!G43 -> 国家资本 | H44: =H43+1 -> 96 | J44: =未审BS!G44 -> 0 | K44: =ABS(L44) -> 0 | L44: =I44-J44 -> 0
A45: =报表格式!B44 -> 0 | B45: 40 | D45: =未审BS!C45 -> 0 | E45: =ABS(F45) -> 0 | F45: =C45-D45 -> 0 | G45: =报表格式!G44 -> 集体资本 | H45: =H44+1 -> 97 | J45: =未审BS!G45 -> 0 | K45: =ABS(L45) -> 0 | L45: =I45-J45 -> 0
A46: =报表格式!B45 -> 0 | B46: 41 | D46: =未审BS!C46 -> 0 | E46: =ABS(F46) -> 0 | F46: =C46-D46 -> 0 | G46: =报表格式!G45 -> 法人资本 | H46: =H45+1 -> 98 | J46: =未审BS!G46 -> 0 | K46: =ABS(L46) -> 0 | L46: =I46-J46 -> 0
A47: =报表格式!B46 -> 固定资产合计 | B47: 42 | C47: =SUM(C40:C46) -> 0 | D47: =SUM(D40:D46) -> 0 | E47: =SUM(E40:E46) -> 0 | F47: =C47-D47 -> 0 | G47: =报表格式!G46 -> 其中：国有法人资本 | H47: =H46+1 -> 99 | J47: =未审BS!G47 -> 0 | K47: =ABS(L47) -> 0 | L47: =I47-J47 -> 0
...

Sheet 期初核对PL
A1: =IF(AND(ABS(F73)<0.005,ABS(F74)<0.005),"期初金额核对一致","期初金额核对不符！") -> 期初金额核对一致
A2: 利润表及利润分配表期初核对
A4: =IF(报表格式!G41=""," 对不起，请到参数表中确定报表类型！",CONCATENATE(" 客户名称：",参数!D3)) -> 客户名称： | B4: =参数!$D$10 -> 2007年度 | F4: =CONCATENATE("金额单位：",参数!$D$13) -> 金额单位：人民币元
A5: =IF(AND(E73<0.005,E74<0.005),"项 目","明细项目不符！") -> 项 目 | B5: 行次 | C5: 上期审定数 ① | D5: 本期上期数 ② | E5: 辅助列 | F5: 差异 ①-②
A6: =报表格式!L5 -> 一、主营业务收入 | B6: 1 | D6: =未审PL!C6 -> 0 | E6: =ABS(F6) -> 0 | F6: =C6-D6 -> 0
A7: =报表格式!L6 -> 其中：进口产品（商品）销售收入 | B7: 2 | D7: =未审PL!C7 -> 0 | E7: =ABS(F7) -> 0 | F7: =C7-D7 -> 0
A8: =报表格式!L7 -> 出口产品（商品）销售收入 | B8: 3 | D8: =未审PL!C8 -> 0 | E8: =ABS(F8) -> 0 | F8: =C8-D8 -> 0
A9: =报表格式!L8 -> 减：折扣与折让 | B9: 4 | D9: =未审PL!C9 -> 0 | E9: =ABS(F9) -> 0 | F9: =C9-D9 -> 0
A10: =报表格式!L9 -> 二、主营业务收入净额 | B10: 5 | C10: =C6-C9 -> 0 | D10: =D6-D9 -> 0 | E10: =ABS(F10) -> 0 | F10: =C10-D10 -> 0
A11: =报表格式!L10 -> 减：（一）主营业务成本 | B11: 6 | D11: =未审PL!C11 -> 0 | E11: =ABS(F11) -> 0 | F11: =C11-D11 -> 0
A12: =报表格式!L11 -> 其中：出口产品（商品）销售成本 | B12: 7 | D12: =未审PL!C12 -> 0 | E12: =ABS(F12) -> 0 | F12: =C12-D12 -> 0
A13: =报表格式!L12 -> （二）主营业务税金及附加 | B13: 8 | D13: =未审PL!C13 -> 0 | E13: =ABS(F13) -> 0 | F13: =C13-D13 -> 0
A14: =报表格式!L13 -> （三）经营费用 | B14: 9 | D14: =未审PL!C14 -> 0 | E14: =ABS(F14) -> 0 | F14: =C14-D14 -> 0
A15: =报表格式!L14 -> （四）其他 | B15: 10 | D15: =未审PL!C15 -> 0 | E15: =ABS(F15) -> 0 | F15: =C15-D15 -> 0
A16: =报表格式!L15 -> 加：（一）递延收益 | B16: 11 | D16: =未审PL!C16 -> 0 | E16: =ABS(F16) -> 0 | F16: =C16-D16 -> 0
A17: =报表格式!L16 -> （二）代购代销收入 | B17: 12 | D17: =未审PL!C17 -> 0 | E17: =ABS(F17) -> 0 | F17: =C17-D17 -> 0
A18: =报表格式!L17 -> （三）其他 | B18: 13 | D18: =未审PL!C18 -> 0 | E18: =ABS(F18) -> 0 | F18: =C18-D18 -> 0
A19: =报表格式!L18 -> 三、主营业务利润 | B19: 14 | C19: =C10-C11-C13-C14-C15+C16+C17+C18 -> 0 | D19: =D10-D11-D13-D14-D15+D16+D17+D18 -> 0 | E19: =ABS(F19) -> 0 | F19: =C19-D19 -> 0
A20: =报表格式!L19 -> 加：其他业务利润 | B20: 15 | D20: =未审PL!C20 -> 0 | E20: =ABS(F20) -> 0 | F20: =C20-D20 -> 0
A21: =报表格式!L20 -> 减：（一）营业费用 | B21: 16 | D21: =未审PL!C21 -> 0 | E21: =ABS(F21) -> 0 | F21: =C21-D21 -> 0
A22: =报表格式!L21 -> （二）管理费用 | B22: 17 | D22: =未审PL!C22 -> 0 | E22: =ABS(F22) -> 0 | F22: =C22-D22 -> 0
A23: =报表格式!L22 -> 其中：业务招待费 | B23: 18 | D23: =未审PL!C23 -> 0 | F23: =C23-D23 -> 0
A24: =报表格式!L23 -> 研究与开发费 | B24: 19 | D24: =未审PL!C24 -> 0 | F24: =C24-D24 -> 0
A25: =报表格式!L24 -> （三）财务费用 | B25: 20 | D25: =未审PL!C25 -> 0 | E25: =ABS(F25) -> 0 | F25: =C25-D25 -> 0
A26: =报表格式!L25 -> 其中：利息支出 | B26: 21 | D26: =未审PL!C26 -> 0 | E26: =ABS(F26) -> 0 | F26: =C26-D26 -> 0
A27: =报表格式!L26 -> 利息收入 | B27: 22 | D27: =未审PL!C27 -> 0 | E27: =ABS(F27) -> 0 | F27: =C27-D27 -> 0
A28: =报表格式!L27 -> 汇兑净损失 | B28: 23 | D28: =未审PL!C28 -> 0 | E28: =ABS(F28) -> 0 | F28: =C28-D28 -> 0
A29: =报表格式!L28 -> （四）其他 | B29: 24 | D29: =未审PL!C29 -> 0 | E29: =ABS(F29) -> 0 | F29: =C29-D29 -> 0
A30: =报表格式!L29 -> 四、营业利润 | B30: 25 | C30: =C19+C20-C21-C22-C25-C29 -> 0 | D30: =D19+D20-D21-D22-D25-D29 -> 0 | E30: =ABS(F30) -> 0 | F30: =C30-D30 -> 0
A31: =报表格式!L30 -> 加：（一）投资收益 | B31: 26 | D31: =未审PL!C31 -> 0 | E31: =ABS(F31) -> 0 | F31: =C31-D31 -> 0
A32: =报表格式!L31 -> （二）期货收益 | B32: 27 | D32: =未审PL!C32 -> 0 | E32: =ABS(F32) -> 0 | F32: =C32-D32 -> 0
A33: =报表格式!L32 -> （三）补贴收入 | B33: 28 | D33: =未审PL!C33 -> 0 | E33: =ABS(F33) -> 0 | F33: =C33-D33 -> 0
A34: =报表格式!L33 -> 其中：补贴前亏损的企业补贴收入 | B34: 29 | D34: =未审PL!C34 -> 0 | E34: =ABS(F34) -> 0 | F34: =C34-D34 -> 0
A35: =报表格式!L34 -> （四）营业外收入 | B35: 30 | D35: =未审PL!C35 -> 0 | E35: =ABS(F35) -> 0 | F35: =C35-D35 -> 0
A36: =报表格式!L35 -> 其中：处置固定资产净收益 | B36: 31 | D36: =未审PL!C36 -> 0 | E36: =ABS(F36) -> 0 | F36: =C36-D36 -> 0
A37: =报表格式!L36 -> 非货币性交易收益 | B37: 32 | D37: =未审PL!C37 -> 0 | E37: =ABS(F37) -> 0 | F37: =C37-D37 -> 0
A38: =报表格式!L37 -> 出售无形资产收益 | B38: 33 | D38: =未审PL!C38 -> 0 | E38: =ABS(F38) -> 0 | F38: =C38-D38 -> 0
A39: =报表格式!L38 -> 罚款净收入 | B39: 34 | D39: =未审PL!C39 -> 0 | E39: =ABS(F39) -> 0 | F39: =C39-D39 -> 0
A40: =报表格式!L39 -> （五）其他 | B40: 35 | D40: =未审PL!C40 -> 0 | E40: =ABS(F40) -> 0 | F40: =C40-D40 -> 0
A41: =报表格式!L40 -> 其中：用以前年度含量工资结余弥补利润 | B41: 36 | D41: =未审PL!C41 -> 0 | E41: =ABS(F41) -> 0 | F41: =C41-D41 -> 0
...

Sheet 账项调整
A1: =IF((L2-(TB资产!C63+TB负债!C63+TB损益!C75)-IF(COUNTIF(E5:E666,"未分配利润")>=1,VLOOKUP("未分配利润",E5:J666,6,0),0))<0.005,"账项调整事项汇总表","调整事项未全部链入试算平衡表，请检查调整科目是否为报表项目!") -> 账项调整事项汇总表 | K1: =SUM(L2:L3) -> 0 | N1: code | O1: 报表项目
A2: =CONCATENATE("客户名称：",参数!D3) -> 客户名称： | E2: =CONCATENATE("编制人：",参数!D17) -> 编制人： | H2: =CONCATENATE("日期：",TEXT(NOW(),"yyyy.mm.dd")) -> 日期：2023.08.14 | J2: 索引： | K2: 借方调整累计 | L2: =SUMIF(E5:E65536,"?*",J5:J65536) -> 0
A3: =CONCATENATE("会计期间：",参数!D10) -> 会计期间：2007年度 | E3: =CONCATENATE("复核人：",参数!D18) -> 复核人： | H3: 日期： | J3: 页码： | K3: 贷方调整累计 | L3: =SUMIF(H5:H65536,"?*",J5:J65536) -> 0
A4: 序号 | B4: 索引号 | C4: 调整说明 | D4: code | E4: 借方科目 | F4: 二级科目 | G4: code | H4: 贷方科目 | I4: 二级科目 | J4: 金额 | L4: =L2-L3 -> 0
A5: 1 | E5: =IF(D5=0,"",VLOOKUP(D5,$N:$O,2,0)) | H5: =IF(G5=0,"",VLOOKUP(G5,$N:$O,2,0)) | K5: 本表可根据需要插入行， | N5: =报表格式!Z5 -> 0 | O5: =报表格式!AA5 -> 流动资产：
E6: =IF(D6=0,"",VLOOKUP(D6,$N:$O,2,0)) | H6: =IF(G6=0,"",VLOOKUP(G6,$N:$O,2,0)) | K6: 请勿删除行。 | N6: =报表格式!Z6 -> G123 | O6: =报表格式!AA6 -> 货币资金
E7: =IF(D7=0,"",VLOOKUP(D7,$N:$O,2,0)) | H7: =IF(G7=0,"",VLOOKUP(G7,$N:$O,2,0)) | N7: =报表格式!Z7 -> F1 | O7: =报表格式!AA7 -> 短期投资
E8: =IF(D8=0,"",VLOOKUP(D8,$N:$O,2,0)) | H8: =IF(G8=0,"",VLOOKUP(G8,$N:$O,2,0)) | N8: =报表格式!Z8 -> D3 | O8: =报表格式!AA8 -> 应收票据
J9: =IF(ABS((SUMIF(E5:E8,"?*",J5:J8)-SUMIF(H5:H8,"?*",J5:J8)))<0.005,"","借贷不等") | N9: =报表格式!Z9 -> F5 | O9: =报表格式!AA9 -> 应收股利
A10: 2 | E10: =IF(D10=0,"",VLOOKUP(D10,$N:$O,2,0)) | H10: =IF(G10=0,"",VLOOKUP(G10,$N:$O,2,0)) | N10: =报表格式!Z10 -> F6 | O10: =报表格式!AA10 -> 应收利息
E11: =IF(D11=0,"",VLOOKUP(D11,$N:$O,2,0)) | H11: =IF(G11=0,"",VLOOKUP(G11,$N:$O,2,0)) | N11: =报表格式!Z11 -> D1 | O11: =报表格式!AA11 -> 应收账款
E12: =IF(D12=0,"",VLOOKUP(D12,$N:$O,2,0)) | H12: =IF(G12=0,"",VLOOKUP(G12,$N:$O,2,0)) | N12: =报表格式!Z12 -> G4 | O12: =报表格式!AA12 -> 其他应收款
E13: =IF(D13=0,"",VLOOKUP(D13,$N:$O,2,0)) | H13: =IF(G13=0,"",VLOOKUP(G13,$N:$O,2,0)) | N13: =报表格式!Z13 -> E3 | O13: =报表格式!AA13 -> 预付账款
J14: =IF(ABS((SUMIF(E10:E13,"?*",J10:J13)-SUMIF(H10:H13,"?*",J10:J13)))<0.005,"","借贷不等") | N14: =报表格式!Z14 -> 0 | O14: =报表格式!AA14 -> 期货保证金
A15: 3 | E15: =IF(D15=0,"",VLOOKUP(D15,$N:$O,2,0)) | H15: =IF(G15=0,"",VLOOKUP(G15,$N:$O,2,0)) | N15: =报表格式!Z15 -> I1 | O15: =报表格式!AA15 -> 应收补贴款
E16: =IF(D16=0,"",VLOOKUP(D16,$N:$O,2,0)) | H16: =IF(G16=0,"",VLOOKUP(G16,$N:$O,2,0)) | N16: =报表格式!Z16 -> 0 | O16: =报表格式!AA16 -> 应收出口退税
E17: =IF(D17=0,"",VLOOKUP(D17,$N:$O,2,0)) | H17: =IF(G17=0,"",VLOOKUP(G17,$N:$O,2,0)) | N17: =报表格式!Z17 -> E1 | O17: =报表格式!AA17 -> 存货
E18: =IF(D18=0,"",VLOOKUP(D18,$N:$O,2,0)) | H18: =IF(G18=0,"",VLOOKUP(G18,$N:$O,2,0)) | N18: =报表格式!Z18 -> 0 | O18: =报表格式!AA18 -> 0
J19: =IF(ABS((SUMIF(E15:E18,"?*",J15:J18)-SUMIF(H15:H18,"?*",J15:J18)))<0.005,"","借贷不等") | N19: =报表格式!Z19 -> 0 | O19: =报表格式!AA19 -> 0
A20: 4 | E20: =IF(D20=0,"",VLOOKUP(D20,$N:$O,2,0)) | H20: =IF(G20=0,"",VLOOKUP(G20,$N:$O,2,0)) | N20: =报表格式!Z20 -> I4 | O20: =报表格式!AA20 -> 待摊费用
E21: =IF(D21=0,"",VLOOKUP(D21,$N:$O,2,0)) | H21: =IF(G21=0,"",VLOOKUP(G21,$N:$O,2,0)) | N21: =报表格式!Z21 -> I6 | O21: =报表格式!AA21 -> 待处理流动资产净损失
E22: =IF(D22=0,"",VLOOKUP(D22,$N:$O,2,0)) | H22: =IF(G22=0,"",VLOOKUP(G22,$N:$O,2,0)) | N22: =报表格式!Z22 -> 0 | O22: =报表格式!AA22 -> 一年内到期的长期债权投资
E23: =IF(D23=0,"",VLOOKUP(D23,$N:$O,2,0)) | H23: =IF(G23=0,"",VLOOKUP(G23,$N:$O,2,0)) | N23: =报表格式!Z23 -> 0 | O23: =报表格式!AA23 -> 其他流动资产
J24: =IF(ABS((SUMIF(E20:E23,"?*",J20:J23)-SUMIF(H20:H23,"?*",J20:J23)))<0.005,"","借贷不等") | N24: =报表格式!Z24 -> 0 | O24: =报表格式!AA24 -> 0
A25: 5 | E25: =IF(D25=0,"",VLOOKUP(D25,$N:$O,2,0)) | H25: =IF(G25=0,"",VLOOKUP(G25,$N:$O,2,0)) | N25: =报表格式!Z25 -> 0 | O25: =报表格式!AA25 -> 0
E26: =IF(D26=0,"",VLOOKUP(D26,$N:$O,2,0)) | H26: =IF(G26=0,"",VLOOKUP(G26,$N:$O,2,0)) | N26: =报表格式!Z26 -> 0 | O26: =报表格式!AA26 -> 流动资产合计
E27: =IF(D27=0,"",VLOOKUP(D27,$N:$O,2,0)) | H27: =IF(G27=0,"",VLOOKUP(G27,$N:$O,2,0)) | N27: =报表格式!Z27 -> 0 | O27: =报表格式!AA27 -> 0
E28: =IF(D28=0,"",VLOOKUP(D28,$N:$O,2,0)) | H28: =IF(G28=0,"",VLOOKUP(G28,$N:$O,2,0)) | N28: =报表格式!Z28 -> 0 | O28: =报表格式!AA28 -> 长期投资：
J29: =IF(ABS((SUMIF(E25:E28,"?*",J25:J28)-SUMIF(H25:H28,"?*",J25:J28)))<0.005,"","借贷不等") | N29: =报表格式!Z29 -> F2 | O29: =报表格式!AA29 -> 长期股权投资
A30: 6 | E30: =IF(D30=0,"",VLOOKUP(D30,$N:$O,2,0)) | H30: =IF(G30=0,"",VLOOKUP(G30,$N:$O,2,0)) | N30: =报表格式!Z30 -> F3 | O30: =报表格式!AA30 -> 长期债权投资
E31: =IF(D31=0,"",VLOOKUP(D31,$N:$O,2,0)) | H31: =IF(G31=0,"",VLOOKUP(G31,$N:$O,2,0)) | N31: =报表格式!Z31 -> 0 | O31: =报表格式!AA31 -> 合并价差
E32: =IF(D32=0,"",VLOOKUP(D32,$N:$O,2,0)) | H32: =IF(G32=0,"",VLOOKUP(G32,$N:$O,2,0)) | N32: =报表格式!Z32 -> 0 | O32: =报表格式!AA32 -> 0
E33: =IF(D33=0,"",VLOOKUP(D33,$N:$O,2,0)) | H33: =IF(G33=0,"",VLOOKUP(G33,$N:$O,2,0)) | N33: =报表格式!Z33 -> 0 | O33: =报表格式!AA33 -> 0
J34: =IF(ABS((SUMIF(E30:E33,"?*",J30:J33)-SUMIF(H30:H33,"?*",J30:J33)))<0.005,"","借贷不等") | N34: =报表格式!Z34 -> 0 | O34: =报表格式!AA34 -> 长期投资合计
A35: 7 | E35: =IF(D35=0,"",VLOOKUP(D35,$N:$O,2,0)) | H35: =IF(G35=0,"",VLOOKUP(G35,$N:$O,2,0)) | N35: =报表格式!Z35 -> 0 | O35: =报表格式!AA35 -> 0
E36: =IF(D36=0,"",VLOOKUP(D36,$N:$O,2,0)) | H36: =IF(G36=0,"",VLOOKUP(G36,$N:$O,2,0)) | N36: =报表格式!Z36 -> 0 | O36: =报表格式!AA36 -> 固定资产：
E37: =IF(D37=0,"",VLOOKUP(D37,$N:$O,2,0)) | H37: =IF(G37=0,"",VLOOKUP(G37,$N:$O,2,0)) | N37: =报表格式!Z37 -> H1 | O37: =报表格式!AA37 -> 固定资产原价
E38: =IF(D38=0,"",VLOOKUP(D38,$N:$O,2,0)) | H38: =IF(G38=0,"",VLOOKUP(G38,$N:$O,2,0)) | N38: =报表格式!Z38 -> H2 | O38: =报表格式!AA38 -> 累计折旧
J39: =IF(ABS((SUMIF(E35:E38,"?*",J35:J38)-SUMIF(H35:H38,"?*",J35:J38)))<0.005,"","借贷不等") | N39: =报表格式!Z39 -> 0 | O39: =报表格式!AA39 -> 0
A40: 8 | E40: =IF(D40=0,"",VLOOKUP(D40,$N:$O,2,0)) | H40: =IF(G40=0,"",VLOOKUP(G40,$N:$O,2,0)) | N40: =报表格式!Z40 -> H3 | O40: =报表格式!AA40 -> 固定资产减值准备
...

Sheet 报表调整
A1: =IF((L2-(TB资产!E63+TB负债!E63+TB损益!E75)-IF(COUNTIF(E5:E666,"未分配利润")>=1,VLOOKUP("未分配利润",E5:J666,6,0),0))<0.005,"报表调整事项汇总表","调整事项未全部链入试算平衡表，请检查调整科目是否为报表项目!") -> 报表调整事项汇总表 | K1: =SUM(L2:L3) -> 0 | N1: code | O1: 报表项目
A2: =CONCATENATE("客户名称：",参数!D3) -> 客户名称： | E2: =CONCATENATE("编制人：",参数!D17) -> 编制人： | H2: =CONCATENATE("日期：",TEXT(NOW(),"yyyy.mm.dd")) -> 日期：2023.08.14 | J2: 索引： | K2: 借方调整累计 | L2: =SUMIF(E5:E65536,"?*",J5:J65536) -> 0
A3: =CONCATENATE("会计期间：",参数!D10) -> 会计期间：2007年度 | E3: =CONCATENATE("复核人：",参数!D18) -> 复核人： | H3: 日期： | J3: 页码： | K3: 贷方调整累计 | L3: =SUMIF(H5:H65536,"?*",J5:J65536) -> 0
A4: 序号 | B4: 索引号 | C4: 调整说明 | D4: code | E4: 借方科目 | F4: 二级科目 | G4: code | H4: 贷方科目 | I4: 二级科目 | J4: 金额 | L4: =L2-L3 -> 0
A5: 1 | E5: =IF(D5=0,"",VLOOKUP(D5,$N:$O,2,0)) | H5: =IF(G5=0,"",VLOOKUP(G5,$N:$O,2,0)) | K5: 本表可根据需要插入行， | N5: =报表格式!Z5 -> 0 | O5: =报表格式!AA5 -> 流动资产：
E6: =IF(D6=0,"",VLOOKUP(D6,$N:$O,2,0)) | H6: =IF(G6=0,"",VLOOKUP(G6,$N:$O,2,0)) | K6: 请勿删除行。 | N6: =报表格式!Z6 -> G123 | O6: =报表格式!AA6 -> 货币资金
E7: =IF(D7=0,"",VLOOKUP(D7,$N:$O,2,0)) | H7: =IF(G7=0,"",VLOOKUP(G7,$N:$O,2,0)) | N7: =报表格式!Z7 -> F1 | O7: =报表格式!AA7 -> 短期投资
E8: =IF(D8=0,"",VLOOKUP(D8,$N:$O,2,0)) | H8: =IF(G8=0,"",VLOOKUP(G8,$N:$O,2,0)) | N8: =报表格式!Z8 -> D3 | O8: =报表格式!AA8 -> 应收票据
J9: =IF(ABS((SUMIF(E5:E8,"?*",J5:J8)-SUMIF(H5:H8,"?*",J5:J8)))<0.005,"","借贷不等") | N9: =报表格式!Z9 -> F5 | O9: =报表格式!AA9 -> 应收股利
A10: 2 | E10: =IF(D10=0,"",VLOOKUP(D10,$N:$O,2,0)) | H10: =IF(G10=0,"",VLOOKUP(G10,$N:$O,2,0)) | N10: =报表格式!Z10 -> F6 | O10: =报表格式!AA10 -> 应收利息
E11: =IF(D11=0,"",VLOOKUP(D11,$N:$O,2,0)) | H11: =IF(G11=0,"",VLOOKUP(G11,$N:$O,2,0)) | N11: =报表格式!Z11 -> D1 | O11: =报表格式!AA11 -> 应收账款
E12: =IF(D12=0,"",VLOOKUP(D12,$N:$O,2,0)) | H12: =IF(G12=0,"",VLOOKUP(G12,$N:$O,2,0)) | N12: =报表格式!Z12 -> G4 | O12: =报表格式!AA12 -> 其他应收款
E13: =IF(D13=0,"",VLOOKUP(D13,$N:$O,2,0)) | H13: =IF(G13=0,"",VLOOKUP(G13,$N:$O,2,0)) | N13: =报表格式!Z13 -> E3 | O13: =报表格式!AA13 -> 预付账款
J14: =IF(ABS((SUMIF(E10:E13,"?*",J10:J13)-SUMIF(H10:H13,"?*",J10:J13)))<0.005,"","借贷不等") | N14: =报表格式!Z14 -> 0 | O14: =报表格式!AA14 -> 期货保证金
A15: 3 | E15: =IF(D15=0,"",VLOOKUP(D15,$N:$O,2,0)) | H15: =IF(G15=0,"",VLOOKUP(G15,$N:$O,2,0)) | N15: =报表格式!Z15 -> I1 | O15: =报表格式!AA15 -> 应收补贴款
E16: =IF(D16=0,"",VLOOKUP(D16,$N:$O,2,0)) | H16: =IF(G16=0,"",VLOOKUP(G16,$N:$O,2,0)) | N16: =报表格式!Z16 -> 0 | O16: =报表格式!AA16 -> 应收出口退税
E17: =IF(D17=0,"",VLOOKUP(D17,$N:$O,2,0)) | H17: =IF(G17=0,"",VLOOKUP(G17,$N:$O,2,0)) | N17: =报表格式!Z17 -> E1 | O17: =报表格式!AA17 -> 存货
E18: =IF(D18=0,"",VLOOKUP(D18,$N:$O,2,0)) | H18: =IF(G18=0,"",VLOOKUP(G18,$N:$O,2,0)) | N18: =报表格式!Z18 -> 0 | O18: =报表格式!AA18 -> 0
J19: =IF(ABS((SUMIF(E15:E18,"?*",J15:J18)-SUMIF(H15:H18,"?*",J15:J18)))<0.005,"","借贷不等") | N19: =报表格式!Z19 -> 0 | O19: =报表格式!AA19 -> 0
A20: 4 | E20: =IF(D20=0,"",VLOOKUP(D20,$N:$O,2,0)) | H20: =IF(G20=0,"",VLOOKUP(G20,$N:$O,2,0)) | N20: =报表格式!Z20 -> I4 | O20: =报表格式!AA20 -> 待摊费用
E21: =IF(D21=0,"",VLOOKUP(D21,$N:$O,2,0)) | H21: =IF(G21=0,"",VLOOKUP(G21,$N:$O,2,0)) | N21: =报表格式!Z21 -> I6 | O21: =报表格式!AA21 -> 待处理流动资产净损失
E22: =IF(D22=0,"",VLOOKUP(D22,$N:$O,2,0)) | H22: =IF(G22=0,"",VLOOKUP(G22,$N:$O,2,0)) | N22: =报表格式!Z22 -> 0 | O22: =报表格式!AA22 -> 一年内到期的长期债权投资
E23: =IF(D23=0,"",VLOOKUP(D23,$N:$O,2,0)) | H23: =IF(G23=0,"",VLOOKUP(G23,$N:$O,2,0)) | N23: =报表格式!Z23 -> 0 | O23: =报表格式!AA23 -> 其他流动资产
J24: =IF(ABS((SUMIF(E20:E23,"?*",J20:J23)-SUMIF(H20:H23,"?*",J20:J23)))<0.005,"","借贷不等") | N24: =报表格式!Z24 -> 0 | O24: =报表格式!AA24 -> 0
A25: 5 | E25: =IF(D25=0,"",VLOOKUP(D25,$N:$O,2,0)) | H25: =IF(G25=0,"",VLOOKUP(G25,$N:$O,2,0)) | N25: =报表格式!Z25 -> 0 | O25: =报表格式!AA25 -> 0
E26: =IF(D26=0,"",VLOOKUP(D26,$N:$O,2,0)) | H26: =IF(G26=0,"",VLOOKUP(G26,$N:$O,2,0)) | N26: =报表格式!Z26 -> 0 | O26: =报表格式!AA26 -> 流动资产合计
E27: =IF(D27=0,"",VLOOKUP(D27,$N:$O,2,0)) | H27: =IF(G27=0,"",VLOOKUP(G27,$N:$O,2,0)) | N27: =报表格式!Z27 -> 0 | O27: =报表格式!AA27 -> 0
E28: =IF(D28=0,"",VLOOKUP(D28,$N:$O,2,0)) | H28: =IF(G28=0,"",VLOOKUP(G28,$N:$O,2,0)) | N28: =报表格式!Z28 -> 0 | O28: =报表格式!AA28 -> 长期投资：
J29: =IF(ABS((SUMIF(E25:E28,"?*",J25:J28)-SUMIF(H25:H28,"?*",J25:J28)))<0.005,"","借贷不等") | N29: =报表格式!Z29 -> F2 | O29: =报表格式!AA29 -> 长期股权投资
A30: 6 | E30: =IF(D30=0,"",VLOOKUP(D30,$N:$O,2,0)) | H30: =IF(G30=0,"",VLOOKUP(G30,$N:$O,2,0)) | N30: =报表格式!Z30 -> F3 | O30: =报表格式!AA30 -> 长期债权投资
E31: =IF(D31=0,"",VLOOKUP(D31,$N:$O,2,0)) | H31: =IF(G31=0,"",VLOOKUP(G31,$N:$O,2,0)) | N31: =报表格式!Z31 -> 0 | O31: =报表格式!AA31 -> 合并价差
E32: =IF(D32=0,"",VLOOKUP(D32,$N:$O,2,0)) | H32: =IF(G32=0,"",VLOOKUP(G32,$N:$O,2,0)) | N32: =报表格式!Z32 -> 0 | O32: =报表格式!AA32 -> 0
E33: =IF(D33=0,"",VLOOKUP(D33,$N:$O,2,0)) | H33: =IF(G33=0,"",VLOOKUP(G33,$N:$O,2,0)) | N33: =报表格式!Z33 -> 0 | O33: =报表格式!AA33 -> 0
J34: =IF(ABS((SUMIF(E30:E33,"?*",J30:J33)-SUMIF(H30:H33,"?*",J30:J33)))<0.005,"","借贷不等") | N34: =报表格式!Z34 -> 0 | O34: =报表格式!AA34 -> 长期投资合计
A35: 7 | E35: =IF(D35=0,"",VLOOKUP(D35,$N:$O,2,0)) | H35: =IF(G35=0,"",VLOOKUP(G35,$N:$O,2,0)) | N35: =报表格式!Z35 -> 0 | O35: =报表格式!AA35 -> 0
E36: =IF(D36=0,"",VLOOKUP(D36,$N:$O,2,0)) | H36: =IF(G36=0,"",VLOOKUP(G36,$N:$O,2,0)) | N36: =报表格式!Z36 -> 0 | O36: =报表格式!AA36 -> 固定资产：
E37: =IF(D37=0,"",VLOOKUP(D37,$N:$O,2,0)) | H37: =IF(G37=0,"",VLOOKUP(G37,$N:$O,2,0)) | N37: =报表格式!Z37 -> H1 | O37: =报表格式!AA37 -> 固定资产原价
E38: =IF(D38=0,"",VLOOKUP(D38,$N:$O,2,0)) | H38: =IF(G38=0,"",VLOOKUP(G38,$N:$O,2,0)) | N38: =报表格式!Z38 -> H2 | O38: =报表格式!AA38 -> 累计折旧
J39: =IF(ABS((SUMIF(E35:E38,"?*",J35:J38)-SUMIF(H35:H38,"?*",J35:J38)))<0.005,"","借贷不等") | N39: =报表格式!Z39 -> 0 | O39: =报表格式!AA39 -> 0
A40: 8 | E40: =IF(D40=0,"",VLOOKUP(D40,$N:$O,2,0)) | H40: =IF(G40=0,"",VLOOKUP(G40,$N:$O,2,0)) | N40: =报表格式!Z40 -> H3 | O40: =报表格式!AA40 -> 固定资产减值准备
...

Sheet  
A1: 报表数值 | B1: 逻辑值 | C1: 判断值 | E1: =NOW() -> 45152.7
A3: =SUM(#REF!)+SUM(#REF!)+SUM(#REF!)+SUM(#REF!)+SUM(#REF!)+SUM(#REF!) -> #REF! | B3: =ISERROR(A3) -> TRUE | C3: =IF(B3=TRUE,"您误使用了剪切或拖拽功能，请用撤销键撤销此操作!!",0) -> 您误使用了剪切或拖拽功能，请用撤销键撤销此操作!!
A5: =IF(ABS(' '!E5)>0.0049,"注意！报表项目栏有空格，试算平衡表将不能统计该栏数据！请填写报表项目名称。",IF(ABS(' '!F5)<0.005,IF(ABS(' '!G5-' '!H5)<0.005,IF(#REF!="调整金额合计",IF(ABS(#REF!)<0.005,IF(ABS(#REF!)<0.005,IF(ABS(#REF!)<0.005,IF(#REF!-#REF!=0,""," 审计调整分录使本年净利润净增加："),"客户同意调整的分录不完整,使期初未分配利润与上期报表数不等。请继续调整！差额:"),"调整分录已使本年“年初未分配利润”和上年“末分配利润”不等。请作进一步调整。"),"调整分录错误！上年的报表项目不能与本年的报表项目套在一起出分录，请纠正；或者已输入的会计分录名称在“02报表格式”中已被修改，请手工作相应修改。"),""),"客户同意调整的分录不平，将导致客户报出会计报表不平，请检查!!差额为："),"“以前年度损益调整”应进一步结转入“年初未分配利润”等科目,借贷相抵后差额为：")) -> #REF! | B5: =IF(ABS(' '!E5)>0.0049,"",IF(ABS(' '!F5)<0.005,IF(ABS(' '!G5-' '!H5)<0.005,IF(#REF!="调整金额合计",IF(ABS(#REF!)<0.005,IF(ABS(#REF!)<0.005,IF(ABS(#REF!)<0.005,IF(#REF!-#REF!=0,"",#REF!-#REF!),#REF!),#REF!),#REF!),""),' '!G5-' '!H5),ABS(' '!F5))) -> #REF! | C5: =SUMIF(#REF!,"",#REF!) -> #REF! | D5: =SUMIF(#REF!,"",#REF!) -> #REF! | E5: =ABS(' '!C5)+ABS(' '!D5) -> #REF! | F5: =SUMIF(#REF!,"以前年度损益调整",#REF!)-SUMIF(#REF!,"以前年度损益调整",#REF!) -> #REF! | G5: =SUMIF(#REF!,"Y",#REF!) -> #REF! | H5: =SUMIF(#REF!,"Y",#REF!) -> #REF! | K5: =CONCATENATE("被审计单位：",参数!D3) -> 被审计单位： | L5: =IF(A8=0,CONCATENATE(A5,B5),"请注意，您在第"&(A7-1)&"行之后输入了数据，本系统无法汇总到这些数据。请撤消此操作，然后在第"&(A7-1)&"行之前插入空白行，并在这些空白行中重新输入或粘贴数据。") -> #REF! | Q5: =IF(ABS(#REF!-#REF!)<0.005,"调整金额合计","调整金额借贷不等,请检查!差额为:") -> #REF! | S5: =IF(#REF!=#REF!,"",#REF!-#REF!) -> #REF! | U5: =CONCATENATE("会计期间： ",参数!D10) -> 会计期间： 2007年度
A6: =IF(#REF!=0,IF(#REF!=0,IF(#REF!=0,IF(#REF!=0,"", "客户同意调整的分录不平，导致客户报出报表不平，请检查!!差额为："),"客户同意调整的分录不平，导致客户报出报表不平，请检查!!差额为："),"调整分录使试算平衡表中“现金及现金等价物净增加额”上下不等,差额为："),"调整分录使试算平衡表中“经营活动产生的现金流量”上下不等,差额为：") -> #REF! | I6: =IF(#REF!=0,IF(#REF!=0,IF(#REF!=0,IF(#REF!=0,"",#REF!),#REF!),#REF!),#REF!) -> #REF! | J6: =CONCATENATE(A6,I6) -> #REF! | N6: =CONCATENATE("调整事项使现金净流量增加：",ROUND(#REF!-#REF!,2),"元。其中，","调增",ROUND(#REF!,2),"元，调减",ROUND(#REF!,2),"元。") -> #REF!
A7: =ROW(#REF!) -> #REF!
A8: =SUM(#REF!) -> #REF!

Sheet CF调整
A1: 现金流量表调整
A2: =参数!D10 -> 2007年度
A3: 项 目 | B3: 原报金额 | C3: 调整金额 | D3: 审定金额
A5: 一、经营活动产生的现金流量
A6: 销售商品、提供劳务收到的现金 | B6: =未审CF!C7 -> 0 | D6: =SUM(B6:C6) -> 0
A7: 收到的税费返还 | B7: =未审CF!C8 -> 0 | D7: =SUM(B7:C7) -> 0
A8: 收到的其他与经营活动有关的现金 | B8: =未审CF!C9 -> 0 | D8: =SUM(B8:C8) -> 0
A9: 现金流入小计 | B9: =SUM(B6:B8) -> 0 | C9: =SUM(C6:C8) -> 0 | D9: =SUM(D6:D8) -> 0
A10: 购买商品、接受劳务支付的现金 | B10: =未审CF!C12 -> 0 | D10: =SUM(B10:C10) -> 0
A11: 支付给职工以及为职工支付的现金 | B11: =未审CF!C13 -> 0 | D11: =SUM(B11:C11) -> 0
A12: 支付的各项税费 | B12: =未审CF!C14 -> 0 | D12: =SUM(B12:C12) -> 0
A13: 支付的其他与经营活动有关的现金 | B13: =未审CF!C15 -> 0 | D13: =SUM(B13:C13) -> 0
A14: 现金流出小计 | B14: =B10+B11+B12+B13 -> 0 | C14: =C10+C11+C12+C13 -> 0 | D14: =D10+D11+D12+D13 -> 0
A15: 经营活动产生的现金流量净额 | B15: =B9-B14 -> 0 | C15: =C9-C14 -> 0 | D15: =D9-D14 -> 0
A17: 二、投资活动产生的现金流量：
A18: 收回投资所收到的现金 | B18: =未审CF!C20 -> 0 | D18: =SUM(B18:C18) -> 0
A19: 其中：出售子公司所收到的现金 | B19: =未审CF!C21 -> 0 | D19: =SUM(B19:C19) -> 0
A20: 取得投资收益所收到的现金 | B20: =未审CF!C22 -> 0 | D20: =SUM(B20:C20) -> 0
A21: 处置固定资产、无形资产和其他长期资产所收回的现金净额 | B21: =未审CF!C23 -> 0 | D21: =SUM(B21:C21) -> 0
A22: 收到的其他与投资活动有关的现金 | B22: =未审CF!C24 -> 0 | D22: =SUM(B22:C22) -> 0
A23: 现金流入小计 | B23: =SUM(B18:B22)-B19 -> 0 | C23: =SUM(C18:C22)-C19 -> 0 | D23: =SUM(D18:D22)-D19 -> 0
A24: 购建固定资产、无形资产和其他长期资产所支付的现金 | B24: =未审CF!C27 -> 0 | D24: =SUM(B24:C24) -> 0
A25: 投资所支付的现金 | B25: =未审CF!C28 -> 0 | D25: =SUM(B25:C25) -> 0
A26: 其中：购买子公司所支付的现金 | B26: =未审CF!C29 -> 0 | D26: =SUM(B26:C26) -> 0
A27: 支付的其他与投资活动有关的现金 | B27: =未审CF!C30 -> 0 | D27: =SUM(B27:C27) -> 0
A28: 现金流出小计 | B28: =SUM(B24:B27)-B26 -> 0 | C28: =SUM(C24:C27)-C26 -> 0 | D28: =SUM(D24:D27)-D26 -> 0
A29: 投资活动产生的现金流量净额 | B29: =B23-B28 -> 0 | C29: =C23-C28 -> 0 | D29: =D23-D28 -> 0
A31: 三、筹资活动产生的现金流量：
A32: 吸收投资所收到的现金 | B32: =未审CF!C35 -> 0 | D32: =SUM(B32:C32) -> 0
A33: 借款所收到的现金 | B33: =未审CF!C36 -> 0 | D33: =SUM(B33:C33) -> 0
A34: 收到的其他与筹资活动有关的现金 | B34: =未审CF!C37 -> 0 | D34: =SUM(B34:C34) -> 0
A35: 现金流入小计 | B35: =SUM(B32:B34) -> 0 | C35: =SUM(C32:C34) -> 0 | D35: =SUM(D32:D34) -> 0
A36: 偿还债务所支付的现金 | B36: =未审CF!C40 -> 0 | D36: =SUM(B36:C36) -> 0
A37: 分配股利、利润或偿付利息所支付的现金 | B37: =未审CF!C41 -> 0 | D37: =SUM(B37:C37) -> 0
A38: 支付的其他与筹资活动有关的现金 | B38: =未审CF!C42 -> 0 | D38: =SUM(B38:C38) -> 0
A39: 现金流出小计 | B39: =B36+B37+B38 -> 0 | C39: =C36+C37+C38 -> 0 | D39: =D36+D37+D38 -> 0
A40: 筹资活动产生的现金流量净额 | B40: =B35-B39 -> 0 | C40: =C35-C39 -> 0 | D40: =D35-D39 -> 0
A42: 四、汇率变动对现金的影响 | B42: =未审CF!C46 -> 0 | D42: =SUM(B42:C42) -> 0
A44: 五、现金及现金等价物净增加额 | B44: =B15+B29+B40+B42 -> 0 | C44: =C15+C29+C40+C42 -> 0 | D44: =D15+D29+D40+D42 -> 0
A46: 1、将净利润调节为经营活动现金流量：
...

Sheet TB资产
A1: 资产负债表试算平衡
A2: =CONCATENATE("客户名称：",参数!D3) -> 客户名称： | C2: =CONCATENATE("编制：",参数!D17) -> 编制： | E2: =CONCATENATE("复核：",参数!D18) -> 复核： | I2: 索引：
A3: =CONCATENATE("会计时点：",TEXT(参数!D12,"yyyy.mm.dd")) -> 会计时点：2007.12.31 | C3: =CONCATENATE("日期：",TEXT(NOW(),"yyyy.mm.dd")) -> 日期：2023.08.14 | E3: 日期： | I3: 分页：
A4: =IF((ROUND(I62,2))=(ROUND(TB负债!I62,2)),"资 产","报表未调平!") -> 资 产 | B4: 企业原报数 | C4: 账项调整 | E4: 报表调整 | G4: 调后数 | H4: 剥离调整 | I4: 审定数
C5: 借方 | D5: 贷方 | E5: 借方 | F5: 贷方
A6: =报表格式!B5 -> 流动资产：
A7: =报表格式!B6 -> 货币资金 | B7: =未审BS!D7 -> 0 | C7: =SUMIF(账项调整!$E$5:$E$65536,IF(OR(MID(TRIM($A7),2,1)="：",MID(TRIM($A7),2,1)="、"),REPLACEB(TRIM($A7),1,4,""),TRIM($A7)),账项调整!$J$5:$J$65536) -> 0 | D7: =SUMIF(账项调整!$H$5:$H$65536,IF(OR(MID(TRIM($A7),2,1)="：",MID(TRIM($A7),2,1)="、"),REPLACEB(TRIM($A7),1,4,""),TRIM($A7)),账项调整!$J$5:$J$65536) -> 0 | E7: =SUMIF(报表调整!$E$5:$E$65536,IF(OR(MID(TRIM($A7),2,1)="：",MID(TRIM($A7),2,1)="、"),REPLACEB(TRIM($A7),1,4,""),TRIM($A7)),报表调整!$J$5:$J$65536) -> 0 | F7: =SUMIF(报表调整!$H$5:$H$65536,IF(OR(MID(TRIM($A7),2,1)="：",MID(TRIM($A7),2,1)="、"),REPLACEB(TRIM($A7),1,4,""),TRIM($A7)),报表调整!$J$5:$J$65536) -> 0 | G7: =B7+C7+E7-D7-F7 -> 0 | I7: =SUM(G7:H7) -> 0
A8: =报表格式!B7 -> 短期投资 | B8: =未审BS!D8 -> 0 | C8: =SUMIF(账项调整!$E$5:$E$65536,IF(OR(MID(TRIM($A8),2,1)="：",MID(TRIM($A8),2,1)="、"),REPLACEB(TRIM($A8),1,4,""),TRIM($A8)),账项调整!$J$5:$J$65536) -> 0 | D8: =SUMIF(账项调整!$H$5:$H$65536,IF(OR(MID(TRIM($A8),2,1)="：",MID(TRIM($A8),2,1)="、"),REPLACEB(TRIM($A8),1,4,""),TRIM($A8)),账项调整!$J$5:$J$65536) -> 0 | E8: =SUMIF(报表调整!$E$5:$E$65536,IF(OR(MID(TRIM($A8),2,1)="：",MID(TRIM($A8),2,1)="、"),REPLACEB(TRIM($A8),1,4,""),TRIM($A8)),报表调整!$J$5:$J$65536) -> 0 | F8: =SUMIF(报表调整!$H$5:$H$65536,IF(OR(MID(TRIM($A8),2,1)="：",MID(TRIM($A8),2,1)="、"),REPLACEB(TRIM($A8),1,4,""),TRIM($A8)),报表调整!$J$5:$J$65536) -> 0 | G8: =B8+C8+E8-D8-F8 -> 0 | I8: =SUM(G8:H8) -> 0
A9: =报表格式!B8 -> 应收票据 | B9: =未审BS!D9 -> 0 | C9: =SUMIF(账项调整!$E$5:$E$65536,IF(OR(MID(TRIM($A9),2,1)="：",MID(TRIM($A9),2,1)="、"),REPLACEB(TRIM($A9),1,4,""),TRIM($A9)),账项调整!$J$5:$J$65536) -> 0 | D9: =SUMIF(账项调整!$H$5:$H$65536,IF(OR(MID(TRIM($A9),2,1)="：",MID(TRIM($A9),2,1)="、"),REPLACEB(TRIM($A9),1,4,""),TRIM($A9)),账项调整!$J$5:$J$65536) -> 0 | E9: =SUMIF(报表调整!$E$5:$E$65536,IF(OR(MID(TRIM($A9),2,1)="：",MID(TRIM($A9),2,1)="、"),REPLACEB(TRIM($A9),1,4,""),TRIM($A9)),报表调整!$J$5:$J$65536) -> 0 | F9: =SUMIF(报表调整!$H$5:$H$65536,IF(OR(MID(TRIM($A9),2,1)="：",MID(TRIM($A9),2,1)="、"),REPLACEB(TRIM($A9),1,4,""),TRIM($A9)),报表调整!$J$5:$J$65536) -> 0 | G9: =B9+C9+E9-D9-F9 -> 0 | I9: =SUM(G9:H9) -> 0
A10: =报表格式!B9 -> 应收股利 | B10: =未审BS!D10 -> 0 | C10: =SUMIF(账项调整!$E$5:$E$65536,IF(OR(MID(TRIM($A10),2,1)="：",MID(TRIM($A10),2,1)="、"),REPLACEB(TRIM($A10),1,4,""),TRIM($A10)),账项调整!$J$5:$J$65536) -> 0 | D10: =SUMIF(账项调整!$H$5:$H$65536,IF(OR(MID(TRIM($A10),2,1)="：",MID(TRIM($A10),2,1)="、"),REPLACEB(TRIM($A10),1,4,""),TRIM($A10)),账项调整!$J$5:$J$65536) -> 0 | E10: =SUMIF(报表调整!$E$5:$E$65536,IF(OR(MID(TRIM($A10),2,1)="：",MID(TRIM($A10),2,1)="、"),REPLACEB(TRIM($A10),1,4,""),TRIM($A10)),报表调整!$J$5:$J$65536) -> 0 | F10: =SUMIF(报表调整!$H$5:$H$65536,IF(OR(MID(TRIM($A10),2,1)="：",MID(TRIM($A10),2,1)="、"),REPLACEB(TRIM($A10),1,4,""),TRIM($A10)),报表调整!$J$5:$J$65536) -> 0 | G10: =B10+C10+E10-D10-F10 -> 0 | I10: =SUM(G10:H10) -> 0
A11: =报表格式!B10 -> 应收利息 | B11: =未审BS!D11 -> 0 | C11: =SUMIF(账项调整!$E$5:$E$65536,IF(OR(MID(TRIM($A11),2,1)="：",MID(TRIM($A11),2,1)="、"),REPLACEB(TRIM($A11),1,4,""),TRIM($A11)),账项调整!$J$5:$J$65536) -> 0 | D11: =SUMIF(账项调整!$H$5:$H$65536,IF(OR(MID(TRIM($A11),2,1)="：",MID(TRIM($A11),2,1)="、"),REPLACEB(TRIM($A11),1,4,""),TRIM($A11)),账项调整!$J$5:$J$65536) -> 0 | E11: =SUMIF(报表调整!$E$5:$E$65536,IF(OR(MID(TRIM($A11),2,1)="：",MID(TRIM($A11),2,1)="、"),REPLACEB(TRIM($A11),1,4,""),TRIM($A11)),报表调整!$J$5:$J$65536) -> 0 | F11: =SUMIF(报表调整!$H$5:$H$65536,IF(OR(MID(TRIM($A11),2,1)="：",MID(TRIM($A11),2,1)="、"),REPLACEB(TRIM($A11),1,4,""),TRIM($A11)),报表调整!$J$5:$J$65536) -> 0 | G11: =B11+C11+E11-D11-F11 -> 0 | I11: =SUM(G11:H11) -> 0
