Workbook
Name 调整类别: [1]试算!$C$7:$E$7

Sheet temp_temp__
C26: =SUM(C6)-SUM(C9,C12,C13,C14,C17,C21,C22)+SUM(C23,C24) -> 0

Sheet 说明
B2: 使用说明： | L2: 序号 | M2: 目录
L3: 1 | M3: 说明
B4: 1 | C4: 本工作簿基于2006年《企业会计准则》编制，并考虑了后续的更新。 | L4: 2 | M4: 参数
C5: 为方便阅读与核对，未删除利润分配项目。 | L5: 3 | M5: 报表格式
L6: 4 | M6: 未审报表
B7: 2 | C7: 本工作簿用于单项会计报表审计调整、试算平衡；未审报表及审定报表的横向、纵向、比率分析。 | L7: 5 | M7: 期初核对
L8: 6 | M8: TB
B9: 3 | C9: 本工作簿没有颜色的单元格可以根据需要进行修改， | L9: 7 | M9: TB(期初)
C10: 修改时，请在拟修改的单元格直接输入新的内容，请不要使用剪切或拖拽填充功能。 | L10: 8 | M10: 账项调整
L11: 9 | M11: 报表调整
B12: 4 | C12: 请在 | D12: “参数表” | E12: 中没有颜色的单元格中输入项目基本情况，其他工作表相应区域会随之改变。 | L12: 10 | M12: 审定报表
L13: 11 | M13: 未审BS分析
B14: 5 | C14: 未审报表、试算平衡表（TB）、审定报表、比较分析表的格式由 | G14: “报表格式” | H14: 链接控制； | L14: 12 | M14: 未审PL分析
C15: 如需修改报表科目，请在 | E15: “报表格式” | F15: 中没有颜色的单元格区域修改，其他报表会相应改变。 | L15: 13 | M15: 未审比率分析
L16: 14 | M16: 已审BS分析
B17: 6 | C17: 调整事项汇总表 | D17: 可以根据需要插入行，请勿删除行；调整金额会自动链接到试算平衡表， | L17: 15 | M17: 已审PL分析
C18: 若调整未全部链入试算平衡表，请检查调整分录的借贷方科目是否为报表科目，如不是报表科目，调整事项汇总表N列、O列会进行提示。 | L18: 16 | M18: 已审比率分析
C19: 若需添加或更改报表科目，请在 | D19: “报表格式” | E19: 中没有颜色的单元格区域进行修改，并相应修改 | H19: “报表格式S列”
B21: 7、 | C21: 由于报表项目名称存在重复的情况，主要涉及利润表中的其他及现金流中的其他，所以在
C22: 调整事项汇总表R列 | D22: 对个别报表项目的名称进行
C23: 了修改，已方便对报表项目进行正确调整，并用红色字体进行了标记，具体包括:
C24: 其他（不能重分类）
C25: 其他（可以重分类）
C26: 其他（分配）
C27: 其他（现）

Sheet 参数
B2: 项 目 | D2: 参 数 | E2: 参考格式
B3: 客户情况 | C3: 单位名称： | D3: 二锅头 | E3: 北京二锅头有限责任公司
C4: 法定代表人： | E4: 张一二
C5: 财务负责人： | E5: 陈一二
C6: 会计主管： | E6: 王一二
B8: 会计报表 | C8: 报表类型 | D8: 股份有限公司 | E8: 股份有限公司或一般企业(执行统一会计制度)
C9: 会计年度（上期）： | D9: 2021年度 | E9: 1999年度 或 1997年10月20日～1998年8月10日 | H9: 股份有限公司
C10: 会计年度（本期）： | D10: 2022年度 | E10: 2000年度 或 1998年8月10日～2000年10月20日 | H10: 非股份有限公司
C11: 会计截止（上期）： | D11: 44561 | E11: 1999年12月31日 或 1998年8月10日 | I11: =MONTH(D11) -> 12
C12: 会计截止（本期）： | D12: 44926 | E12: 2000年12月31日 或 2000年10月20日 | I12: =MONTH(D12) -> 12
C13: 金额单位： | D13: 人民币元 | E13: 人民币元
B15: 审计单位 | C15: 审计单位名称： | D15: 致同会计师事务所
C16: 项目负责人：
C17: 底稿编制人： | D17: 张 | E17: 刘一二
C18: 底稿复核人： | D18: 刘 | E18: 周一二
B20: NB | C20: 本表没有颜色的单元格可以根据需要进行修改
B24: 报表勾稽关系审核表
B25: No. | C25: 勾稽审核内容 | D25: 审核结果 | E25: 不符原因
B26: 1 | C26: 期末资产总计＝期末负债和股东权益总计 | D26: =IF(ABS(审定报表!C127-审定报表!C190)<0.01,TRUE,FALSE) -> TRUE | E26: =IF(D26=TRUE,"","期末资产负债表不平")
B27: 2 | C27: 期初资产总计＝期初负债和股东权益总计 | D27: =IF(ABS(审定报表!D127-审定报表!D190)<0.01,TRUE,FALSE) -> TRUE | E27: =IF(D27=TRUE,"","期初资产负债表不平")
B28: 3 | C28: B/S期末未分配利润＝P/L期末未分配利润 | D28: =IF(ABS(审定报表!C186-审定报表!C277)<0.01,TRUE,FALSE) -> TRUE | E28: =IF(D28=TRUE,"","期末利润分配表与资产负债表未分配利润勾稽不对")
B29: 4 | C29: B/S期初未分配利润＝P/L期初未分配利润 | D29: =IF(ABS(审定报表!D277-审定报表!D186)<0.01,TRUE,FALSE) -> TRUE | E29: =IF(D29=TRUE,"","期初利润分配表与资产负债表未分配利润勾稽不对")
B30: 5 | C30: 期末年初未分配利润＝期初未分配利润 | D30: =IF(ABS(审定报表!C266-审定报表!D277)<0.01,TRUE,FALSE) -> TRUE | E30: =IF(D30=TRUE,"","利润及利润分配表年初未分配利润与上期勾稽不对")
B31: 6 | C31: B/S期末货币资金＝Cashflow期末货币资金 | D31: =IF(ABS(审定报表!C8-审定报表!C342)<0.01,TRUE,FALSE) -> FALSE | E31: =IF(D31=TRUE,"","现金流量表与资产负债表期末货币资金勾稽不对") -> 现金流量表与资产负债表期末货币资金勾稽不对
B32: 7 | C32: B/S期初货币资金＝Cashflow期初货币资金 | D32: =IF(ABS(审定报表!D8-审定报表!D342)<0.01,TRUE,FALSE) -> FALSE | E32: =IF(D32=TRUE,"","现金流量表与资产负债表期初货币资金勾稽不对") -> 现金流量表与资产负债表期初货币资金勾稽不对
B33: 8 | C33: 直接法OperatingCF＝间接法OperatingCF | D33: =IF(ABS(审定报表!C307-审定报表!C366)<0.01,TRUE,FALSE) -> FALSE | E33: =IF(D33=TRUE,"","现金流量表主表与附表勾稽不对-经营活动现金净增加额") -> 现金流量表主表与附表勾稽不对-经营活动现金净增加额
B34: 9 | C34: 直接法NetCashflow＝间接法NetCashflow | D34: =IF(ABS(审定报表!C342-审定报表!C382)<0.01,TRUE,FALSE) -> TRUE | E34: =IF(D34=TRUE,"","现金流量表主表与附表勾稽不对-现金净增加额")
B35: 10 | C35: P/L净利润＝Cashflow间接法净利润 | D35: =IF(ABS(审定报表!C233-审定报表!C345)<0.01,TRUE,FALSE) -> TRUE | E35: =IF(D35=TRUE,"","现金流量表与利润表勾稽不对-净利润")
B36: 11 | C36: Cashflow存货的减少＝B/S存货的减少 | D36: =IF(ABS(审定报表!C361-(审定报表!D46-审定报表!C46))<0.01,TRUE,FALSE) -> FALSE | E36: =IF(D36=TRUE,"","现金流量表存货与资产负债表勾稽不对") -> 现金流量表存货与资产负债表勾稽不对
B37: 12 | C37: Cashflow投资收益＝P/L投资收益 | D37: =IF(ABS(审定报表!C358+审定报表!C218)<0.01,TRUE,FALSE) -> FALSE | E37: =IF(D37=TRUE,"","利润分配表与现金流量表投资收益勾稽不对") -> 利润分配表与现金流量表投资收益勾稽不对
B38: 13 | C38: 按净利润的10%提取法定盈余公积 | D38: =IF(ABS(审定报表!C233*0.1-审定报表!C268)<0.01,TRUE,FALSE) -> TRUE | E38: =IF(D38=TRUE,"","按照公司政策，公司提取的法定盈余公积不符")

Sheet 报表格式
A1: 会计报表格式及科目名称 | K1: 会计报表格式及科目名称 | R1: code | S1: 报表项目
B2: 本表没有颜色的单元格可以根据需要进行修改，本系统的其它表格将随之改变。比如，可将“存货”改为“存货1”。正确的修改方法，是在拟修改的单元格直接输入新的内容，请不要使用剪切或拖拽功能。
B3: 资 产 类 | E3: 负债及所有者权益类 | H3: 损 益 类 | K3: 现金流量表类 | N3: 现金流量表类
B4: 项目 | C4: 行 | E4: 项目 | F4: 行 | H4: 项目 | I4: 行 | K4: 项目 | L4: 行 | N4: 补充资料 | O4: 行
B5: 流动资产： | C5: 1 | E5: 流动负债： | F5: =C125+1 -> 122 | H5: 一、营业总收入 | I5: 1 | K5: 一、经营活动产生的现金流量 | L5: 1 | N5: 1、将净利润调节为经营活动现金流量： | O5: =L68+1 -> 65 | S5: 流动资产：
B6: 货币资金 | C6: =C5+1 -> 2 | E6: 短期借款 | F6: =F5+1 -> 123 | H6: 其中：主营业务收入 | I6: =I5+1 -> 2 | K6: 销售商品、提供劳务收到的现金 | L6: =L5+1 -> 2 | N6: 净利润 | O6: =O5+1 -> 66 | R6: D1 | S6: =B6 -> 货币资金
B7: 结算备付金* | C7: =C6+1 -> 3 | E7: 向中央银行借款* | F7: =F6+1 -> 124 | H7: 其他业务收入 | I7: =I6+1 -> 3 | K7: 客户存款和同业存放款项净增加额* | L7: =L6+1 -> 3 | O7: =O6+1 -> 67 | R7: D2 | S7: =B7 -> 结算备付金*
B8: 拆出资金原值* | C8: =C7+1 -> 4 | E8: 拆入资金* | F8: =F7+1 -> 125 | H8: 利息收入* | I8: =I7+1 -> 4 | K8: 向中央银行借款净增加额* | L8: =L7+1 -> 4 | O8: =O7+1 -> 68 | R8: D3 | S8: =B8 -> 拆出资金原值*
B9: 拆出资金减值准备* | C9: =C8+1 -> 5 | E9: 交易性金融负债 | F9: =F8+1 -> 126 | H9: 已赚保费* | I9: =I8+1 -> 5 | K9: 向其他金融机构拆入资金净增加额* | L9: =L8+1 -> 5 | N9: 加：资产减值损失 | O9: =O8+1 -> 69 | R9: D4 | S9: =B9 -> 拆出资金减值准备*
B10: 拆出资金* | C10: =C9+1 -> 6 | E10: 衍生金融负债 | F10: =F9+1 -> 127 | H10: 手续费及佣金收入* | I10: =I9+1 -> 6 | K10: 收到原保险合同保费取得的现金* | L10: =L9+1 -> 6 | N10: 信用减值损失 | O10: =O9+1 -> 70 | S10: =B10 -> 拆出资金*
B11: 交易性金融资产 | C11: =C10+1 -> 7 | E11: 应付票据 | F11: =F10+1 -> 128 | H11: 减：营业总成本 | I11: =I10+1 -> 7 | K11: 收到再保业务现金净额* | L11: =L10+1 -> 7 | N11: 固定资产折旧、投资性房地产折旧、油气资产折耗、生产性生物资产折旧 | O11: =O10+1 -> 71 | R11: D5 | S11: =B11 -> 交易性金融资产
B12: 衍生金融资产 | C12: =C11+1 -> 8 | E12: 应付账款 | F12: =F11+1 -> 129 | H12: 其中：主营业务成本 | I12: =I11+1 -> 8 | K12: 保户储金及投资款净增加额* | L12: =L11+1 -> 8 | N12: 使用权资产折旧 | O12: =O11+1 -> 72 | R12: D6 | S12: =B12 -> 衍生金融资产
B13: 应收票据原值 | C13: =C12+1 -> 9 | E13: 预收款项 | F13: =F12+1 -> 130 | H13: 其他业务成本 | I13: =I12+1 -> 9 | K13: 收取利息、手续费及佣金的现金* | L13: =L12+1 -> 9 | N13: 无形资产摊销 | O13: =O12+1 -> 73 | R13: D7 | S13: =B13 -> 应收票据原值
B14: 应收票据坏账准备 | C14: =C13+1 -> 10 | E14: 合同负债 | F14: =F13+1 -> 131 | H14: 利息支出* | I14: =I13+1 -> 10 | K14: 拆入资金净增加额* | L14: =L13+1 -> 10 | N14: 长期待摊费用摊销 | O14: =O13+1 -> 74 | R14: D8 | S14: =B14 -> 应收票据坏账准备
B15: 应收票据 | C15: =C14+1 -> 11 | E15: 卖出回购金融资产款* | F15: =F14+1 -> 132 | H15: 手续费及佣金支出* | I15: =I14+1 -> 11 | K15: 回购业务资金净增加额* | L15: =L14+1 -> 11 | N15: 处置固定资产、无形资产和其他长期资产的损失（收益以“－”号填列） | O15: =O14+1 -> 75 | S15: =B15 -> 应收票据
B16: 应收账款原值 | C16: =C15+1 -> 12 | E16: 吸收存款及同业存放* | F16: =F15+1 -> 133 | H16: 退保金* | I16: =I15+1 -> 12 | K16: 代理买卖证券收到的现金净额* | L16: =L15+1 -> 12 | N16: 固定资产报废损失（收益以“－”号填列） | O16: =O15+1 -> 76 | R16: D9 | S16: =B16 -> 应收账款原值
B17: 应收账款坏账准备 | C17: =C16+1 -> 13 | E17: 代理买卖证券款* | F17: =F16+1 -> 134 | H17: 赔付支出净额* | I17: =I16+1 -> 13 | K17: 收到的税费返还 | L17: =L16+1 -> 13 | N17: 公允价值变动损失（收益以“－”号填列） | O17: =O16+1 -> 77 | R17: D10 | S17: =B17 -> 应收账款坏账准备
B18: 应收账款 | C18: =C17+1 -> 14 | E18: 代理承销证券款* | F18: =F17+1 -> 135 | H18: 提取保险责任准备金净额* | I18: =I17+1 -> 14 | K18: 收到的其他与经营活动有关的现金 | L18: =L17+1 -> 14 | N18: 财务费用（收益以“－”号填列） | O18: =O17+1 -> 78 | S18: =B18 -> 应收账款
B19: 应收款项融资原值 | C19: =C18+1 -> 15 | E19: 应付职工薪酬 | F19: =F18+1 -> 136 | H19: 保单红利支出* | I19: =I18+1 -> 15 | L19: =L18+1 -> 15 | N19: 投资损失（收益以“－”号填列） | O19: =O18+1 -> 79 | R19: D11 | S19: =B19 -> 应收款项融资原值
B20: 应收款项融资坏账准备 | C20: =C19+1 -> 16 | E20: 其中：应付工资 | F20: =F19+1 -> 137 | H20: 分保费用* | I20: =I19+1 -> 16 | K20: 经营活动现金流入小计 | L20: =L19+1 -> 16 | N20: 递延所得税资产减少（增加以“－”号填列） | O20: =O19+1 -> 80 | R20: D12 | S20: =B20 -> 应收款项融资坏账准备
B21: 应收款项融资 | C21: =C20+1 -> 17 | E21: 应付福利费 | F21: =F20+1 -> 138 | H21: 税金及附加 | I21: =I20+1 -> 17 | K21: 购买商品、接受劳务支付的现金 | L21: =L20+1 -> 17 | N21: 递延所得税负债增加（减少以“－”号填列） | O21: =O20+1 -> 81 | S21: =B21 -> 应收款项融资
B22: 预付款项原值 | C22: =C21+1 -> 18 | E22: #其中：职工奖励及福利基金 | F22: =F21+1 -> 139 | H22: 销售费用 | I22: =I21+1 -> 18 | K22: 客户贷款及垫款净增加额* | L22: =L21+1 -> 18 | N22: 存货的减少（增加以“－”号填列） | O22: =O21+1 -> 82 | R22: D13 | S22: =B22 -> 预付款项原值
B23: 预付款项坏账准备 | C23: =C22+1 -> 19 | E23: 应交税费 | F23: =F22+1 -> 140 | H23: 管理费用 | I23: =I22+1 -> 19 | K23: 存放中央银行和同业款项净增加额* | L23: =L22+1 -> 19 | N23: 经营性应收项目的减少（增加以“－”号填列） | O23: =O22+1 -> 83 | R23: D14 | S23: =B23 -> 预付款项坏账准备
B24: 预付款项 | C24: =C23+1 -> 20 | E24: 其中：应交税金 | F24: =F23+1 -> 141 | H24: 研发费用 | I24: =I23+1 -> 20 | K24: 支付原保险合同赔付款项的现金* | L24: =L23+1 -> 20 | N24: 经营性应付项目的增加（减少以“－”号填列） | O24: =O23+1 -> 84 | S24: =B24 -> 预付款项
B25: 应收保费原值* | C25: =C24+1 -> 21 | E25: 其他应付款 | F25: =F24+1 -> 142 | H25: 财务费用 | I25: =I24+1 -> 21 | K25: 拆出资金净增加额* | L25: =L24+1 -> 21 | N25: 其他 | O25: =O24+1 -> 85 | R25: D15 | S25: =B25 -> 应收保费原值*
B26: 应收保费坏账准备* | C26: =C25+1 -> 22 | E26: 其中：应付利息 | F26: =F25+1 -> 143 | H26: 其中：利息费用 | I26: =I25+1 -> 22 | K26: 支付利息、手续费及佣金的现金* | L26: =L25+1 -> 22 | O26: =O25+1 -> 86 | R26: D16 | S26: =B26 -> 应收保费坏账准备*
B27: 应收保费* | C27: =C26+1 -> 23 | E27: 应付股利 | F27: =F26+1 -> 144 | H27: 利息收入 | I27: =I26+1 -> 23 | K27: 支付保单红利的现金* | L27: =L26+1 -> 23 | N27: 经营活动产生的现金流量净额 | O27: =O26+1 -> 87 | S27: =B27 -> 应收保费*
B28: 应收分保账款原值* | C28: =C27+1 -> 24 | E28: 应付手续费及佣金* | F28: =F27+1 -> 145 | H28: 汇兑净损失（净收益以“－”号填列） | I28: =I27+1 -> 24 | K28: 支付给职工以及为职工支付的现金 | L28: =L27+1 -> 24 | O28: =O27+1 -> 88 | R28: D15 | S28: =B28 -> 应收分保账款原值*
B29: 应收分保账款坏账准备* | C29: =C28+1 -> 25 | E29: 应付分保账款* | F29: =F28+1 -> 146 | H29: 其他 | I29: =I28+1 -> 25 | K29: 支付各项税费 | L29: =L28+1 -> 25 | N29: 2、不涉及现金收支的投资和筹资活动： | O29: =O28+1 -> 89 | R29: D16 | S29: =B29 -> 应收分保账款坏账准备*
B30: 应收分保账款* | C30: =C29+1 -> 26 | E30: 持有待售负债 | F30: =F29+1 -> 147 | H30: 加：其他收益 | I30: =I29+1 -> 26 | K30: 支付的其他与经营活动有关的现金 | L30: =L29+1 -> 26 | N30: 债务转为资本 | O30: =O29+1 -> 90 | S30: =B30 -> 应收分保账款*
B31: 应收分保合同准备金* | C31: =C30+1 -> 27 | E31: 一年内到期的非流动负债 | F31: =F30+1 -> 148 | H31: 投资收益（损失以“－”号填列） | I31: =I30+1 -> 27 | L31: =L30+1 -> 27 | N31: 一年内到期的可转换公司债券 | O31: =O30+1 -> 91 | R31: D17 | S31: =B31 -> 应收分保合同准备金*
B32: 应收利息原值 | C32: =C31+1 -> 28 | E32: 其他流动负债 | F32: =F31+1 -> 149 | H32: 其中：对联营企业和合营企业的投资收益 | I32: =I31+1 -> 28 | K32: 经营活动现金流出小计 | L32: =L31+1 -> 28 | N32: 融资租入固定资产 | O32: =O31+1 -> 92 | R32: D18 | S32: =B32 -> 应收利息原值
B33: 应收利息坏账准备 | C33: =C32+1 -> 29 | E33: 保险合同准备金* | F33: =F32+1 -> 150 | H33: 以摊余成本计量的金融资产终止确认收益（损失以“-”号填列） | I33: =I32+1 -> 29 | K33: 经营活动产生的现金流量净额 | L33: =L32+1 -> 29 | N33: 当期新增的使用权资产 | O33: =O32+1 -> 93 | R33: D19 | S33: =B33 -> 应收利息坏账准备
B34: 应收利息 | C34: =C33+1 -> 30 | E34: 流动负债合计 | F34: =F33+1 -> 151 | H34: 汇兑收益（损失以“-”号填列）* | I34: =I33+1 -> 30 | K34: 二、投资活动产生的现金流量 | L34: =L33+1 -> 30 | O34: =O33+1 -> 94 | S34: =B34 -> 应收利息
B35: 应收股利原值 | C35: =C34+1 -> 31 | E35: 非流动负债: | F35: =F34+1 -> 152 | H35: 净敞口套期收益（损失以“-”号填列） | I35: =I34+1 -> 31 | K35: 收回投资所收到的现金 | L35: =L34+1 -> 31 | O35: =O34+1 -> 95 | R35: D20 | S35: =B35 -> 应收股利原值
B36: 应收股利坏账准备 | C36: =C35+1 -> 32 | E36: 长期借款 | F36: =F35+1 -> 153 | H36: 公允价值变动收益（损失以“－”号填列） | I36: =I35+1 -> 32 | K36: 取得投资收益所收到的现金 | L36: =L35+1 -> 32 | N36: 3、现金及现金等价物净变动情况： | O36: =O35+1 -> 96 | R36: D21 | S36: =B36 -> 应收股利坏账准备
B37: 应收股利 | C37: =C36+1 -> 33 | E37: 应付债券 | F37: =F36+1 -> 154 | H37: 信用减值损失（损失以“-”号填列） | I37: =I36+1 -> 33 | K37: 处置固定资产、无形资产和其他长期资产而收到的现金净额 | L37: =L36+1 -> 33 | N37: 现金的期末余额 | O37: =O36+1 -> 97 | S37: =B37 -> 应收股利
B38: 其他应收款原值 | C38: =C37+1 -> 34 | E38: 其中：优先股 | F38: =F37+1 -> 155 | H38: 资产减值损失（损失以“-”号填列） | I38: =I37+1 -> 34 | K38: 处置子公司及其他营业单位收到的现金净额 | L38: =L37+1 -> 34 | N38: 减：现金的期初余额 | O38: =O37+1 -> 98 | R38: D22 | S38: =B38 -> 其他应收款原值
B39: 其他应收款坏账准备 | C39: =C38+1 -> 35 | E39: 永续债 | F39: =F38+1 -> 156 | H39: 资产处置收益（损失以“-”号填列） | I39: =I38+1 -> 35 | K39: 收到其他与投资活动有关的现金 | L39: =L38+1 -> 35 | N39: 加：现金等价物的期末余额 | O39: =O38+1 -> 99 | R39: D23 | S39: =B39 -> 其他应收款坏账准备
B40: 其他应收款 | C40: =C39+1 -> 36 | E40: 租赁负债 | F40: =F39+1 -> 157 | H40: 二、营业利润（亏损以“－”号填列） | I40: =I39+1 -> 36 | L40: =L39+1 -> 36 | N40: 减：现金等价物的期初余额 | O40: =O39+1 -> 100 | S40: =B40 -> 其他应收款
...

Sheet 试算
A1: 致同会计师事务所
A2: 试算平衡表
A3: 编制单位： | C3: 编制： | D3: 日期： | E3: 索引： | F3: A2-2
A4: 截止/期间： | C4: 复核： | D4: 日期： | E4: 页次：
B5: =IF(ROUND(B121-B167,2)=0,"",ROUND(B121-B167,2)) | C5: =IF(ROUND(C121-C167,2)=0,"",ROUND(C121-C167,2)) | D5: =IF(ROUND(D121-D167,2)=0,"",ROUND(D121-D167,2)) | E5: =IF(ROUND(E121-E167,2)=0,"",ROUND(E121-E167,2)) | F5: =IF(ROUND(F121-F167,2)=0,"",ROUND(F121-F167,2))
A6: =IF(SUM(B6:F6)=0,"","现金流量不平") | B6: =IF(AND(ROUND(B232-B282,2)=0,ROUND(B261-B292,2)<>0),ROUND(B261-B292,2),IF(AND(ROUND(B232-B282,2)<>0,ROUND(B261-B292,2)=0),ROUND(B232-B282,2),IF(AND(ROUND(B232-B282,2)<>0,ROUND(B261-B292,2)),ROUND(B261-B292,2),""))) | C6: =IF(AND(ROUND(C232-C282,2)=0,ROUND(C261-C292,2)<>0),ROUND(C261-C292,2),IF(AND(ROUND(C232-C282,2)<>0,ROUND(C261-C292,2)=0),ROUND(C232-C282,2),IF(AND(ROUND(C232-C282,2)<>0,ROUND(C261-C292,2)),ROUND(C261-C292,2),""))) | D6: =IF(AND(ROUND(D232-D282,2)=0,ROUND(D261-D292,2)<>0),ROUND(D261-D292,2),IF(AND(ROUND(D232-D282,2)<>0,ROUND(D261-D292,2)=0),ROUND(D232-D282,2),IF(AND(ROUND(D232-D282,2)<>0,ROUND(D261-D292,2)),ROUND(D261-D292,2),""))) | E6: =IF(AND(ROUND(E232-E282,2)=0,ROUND(E261-E292,2)<>0),ROUND(E261-E292,2),IF(AND(ROUND(E232-E282,2)<>0,ROUND(E261-E292,2)=0),ROUND(E232-E282,2),IF(AND(ROUND(E232-E282,2)<>0,ROUND(E261-E292,2)),ROUND(E261-E292,2),""))) | F6: =IF(AND(ROUND(F232-F282,2)=0,ROUND(F261-F292,2)<>0),ROUND(F261-F292,2),IF(AND(ROUND(F232-F282,2)<>0,ROUND(F261-F292,2)=0),ROUND(F232-F282,2),IF(AND(ROUND(F232-F282,2)<>0,ROUND(F261-F292,2)),ROUND(F261-F292,2),"")))
A7: 项目 | B7: 未审 | C7: 调账 | D7: 重分类 | E7: 其他 | F7: 审定
A8: 流动资产：
A9: 货币资金 | B9: 1.2884156e+08 | C9: =SUMPRODUCT(([3]分录!$D$7:$D$100=$A9)*INT((([3]分录!$C$7:$C$100="借：")-0.5)*2)*([3]分录!$I$7:$I$100=C$7)*([3]分录!$H$7:$H$100)) -> 0 | D9: =SUMPRODUCT(([3]分录!$D$7:$D$100=$A9)*INT((([3]分录!$C$7:$C$100="借：")-0.5)*2)*([3]分录!$I$7:$I$100=D$7)*([3]分录!$H$7:$H$100)) -> 0 | E9: =SUMPRODUCT(([3]分录!$D$7:$D$100=$A9)*INT((([3]分录!$C$7:$C$100="借：")-0.5)*2)*([3]分录!$I$7:$I$100=E$7)*([3]分录!$H$7:$H$100)) -> 0 | F9: =ROUND(SUM(B9:E9),2) -> 1.2884156e+08
A10: 交易性金融资产 | B10: 1.0338995e+10 | C10: =SUMPRODUCT(([3]分录!$D$7:$D$100=$A10)*INT((([3]分录!$C$7:$C$100="借：")-0.5)*2)*([3]分录!$I$7:$I$100=C$7)*([3]分录!$H$7:$H$100)) -> 0 | D10: =SUMPRODUCT(([3]分录!$D$7:$D$100=$A10)*INT((([3]分录!$C$7:$C$100="借：")-0.5)*2)*([3]分录!$I$7:$I$100=D$7)*([3]分录!$H$7:$H$100)) -> 0 | E10: =SUMPRODUCT(([3]分录!$D$7:$D$100=$A10)*INT((([3]分录!$C$7:$C$100="借：")-0.5)*2)*([3]分录!$I$7:$I$100=E$7)*([3]分录!$H$7:$H$100)) -> 0 | F10: =ROUND(SUM(B10:E10),2) -> 1.0338995e+10
A11: 以公允价值计量且其变动计入当期损益的金融资产 | B11: 0 | C11: =SUMPRODUCT(([3]分录!$D$7:$D$100=$A11)*INT((([3]分录!$C$7:$C$100="借：")-0.5)*2)*([3]分录!$I$7:$I$100=C$7)*([3]分录!$H$7:$H$100)) -> 0 | D11: =SUMPRODUCT(([3]分录!$D$7:$D$100=$A11)*INT((([3]分录!$C$7:$C$100="借：")-0.5)*2)*([3]分录!$I$7:$I$100=D$7)*([3]分录!$H$7:$H$100)) -> 0 | E11: =SUMPRODUCT(([3]分录!$D$7:$D$100=$A11)*INT((([3]分录!$C$7:$C$100="借：")-0.5)*2)*([3]分录!$I$7:$I$100=E$7)*([3]分录!$H$7:$H$100)) -> 0 | F11: =ROUND(SUM(B11:E11),2) -> 0
A12: 衍生金融资产 | B12: 0 | C12: =SUMPRODUCT(([3]分录!$D$7:$D$100=$A12)*INT((([3]分录!$C$7:$C$100="借：")-0.5)*2)*([3]分录!$I$7:$I$100=C$7)*([3]分录!$H$7:$H$100)) -> 0 | D12: =SUMPRODUCT(([3]分录!$D$7:$D$100=$A12)*INT((([3]分录!$C$7:$C$100="借：")-0.5)*2)*([3]分录!$I$7:$I$100=D$7)*([3]分录!$H$7:$H$100)) -> 0 | E12: =SUMPRODUCT(([3]分录!$D$7:$D$100=$A12)*INT((([3]分录!$C$7:$C$100="借：")-0.5)*2)*([3]分录!$I$7:$I$100=E$7)*([3]分录!$H$7:$H$100)) -> 0 | F12: =ROUND(SUM(B12:E12),2) -> 0
A13: 应收票据原值 | B13: 0 | C13: =SUMPRODUCT(([3]分录!$D$7:$D$100=$A13)*INT((([3]分录!$C$7:$C$100="借：")-0.5)*2)*([3]分录!$I$7:$I$100=C$7)*([3]分录!$H$7:$H$100)) -> 0 | D13: =SUMPRODUCT(([3]分录!$D$7:$D$100=$A13)*INT((([3]分录!$C$7:$C$100="借：")-0.5)*2)*([3]分录!$I$7:$I$100=D$7)*([3]分录!$H$7:$H$100)) -> 0 | E13: =SUMPRODUCT(([3]分录!$D$7:$D$100=$A13)*INT((([3]分录!$C$7:$C$100="借：")-0.5)*2)*([3]分录!$I$7:$I$100=E$7)*([3]分录!$H$7:$H$100)) -> 0 | F13: =ROUND(SUM(B13:E13),2) -> 0
A14: 应收票据坏账准备 | B14: 0 | C14: =-SUMPRODUCT(([3]分录!$D$7:$D$100=$A14)*INT((([3]分录!$C$7:$C$100="借：")-0.5)*2)*([3]分录!$I$7:$I$100=C$7)*([3]分录!$H$7:$H$100)) -> 0 | D14: =-SUMPRODUCT(([3]分录!$D$7:$D$100=$A14)*INT((([3]分录!$C$7:$C$100="借：")-0.5)*2)*([3]分录!$I$7:$I$100=D$7)*([3]分录!$H$7:$H$100)) -> 0 | E14: =-SUMPRODUCT(([3]分录!$D$7:$D$100=$A14)*INT((([3]分录!$C$7:$C$100="借：")-0.5)*2)*([3]分录!$I$7:$I$100=E$7)*([3]分录!$H$7:$H$100)) -> 0 | F14: =ROUND(SUM(B14:E14),2) -> 0
A15: 应收票据 | B15: 0 | C15: =C13-C14 -> 0 | D15: =D13-D14 -> 0 | E15: =E13-E14 -> 0 | F15: =ROUND(SUM(B15:E15),2) -> 0
A16: 应收账款原值 | B16: 0 | C16: =SUMPRODUCT(([3]分录!$D$7:$D$100=$A16)*INT((([3]分录!$C$7:$C$100="借：")-0.5)*2)*([3]分录!$I$7:$I$100=C$7)*([3]分录!$H$7:$H$100)) -> 0 | D16: =SUMPRODUCT(([3]分录!$D$7:$D$100=$A16)*INT((([3]分录!$C$7:$C$100="借：")-0.5)*2)*([3]分录!$I$7:$I$100=D$7)*([3]分录!$H$7:$H$100)) -> 0 | E16: =SUMPRODUCT(([3]分录!$D$7:$D$100=$A16)*INT((([3]分录!$C$7:$C$100="借：")-0.5)*2)*([3]分录!$I$7:$I$100=E$7)*([3]分录!$H$7:$H$100)) -> 0 | F16: =ROUND(SUM(B16:E16),2) -> 0
A17: 应收账款坏账准备 | B17: 0 | C17: =-SUMPRODUCT(([3]分录!$D$7:$D$100=$A17)*INT((([3]分录!$C$7:$C$100="借：")-0.5)*2)*([3]分录!$I$7:$I$100=C$7)*([3]分录!$H$7:$H$100)) -> -1807111.9 | D17: =-SUMPRODUCT(([3]分录!$D$7:$D$100=$A17)*INT((([3]分录!$C$7:$C$100="借：")-0.5)*2)*([3]分录!$I$7:$I$100=D$7)*([3]分录!$H$7:$H$100)) -> 0 | E17: =-SUMPRODUCT(([3]分录!$D$7:$D$100=$A17)*INT((([3]分录!$C$7:$C$100="借：")-0.5)*2)*([3]分录!$I$7:$I$100=E$7)*([3]分录!$H$7:$H$100)) -> 0 | F17: =ROUND(SUM(B17:E17),2) -> -1807111.9
A18: 应收账款 | B18: 0 | C18: =C16-C17 -> 1807111.9 | D18: =D16-D17 -> 0 | E18: =E16-E17 -> 0 | F18: =ROUND(SUM(B18:E18),2) -> 1807111.9
A19: 应收款项融资原值 | B19: 0 | C19: =SUMPRODUCT(([3]分录!$D$7:$D$100=$A19)*INT((([3]分录!$C$7:$C$100="借：")-0.5)*2)*([3]分录!$I$7:$I$100=C$7)*([3]分录!$H$7:$H$100)) -> 0 | D19: =SUMPRODUCT(([3]分录!$D$7:$D$100=$A19)*INT((([3]分录!$C$7:$C$100="借：")-0.5)*2)*([3]分录!$I$7:$I$100=D$7)*([3]分录!$H$7:$H$100)) -> 0 | E19: =SUMPRODUCT(([3]分录!$D$7:$D$100=$A19)*INT((([3]分录!$C$7:$C$100="借：")-0.5)*2)*([3]分录!$I$7:$I$100=E$7)*([3]分录!$H$7:$H$100)) -> 0 | F19: =ROUND(SUM(B19:E19),2) -> 0
A20: 应收款项融资坏账准备 | B20: 0 | C20: =-SUMPRODUCT(([3]分录!$D$7:$D$100=$A20)*INT((([3]分录!$C$7:$C$100="借：")-0.5)*2)*([3]分录!$I$7:$I$100=C$7)*([3]分录!$H$7:$H$100)) -> 0 | D20: =-SUMPRODUCT(([3]分录!$D$7:$D$100=$A20)*INT((([3]分录!$C$7:$C$100="借：")-0.5)*2)*([3]分录!$I$7:$I$100=D$7)*([3]分录!$H$7:$H$100)) -> 0 | E20: =-SUMPRODUCT(([3]分录!$D$7:$D$100=$A20)*INT((([3]分录!$C$7:$C$100="借：")-0.5)*2)*([3]分录!$I$7:$I$100=E$7)*([3]分录!$H$7:$H$100)) -> 0 | F20: =ROUND(SUM(B20:E20),2) -> 0
A21: 应收款项融资 | B21: 0 | C21: =C19-C20 -> 0 | D21: =D19-D20 -> 0 | E21: =E19-E20 -> 0 | F21: =ROUND(SUM(B21:E21),2) -> 0
A22: 预付款项原值 | B22: 0 | C22: =SUMPRODUCT(([3]分录!$D$7:$D$100=$A22)*INT((([3]分录!$C$7:$C$100="借：")-0.5)*2)*([3]分录!$I$7:$I$100=C$7)*([3]分录!$H$7:$H$100)) -> 0 | D22: =SUMPRODUCT(([3]分录!$D$7:$D$100=$A22)*INT((([3]分录!$C$7:$C$100="借：")-0.5)*2)*([3]分录!$I$7:$I$100=D$7)*([3]分录!$H$7:$H$100)) -> 0 | E22: =SUMPRODUCT(([3]分录!$D$7:$D$100=$A22)*INT((([3]分录!$C$7:$C$100="借：")-0.5)*2)*([3]分录!$I$7:$I$100=E$7)*([3]分录!$H$7:$H$100)) -> 0 | F22: =ROUND(SUM(B22:E22),2) -> 0
A23: 预付款项坏账准备 | B23: 0 | C23: =-SUMPRODUCT(([3]分录!$D$7:$D$100=$A23)*INT((([3]分录!$C$7:$C$100="借：")-0.5)*2)*([3]分录!$I$7:$I$100=C$7)*([3]分录!$H$7:$H$100)) -> 0 | D23: =-SUMPRODUCT(([3]分录!$D$7:$D$100=$A23)*INT((([3]分录!$C$7:$C$100="借：")-0.5)*2)*([3]分录!$I$7:$I$100=D$7)*([3]分录!$H$7:$H$100)) -> 0 | E23: =-SUMPRODUCT(([3]分录!$D$7:$D$100=$A23)*INT((([3]分录!$C$7:$C$100="借：")-0.5)*2)*([3]分录!$I$7:$I$100=E$7)*([3]分录!$H$7:$H$100)) -> 0 | F23: =ROUND(SUM(B23:E23),2) -> 0
A24: 预付款项 | B24: 0 | C24: =C22-C23 -> 0 | D24: =D22-D23 -> 0 | E24: =E22-E23 -> 0 | F24: =ROUND(SUM(B24:E24),2) -> 0
A25: 应收利息原值 | B25: 0 | C25: =SUMPRODUCT(([3]分录!$D$7:$D$100=$A25)*INT((([3]分录!$C$7:$C$100="借：")-0.5)*2)*([3]分录!$I$7:$I$100=C$7)*([3]分录!$H$7:$H$100)) -> 0 | D25: =SUMPRODUCT(([3]分录!$D$7:$D$100=$A25)*INT((([3]分录!$C$7:$C$100="借：")-0.5)*2)*([3]分录!$I$7:$I$100=D$7)*([3]分录!$H$7:$H$100)) -> 0 | E25: =SUMPRODUCT(([3]分录!$D$7:$D$100=$A25)*INT((([3]分录!$C$7:$C$100="借：")-0.5)*2)*([3]分录!$I$7:$I$100=E$7)*([3]分录!$H$7:$H$100)) -> 0 | F25: =ROUND(SUM(B25:E25),2) -> 0
A26: 应收利息坏账准备 | B26: 0 | C26: =-SUMPRODUCT(([3]分录!$D$7:$D$100=$A26)*INT((([3]分录!$C$7:$C$100="借：")-0.5)*2)*([3]分录!$I$7:$I$100=C$7)*([3]分录!$H$7:$H$100)) -> 0 | D26: =-SUMPRODUCT(([3]分录!$D$7:$D$100=$A26)*INT((([3]分录!$C$7:$C$100="借：")-0.5)*2)*([3]分录!$I$7:$I$100=D$7)*([3]分录!$H$7:$H$100)) -> 0 | E26: =-SUMPRODUCT(([3]分录!$D$7:$D$100=$A26)*INT((([3]分录!$C$7:$C$100="借：")-0.5)*2)*([3]分录!$I$7:$I$100=E$7)*([3]分录!$H$7:$H$100)) -> 0 | F26: =ROUND(SUM(B26:E26),2) -> 0
A27: 应收利息 | B27: 0 | C27: =C25-C26 -> 0 | D27: =D25-D26 -> 0 | E27: =E25-E26 -> 0 | F27: =ROUND(SUM(B27:E27),2) -> 0
A28: 应收股利原值 | B28: 0 | C28: =SUMPRODUCT(([3]分录!$D$7:$D$100=$A28)*INT((([3]分录!$C$7:$C$100="借：")-0.5)*2)*([3]分录!$I$7:$I$100=C$7)*([3]分录!$H$7:$H$100)) -> 0 | D28: =SUMPRODUCT(([3]分录!$D$7:$D$100=$A28)*INT((([3]分录!$C$7:$C$100="借：")-0.5)*2)*([3]分录!$I$7:$I$100=D$7)*([3]分录!$H$7:$H$100)) -> 0 | E28: =SUMPRODUCT(([3]分录!$D$7:$D$100=$A28)*INT((([3]分录!$C$7:$C$100="借：")-0.5)*2)*([3]分录!$I$7:$I$100=E$7)*([3]分录!$H$7:$H$100)) -> 0 | F28: =ROUND(SUM(B28:E28),2) -> 0
A29: 应收股利坏账准备 | B29: 0 | C29: =-SUMPRODUCT(([3]分录!$D$7:$D$100=$A29)*INT((([3]分录!$C$7:$C$100="借：")-0.5)*2)*([3]分录!$I$7:$I$100=C$7)*([3]分录!$H$7:$H$100)) -> 0 | D29: =-SUMPRODUCT(([3]分录!$D$7:$D$100=$A29)*INT((([3]分录!$C$7:$C$100="借：")-0.5)*2)*([3]分录!$I$7:$I$100=D$7)*([3]分录!$H$7:$H$100)) -> 0 | E29: =-SUMPRODUCT(([3]分录!$D$7:$D$100=$A29)*INT((([3]分录!$C$7:$C$100="借：")-0.5)*2)*([3]分录!$I$7:$I$100=E$7)*([3]分录!$H$7:$H$100)) -> 0 | F29: =ROUND(SUM(B29:E29),2) -> 0
A30: 应收股利 | B30: 0 | C30: =C28-C29 -> 0 | D30: =D28-D29 -> 0 | E30: =E28-E29 -> 0 | F30: =ROUND(SUM(B30:E30),2) -> 0
A31: 其他应收款原值 | B31: 0 | C31: =SUMPRODUCT(([3]分录!$D$7:$D$100=$A31)*INT((([3]分录!$C$7:$C$100="借：")-0.5)*2)*([3]分录!$I$7:$I$100=C$7)*([3]分录!$H$7:$H$100)) -> 0 | D31: =SUMPRODUCT(([3]分录!$D$7:$D$100=$A31)*INT((([3]分录!$C$7:$C$100="借：")-0.5)*2)*([3]分录!$I$7:$I$100=D$7)*([3]分录!$H$7:$H$100)) -> 0 | E31: =SUMPRODUCT(([3]分录!$D$7:$D$100=$A31)*INT((([3]分录!$C$7:$C$100="借：")-0.5)*2)*([3]分录!$I$7:$I$100=E$7)*([3]分录!$H$7:$H$100)) -> 0 | F31: =ROUND(SUM(B31:E31),2) -> 0
A32: 其他应收款坏账准备 | B32: 0 | C32: =-SUMPRODUCT(([3]分录!$D$7:$D$100=$A32)*INT((([3]分录!$C$7:$C$100="借：")-0.5)*2)*([3]分录!$I$7:$I$100=C$7)*([3]分录!$H$7:$H$100)) -> 2276.74 | D32: =-SUMPRODUCT(([3]分录!$D$7:$D$100=$A32)*INT((([3]分录!$C$7:$C$100="借：")-0.5)*2)*([3]分录!$I$7:$I$100=D$7)*([3]分录!$H$7:$H$100)) -> 0 | E32: =-SUMPRODUCT(([3]分录!$D$7:$D$100=$A32)*INT((([3]分录!$C$7:$C$100="借：")-0.5)*2)*([3]分录!$I$7:$I$100=E$7)*([3]分录!$H$7:$H$100)) -> 0 | F32: =ROUND(SUM(B32:E32),2) -> 2276.74
A33: 其他应收款 | B33: 0 | C33: =C31-C32 -> -2276.74 | D33: =D31-D32 -> 0 | E33: =E31-E32 -> 0 | F33: =ROUND(SUM(B33:E33),2) -> -2276.74
A34: 存货原值 | B34: 4.0768702e+08 | C34: =SUMPRODUCT(([3]分录!$D$7:$D$100=$A34)*INT((([3]分录!$C$7:$C$100="借：")-0.5)*2)*([3]分录!$I$7:$I$100=C$7)*([3]分录!$H$7:$H$100)) -> 0 | D34: =SUMPRODUCT(([3]分录!$D$7:$D$100=$A34)*INT((([3]分录!$C$7:$C$100="借：")-0.5)*2)*([3]分录!$I$7:$I$100=D$7)*([3]分录!$H$7:$H$100)) -> 0 | E34: =SUMPRODUCT(([3]分录!$D$7:$D$100=$A34)*INT((([3]分录!$C$7:$C$100="借：")-0.5)*2)*([3]分录!$I$7:$I$100=E$7)*([3]分录!$H$7:$H$100)) -> 0 | F34: =ROUND(SUM(B34:E34),2) -> 4.0768702e+08
A35: 存货跌价准备 | B35: 0 | C35: =-SUMPRODUCT(([3]分录!$D$7:$D$100=$A35)*INT((([3]分录!$C$7:$C$100="借：")-0.5)*2)*([3]分录!$I$7:$I$100=C$7)*([3]分录!$H$7:$H$100)) -> 0 | D35: =-SUMPRODUCT(([3]分录!$D$7:$D$100=$A35)*INT((([3]分录!$C$7:$C$100="借：")-0.5)*2)*([3]分录!$I$7:$I$100=D$7)*([3]分录!$H$7:$H$100)) -> 0 | E35: =-SUMPRODUCT(([3]分录!$D$7:$D$100=$A35)*INT((([3]分录!$C$7:$C$100="借：")-0.5)*2)*([3]分录!$I$7:$I$100=E$7)*([3]分录!$H$7:$H$100)) -> 0 | F35: =ROUND(SUM(B35:E35),2) -> 0
A36: 存货 | B36: 0 | C36: =C34-C35 -> 0 | D36: =D34-D35 -> 0 | E36: =E34-E35 -> 0 | F36: =ROUND(SUM(B36:E36),2) -> 0
A37: 合同资产原值 | B37: 0 | C37: =SUMPRODUCT(([3]分录!$D$7:$D$100=$A37)*INT((([3]分录!$C$7:$C$100="借：")-0.5)*2)*([3]分录!$I$7:$I$100=C$7)*([3]分录!$H$7:$H$100)) -> 0 | D37: =SUMPRODUCT(([3]分录!$D$7:$D$100=$A37)*INT((([3]分录!$C$7:$C$100="借：")-0.5)*2)*([3]分录!$I$7:$I$100=D$7)*([3]分录!$H$7:$H$100)) -> 0 | E37: =SUMPRODUCT(([3]分录!$D$7:$D$100=$A37)*INT((([3]分录!$C$7:$C$100="借：")-0.5)*2)*([3]分录!$I$7:$I$100=E$7)*([3]分录!$H$7:$H$100)) -> 0 | F37: =ROUND(SUM(B37:E37),2) -> 0
A38: 合同资产减值准备 | B38: 0 | C38: =-SUMPRODUCT(([3]分录!$D$7:$D$100=$A38)*INT((([3]分录!$C$7:$C$100="借：")-0.5)*2)*([3]分录!$I$7:$I$100=C$7)*([3]分录!$H$7:$H$100)) -> 0 | D38: =-SUMPRODUCT(([3]分录!$D$7:$D$100=$A38)*INT((([3]分录!$C$7:$C$100="借：")-0.5)*2)*([3]分录!$I$7:$I$100=D$7)*([3]分录!$H$7:$H$100)) -> 0 | E38: =-SUMPRODUCT(([3]分录!$D$7:$D$100=$A38)*INT((([3]分录!$C$7:$C$100="借：")-0.5)*2)*([3]分录!$I$7:$I$100=E$7)*([3]分录!$H$7:$H$100)) -> 0 | F38: =ROUND(SUM(B38:E38),2) -> 0
A39: 合同资产 | B39: 0 | C39: =C37-C38 -> 0 | D39: =D37-D38 -> 0 | E39: =E37-E38 -> 0 | F39: =ROUND(SUM(B39:E39),2) -> 0
A40: 持有待售资产原值 | B40: 0 | C40: =SUMPRODUCT(([3]分录!$D$7:$D$100=$A40)*INT((([3]分录!$C$7:$C$100="借：")-0.5)*2)*([3]分录!$I$7:$I$100=C$7)*([3]分录!$H$7:$H$100)) -> 0 | D40: =SUMPRODUCT(([3]分录!$D$7:$D$100=$A40)*INT((([3]分录!$C$7:$C$100="借：")-0.5)*2)*([3]分录!$I$7:$I$100=D$7)*([3]分录!$H$7:$H$100)) -> 0 | E40: =SUMPRODUCT(([3]分录!$D$7:$D$100=$A40)*INT((([3]分录!$C$7:$C$100="借：")-0.5)*2)*([3]分录!$I$7:$I$100=E$7)*([3]分录!$H$7:$H$100)) -> 0 | F40: =ROUND(SUM(B40:E40),2) -> 0
...

Sheet Sheet1
A2: 项目 | B2: 行
A3: 流动资产： | B3: 1 | C3: =VLOOKUP(A3,试算!$A$9:$B$121,2,FALSE) -> #N/A | O3: TB调整分录 横向还是纵向
A4: 货币资金 | B4: =B3+1 -> 2 | C4: =VLOOKUP(A4,试算!$A$9:$B$121,2,FALSE) -> 1.2884156e+08
A5: 结算备付金* | B5: =B4+1 -> 3 | C5: =VLOOKUP(A5,试算!$A$9:$B$121,2,FALSE) -> #N/A | F5: 财务费用
A6: 拆出资金* | B6: =B5+1 -> 4 | C6: =VLOOKUP(A6,试算!$A$9:$B$121,2,FALSE) -> #N/A | F6: 其中：利息费用
A7: 交易性金融资产 | B7: =B6+1 -> 5 | C7: =VLOOKUP(A7,试算!$A$9:$B$121,2,FALSE) -> 1.0338995e+10 | F7: 利息收入
A8: 衍生金融资产 | B8: =B7+1 -> 6 | C8: =VLOOKUP(A8,试算!$A$9:$B$121,2,FALSE) -> 0 | F8: 汇兑净损失（净收益以“－”号填列）
A9: 应收票据 | B9: =B8+1 -> 7 | C9: =VLOOKUP(A9,试算!$A$9:$B$121,2,FALSE) -> 0
A10: 应收票据原值 | B10: =B9+1 -> 8 | C10: =VLOOKUP(A10,试算!$A$9:$B$121,2,FALSE) -> 0
A11: 应收票据坏账准备 | B11: =B10+1 -> 9 | C11: =VLOOKUP(A11,试算!$A$9:$B$121,2,FALSE) -> 0
A12: 应收账款原值 | B12: =B11+1 -> 10 | C12: =VLOOKUP(A12,试算!$A$9:$B$121,2,FALSE) -> 0 | H12: 加： 营业外收入
A13: 应收账款坏账准备 | B13: =B12+1 -> 11 | C13: =VLOOKUP(A13,试算!$A$9:$B$121,2,FALSE) -> 0 | H13: 其中：政府补助
A14: 应收账款 | B14: =B13+1 -> 12 | C14: =VLOOKUP(A14,试算!$A$9:$B$121,2,FALSE) -> 0
A15: 应收款项融资 | B15: =B14+1 -> 13 | C15: =VLOOKUP(A15,试算!$A$9:$B$121,2,FALSE) -> 0
A16: 应收款项融资原值 | B16: =B15+1 -> 14 | C16: =VLOOKUP(A16,试算!$A$9:$B$121,2,FALSE) -> 0 | H16: 应付职工薪酬
A17: 应收款项融资坏账准备 | B17: =B16+1 -> 15 | C17: =VLOOKUP(A17,试算!$A$9:$B$121,2,FALSE) -> 0 | H17: 其中：应付工资
A18: 预付款项原值 | B18: =B17+1 -> 16 | C18: =VLOOKUP(A18,试算!$A$9:$B$121,2,FALSE) -> 0 | H18: 应付福利费
A19: 预付款项坏账准备 | B19: =B18+1 -> 17 | C19: =VLOOKUP(A19,试算!$A$9:$B$121,2,FALSE) -> 0 | H19: #其中：职工奖励及福利基金
A20: 预付款项 | B20: =B19+1 -> 18 | C20: =VLOOKUP(A20,试算!$A$9:$B$121,2,FALSE) -> 0
A21: 应收保费* | B21: =B20+1 -> 19 | C21: =VLOOKUP(A21,试算!$A$9:$B$121,2,FALSE) -> #N/A | H21: 应交税费
A22: 应收分保账款* | B22: =B21+1 -> 20 | C22: =VLOOKUP(A22,试算!$A$9:$B$121,2,FALSE) -> #N/A | H22: 其中：应交税金
A23: 应收分保合同准备金* | B23: =B22+1 -> 21 | C23: =VLOOKUP(A23,试算!$A$9:$B$121,2,FALSE) -> #N/A
A24: 应收利息原值 | B24: =B23+1 -> 22 | C24: =VLOOKUP(A24,试算!$A$9:$B$121,2,FALSE) -> 0
A25: 应收利息坏账准备 | B25: =B24+1 -> 23 | C25: =VLOOKUP(A25,试算!$A$9:$B$121,2,FALSE) -> 0 | H25: 存货
A26: 应收利息 | B26: =B25+1 -> 24 | C26: =VLOOKUP(A26,试算!$A$9:$B$121,2,FALSE) -> 0 | H26: 其中：原材料
A27: 应收股利原值 | B27: =B26+1 -> 25 | C27: =VLOOKUP(A27,试算!$A$9:$B$121,2,FALSE) -> 0 | H27: 库存商品（产成品）
A28: 应收股利坏账准备 | B28: =B27+1 -> 26 | C28: =VLOOKUP(A28,试算!$A$9:$B$121,2,FALSE) -> 0
A29: 应收股利 | B29: =B28+1 -> 27 | C29: =VLOOKUP(A29,试算!$A$9:$B$121,2,FALSE) -> 0
A30: 其他应收款原值 | B30: =B29+1 -> 28 | C30: =VLOOKUP(A30,试算!$A$9:$B$121,2,FALSE) -> 0
A31: 其他应收款坏账准备 | B31: =B30+1 -> 29 | C31: =VLOOKUP(A31,试算!$A$9:$B$121,2,FALSE) -> 0
A32: 其他应收款 | B32: =B31+1 -> 30 | C32: =VLOOKUP(A32,试算!$A$9:$B$121,2,FALSE) -> 0
A33: 买入返售金融资产* | B33: =B32+1 -> 31 | C33: =VLOOKUP(A33,试算!$A$9:$B$121,2,FALSE) -> #N/A
A34: 存货原值 | B34: =B33+1 -> 32 | C34: =VLOOKUP(A34,试算!$A$9:$B$121,2,FALSE) -> 4.0768702e+08
A35: 存货跌价准备 | B35: =B34+1 -> 33 | C35: =VLOOKUP(A35,试算!$A$9:$B$121,2,FALSE) -> 0
A36: 存货 | B36: =B35+1 -> 34 | C36: =VLOOKUP(A36,试算!$A$9:$B$121,2,FALSE) -> 0
A37: 其中：原材料 | B37: =B36+1 -> 35 | C37: =VLOOKUP(A37,试算!$A$9:$B$121,2,FALSE) -> #N/A
A38: 库存商品（产成品） | B38: =B37+1 -> 36 | C38: =VLOOKUP(A38,试算!$A$9:$B$121,2,FALSE) -> #N/A
A39: 合同资产原值 | B39: =B38+1 -> 37 | C39: =VLOOKUP(A39,试算!$A$9:$B$121,2,FALSE) -> 0
... A113: 资 产 总 计 | B113: =B112+1 -> 111 | C113: =VLOOKUP(A113,试算!$A$9:$B$121,2,FALSE) -> #N/A

Sheet 未审报表
A1: =IF(ABS(D171-D255)<0.005,"","年初未分配利润勾稽有误！")
A2: 未审报表
D3: 索引号：B15-1-1/B15-1-2/B15-1-3
A4: =IF(ABS(D127-D190)<0.005,0,"年初数不平，差额为：") -> 0
A5: =IF(报表格式!E55=""," 对不起，请到参数表中确定报表类型！",CONCATENATE(" 编制单位：",参数!D3)) -> 编制单位：二锅头 | C5: =参数!$D$12 -> 44926 | D5: =CONCATENATE("金额单位：",参数!$D$13) -> 金额单位：人民币元
A6: 资 产 | B6: 行次 | C6: =参数!D12 -> 44926 | D6: =参数!D11 -> 44561
A7: =报表格式!B5 -> 流动资产： | B7: =报表格式!C5 -> 1
A8: =报表格式!B6 -> 货币资金 | B8: =报表格式!C6 -> 2 | C8: 17053593 | D8: 645471.35
A9: =报表格式!B7 -> 结算备付金* | B9: =报表格式!C7 -> 3
A10: =报表格式!B8 -> 拆出资金原值* | B10: =报表格式!C8 -> 4
A11: =报表格式!B9 -> 拆出资金减值准备* | B11: =报表格式!C9 -> 5
A12: =报表格式!B10 -> 拆出资金* | B12: =报表格式!C10 -> 6 | C12: =C10-C11 -> 0 | D12: =D10-D11 -> 0 | G12: 25580389
A13: =报表格式!B11 -> 交易性金融资产 | B13: =报表格式!C11 -> 7 | G13: 8526796.3
A14: =报表格式!B12 -> 衍生金融资产 | B14: =报表格式!C12 -> 8 | G14: =G12-G13 -> 17053593
A15: =报表格式!B13 -> 应收票据原值 | B15: =报表格式!C13 -> 9
A16: =报表格式!B14 -> 应收票据坏账准备 | B16: =报表格式!C14 -> 10
A17: =报表格式!B15 -> 应收票据 | B17: =报表格式!C15 -> 11 | C17: =C15-C16 -> 0 | D17: =D15-D16 -> 0
A18: =报表格式!B16 -> 应收账款原值 | B18: =报表格式!C16 -> 12 | C18: 15449122 | D18: 16718591
A19: =报表格式!B17 -> 应收账款坏账准备 | B19: =报表格式!C17 -> 13 | C19: 1423224.6
A20: =报表格式!B18 -> 应收账款 | B20: =报表格式!C18 -> 14 | C20: =C18-C19 -> 14025898 | D20: =D18-D19 -> 16718591
A21: =报表格式!B19 -> 应收款项融资原值 | B21: =报表格式!C19 -> 15
A22: =报表格式!B20 -> 应收款项融资坏账准备 | B22: =报表格式!C20 -> 16
A23: =报表格式!B21 -> 应收款项融资 | B23: =报表格式!C21 -> 17 | C23: =C21-C22 -> 0 | D23: =D21-D22 -> 0
A24: =报表格式!B22 -> 预付款项原值 | B24: =报表格式!C22 -> 18 | C24: 574623.4 | D24: 1584.26
A25: =报表格式!B23 -> 预付款项坏账准备 | B25: =报表格式!C23 -> 19
A26: =报表格式!B24 -> 预付款项 | B26: =报表格式!C24 -> 20 | C26: =C24-C25 -> 574623.4 | D26: =D24-D25 -> 1584.26
A27: =报表格式!B25 -> 应收保费原值* | B27: =报表格式!C25 -> 21
A28: =报表格式!B26 -> 应收保费坏账准备* | B28: =报表格式!C26 -> 22
A29: =报表格式!B27 -> 应收保费* | B29: =报表格式!C27 -> 23 | C29: =C27-C28 -> 0 | D29: =D27-D28 -> 0
A30: =报表格式!B28 -> 应收分保账款原值* | B30: =报表格式!C28 -> 24
A31: =报表格式!B29 -> 应收分保账款坏账准备* | B31: =报表格式!C29 -> 25
A32: =报表格式!B30 -> 应收分保账款* | B32: =报表格式!C30 -> 26 | C32: =C30-C31 -> 0 | D32: =D30-D31 -> 0
A33: =报表格式!B31 -> 应收分保合同准备金* | B33: =报表格式!C31 -> 27
A34: =报表格式!B32 -> 应收利息原值 | B34: =报表格式!C32 -> 28
A35: =报表格式!B33 -> 应收利息坏账准备 | B35: =报表格式!C33 -> 29
A36: =报表格式!B34 -> 应收利息 | B36: =报表格式!C34 -> 30 | C36: =C34-C35 -> 0 | D36: =D34-D35 -> 0
A37: =报表格式!B35 -> 应收股利原值 | B37: =报表格式!C35 -> 31 | C37: 32823183 | D37: 10512385
A38: =报表格式!B36 -> 应收股利坏账准备 | B38: =报表格式!C36 -> 32
A39: =报表格式!B37 -> 应收股利 | B39: =报表格式!C37 -> 33 | C39: =C37-C38 -> 32823183 | D39: =D37-D38 -> 10512385
A40: =报表格式!B38 -> 其他应收款原值 | B40: =报表格式!C38 -> 34 | C40: 8096269.4 | D40: 12543397
...

Sheet 期初核对
A2: 期初报表核对
A5: =IF(报表格式!E55=""," 对不起，请到参数表中确定报表类型！",CONCATENATE(" 客户名称：",参数!D3)) -> 客户名称：二锅头 | C5: =参数!D11 -> 44561 | E5: =CONCATENATE("金额单位：",参数!$D$13) -> 金额单位：人民币元
A6: =IF(E61<=0.005,"资 产","资产明细核对不符！") -> 资 产 | B6: 行次 | C6: 上期审定数 ① | D6: 本年期初数 ② | E6: 辅助列 | F6: 差异 ①-②
A7: =未审报表!A7 -> 流动资产： | B7: =未审报表!B7 -> 1
A8: =未审报表!A8 -> 货币资金 | B8: =未审报表!B8 -> 2 | C8: 645471.35 | D8: =未审报表!D8 -> 645471.35 | E8: =ABS(F8) -> 0 | F8: =C8-D8 -> 0
A9: =未审报表!A9 -> 结算备付金* | B9: =未审报表!B9 -> 3 | D9: =未审报表!D9 -> 0 | E9: =ABS(F9) -> 0 | F9: =C9-D9 -> 0
A10: =未审报表!A10 -> 拆出资金原值* | B10: =未审报表!B10 -> 4 | D10: =未审报表!D10 -> 0 | E10: =ABS(F10) -> 0 | F10: =C10-D10 -> 0
A11: =未审报表!A11 -> 拆出资金减值准备* | B11: =未审报表!B11 -> 5 | D11: =未审报表!D11 -> 0 | E11: =ABS(F11) -> 0 | F11: =C11-D11 -> 0
A12: =未审报表!A12 -> 拆出资金* | B12: =未审报表!B12 -> 6 | C12: =C10-C11 -> 0 | D12: =D10-D11 -> 0 | E12: =ABS(F12) -> 0 | F12: =C12-D12 -> 0
A13: =未审报表!A13 -> 交易性金融资产 | B13: =未审报表!B13 -> 7 | D13: =未审报表!D13 -> 0 | E13: =ABS(F13) -> 0 | F13: =C13-D13 -> 0
A14: =未审报表!A14 -> 衍生金融资产 | B14: =未审报表!B14 -> 8 | D14: =未审报表!D14 -> 0 | E14: =ABS(F14) -> 0 | F14: =C14-D14 -> 0
A15: =未审报表!A15 -> 应收票据原值 | B15: =未审报表!B15 -> 9 | D15: =未审报表!D15 -> 0 | E15: =ABS(F15) -> 0 | F15: =C15-D15 -> 0
A16: =未审报表!A16 -> 应收票据坏账准备 | B16: =未审报表!B16 -> 10 | D16: =未审报表!D16 -> 0 | E16: =ABS(F16) -> 0 | F16: =C16-D16 -> 0
A17: =未审报表!A17 -> 应收票据 | B17: =未审报表!B17 -> 11 | C17: =C15-C16 -> 0 | D17: =D15-D16 -> 0 | E17: =ABS(F17) -> 0 | F17: =C17-D17 -> 0
A18: =未审报表!A18 -> 应收账款原值 | B18: =未审报表!B18 -> 12 | C18: 16718591 | D18: =未审报表!D18 -> 16718591 | E18: =ABS(F18) -> 0 | F18: =C18-D18 -> 0
A19: =未审报表!A19 -> 应收账款坏账准备 | B19: =未审报表!B19 -> 13 | D19: =未审报表!D19 -> 0 | E19: =ABS(F19) -> 0 | F19: =C19-D19 -> 0
A20: =未审报表!A20 -> 应收账款 | B20: =未审报表!B20 -> 14 | C20: =C18-C19 -> 16718591 | D20: =D18-D19 -> 16718591 | E20: =ABS(F20) -> 0 | F20: =C20-D20 -> 0
A21: =未审报表!A21 -> 应收款项融资原值 | B21: =未审报表!B21 -> 15 | D21: =未审报表!D21 -> 0 | E21: =ABS(F21) -> 0 | F21: =C21-D21 -> 0
A22: =未审报表!A22 -> 应收款项融资坏账准备 | B22: =未审报表!B22 -> 16 | D22: =未审报表!D22 -> 0 | E22: =ABS(F22) -> 0 | F22: =C22-D22 -> 0
A23: =未审报表!A23 -> 应收款项融资 | B23: =未审报表!B23 -> 17 | C23: =C21-C22 -> 0 | D23: =D21-D22 -> 0 | E23: =ABS(F23) -> 0 | F23: =C23-D23 -> 0
A24: =未审报表!A24 -> 预付款项原值 | B24: =未审报表!B24 -> 18 | C24: 1584.26 | D24: =未审报表!D24 -> 1584.26 | E24: =ABS(F24) -> 0 | F24: =C24-D24 -> 0
A25: =未审报表!A25 -> 预付款项坏账准备 | B25: =未审报表!B25 -> 19 | D25: =未审报表!D25 -> 0 | E25: =ABS(F25) -> 0 | F25: =C25-D25 -> 0
A26: =未审报表!A26 -> 预付款项 | B26: =未审报表!B26 -> 20 | C26: =C24-C25 -> 1584.26 | D26: =D24-D25 -> 1584.26 | E26: =ABS(F26) -> 0 | F26: =C26-D26 -> 0
A27: =未审报表!A27 -> 应收保费原值* | B27: =未审报表!B27 -> 21 | D27: =未审报表!D27 -> 0 | E27: =ABS(F27) -> 0 | F27: =C27-D27 -> 0
A28: =未审报表!A28 -> 应收保费坏账准备* | B28: =未审报表!B28 -> 22 | D28: =未审报表!D28 -> 0 | E28: =ABS(F28) -> 0 | F28: =C28-D28 -> 0
A29: =未审报表!A29 -> 应收保费* | B29: =未审报表!B29 -> 23 | C29: =C27-C28 -> 0 | D29: =D27-D28 -> 0 | E29: =ABS(F29) -> 0 | F29: =C29-D29 -> 0
A30: =未审报表!A30 -> 应收分保账款原值* | B30: =未审报表!B30 -> 24 | D30: =未审报表!D30 -> 0 | E30: =ABS(F30) -> 0 | F30: =C30-D30 -> 0
A31: =未审报表!A31 -> 应收分保账款坏账准备* | B31: =未审报表!B31 -> 25 | D31: =未审报表!D31 -> 0 | E31: =ABS(F31) -> 0 | F31: =C31-D31 -> 0
A32: =未审报表!A32 -> 应收分保账款* | B32: =未审报表!B32 -> 26 | C32: =C30-C31 -> 0 | D32: =D30-D31 -> 0 | E32: =ABS(F32) -> 0 | F32: =C32-D32 -> 0
A33: =未审报表!A33 -> 应收分保合同准备金* | B33: =未审报表!B33 -> 27 | D33: =未审报表!D33 -> 0 | E33: =ABS(F33) -> 0 | F33: =C33-D33 -> 0
A34: =未审报表!A34 -> 应收利息原值 | B34: =未审报表!B34 -> 28 | D34: =未审报表!D34 -> 0 | E34: =ABS(F34) -> 0 | F34: =C34-D34 -> 0
A35: =未审报表!A35 -> 应收利息坏账准备 | B35: =未审报表!B35 -> 29 | D35: =未审报表!D35 -> 0 | E35: =ABS(F35) -> 0 | F35: =C35-D35 -> 0
A36: =未审报表!A36 -> 应收利息 | B36: =未审报表!B36 -> 30 | C36: =C34-C35 -> 0 | D36: =D34-D35 -> 0 | E36: =ABS(F36) -> 0 | F36: =C36-D36 -> 0
A37: =未审报表!A37 -> 应收股利原值 | B37: =未审报表!B37 -> 31 | C37: 10512385 | D37: =未审报表!D37 -> 10512385 | E37: =ABS(F37) -> 0 | F37: =C37-D37 -> 0
A38: =未审报表!A38 -> 应收股利坏账准备 | B38: =未审报表!B38 -> 32 | D38: =未审报表!D38 -> 0 | E38: =ABS(F38) -> 0 | F38: =C38-D38 -> 0
A39: =未审报表!A39 -> 应收股利 | B39: =未审报表!B39 -> 33 | C39: =C37-C38 -> 10512385 | D39: =D37-D38 -> 10512385 | E39: =ABS(F39) -> 0 | F39: =C39-D39 -> 0
A40: =未审报表!A40 -> 其他应收款原值 | B40: =未审报表!B40 -> 34 | C40: 12543397 | D40: =未审报表!D40 -> 12543397 | E40: =ABS(F40) -> 0 | F40: =C40-D40 -> 0
A41: =未审报表!A41 -> 其他应收款坏账准备 | B41: =未审报表!B41 -> 35 | D41: =未审报表!D41 -> 0 | E41: =ABS(F41) -> 0 | F41: =C41-D41 -> 0
A42: =未审报表!A42 -> 其他应收款 | B42: =未审报表!B42 -> 36 | C42: =C40-C41 -> 12543397 | D42: =D40-D41 -> 12543397 | E42: =ABS(F42) -> 0 | F42: =C42-D42 -> 0
A43: =未审报表!A43 -> 买入返售金融资产原值* | B43: =未审报表!B43 -> 37 | D43: =未审报表!D43 -> 0 | E43: =ABS(F43) -> 0 | F43: =C43-D43 -> 0
...

Sheet TB
D1: 期末报表
A2: =CONCATENATE("客户名称：",参数!D3) -> 客户名称：二锅头 | C2: =CONCATENATE("编制：",参数!D17) -> 编制：张 | E2: =CONCATENATE("日期：",TEXT(NOW(),"yyyy.mm.dd")) -> 日期：2025.11.06 | I2: 索引：A2-1
A3: =CONCATENATE("会计时点：",TEXT(参数!D12,"yyyy.mm.dd")) -> 会计时点：2022.12.31 | C3: =CONCATENATE("复核：",参数!D18) -> 复核：刘 | E3: 日期： | I3: 分页：
A4: =CONCATENATE("会计年度：",TEXT(参数!D10,"yyyy.mm.dd")) -> 会计年度：2022年度
A5: =IF((ROUND(I127,2))=(ROUND(I190,2)),"资 产","报表未调平!") -> 资 产 | B5: 企业原报数 | C5: 账项调整 | E5: 报表调整 | G5: 其他调整 | I5: 审定数
C6: 借方 | D6: 贷方 | E6: 借方 | F6: 贷方 | G6: 借方 | H6: 贷方
A7: =未审报表!A7 -> 流动资产： | I7: =B7 -> 0 | J7: =A7=未审报表!A7 -> TRUE | K7: =审定报表!A7=TB!A7 -> TRUE
A8: =未审报表!A8 -> 货币资金 | B8: =未审报表!C8 -> 17053593 | C8: =SUMIFS(调整事项汇总表!$I$7:$I$10020,调整事项汇总表!$D$7:$D$10020,"账项调整",调整事项汇总表!$E$7:$E$10020,IF(OR(MID(TRIM($A8),2,1)="：",MID(TRIM($A8),2,1)="、"),REPLACEB(TRIM($A8),1,4,""),TRIM($A8))) -> 0 | D8: =SUMIFS(调整事项汇总表!$J$7:$J$10020,调整事项汇总表!$D$7:$D$10020,"账项调整",调整事项汇总表!$E$7:$E$10020,IF(OR(MID(TRIM($A8),2,1)="：",MID(TRIM($A8),2,1)="、"),REPLACEB(TRIM($A8),1,4,""),TRIM($A8))) -> 0 | E8: =SUMIFS(调整事项汇总表!$I$7:$I$10020,调整事项汇总表!$D$7:$D$10020,"报表调整",调整事项汇总表!$E$7:$E$10020,IF(OR(MID(TRIM($A8),2,1)="：",MID(TRIM($A8),2,1)="、"),REPLACEB(TRIM($A8),1,4,""),TRIM($A8))) -> 0 | F8: =SUMIFS(调整事项汇总表!$J$7:$J$10020,调整事项汇总表!$D$7:$D$10020,"报表调整",调整事项汇总表!$E$7:$E$10020,IF(OR(MID(TRIM($A8),2,1)="：",MID(TRIM($A8),2,1)="、"),REPLACEB(TRIM($A8),1,4,""),TRIM($A8))) -> 0 | G8: =SUMIFS(调整事项汇总表!$I$7:$I$10020,调整事项汇总表!$D$7:$D$10020,"其他",调整事项汇总表!$E$7:$E$10020,IF(OR(MID(TRIM($A8),2,1)="：",MID(TRIM($A8),2,1)="、"),REPLACEB(TRIM($A8),1,4,""),TRIM($A8))) -> 0 | H8: =SUMIFS(调整事项汇总表!$J$7:$J$10020,调整事项汇总表!$D$7:$D$10020,"其他",调整事项汇总表!$E$7:$E$10020,IF(OR(MID(TRIM($A8),2,1)="：",MID(TRIM($A8),2,1)="、"),REPLACEB(TRIM($A8),1,4,""),TRIM($A8))) -> 0 | I8: =B8+C8+E8+G8-H8-F8-D8 -> 17053593 | J8: =A8=未审报表!A8 -> TRUE | K8: =审定报表!A8=TB!A8 -> TRUE
A9: =未审报表!A9 -> 结算备付金* | B9: =未审报表!C9 -> 0 | C9: =SUMIFS(调整事项汇总表!$I$7:$I$10020,调整事项汇总表!$D$7:$D$10020,"账项调整",调整事项汇总表!$E$7:$E$10020,IF(OR(MID(TRIM($A9),2,1)="：",MID(TRIM($A9),2,1)="、"),REPLACEB(TRIM($A9),1,4,""),TRIM($A9))) -> 0 | D9: =SUMIFS(调整事项汇总表!$J$7:$J$10020,调整事项汇总表!$D$7:$D$10020,"账项调整",调整事项汇总表!$E$7:$E$10020,IF(OR(MID(TRIM($A9),2,1)="：",MID(TRIM($A9),2,1)="、"),REPLACEB(TRIM($A9),1,4,""),TRIM($A9))) -> 0 | E9: =SUMIFS(调整事项汇总表!$I$7:$I$10020,调整事项汇总表!$D$7:$D$10020,"报表调整",调整事项汇总表!$E$7:$E$10020,IF(OR(MID(TRIM($A9),2,1)="：",MID(TRIM($A9),2,1)="、"),REPLACEB(TRIM($A9),1,4,""),TRIM($A9))) -> 0 | F9: =SUMIFS(调整事项汇总表!$J$7:$J$10020,调整事项汇总表!$D$7:$D$10020,"报表调整",调整事项汇总表!$E$7:$E$10020,IF(OR(MID(TRIM($A9),2,1)="：",MID(TRIM($A9),2,1)="、"),REPLACEB(TRIM($A9),1,4,""),TRIM($A9))) -> 0 | G9: =SUMIFS(调整事项汇总表!$I$7:$I$10020,调整事项汇总表!$D$7:$D$10020,"其他",调整事项汇总表!$E$7:$E$10020,IF(OR(MID(TRIM($A9),2,1)="：",MID(TRIM($A9),2,1)="、"),REPLACEB(TRIM($A9),1,4,""),TRIM($A9))) -> 0 | H9: =SUMIFS(调整事项汇总表!$J$7:$J$10020,调整事项汇总表!$D$7:$D$10020,"其他",调整事项汇总表!$E$7:$E$10020,IF(OR(MID(TRIM($A9),2,1)="：",MID(TRIM($A9),2,1)="、"),REPLACEB(TRIM($A9),1,4,""),TRIM($A9))) -> 0 | I9: =B9+C9+E9+G9-H9-F9-D9 -> 0 | J9: =A9=未审报表!A9 -> TRUE | K9: =审定报表!A9=TB!A9 -> TRUE
A10: =未审报表!A10 -> 拆出资金原值* | B10: =未审报表!C10 -> 0 | C10: =SUMIFS(调整事项汇总表!$I$7:$I$10020,调整事项汇总表!$D$7:$D$10020,"账项调整",调整事项汇总表!$E$7:$E$10020,IF(OR(MID(TRIM($A10),2,1)="：",MID(TRIM($A10),2,1)="、"),REPLACEB(TRIM($A10),1,4,""),TRIM($A10))) -> 0 | D10: =SUMIFS(调整事项汇总表!$J$7:$J$10020,调整事项汇总表!$D$7:$D$10020,"账项调整",调整事项汇总表!$E$7:$E$10020,IF(OR(MID(TRIM($A10),2,1)="：",MID(TRIM($A10),2,1)="、"),REPLACEB(TRIM($A10),1,4,""),TRIM($A10))) -> 0 | E10: =SUMIFS(调整事项汇总表!$I$7:$I$10020,调整事项汇总表!$D$7:$D$10020,"报表调整",调整事项汇总表!$E$7:$E$10020,IF(OR(MID(TRIM($A10),2,1)="：",MID(TRIM($A10),2,1)="、"),REPLACEB(TRIM($A10),1,4,""),TRIM($A10))) -> 0 | F10: =SUMIFS(调整事项汇总表!$J$7:$J$10020,调整事项汇总表!$D$7:$D$10020,"报表调整",调整事项汇总表!$E$7:$E$10020,IF(OR(MID(TRIM($A10),2,1)="：",MID(TRIM($A10),2,1)="、"),REPLACEB(TRIM($A10),1,4,""),TRIM($A10))) -> 0 | G10: =SUMIFS(调整事项汇总表!$I$7:$I$10020,调整事项汇总表!$D$7:$D$10020,"其他",调整事项汇总表!$E$7:$E$10020,IF(OR(MID(TRIM($A10),2,1)="：",MID(TRIM($A10),2,1)="、"),REPLACEB(TRIM($A10),1,4,""),TRIM($A10))) -> 0 | H10: =SUMIFS(调整事项汇总表!$J$7:$J$10020,调整事项汇总表!$D$7:$D$10020,"其他",调整事项汇总表!$E$7:$E$10020,IF(OR(MID(TRIM($A10),2,1)="：",MID(TRIM($A10),2,1)="、"),REPLACEB(TRIM($A10),1,4,""),TRIM($A10))) -> 0 | I10: =B10+C10+E10+G10-H10-F10-D10 -> 0 | J10: =A10=未审报表!A10 -> TRUE | K10: =审定报表!A10=TB!A10 -> TRUE
A11: =未审报表!A11 -> 拆出资金减值准备* | B11: =未审报表!C11 -> 0 | C11: =SUMIFS(调整事项汇总表!$I$7:$I$10020,调整事项汇总表!$D$7:$D$10020,"账项调整",调整事项汇总表!$E$7:$E$10020,IF(OR(MID(TRIM($A11),2,1)="：",MID(TRIM($A11),2,1)="、"),REPLACEB(TRIM($A11),1,4,""),TRIM($A11))) -> 0 | D11: =SUMIFS(调整事项汇总表!$J$7:$J$10020,调整事项汇总表!$D$7:$D$10020,"账项调整",调整事项汇总表!$E$7:$E$10020,IF(OR(MID(TRIM($A11),2,1)="：",MID(TRIM($A11),2,1)="、"),REPLACEB(TRIM($A11),1,4,""),TRIM($A11))) -> 0 | E11: =SUMIFS(调整事项汇总表!$I$7:$I$10020,调整事项汇总表!$D$7:$D$10020,"报表调整",调整事项汇总表!$E$7:$E$10020,IF(OR(MID(TRIM($A11),2,1)="：",MID(TRIM($A11),2,1)="、"),REPLACEB(TRIM($A11),1,4,""),TRIM($A11))) -> 0 | F11: =SUMIFS(调整事项汇总表!$J$7:$J$10020,调整事项汇总表!$D$7:$D$10020,"报表调整",调整事项汇总表!$E$7:$E$10020,IF(OR(MID(TRIM($A11),2,1)="：",MID(TRIM($A11),2,1)="、"),REPLACEB(TRIM($A11),1,4,""),TRIM($A11))) -> 0 | G11: =SUMIFS(调整事项汇总表!$I$7:$I$10020,调整事项汇总表!$D$7:$D$10020,"其他",调整事项汇总表!$E$7:$E$10020,IF(OR(MID(TRIM($A11),2,1)="：",MID(TRIM($A11),2,1)="、"),REPLACEB(TRIM($A11),1,4,""),TRIM($A11))) -> 0 | H11: =SUMIFS(调整事项汇总表!$J$7:$J$10020,调整事项汇总表!$D$7:$D$10020,"其他",调整事项汇总表!$E$7:$E$10020,IF(OR(MID(TRIM($A11),2,1)="：",MID(TRIM($A11),2,1)="、"),REPLACEB(TRIM($A11),1,4,""),TRIM($A11))) -> 0 | I11: =B11+D11+F11+H11-G11-E11-C11 -> 0 | J11: =A11=未审报表!A11 -> TRUE | K11: =审定报表!A11=TB!A11 -> TRUE
A12: =未审报表!A12 -> 拆出资金* | B12: =未审报表!C12 -> 0 | C12: =C10+C11 -> 0 | D12: =D10+D11 -> 0 | E12: =E10+E11 -> 0 | F12: =F10+F11 -> 0 | G12: =G10+G11 -> 0 | H12: =H10+H11 -> 0 | I12: =B12+C12+E12+G12-H12-F12-D12 -> 0 | J12: =A12=未审报表!A12 -> TRUE | K12: =审定报表!A12=TB!A12 -> TRUE
A13: =未审报表!A13 -> 交易性金融资产 | B13: =未审报表!C13 -> 0 | C13: =SUMIFS(调整事项汇总表!$I$7:$I$10020,调整事项汇总表!$D$7:$D$10020,"账项调整",调整事项汇总表!$E$7:$E$10020,IF(OR(MID(TRIM($A13),2,1)="：",MID(TRIM($A13),2,1)="、"),REPLACEB(TRIM($A13),1,4,""),TRIM($A13))) -> 0 | D13: =SUMIFS(调整事项汇总表!$J$7:$J$10020,调整事项汇总表!$D$7:$D$10020,"账项调整",调整事项汇总表!$E$7:$E$10020,IF(OR(MID(TRIM($A13),2,1)="：",MID(TRIM($A13),2,1)="、"),REPLACEB(TRIM($A13),1,4,""),TRIM($A13))) -> 0 | E13: =SUMIFS(调整事项汇总表!$I$7:$I$10020,调整事项汇总表!$D$7:$D$10020,"报表调整",调整事项汇总表!$E$7:$E$10020,IF(OR(MID(TRIM($A13),2,1)="：",MID(TRIM($A13),2,1)="、"),REPLACEB(TRIM($A13),1,4,""),TRIM($A13))) -> 0 | F13: =SUMIFS(调整事项汇总表!$J$7:$J$10020,调整事项汇总表!$D$7:$D$10020,"报表调整",调整事项汇总表!$E$7:$E$10020,IF(OR(MID(TRIM($A13),2,1)="：",MID(TRIM($A13),2,1)="、"),REPLACEB(TRIM($A13),1,4,""),TRIM($A13))) -> 0 | G13: =SUMIFS(调整事项汇总表!$I$7:$I$10020,调整事项汇总表!$D$7:$D$10020,"其他",调整事项汇总表!$E$7:$E$10020,IF(OR(MID(TRIM($A13),2,1)="：",MID(TRIM($A13),2,1)="、"),REPLACEB(TRIM($A13),1,4,""),TRIM($A13))) -> 0 | H13: =SUMIFS(调整事项汇总表!$J$7:$J$10020,调整事项汇总表!$D$7:$D$10020,"其他",调整事项汇总表!$E$7:$E$10020,IF(OR(MID(TRIM($A13),2,1)="：",MID(TRIM($A13),2,1)="、"),REPLACEB(TRIM($A13),1,4,""),TRIM($A13))) -> 0 | I13: =B13+C13+E13+G13-H13-F13-D13 -> 0 | J13: =A13=未审报表!A13 -> TRUE | K13: =审定报表!A13=TB!A13 -> TRUE
A14: =未审报表!A14 -> 衍生金融资产 | B14: =未审报表!C14 -> 0 | C14: =SUMIFS(调整事项汇总表!$I$7:$I$10020,调整事项汇总表!$D$7:$D$10020,"账项调整",调整事项汇总表!$E$7:$E$10020,IF(OR(MID(TRIM($A14),2,1)="：",MID(TRIM($A14),2,1)="、"),REPLACEB(TRIM($A14),1,4,""),TRIM($A14))) -> 0 | D14: =SUMIFS(调整事项汇总表!$J$7:$J$10020,调整事项汇总表!$D$7:$D$10020,"账项调整",调整事项汇总表!$E$7:$E$10020,IF(OR(MID(TRIM($A14),2,1)="：",MID(TRIM($A14),2,1)="、"),REPLACEB(TRIM($A14),1,4,""),TRIM($A14))) -> 0 | E14: =SUMIFS(调整事项汇总表!$I$7:$I$10020,调整事项汇总表!$D$7:$D$10020,"报表调整",调整事项汇总表!$E$7:$E$10020,IF(OR(MID(TRIM($A14),2,1)="：",MID(TRIM($A14),2,1)="、"),REPLACEB(TRIM($A14),1,4,""),TRIM($A14))) -> 0 | F14: =SUMIFS(调整事项汇总表!$J$7:$J$10020,调整事项汇总表!$D$7:$D$10020,"报表调整",调整事项汇总表!$E$7:$E$10020,IF(OR(MID(TRIM($A14),2,1)="：",MID(TRIM($A14),2,1)="、"),REPLACEB(TRIM($A14),1,4,""),TRIM($A14))) -> 0 | G14: =SUMIFS(调整事项汇总表!$I$7:$I$10020,调整事项汇总表!$D$7:$D$10020,"其他",调整事项汇总表!$E$7:$E$10020,IF(OR(MID(TRIM($A14),2,1)="：",MID(TRIM($A14),2,1)="、"),REPLACEB(TRIM($A14),1,4,""),TRIM($A14))) -> 0 | H14: =SUMIFS(调整事项汇总表!$J$7:$J$10020,调整事项汇总表!$D$7:$D$10020,"其他",调整事项汇总表!$E$7:$E$10020,IF(OR(MID(TRIM($A14),2,1)="：",MID(TRIM($A14),2,1)="、"),REPLACEB(TRIM($A14),1,4,""),TRIM($A14))) -> 0 | I14: =B14+C14+E14+G14-H14-F14-D14 -> 0 | J14: =A14=未审报表!A14 -> TRUE | K14: =审定报表!A14=TB!A14 -> TRUE
A15: =未审报表!A15 -> 应收票据原值 | B15: =未审报表!C15 -> 0 | C15: =SUMIFS(调整事项汇总表!$I$7:$I$10020,调整事项汇总表!$D$7:$D$10020,"账项调整",调整事项汇总表!$E$7:$E$10020,IF(OR(MID(TRIM($A15),2,1)="：",MID(TRIM($A15),2,1)="、"),REPLACEB(TRIM($A15),1,4,""),TRIM($A15))) -> 0 | D15: =SUMIFS(调整事项汇总表!$J$7:$J$10020,调整事项汇总表!$D$7:$D$10020,"账项调整",调整事项汇总表!$E$7:$E$10020,IF(OR(MID(TRIM($A15),2,1)="：",MID(TRIM($A15),2,1)="、"),REPLACEB(TRIM($A15),1,4,""),TRIM($A15))) -> 0 | E15: =SUMIFS(调整事项汇总表!$I$7:$I$10020,调整事项汇总表!$D$7:$D$10020,"报表调整",调整事项汇总表!$E$7:$E$10020,IF(OR(MID(TRIM($A15),2,1)="：",MID(TRIM($A15),2,1)="、"),REPLACEB(TRIM($A15),1,4,""),TRIM($A15))) -> 0 | F15: =SUMIFS(调整事项汇总表!$J$7:$J$10020,调整事项汇总表!$D$7:$D$10020,"报表调整",调整事项汇总表!$E$7:$E$10020,IF(OR(MID(TRIM($A15),2,1)="：",MID(TRIM($A15),2,1)="、"),REPLACEB(TRIM($A15),1,4,""),TRIM($A15))) -> 0 | G15: =SUMIFS(调整事项汇总表!$I$7:$I$10020,调整事项汇总表!$D$7:$D$10020,"其他",调整事项汇总表!$E$7:$E$10020,IF(OR(MID(TRIM($A15),2,1)="：",MID(TRIM($A15),2,1)="、"),REPLACEB(TRIM($A15),1,4,""),TRIM($A15))) -> 0 | H15: =SUMIFS(调整事项汇总表!$J$7:$J$10020,调整事项汇总表!$D$7:$D$10020,"其他",调整事项汇总表!$E$7:$E$10020,IF(OR(MID(TRIM($A15),2,1)="：",MID(TRIM($A15),2,1)="、"),REPLACEB(TRIM($A15),1,4,""),TRIM($A15))) -> 0 | I15: =B15+C15+E15+G15-H15-F15-D15 -> 0 | J15: =A15=未审报表!A15 -> TRUE | K15: =审定报表!A15=TB!A15 -> TRUE
A16: =未审报表!A16 -> 应收票据坏账准备 | B16: =未审报表!C16 -> 0 | C16: =SUMIFS(调整事项汇总表!$I$7:$I$10020,调整事项汇总表!$D$7:$D$10020,"账项调整",调整事项汇总表!$E$7:$E$10020,IF(OR(MID(TRIM($A16),2,1)="：",MID(TRIM($A16),2,1)="、"),REPLACEB(TRIM($A16),1,4,""),TRIM($A16))) -> 0 | D16: =SUMIFS(调整事项汇总表!$J$7:$J$10020,调整事项汇总表!$D$7:$D$10020,"账项调整",调整事项汇总表!$E$7:$E$10020,IF(OR(MID(TRIM($A16),2,1)="：",MID(TRIM($A16),2,1)="、"),REPLACEB(TRIM($A16),1,4,""),TRIM($A16))) -> 0 | E16: =SUMIFS(调整事项汇总表!$I$7:$I$10020,调整事项汇总表!$D$7:$D$10020,"报表调整",调整事项汇总表!$E$7:$E$10020,IF(OR(MID(TRIM($A16),2,1)="：",MID(TRIM($A16),2,1)="、"),REPLACEB(TRIM($A16),1,4,""),TRIM($A16))) -> 0 | F16: =SUMIFS(调整事项汇总表!$J$7:$J$10020,调整事项汇总表!$D$7:$D$10020,"报表调整",调整事项汇总表!$E$7:$E$10020,IF(OR(MID(TRIM($A16),2,1)="：",MID(TRIM($A16),2,1)="、"),REPLACEB(TRIM($A16),1,4,""),TRIM($A16))) -> 0 | G16: =SUMIFS(调整事项汇总表!$I$7:$I$10020,调整事项汇总表!$D$7:$D$10020,"其他",调整事项汇总表!$E$7:$E$10020,IF(OR(MID(TRIM($A16),2,1)="：",MID(TRIM($A16),2,1)="、"),REPLACEB(TRIM($A16),1,4,""),TRIM($A16))) -> 0 | H16: =SUMIFS(调整事项汇总表!$J$7:$J$10020,调整事项汇总表!$D$7:$D$10020,"其他",调整事项汇总表!$E$7:$E$10020,IF(OR(MID(TRIM($A16),2,1)="：",MID(TRIM($A16),2,1)="、"),REPLACEB(TRIM($A16),1,4,""),TRIM($A16))) -> 0 | I16: =B16+D16+F16+H16-G16-E16-C16 -> 0 | J16: =A16=未审报表!A16 -> TRUE | K16: =审定报表!A16=TB!A16 -> TRUE
A17: =未审报表!A17 -> 应收票据 | B17: =未审报表!C17 -> 0 | C17: =C15+C16 -> 0 | D17: =D15+D16 -> 0 | E17: =E15+E16 -> 0 | F17: =F15+F16 -> 0 | G17: =G15+G16 -> 0 | H17: =H15+H16 -> 0 | I17: =B17+C17+E17+G17-H17-F17-D17 -> 0 | J17: =A17=未审报表!A17 -> TRUE | K17: =审定报表!A17=TB!A17 -> TRUE
A18: =未审报表!A18 -> 应收账款原值 | B18: =未审报表!C18 -> 15449122 | C18: =SUMIFS(调整事项汇总表!$I$7:$I$10020,调整事项汇总表!$D$7:$D$10020,"账项调整",调整事项汇总表!$E$7:$E$10020,IF(OR(MID(TRIM($A18),2,1)="：",MID(TRIM($A18),2,1)="、"),REPLACEB(TRIM($A18),1,4,""),TRIM($A18))) -> 3862755.9 | D18: =SUMIFS(调整事项汇总表!$J$7:$J$10020,调整事项汇总表!$D$7:$D$10020,"账项调整",调整事项汇总表!$E$7:$E$10020,IF(OR(MID(TRIM($A18),2,1)="：",MID(TRIM($A18),2,1)="、"),REPLACEB(TRIM($A18),1,4,""),TRIM($A18))) -> 0 | E18: =SUMIFS(调整事项汇总表!$I$7:$I$10020,调整事项汇总表!$D$7:$D$10020,"报表调整",调整事项汇总表!$E$7:$E$10020,IF(OR(MID(TRIM($A18),2,1)="：",MID(TRIM($A18),2,1)="、"),REPLACEB(TRIM($A18),1,4,""),TRIM($A18))) -> 0 | F18: =SUMIFS(调整事项汇总表!$J$7:$J$10020,调整事项汇总表!$D$7:$D$10020,"报表调整",调整事项汇总表!$E$7:$E$10020,IF(OR(MID(TRIM($A18),2,1)="：",MID(TRIM($A18),2,1)="、"),REPLACEB(TRIM($A18),1,4,""),TRIM($A18))) -> 0 | G18: =SUMIFS(调整事项汇总表!$I$7:$I$10020,调整事项汇总表!$D$7:$D$10020,"其他",调整事项汇总表!$E$7:$E$10020,IF(OR(MID(TRIM($A18),2,1)="：",MID(TRIM($A18),2,1)="、"),REPLACEB(TRIM($A18),1,4,""),TRIM($A18))) -> 0 | H18: =SUMIFS(调整事项汇总表!$J$7:$J$10020,调整事项汇总表!$D$7:$D$10020,"其他",调整事项汇总表!$E$7:$E$10020,IF(OR(MID(TRIM($A18),2,1)="：",MID(TRIM($A18),2,1)="、"),REPLACEB(TRIM($A18),1,4,""),TRIM($A18))) -> 0 | I18: =B18+C18+E18+G18-H18-F18-D18 -> 19311878 | J18: =A18=未审报表!A18 -> TRUE | K18: =审定报表!A18=TB!A18 -> TRUE
A19: =未审报表!A19 -> 应收账款坏账准备 | B19: =未审报表!C19 -> 1423224.6 | C19: =SUMIFS(调整事项汇总表!$I$7:$I$10020,调整事项汇总表!$D$7:$D$10020,"账项调整",调整事项汇总表!$E$7:$E$10020,IF(OR(MID(TRIM($A19),2,1)="：",MID(TRIM($A19),2,1)="、"),REPLACEB(TRIM($A19),1,4,""),TRIM($A19))) -> 0 | D19: =SUMIFS(调整事项汇总表!$J$7:$J$10020,调整事项汇总表!$D$7:$D$10020,"账项调整",调整事项汇总表!$E$7:$E$10020,IF(OR(MID(TRIM($A19),2,1)="：",MID(TRIM($A19),2,1)="、"),REPLACEB(TRIM($A19),1,4,""),TRIM($A19))) -> 207942.74 | E19: =SUMIFS(调整事项汇总表!$I$7:$I$10020,调整事项汇总表!$D$7:$D$10020,"报表调整",调整事项汇总表!$E$7:$E$10020,IF(OR(MID(TRIM($A19),2,1)="：",MID(TRIM($A19),2,1)="、"),REPLACEB(TRIM($A19),1,4,""),TRIM($A19))) -> 0 | F19: =SUMIFS(调整事项汇总表!$J$7:$J$10020,调整事项汇总表!$D$7:$D$10020,"报表调整",调整事项汇总表!$E$7:$E$10020,IF(OR(MID(TRIM($A19),2,1)="：",MID(TRIM($A19),2,1)="、"),REPLACEB(TRIM($A19),1,4,""),TRIM($A19))) -> 0 | G19: =SUMIFS(调整事项汇总表!$I$7:$I$10020,调整事项汇总表!$D$7:$D$10020,"其他",调整事项汇总表!$E$7:$E$10020,IF(OR(MID(TRIM($A19),2,1)="：",MID(TRIM($A19),2,1)="、"),REPLACEB(TRIM($A19),1,4,""),TRIM($A19))) -> 0 | H19: =SUMIFS(调整事项汇总表!$J$7:$J$10020,调整事项汇总表!$D$7:$D$10020,"其他",调整事项汇总表!$E$7:$E$10020,IF(OR(MID(TRIM($A19),2,1)="：",MID(TRIM($A19),2,1)="、"),REPLACEB(TRIM($A19),1,4,""),TRIM($A19))) -> 0 | I19: =B19+D19+F19+H19-G19-E19-C19 -> 1631167.3 | J19: =A19=未审报表!A19 -> TRUE | K19: =审定报表!A19=TB!A19 -> TRUE
A20: =未审报表!A20 -> 应收账款 | B20: =未审报表!C20 -> 14025898 | C20: =C18+C19 -> 3862755.9 | D20: =D18+D19 -> 207942.74 | E20: =E18+E19 -> 0 | F20: =F18+F19 -> 0 | G20: =G18+G19 -> 0 | H20: =H18+H19 -> 0 | I20: =B20+C20+E20+G20-H20-F20-D20 -> 17680711 | J20: =A20=未审报表!A20 -> TRUE | K20: =审定报表!A20=TB!A20 -> TRUE
A21: =未审报表!A21 -> 应收款项融资原值 | B21: =未审报表!C21 -> 0 | C21: =SUMIFS(调整事项汇总表!$I$7:$I$10020,调整事项汇总表!$D$7:$D$10020,"账项调整",调整事项汇总表!$E$7:$E$10020,IF(OR(MID(TRIM($A21),2,1)="：",MID(TRIM($A21),2,1)="、"),REPLACEB(TRIM($A21),1,4,""),TRIM($A21))) -> 0 | D21: =SUMIFS(调整事项汇总表!$J$7:$J$10020,调整事项汇总表!$D$7:$D$10020,"账项调整",调整事项汇总表!$E$7:$E$10020,IF(OR(MID(TRIM($A21),2,1)="：",MID(TRIM($A21),2,1)="、"),REPLACEB(TRIM($A21),1,4,""),TRIM($A21))) -> 0 | E21: =SUMIFS(调整事项汇总表!$I$7:$I$10020,调整事项汇总表!$D$7:$D$10020,"报表调整",调整事项汇总表!$E$7:$E$10020,IF(OR(MID(TRIM($A21),2,1)="：",MID(TRIM($A21),2,1)="、"),REPLACEB(TRIM($A21),1,4,""),TRIM($A21))) -> 0 | F21: =SUMIFS(调整事项汇总表!$J$7:$J$10020,调整事项汇总表!$D$7:$D$10020,"报表调整",调整事项汇总表!$E$7:$E$10020,IF(OR(MID(TRIM($A21),2,1)="：",MID(TRIM($A21),2,1)="、"),REPLACEB(TRIM($A21),1,4,""),TRIM($A21))) -> 0 | G21: =SUMIFS(调整事项汇总表!$I$7:$I$10020,调整事项汇总表!$D$7:$D$10020,"其他",调整事项汇总表!$E$7:$E$10020,IF(OR(MID(TRIM($A21),2,1)="：",MID(TRIM($A21),2,1)="、"),REPLACEB(TRIM($A21),1,4,""),TRIM($A21))) -> 0 | H21: =SUMIFS(调整事项汇总表!$J$7:$J$10020,调整事项汇总表!$D$7:$D$10020,"其他",调整事项汇总表!$E$7:$E$10020,IF(OR(MID(TRIM($A21),2,1)="：",MID(TRIM($A21),2,1)="、"),REPLACEB(TRIM($A21),1,4,""),TRIM($A21))) -> 0 | I21: =B21+C21+E21+G21-H21-F21-D21 -> 0 | J21: =A21=未审报表!A21 -> TRUE | K21: =审定报表!A21=TB!A21 -> TRUE
A22: =未审报表!A22 -> 应收款项融资坏账准备 | B22: =未审报表!C22 -> 0 | C22: =SUMIFS(调整事项汇总表!$I$7:$I$10020,调整事项汇总表!$D$7:$D$10020,"账项调整",调整事项汇总表!$E$7:$E$10020,IF(OR(MID(TRIM($A22),2,1)="：",MID(TRIM($A22),2,1)="、"),REPLACEB(TRIM($A22),1,4,""),TRIM($A22))) -> 0 | D22: =SUMIFS(调整事项汇总表!$J$7:$J$10020,调整事项汇总表!$D$7:$D$10020,"账项调整",调整事项汇总表!$E$7:$E$10020,IF(OR(MID(TRIM($A22),2,1)="：",MID(TRIM($A22),2,1)="、"),REPLACEB(TRIM($A22),1,4,""),TRIM($A22))) -> 0 | E22: =SUMIFS(调整事项汇总表!$I$7:$I$10020,调整事项汇总表!$D$7:$D$10020,"报表调整",调整事项汇总表!$E$7:$E$10020,IF(OR(MID(TRIM($A22),2,1)="：",MID(TRIM($A22),2,1)="、"),REPLACEB(TRIM($A22),1,4,""),TRIM($A22))) -> 0 | F22: =SUMIFS(调整事项汇总表!$J$7:$J$10020,调整事项汇总表!$D$7:$D$10020,"报表调整",调整事项汇总表!$E$7:$E$10020,IF(OR(MID(TRIM($A22),2,1)="：",MID(TRIM($A22),2,1)="、"),REPLACEB(TRIM($A22),1,4,""),TRIM($A22))) -> 0 | G22: =SUMIFS(调整事项汇总表!$I$7:$I$10020,调整事项汇总表!$D$7:$D$10020,"其他",调整事项汇总表!$E$7:$E$10020,IF(OR(MID(TRIM($A22),2,1)="：",MID(TRIM($A22),2,1)="、"),REPLACEB(TRIM($A22),1,4,""),TRIM($A22))) -> 0 | H22: =SUMIFS(调整事项汇总表!$J$7:$J$10020,调整事项汇总表!$D$7:$D$10020,"其他",调整事项汇总表!$E$7:$E$10020,IF(OR(MID(TRIM($A22),2,1)="：",MID(TRIM($A22),2,1)="、"),REPLACEB(TRIM($A22),1,4,""),TRIM($A22))) -> 0 | I22: =B22+D22+F22+H22-G22-E22-C22 -> 0 | J22: =A22=未审报表!A22 -> TRUE | K22: =审定报表!A22=TB!A22 -> TRUE
A23: =未审报表!A23 -> 应收款项融资 | B23: =未审报表!C23 -> 0 | C23: =C21+C22 -> 0 | D23: =D21+D22 -> 0 | E23: =E21+E22 -> 0 | F23: =F21+F22 -> 0 | G23: =G21+G22 -> 0 | H23: =H21+H22 -> 0 | I23: =B23+C23+E23+G23-H23-F23-D23 -> 0 | J23: =A23=未审报表!A23 -> TRUE | K23: =审定报表!A23=TB!A23 -> TRUE
A24: =未审报表!A24 -> 预付款项原值 | B24: =未审报表!C24 -> 574623.4 | C24: =SUMIFS(调整事项汇总表!$I$7:$I$10020,调整事项汇总表!$D$7:$D$10020,"账项调整",调整事项汇总表!$E$7:$E$10020,IF(OR(MID(TRIM($A24),2,1)="：",MID(TRIM($A24),2,1)="、"),REPLACEB(TRIM($A24),1,4,""),TRIM($A24))) -> 0 | D24: =SUMIFS(调整事项汇总表!$J$7:$J$10020,调整事项汇总表!$D$7:$D$10020,"账项调整",调整事项汇总表!$E$7:$E$10020,IF(OR(MID(TRIM($A24),2,1)="：",MID(TRIM($A24),2,1)="、"),REPLACEB(TRIM($A24),1,4,""),TRIM($A24))) -> 0 | E24: =SUMIFS(调整事项汇总表!$I$7:$I$10020,调整事项汇总表!$D$7:$D$10020,"报表调整",调整事项汇总表!$E$7:$E$10020,IF(OR(MID(TRIM($A24),2,1)="：",MID(TRIM($A24),2,1)="、"),REPLACEB(TRIM($A24),1,4,""),TRIM($A24))) -> 0 | F24: =SUMIFS(调整事项汇总表!$J$7:$J$10020,调整事项汇总表!$D$7:$D$10020,"报表调整",调整事项汇总表!$E$7:$E$10020,IF(OR(MID(TRIM($A24),2,1)="：",MID(TRIM($A24),2,1)="、"),REPLACEB(TRIM($A24),1,4,""),TRIM($A24))) -> 0 | G24: =SUMIFS(调整事项汇总表!$I$7:$I$10020,调整事项汇总表!$D$7:$D$10020,"其他",调整事项汇总表!$E$7:$E$10020,IF(OR(MID(TRIM($A24),2,1)="：",MID(TRIM($A24),2,1)="、"),REPLACEB(TRIM($A24),1,4,""),TRIM($A24))) -> 0 | H24: =SUMIFS(调整事项汇总表!$J$7:$J$10020,调整事项汇总表!$D$7:$D$10020,"其他",调整事项汇总表!$E$7:$E$10020,IF(OR(MID(TRIM($A24),2,1)="：",MID(TRIM($A24),2,1)="、"),REPLACEB(TRIM($A24),1,4,""),TRIM($A24))) -> 0 | I24: =B24+C24+E24+G24-H24-F24-D24 -> 574623.4 | J24: =A24=未审报表!A24 -> TRUE | K24: =审定报表!A24=TB!A24 -> TRUE
A25: =未审报表!A25 -> 预付款项坏账准备 | B25: =未审报表!C25 -> 0 | C25: =SUMIFS(调整事项汇总表!$I$7:$I$10020,调整事项汇总表!$D$7:$D$10020,"账项调整",调整事项汇总表!$E$7:$E$10020,IF(OR(MID(TRIM($A25),2,1)="：",MID(TRIM($A25),2,1)="、"),REPLACEB(TRIM($A25),1,4,""),TRIM($A25))) -> 0 | D25: =SUMIFS(调整事项汇总表!$J$7:$J$10020,调整事项汇总表!$D$7:$D$10020,"账项调整",调整事项汇总表!$E$7:$E$10020,IF(OR(MID(TRIM($A25),2,1)="：",MID(TRIM($A25),2,1)="、"),REPLACEB(TRIM($A25),1,4,""),TRIM($A25))) -> 0 | E25: =SUMIFS(调整事项汇总表!$I$7:$I$10020,调整事项汇总表!$D$7:$D$10020,"报表调整",调整事项汇总表!$E$7:$E$10020,IF(OR(MID(TRIM($A25),2,1)="：",MID(TRIM($A25),2,1)="、"),REPLACEB(TRIM($A25),1,4,""),TRIM($A25))) -> 0 | F25: =SUMIFS(调整事项汇总表!$J$7:$J$10020,调整事项汇总表!$D$7:$D$10020,"报表调整",调整事项汇总表!$E$7:$E$10020,IF(OR(MID(TRIM($A25),2,1)="：",MID(TRIM($A25),2,1)="、"),REPLACEB(TRIM($A25),1,4,""),TRIM($A25))) -> 0 | G25: =SUMIFS(调整事项汇总表!$I$7:$I$10020,调整事项汇总表!$D$7:$D$10020,"其他",调整事项汇总表!$E$7:$E$10020,IF(OR(MID(TRIM($A25),2,1)="：",MID(TRIM($A25),2,1)="、"),REPLACEB(TRIM($A25),1,4,""),TRIM($A25))) -> 0 | H25: =SUMIFS(调整事项汇总表!$J$7:$J$10020,调整事项汇总表!$D$7:$D$10020,"其他",调整事项汇总表!$E$7:$E$10020,IF(OR(MID(TRIM($A25),2,1)="：",MID(TRIM($A25),2,1)="、"),REPLACEB(TRIM($A25),1,4,""),TRIM($A25))) -> 0 | I25: =B25+D25+F25+H25-G25-E25-C25 -> 0 | J25: =A25=未审报表!A25 -> TRUE | K25: =审定报表!A25=TB!A25 -> TRUE
A26: =未审报表!A26 -> 预付款项 | B26: =未审报表!C26 -> 574623.4 | C26: =C24+C25 -> 0 | D26: =D24+D25 -> 0 | E26: =E24+E25 -> 0 | F26: =F24+F25 -> 0 | G26: =G24+G25 -> 0 | H26: =H24+H25 -> 0 | I26: =B26+C26+E26+G26-H26-F26-D26 -> 574623.4 | J26: =A26=未审报表!A26 -> TRUE | K26: =审定报表!A26=TB!A26 -> TRUE
A27: =未审报表!A27 -> 应收保费原值* | B27: =未审报表!C27 -> 0 | C27: =SUMIFS(调整事项汇总表!$I$7:$I$10020,调整事项汇总表!$D$7:$D$10020,"账项调整",调整事项汇总表!$E$7:$E$10020,IF(OR(MID(TRIM($A27),2,1)="：",MID(TRIM($A27),2,1)="、"),REPLACEB(TRIM($A27),1,4,""),TRIM($A27))) -> 0 | D27: =SUMIFS(调整事项汇总表!$J$7:$J$10020,调整事项汇总表!$D$7:$D$10020,"账项调整",调整事项汇总表!$E$7:$E$10020,IF(OR(MID(TRIM($A27),2,1)="：",MID(TRIM($A27),2,1)="、"),REPLACEB(TRIM($A27),1,4,""),TRIM($A27))) -> 0 | E27: =SUMIFS(调整事项汇总表!$I$7:$I$10020,调整事项汇总表!$D$7:$D$10020,"报表调整",调整事项汇总表!$E$7:$E$10020,IF(OR(MID(TRIM($A27),2,1)="：",MID(TRIM($A27),2,1)="、"),REPLACEB(TRIM($A27),1,4,""),TRIM($A27))) -> 0 | F27: =SUMIFS(调整事项汇总表!$J$7:$J$10020,调整事项汇总表!$D$7:$D$10020,"报表调整",调整事项汇总表!$E$7:$E$10020,IF(OR(MID(TRIM($A27),2,1)="：",MID(TRIM($A27),2,1)="、"),REPLACEB(TRIM($A27),1,4,""),TRIM($A27))) -> 0 | G27: =SUMIFS(调整事项汇总表!$I$7:$I$10020,调整事项汇总表!$D$7:$D$10020,"其他",调整事项汇总表!$E$7:$E$10020,IF(OR(MID(TRIM($A27),2,1)="：",MID(TRIM($A27),2,1)="、"),REPLACEB(TRIM($A27),1,4,""),TRIM($A27))) -> 0 | H27: =SUMIFS(调整事项汇总表!$J$7:$J$10020,调整事项汇总表!$D$7:$D$10020,"其他",调整事项汇总表!$E$7:$E$10020,IF(OR(MID(TRIM($A27),2,1)="：",MID(TRIM($A27),2,1)="、"),REPLACEB(TRIM($A27),1,4,""),TRIM($A27))) -> 0 | I27: =B27+C27+E27+G27-H27-F27-D27 -> 0 | J27: =A27=未审报表!A27 -> TRUE | K27: =审定报表!A27=TB!A27 -> TRUE
A28: =未审报表!A28 -> 应收保费坏账准备* | B28: =未审报表!C28 -> 0 | C28: =SUMIFS(调整事项汇总表!$I$7:$I$10020,调整事项汇总表!$D$7:$D$10020,"账项调整",调整事项汇总表!$E$7:$E$10020,IF(OR(MID(TRIM($A28),2,1)="：",MID(TRIM($A28),2,1)="、"),REPLACEB(TRIM($A28),1,4,""),TRIM($A28))) -> 0 | D28: =SUMIFS(调整事项汇总表!$J$7:$J$10020,调整事项汇总表!$D$7:$D$10020,"账项调整",调整事项汇总表!$E$7:$E$10020,IF(OR(MID(TRIM($A28),2,1)="：",MID(TRIM($A28),2,1)="、"),REPLACEB(TRIM($A28),1,4,""),TRIM($A28))) -> 0 | E28: =SUMIFS(调整事项汇总表!$I$7:$I$10020,调整事项汇总表!$D$7:$D$10020,"报表调整",调整事项汇总表!$E$7:$E$10020,IF(OR(MID(TRIM($A28),2,1)="：",MID(TRIM($A28),2,1)="、"),REPLACEB(TRIM($A28),1,4,""),TRIM($A28))) -> 0 | F28: =SUMIFS(调整事项汇总表!$J$7:$J$10020,调整事项汇总表!$D$7:$D$10020,"报表调整",调整事项汇总表!$E$7:$E$10020,IF(OR(MID(TRIM($A28),2,1)="：",MID(TRIM($A28),2,1)="、"),REPLACEB(TRIM($A28),1,4,""),TRIM($A28))) -> 0 | G28: =SUMIFS(调整事项汇总表!$I$7:$I$10020,调整事项汇总表!$D$7:$D$10020,"其他",调整事项汇总表!$E$7:$E$10020,IF(OR(MID(TRIM($A28),2,1)="：",MID(TRIM($A28),2,1)="、"),REPLACEB(TRIM($A28),1,4,""),TRIM($A28))) -> 0 | H28: =SUMIFS(调整事项汇总表!$J$7:$J$10020,调整事项汇总表!$D$7:$D$10020,"其他",调整事项汇总表!$E$7:$E$10020,IF(OR(MID(TRIM($A28),2,1)="：",MID(TRIM($A28),2,1)="、"),REPLACEB(TRIM($A28),1,4,""),TRIM($A28))) -> 0 | I28: =B28+D28+F28+H28-G28-E28-C28 -> 0 | J28: =A28=未审报表!A28 -> TRUE | K28: =审定报表!A28=TB!A28 -> TRUE
A29: =未审报表!A29 -> 应收保费* | B29: =未审报表!C29 -> 0 | C29: =C27+C28 -> 0 | D29: =D27+D28 -> 0 | E29: =E27+E28 -> 0 | F29: =F27+F28 -> 0 | G29: =G27+G28 -> 0 | H29: =H27+H28 -> 0 | I29: =B29+C29+E29+G29-H29-F29-D29 -> 0 | J29: =A29=未审报表!A29 -> TRUE | K29: =审定报表!A29=TB!A29 -> TRUE
