Workbook
Name _: [1]低值易耗品!$A$1:$I$225
Name _.dbf: '[2]12进销存'!$A$3:$Q$235
Name _0.dbf: [3]累计销售!$A$6:$E$62
Name _11: [4]其他业务利润!$A$5:$G$12
Name _999年12月31日股份应收帐款.dbf: #REF!
Name _999年12月31日股份应收帐款.dbf: #REF!
Name _999年12月31日股份应收帐款.dbf: #REF!
Name _Hlk533511527: 'RP 016'!$A$42
Name _Hlk533597423: 'RP 016'!$A$57
Name a: #REF!
Name a: #REF!
Name a: #REF!
Name AFSDGEGQ: #REF!
Name AFSDGEGQ: #REF!
Name AFSDGEGQ: #REF!
Name ASDFA: #REF!
Name ASDFA: #REF!
Name ASDFA: #REF!
Name ASFDA: #REF!
Name ASFDA: #REF!
Name ASFDA: #REF!
Name clah: #REF!
Name clah: #REF!
Name clah: #REF!
Name clz: #REF!
Name clz: #REF!
Name clz: #REF!
Name fuck: [6]资产负债表!#REF!
Name fuck: [6]资产负债表!#REF!
Name fuck: [6]资产负债表!#REF!
Name OLE_LINK1: 'RP 095'!$A$32
Name OLE_LINK2: 'RP 095'!$A$35
Name OLE_LINK4: 'RP 095'!$A$29
Name OLE_LINK9: 'RP 095'!$A$33
Name Print_Area_MI: #REF!
Name Print_Area_MI: #REF!
Name Print_Area_MI: #REF!
Name Print_Area_MI: #REF!
Name Print_Area_MI: #REF!
Name SD: #REF!
Name SD: #REF!
Name SD: #REF!
Name SDF: #REF!
Name SDF: #REF!
Name SDF: #REF!
Name SDFA: #REF!
Name SDFA: #REF!
Name SDFA: #REF!
Name SDFSD: #REF!
Name SDFSD: #REF!
Name SDFSD: #REF!
Name SF: #REF!
Name SF: #REF!
Name SF: #REF!
Name Sheet1: #REF!
Name Sheet1: #REF!
Name Sheet1: #REF!
Name Sheet10: #REF!
Name Sheet10: #REF!
Name Sheet10: #REF!

Sheet 目录
A2: 20XX年XX月XX日ABC公司报告文件包 | E2: B30-13-1
A4: 序号 | B4: 文件名称 | C4: 目的 | D4: 工作表 | E4: 核对（是否完成）
B5: 基础信息 | C5: 一般信息 | D5: 基础信息 | E5: 完成
A6: =1+A5 -> 1 | B6: 会计政策 | C6: 一般信息 | D6: RP 001 | E6: 完成
A7: 2.1 | B7: 资产负债表 | C7: 财务报表 | D7: RP 002-1 | E7: 完成
A8: 2.2 | B8: 资产负债表 | C8: 财务报表 | D8: RP 002-2 | E8: 完成
A9: 3 | B9: 利润表 | C9: 财务报表 | D9: RP 003 | E9: 完成
A10: =1+A9 -> 4 | B10: 现金流量表 | C10: 财务报表 | D10: RP 004 | E10: 完成
A11: =1+A10 -> 5 | B11: 所有者权益变动表 | C11: 财务报表 | D11: RP 005 | E11: 完成
A12: =1+A11 -> 6 | B12: 准则差异调节表 | C12: 备查信息 | D12: RP 006 | E12: 完成
A13: =1+A12 -> 7 | B13: 集团间交易（销售、采购、费用） | C13: 集团间交易 | D13: RP 007 | E13: 完成
A14: =1+A13 -> 8 | B14: 集团间交易（资产、负债） | C14: 集团间交易 | D14: RP 008 | E14: 完成
A15: =1+A14 -> 9 | B15: 集团间交易（存货） | C15: 未实现内部利润 | D15: RP 009 | E15: 完成
A16: =1+A15 -> 10 | B16: 集团间交易（销售采购固定资产） | C16: 未实现内部利润 | D16: RP 010 | E16: 完成
A17: =1+A16 -> 11 | B17: 集团间交易（现金流量） | C17: 集团间交易 | D17: RP 011 | E17: 完成
A18: =1+A17 -> 12 | B18: 货币资金 | C18: 披露信息 | D18: RP 012 | E18: 完成
A19: 13 | B19: 交易性金融资产 | C19: 披露信息 | D19: RP 013 | E19: 完成
A20: 14 | B20: 以公允价值计量且其变动计入当期损益的金融资产 | C20: 披露信息 | D20: RP 014 | E20: 完成
A21: =1+A20 -> 15 | B21: 衍生金融资产 | C21: 披露信息 | D21: RP 015 | E21: 完成
A22: 16 | B22: 应收票据 | C22: 披露信息 | D22: RP 016 | E22: 完成
A23: 17 | B23: 应收账款 | C23: 披露信息 | D23: RP 017 | E23: 完成
A24: 18 | B24: 应收款项融资 | C24: 披露信息 | D24: RP 018 | E24: 完成
A25: 19 | B25: 预付款项 | C25: 披露信息 | D25: RP 019 | E25: 完成
A26: 20 | B26: 其他应收款（应收利息、应收股利、其他应收款） | C26: 披露信息 | D26: RP 020 | E26: 完成
A27: 20.1 | B27: 其中：应收利息 | C27: 披露信息 | D27: RP 020-1 | E27: 完成
A28: 20.2 | B28: 应收股利 | C28: 披露信息 | D28: RP 020-2 | E28: 完成
A29: 20.3 | B29: 其他应收款 | C29: 披露信息 | D29: RP 020-3 | E29: 完成
A30: 21 | B30: 存货 | C30: 披露信息 | D30: RP 021 | E30: 完成
A31: =A30+1 -> 22 | B31: 合同资产 | C31: 披露信息 | D31: RP 022 | E31: 完成
A32: =A31+1 -> 23 | B32: 持有待售的资产和持有待售的负债 | C32: 披露信息 | D32: RP 023 | E32: 完成
A33: =A32+1 -> 24 | B33: 一年内到期的非流动负债 | C33: 披露信息 | D33: RP 024 | E33: 完成
A34: =A33+1 -> 25 | B34: 其他流动资产 | C34: 披露信息 | D34: RP 025 | E34: 完成
A35: =A34+1 -> 26 | B35: 债权投资 | C35: 披露信息 | D35: RP 026 | E35: 完成
A36: =A35+1 -> 27 | B36: 可供出售金融资产 | C36: 披露信息 | D36: RP 027 | E36: 完成
A37: =A36+1 -> 28 | B37: 其他债权投资 | C37: 披露信息 | D37: RP 028 | E37: 完成
A38: =A37+1 -> 29 | B38: 持有至到期投资 | C38: 披露信息 | D38: RP 029 | E38: 完成
A39: =A38+1 -> 30 | B39: 长期应收款 | C39: 披露信息 | D39: RP 030 | E39: 完成
A40: =A39+1 -> 31 | B40: 设定受益计划净资产 | C40: 披露信息 | D40: RP 031 | E40: 完成
A41: =A40+1 -> 32 | B41: 长期股权投资 | C41: 披露信息 | D41: RP 032 | E41: 完成
A42: =A41+1 -> 33 | B42: 其他权益工具投资 | C42: 披露信息 | D42: RP 033 | E42: 完成
...

Sheet 基础信息
A1: 基础信息
A2: 一般信息
A4: 公司代码
A5: 公司简称
A6: 公司名称
A7: 报告币种代码
A8: 报告币种
A9: 财务期间
A12: 地址
A13: 董事长
A14: 总经理
A15: 审计师
... A22: 电子邮件
A25: 项目 | B25: 人数
A26: 总经理、董事会秘书、内审
A27: 一般经理
A28: 员工
A29: 合计
A30: 临时工
A31: 外包人员

Sheet RP 001
A1: 公司名称 | B1: =基础信息!C5 -> 0 | E1: BACK
A2: 财务期间 | B2: =基础信息!B9 -> 0
A3: 内容 | B3: 主要会计政策、会计估计（根据具体情况适当增减）
A4: 1 | B4: 会计年度
A6: 2 | B6: 营业周期
A8: 3 | B8: 记账本位币
A10: 4 | B10: 同一控制下和非同一控制下企业合并的会计处理
A12: 5 | B12: 合并财务报表编制方法
A14: 6 | B14: 合营安排的分类及共同经营的会计处理
A16: 7 | B16: 现金等价物
A18: 8 | B18: 外币折算
A20: 9 | B20: 金融工具
A22: 10 | B22: 公允价值计量
A24: 11 | B24: 应收票据及应收账款
A26: 12 | B26: 存货
... A74: 36 | B74: 非金融资产证券化业务的主要会计处理方法

Sheet RP 002-1
A1: 资产负债表
A2: =基础信息!B6 -> 0 | D2: 单位：人民币元
A3: 项目 | B3: 附注 | C3: 20X8.12.31 | D3: 20X7.12.31
A4: 流动资产:
A5: 货币资金 | C5: ='RP 006'!E6 -> 0
A6: 交易性金融资产
A7: 以公允价值计量且其变动计入当期损益的金融资产 | C7: ='RP 006'!E8 -> 0
A8: 衍生金融资产 （不适用的删除）
A9: 应收票据 | C9: ='RP 006'!E10 -> 0
A10: 应收账款
A11: 应收款项融资
A12: 预付款项 | C12: ='RP 006'!E19 -> 0
A13: 其他应收款
A14: 存货 | C14: ='RP 006'!E25 -> 0
A15: 合同资产
A16: 持有待售资产 （不适用的删除）
A17: 一年内到期的非流动资产 | C17: ='RP 006'!E30 -> 0
A18: 其他流动资产 | C18: ='RP 006'!E41 -> 0
A19: 流动资产合计 | C19: =SUM(C5:C18) -> 0 | D19: =SUM(D5:D18) -> 0
A20: 非流动资产:
A21: 债权投资
A22: 可供出售金融资产 | C22: ='RP 006'!E46 -> 0
A23: 其他债权投资
A24: 持有至到期投资 | C24: ='RP 006'!E47 -> 0
A25: 长期应收款 | C25: ='RP 006'!E48 -> 0
A26: 设定受益计划净资产 （不适用的删除）
A27: 长期股权投资 | C27: ='RP 006'!E52 -> 0
A28: 其他权益工具投资
A29: 其他非流动金融资产
A30: 投资性房地产 | C30: ='RP 006'!E57 -> 0
A31: 固定资产 | C31: ='RP 006'!E62 -> 0
A32: 在建工程 | C32: ='RP 006'!E63 -> 0
A33: 生产性生物资产 | C33: ='RP 006'!E64 -> 0
A34: 油气资产 | C34: ='RP 006'!E65 -> 0
A35: 无形资产 | C35: ='RP 006'!E68 -> 0
A36: 开发支出 | C36: ='RP 006'!E69 -> 0
A37: 商誉 | C37: ='RP 006'!E70 -> 0
A38: 长期待摊费用 | C38: ='RP 006'!E71 -> 0
A39: 递延所得税资产 | C39: ='RP 006'!E72 -> 0
A40: 其他非流动资产 | C40: ='RP 006'!E73 -> 0
...

Sheet RP 002-2
A1: 资产负债表（续）
A3: 项目 | B3: 附注 | C3: 20X7.12.31 | D3: 20X6.12.31
A4: 流动负债:
A5: 短期借款 | C5: ='RP 006'!E81 -> 0
A6: 交易性金融负债
A7: 以公允价值计量且其变动计入当期损益的金融负债 | C7: ='RP 006'!E83 -> 0
A8: 衍生金融负债 （不适用的删除）
A9: 应付票据 | C9: ='RP 006'!E85 -> 0
A10: 应付账款
A11: 预收款项 | C11: ='RP 006'!E87 -> 0
A12: 合同负债
A13: 应付职工薪酬 | C13: ='RP 006'!E89 -> 0
A14: 应交税费 | C14: ='RP 006'!E90 -> 0
A15: 其他应付款 | C15: ='RP 006'!E91 -> 0
A16: 持有待售负债（不适用的删除）
A17: 一年内到期的非流动负债 | C17: ='RP 006'!E93 -> 0
A18: 其他流动负债 | C18: ='RP 006'!E102 -> 0
A19: 流动负债合计 | C19: =SUM(C5:C18) -> 0 | D19: =SUM(D5:D18) -> 0
A20: 非流动负债:
A21: 长期借款 | C21: ='RP 006'!E105 -> 0
A22: 应付债券 | C22: ='RP 006'!E106 -> 0
A23: 其中：优先股（不适用的删除）
A24: 永续债（不适用的删除）
A25: 长期应付款 | C25: ='RP 006'!E107 -> 0
A26: 长期应付职工薪酬（不适用的删除）
A27: 预计负债 | C27: ='RP 006'!E110 -> 0
A28: 递延收益
A29: 递延所得税负债 | C29: ='RP 006'!E112 -> 0
A30: 其他非流动负债 | C30: ='RP 006'!E113 -> 0
A31: 非流动负债合计 | C31: =SUM(C21:C30) -> 0 | D31: =SUM(D21:D30) -> 0
A32: 负债合计 | C32: =C19+C31 -> 0 | D32: =D19+D31 -> 0
A33: 股东权益:
A34: 股本 | C34: ='RP 006'!E117 -> 0
A35: 其他权益工具（不适用的删除）
A36: 其中：优先股
A37: 永续债
A38: 资本公积 | C38: ='RP 006'!E121 -> 0
A39: 减：库存股 | C39: ='RP 006'!E122 -> 0
A40: 其他综合收益
A41: 专项储备
...

Sheet RP 003 
A1: 利润表
A2: =基础信息!B6 -> 0 | F2: 单位：人民币元
A3: 项目 | B3: 附注 | C3: 20X7年度 | E3: 20X6年度
A5: 一、营业收入 | C5: ='RP 006'!E135 -> 0
A6: 减：营业成本 | C6: ='RP 006'!E136 -> 0
A7: 税金及附加 | C7: ='RP 006'!E137 -> 0
A8: 销售费用 | C8: ='RP 006'!E138 -> 0
A9: 管理费用 | C9: ='RP 006'!E139 -> 0
A10: 研发费用
A11: 财务费用 | C11: ='RP 006'!E141 -> 0
A12: 其中：利息费用
A13: 利息收入
A14: 加：其他收益 | C14: ='RP 006'!E144 -> 0
A15: 投资收益(损失以“-”号填列）
A16: 其中：对联营企业和合营企业的投资收益
A17: 净敞口套期收益（损失以“-”号填列） | C17: ='RP 006'!E141 -> 0
A18: 公允价值变动收益(损失以“-”号填列） | C18: ='RP 006'!E144 -> 0
A19: 信用减值损失
A20: 资产减值损失 | C20: ='RP 006'!E147 -> 0
A21: 资产处置收益(损失以“-”号填列）
A22: 二、营业利润(损失以“-”号填列） | C22: =C5-C6-C7-C8-C9-C10-C11-C14+C16+C17+C20+C21 -> 0 | D22: =D5-D6-D7-D8-D9-D10-D11-D14+D16+D17+D20+D21 -> 0 | E22: =E5-E6-E7-E8-E9-E10-E11-E14+E16+E17+E20+E21 -> 0
A23: 加：营业外收入 | C23: ='RP 006'!E155 -> 0
A24: 减：营业外支出 | C24: ='RP 006'!E156 -> 0
A25: 三、利润总额(损失以“-”号填列） | C25: =C22+C23-C24 -> 0 | E25: =E22+E23-E24 -> 0
A26: 减：所得税费用 | C26: ='RP 006'!E158 -> 0
A27: 四、净利润(损失以“-”号填列） | C27: =C25-C26 -> 0 | E27: =E25-E26 -> 0
A28: （一）按经营持续性分类
A29: 1、持续经营净利润（净亏损以“-”号填列） | C29: ='RP 006'!E161 -> 0
A30: 2、终止经营净利润（净亏损以“-”号填列） | C30: ='RP 006'!E162 -> 0
A31: （二）按所有权归属分类
A32: 1、归属于母公司股东的净利润 | C32: ='RP 006'!E164 -> 0
A33: 2、少数股东损益 | C33: ='RP 006'!E165 -> 0
A34: 五、其他综合收益的税后净额
A35: 归属于母公司股东的其他综合收益的税后净额
A36: （一）以后不能重分类进损益的其他综合收益
A37: 1、重新计量设定受益计划变动额（不适用的删除）
A38: 2、权益法下不能转损益的其他综合收益（不适用的删除）
A39: 3、其他权益工具投资公允价值变动
A40: 4、企业自身信用风险公允价值变动
A41: ……
...

Sheet RP 004 
A1: 现金流量表
A2: =基础信息!B6 -> 0 | I2: 单位：人民币元
A3: 项目 | B3: 附注 | C3: 20X7年度 | E3: 20X3年度 | H3: 20X6年度
A5: 一、经营活动产生的现金流量：
A6: 销售商品、提供劳务收到的现金
A7: 收到的税费返还
A8: 收到其他与经营活动有关的现金
A9: 经营活动现金流入小计 | C9: =SUM(C6:C8) -> 0 | E9: =SUM(E6:E8) -> 0 | F9: =SUM(F6:F8) -> 0 | G9: =SUM(G6:G8) -> 0 | H9: =SUM(H6:H8) -> 0
A10: 购买商品、接受劳务支付的现金
A11: 支付给职工以及为职工支付的现金
A12: 支付的各项税费
A13: 支付其他与经营活动有关的现金
A14: 经营活动现金流出小计 | C14: =C10+C11+C12+C13 -> 0 | E14: =E10+E11+E12+E13 -> 0 | F14: =F10+F11+F12+F13 -> 0 | G14: =G10+G11+G12+G13 -> 0 | H14: =H10+H11+H12+H13 -> 0
A15: 经营活动产生的现金流量净额 | C15: =C9-C14 -> 0 | E15: =E9-E14 -> 0 | F15: =F9-F14 -> 0 | G15: =G9-G14 -> 0 | H15: =H9-H14 -> 0
A16: 二、投资活动产生的现金流量：
A17: 收回投资收到的现金
A18: 取得投资收益收到的现金
A19: 处置固定资产、无形资产和其他长期资产收回的 现金净额
A20: 处置子公司及其他营业单位收到的现金净额
A21: 收到其他与投资活动有关的现金
A22: 投资活动现金流入小计 | C22: =SUM(C17:C21) -> 0 | E22: =SUM(E17:E21) -> 0 | F22: =SUM(F17:F21) -> 0 | G22: =SUM(G17:G21) -> 0 | H22: =SUM(H17:H21) -> 0
A23: 购置固定资产、无形资产和其他长期资产支付的现金
A24: 投资支付的现金
A25: 取得子公司及其他营业单位支付的现金净额
A26: 支付其他与投资活动有关的现金
A27: 投资活动现金流出小计 | C27: =SUM(C23:C26) -> 0 | E27: =SUM(E23:E26) -> 0 | F27: =SUM(F23:F26) -> 0 | G27: =SUM(G23:G26) -> 0 | H27: =SUM(H23:H26) -> 0
A28: 投资活动产生的现金流量净额 | C28: =C22-C27 -> 0 | E28: =E22-E27 -> 0 | F28: =F22-F27 -> 0 | G28: =G22-G27 -> 0 | H28: =H22-H27 -> 0
A29: 三、筹资活动产生的现金流量：
A30: 吸收投资收到的现金
A31: 其中：子公司吸收少数股东权益性投资收到的现金
A32: 取得借款收到的现金
A33: 收到其他与筹资活动有关的现金
A34: 筹资活动现金流入小计 | C34: =C30+C32+C33 -> 0 | E34: =E30+E32+E33 -> 0 | F34: =F30+F32+F33 -> 0 | G34: =G30+G32+G33 -> 0 | H34: =H30+H32+H33 -> 0
A35: 偿还债务支付的现金
A36: 分配股利、利润或偿付利息支付的现金
A37: 其中：子公司支付少数股东的现金股利
A38: 支付其他与筹资活动有关的现金
A39: 其中：子公司减资支付给少数股东的现金
A40: 筹资活动现金流出小计 | C40: =C35+C36+C38 -> 0 | E40: =E35+E36+E38 -> 0 | F40: =F35+F36+F38 -> 0 | G40: =G35+G36+G38 -> 0 | H40: =H35+H36+H38 -> 0
A41: 筹资活动产生的现金流量净额 | C41: =C34-C40 -> 0 | E41: =E34-E40 -> 0 | F41: =F34-F40 -> 0 | G41: =G34-G40 -> 0 | H41: =H34-H40 -> 0
...

Sheet RP 005
B1: 合并股东（或所有者）权益变动表 | O1: 合并股东（或所有者）权益变动表
A3: =基础信息!B6 -> 0 | N3: 单位：人民币元 | AA3: 单位：人民币元
A4: 项 目 | B4: 20X8年度 | O4: 20X7年度
B5: 归属于母公司股东权益 | M5: 少数股东 权益 | N5: 股东（或所有者）权益 合计 | O5: 归属于母公司股东权益 | Z5: 少数股东 权益 | AA5: 股东（或所有者）权益 合计
B6: 股本 | C6: 其他权益工具（不适用的删除） | F6: 资本公积 | G6: 减：库存股 | H6: 其他综合收益 | I6: 专项储备 | J6: 盈余公积 | K6: 未分配利润 | L6: 其他 | O6: 股本 | P6: 其他权益工具（不适用的删除） | S6: 资本公积 | T6: 减：库存股 | U6: 其他综合收益 | V6: 专项储备 | W6: 盈余公积 | X6: 未分配利润 | Y6: 其他
C7: 优先股 | D7: 永续债 | E7: 其他 | P7: 优先股 | Q7: 永续债 | R7: 其他
A8: 一、上年年末余额 | B8: =O35 -> 0 | C8: =P35 -> 0 | D8: =Q35 -> 0 | E8: =R35 -> 0 | F8: =S35 -> 0 | G8: =T35 -> 0 | H8: =U35 -> 0 | I8: =V35 -> 0 | ... M8: =Z35 -> 0 | N8: =B8+C8+D8+E8+F8-G8+H8+I8+J8+K8+L8+M8 -> 0 | AA8: =O8+P8+Q8+R8+S8-T8+V8+W8+X8+Y8+Z8+U8 -> 0
A9: 加：会计政策变更 | B9: —— | C9: —— | D9: —— | E9: —— | F9: —— | G9: —— | H9: —— | I9: —— | J9: —— | K9: —— | L9: —— | M9: —— | N9: —— | AA9: =O9+P9+Q9+R9+S9-T9+V9+W9+X9+Y9+Z9+U9 -> 0
A10: 前期差错更正 | B10: —— | C10: —— | D10: —— | E10: —— | F10: —— | G10: —— | H10: —— | I10: —— | J10: —— | K10: —— | L10: —— | M10: —— | N10: —— | AA10: =O10+P10+Q10+R10+S10-T10+V10+W10+X10+Y10+Z10+U10 -> 0
A11: 其他 | N11: =B11+C11+D11+E11+F11-G11+H11+I11+J11+K11+L11+M11 -> 0 | AA11: =O11+P11+Q11+R11+S11-T11+V11+W11+X11+Y11+Z11+U11 -> 0
A12: 二、本年年初余额 | B12: =B8+B11 -> 0 | C12: =C8+C11 -> 0 | D12: =D8+D11 -> 0 | E12: =E8+E11 -> 0 | F12: =F8+F11 -> 0 | G12: =G8+G11 -> 0 | H12: =H8+H11 -> 0 | I12: =I8+I11 -> 0 | ... M12: =M8+M11 -> 0 | N12: =B12+C12+D12+E12+F12-G12+H12+I12+J12+K12+L12+M12 -> 0 | O12: =O8+O9+O10+O11 -> 0 | P12: =P8+P9+P10+P11 -> 0 | Q12: =Q8+Q9+Q10+Q11 -> 0 | R12: =R8+R9+R10+R11 -> 0 | S12: =S8+S9+S10+S11 -> 0 | T12: =T8+T9+T10+T11 -> 0 | U12: =U8+U9+U10+U11 -> 0 | V12: =V8+V9+V10+V11 -> 0 | ... Z12: =Z8+Z9+Z10+Z11 -> 0 | AA12: =O12+P12+Q12+R12+S12-T12+V12+W12+X12+Y12+Z12+U12 -> 0
A13: 三、本年增减变动金额（减少以“-”号填列） | B13: =B14+B15+B20+B24+B31 -> 0 | C13: =C14+C15+C20+C24+C31 -> 0 | D13: =D14+D15+D20+D24+D31 -> 0 | E13: =E14+E15+E20+E24+E31 -> 0 | F13: =F14+F15+F20+F24+F31 -> 0 | G13: =G14+G15+G20+G24+G31 -> 0 | H13: =H14+H15+H20+H24+H31 -> 0 | I13: =I14+I15+I20+I24+I31 -> 0 | ... M13: =M14+M15+M20+M24+M31 -> 0 | N13: =B13+C13+D13+E13+F13-G13+H13+I13+J13+K13+L13+M13 -> 0 | O13: =O14+O15+O20+O24+O31 -> 0 | P13: =P14+P15+P20+P24+P31 -> 0 | Q13: =Q14+Q15+Q20+Q24+Q31 -> 0 | R13: =R14+R15+R20+R24+R31 -> 0 | S13: =S14+S15+S20+S24+S31 -> 0 | T13: =T14+T15+T20+T24+T31 -> 0 | U13: =U14+U15+U20+U24+U31 -> 0 | V13: =V14+V15+V20+V24+V31 -> 0 | ... Z13: =Z14+Z15+Z20+Z24+Z31 -> 0 | AA13: =O13+P13+Q13+R13+S13-T13+V13+W13+X13+Y13+Z13+U13 -> 0
A14: （一）综合收益总额 | N14: =B14+C14+D14+E14+F14-G14+H14+I14+J14+K14+L14+M14 -> 0 | AA14: =O14+P14+Q14+R14+S14-T14+V14+W14+X14+Y14+Z14+U14 -> 0
A15: （二）股东（或所有者）投入和减少资本 | B15: =SUM(B16:B19) -> 0 | C15: =SUM(C16:C19) -> 0 | D15: =SUM(D16:D19) -> 0 | E15: =SUM(E16:E19) -> 0 | F15: =SUM(F16:F19) -> 0 | G15: =SUM(G16:G19) -> 0 | H15: =SUM(H16:H19) -> 0 | I15: =SUM(I16:I19) -> 0 | ... M15: =SUM(M16:M19) -> 0 | N15: =B15+C15+D15+E15+F15-G15+H15+I15+J15+K15+L15+M15 -> 0 | O15: =SUM(O16:O19) -> 0 | P15: =SUM(P16:P19) -> 0 | Q15: =SUM(Q16:Q19) -> 0 | R15: =SUM(R16:R19) -> 0 | S15: =SUM(S16:S19) -> 0 | T15: =SUM(T16:T19) -> 0 | U15: =SUM(U16:U19) -> 0 | V15: =SUM(V16:V19) -> 0 | ... Z15: =SUM(Z16:Z19) -> 0 | AA15: =O15+P15+Q15+R15+S15-T15+V15+W15+X15+Y15+Z15+U15 -> 0
A16: 1．股东投入资本 | N16: =B16+C16+D16+E16+F16-G16+H16+I16+J16+K16+L16+M16 -> 0 | AA16: =O16+P16+Q16+R16+S16-T16+V16+W16+X16+Y16+Z16+U16 -> 0
A17: 2. 其他权益工具持有者投入资本（不适用的删除） | N17: =B17+C17+D17+E17+F17-G17+H17+I17+J17+K17+L17+M17 -> 0 | AA17: =O17+P17+Q17+R17+S17-T17+V17+W17+X17+Y17+Z17+U17 -> 0
A18: 3．股份支付计入股东权益的金额 | N18: =B18+C18+D18+E18+F18-G18+H18+I18+J18+K18+L18+M18 -> 0 | AA18: =O18+P18+Q18+R18+S18-T18+V18+W18+X18+Y18+Z18+U18 -> 0
A19: 4．其他 | N19: =B19+C19+D19+E19+F19-G19+H19+I19+J19+K19+L19+M19 -> 0 | AA19: =O19+P19+Q19+R19+S19-T19+V19+W19+X19+Y19+Z19+U19 -> 0
A20: （三）利润分配 | B20: =SUM(B21:B23) -> 0 | C20: =SUM(C21:C23) -> 0 | D20: =SUM(D21:D23) -> 0 | E20: =SUM(E21:E23) -> 0 | F20: =SUM(F21:F23) -> 0 | G20: =SUM(G21:G23) -> 0 | H20: =SUM(H21:H23) -> 0 | I20: =SUM(I21:I23) -> 0 | ... M20: =SUM(M21:M23) -> 0 | N20: =B20+C20+D20+E20+F20-G20+H20+I20+J20+K20+L20+M20 -> 0 | O20: =SUM(O21:O23) -> 0 | P20: =SUM(P21:P23) -> 0 | Q20: =SUM(Q21:Q23) -> 0 | R20: =SUM(R21:R23) -> 0 | S20: =SUM(S21:S23) -> 0 | T20: =SUM(T21:T23) -> 0 | U20: =SUM(U21:U23) -> 0 | V20: =SUM(V21:V23) -> 0 | ... Z20: =SUM(Z21:Z23) -> 0 | AA20: =O20+P20+Q20+R20+S20-T20+V20+W20+X20+Y20+Z20+U20 -> 0
A21: 1．提取盈余公积 | N21: =B21+C21+D21+E21+F21-G21+H21+I21+J21+K21+L21+M21 -> 0 | AA21: =O21+P21+Q21+R21+S21-T21+V21+W21+X21+Y21+Z21+U21 -> 0
A22: 2．对股东（或所有者）的分配 | N22: =B22+C22+D22+E22+F22-G22+H22+I22+J22+K22+L22+M22 -> 0 | AA22: =O22+P22+Q22+R22+S22-T22+V22+W22+X22+Y22+Z22+U22 -> 0
A23: 3．其他 | N23: =B23+C23+D23+E23+F23-G23+H23+I23+J23+K23+L23+M23 -> 0 | AA23: =O23+P23+Q23+R23+S23-T23+V23+W23+X23+Y23+Z23+U23 -> 0
A24: （四）股东权益内部结转 | B24: =SUM(B25:B30) -> 0 | C24: =SUM(C25:C30) -> 0 | D24: =SUM(D25:D30) -> 0 | E24: =SUM(E25:E30) -> 0 | F24: =SUM(F25:F30) -> 0 | G24: =SUM(G25:G30) -> 0 | H24: =SUM(H25:H30) -> 0 | I24: =SUM(I25:I30) -> 0 | ... M24: =SUM(M25:M30) -> 0 | N24: =B24+C24+D24+E24+F24-G24+H24+I24+J24+K24+L24+M24 -> 0 | O24: =SUM(O25:O30) -> 0 | P24: =SUM(P25:P30) -> 0 | Q24: =SUM(Q25:Q30) -> 0 | R24: =SUM(R25:R30) -> 0 | S24: =SUM(S25:S30) -> 0 | T24: =SUM(T25:T30) -> 0 | U24: =SUM(U25:U30) -> 0 | V24: =SUM(V25:V30) -> 0 | ... Z24: =SUM(Z25:Z30) -> 0 | AA24: =O24+P24+Q24+R24+S24-T24+V24+W24+X24+Y24+Z24+U24 -> 0
A25: 1．资本公积转增股本（或资本） | N25: =B25+C25+D25+E25+F25-G25+H25+I25+J25+K25+L25+M25 -> 0 | AA25: =O25+P25+Q25+R25+S25-T25+V25+W25+X25+Y25+Z25+U25 -> 0
A26: 2．盈余公积转增股本（或资本） | N26: =B26+C26+D26+E26+F26-G26+H26+I26+J26+K26+L26+M26 -> 0 | AA26: =O26+P26+Q26+R26+S26-T26+V26+W26+X26+Y26+Z26+U26 -> 0
A27: 3．盈余公积弥补亏损 | N27: =B27+C27+D27+E27+F27-G27+H27+I27+J27+K27+L27+M27 -> 0 | AA27: =O27+P27+Q27+R27+S27-T27+V27+W27+X27+Y27+Z27+U27 -> 0
A28: 4. 设定受益计划变动额结转留存收益（不适用的删除） | N28: =B28+C28+D28+E28+F28-G28+H28+I28+J28+K28+L28+M28 -> 0 | AA28: =O28+P28+Q28+R28+S28-T28+V28+W28+X28+Y28+Z28+U28 -> 0
A29: 5．其他综合收益结转留存收益
A30: 6．其他 | N30: =B30+C30+D30+E30+F30-G30+H30+I30+J30+K30+L30+M30 -> 0 | AA30: =O30+P30+Q30+R30+S30-T30+V30+W30+X30+Y30+Z30+U30 -> 0
A31: （五）专项储备 | B31: =B32+B33 -> 0 | C31: =C32+C33 -> 0 | D31: =D32+D33 -> 0 | E31: =E32+E33 -> 0 | F31: =F32+F33 -> 0 | G31: =G32+G33 -> 0 | H31: =H32+H33 -> 0 | I31: =SUM(I32:I33) -> 0 | J31: =SUM(J32:J33) -> 0 | K31: =SUM(K32:K33) -> 0 | L31: =SUM(L32:L33) -> 0 | M31: =SUM(M32:M33) -> 0 | N31: =B31+C31+D31+E31+F31-G31+H31+I31+J31+K31+L31+M31 -> 0 | O31: =SUM(O32:O33) -> 0 | P31: =SUM(P32:P33) -> 0 | Q31: =SUM(Q32:Q33) -> 0 | R31: =SUM(R32:R33) -> 0 | S31: =SUM(S32:S33) -> 0 | T31: =SUM(T32:T33) -> 0 | U31: =SUM(U32:U33) -> 0 | V31: =SUM(V32:V33) -> 0 | ... Z31: =SUM(Z32:Z33) -> 0 | AA31: =O31+P31+Q31+R31+S31-T31+V31+W31+X31+Y31+Z31+U31 -> 0
A32: 1．本期提取 | N32: =B32+C32+D32+E32+F32-G32+H32+I32+J32+K32+L32+M32 -> 0 | AA32: =O32+P32+Q32+R32+S32-T32+V32+W32+X32+Y32+Z32+U32 -> 0
A33: 2．本期使用（以负号填列） | N33: =B33+C33+D33+E33+F33-G33+H33+I33+J33+K33+L33+M33 -> 0 | AA33: =O33+P33+Q33+R33+S33-T33+V33+W33+X33+Y33+Z33+U33 -> 0
A34: （六）其他 | N34: =B34+C34+D34+E34+F34-G34+H34+I34+J34+K34+L34+M34 -> 0 | Z34: =SUM(O34:Y34) -> 0 | AA34: =SUM(P34:Z34) -> 0 | AB34: 备忘录第3号二、6
A35: 四、本年年末余额 | B35: =B12+B13 -> 0 | C35: =C12+C13 -> 0 | D35: =D12+D13 -> 0 | E35: =E12+E13 -> 0 | F35: =F12+F13 -> 0 | G35: =G12+G13 -> 0 | H35: =H12+H13 -> 0 | I35: =I12+I13 -> 0 | ... O35: =O12+O13 -> 0 | P35: 0 | Q35: 0 | R35: 0 | S35: =S12+S13 -> 0 | T35: =T12+T13 -> 0 | U35: 0 | V35: =V12+V13 -> 0 | W35: =W12+W13 -> 0 | X35: =X12+X13 -> 0 | Y35: =Y12+Y13 -> 0 | Z35: =Z12+Z13 -> 0 | AA35: =AA12+AA13 -> 0
A37: 公司法定代表人： | F37: 主管会计工作的公司负责人： | L37: 公司会计机构负责人： | S37: 主管会计工作的公司负责人： | Y37: 公司会计机构负责人：

Sheet RP 006
A1: 公司名称 | B1: =基础信息!B6 -> 0
A2: 财务期间 | B2: =基础信息!B9 -> 0 | J2: 准则差异调整-政策调整 | R2: 准则差异调整-列报调整
A3: 内容 | B3: 准则差异调节表
A4: 项目 | B4: HKFRS | C4: 准则列报调整 | D4: 准则政策调整调整 | E4: PRC | F4: 序号 | G4: 调整事项 | H4: 一级科目 | I4: 二级科目 | J4: 借方金额 | K4: 贷方金额 | L4: 备注 | M4: 索引号 | N4: 序号 | O4: 调整事项 | P4: 一级科目 | Q4: 二级科目 | R4: 借方金额 | S4: 贷方金额 | T4: 备注 | U4: 索引号
A5: 流动资产:
A6: 货币资金 | C6: =SUMIF($P:$P,A6,R:R)-SUMIF($P:$P,A6,S:S) -> 0 | D6: =SUMIF($H:$H,A6,J:J)-SUMIF($H:$H,A6,K:K) -> 0 | E6: =SUM(B6:D6) -> 0
A7: 交易性金融资产 | C7: =SUMIF($P:$P,A7,R:R)-SUMIF($P:$P,A7,S:S) -> 0 | D7: =SUMIF($H:$H,A7,J:J)-SUMIF($H:$H,A7,K:K) -> 0 | E7: =SUM(B7:D7) -> 0
A8: 以公允价值计量且其变动计入当期损益的金融资产 | C8: =SUMIF($P:$P,A8,R:R)-SUMIF($P:$P,A8,S:S) -> 0 | D8: =SUMIF($H:$H,A8,J:J)-SUMIF($H:$H,A8,K:K) -> 0 | E8: =SUM(B8:D8) -> 0
A9: 衍生金融资产 | C9: =SUMIF($P:$P,A9,R:R)-SUMIF($P:$P,A9,S:S) -> 0 | D9: =SUMIF($H:$H,A9,J:J)-SUMIF($H:$H,A9,K:K) -> 0 | E9: =SUM(B9:D9) -> 0
A10: 应收票据 | C10: =SUMIF($P:$P,A10,R:R)-SUMIF($P:$P,A10,S:S) -> 0 | D10: =SUMIF($H:$H,A10,J:J)-SUMIF($H:$H,A10,K:K) -> 0 | E10: =SUM(B10:D10) -> 0
A11: 应收票据坏帐准备 | C11: =-SUMIF($P:$P,A11,R:R)+SUMIF($P:$P,A11,S:S) -> 0 | D11: =-SUMIF($H:$H,A11,J:J)+SUMIF($H:$H,A11,K:K) -> 0 | E11: =SUM(B11:D11) -> 0
A12: 应收票据净值 | B12: =B10-B11 -> 0 | C12: =C10-C11 -> 0 | D12: =D10-D11 -> 0 | E12: =E10-E11 -> 0
A13: 应收账款 | C13: =SUMIF($P:$P,A13,R:R)-SUMIF($P:$P,A13,S:S) -> 0 | D13: =SUMIF($H:$H,A13,J:J)-SUMIF($H:$H,A13,K:K) -> 0 | E13: =SUM(B13:D13) -> 0
A14: 应收账款坏帐准备 | C14: =-SUMIF($P:$P,A14,R:R)+SUMIF($P:$P,A14,S:S) -> 0 | D14: =-SUMIF($H:$H,A14,J:J)+SUMIF($H:$H,A14,K:K) -> 0 | E14: =SUM(B14:D14) -> 0
A15: 应收账款净值 | B15: =B13-B14 -> 0 | C15: =C13-C14 -> 0 | D15: =D13-D14 -> 0 | E15: =E13-E14 -> 0
A16: 应收款项融资 | C16: =SUMIF($P:$P,A16,R:R)-SUMIF($P:$P,A16,S:S) -> 0 | D16: =SUMIF($H:$H,A16,J:J)-SUMIF($H:$H,A16,K:K) -> 0 | E16: =SUM(B16:D16) -> 0
A17: 应收款项融资坏账准备 | C17: =-SUMIF($P:$P,A17,R:R)+SUMIF($P:$P,A17,S:S) -> 0 | D17: =-SUMIF($H:$H,A17,J:J)+SUMIF($H:$H,A17,K:K) -> 0 | E17: =SUM(B17:D17) -> 0
A18: 应收款项融资净值 | B18: =B16-B17 -> 0 | C18: =C16-C17 -> 0 | D18: =D16-D17 -> 0 | E18: =E16-E17 -> 0
A19: 预付款项 | C19: =SUMIF($P:$P,A19,R:R)-SUMIF($P:$P,A19,S:S) -> 0 | D19: =SUMIF($H:$H,A19,J:J)-SUMIF($H:$H,A19,K:K) -> 0 | E19: =SUM(B19:D19) -> 0
A20: 其他应收款 | C20: =SUMIF($P:$P,A20,R:R)-SUMIF($P:$P,A20,S:S) -> 0 | D20: =SUMIF($H:$H,A20,J:J)-SUMIF($H:$H,A20,K:K) -> 0 | E20: =SUM(B20:D20) -> 0
A21: 其他应收款坏帐准备 | C21: =-SUMIF($P:$P,A21,R:R)+SUMIF($P:$P,A21,S:S) -> 0 | D21: =-SUMIF($H:$H,A21,J:J)+SUMIF($H:$H,A21,K:K) -> 0 | E21: =SUM(B21:D21) -> 0
A22: 其他应收款净值 | B22: =B20-B21 -> 0 | C22: =C20-C21 -> 0 | D22: =D20-D21 -> 0 | E22: =E20-E21 -> 0
A23: 存货 | C23: =SUMIF($P:$P,A23,R:R)-SUMIF($P:$P,A23,S:S) -> 0 | D23: =SUMIF($H:$H,A23,J:J)-SUMIF($H:$H,A23,K:K) -> 0 | E23: =SUM(B23:D23) -> 0
A24: 存货跌价准备 | C24: =-SUMIF($P:$P,A24,R:R)+SUMIF($P:$P,A24,S:S) -> 0 | D24: =-SUMIF($H:$H,A24,J:J)+SUMIF($H:$H,A24,K:K) -> 0 | E24: =SUM(B24:D24) -> 0
A25: 存货净值 | B25: =B23-B24 -> 0 | C25: =C23-C24 -> 0 | D25: =D23-D24 -> 0 | E25: =E23-E24 -> 0
A26: 合同资产 | C26: =C24-C25 -> 0 | D26: =D24-D25 -> 0 | E26: =E24-E25 -> 0
A27: 合同资产减值准备 | C27: =C25-C26 -> 0 | D27: =D25-D26 -> 0 | E27: =E25-E26 -> 0
A28: 合同资产净值 | B28: =B26-B27 -> 0 | C28: =C26-C27 -> 0 | D28: =D26-D27 -> 0 | E28: =E26-E27 -> 0
A29: 持有待售资产 | C29: =C24-C25 -> 0 | D29: =D24-D25 -> 0 | E29: =E24-E25 -> 0
A30: 一年内到期的非流动资产 | C30: =SUMIF($P:$P,A30,R:R)-SUMIF($P:$P,A30,S:S) -> 0 | D30: =SUMIF($H:$H,A30,J:J)-SUMIF($H:$H,A30,K:K) -> 0 | E30: =SUM(B30:D30) -> 0
A31: 待摊费用 | C31: =SUMIF($P:$P,A31,R:R)-SUMIF($P:$P,A31,S:S) -> 0 | D31: =SUMIF($H:$H,A31,J:J)-SUMIF($H:$H,A31,K:K) -> 0 | E31: =SUM(B31:D31) -> 0
A32: 内部应收 | C32: =SUMIF($P:$P,A32,R:R)-SUMIF($P:$P,A32,S:S) -> 0 | D32: =SUMIF($H:$H,A32,J:J)-SUMIF($H:$H,A32,K:K) -> 0 | E32: =SUM(B32:D32) -> 0
A33: 材料采购 | C33: =SUMIF($P:$P,A33,R:R)-SUMIF($P:$P,A33,S:S) -> 0 | D33: =SUMIF($H:$H,A33,J:J)-SUMIF($H:$H,A33,K:K) -> 0 | E33: =SUM(B33:D33) -> 0
A34: 公司间应收 | C34: =SUMIF($P:$P,A34,R:R)-SUMIF($P:$P,A34,S:S) -> 0 | D34: =SUMIF($H:$H,A34,J:J)-SUMIF($H:$H,A34,K:K) -> 0 | E34: =SUM(B34:D34) -> 0
A35: 应收下级单位利润 | C35: =SUMIF($P:$P,A35,R:R)-SUMIF($P:$P,A35,S:S) -> 0 | D35: =SUMIF($H:$H,A35,J:J)-SUMIF($H:$H,A35,K:K) -> 0 | E35: =SUM(B35:D35) -> 0
A36: 应收采购款 | C36: =SUMIF($P:$P,A36,R:R)-SUMIF($P:$P,A36,S:S) -> 0 | D36: =SUMIF($H:$H,A36,J:J)-SUMIF($H:$H,A36,K:K) -> 0 | E36: =SUM(B36:D36) -> 0
A37: 应收采购款坏帐准备 | C37: =-SUMIF($P:$P,A37,R:R)+SUMIF($P:$P,A37,S:S) -> 0 | D37: =-SUMIF($H:$H,A37,J:J)+SUMIF($H:$H,A37,K:K) -> 0 | E37: =SUM(B37:D37) -> 0
A38: 应收采购款净额 | B38: =B36-B37 -> 0 | C38: =C36-C37 -> 0 | D38: =D36-D37 -> 0 | E38: =E36-E37 -> 0
A39: 空行 | C39: =SUMIF($P:$P,A39,R:R)-SUMIF($P:$P,A39,S:S) -> 0 | D39: =SUMIF($H:$H,A39,J:J)-SUMIF($H:$H,A39,K:K) -> 0 | E39: =SUM(B39:D39) -> 0
A40: 空行 | C40: =SUMIF($P:$P,A40,R:R)-SUMIF($P:$P,A40,S:S) -> 0 | D40: =SUMIF($H:$H,A40,J:J)-SUMIF($H:$H,A40,K:K) -> 0 | E40: =SUM(B40:D40) -> 0
...

Sheet RP 007
A1: 公司名称 | B1: =基础信息!B6 -> 0
A2: 财务期间 | B2: =基础信息!B9 -> 0
A3: 内容 | B3: 集团间交易（销售、采购、费用）
A4: 销售交易对象 | B4: 交易项目
B5: 主营业务收入 | F5: 主营业务成本 | J5: 其他业务收入 | K5: 财务费用 | L5: 营业外收入
B6: 小计 | C6: 硬件 | D6: 服务 | E6: 软件及软件开发 | F6: 小计 | G6: 硬件 | H6: 服务 | I6: 软件及软件开发 | K6: 利息收入
B7: =SUM(C7:E7) -> 0 | F7: =SUM(G7:I7) -> 0
B8: =SUM(C8:E8) -> 0 | F8: =SUM(G8:I8) -> 0
B9: =SUM(C9:E9) -> 0 | F9: =SUM(G9:I9) -> 0
B10: =SUM(C10:E10) -> 0 | F10: =SUM(G10:I10) -> 0
B11: =SUM(C11:E11) -> 0 | F11: =SUM(G11:I11) -> 0
B12: =SUM(C12:E12) -> 0 | F12: =SUM(G12:I12) -> 0
B13: =SUM(C13:E13) -> 0 | F13: =SUM(G13:I13) -> 0
B14: =SUM(C14:E14) -> 0 | F14: =SUM(G14:I14) -> 0
B15: =SUM(C15:E15) -> 0 | F15: =SUM(G15:I15) -> 0
B16: =SUM(C16:E16) -> 0 | F16: =SUM(G16:I16) -> 0
B17: =SUM(C17:E17) -> 0 | F17: =SUM(G17:I17) -> 0
B18: =SUM(C18:E18) -> 0 | F18: =SUM(G18:I18) -> 0
... B20: =SUM(C20:E20) -> 0 | F20: =SUM(G20:I20) -> 0
A21: 合计 | B21: =SUM(B7:B20) -> 0 | C21: =SUM(C7:C20) -> 0 | D21: =SUM(D7:D20) -> 0 | E21: =SUM(E7:E20) -> 0 | F21: =SUM(F7:F20) -> 0 | G21: =SUM(G7:G20) -> 0 | H21: =SUM(H7:H20) -> 0 | I21: =SUM(I7:I20) -> 0 | ... L21: =SUM(L7:L20) -> 0
A23: 采购及费用交易对象 | B23: 交易项目
B24: 采购 | F24: 其他业务成本 | G24: 财务费用 | I24: 营业外支出
B25: 小计 | C25: 硬件 | D25: 服务 | E25: 软件及软件开发 | G25: 利息支出 | H25: 手续费
B26: =SUM(C26:E26) -> 0
B27: =SUM(C27:E27) -> 0
B28: =SUM(C28:E28) -> 0
B29: =SUM(C29:E29) -> 0
B30: =SUM(C30:E30) -> 0
B31: =SUM(C31:E31) -> 0
B32: =SUM(C32:E32) -> 0
B33: =SUM(C33:E33) -> 0
B34: =SUM(C34:E34) -> 0
B35: =SUM(C35:E35) -> 0
B36: =SUM(C36:E36) -> 0
B37: =SUM(C37:E37) -> 0
... B39: =SUM(C39:E39) -> 0
A40: 合计 | B40: =SUM(B26:B39) -> 0 | C40: =SUM(C26:C39) -> 0 | D40: =SUM(D26:D39) -> 0 | E40: =SUM(E26:E39) -> 0 | F40: =SUM(F26:F39) -> 0 | G40: =SUM(G26:G39) -> 0 | I40: =SUM(I26:I39) -> 0

Sheet RP 008
A1: 公司名称 | B1: =基础信息!B6 -> 0
A2: =基础信息!A9 -> 财务期间 | B2: =日期2 -> 0
A3: 内容 | B3: 集团内部往来余额
A4: 债权交易项目 | B4: 应收票据 | G4: 应收账款 | L4: 预付账款 | Q4: 其他应收款
B5: 小计 | C5: 1年以内 | D5: 1-2年 | E5: 2-3年 | F5: 3年以上 | G5: 小计 | H5: 1年以内 | I5: 1-2年 | J5: 2-3年 | K5: 3年以上 | L5: 小计 | M5: 1年以内 | N5: 1-2年 | O5: 2-3年 | P5: 3年以上 | Q5: 小计 | R5: 1年以内 | S5: 1-2年 | T5: 2-3年 | U5: 3年以上
G6: =SUM(H6:K6) -> 0 | Q6: =SUM(R6:U6) -> 0
G7: =SUM(H7:K7) -> 0 | Q7: =SUM(R7:U7) -> 0
G8: =SUM(H8:K8) -> 0 | Q8: =SUM(R8:U8) -> 0
G9: =SUM(H9:K9) -> 0 | Q9: =SUM(R9:U9) -> 0
G10: =SUM(H10:K10) -> 0 | Q10: =SUM(R10:U10) -> 0
G11: =SUM(H11:K11) -> 0 | Q11: =SUM(R11:U11) -> 0
G12: =SUM(H12:K12) -> 0 | Q12: =SUM(R12:U12) -> 0
G13: =SUM(H13:K13) -> 0 | Q13: =SUM(R13:U13) -> 0
G14: =SUM(H14:K14) -> 0 | Q14: =SUM(R14:U14) -> 0
G15: =SUM(H15:K15) -> 0 | Q15: =SUM(R15:U15) -> 0
G16: =SUM(H16:K16) -> 0 | Q16: =SUM(R16:U16) -> 0
G17: =SUM(H17:K17) -> 0 | Q17: =SUM(R17:U17) -> 0
... G19: =SUM(H19:K19) -> 0 | Q19: =SUM(R19:U19) -> 0
A20: 合计 | G20: =SUM(G6:G19) -> 0 | H20: =SUM(H6:H19) -> 0 | I20: =SUM(I6:I19) -> 0 | J20: =SUM(J6:J19) -> 0 | K20: =SUM(K6:K19) -> 0 | Q20: =SUM(Q6:Q19) -> 0 | R20: =SUM(R6:R19) -> 0 | S20: =SUM(S6:S19) -> 0 | T20: =SUM(T6:T19) -> 0 | U20: =SUM(U6:U19) -> 0
A21: 债务交易项目 | B21: 应付票据 | G21: 应付账款 | L21: 预收账款 | Q21: 其他应付款
B22: 小计 | C22: 1年以内 | D22: 1-2年 | E22: 2-3年 | F22: 3年以上 | G22: 小计 | H22: 1年以内 | I22: 1-2年 | J22: 2-3年 | K22: 3年以上 | L22: 小计 | M22: 1年以内 | N22: 1-2年 | O22: 2-3年 | P22: 3年以上 | Q22: 小计 | R22: 1年以内 | S22: 1-2年 | T22: 2-3年 | U22: 3年以上
A23: =A6 -> 0 | G23: =SUM(H23:K23) -> 0 | Q23: =SUM(R23:U23) -> 0
A24: =A7 -> 0 | G24: =SUM(H24:K24) -> 0 | Q24: =SUM(R24:U24) -> 0
A25: =A8 -> 0 | G25: =SUM(H25:K25) -> 0 | Q25: =SUM(R25:U25) -> 0
A26: =A9 -> 0 | G26: =SUM(H26:K26) -> 0 | Q26: =SUM(R26:U26) -> 0
A27: =A10 -> 0 | G27: =SUM(H27:K27) -> 0 | Q27: =SUM(R27:U27) -> 0
A28: =A11 -> 0 | G28: =SUM(H28:K28) -> 0 | Q28: =SUM(R28:U28) -> 0
A29: =A12 -> 0 | G29: =SUM(H29:K29) -> 0 | Q29: =SUM(R29:U29) -> 0
A30: =A13 -> 0 | G30: =SUM(H30:K30) -> 0 | Q30: =SUM(R30:U30) -> 0
A31: =A14 -> 0 | G31: =SUM(H31:K31) -> 0 | Q31: =SUM(R31:U31) -> 0
A32: =A15 -> 0 | G32: =SUM(H32:K32) -> 0 | Q32: =SUM(R32:U32) -> 0
A33: =A16 -> 0 | G33: =SUM(H33:K33) -> 0 | Q33: =SUM(R33:U33) -> 0
A34: =A17 -> 0 | G34: =SUM(H34:K34) -> 0 | Q34: =SUM(R34:U34) -> 0
... A36: =A19 -> 0 | G36: =SUM(H36:K36) -> 0 | Q36: =SUM(R36:U36) -> 0
A37: 合计 | G37: =SUM(G23:G36) -> 0 | H37: =SUM(H23:H36) -> 0 | I37: =SUM(I23:I36) -> 0 | J37: =SUM(J23:J36) -> 0 | K37: =SUM(K23:K36) -> 0 | Q37: =SUM(Q23:Q36) -> 0 | R37: =SUM(R23:R36) -> 0 | S37: =SUM(S23:S36) -> 0 | T37: =SUM(T23:T36) -> 0 | U37: =SUM(U23:U36) -> 0

Sheet RP 009
A1: 公司名称 | B1: =基础信息!B6 -> 0
A2: =基础信息!A9 -> 财务期间 | B2: =基础信息!B9 -> 0
A3: 内容 | B3: 未实现内部利润
A4: 交易对象 | B4: 采购项目 | C4: 存货名称 | D4: 期末库存金额 | E4: 其中：期初结转至期末库存金额 | F4: 期末已计提跌价准备 | G4: 内部毛利率
A22: 合计

Sheet RP 010
A1: 公司名称 | B1: =基础信息!B6 -> 0
A2: =基础信息!A9 -> 财务期间 | B2: =基础信息!B9 -> 0
A3: 内容 | B3: 集团内部固定资产/无形资产交易
A4: 本期销售固定资产/无形资产
A5: 交易对象 | B5: 类别 | C5: 名称 | D5: 原值 | E5: 销售时累计折旧/累计摊销 | F5: 销售时已计提减值准备 | G5: 销售价款 | H5: 处置费用 | I5: 营业外收入（支出“-”） | J5: Check Box | R5: 交易主体 | S5: 类别 | T5: Category | U5: 是/否
J6: =IF(G6-(D6-E6-F6)-H6=I6,"OK","NO") -> OK | R6: TS | S6: 房屋及建筑物 | T6: Buildings | U6: √
J7: =IF(G7-(D7-E7-F7)-H7=I7,"OK","NO") -> OK | R7: JF | S7: 电子设备 | T7: Electronic equipment | U7: ×
J8: =IF(G8-(D8-E8-F8)-H8=I8,"OK","NO") -> OK | R8: US | S8: 办公设备 | T8: Office equipment
J9: =IF(G9-(D9-E9-F9)-H9=I9,"OK","NO") -> OK | R9: HK | S9: 运输设备 | T9: Transportation equipment
J10: =IF(G10-(D10-E10-F10)-H10=I10,"OK","NO") -> OK | R10: ST | S10: 房屋装修 | T10: House decoration
J11: =IF(G11-(D11-E11-F11)-H11=I11,"OK","NO") -> OK | R11: FJ | S11: 其他 | T11: Others
J12: =IF(G12-(D12-E12-F12)-H12=I12,"OK","NO") -> OK | R12: JDSY
J13: =IF(G13-(D13-E13-F13)-H13=I13,"OK","NO") -> OK | R13: SZ | S13: 类别 | T13: Category
J14: =IF(G14-(D14-E14-F14)-H14=I14,"OK","NO") -> OK | R14: NJ | S14: UCWEB软件
J15: =IF(G15-(D15-E15-F15)-H15=I15,"OK","NO") -> OK | R15: CD | S15: 其他软件 | T15: Other software
J16: =IF(G16-(D16-E16-F16)-H16=I16,"OK","NO") -> OK | R16: HWKJ | S16: 专利权及牌照 | T16: Patents and licences
J17: =IF(G17-(D17-E17-F17)-H17=I17,"OK","NO") -> OK | R17: HZWK | S17: 会所会籍 | T17: Club memberships
J18: =IF(G18-(D18-E18-F18)-H18=I18,"OK","NO") -> OK | R18: ITMS
J19: =IF(G19-(D19-E19-F19)-H19=I19,"OK","NO") -> OK | R19: HZKJ
J20: =IF(G20-(D20-E20-F20)-H20=I20,"OK","NO") -> OK | R20: HWST
J21: =IF(G21-(D21-E21-F21)-H21=I21,"OK","NO") -> OK | R21: GCGV
J22: =IF(G22-(D22-E22-F22)-H22=I22,"OK","NO") -> OK | R22: ASL
A23: 合计 | J23: =IF(G23-(D23-E23-F23)-H23=I23,"OK","NO") -> OK
A25: 采购固定资产/无形资产
A26: 交易对象 | B26: 类别 | C26: 名称 | D26: 购买日期 | E26: 采购成本 | F26: 折旧方法 | G26: 预计使用年限 | H26: 预计残值 | I26: 备注（发票）
A44: 合计

Sheet RP 011
A1: 公司名称 | B1: =基础信息!B6 -> 0
A2: =基础信息!A9 -> 财务期间 | B2: =基础信息!B9 -> 0
A3: 内容 | B3: 集团内部现金流
A4: 收到的现金 | B4: 销售商品、提供劳务收到的现金 | C4: 收到其他与经营活动有关的现金 | D4: 收回投资收到的现金 | E4: 取得投资收益收到的现金 | F4: 处置固定资产、无形资产和其他长期资产收回的现金净额 | G4: 处置子公司及其他营业单位收到的现金净额 | H4: 收到其他与投资活动有关的现金 | I4: 吸收投资收到的现金 | J4: 取得借款收到的现金 | K4: 收到其他与筹资活动有关的现金
A21: 合计 | B21: =SUM(B5:B20) -> 0 | C21: =SUM(C5:C20) -> 0
A23: 支付的现金 | B23: 购买商品、接受劳务支付的现金 | C23: 支付其他与经营活动有关的现金 | D23: 购置固定资产、无形资产和其他长期资产支付的现金 | E23: 投资支付的现金 | F23: 取得子公司及其他营业单位支付的现金净额 | G23: 支付其他与投资活动有关的现金 | I23: 偿还债务支付的现金 | J23: 分配股利、利润或偿付利息支付的现金 | K23: 支付其他与筹资活动有关的现金
A24: =A5 -> 0
A25: =A6 -> 0
A26: =A7 -> 0
A27: =A8 -> 0
A28: =A9 -> 0
A29: =A10 -> 0
A30: =A11 -> 0
A31: =A12 -> 0
A32: =A13 -> 0
A33: =A14 -> 0
A34: =A15 -> 0
A35: =A15 -> 0
A36: =A16 -> 0
A37: =A17 -> 0
A38: =A18 -> 0
A39: =A19 -> 0
A40: =A20 -> 0
A41: 合计 | B41: =SUM(B24:B40) -> 0 | C41: =SUM(C24:C40) -> 0

Sheet RP 012
A1: 公司名称 | B1: =基础信息!B5 -> 0
A2: 财务期间 | B2: =基础信息!B9 -> 0
A3: 内容 | B3: 货币资金
A5: 项 目 | B5: 期末
A6: 现金
A7: 银行存款
A8: 银行存款中：财务公司存款
A9: 其他货币资金
A10: 合 计 | B10: =SUM(B6:B9) -> 0
A11: 其中：存放在境外的款项总额
A12: 报表金额 | B12: ='RP 006'!E6 -> 0
B13: =B10-B12 -> 0
B14: =IF(B13=0,"OK","NO") -> OK
A15: 其中，外币如下：(除人民币以外的币种)
A16: 币 种 | B16: 期末
B17: 原 币 | C17: 汇率 | D17: 折合本位币
A18: 美元
A19: 港币
A22: 合 计 | B22: =SUM(B18:B21) -> 0 | D22: =SUM(D18:D21) -> 0
A24: 列示于现金流量表的现金及现金等价物包括： | B24: 金 额
A25: 期末货币资金
A26: 减：使用受到限制的存款
A27: 加：现金等价物
A28: 期末现金及现金等价物余额 | B28: =B25-B26+B27 -> 0
A29: 减：期初现金及现金等价物余额
A30: 现金及现金等价物净增加/（减少）额 | B30: =B28-B29 -> 0
A31: 说明：因抵押或冻结等对使用有限制、存放在境外、有潜在回收风险的款项内容

Sheet RP 013
A1: 公司名称 | B1: =基础信息!B6 -> 0
A2: 财务期间 | B2: =基础信息!B9 -> 0
A3: 内容 | B3: 交易性金融资产
A5: 项 目 | B5: 期末
A6: 债务工具投资
A7: 权益工具投资
A8: 衍生金融资产
A9: 其他
A10: 合 计 | B10: =SUM(B6:B9) -> 0
A11: 报表金额 | B11: ='RP 006'!E7 -> 0
B12: =B10-B11 -> 0
B13: =IF(B12=0,"OK","NO") -> OK
A14: 说明：

Sheet RP 014
A1: 公司名称 | B1: =基础信息!B6 -> 0
A2: 财务期间 | B2: =基础信息!B9 -> 0
A3: 内容 | B3: 以公允价值计量且其变动计入当期损益的金融资产
A5: 项 目 | B5: 期末
A6: 交易性金融资产 | B6: =SUM(B7:B10) -> 0
A7: 其中：债务工具投资
A8: 权益工具投资
A9: 衍生金融资产
A10: 其他
A11: 指定为以公允价值计量且其变动计入当期损益的金融资产 | B11: =SUM(B12:B15) -> 0
A12: 其中：债务工具投资
A13: 权益工具投资
A14: 衍生金融资产
A15: 其他
A16: 合 计 | B16: =B6+B11 -> 0
A17: 报表金额 | B17: ='RP 006'!E8 -> 0
B18: =B16-B17 -> 0
B19: =IF(B18=0,"OK","NO") -> OK
A20: 说明：

Sheet RP 015
A1: 公司名称 | B1: =基础信息!B6 -> 0
A2: 财务期间 | B2: =基础信息!B9 -> 0
A3: 内容 | B3: 衍生金融资产
A5: 项 目 | B5: 期末公允价值
A11: 合 计 | B11: =SUM(B6:B10) -> 0
A12: 报表金额 | B12: ='RP 006'!E9 -> 0
B13: =B11-B12 -> 0
B14: =IF(B13=0,"OK","NO") -> OK
A15: 说明：（衍生金融资产产生的原因以及相关会计处理。）

Sheet RP 016
A1: 公司名称 | B1: =基础信息!B6 -> 0
A2: 财务期间 | B2: =基础信息!B9 -> 0
A3: 内容 | B3: 应收票据
A5: 种 类 | B5: 期末
A6: 银行承兑汇票
A7: 商业承兑汇票
A8: 合 计 | B8: =SUM(B6:B7) -> 0
A9: 报表金额 | B9: ='RP 006'!E12 -> 0
B10: =B8-B9 -> 0
B11: =IF(B10=0,"OK","NO") -> OK
A12: 如发生减值披露格式如下：
A13: 种 类 | B13: 期末数
B14: 期末余额 | C14: 坏账准备 | D14: 期末账面价值
A15: 银行承兑汇票 | C15: 0
A16: 商业承兑汇票
A17: 合 计
A20: 其中，用于质押的票据如下：
A21: 种 类 | B21: 期末已质押金额
A22: 银行承兑汇票
A23: 商业承兑汇票
A25: 合 计 | B25: =SUM(B22:B24) -> 0
A27: 其中，已背书或贴现但尚未到期的应收票据
A28: 种 类 | B28: 期末终止确认金额 | C28: 期末未终止确认金额
A29: 银行承兑票据
A30: 商业承兑票据
A31: 可无限量添加行
A32: 合 计 | B32: =SUM(B29:B31) -> 0 | C32: =SUM(C29:C31) -> 0
A34: 其中，因出票人未履约而其转应收账款
A35: 种 类 | B35: 期末转应收账款金额
A36: 商业承兑票据
A39: 合 计 | B39: =SUM(B36:B38) -> 0
A41: 按坏账计提方法分类
A42: 类别 | B42: 20xx.xx.xx | G42: 20xx.xx.xx
B43: 账面余额 | D43: 坏账准备 | F43: 账面 | G43: 账面余额 | I43: 坏账准备 | K43: 账面
B44: 金额 | C44: 比例(%) | D44: 金额 | E44: 预期信用损失率(%) | F44: 价值 | G44: 金额 | H44: 比例(%) | I44: 金额 | J44: 预期信用损失率(%) | K44: 价值
A45: 按单项计提坏账准备 | B45: =B47+B48 -> 0 | C45: =ROUND(B45/B53*100,2) -> #DIV/0! | D45: =D47+D48 -> 0 | E45: =ROUND(D45/B45*100,2) -> #DIV/0! | F45: =B45-D45 -> 0 | G45: =G47+G48 -> 0 | H45: =ROUND(G45/G53*100,2) -> #DIV/0! | I45: =I47+I48 -> 0 | J45: =ROUND(I45/G45*100,2) -> #DIV/0! | K45: =G45-I45 -> 0
A46: 其中：
C47: =ROUND(B47/$B$53*100,2) -> #DIV/0! | E47: =ROUND(D47/B47*100,2) -> #DIV/0! | F47: =B47-D47 -> 0 | H47: =ROUND(G47/$F$53*100,2) -> #DIV/0! | J47: =ROUND(I47/G47*100,2) -> #DIV/0! | K47: =G47-I47 -> 0
C48: =ROUND(B48/$B$53*100,2) -> #DIV/0! | E48: =ROUND(D48/B48*100,2) -> #DIV/0! | F48: =B48-D48 -> 0 | H48: =ROUND(G48/$F$53*100,2) -> #DIV/0! | J48: =ROUND(I48/G48*100,2) -> #DIV/0! | K48: =G48-I48 -> 0
A49: 按组合计提坏账准备 | B49: =B51+B52 -> 0 | C49: =ROUND(B49/$B$53*100,2) -> #DIV/0! | D49: =D51+D52 -> 0 | E49: =ROUND(D49/B49*100,2) -> #DIV/0! | F49: =B49-D49 -> 0 | G49: =G51+G52 -> 0 | H49: =ROUND(G49/$F$53*100,2) -> #DIV/0! | I49: =I51+I52 -> 0 | J49: =ROUND(I49/G49*100,2) -> #DIV/0! | K49: =G49-I49 -> 0
...

Sheet RP 017
A1: 公司名称 | B1: =基础信息!B6 -> 0
A2: 财务期间 | B2: =基础信息!B9 -> 0
A3: 内容 | B3: 应收账款
A4: （1）A、按风险分类
A5: 类 别 | B5: 期末
B6: 金 额 | C6: 坏账准备
A7: 单项金额重大的应收账款
A8: 单项金额不重大但按信用风险特征组合后该组合的风险较大的应收账款
A9: 其他不重大应收账款
A10: 合 计 | B10: =SUM(B7:B9) -> 0 | C10: =SUM(C7:C9) -> 0
A11: 报表金额 | B11: ='RP 006'!E13 -> 0 | C11: ='RP 006'!E14 -> 0
B12: =B10-B11 -> 0 | C12: =C10-C11 -> 0
B13: =IF(B12=0,"OK","NO") -> OK | C13: =IF(C12=0,"OK","NO") -> OK
A16: （1）B、期末单项金额重大并单项计提坏账准备的应收账款
A17: 应收账款（按单位） | B17: 账面余额 | C17: 坏账准备 | D17: 计提比例% | E17: 计提理由
A22: 合 计
A23: 核对金额 | B23: =B7 -> 0 | C23: =C7 -> 0
B24: =B22-B23 -> 0 | C24: =C22-C23 -> 0
B25: =IF(B24=0,"OK","NO") -> OK | C25: =IF(C24=0,"OK","NO") -> OK
A27: （1）C、账龄组合（和XX组合），按账龄分析法计提坏账准备的应收账款
A28: 账 龄 | B28: 期末
B29: 金 额 | C29: 坏账准备
A30: 1年以内
A31: 1至2年
A32: 2至3年
A33: 3至4年
A34: 4至5年
A35: 5年以上
A36: 合 计 | B36: =SUM(B30:B33) -> 0 | C36: =SUM(C30:C33) -> 0
A37: 核对金额 | B37: =B8 -> 0 | C37: =C8 -> 0
B38: =B36-B37 -> 0 | C38: =C36-C37 -> 0
B39: =IF(B38=0,"OK","NO") -> OK | C39: =IF(C38=0,"OK","NO") -> OK
A41: （2）本期计提、收回或转回的坏账准备情况
A42: 本期计提坏账准备金额XX元；本期收回或转回坏账准备金额XX元。
A43: 其中，本期坏账准备转回或收回金额重要的：
A44: 单位名称 | B44: 转回原因 | C44: 收回方式 | D44: 原确定坏账准备的依据 | E44: 转回或收回金额
A46: 可无限量添加行
A47: 合 计 | B47: =SUM(B45:B46) -> 0 | E47: =SUM(E45:E46) -> 0
A49: （3）本期实际核销的应收账款情况
A50: 项目 | B50: 核销金额
...

Sheet RP 018
A1: 公司名称 | B1: =基础信息!B6 -> 0
A2: 财务期间 | B2: =基础信息!B9 -> 0
A3: 内容 | B3: 应收款项融资
A5: 项 目 | B5: 2019.XX.XX | C5: 2018.12.31
A6: 应收票据
A7: 应收账款
A9: 合 计 | B9: =SUM(B6:B8) -> 0 | C9: =SUM(C6:C8) -> 0
A10: 报表金额 | B10: ='RP 006'!E18 -> 0
B11: =B9-B10 -> 0
B12: =IF(B11=0,"OK","NO") -> OK
A14: 各报告期期末减值准备计提情况
A15: 类别 | B15: 2019.XX.XX | G15: 2019.01.01
B16: 账面余额 | D16: 坏账准备 | F16: 账面 | G16: 账面余额 | I16: 坏账准备 | K16: 账面
B17: 金额 | C17: 比例(%) | D17: 金额 | E17: 预期信用损失率(%) | F17: 价值 | G17: 金额 | H17: 比例(%) | I17: 金额 | J17: 预期信用损失率(%) | K17: 价值
A18: 按单项计提坏账准备 | B18: =B20+B21 -> 0 | C18: =C20+C21 -> #DIV/0! | D18: =D20+D21 -> 0 | E18: =ROUND(D18/B18*100,2) -> #DIV/0! | F18: =F20+F21 -> 0 | G18: =G20+G21 -> 0 | H18: =H20+H21 -> #DIV/0! | I18: =I20+I21 -> 0 | J18: =ROUND(I18/G18*100,2) -> #DIV/0! | K18: =K20+K21 -> 0
A19: 其中：
C20: =ROUND(B20/$B$26*100,2) -> #DIV/0! | E20: =ROUND(D20/B20*100,2) -> #DIV/0! | F20: =B20-D20 -> 0 | H20: =ROUND(G20/$G$26*100,2) -> #DIV/0! | J20: =ROUND(I20/G20*100,2) -> #DIV/0! | K20: =G20-I20 -> 0
C21: =ROUND(B21/$B$26*100,2) -> #DIV/0! | E21: =ROUND(D21/B21*100,2) -> #DIV/0! | F21: =B21-D21 -> 0 | H21: =ROUND(G21/$G$26*100,2) -> #DIV/0! | J21: =ROUND(I21/G21*100,2) -> #DIV/0! | K21: =G21-I21 -> 0
A22: 按组合 计提坏账准备 | B22: =B24+B25 -> 0 | C22: =C24+C25 -> #DIV/0! | D22: =D24+D25 -> 0 | F22: =F24+F25 -> 0 | G22: =G24+G25 -> 0 | H22: =H24+H25 -> #DIV/0! | I22: =I24+I25 -> 0 | J22: =ROUND(I22/G22*100,2) -> #DIV/0! | K22: =K24+K25 -> 0
A23: 其中：
A24: 应收中央企业客户 | C24: =ROUND(B24/$B$26*100,2) -> #DIV/0! | E24: =ROUND(D24/B24*100,2) -> #DIV/0! | F24: =B24-D24 -> 0 | H24: =ROUND(G24/$G$26*100,2) -> #DIV/0! | J24: =ROUND(I24/G24*100,2) -> #DIV/0! | K24: =G24-I24 -> 0
A25: 应收海外企业客户 | C25: =ROUND(B25/$B$26*100,2) -> #DIV/0! | E25: =ROUND(D25/B25*100,2) -> #DIV/0! | F25: =B25-D25 -> 0 | H25: =ROUND(G25/$G$26*100,2) -> #DIV/0! | J25: =ROUND(I25/G25*100,2) -> #DIV/0! | K25: =G25-I25 -> 0
A26: 合 计 | B26: =B22+B18 -> 0 | C26: =C22+C18 -> #DIV/0! | D26: =D22+D18 -> 0 | E26: =ROUND(D26/B26*100,2) -> #DIV/0! | F26: =F22+F18 -> 0 | H26: =H22+H18 -> #DIV/0! | J26: =ROUND(I26/G26*100,2) -> #DIV/0! | K26: =K22+K18 -> 0
A27: 核对金额 | F27: =B9 -> 0
F28: =F26-F27 -> 0
F29: =IF(F28=0,"OK","NO") -> OK
A30: 按单项计提坏账准备：
A31: 名 称 | B31: 2019.12.31
B32: 账面余额 | C32: 坏账准备 | D32: 预期信用损失率(%) | E32: 计提理由
D34: =ROUND(C34/B34*100,2) -> #DIV/0!
D35: =ROUND(C35/B35*100,2) -> #DIV/0!
A36: 合 计 | B36: =SUM(B34:B35) -> 0 | C36: =SUM(C34:C35) -> 0
A37: 核对金额 | B37: =B18 -> 0 | C37: =D18 -> 0
B38: =B36-B37 -> 0 | C38: =C36-C37 -> 0
B39: =IF(B38=0,"OK","NO") -> OK | C39: =IF(C38=0,"OK","NO") -> OK
A40: 按组合计提坏账准备：
A41: 组合计提项目：应收中央企业客户
A42: 名 称 | B42: 2019.12.31
B43: 账面余额 | C43: 坏账准备 | D43: 预期信用损失率(%)
A45: 1年以内 | D45: =ROUND(C45/B45*100,2) -> #DIV/0!
...

Sheet RP 019
A1: 公司名称 | B1: =基础信息!B6 -> 0
A2: 财务期间 | B2: =基础信息!B9 -> 0
A3: 内容 | B3: 预付款项
A4: （1）账龄分析
A5: 账 龄 | B5: 期 末
B6: 金 额 | C6: 比例%
A7: 1年以内
A8: 1至2年
A9: 2至3年
A10: 3年以上
A11: 合 计 | B11: =SUM(B7:B10) -> 0 | C11: =SUM(C7:C10) -> 0
A12: 报表金额 | B12: ='RP 006'!E19 -> 0
B13: =B11-B12 -> 0
B14: =IF(B13=0,"OK","NO") -> OK
A15: 说明：
A16: 账龄在1年以上的预付款项超过XX万元，请说明如下信息
A17: 公司名称 | B17: 预付款项金额 | C17: 账龄超过一年的原因
A19: （2）按预付对象归集的预付款项期末余额前五名单位情况
A20: 汇总披露格式：
A21: 本期按预付对象归集的期末余额前五名预付款项汇总金额XXXX元，占预付款项期末余额合计数的比例 %。
A22: 分别披露格式：
A23: 单位名称 | B23: 预付款项期末余额 | C23: 占预付款项期末余额合计数的比例%
A27: 合 计 | B27: =SUM(B24:B26) -> 0 | C27: =SUM(C24:C26) -> 0

Sheet RP 020
A1: 公司名称 | B1: =基础信息!B6 -> 0
A2: 财务期间 | B2: =基础信息!B9 -> 0
A3: 内容 | B3: 其他应收款
A4: 项 目 | B4: 期末
A5: 应收利息 | B5: ='RP 020-1'!B9 -> 0
A6: 应收股利 | B6: ='RP 020-2'!B8 -> 0
A7: 其他应收款 | B7: ='RP 020-3'!B10-'RP 020-3'!C10 -> 0
A8: 合 计 | B8: =SUM(B5:B7) -> 0
A9: 报表金额 | B9: ='RP 006'!E22 -> 0
B10: =B8-B9 -> 0
B11: =IF(B10=0,"OK","NO") -> OK

Sheet RP 020-1
A1: 公司名称 | B1: =基础信息!B6 -> 0
A2: 财务期间 | B2: =基础信息!B9 -> 0
A3: 内容 | B3: 应收利息
A4: 项 目 | B4: 期末
A5: 定期存款
A6: 委托贷款
A7: 债券投资
A8: 可无限量添加行
A9: 合 计 | B9: =SUM(B5:B8) -> 0
A10: 核对金额 | B10: ='RP 020'!B5 -> 0
B11: =B9-B10 -> 0
B12: =IF(B11=0,"OK","NO") -> OK
A14: 其中，重要的逾期应收利息如下：
A15: 借款单位 | B15: 期末数 | C15: 逾期时间 | D15: 逾期原因 | E15: 是否发生减值及其原因
A19: 合 计 | B19: =SUM(B16:B18) -> 0
A20: （对于重要的逾期应收利息，应按借款单位披露应收利息的期末余额、逾期时间和逾期原因、是否发生减值的判断。）

Sheet RP 020-2
A1: 公司名称 | B1: =基础信息!B6 -> 0
A2: 财务期间 | B2: =基础信息!B9 -> 0
A3: 内容 | B3: 应收股利
A5: 被投资单位名称 | B5: 期末
A8: 合 计 | B8: =SUM(B6:B7) -> 0
A9: 核对金额 | B9: ='RP 020'!B6 -> 0
B10: =B8-B9 -> 0
B11: =IF(B10=0,"OK","NO") -> OK
A14: 其中，重要的账龄超过1年的应收股利如下：
A15: 项目（或被投资单位） | B15: 期末数 | C15: 账龄 | D15: 未收回的原因 | E15: 是否发生减值及其判断依据
A19: 合 计 | B19: =SUM(B16:B18) -> 0
A20: （对于重要的账龄超过1 年的应收股利，应披露未收回的原因和对相关款项是否发生减值的判断。）

Sheet RP 020-3
A1: 公司名称 | B1: =基础信息!B6 -> 0
A2: 财务期间 | B2: =基础信息!B9 -> 0
A3: 内容 | B3: 其他应收款
A4: （1）A、按风险分类
A5: 类 别 | B5: 期末
B6: 金 额 | C6: 坏账准备
A7: 单项金额重大的其他应收款(XX万元以上)
A8: 单项金额不重大但按信用风险特征组合后该组合的风险较大的其他应收款
A9: 其他不重大其他应收款
A10: 合 计 | B10: =SUM(B7:B9) -> 0 | C10: =SUM(C7:C9) -> 0
A11: 核对金额 | C11: ='RP 020'!B7 -> 0
C12: =B10-C10-C11 -> 0
C13: =IF(C12=0,"OK","NO") -> OK
A14: （1）B、期末单项金额重大并单项计提坏账准备的其他应收款
A15: 其他应收款（按单位） | B15: 账面余额 | C15: 坏账准备 | D15: 计提比例% | E15: 计提理由
A16: 可无限量添加行
A17: 合 计 | B17: =SUM(B16) -> 0 | C17: =SUM(C16) -> 0 | D17: =SUM(D16) -> 0
A18: 报表金额 | B18: =B7 -> 0 | C18: =C7 -> 0
B19: =B17-B18 -> 0 | C19: =C17-C18 -> 0
B20: =IF(B19=0,"OK","NO") -> OK | C20: =IF(C19=0,"OK","NO") -> OK
A21: （1）C、账龄组合（和XX组合），按账龄分析法计提坏账准备的其他应收账款
A22: 账 龄 | B22: 期末
B23: 金 额 | C23: 坏账准备
A24: 1年以内
A25: 1至2年
A26: 2至3年
A27: 3年以上
A28: 合 计 | B28: =SUM(B24:B27) -> 0 | C28: =SUM(C24:C27) -> 0
A29: 报表金额 | B29: =B8 -> 0 | C29: =C8 -> 0
B30: =B28-B29 -> 0 | C30: =C28-C29 -> 0
B31: =IF(B30=0,"OK","NO") -> OK | C31: =IF(C30=0,"OK","NO") -> OK
A33: （2）本期计提、收回或转回的坏账准备情况
A34: 本期计提坏账准备金额XX元；本期收回或转回坏账准备金额XX元。
A35: 其中，本期坏账准备转回或收回金额重要的：
A36: 单位名称 | B36: 转回原因 | C36: 收回方式 | D36: 原确定坏账准备的依据 | E36: 转回或收回金额
A38: 可无限量添加行
A39: 合 计 | E39: =SUM(E37:E38) -> 0
A41: （3）本期实际核销的其他应收账款情况
A42: 项目 | B42: 核销金额
A43: 实际核销的其他应收账款
...

Sheet RP 021
A1: 公司名称 | B1: =基础信息!B6 -> 0
A2: 财务期间 | B2: =基础信息!B9 -> 0
A3: 内容 | B3: 存货
A4: （1）存货分项目列示
A5: 项 目 | B5: 期末数
B6: 账面余额 | C6: 跌价准备 | D6: 账面价值
A7: 原材料 | D7: =B7-C7 -> 0
A8: 自制半成品及在产品 | D8: =B8-C8 -> 0
A9: 库存商品（产成品） | D9: =B9-C9 -> 0
A10: 周转材料（包装物、低值易耗品等） | D10: =B10-C10 -> 0
A11: 消耗性生物资产 | D11: =B11-C11 -> 0
A12: 房地产开发成本 | D12: =B12-C12 -> 0
A13: 房地产开发产品 | D13: =B13-C13 -> 0
D14: =B14-C14 -> 0
A15: 其他 | D15: =B15-C15 -> 0
A16: 合 计 | B16: =SUM(B7:B15) -> 0 | C16: =SUM(C7:C15) -> 0 | D16: =SUM(D7:D15) -> 0
A17: 报表金额 | B17: ='RP 006'!E23 -> 0 | C17: ='RP 006'!E24 -> 0 | D17: ='RP 006'!E25 -> 0
B18: =B16-B17 -> 0 | C18: =C16-C17 -> 0 | D18: =D16-D17 -> 0
B19: =IF(B18=0,"OK","NO") -> OK | C19: =IF(C18=0,"OK","NO") -> OK | D19: =IF(D18=0,"OK","NO") -> OK
A20: （注：根据企业具体情况分类，房地产开发企业应增加“开发成本”、“开发产品”等种类）
A21: （2）存货跌价准备
A22: 存货种类 | B22: 期初数 | C22: 本期增加 | E22: 本期减少 | G22: 期末数
C23: 计提 | D23: 其他 | E23: 转回或转销 | F23: 其他
A24: 原材料
A25: 在产品
A26: 库存商品
A27: 周转材料
A28: 消耗性生物资产
A29: 合 计 | B29: =SUM(B24:B28) -> 0 | C29: =SUM(C24:C28) -> 0 | D29: =SUM(D24:D28) -> 0 | E29: =SUM(E24:E28) -> 0 | F29: =SUM(F24:F28) -> 0 | G29: =SUM(G24:G28) -> 0
A30: 报表金额 | G30: =C17 -> 0
G31: =IF(G30=0,"OK","NO") -> OK
A33: 存货跌价准备（续）
A34: 存货种类 | B34: 确定可变现净值的具体依据 | C34: 本期转回或转销存货跌价准备的原因
A35: 原材料
A36: 在产品
A37: 库存商品
A38: 周转材料
A39: 消耗性生物资产 | D39: s
A40: 合 计
A41: 【披露确定可变现净值的具体依据及本期转回或转销存货跌价准备的原因。】
...

Sheet RP 022
A1: 公司名称 | B1: =基础信息!B6 -> 0
A2: 财务期间 | B2: =基础信息!B9 -> 0
A3: 内容 | B3: 合同资产
A4: （1）合同资产
A5: 项 目 | B5: 期末数
B6: 账面余额 | C6: 跌价准备 | D6: 账面价值
D7: =B7-C7 -> 0
D8: =B8-C8 -> 0
D9: =B9-C9 -> 0
D10: =B10-C10 -> 0
D11: =B11-C11 -> 0
D12: =B12-C12 -> 0
A13: 合 计 | B13: =SUM(B7:B12) -> 0 | C13: =SUM(C7:C12) -> 0 | D13: =SUM(D7:D12) -> 0
A14: 报表金额 | B14: ='RP 006'!E26 -> 0 | C14: ='RP 006'!E27 -> 0 | D14: ='RP 006'!E28 -> 0
B15: =B13-B14 -> 0 | C15: =C13-C14 -> 0 | D15: =D13-D14 -> 0
B16: =IF(B15=0,"OK","NO") -> OK | C16: =IF(C15=0,"OK","NO") -> OK | D16: =IF(D15=0,"OK","NO") -> OK
A18: （2）合同资产减值准备计提情况
A19: 类别 | B19: 2019.XX.XX | G19: 2019.01.01
B20: 账面余额 | D20: 坏账准备 | F20: 账面 | G20: 账面余额 | I20: 坏账准备 | K20: 账面
B21: 金额 | C21: 比例(%) | D21: 金额 | E21: 预期信用损失率(%) | F21: 价值 | G21: 金额 | H21: 比例(%) | I21: 金额 | J21: 预期信用损失率(%) | K21: 价值
A22: 按单项计提坏账准备 | B22: =B24+B25 -> 0 | C22: =C24+C25 -> #DIV/0! | D22: =D24+D25 -> 0 | E22: =ROUND(D22/B22*100,2) -> #DIV/0! | F22: =F24+F25 -> 0 | G22: =G24+G25 -> 0 | H22: =H24+H25 -> #DIV/0! | I22: =I24+I25 -> 0 | J22: =ROUND(I22/G22*100,2) -> #DIV/0! | K22: =K24+K25 -> 0
A23: 其中：
C24: =ROUND(B24/$B$24*100,2) -> #DIV/0! | E24: =ROUND(D24/B24*100,2) -> #DIV/0! | F24: =B24-D24 -> 0 | H24: =ROUND(G24/$G$24*100,2) -> #DIV/0! | J24: =ROUND(I24/G24*100,2) -> #DIV/0! | K24: =G24-I24 -> 0
C25: =ROUND(B25/$B$24*100,2) -> #DIV/0! | E25: =ROUND(D25/B25*100,2) -> #DIV/0! | F25: =B25-D25 -> 0 | H25: =ROUND(G25/$G$24*100,2) -> #DIV/0! | J25: =ROUND(I25/G25*100,2) -> #DIV/0! | K25: =G25-I25 -> 0
A26: 按组合 计提坏账准备 | B26: =B28+B29 -> 0 | C26: =C28+C29 -> #DIV/0! | D26: =D28+D29 -> 0 | F26: =F28+F29 -> 0 | G26: =G28+G29 -> 0 | H26: =H28+H29 -> #DIV/0! | I26: =I28+I29 -> 0 | J26: =ROUND(I26/G26*100,2) -> #DIV/0! | K26: =K28+K29 -> 0
A27: 其中：
C28: =ROUND(B28/$B$24*100,2) -> #DIV/0! | E28: =ROUND(D28/B28*100,2) -> #DIV/0! | F28: =B28-D28 -> 0 | H28: =ROUND(G28/$G$24*100,2) -> #DIV/0! | J28: =ROUND(I28/G28*100,2) -> #DIV/0! | K28: =G28-I28 -> 0
C29: =ROUND(B29/$B$24*100,2) -> #DIV/0! | E29: =ROUND(D29/B29*100,2) -> #DIV/0! | F29: =B29-D29 -> 0 | H29: =ROUND(G29/$G$24*100,2) -> #DIV/0! | J29: =ROUND(I29/G29*100,2) -> #DIV/0! | K29: =G29-I29 -> 0
A30: 合 计 | B30: =B26+B22 -> 0 | C30: =C26+C22 -> #DIV/0! | D30: =D26+D22 -> 0 | E30: =ROUND(D30/B30*100,2) -> #DIV/0! | F30: =F26+F22 -> 0 | H30: =H26+H22 -> #DIV/0! | J30: =ROUND(I30/G30*100,2) -> #DIV/0! | K30: =K26+K22 -> 0
A31: 应与会计政策中披露的组合一致
A32: 核对金额 | F32: =D14 -> 0
F33: =IF(F32-F30=0,"OK","NO") -> OK
A34: （3）本期计提、收回或转回的合同资产减值准备情况
A35: 项目 | B35: 期初数 | C35: 本期增加 | E35: 本期减少 | G35: 期末数
C36: 计提 | D36: 其他 | E36: 转回或转销 | F36: 其他
A43: 合 计 | B43: =SUM(B37:B42) -> 0 | C43: =SUM(C37:C42) -> 0 | D43: =SUM(D37:D42) -> 0 | E43: =SUM(E37:E42) -> 0 | F43: =SUM(F37:F42) -> 0 | G43: =SUM(G37:G42) -> 0
A44: 核对金额 | G44: =C14 -> 0
G45: =IF(G44=0,"OK","NO") -> OK

Sheet RP 023
A1: 公司名称 | B1: =基础信息!B6 -> 0
A2: 财务期间 | B2: =基础信息!B9 -> 0
A3: 内容 | B3: 持有待售资产和持有待售负债
A6: 项 目 | B6: 期末数
A7: 持有待售的资产：
A8: 持有待售的非流动资产
A9: 持有待售的处置组中的资产
A10: 其中：子公司A
A11: 分公司B
A12: 合 计 | B12: =SUM(B7:B11) -> 0
A13: 报表金额 | B13: ='RP 006'!E29 -> 0
B14: =B12-B13 -> 0
B15: =IF(B14=0,"OK","NO") -> OK
A17: 项 目 | B17: 期末数
A18: 持有待售的负债：
A19: 持有待售的处置组中的负债
A20: 其中：子公司A
A21: 分公司B
A22: 合 计 | B22: =SUM(B18:B21) -> 0
A23: 报表金额 | B23: ='RP 006'!E92 -> 0
B24: =B22-B23 -> 0
B25: =IF(B24=0,"OK","NO") -> OK
A27: 说明：（应当说明持有待售的非流动资产及持有待售的处置组中的资产产生的原因、内容及性质）
A28: （1）持有待售的非流动资产
A29: 期末，持有待售的资产的情况：
A30: 项 目 | B30: 账面价值 | C30: 公允价值 | D30: 预计处置费用 | E30: 预计处置时间
A35: 合 计
A37: （2）持有待售的处置组
A38: ①子公司A
A39: 项 目 | B39: 账面价值 | C39: 公允价值 | D39: 预计处置费用 | E39: 预计处置时间
A40: 持有待售的处置组中的资产
A41: 货币资金
A43: 固定资产
A44: ……
A46: 持有待售的处置组中的负债
A47: 应付账款
A48: 长期应付款
A49: ……
A51: ②分公司B
A52: 项 目 | B52: 账面价值 | C52: 公允价值 | D52: 预计处置费用 | E52: 预计处置时间
...

Sheet RP 024
A1: 公司名称 | B1: =基础信息!B6 -> 0
A2: 财务期间 | B2: =基础信息!B9 -> 0
A3: 内容 | B3: 一年内到期的非流动资产
A6: （1）项目分析
A7: 项 目 | B7: 期末数
A8: 1年内到期的长期应收款
A9: 1年内到期的持有至到期投资
A10: 1年内到期的债权投资
A11: 1年内到期的其他债权投资
A12: 其他
A13: 合 计 | B13: =SUM(B8:B11) -> 0
A14: 报表金额 | B14: ='RP 006'!E30 -> 0
B15: =B17-B14 -> 0
B16: =IF(B15=0,"OK","NO") -> OK
A17: 说明：（对于大额的一年内到期的非流动资产说明形成的原因、内容、性质。）
A19: 其他债权投资行项目，反映资产负债表日企业分类为以公允价值计量且其变动计入其他综合收益的长期债权投资的期末账面价值。该项目应根据"其他债权投资"科目的相关明细科目期末余额分析填列。自资产负债表日起一年内到期的长期债权投资的期末账面价值，在"一年内到期的非流动资产"行项目反映。

Sheet RP 025
A1: 公司名称 | B1: =基础信息!B6 -> 0
A2: 财务期间 | B2: =基础信息!B9 -> 0
A3: 内容 | B3: 其他流动资产
A4: 项 目 | B4: 期末
A5: 进项税额
A6: 多交或预缴的增值税额
A7: 待抵扣进项税额
A8: 待认证进项税额
A9: 增值税留抵税额
A10: 预缴所得税
A11: 委托贷款
A12: 预缴其他税费
A13: 短期债权投资
A14: 短期其他债权投资
A15: 合同取得成本
A16: 应收退货成本
A17: 合 计 | B17: =SUM(B5:B16) -> 0
A18: 报表金额 | B18: ='RP 006'!E41 -> 0
B19: =B17-B18 -> 0
B20: =IF(B19=0,"OK","NO") -> OK
A23: 进项税额
A24: 多交或预缴的增值税额
A25: 待抵扣进项税额
A26: 待认证进项税额
A27: 增值税留抵税额
A28: 预缴所得税
A29: 委托贷款
A30: 预缴其他税费
A31: 短期债权投资
A32: 短期其他债权投资
A33: 合同取得成本
A34: 应收退货成本

Sheet RP 026
A1: 公司名称 | B1: =基础信息!B6 -> 0
A2: 财务期间 | B2: =基础信息!B9 -> 0
A3: 内容 | B3: 债权投资
A4: 债券投资情况
A5: 项 目 | B5: 期末数
B6: 账面余额 | C6: 减值准备 | D6: 账面价值
D7: =B7-C7 -> 0
D8: =B8-C8 -> 0
D9: =B9-C9 -> 0
D10: =B10-C10 -> 0
D11: =B11-C11 -> 0
A12: 小 计 | B12: =SUM(B7:B11) -> 0 | C12: =SUM(C7:C11) -> 0 | D12: =SUM(D7:D11) -> 0
A13: 减：1年内到期的债权投资
A14: 合 计 | B14: =B12-B13 -> 0 | C14: =C12-C13 -> 0 | D14: =D12-D13 -> 0
A15: 报表金额 | D15: ='RP 006'!E45 -> 0
D16: =D14-D15 -> 0
D17: =IF(D16=0,"OK","NO") -> OK
A19: （1）重要的债权投资
A20: 债权投资项目 | B20: 面值 | C20: 票面利率 | D20: 实际利率 | E20: 到期日
A22: 合 计 | B22: X.XX | C22: -- | D22: -- | E22: --
A25: （2）减值准备计提情况
A26: 【15号文第十九条（十一），披露用以确定本期减值准备计提金额以及评估金融工具的信用风险自初始确认后是否已显著增加等事项时所采用的输入值、假设等信息。】
A27: 于2019年12月31日，处于第一阶段的债权投资的减值准备分析如下：
A28: 类别 | B28: 账面余额 | C28: 未来12个月内预期信用损失率（%） | D28: 减值准备 | E28: 账面价值 | F28: 理由
A29: 按单项计提坏账准备
A30: 其中：
A33: 按组合计提坏账准备
A34: 其中：
A37: 合 计
A38: 于2018年12月31日，处于第二阶段的债权投资的减值准备分析如下：
A39: 类别 | B39: 账面余额 | C39: 整个存续期预期信用损失率（%） | D39: 减值准备 | E39: 账面价值 | F39: 理由
A40: 按单项计提坏账准备 | B40: =B42+B43 -> 0 | D40: =D42+D43 -> 0 | E40: =B40-C40 -> 0
A41: 其中： | E41: =B41-C41 -> 0
E42: =B42-C42 -> 0
E43: =B43-C43 -> 0
A44: 按组合计提坏账准备 | B44: =B45+B46+B47 -> 0 | D44: =D46+D47 -> 0 | E44: =B44-C44 -> 0
A45: 其中： | E45: =B45-C45 -> 0
E46: =B46-C46 -> 0
E47: =B47-C47 -> 0
A48: 合 计 | B48: =B44+B40 -> 0 | D48: =D44+D40 -> 0 | E48: =E44+E40 -> 0
...

Sheet RP 027
A1: 公司名称 | B1: =基础信息!B6 -> 0
A2: 财务期间 | B2: =基础信息!B9 -> 0
A3: 内容 | B3: 可供出售金融资产
A4: （1）可供出售金融资产情况
A5: 项 目 | B5: 期末数
B6: 账面余额 | C6: 减值准备 | D6: 账面价值
A7: 可供出售债务工具 | D7: =B7-C7 -> 0
A8: 可供出售权益工具 | D8: =B8-C8 -> 0
A9: 其中：按公允价值计量 | D9: =B9-C9 -> 0
A10: 按成本计量 | D10: =B10-C10 -> 0
A11: 其他 | D11: =B11-C11 -> 0
A12: 合 计 | B12: =SUM(B7:B11) -> 0 | C12: =SUM(C7:C11) -> 0 | D12: =SUM(D7:D11) -> 0
A13: 报表金额 | D13: ='RP 006'!E46 -> 0
D14: =D12-D13 -> 0
D15: =IF(D14=0,"OK","NO") -> OK

Sheet RP 028
A1: 公司名称 | B1: =基础信息!B6 -> 0
A2: 财务期间 | B2: =基础信息!B9 -> 0
A3: 内容 | B3: 其他债权投资
A4: （1）其他债权投资情况
A5: 项 目 | B5: 期末数
B6: 账面价值
A12: 小计 | B12: =SUM(B7:B11) -> 0
A13: 减：1年内到期的债权投资
A15: 合计 | B15: =B12-B14 -> 0
A16: 报表金额 | B16: ='RP 006'!E53 -> 0
B17: =B15-B16 -> 0
B18: =IF(B17=0,"OK","NO") -> OK
A19: （1）其他债权投资情况
A20: 项目 | B20: 2019.01.01 | C20: 应计利息 | D20: 本期公允价值变动 | E20: 2019.12.31 | F20: 成本 | G20: 累计公允价值变动 | H20: 累计在其他综合收益中确认的损失准备
A23: 合计
A24: 说明：
A25: （2）期末重要的其他债权投资
A26: 项目 | B26: 2019.12.31 | F26: 2018.12.31
B27: 面值 | C27: 票面利率 | D27: 实际利率 | E27: 到期日 | F27: 面值 | G27: 票面利率 | H27: 实际利率 | I27: 到期日
F28: - | G28: - | H28: - | I28: -
F29: - | G29: - | H29: - | I29: -
A30: 合计 | C30: / | D30: / | E30: / | F30: - | G30: / | H30: / | I30: /
A31: （3）减值准备计提情况
A32: 【15号文第十九条（十一），披露用以确定本期减值准备计提金额以及评估金融工具的信用风险自初始确认后是否已显著增加等事项时所采用的输入值、假设等信息。】
A33: 于2019年12月31日，处于第一阶段的其他债权投资的减值准备分析如下：
A34: 类别 | B34: 账面余额 | C34: 未来12个月内预期信用损失率（%） | D34: 减值准备 | E34: 账面价值 | F34: 理由
A35: 按单项计提坏账准备
A36: 其中：
A39: 按组合计提坏账准备
A40: 其中：
A43: 合 计
A45: 于2019年12月31日，处于第二阶段的其他债权投资的减值准备分析如下：
A46: 类别 | B46: 账面余额 | C46: 整个存续期预期信用损失率（%） | D46: 减值准备 | E46: 账面价值 | F46: 理由
A47: 按单项计提坏账准备
A48: 其中：
A51: 按组合计提坏账准备
A52: 其中：
A55: 合 计
A56: 于2019年12月31日，处于第三阶段的其他债权投资的减值准备分析如下：
A57: 类别 | B57: 账面余额 | C57: 整个存续期预期信用损失率（%） | D57: 减值准备 | E57: 账面价值 | F57: 理由
...

Sheet RP 029
A1: 公司名称 | B1: =基础信息!B6 -> 0
A2: 财务期间 | B2: =基础信息!B9 -> 0
A3: 内容 | B3: 持有至到期投资
A4: （1）持有至到期投资情况
A5: 项 目 | B5: 期末数
B6: 账面余额 | C6: 减值准备 | D6: 账面价值
D7: =B7-C7 -> 0
D8: =B8-C8 -> 0
D9: =B9-C9 -> 0
D10: =B10-C10 -> 0
D11: =B11-C11 -> 0
A12: 小 计 | B12: =SUM(B7:B11) -> 0 | C12: =SUM(C7:C11) -> 0 | D12: =SUM(D7:D11) -> 0
A13: 减：1年内到期的持有至到期投资
A14: 合 计 | B14: =B12-B13 -> 0 | C14: =C12-C13 -> 0 | D14: =D12-D13 -> 0
A15: 报表金额 | D15: ='RP 006'!E47 -> 0
D16: =D14-D15 -> 0
D17: =IF(D16=0,"OK","NO") -> OK
A19: （2）重要的持有至到期投资
A20: 债券项目 | B20: 面值 | C20: 票面利率 | D20: 实际利率 | E20: 到期日
A22: 合 计 | B22: X.XX | C22: -- | D22: -- | E22: --
A23: （对于重要的持有至到期投资，应分别列示其面值、票面利率、实际利率、到期日。）
A24: （3）持有至到期投资重分类情况
A25: （本期存在重分类的，应披露重分类的原因和具体情况。）
A26: 由于XX原因，本期将持有至到期投资重分类为可供出售金融资产，重分类的金额XX元，该金额占重分类前持有至到期投资总额的比例XX%。

Sheet RP 030
A1: 公司名称 | B1: =基础信息!B6 -> 0
A2: 财务期间 | B2: =基础信息!B9 -> 0
A3: 内容 | B3: 长期应收款
A4: （1）长期应收款按性质披露
A5: 项 目 | B5: 期末数 | E5: 折现率区间
B6: 账面余额 | C6: 坏账准备 | D6: 账面价值
A7: 融资租赁款 | D7: =B7-C7 -> 0
A8: 其中：未实现融资收益 | D8: =B8-C8 -> 0
A9: 分期收款销售商品 | D9: =B9-C9 -> 0
A10: 其中：未实现融资收益 | D10: =B10-C10 -> 0
A11: 分期收款提供劳务 | D11: =B11-C11 -> 0
A12: 其中：未实现融资收益 | D12: =B12-C12 -> 0
A13: 其他 | D13: =B13-C13 -> 0
A14: 可无限量添加行 | D14: =B14-C14 -> 0
A15: 小 计 | D15: =B15-C15 -> 0
A16: 减：1年内到期的长期应收款 | D16: =B16-C16 -> 0
A17: 合 计 | B17: =B15-B16 -> 0 | C17: =C15-C16 -> 0 | D17: =D15-D16 -> 0
A18: 报表金额 | D18: ='RP 006'!E48 -> 0
D19: =D17-D18 -> 0
D20: =IF(D19=0,"OK","NO") -> OK
A22: （2）坏账准备计提情况
A23: 类别 | B23: 2019.XX.XX | G23: 2019.01.01
B24: 账面余额 | D24: 坏账准备 | F24: 账面 | G24: 账面余额 | I24: 坏账准备 | K24: 账面
B25: 金额 | C25: 比例(%) | D25: 金额 | E25: 预期信用损失率(%) | F25: 价值 | G25: 金额 | H25: 比例(%) | I25: 金额 | J25: 预期信用损失率(%) | K25: 价值
A26: 按单项计提坏账准备 | B26: =B28+B29 -> 0 | C26: =C28+C29 -> #VALUE! | D26: =D28+D29 -> 0 | E26: =ROUND(D26/B26*100,2) -> #DIV/0! | F26: =F28+F29 -> 0 | G26: =G28+G29 -> 0 | H26: =H28+H29 -> #VALUE! | I26: =I28+I29 -> 0 | J26: =ROUND(I26/G26*100,2) -> #DIV/0! | K26: =K28+K29 -> 0
A27: 其中：
C28: =ROUND(B28/$B$24*100,2) -> #VALUE! | E28: =ROUND(D28/B28*100,2) -> #DIV/0! | F28: =B28-D28 -> 0 | H28: =ROUND(G28/$G$24*100,2) -> #VALUE! | J28: =ROUND(I28/G28*100,2) -> #DIV/0! | K28: =G28-I28 -> 0
C29: =ROUND(B29/$B$24*100,2) -> #VALUE! | E29: =ROUND(D29/B29*100,2) -> #DIV/0! | F29: =B29-D29 -> 0 | H29: =ROUND(G29/$G$24*100,2) -> #VALUE! | J29: =ROUND(I29/G29*100,2) -> #DIV/0! | K29: =G29-I29 -> 0
A30: 按组合 计提坏账准备 | B30: =B32+B33 -> 0 | C30: =C32+C33 -> #VALUE! | D30: =D32+D33 -> 0 | F30: =F32+F33 -> 0 | G30: =G32+G33 -> 0 | H30: =H32+H33 -> #VALUE! | I30: =I32+I33 -> 0 | J30: =ROUND(I30/G30*100,2) -> #DIV/0! | K30: =K32+K33 -> 0
A31: 其中：
C32: =ROUND(B32/$B$24*100,2) -> #VALUE! | E32: =ROUND(D32/B32*100,2) -> #DIV/0! | F32: =B32-D32 -> 0 | H32: =ROUND(G32/$G$24*100,2) -> #VALUE! | J32: =ROUND(I32/G32*100,2) -> #DIV/0! | K32: =G32-I32 -> 0
C33: =ROUND(B33/$B$24*100,2) -> #VALUE! | E33: =ROUND(D33/B33*100,2) -> #DIV/0! | F33: =B33-D33 -> 0 | H33: =ROUND(G33/$G$24*100,2) -> #VALUE! | J33: =ROUND(I33/G33*100,2) -> #DIV/0! | K33: =G33-I33 -> 0
A34: 合 计 | B34: =B30+B26 -> 0 | C34: =C30+C26 -> #VALUE! | D34: =D30+D26 -> 0 | E34: =ROUND(D34/B34*100,2) -> #DIV/0! | F34: =F30+F26 -> 0 | H34: =H30+H26 -> #VALUE! | J34: =ROUND(I34/G34*100,2) -> #DIV/0! | K34: =K30+K26 -> 0
A35: 按单项计提坏账准备：
A36: 名 称 | B36: 2019.12.31
B37: 账面余额 | C37: 坏账准备 | D37: 预期信用损失率(%) | E37: 计提理由
D38: =C38/B38*100 -> #DIV/0!
D39: =C39/B39*100 -> #DIV/0!
A40: 合 计 | B40: =SUM(B38:B39) -> 0 | C40: =SUM(C38:C39) -> 0 | D40: =C40/B40*100 -> #DIV/0! | E40: /
A41: 按组合计提坏账准备：
...

Sheet RP 031
A1: 公司名称 | B1: =基础信息!B6 -> 0
A2: 财务期间 | B2: =基础信息!B9 -> 0
A3: 内容 | B3: 设定受益计划净资产
A4: （1）项目分析
A5: 项 目 | B5: 期初数 | C5: 本期增加 | D5: 本期减少 | E5: 期末数
A6: 设定受益计划净资产 | E6: =B6+C6-D6 -> 0
E7: =B7+C7-D7 -> 0
A8: 符合设定受益计划条件的其他长期职工福利的净资产（不适用删除） | E8: =B8+C8-D8 -> 0
A9: 合 计 | B9: =SUM(B6:B8) -> 0 | C9: =SUM(C6:C8) -> 0 | D9: =SUM(D6:D8) -> 0 | E9: =SUM(E6:E8) -> 0
A10: 报表金额 | E10: ='RP 006'!E49 -> 0
E11: =E9-E10 -> 0
E12: =IF(E11=0,"OK","NO") -> OK
A13: 【提示：需要按照五、46中的披露格式披露设定收益计划相关信息。】

Sheet RP 032
A1: 公司名称 | B1: =基础信息!B6 -> 0
A2: 财务期间 | B2: =基础信息!B9 -> 0
A3: 内容 | B3: 长期股权投资
A4: 被投资单位 | B4: 期初余额 | C4: 本期增减变动 | K4: 期末余额 | L4: 减值准备期末余额
C5: 追加投资 | D5: 减少投资 | E5: 权益法下确认的投资损益 | F5: 其他综合收益调整 | G5: 其他权益变动 | H5: 宣告发放现金股利或利润 | I5: 计提减准备值 | J5: 其他
A6: ①合营企业
A7: …
A9: 小计
A10: ②联营企业
A11: …
A16: 小计
A17: 合 计
A18: 报表金额 | K18: ='RP 006'!E50 -> 0 | L18: ='RP 006'!E51 -> 0
K19: =K17-K18 -> 0 | L19: =L17-L18 -> 0
K20: =IF(K19=0,"OK","NO") -> OK | L20: =IF(L19=0,"OK","NO") -> OK
A22: （1）重要的合营企业或联营企业
A23: 合营企业或联营企业名称 | B23: 主要经营地 | C23: 注册地 | D23: 业务性质 | E23: 持股比例(%) | G23: 对合营企业或联营企业投资的会计处理方法
E24: 直接 | F24: 间接
A25: ①合营企业
A29: ②联营企业
A31: 可无限量添加行
A33: 说明：
A34: （1）持股比例不同于表决权比例的，应说明表决权比例及差异原因。
A35: （2）持有其他主体20%以下表决权但具有重大影响，或者持有其他主体20%或以上表决权但不具有重大影响的，应披露相关判断和依据。
A36: （2）重要合营企业的主要财务信息：（划分为持有待售的除外）
A37: （主要财务信息按照权益法调整后的金额披露；）
A38: （“调整事项”包括投资形成的正商誉、抵消的未实现内部交易损益、减值准备等事项；）
A39: （如果母公司为投资性主体，无需披露下列财务信息。）
A40: 项 目 | B40: （A公司） | D40: （B公司） | F40: （C公司）
B41: 期末数 | C41: 期初数 | D41: 期末数 | E41: 期初数 | F41: 期末数 | G41: 期初数
A42: 流动资产
A43: 其中：现金和现金等价物
A44: 非流动资产
A45: 资产合计
A46: 流动负债
A47: 非流动负债
A48: 负债合计
A49: 净资产
A50: 其中：少数股东权益
A51: 归属于母公司的所有制权益
...

Sheet RP 033
A1: 公司名称 | B1: =基础信息!B6 -> 0
A2: 财务期间 | B2: =基础信息!B9 -> 0
A3: 内容 | B3: 其他权益工具投资
A6: 项目 | B6: 2019.12.31 | C6: 2018.12.31
C7: -
C8: -
C9: -
A10: 合 计 | B10: =SUM(B7:B9) -> 0 | C10: =SUM(C7:C9) -> 0
A11: 报表金额 | B11: ='RP 006'!E53 -> 0
B12: =B10-B11 -> 0
B13: =IF(B12=0,"OK","NO") -> OK
A15: [披露企业将上述各项目指定为以公允价值计量且其变动计入其他综合收益的原因。例如：
A16: 由于[项目名称1]是本集团出于战略目的而计划长期持有的投资，因此本集团将其指定为以公允价值计量且其变动计入其他综合收益的金融资产。]
A17: 项 目 | B17: 本期确认的股利收入 | C17: 累计利得 | D17: 累计损失 | E17: 其他综合收益转入留存收益的金额 | F17: 转入原因
A21: [企业本期终止确认了其他权益工具投资的，应披露处置该权益工具投资的原因，该权益工具投资在终止确认时的公允价值及该权益工具投资在终止确认时的累计利得或损失。]

Sheet RP 034
A1: 公司名称 | B1: =基础信息!B6 -> 0
A2: 财务期间 | B2: =基础信息!B9 -> 0
A3: 内容 | B3: 其他非流动金融资产
A6: 种类 | B6: 2018.12.31 | C6: 2017.12.31
A7: 债务工具投资 | C7: -
A8: 权益工具投资 | C8: -
A9: 指定为以公允价值计量且其变动计入当期损益的金融资产 | C9: -
A10: 其他 | C10: -
A11: 合 计 | B11: =SUM(B7:B10) -> 0 | C11: =SUM(C7:C10) -> 0
A12: 报表金额 | B12: ='RP 006'!E54 -> 0
B13: =B11-B12 -> 0
B14: =IF(B13=0,"OK","NO") -> OK

Sheet RP 035
A1: 公司名称 | B1: =基础信息!B6 -> 0
A2: 财务期间 | B2: =基础信息!B9 -> 0
A3: 内容 | B3: 投资性房地产
A4: （1）按成本计量的投资性房地产（如无按公允价值计量的投资性房地产，删除此标题）
A5: 项 目 | B5: 房屋、建筑物 | C5: 土地使用权 | D5: 在建工程 | E5: 合计
A6: 一、账面原值
A7: 1.期初余额 | E7: =SUM(B7:D7) -> 0
A8: 2.本期增加金额 | B8: =SUM(B9:B12) -> 0 | C8: =SUM(C9:C12) -> 0 | D8: =SUM(D9:D12) -> 0 | E8: =SUM(E9:E12) -> 0
A9: （1）外购
A10: （2）存货\固定资产\在建工程转入
A11: （3）企业合并增加
A12: 可无限量添加行
A13: 3.本期减少金额 | B13: =SUM(B14:B16) -> 0 | C13: =SUM(C14:C16) -> 0 | D13: =SUM(D14:D16) -> 0 | E13: =SUM(E14:E16) -> 0
A14: （1）处置
A15: （2）其他转出
A16: 可无限量添加行
A17: 4.期末余额 | B17: =B7+B8-B13 -> 0 | C17: =C7+C8-C13 -> 0 | D17: =D7+D8-D13 -> 0 | E17: =E7+E8-E13 -> 0
A18: 二、累计折旧和累计摊销
A19: 1.期初余额
A20: 2.本期增加金额 | B20: =SUM(B21:B24) -> 0 | C20: =SUM(C21:C24) -> 0 | D20: =SUM(D21:D24) -> 0 | E20: =SUM(E21:E24) -> 0
A21: （1）计提或摊销
A22: （2）企业合并增加
A23: （3）其他增加
A24: 可无限量添加行
A25: 3.本期减少金额 | B25: =SUM(B26:B28) -> 0 | C25: =SUM(C26:C28) -> 0 | D25: =SUM(D26:D28) -> 0 | E25: =SUM(E26:E28) -> 0
A26: （1）处置
A27: （2）其他转出
A28: 可无限量添加行
A29: 4.期末余额 | B29: =B19+B20-B25 -> 0 | C29: =C19+C20-C25 -> 0 | D29: =D19+D20-D25 -> 0 | E29: =E19+E20-E25 -> 0
A30: 三、减值准备
A31: 1.期初余额
A32: 2.本期增加金额 | B32: =SUM(B33:B35) -> 0 | C32: =SUM(C33:C35) -> 0 | D32: =SUM(D33:D35) -> 0 | E32: =SUM(E33:E35) -> 0
A33: （1）计提
A34: （2）其他增加
A35: 可无限量添加行
A36: 3、本期减少金额 | B36: =SUM(B37:B39) -> 0 | C36: =SUM(C37:C39) -> 0 | D36: =SUM(D37:D39) -> 0 | E36: =SUM(E37:E39) -> 0
A37: （1）处置
A38: （2）其他转出
A39: 可无限量添加行
A40: 4.期末余额
...

Sheet RP 036
A1: 公司名称 | B1: =基础信息!B6 -> 0
A2: 财务期间 | B2: =基础信息!B9 -> 0
A3: 内容 | B3: 固定资产
A4: 项 目 | B4: 期末数 | C4: 转入清理的原因
A5: 固定资产 | B5: ='RP 036-1'!F41 -> 0
A6: 固定资产清理 | B6: ='RP 036-2'!B7 -> 0
A7: 合 计 | B7: =SUM(B5:B6) -> 0
A8: 报表金额 | B8: ='RP 006'!E62 -> 0
B9: =B7-B8 -> 0
B10: =IF(B9=0,"OK","NO") -> OK

Sheet RP 036-1
A1: 公司名称 | B1: =基础信息!B6 -> 0
A2: 财务期间 | B2: =基础信息!B9 -> 0
A3: 内容 | B3: 固定资产及累计折旧
A4: （1）固定资产情况
A5: 项 目 | B5: 房屋及建筑物 | C5: 机器设备 | D5: 运输设备 | E5: …… | F5: 合 计
A6: 一、账面原值： | F6: =SUM(B6:E6) -> 0
A7: 1.期初余额 | F7: =SUM(B7:E7) -> 0
A8: 2.本期增加金额 | B8: =SUM(B9:B12) -> 0 | C8: =SUM(C9:C12) -> 0 | D8: =SUM(D9:D12) -> 0 | E8: =SUM(E9:E12) -> 0 | F8: =SUM(B8:E8) -> 0
A9: （1）购置 | F9: =SUM(B9:E9) -> 0
A10: （2）在建工程转入 | F10: =SUM(B10:E10) -> 0
A11: （3）企业合并增加 | F11: =SUM(B11:E11) -> 0
A12: …… | F12: =SUM(B12:E12) -> 0
A13: 3.本期减少金额 | F13: =SUM(B13:E13) -> 0
A14: （1）处置或报废 | F14: =SUM(B14:E14) -> 0
A15: （2）其他减少 | F15: =SUM(B15:E15) -> 0
A16: …… | F16: =SUM(B16:E16) -> 0
A17: 4.期末余额 | F17: =SUM(B17:E17) -> 0
A18: 二、累计折旧 | F18: =SUM(B18:E18) -> 0
A19: 1.期初余额 | F19: =SUM(B19:E19) -> 0
A20: 2.本期增加金额 | F20: =SUM(B20:E20) -> 0
... A42: 2.期初账面价值 | F42: =SUM(B42:E42) -> 0
A43: 核对金额 | F43: ='RP 036'!B5 -> 0
F44: =F41-F43 -> 0
F45: =IF(F44=0,"OK","NO") -> OK
A46: 说明：
A47: ①（抵押、担保的固定资产情况）
A48: （注：本期发生以明显高于账面价值的价格出售固定资产交易的，应详细说明交易作价的基础和依据，如：估值模型、重要参数的选取依据和估值过程，以及必要的敏感性分析。）
A49: 【提示：在“其他减少”中列示本期收到的政府补助冲减固定资产账面价值的金额。对于冲减无形资产或其他资产账面价值的政府补助，比照披露。】
A50: （提示：对于冲减无形资产或其他资产账面价值的政府补助，在无形资产或其他资产的科目附注中比照上述要求进行披露。）
