Workbook

Sheet 底稿目录
A1: 底稿开列时，可先在以下单元格填写有关内容，以便其他底稿引用有关数据：
A2: 被审计单位： | G2: 后续计量模式选择 | H2: 成本模式
A3: 截止日：202X年12月31日 | D3: 序号 | E3: 内容 | F3: 索引号 | G3: 备注
A4: 编制人： | D4: 1 | E4: 投资性房地产实质性程序表 | F4: H3A
A5: 复核人： | D5: =D4+1 -> 2 | E5: 审定表（成本模式） | F5: H3-1 | G5: =IF(底稿目录!$H$2="成本模式","有效（当前模式）","不适用（请标注并留空）") -> 有效（当前模式）
A6: 编制日期： | D6: =D5+1 -> 3 | E6: 审定表（公允价值模式） | F6: H3-1 | G6: =IF(底稿目录!$H$2="公允价值模式","有效（当前模式）","不适用（请标注并留空）") -> 不适用（请标注并留空）
A7: 复核日期： | D7: =D6+1 -> 4 | E7: 附注披露信息（上市公司） | G7: 无需打印
A8: 固定资产类别设置（以下内容请根据实际情况修改）： | D8: =D7+1 -> 5 | E8: 附注披露信息（国有企业） | G8: 无需打印
A9: 房屋、建筑物 | D9: =D8+1 -> 6 | E9: 明细表（成本模式） | F9: H3-2
A10: 土地使用权 | D10: =D9+1 -> 7 | E10: 明细表（公允价值模式） | F10: H3-2
A11: 在建工程 | D11: =D10+1 -> 8 | E11: 调整分录汇总 | F11: H3-3
A12: …… | D12: =D11+1 -> 9 | E12: 会计政策会计估计检查表 | F12: H3-4
D13: =D12+1 -> 10 | E13: 增减检查表（成本模式） | F13: H3-5
D14: =D13+1 -> 11 | E14: 增减检查表（公允价值模式） | F14: H3-5
A15: 关于工作底稿与审计程序索引号对应的说明 | D15: =D14+1 -> 12 | E15: 互转审核表 | F15: H3-6
A16: 1.编制的审计工作底稿应与审计程序对应。审计项目组应根据被审计单位实际情况和风险评估情况在实质性程序表中裁剪、修改或增加审计程序，根据实际执行的审计程序完成相应审计工作底稿，编制的工作底稿中应按自然顺序依次编制索引号，并通过唯一的索引号将与实质性程序表中的程序对应关联（即将工作底稿的索引号填入实质性程序表中的底稿索引号列）。 | D16: =D15+1 -> 13 | E16: 折旧测算表（成本模式不含减值） | F16: H3-7
D17: =D16+1 -> 14 | E17: 折旧测算表（成本模式含减值） | F17: H3-7
D18: =D17+1 -> 15 | E18: 公允价值复核表 | F18: H3-8
D19: =D18+1 -> 16 | E19: 盘点检查表 | F19: H3-9
A20: 2.获取的支持性证据应与审计底稿或程序对应。审计项目组在完成底稿时获取的支持性证据应根据底稿索引号编制下一级按自然顺序排序的索引号（如D1-2-1、D1-2-2、……），并在底稿中说明引用的支持性证据、关联索引号。 | D20: =D19+1 -> 17 | E20: 减值测算表 | F20: H3-10
D21: =D20+1 -> 18 | E21: 可收回金额测试表 | F21: H3-11
D22: =D21+1 -> 19 | E22: 产权核对表 | F22: H3-12
A23: 3.工作底稿索引号的编码规则：实质性程序索引号按循环从“D”到“N”,循环内账户以顺序号排列，模板中底稿索引号按账户顺序+自然数顺序（即模板中索引号按二级自然顺序排列，如D1-1、D1-2、D1-3、……D1-N）。 | D23: =D22+1 -> 20 | E23: 关联交易检查表 | F23: H3-13
D24: =D23+1 -> 21 | E24: 租金收入测算表 | F24: H3-14

Sheet 投资性房地产实质性程序表H3A
A1: 致同会计师事务所
A2: 投资性房地产、累计折旧/摊销及减值准备实质性程序表
A3: =底稿目录!A2 -> 被审计单位： | C3: =底稿目录!A4 -> 编制人： | E3: =底稿目录!A6 -> 编制日期： | H3: 索引号： | I3: H3A
A4: =底稿目录!A3 -> 截止日：202X年12月31日 | C4: =底稿目录!A5 -> 复核人： | E4: =底稿目录!A7 -> 复核日期： | H4: 页 次：
A5: 一、本账户涉及的科目
A6: 投资性房地产、累计折旧/摊销、减值准备
A7: 二、审计目标与认定的对应关系
A8: 审计目标 | G8: 财务报表的认定
A9: A. 资产负债表中记录的投资性房地产是存在的，且已记录于恰当的账户 | G9: 存在
A10: B. 所有应记录的投资性房地产均已记录，所有应当包括在财务报表中的相关披露均已包括 | G10: 完整性
A11: C. 记录的投资性房地产由被审计单位拥有或控制； | G11: 权利和义务
A12: D. 投资性房地产以恰当的金额包括在财务报表中，与之相关的计价或分摊调整已恰当记录，相关披露已得到恰当计量和描述 | G12: 准确性、计价和分摊
A13: E. 投资性房地产已被恰当地汇总或分解且表述清楚，相关披露在按照企业会计准则的编制基础下是相关的、可理解的 | G13: 列报
A14: 三、计划实施的实质性程序
A15: 序号 | B15: 审计程序 | C15: 程序分类 | D15: 财务报表的认定 | I15: 底稿索引号
D16: 存在 | E16: 完整性 | F16: 权利和 义务 | G16: 准确性、计价和分摊 | H16: 列报 | J16: 根据被审计单位实际情况和风险评估情况裁剪、修改或增加审计程序
A17: 1 | B17: 获取或编制投资性房地产的明细表，完成以下工作，并编制审定表： （1）复核加计是否正确，并与总账数和明细账合计数核对是否相符，期初余额与上期审定期末余额是否相符； （3）分析投资性房地产与上期变动情况； （2）询问闲置资产或未入账资产处置情况（如有）。 | C17: 常规★ | D17: √ | E17: √ | G17: √ | I17: H3-1 /H3-2
A18: 2 | B18: 在使用手工编制、自定义信息报告、系统生成的非固定格式报告等由被审计单位生成的信息时，测试有关信息准确性和完整性，并考虑针对编制和维护由被审计单位生成的信息的相关控制实施控制测试，以评价该信息是否能够为实现审计目的提供基础。 | C18: 常规★ | E18: √ | G18: √ | I18: T1 / | J18: 可参见《审计手册》4.2.6，由被审计单位生成的信息可能是由系统生成的、或手工编制的、或二者兼而有之的方式生成的。例如，由被审计单位生成的信息可能包括： • 不涉及自定义的、由系统生成的报告（如，固定格式报告）； • 可能通过人工自定义的、由系统生成的报告，例如，（计算机）查询信息或特别定制的报告； • 手工编制的信息，例如，汇总信息的电子表格或用以支持分配、计算以及调节的电子表格； • 其他系统生成或手工编制的信息，例如，由被审计单位编制的客户发票； • 通过影印、拍摄、扫描或其他方式转换成电子形式的文件记录。
A19: 3 | B19: 对期初余额的审计，取得上期投资性房地产明细表复核加计是否正确，与总账、明细账合计数是否相符； 重新测算期初累计折旧余额准确性；对单项金额重大资产，进行实地查看资产或检查支持性文件，其他必要追加的审计程序。（适用于首次承接） | C19: 备选 | D19: √ | E19: √ | F19: √ | G19: √ | J19: 由被审计单位生成的信息不包括： • 总分类账或明细分类账、试算平衡表、或经审计的财务报表； • 第三方（除了服务机构）的报表或报告，例如，原始银行对账单，或函证的回函； • 外部数据（例如，第三方发布的数据，如，定价来源）。
A20: 4 | B20: 关注会计政策、会计估计合理性、一贯性，关注其是否利用会计政策和会计估计及其变更操纵利润。必要时与同行业其他公司会计政策、会计估计进行对比，主要会计政策和估计包括： （1）投资性房地产的分类和采用的计量模式和依据； （2）投资性房地产折旧/减值的政策和方法； （3）投资性房地产的后续支出（包括支出费用化和资本化）及终止确认； （4）投资性房地产变更用途和计量属性的合理性。 | C20: 常规★ | D20: √ | E20: √ | G20: √ | I20: H3-4
A21: 5 | B21: 检查本期增加的投资性房地产： （1）对于外购的投资性房地产，追查至购买合同/协议、原始发票、验收报告等以确认其有效性、金额的正确性以及新增投资性房地产是否经过有效批准； （2）对于投资性房地产后续支出，检查后续支出的核算是否符合规定，如果后续支出金额较大，进行细节测试：检查大额支出的原始记录，分析资本性支出和收益性支出的划分是否合理。 （3）检查本期对投资性房地产进行改良或装修的会计处理是否正确。 | C21: 常规 | D21: √ | E21: √ | F21: √ | G21: √ | I21: H3-5
A22: 7 | B22: 检查本期减少的投资性房地产： （1）对于处置、报废、盘亏的投资性房地产，确认已经办理审批手续，相关收益或损失已正确计算，并进行正确的会计处理。 （2）对于投资性房地产转为自用房地产，关注转换依据是否充分，检查是否经过有效批准，会计处理是否正确。 | C22: 常规★ | D22: √ | E22: √ | G22: √ | I22: H3-5
A23: 6 | B23: 如存在投资性房地产转换：对于自用房地产或存货转入的投资性房地产，关注转换依据是否充分，检查是否经过有效批准，转换日成本计量是否正确，会计处理是否正确； | C23: 备选 | D23: √ | G23: √ | I23: H3-6
A24: 8 | B24: 以其他方式增加或减少投资性房地产，考虑执行的程序 （1）对于非货币性资产交换、债务重组、企业合并、投资者投入等交易方式取得或减少投资性房地产，检查相关合同/协议，关注计价是否正确、移交手续是否办理以及会计处理是否正确。 （2）对于因清产核资、资产评估调增或调减投资性房地产的，检查有关清产核资报告、资产评估报告、国有资产管理等部门的确认文件、验资报告等，检查会计处理是否正确。 | C24: 备选 | D24: √ | E24: √ | F24: √ | G24: √ | I24: H3-5
A25: 9 | B25: 投资性房地产后续计量选用成本计量模式的，确定投资性房地产累计折旧/摊销政策恰当，重新计算本期折旧/摊销的计提是否正确，分配是否恰当 | C25: 常规★ | G25: √ | I25: H3-7
A26: 10 | B26: 投资性房地产后续计量选用公允价值计量模式的，确定投资性房地产后续计量选用公允价值模式政策恰当，计算复核期末计价正确： （1）询问并获取相关资料，评价被审计单位确定公允价值方法的适当性、公允价值选用的合理性，包括公允价值的确定方法、估值模型的选择、披露的充分性等。检查公允价值的确定依据是否充分，复核公允价值变动计算是否正确，会计处理是否正确； （2）如果需利用专家等工作，应对专家的执业资格和胜任能力、工作结果等进行评价。 | C26: 常规★ | G26: √ | H26: √ | I26: H3-8
A27: 11 | B27: 确定投资性房地产后续计量模式的转换是否恰当： （1）检查董事会等决议文件，确定后续计量模式改变的适当性、会计处理的正确性，并提请被审计单位进行充分披露。 （2）审查投资性房地产成本计量模式转为公允价值计量模式是否作为会计政策变更进行追溯调整期初留存收益处理； | C27: 备选 | G27: √ | H27: √
A28: 12 | B28: 盘点程序： （1）取得公司投资性房地产清单，盘点范围考虑包括本期新增、容易侵占、重要、数量巨大及其他异常等； （2）获取被审计单位对于投资性房地产的盘点计划，制定和实施监盘计划（如有）； （3）取得投资性房地产地点清单，初步确定监盘方式、时间、监盘计划； （4）观察被审计单位制定的盘点程序的执行情况 （5）抽取投资性房地产盘点，并检查投资性房地产的状态（空置、出租、在建、毁损或陈旧等）； （6）评价投资性房地产盘点结果，完成监盘小结。 | C28: 常规★ | D28: √ | F28: √ | G28: √ | I28: H3-9
A29: 13 | B29: 结合投资性房地产清单和盘点程序，了解投资性房地产的状态。针对存在减值迹象的投资性房地产，考虑执行下列程序： 获取被审计单位在资产负债表日就投资性房地产是否可能发生减值迹象的判断的说明，判断其合理性。对于已计提减值准备的投资性房地产，检查减值测试相关参数是否合理，减值准备计提是否正确。对于管理层聘请评估专家出具的评估报告，复核评估报告。 | C29: 常规★ | G29: √ | I29: H3-10 /H3-11
A30: 14 | B30: 检查投资性房地产的所有权或控制权 （1）查看资产权属证明原件，结合银行借款等项目的检查，了解是否存在重大的抵押、担保情况，并取得复印件作为工作底稿； （2）对于正在办理权属证明的大额资产，了解权属证明办理情况，确认是否存在权属纠纷或实质性障碍。 | C30: 常规★ | F30: √ | I30: H3-12
A31: 15 | B31: 检查关联交易情况，检查关联交易的真实性、合理性及合规性；检查关联交易会计处理是否正确，考虑是否存在未识别的关联方，检查关联交易和余额披露是否正确。 | C31: 常规★ | D31: √ | E31: √ | F31: √ | G31: √ | H31: √ | I31: H3-13
A32: 16 | B32: 对于投资性房地产租赁，结合其他业务收入审计考虑执行下列程序： 根据租赁合同/协议等文件，重新计算租金收入，检查投资性房地产的租金收入计算是否正确、会计处理是否正确，租金收人是否计人其他业务收人。 | C32: 常规★ | G32: √ | I32: H3-14
A33: 17 | B33: 根据评估的舞弊风险等因素增加的审计程序。 | C33: IPO/上市/新三板/重组/舞弊应对 | D33: √ | E33: √ | F33: √ | G33: √
A34: 18 | B34: 检查投资性房地产、抵押和担保情况等是否已按企业会计准则或其他适用的规定在财务报表中做出恰当列报和披露 | C34: 常规★ | H34: √ | I34: A 1-1/A1-15 /A1-16

Sheet 审定表（成本模式）H3-1
A1: 致同会计师事务所
A2: =IF(底稿目录!$H$2="公允价值模式","[不适用] 当前企业选择公允价值模式，本页无需填列，请标注不适用。","投资性房地产审定表（成本模式）") -> 投资性房地产审定表（成本模式）
A3: =底稿目录!A2 -> 被审计单位： | D3: =底稿目录!A4 -> 编制人： | F3: =底稿目录!A6 -> 编制日期： | H3: 索引号： | I3: H3-1
A4: =底稿目录!A3 -> 截止日：202X年12月31日 | D4: =底稿目录!A5 -> 复核人： | F4: =底稿目录!A7 -> 复核日期： | H4: 页 次：
A5: 项目 | B5: 期初数 | E5: 期末数 | H5: 本期审定数与上期 审定数的比较
B6: 未审数 | C6: 账项调整 | D6: 审定数 | E6: 未审数 | F6: 账项调整 | G6: 审定数 | H6: 变动额 | I6: 变动率
A7: 一、投资性房地产原值
A8: =底稿目录!A9 -> 房屋、建筑物 | B8: ='明细表（成本模式）H3-2'!C30 -> 0 | C8: ='明细表（成本模式）H3-2'!I30 -> 0 | D8: =B8+C8 -> 0 | E8: ='明细表（成本模式）H3-2'!H30 -> 0 | F8: ='明细表（成本模式）H3-2'!I30+'明细表（成本模式）H3-2'!J30-'明细表（成本模式）H3-2'!K30 -> 0 | G8: ='明细表（成本模式）H3-2'!O30 -> 0 | H8: =G8-D8 -> 0 | I8: =IF(AND(D8=0,H8=0),0,IF(AND(D8=0,H8>0),1,H8/D8)) -> 0
A9: =底稿目录!A10 -> 土地使用权 | B9: ='明细表（成本模式）H3-2'!C31 -> 0 | C9: ='明细表（成本模式）H3-2'!I31 -> 0 | D9: =B9+C9 -> 0 | E9: ='明细表（成本模式）H3-2'!H31 -> 0 | F9: ='明细表（成本模式）H3-2'!I31+'明细表（成本模式）H3-2'!J31-'明细表（成本模式）H3-2'!K31 -> 0 | G9: ='明细表（成本模式）H3-2'!O31 -> 0 | H9: =G9-D9 -> 0 | I9: =IF(AND(D9=0,H9=0),0,IF(AND(D9=0,H9>0),1,H9/D9)) -> 0
A10: =底稿目录!A11 -> 在建工程 | B10: ='明细表（成本模式）H3-2'!C32 -> 0 | C10: ='明细表（成本模式）H3-2'!I32 -> 0 | D10: =B10+C10 -> 0 | E10: ='明细表（成本模式）H3-2'!H32 -> 0 | F10: ='明细表（成本模式）H3-2'!I32+'明细表（成本模式）H3-2'!J32-'明细表（成本模式）H3-2'!K32 -> 0 | G10: ='明细表（成本模式）H3-2'!O32 -> 0 | H10: =G10-D10 -> 0 | I10: =IF(AND(D10=0,H10=0),0,IF(AND(D10=0,H10>0),1,H10/D10)) -> 0
A11: =底稿目录!A12 -> …… | B11: ='明细表（成本模式）H3-2'!C33 -> 0 | C11: ='明细表（成本模式）H3-2'!I33 -> 0 | D11: =B11+C11 -> 0 | E11: ='明细表（成本模式）H3-2'!H33 -> 0 | F11: ='明细表（成本模式）H3-2'!I33+'明细表（成本模式）H3-2'!J33-'明细表（成本模式）H3-2'!K33 -> 0 | G11: ='明细表（成本模式）H3-2'!O33 -> 0 | H11: =G11-D11 -> 0 | I11: =IF(AND(D11=0,H11=0),0,IF(AND(D11=0,H11>0),1,H11/D11)) -> 0
A12: 合计 | B12: =SUM(B8:B11) -> 0 | C12: =SUM(C8:C11) -> 0 | D12: =SUM(D8:D11) -> 0 | E12: =SUM(E8:E11) -> 0 | F12: =SUM(F8:F11) -> 0 | G12: =SUM(G8:G11) -> 0 | H12: =G12-D12 -> 0 | I12: =IF(AND(D12=0,H12=0),0,IF(AND(D12=0,H12>0),1,H12/D12)) -> 0
A13: 二、累计折旧或累计摊销
A14: =A8 -> 房屋、建筑物 | B14: ='明细表（成本模式）H3-2'!P30 -> 0 | C14: ='明细表（成本模式）H3-2'!V30 -> 0 | D14: =B14+C14 -> 0 | E14: ='明细表（成本模式）H3-2'!U30 -> 0 | F14: ='明细表（成本模式）H3-2'!V30+'明细表（成本模式）H3-2'!W30-'明细表（成本模式）H3-2'!X30 -> 0 | G14: =E14+F14 -> 0 | H14: =G14-D14 -> 0 | I14: =IF(AND(D14=0,H14=0),0,IF(AND(D14=0,H14>0),1,H14/D14)) -> 0
A15: =A9 -> 土地使用权 | B15: ='明细表（成本模式）H3-2'!P31 -> 0 | C15: ='明细表（成本模式）H3-2'!V31 -> 0 | D15: =B15+C15 -> 0 | E15: ='明细表（成本模式）H3-2'!U31 -> 0 | F15: ='明细表（成本模式）H3-2'!V31+'明细表（成本模式）H3-2'!W31-'明细表（成本模式）H3-2'!X31 -> 0 | G15: =E15+F15 -> 0 | H15: =G15-D15 -> 0 | I15: =IF(AND(D15=0,H15=0),0,IF(AND(D15=0,H15>0),1,H15/D15)) -> 0
A16: =A10 -> 在建工程 | B16: ='明细表（成本模式）H3-2'!P32 -> 0 | C16: ='明细表（成本模式）H3-2'!V32 -> 0 | D16: =B16+C16 -> 0 | E16: ='明细表（成本模式）H3-2'!U32 -> 0 | F16: ='明细表（成本模式）H3-2'!V32+'明细表（成本模式）H3-2'!W32-'明细表（成本模式）H3-2'!X32 -> 0 | G16: =E16+F16 -> 0 | H16: =G16-D16 -> 0 | I16: =IF(AND(D16=0,H16=0),0,IF(AND(D16=0,H16>0),1,H16/D16)) -> 0
A17: =A11 -> …… | B17: ='明细表（成本模式）H3-2'!P33 -> 0 | C17: ='明细表（成本模式）H3-2'!V33 -> 0 | D17: =B17+C17 -> 0 | E17: ='明细表（成本模式）H3-2'!U33 -> 0 | F17: ='明细表（成本模式）H3-2'!V33+'明细表（成本模式）H3-2'!W33-'明细表（成本模式）H3-2'!X33 -> 0 | G17: =E17+F17 -> 0 | H17: =G17-D17 -> 0 | I17: =IF(AND(D17=0,H17=0),0,IF(AND(D17=0,H17>0),1,H17/D17)) -> 0
A18: 合计 | B18: =SUM(B14:B17) -> 0 | C18: =SUM(C14:C17) -> 0 | D18: =SUM(D14:D17) -> 0 | E18: =SUM(E14:E17) -> 0 | F18: =SUM(F14:F17) -> 0 | G18: =SUM(G14:G17) -> 0 | H18: =SUM(H14:H17) -> 0 | I18: =IF(AND(D18=0,H18=0),0,IF(AND(D18=0,H18>0),1,H18/D18)) -> 0
A19: 三、减值准备
A20: =A14 -> 房屋、建筑物 | B20: ='明细表（成本模式）H3-2'!AC30 -> 0 | C20: ='明细表（成本模式）H3-2'!AI30 -> 0 | D20: =B20+C20 -> 0 | E20: ='明细表（成本模式）H3-2'!AH30 -> 0 | F20: ='明细表（成本模式）H3-2'!AI30+'明细表（成本模式）H3-2'!AJ30-'明细表（成本模式）H3-2'!AK30 -> 0 | G20: =E20+F20 -> 0 | H20: =G20-D20 -> 0 | I20: =IF(AND(D20=0,H20=0),0,IF(AND(D20=0,H20>0),1,H20/D20)) -> 0
A21: =A15 -> 土地使用权 | B21: ='明细表（成本模式）H3-2'!AC31 -> 0 | C21: ='明细表（成本模式）H3-2'!AI31 -> 0 | D21: =B21+C21 -> 0 | E21: ='明细表（成本模式）H3-2'!AH31 -> 0 | F21: ='明细表（成本模式）H3-2'!AI31+'明细表（成本模式）H3-2'!AJ31-'明细表（成本模式）H3-2'!AK31 -> 0 | G21: =E21+F21 -> 0 | H21: =G21-D21 -> 0 | I21: =IF(AND(D21=0,H21=0),0,IF(AND(D21=0,H21>0),1,H21/D21)) -> 0
A22: =A16 -> 在建工程 | B22: ='明细表（成本模式）H3-2'!AC32 -> 0 | C22: ='明细表（成本模式）H3-2'!AI32 -> 0 | D22: =B22+C22 -> 0 | E22: ='明细表（成本模式）H3-2'!AH32 -> 0 | F22: ='明细表（成本模式）H3-2'!AI32+'明细表（成本模式）H3-2'!AJ32-'明细表（成本模式）H3-2'!AK32 -> 0 | G22: =E22+F22 -> 0 | H22: =G22-D22 -> 0 | I22: =IF(AND(D22=0,H22=0),0,IF(AND(D22=0,H22>0),1,H22/D22)) -> 0
A23: =A17 -> …… | B23: ='明细表（成本模式）H3-2'!AC33 -> 0 | C23: ='明细表（成本模式）H3-2'!AI33 -> 0 | D23: =B23+C23 -> 0 | E23: ='明细表（成本模式）H3-2'!AH33 -> 0 | F23: ='明细表（成本模式）H3-2'!AI33+'明细表（成本模式）H3-2'!AJ33-'明细表（成本模式）H3-2'!AK33 -> 0 | G23: =E23+F23 -> 0 | H23: =G23-D23 -> 0 | I23: =IF(AND(D23=0,H23=0),0,IF(AND(D23=0,H23>0),1,H23/D23)) -> 0
A24: 合计 | B24: =SUM(B20:B23) -> 0 | C24: =SUM(C20:C23) -> 0 | D24: =SUM(D20:D23) -> 0 | E24: =SUM(E20:E23) -> 0 | F24: =SUM(F20:F23) -> 0 | G24: =SUM(G20:G23) -> 0 | H24: =SUM(H20:H23) -> 0 | I24: =IF(AND(D24=0,H24=0),0,IF(AND(D24=0,H24>0),1,H24/D24)) -> 0
A25: 四、净值
A26: =A20 -> 房屋、建筑物 | B26: =B8-B14-B20 -> 0 | C26: =C8-C14-C20 -> 0 | D26: =D8-D14-D20 -> 0 | E26: =E8-E14-E20 -> 0 | F26: =F8-F14-F20 -> 0 | G26: =G8-G14-G20 -> 0 | H26: =G26-D26 -> 0 | I26: =IF(AND(D26=0,H26=0),0,IF(AND(D26=0,H26>0),1,H26/D26)) -> 0
A27: =A21 -> 土地使用权 | B27: =B9-B15-B21 -> 0 | C27: =C9-C15-C21 -> 0 | D27: =D9-D15-D21 -> 0 | E27: =E9-E15-E21 -> 0 | F27: =F9-F15-F21 -> 0 | G27: =G9-G15-G21 -> 0 | H27: =G27-D27 -> 0 | I27: =IF(AND(D27=0,H27=0),0,IF(AND(D27=0,H27>0),1,H27/D27)) -> 0
A28: =A22 -> 在建工程 | B28: =B10-B16-B22 -> 0 | C28: =C10-C16-C22 -> 0 | D28: =D10-D16-D22 -> 0 | E28: =E10-E16-E22 -> 0 | F28: =F10-F16-F22 -> 0 | G28: =G10-G16-G22 -> 0 | H28: =G28-D28 -> 0 | I28: =IF(AND(D28=0,H28=0),0,IF(AND(D28=0,H28>0),1,H28/D28)) -> 0
A29: =A23 -> …… | B29: =B11-B17-B23 -> 0 | C29: =C11-C17-C23 -> 0 | D29: =D11-D17-D23 -> 0 | E29: =E11-E17-E23 -> 0 | F29: =F11-F17-F23 -> 0 | G29: =G11-G17-G23 -> 0 | H29: =G29-D29 -> 0 | I29: =IF(AND(D29=0,H29=0),0,IF(AND(D29=0,H29>0),1,H29/D29)) -> 0
A30: 合计 | B30: =SUM(B26:B29) -> 0 | C30: =SUM(C26:C29) -> 0 | D30: =SUM(D26:D29) -> 0 | E30: =SUM(E26:E29) -> 0 | F30: =SUM(F26:F29) -> 0 | G30: =SUM(G26:G29) -> 0 | H30: =SUM(H26:H29) -> 0 | I30: =IF(AND(D30=0,H30=0),0,IF(AND(D30=0,H30>0),1,H30/D30)) -> 0
A31: 试算平衡表数
A32: 差异数 | D32: =D30-D31 -> 0 | G32: =G30-G31 -> 0
A33: 1、审计说明（先判断计量模式：同一企业通常仅选择一种后续计量模式；本页仅适用于成本模式）
A34: （1）投资性房地产期末净值较期初净值增加（负数为减少）：
A35: 主要原因（比例超过30%的）：
A36: 编制逻辑：原值 -> 累计折旧/摊销 -> 减值准备 -> 净值，且净值审定数应与试算平衡表数核对一致。
A37: 交叉核对：成本模式下通常还应结合 H3-2 明细表、H3-7 折旧摊销表、H3-10/11 减值测试底稿检查取数来源。
A38: （2）自用房地产或存货转换为投资性房地产/投资性房地产转换为自用房地产的原因及其影响：
A39: 如本期存在自用房地产/存货与投资性房地产之间转换，应说明转换时点、依据、转换前后计量口径及对折旧、减值、净值的影响。
A41: （3）其他说明：
...

Sheet 审定表（公允价值模式）H3-1
A1: 致同会计师事务所
A2: =IF(底稿目录!$H$2="成本模式","[不适用] 当前企业选择成本模式，本页无需填列，请标注不适用。","投资性房地产审定表（公允价值模式）") -> [不适用] 当前企业选择成本模式，本页无需填列，请标注不适用。
A3: =底稿目录!A2 -> 被审计单位： | D3: =底稿目录!A4 -> 编制人： | F3: =底稿目录!A6 -> 编制日期： | H3: 索引号： | I3: H3-1
A4: =底稿目录!A3 -> 截止日：202X年12月31日 | D4: =底稿目录!A5 -> 复核人： | F4: =底稿目录!A7 -> 复核日期： | H4: 页 次：
A5: 项目 | B5: 期初数 | E5: 期末数 | H5: 本期审定数与上期 审定数的比较
B6: 未审数 | C6: 账项调整 | D6: 审定数 | E6: 未审数 | F6: 账项调整 | G6: 审定数 | H6: 变动额 | I6: 变动率
A7: 一、投资性房地产原值
A8: =底稿目录!A9 -> 房屋、建筑物 | B8: ='明细表（公允价值模式）H3-2'!C29 -> 0 | C8: ='明细表（公允价值模式）H3-2'!I29 -> 0 | D8: =B8+C8 -> 0 | E8: ='明细表（公允价值模式）H3-2'!H29 -> 0 | F8: ='明细表（公允价值模式）H3-2'!I29+'明细表（公允价值模式）H3-2'!J29-'明细表（公允价值模式）H3-2'!K29 -> 0 | G8: =E8+F8 -> 0 | H8: =G8-D8 -> 0 | I8: =IF(AND(D8=0,H8=0),0,IF(AND(D8=0,H8>0),1,H8/D8)) -> 0
A9: =底稿目录!A10 -> 土地使用权 | B9: ='明细表（公允价值模式）H3-2'!C30 -> 0 | C9: ='明细表（公允价值模式）H3-2'!I30 -> 0 | D9: =B9+C9 -> 0 | E9: ='明细表（公允价值模式）H3-2'!H30 -> 0 | F9: ='明细表（公允价值模式）H3-2'!I30+'明细表（公允价值模式）H3-2'!J30-'明细表（公允价值模式）H3-2'!K30 -> 0 | G9: =E9+F9 -> 0 | H9: =G9-D9 -> 0 | I9: =IF(AND(D9=0,H9=0),0,IF(AND(D9=0,H9>0),1,H9/D9)) -> 0
A10: =底稿目录!A11 -> 在建工程 | B10: ='明细表（公允价值模式）H3-2'!C31 -> 0 | C10: ='明细表（公允价值模式）H3-2'!I31 -> 0 | D10: =B10+C10 -> 0 | E10: ='明细表（公允价值模式）H3-2'!H31 -> 0 | F10: ='明细表（公允价值模式）H3-2'!I31+'明细表（公允价值模式）H3-2'!J31-'明细表（公允价值模式）H3-2'!K31 -> 0 | G10: =E10+F10 -> 0 | H10: =G10-D10 -> 0 | I10: =IF(AND(D10=0,H10=0),0,IF(AND(D10=0,H10>0),1,H10/D10)) -> 0
A11: =底稿目录!A12 -> …… | B11: ='明细表（公允价值模式）H3-2'!C32 -> 0 | C11: ='明细表（公允价值模式）H3-2'!I32 -> 0 | D11: =B11+C11 -> 0 | E11: ='明细表（公允价值模式）H3-2'!H32 -> 0 | F11: ='明细表（公允价值模式）H3-2'!I32+'明细表（公允价值模式）H3-2'!J32-'明细表（公允价值模式）H3-2'!K32 -> 0 | G11: =E11+F11 -> 0 | H11: =G11-D11 -> 0 | I11: =IF(AND(D11=0,H11=0),0,IF(AND(D11=0,H11>0),1,H11/D11)) -> 0
A12: 合计 | B12: =SUM(B8:B11) -> 0 | C12: =SUM(C8:C11) -> 0 | D12: =SUM(D8:D11) -> 0 | E12: =SUM(E8:E11) -> 0 | F12: =SUM(F8:F11) -> 0 | G12: =SUM(G8:G11) -> 0 | H12: =G12-D12 -> 0 | I12: =IF(AND(D12=0,H12=0),0,IF(AND(D12=0,H12>0),1,H12/D12)) -> 0
A13: 二、公允价值变动
A14: =A8 -> 房屋、建筑物 | B14: ='明细表（公允价值模式）H3-2'!P29 -> 0 | C14: ='明细表（公允价值模式）H3-2'!S29 -> 0 | D14: =B14+C14 -> 0 | E14: ='明细表（公允价值模式）H3-2'!R29 -> 0 | F14: ='明细表（公允价值模式）H3-2'!S29+'明细表（公允价值模式）H3-2'!T29 -> 0 | G14: =E14+F14 -> 0 | H14: =G14-D14 -> 0 | I14: =IF(AND(D14=0,H14=0),0,IF(AND(D14=0,H14>0),1,H14/D14)) -> 0
A15: =A9 -> 土地使用权 | B15: ='明细表（公允价值模式）H3-2'!P30 -> 0 | C15: ='明细表（公允价值模式）H3-2'!S30 -> 0 | D15: =B15+C15 -> 0 | E15: ='明细表（公允价值模式）H3-2'!R30 -> 0 | F15: ='明细表（公允价值模式）H3-2'!S30+'明细表（公允价值模式）H3-2'!T30 -> 0 | G15: =E15+F15 -> 0 | H15: =G15-D15 -> 0 | I15: =IF(AND(D15=0,H15=0),0,IF(AND(D15=0,H15>0),1,H15/D15)) -> 0
A16: =A10 -> 在建工程 | B16: ='明细表（公允价值模式）H3-2'!P31 -> 0 | C16: ='明细表（公允价值模式）H3-2'!S31 -> 0 | D16: =B16+C16 -> 0 | E16: ='明细表（公允价值模式）H3-2'!R31 -> 0 | F16: ='明细表（公允价值模式）H3-2'!S31+'明细表（公允价值模式）H3-2'!T31 -> 0 | G16: =E16+F16 -> 0 | H16: =G16-D16 -> 0 | I16: =IF(AND(D16=0,H16=0),0,IF(AND(D16=0,H16>0),1,H16/D16)) -> 0
A17: =A11 -> …… | B17: ='明细表（公允价值模式）H3-2'!P32 -> 0 | C17: ='明细表（公允价值模式）H3-2'!S32 -> 0 | D17: =B17+C17 -> 0 | E17: ='明细表（公允价值模式）H3-2'!R32 -> 0 | F17: ='明细表（公允价值模式）H3-2'!S32+'明细表（公允价值模式）H3-2'!T32 -> 0 | G17: =E17+F17 -> 0 | H17: =G17-D17 -> 0 | I17: =IF(AND(D17=0,H17=0),0,IF(AND(D17=0,H17>0),1,H17/D17)) -> 0
A18: 合计 | B18: =SUM(B14:B17) -> 0 | C18: =SUM(C14:C17) -> 0 | D18: =SUM(D14:D17) -> 0 | E18: =SUM(E14:E17) -> 0 | F18: =SUM(F14:F17) -> 0 | G18: =SUM(G14:G17) -> 0 | H18: =G18-D18 -> 0 | I18: =IF(AND(D18=0,H18=0),0,IF(AND(D18=0,H18>0),1,H18/D18)) -> 0
A19: 三、净值
A20: =A8 -> 房屋、建筑物 | B20: =B8+B14 -> 0 | C20: =C8+C14 -> 0 | D20: =D8+D14 -> 0 | E20: =E8+E14 -> 0 | F20: =F8+F14 -> 0 | G20: =G8+G14 -> 0 | H20: =G20-D20 -> 0 | I20: =IF(AND(D20=0,H20=0),0,IF(AND(D20=0,H20>0),1,H20/D20)) -> 0
A21: =A9 -> 土地使用权 | B21: =B9+B15 -> 0 | C21: =C9+C15 -> 0 | D21: =D9+D15 -> 0 | E21: =E9+E15 -> 0 | F21: =F9+F15 -> 0 | G21: =G9+G15 -> 0 | H21: =G21-D21 -> 0 | I21: =IF(AND(D21=0,H21=0),0,IF(AND(D21=0,H21>0),1,H21/D21)) -> 0
A22: =A10 -> 在建工程 | B22: =B10+B16 -> 0 | C22: =C10+C16 -> 0 | D22: =D10+D16 -> 0 | E22: =E10+E16 -> 0 | F22: =F10+F16 -> 0 | G22: =G10+G16 -> 0 | H22: =G22-D22 -> 0 | I22: =IF(AND(D22=0,H22=0),0,IF(AND(D22=0,H22>0),1,H22/D22)) -> 0
A23: =A11 -> …… | B23: =B11+B17 -> 0 | C23: =C11+C17 -> 0 | D23: =D11+D17 -> 0 | E23: =E11+E17 -> 0 | F23: =F11+F17 -> 0 | G23: =G11+G17 -> 0 | H23: =G23-D23 -> 0 | I23: =IF(AND(D23=0,H23=0),0,IF(AND(D23=0,H23>0),1,H23/D23)) -> 0
A24: 合计 | B24: =SUM(B20:B23) -> 0 | C24: =SUM(C20:C23) -> 0 | D24: =SUM(D20:D23) -> 0 | E24: =SUM(E20:E23) -> 0 | F24: =SUM(F20:F23) -> 0 | G24: =SUM(G20:G23) -> 0 | H24: =SUM(H20:H23) -> 0 | I24: =IF(AND(D24=0,H24=0),0,IF(AND(D24=0,H24>0),1,H24/D24)) -> 0
A25: 试算平衡表数
A26: 差异数 | D26: =D24-D25 -> 0 | G26: =G24-G25 -> 0
A27: 1、审计说明：
A28: （1）投资性房地产期末账面价值较期初账面价值增加（负数为减少）：
A29: 主要原因（比例超过30%的）：
A31: 编制提示：本页仅适用于公允价值模式；若企业采用成本模式，本页应标注“不适用”，不应与成本模式审定表同时作为有效底稿。
A32: （2）投资性房地产公允价值的确定依据及公允价值金额的增减变动情况说明：
A33: 重点说明：估值方法、关键假设、第三方评估机构或市场依据，以及本期公允价值变动计入损益的原因。
A34: 编制逻辑：原值 + 公允价值变动 = 净值；公允价值模式下一般不再单独计提折旧/摊销和减值准备。
A35: （3）自用房地产或存货转换为投资性房地产/投资性房地产转换为自用房地产的原因及其影响：
A36: 交叉核对：公允价值模式下应重点结合 H3-2 明细表、附注披露信息及评估/市场证据核对期末净值与公允价值变动。
A38: （4）其他说明（如模式变更、估值层次变化、关键参数敏感性、与财报披露不一致事项等）：
A40: 2、审计结论（核对模式选择、公允价值依据及损益影响后填写）

Sheet 附注披露信息（上市公司）
A1: 致同会计师事务所
A2: 附注披露信息（上市公司）
A3: =底稿目录!A2 -> 被审计单位： | B3: =底稿目录!A4 -> 编制人： | C3: =底稿目录!A6 -> 编制日期： | E3: 索引号： | F3: 返回目录
A4: =底稿目录!A3 -> 截止日：202X年12月31日 | B4: =底稿目录!A5 -> 复核人： | C4: =底稿目录!A7 -> 复核日期： | E4: 页 次：
A6: 21、投资性房地产
A7: （1）按成本计量的投资性房地产（如无以公允价值计量的投资性房地产，删除此标题）
A8: 项 目 | B8: 房屋、建筑物 | C8: 土地使用权 | D8: 在建工程 | E8: 合计
A9: 一、账面原值
A10: 1.期初余额
A11: 2.本期增加金额
A12: （1）外购
A13: （2）存货\固定资产\在建工程转入
A14: （3）企业合并增加
A15: 可无限量添加行
A16: 3.本期减少金额
A17: （1）处置
A18: （2）其他转出
A19: 可无限量添加行
A20: 4.期末余额
... A52: （采用公允价值计量模式的投资性房地产，分类列示期初余额、期末余额和本期增减变动情况。）
A53: 项 目 | B53: 房屋、建筑物 | C53: 土地使用权 | D53: 在建工程 | E53: 合计
A54: 一、期初余额
A55: 二、本期变动
A56: 加：外购
A57: 存货\固定资产\在建工程转入
A58: 企业合并增加
A59: 减：处置
A60: 其他转出
A61: 公允价值变动
A63: 三、期末余额
A65: （3）未办妥产权证书的情况
A66: （披露未办妥产权证书的投资性房地产账面价值及原因。）
A67: 项 目 | B67: 账面价值 | C67: 未办妥产权证书原因
A68: 可无限量添加行
A71: （4）房地产转换情况及改变计量模式的情况
A72: （说明报告期内房地产转换或改变计量模式的情况、理由，以及对损益或所有者权益的影响。
A73: 对于转换为投资性房地产并采用公允价值计量模式的，应披露转换的理由、审批程序，以及对损益、其他综合收益的影响。（15号文第十九条（十二）
A74: 房地产开发企业列示出租开发产品时，应披露出租开发产品的成本、租赁合同主要条款等内容。对重要的出租房产应单项披露，非重要或零星的出租房产可采用合并披露。）

Sheet 附注披露信息（国有企业）
A1: 致同会计师事务所
A2: 附注披露信息（国有企业）
A3: =底稿目录!A2 -> 被审计单位： | C3: =底稿目录!A4 -> 编制人： | E3: =底稿目录!A6 -> 编制日期： | H3: 索引号： | I3: 返回目录
A4: =底稿目录!A3 -> 截止日：202X年12月31日 | C4: =底稿目录!A5 -> 复核人： | E4: =底稿目录!A7 -> 复核日期： | H4: 页 次：
A6: 21、投资性房地产
A7: （1）以成本计量（如无按公允价值计量的投资性房地产，删除此标题）
A8: 项 目 | B8: 期初余额 | C8: 本期增加 | E8: 本期减少 | G8: 期末余额
C9: 购置或 | D9: 自用房地产或存货转入 | E9: 处 置 | F9: 转为自用房地产
C10: 计提
A11: 一、账面原值合计 | B11: X.XX | C11: X.XX | D11: X.XX | E11: X.XX | F11: X.XX | G11: X.XX
A12: 1、房屋、建筑物
A13: 2、土地使用权
A14: 二、累计折旧和累计摊销合计 | B14: X.XX | C14: X.XX | D14: X.XX | E14: X.XX | F14: X.XX | G14: X.XX
A15: 1、房屋、建筑物
A16: 2、土地使用权
A17: 三、投资性房地产账面净值合计 | B17: X.XX | C17: X.XX | D17: X.XX | E17: X.XX | F17: X.XX | G17: X.XX
A18: 1、房屋、建筑物
A19: 2、土地使用权
A20: 四、投资性房地产减值准备累计金额合计 | B20: X.XX | C20: X.XX | D20: X.XX | E20: X.XX | F20: X.XX | G20: X.XX
A21: 1、房屋、建筑物
A22: 2、土地使用权
A23: 五、投资性房地产账面价值合计 | B23: X.XX | C23: X.XX | D23: X.XX | E23: X.XX | F23: X.XX | G23: X.XX
A24: 1、房屋、建筑物
A25: 2、土地使用权
A26: ① 本期折旧和摊销额XX元。
A27: ② 投资性房地产本期减值准备计提额XX元。
A28: （2）以公允价值计量（不适用的删除）
A29: 项 目 | B29: 期初公允价值 | C29: 本期增加 | F29: 本期减少 | H29: 期末公允价值
C30: 购置 | D30: 自用房地产或存货转入 | E30: 公允价值变动损益 | F30: 处 置 | G30: 转为自用房地产
A31: 一、成本合计 | B31: X.XX | C31: X.XX | D31: X.XX | E31: X.XX | F31: X.XX | G31: X.XX | H31: X.XX
A32: 其中：1、房屋、建筑物
A33: 2、土地使用权
A34: 二、公允价值变动合计 | B34: X.XX | C34: X.XX | D34: X.XX | E34: X.XX | F34: X.XX | G34: X.XX | H34: X.XX
A35: 其中：1、房屋、建筑物
A36: 2、土地使用权
A37: 三、投资性房地产账面价值合计 | B37: X.XX | C37: X.XX | D37: X.XX | E37: X.XX | F37: X.XX | G37: X.XX | H37: X.XX
A38: 其中：1、房屋、建筑物
A39: 2、土地使用权
A40: （注：①应披露公允价值确认依据。②说明报告期内改变计量模式的投资性房地产转换的原因及其影响。）
A41: （3）未办妥产权证书的投资性房地产
...

Sheet 明细表（成本模式）H3-2
A1: 致同会计师事务所 | P1: 致同会计师事务所 | AC1: 致同会计师事务所
A2: 投资性房地产明细表（成本模式） | P2: 投资性房地产明细表（成本模式） | AC2: 投资性房地产明细表（成本模式）
A3: =底稿目录!A2 -> 被审计单位： | G3: =底稿目录!A4 -> 编制人： | K3: =底稿目录!A6 -> 编制日期： | N3: 索引号： | O3: H3-2 | P3: =底稿目录!A2 -> 被审计单位： | U3: =底稿目录!A4 -> 编制人： | X3: =底稿目录!A6 -> 编制日期： | AA3: 索引号： | AB3: H3-2 | AC3: =底稿目录!A2 -> 被审计单位： | AI3: =底稿目录!A4 -> 编制人： | AM3: =底稿目录!A6 -> 编制日期： | AR3: 索引号： | AS3: H3-2
A4: =底稿目录!A3 -> 截止日：202X年12月31日 | G4: =底稿目录!A5 -> 复核人： | K4: =底稿目录!A7 -> 复核日期： | N4: 页 次： | P4: =底稿目录!A3 -> 截止日：202X年12月31日 | U4: =底稿目录!A5 -> 复核人： | X4: =底稿目录!A7 -> 复核日期： | AA4: 页 次： | AC4: =底稿目录!A3 -> 截止日：202X年12月31日 | AI4: =底稿目录!A5 -> 复核人： | AM4: =底稿目录!A7 -> 复核日期： | AR4: 页 次：
A5: 一、审计目标：
A6: 1. 资产负债表中记录的投资性房地产是存在的，且已记录于恰当的账户；2. 所有应记录的投资性房地产均已记录，所有应当包括在财务报表中的相关披露均已包括；
A7: 3.投资性房地产以恰当的金额包括在财务报表中，与之相关的计价或分摊调整已恰当记录，相关披露已得到恰当计量和描述
A8: 二、审计过程：
A9: 投资性房地产类别 | B9: 投资性房地产名称 | C9: 投资性房地产原值 | P9: 累计折旧/累计摊销 | AC9: 减值准备 | AP9: 期初净值 | AQ9: 期末净值 | AR9: 是否有权属证明 | AS9: 是否抵押受限
C10: 未审数 | I10: 期初调整 | J10: 账项调整 | L10: 审定数 | P10: 未审数 | V10: 期初调整 | W10: 账项调整 | Y10: 审定数 | AC10: 未审数 | AI10: 期初调整 | AJ10: 账项调整 | AL10: 审定数
C11: 期初余额 | D11: 本年增加 | E11: 增加方式 | F11: 本年减少 | G11: 减少方式 | H11: 期末余额 | J11: 本期增加 | K11: 本期减少 | L11: 期初余额 | M11: 本年增加 | N11: 本年减少 | O11: 期末余额 | P11: 期初余额 | Q11: 本年增加 | R11: 增加方式 | S11: 本年减少 | T11: 减少方式 | U11: 期末余额 | W11: 本期增加 | X11: 本期减少 | Y11: 期初余额 | Z11: 本年增加 | AA11: 本年减少 | AB11: 期末余额 | AC11: 期初余额 | AD11: 本年增加 | AE11: 增加方式 | AF11: 本年减少 | AG11: 减少方式 | AH11: 期末余额 | AJ11: 本期增加 | AK11: 本期减少 | AL11: 期初余额 | AM11: 本年增加 | AN11: 本年减少 | AO11: 期末余额
A13: 房屋、建筑物 | H13: =C13+D13-F13 -> 0 | L13: =C13+I13 -> 0 | M13: =D13+J13 -> 0 | N13: =F13+K13 -> 0 | O13: =L13+M13-N13 -> 0 | U13: =P13+Q13-S13 -> 0 | Y13: =P13+V13 -> 0 | Z13: =Q13+W13 -> 0 | AA13: =S13+X13 -> 0 | AB13: =Y13+Z13-AA13 -> 0 | AH13: =AC13+AD13-AF13 -> 0 | AL13: =AC13+AI13 -> 0 | AM13: =AD13+AJ13 -> 0 | AN13: =AF13+AK13 -> 0 | AO13: =AL13+AM13-AN13 -> 0 | AP13: =L13-Y13-AL13 -> 0 | AQ13: =O13-AB13-AO13 -> 0
A14: 房屋、建筑物 | H14: =C14+D14-F14 -> 0 | L14: =C14+I14 -> 0 | M14: =D14+J14 -> 0 | N14: =F14+K14 -> 0 | O14: =L14+M14-N14 -> 0 | U14: =P14+Q14-S14 -> 0 | Y14: =P14+V14 -> 0 | Z14: =Q14+W14 -> 0 | AA14: =S14+X14 -> 0 | AB14: =Y14+Z14-AA14 -> 0 | AH14: =AC14+AD14-AF14 -> 0 | AL14: =AC14+AI14 -> 0 | AM14: =AD14+AJ14 -> 0 | AN14: =AF14+AK14 -> 0 | AO14: =AL14+AM14-AN14 -> 0 | AP14: =L14-Y14-AL14 -> 0 | AQ14: =O14-AB14-AO14 -> 0
A15: 房屋、建筑物 | H15: =C15+D15-F15 -> 0 | L15: =C15+I15 -> 0 | M15: =D15+J15 -> 0 | N15: =F15+K15 -> 0 | O15: =L15+M15-N15 -> 0 | U15: =P15+Q15-S15 -> 0 | Y15: =P15+V15 -> 0 | Z15: =Q15+W15 -> 0 | AA15: =S15+X15 -> 0 | AB15: =Y15+Z15-AA15 -> 0 | AH15: =AC15+AD15-AF15 -> 0 | AL15: =AC15+AI15 -> 0 | AM15: =AD15+AJ15 -> 0 | AN15: =AF15+AK15 -> 0 | AO15: =AL15+AM15-AN15 -> 0 | AP15: =L15-Y15-AL15 -> 0 | AQ15: =O15-AB15-AO15 -> 0
A16: 房屋、建筑物 | H16: =C16+D16-F16 -> 0 | L16: =C16+I16 -> 0 | M16: =D16+J16 -> 0 | N16: =F16+K16 -> 0 | O16: =L16+M16-N16 -> 0 | U16: =P16+Q16-S16 -> 0 | Y16: =P16+V16 -> 0 | Z16: =Q16+W16 -> 0 | AA16: =S16+X16 -> 0 | AB16: =Y16+Z16-AA16 -> 0 | AH16: =AC16+AD16-AF16 -> 0 | AL16: =AC16+AI16 -> 0 | AM16: =AD16+AJ16 -> 0 | AN16: =AF16+AK16 -> 0 | AO16: =AL16+AM16-AN16 -> 0 | AP16: =L16-Y16-AL16 -> 0 | AQ16: =O16-AB16-AO16 -> 0
A17: 房屋、建筑物 | H17: =C17+D17-F17 -> 0 | L17: =C17+I17 -> 0 | M17: =D17+J17 -> 0 | N17: =F17+K17 -> 0 | O17: =L17+M17-N17 -> 0 | U17: =P17+Q17-S17 -> 0 | Y17: =P17+V17 -> 0 | Z17: =Q17+W17 -> 0 | AA17: =S17+X17 -> 0 | AB17: =Y17+Z17-AA17 -> 0 | AH17: =AC17+AD17-AF17 -> 0 | AL17: =AC17+AI17 -> 0 | AM17: =AD17+AJ17 -> 0 | AN17: =AF17+AK17 -> 0 | AO17: =AL17+AM17-AN17 -> 0 | AP17: =L17-Y17-AL17 -> 0 | AQ17: =O17-AB17-AO17 -> 0
A18: 房屋、建筑物 | H18: =C18+D18-F18 -> 0 | L18: =C18+I18 -> 0 | M18: =D18+J18 -> 0 | N18: =F18+K18 -> 0 | O18: =L18+M18-N18 -> 0 | U18: =P18+Q18-S18 -> 0 | Y18: =P18+V18 -> 0 | Z18: =Q18+W18 -> 0 | AA18: =S18+X18 -> 0 | AB18: =Y18+Z18-AA18 -> 0 | AH18: =AC18+AD18-AF18 -> 0 | AL18: =AC18+AI18 -> 0 | AM18: =AD18+AJ18 -> 0 | AN18: =AF18+AK18 -> 0 | AO18: =AL18+AM18-AN18 -> 0 | AP18: =L18-Y18-AL18 -> 0 | AQ18: =O18-AB18-AO18 -> 0
A19: 房屋、建筑物 | H19: =C19+D19-F19 -> 0 | L19: =C19+I19 -> 0 | M19: =D19+J19 -> 0 | N19: =F19+K19 -> 0 | O19: =L19+M19-N19 -> 0 | U19: =P19+Q19-S19 -> 0 | Y19: =P19+V19 -> 0 | Z19: =Q19+W19 -> 0 | AA19: =S19+X19 -> 0 | AB19: =Y19+Z19-AA19 -> 0 | AH19: =AC19+AD19-AF19 -> 0 | AL19: =AC19+AI19 -> 0 | AM19: =AD19+AJ19 -> 0 | AN19: =AF19+AK19 -> 0 | AO19: =AL19+AM19-AN19 -> 0 | AP19: =L19-Y19-AL19 -> 0 | AQ19: =O19-AB19-AO19 -> 0
A20: 房屋、建筑物 | H20: =C20+D20-F20 -> 0 | L20: =C20+I20 -> 0 | M20: =D20+J20 -> 0 | N20: =F20+K20 -> 0 | O20: =L20+M20-N20 -> 0 | U20: =P20+Q20-S20 -> 0 | Y20: =P20+V20 -> 0 | Z20: =Q20+W20 -> 0 | AA20: =S20+X20 -> 0 | AB20: =Y20+Z20-AA20 -> 0 | AH20: =AC20+AD20-AF20 -> 0 | AL20: =AC20+AI20 -> 0 | AM20: =AD20+AJ20 -> 0 | AN20: =AF20+AK20 -> 0 | AO20: =AL20+AM20-AN20 -> 0 | AP20: =L20-Y20-AL20 -> 0 | AQ20: =O20-AB20-AO20 -> 0
A21: 土地使用权 | H21: =C21+D21-F21 -> 0 | L21: =C21+I21 -> 0 | M21: =D21+J21 -> 0 | N21: =F21+K21 -> 0 | O21: =L21+M21-N21 -> 0 | U21: =P21+Q21-S21 -> 0 | Y21: =P21+V21 -> 0 | Z21: =Q21+W21 -> 0 | AA21: =S21+X21 -> 0 | AB21: =Y21+Z21-AA21 -> 0 | AH21: =AC21+AD21-AF21 -> 0 | AL21: =AC21+AI21 -> 0 | AM21: =AD21+AJ21 -> 0 | AN21: =AF21+AK21 -> 0 | AO21: =AL21+AM21-AN21 -> 0 | AP21: =L21-Y21-AL21 -> 0 | AQ21: =O21-AB21-AO21 -> 0
A22: 土地使用权 | H22: =C22+D22-F22 -> 0 | L22: =C22+I22 -> 0 | M22: =D22+J22 -> 0 | N22: =F22+K22 -> 0 | O22: =L22+M22-N22 -> 0 | U22: =P22+Q22-S22 -> 0 | Y22: =P22+V22 -> 0 | Z22: =Q22+W22 -> 0 | AA22: =S22+X22 -> 0 | AB22: =Y22+Z22-AA22 -> 0 | AH22: =AC22+AD22-AF22 -> 0 | AL22: =AC22+AI22 -> 0 | AM22: =AD22+AJ22 -> 0 | AN22: =AF22+AK22 -> 0 | AO22: =AL22+AM22-AN22 -> 0 | AP22: =L22-Y22-AL22 -> 0 | AQ22: =O22-AB22-AO22 -> 0
A23: 土地使用权 | H23: =C23+D23-F23 -> 0 | L23: =C23+I23 -> 0 | M23: =D23+J23 -> 0 | N23: =F23+K23 -> 0 | O23: =L23+M23-N23 -> 0 | U23: =P23+Q23-S23 -> 0 | Y23: =P23+V23 -> 0 | Z23: =Q23+W23 -> 0 | AA23: =S23+X23 -> 0 | AB23: =Y23+Z23-AA23 -> 0 | AH23: =AC23+AD23-AF23 -> 0 | AL23: =AC23+AI23 -> 0 | AM23: =AD23+AJ23 -> 0 | AN23: =AF23+AK23 -> 0 | AO23: =AL23+AM23-AN23 -> 0 | AP23: =L23-Y23-AL23 -> 0 | AQ23: =O23-AB23-AO23 -> 0
A24: 在建工程 | H24: =C24+D24-F24 -> 0 | L24: =C24+I24 -> 0 | M24: =D24+J24 -> 0 | N24: =F24+K24 -> 0 | O24: =L24+M24-N24 -> 0 | U24: =P24+Q24-S24 -> 0 | Y24: =P24+V24 -> 0 | Z24: =Q24+W24 -> 0 | AA24: =S24+X24 -> 0 | AB24: =Y24+Z24-AA24 -> 0 | AH24: =AC24+AD24-AF24 -> 0 | AL24: =AC24+AI24 -> 0 | AM24: =AD24+AJ24 -> 0 | AN24: =AF24+AK24 -> 0 | AO24: =AL24+AM24-AN24 -> 0 | AP24: =L24-Y24-AL24 -> 0 | AQ24: =O24-AB24-AO24 -> 0
... A27: 在建工程 | H27: =C27+D27-F27 -> 0 | L27: =C27+I27 -> 0 | M27: =D27+J27 -> 0 | N27: =F27+K27 -> 0 | O27: =L27+M27-N27 -> 0 | U27: =P27+Q27-S27 -> 0 | Y27: =P27+V27 -> 0 | Z27: =Q27+W27 -> 0 | AA27: =S27+X27 -> 0 | AB27: =Y27+Z27-AA27 -> 0 | AH27: =AC27+AD27-AF27 -> 0 | AL27: =AC27+AI27 -> 0 | AM27: =AD27+AJ27 -> 0 | AN27: =AF27+AK27 -> 0 | AO27: =AL27+AM27-AN27 -> 0 | AP27: =L27-Y27-AL27 -> 0 | AQ27: =O27-AB27-AO27 -> 0
A28: 合计 | C28: =SUM(C13:C27) -> 0 | D28: =SUM(D13:D27) -> 0 | E28: =SUM(E13:E27) -> 0 | F28: =SUM(F13:F27) -> 0 | G28: =SUM(G13:G27) -> 0 | H28: =SUM(H13:H27) -> 0 | I28: =SUM(I13:I27) -> 0 | J28: =SUM(J13:J27) -> 0 | ... AQ28: =SUM(AQ13:AQ27) -> 0
A29: 其中：
A30: =底稿目录!A9 -> 房屋、建筑物 | C30: =SUMPRODUCT(($A$13:$A$27=$A30)*(C$13:C$27)) -> 0 | D30: =SUMPRODUCT(($A$13:$A$27=$A30)*(D$13:D$27)) -> 0 | F30: =SUMPRODUCT(($A$13:$A$27=$A30)*(F$13:F$27)) -> 0 | H30: =SUMPRODUCT(($A$13:$A$27=$A30)*(H$13:H$27)) -> 0 | I30: =SUMPRODUCT(($A$13:$A$27=$A30)*(I$13:I$27)) -> 0 | J30: =SUMPRODUCT(($A$13:$A$27=$A30)*(J$13:J$27)) -> 0 | K30: =SUMPRODUCT(($A$13:$A$27=$A30)*(K$13:K$27)) -> 0 | L30: =SUMPRODUCT(($A$13:$A$27=$A30)*(L$13:L$27)) -> 0 | M30: =SUMPRODUCT(($A$13:$A$27=$A30)*(M$13:M$27)) -> 0 | N30: =SUMPRODUCT(($A$13:$A$27=$A30)*(N$13:N$27)) -> 0 | O30: =SUMPRODUCT(($A$13:$A$27=$A30)*(O$13:O$27)) -> 0 | ... Q30: =SUMPRODUCT(($A$13:$A$27=$A30)*(Q$13:Q$27)) -> 0 | S30: =SUMPRODUCT(($A$13:$A$27=$A30)*(S$13:S$27)) -> 0 | U30: =SUMPRODUCT(($A$13:$A$27=$A30)*(U$13:U$27)) -> 0 | V30: =SUMPRODUCT(($A$13:$A$27=$A30)*(V$13:V$27)) -> 0 | W30: =SUMPRODUCT(($A$13:$A$27=$A30)*(W$13:W$27)) -> 0 | X30: =SUMPRODUCT(($A$13:$A$27=$A30)*(X$13:X$27)) -> 0 | Y30: =SUMPRODUCT(($A$13:$A$27=$A30)*(Y$13:Y$27)) -> 0 | Z30: =SUMPRODUCT(($A$13:$A$27=$A30)*(Z$13:Z$27)) -> 0 | AA30: =SUMPRODUCT(($A$13:$A$27=$A30)*(AA$13:AA$27)) -> 0 | AB30: =SUMPRODUCT(($A$13:$A$27=$A30)*(AB$13:AB$27)) -> 0 | ... AD30: =SUMPRODUCT(($A$13:$A$27=$A30)*(AD$13:AD$27)) -> 0 | AF30: =SUMPRODUCT(($A$13:$A$27=$A30)*(AF$13:AF$27)) -> 0 | AH30: =SUMPRODUCT(($A$13:$A$27=$A30)*(AH$13:AH$27)) -> 0 | AI30: =SUMPRODUCT(($A$13:$A$27=$A30)*(AI$13:AI$27)) -> 0 | AJ30: =SUMPRODUCT(($A$13:$A$27=$A30)*(AJ$13:AJ$27)) -> 0 | AK30: =SUMPRODUCT(($A$13:$A$27=$A30)*(AK$13:AK$27)) -> 0 | AL30: =SUMPRODUCT(($A$13:$A$27=$A30)*(AL$13:AL$27)) -> 0 | AM30: =SUMPRODUCT(($A$13:$A$27=$A30)*(AM$13:AM$27)) -> 0 | AN30: =SUMPRODUCT(($A$13:$A$27=$A30)*(AN$13:AN$27)) -> 0 | AO30: =SUMPRODUCT(($A$13:$A$27=$A30)*(AO$13:AO$27)) -> 0 | ... AQ30: =SUMPRODUCT(($A$13:$A$27=$A30)*(AQ$13:AQ$27)) -> 0
A31: =底稿目录!A10 -> 土地使用权 | C31: =SUMPRODUCT(($A$13:$A$27=$A31)*(C$13:C$27)) -> 0 | D31: =SUMPRODUCT(($A$13:$A$27=$A31)*(D$13:D$27)) -> 0 | F31: =SUMPRODUCT(($A$13:$A$27=$A31)*(F$13:F$27)) -> 0 | H31: =SUMPRODUCT(($A$13:$A$27=$A31)*(H$13:H$27)) -> 0 | I31: =SUMPRODUCT(($A$13:$A$27=$A31)*(I$13:I$27)) -> 0 | J31: =SUMPRODUCT(($A$13:$A$27=$A31)*(J$13:J$27)) -> 0 | K31: =SUMPRODUCT(($A$13:$A$27=$A31)*(K$13:K$27)) -> 0 | L31: =SUMPRODUCT(($A$13:$A$27=$A31)*(L$13:L$27)) -> 0 | M31: =SUMPRODUCT(($A$13:$A$27=$A31)*(M$13:M$27)) -> 0 | N31: =SUMPRODUCT(($A$13:$A$27=$A31)*(N$13:N$27)) -> 0 | O31: =SUMPRODUCT(($A$13:$A$27=$A31)*(O$13:O$27)) -> 0 | ... Q31: =SUMPRODUCT(($A$13:$A$27=$A31)*(Q$13:Q$27)) -> 0 | S31: =SUMPRODUCT(($A$13:$A$27=$A31)*(S$13:S$27)) -> 0 | U31: =SUMPRODUCT(($A$13:$A$27=$A31)*(U$13:U$27)) -> 0 | V31: =SUMPRODUCT(($A$13:$A$27=$A31)*(V$13:V$27)) -> 0 | W31: =SUMPRODUCT(($A$13:$A$27=$A31)*(W$13:W$27)) -> 0 | X31: =SUMPRODUCT(($A$13:$A$27=$A31)*(X$13:X$27)) -> 0 | Y31: =SUMPRODUCT(($A$13:$A$27=$A31)*(Y$13:Y$27)) -> 0 | Z31: =SUMPRODUCT(($A$13:$A$27=$A31)*(Z$13:Z$27)) -> 0 | AA31: =SUMPRODUCT(($A$13:$A$27=$A31)*(AA$13:AA$27)) -> 0 | AB31: =SUMPRODUCT(($A$13:$A$27=$A31)*(AB$13:AB$27)) -> 0 | ... AD31: =SUMPRODUCT(($A$13:$A$27=$A31)*(AD$13:AD$27)) -> 0 | AF31: =SUMPRODUCT(($A$13:$A$27=$A31)*(AF$13:AF$27)) -> 0 | AH31: =SUMPRODUCT(($A$13:$A$27=$A31)*(AH$13:AH$27)) -> 0 | AI31: =SUMPRODUCT(($A$13:$A$27=$A31)*(AI$13:AI$27)) -> 0 | AJ31: =SUMPRODUCT(($A$13:$A$27=$A31)*(AJ$13:AJ$27)) -> 0 | AK31: =SUMPRODUCT(($A$13:$A$27=$A31)*(AK$13:AK$27)) -> 0 | AL31: =SUMPRODUCT(($A$13:$A$27=$A31)*(AL$13:AL$27)) -> 0 | AM31: =SUMPRODUCT(($A$13:$A$27=$A31)*(AM$13:AM$27)) -> 0 | AN31: =SUMPRODUCT(($A$13:$A$27=$A31)*(AN$13:AN$27)) -> 0 | AO31: =SUMPRODUCT(($A$13:$A$27=$A31)*(AO$13:AO$27)) -> 0 | ... AQ31: =SUMPRODUCT(($A$13:$A$27=$A31)*(AQ$13:AQ$27)) -> 0
A32: =底稿目录!A11 -> 在建工程 | C32: =SUMPRODUCT(($A$13:$A$27=$A32)*(C$13:C$27)) -> 0 | D32: =SUMPRODUCT(($A$13:$A$27=$A32)*(D$13:D$27)) -> 0 | F32: =SUMPRODUCT(($A$13:$A$27=$A32)*(F$13:F$27)) -> 0 | H32: =SUMPRODUCT(($A$13:$A$27=$A32)*(H$13:H$27)) -> 0 | I32: =SUMPRODUCT(($A$13:$A$27=$A32)*(I$13:I$27)) -> 0 | J32: =SUMPRODUCT(($A$13:$A$27=$A32)*(J$13:J$27)) -> 0 | K32: =SUMPRODUCT(($A$13:$A$27=$A32)*(K$13:K$27)) -> 0 | L32: =SUMPRODUCT(($A$13:$A$27=$A32)*(L$13:L$27)) -> 0 | M32: =SUMPRODUCT(($A$13:$A$27=$A32)*(M$13:M$27)) -> 0 | N32: =SUMPRODUCT(($A$13:$A$27=$A32)*(N$13:N$27)) -> 0 | O32: =SUMPRODUCT(($A$13:$A$27=$A32)*(O$13:O$27)) -> 0 | ... Q32: =SUMPRODUCT(($A$13:$A$27=$A32)*(Q$13:Q$27)) -> 0 | S32: =SUMPRODUCT(($A$13:$A$27=$A32)*(S$13:S$27)) -> 0 | U32: =SUMPRODUCT(($A$13:$A$27=$A32)*(U$13:U$27)) -> 0 | V32: =SUMPRODUCT(($A$13:$A$27=$A32)*(V$13:V$27)) -> 0 | W32: =SUMPRODUCT(($A$13:$A$27=$A32)*(W$13:W$27)) -> 0 | X32: =SUMPRODUCT(($A$13:$A$27=$A32)*(X$13:X$27)) -> 0 | Y32: =SUMPRODUCT(($A$13:$A$27=$A32)*(Y$13:Y$27)) -> 0 | Z32: =SUMPRODUCT(($A$13:$A$27=$A32)*(Z$13:Z$27)) -> 0 | AA32: =SUMPRODUCT(($A$13:$A$27=$A32)*(AA$13:AA$27)) -> 0 | AB32: =SUMPRODUCT(($A$13:$A$27=$A32)*(AB$13:AB$27)) -> 0 | ... AD32: =SUMPRODUCT(($A$13:$A$27=$A32)*(AD$13:AD$27)) -> 0 | AF32: =SUMPRODUCT(($A$13:$A$27=$A32)*(AF$13:AF$27)) -> 0 | AH32: =SUMPRODUCT(($A$13:$A$27=$A32)*(AH$13:AH$27)) -> 0 | AI32: =SUMPRODUCT(($A$13:$A$27=$A32)*(AI$13:AI$27)) -> 0 | AJ32: =SUMPRODUCT(($A$13:$A$27=$A32)*(AJ$13:AJ$27)) -> 0 | AK32: =SUMPRODUCT(($A$13:$A$27=$A32)*(AK$13:AK$27)) -> 0 | AL32: =SUMPRODUCT(($A$13:$A$27=$A32)*(AL$13:AL$27)) -> 0 | AM32: =SUMPRODUCT(($A$13:$A$27=$A32)*(AM$13:AM$27)) -> 0 | AN32: =SUMPRODUCT(($A$13:$A$27=$A32)*(AN$13:AN$27)) -> 0 | AO32: =SUMPRODUCT(($A$13:$A$27=$A32)*(AO$13:AO$27)) -> 0 | ... AQ32: =SUMPRODUCT(($A$13:$A$27=$A32)*(AQ$13:AQ$27)) -> 0
A33: =底稿目录!A12 -> …… | C33: =SUMPRODUCT(($A$13:$A$27=$A33)*(C$13:C$27)) -> 0 | D33: =SUMPRODUCT(($A$13:$A$27=$A33)*(D$13:D$27)) -> 0 | F33: =SUMPRODUCT(($A$13:$A$27=$A33)*(F$13:F$27)) -> 0 | H33: =SUMPRODUCT(($A$13:$A$27=$A33)*(H$13:H$27)) -> 0 | I33: =SUMPRODUCT(($A$13:$A$27=$A33)*(I$13:I$27)) -> 0 | J33: =SUMPRODUCT(($A$13:$A$27=$A33)*(J$13:J$27)) -> 0 | K33: =SUMPRODUCT(($A$13:$A$27=$A33)*(K$13:K$27)) -> 0 | L33: =SUMPRODUCT(($A$13:$A$27=$A33)*(L$13:L$27)) -> 0 | M33: =SUMPRODUCT(($A$13:$A$27=$A33)*(M$13:M$27)) -> 0 | N33: =SUMPRODUCT(($A$13:$A$27=$A33)*(N$13:N$27)) -> 0 | O33: =SUMPRODUCT(($A$13:$A$27=$A33)*(O$13:O$27)) -> 0 | ... Q33: =SUMPRODUCT(($A$13:$A$27=$A33)*(Q$13:Q$27)) -> 0 | S33: =SUMPRODUCT(($A$13:$A$27=$A33)*(S$13:S$27)) -> 0 | U33: =SUMPRODUCT(($A$13:$A$27=$A33)*(U$13:U$27)) -> 0 | V33: =SUMPRODUCT(($A$13:$A$27=$A33)*(V$13:V$27)) -> 0 | W33: =SUMPRODUCT(($A$13:$A$27=$A33)*(W$13:W$27)) -> 0 | X33: =SUMPRODUCT(($A$13:$A$27=$A33)*(X$13:X$27)) -> 0 | Y33: =SUMPRODUCT(($A$13:$A$27=$A33)*(Y$13:Y$27)) -> 0 | Z33: =SUMPRODUCT(($A$13:$A$27=$A33)*(Z$13:Z$27)) -> 0 | AA33: =SUMPRODUCT(($A$13:$A$27=$A33)*(AA$13:AA$27)) -> 0 | AB33: =SUMPRODUCT(($A$13:$A$27=$A33)*(AB$13:AB$27)) -> 0 | ... AD33: =SUMPRODUCT(($A$13:$A$27=$A33)*(AD$13:AD$27)) -> 0 | AF33: =SUMPRODUCT(($A$13:$A$27=$A33)*(AF$13:AF$27)) -> 0 | AH33: =SUMPRODUCT(($A$13:$A$27=$A33)*(AH$13:AH$27)) -> 0 | AI33: =SUMPRODUCT(($A$13:$A$27=$A33)*(AI$13:AI$27)) -> 0 | AJ33: =SUMPRODUCT(($A$13:$A$27=$A33)*(AJ$13:AJ$27)) -> 0 | AK33: =SUMPRODUCT(($A$13:$A$27=$A33)*(AK$13:AK$27)) -> 0 | AL33: =SUMPRODUCT(($A$13:$A$27=$A33)*(AL$13:AL$27)) -> 0 | AM33: =SUMPRODUCT(($A$13:$A$27=$A33)*(AM$13:AM$27)) -> 0 | AN33: =SUMPRODUCT(($A$13:$A$27=$A33)*(AN$13:AN$27)) -> 0 | AO33: =SUMPRODUCT(($A$13:$A$27=$A33)*(AO$13:AO$27)) -> 0 | ... AQ33: =SUMPRODUCT(($A$13:$A$27=$A33)*(AQ$13:AQ$27)) -> 0
A34: 三、审计说明：
A36: 四、审计结论:
A40: 提示：
A41: 1、投资性房地产，是指为赚取租金或资本增值，或两者兼有而持有的房地产。投资性房地产应当能够单独计量和出售。
A42: 2、包括：已出租的土地使用权；持有并准备增值后转让的土地使用权；已出租的建筑物。
A43: 3、通常情况下，对企业持有以备经营出租的空置建筑物，如董事会或类似机构作出书面决议，明确表明将其用于经营
A44: 租出且持有意图短期内不再发生变化的，即使尚未签定租赁协议，也应视为投资性房地产。
A45: 4.审计说明可以概述：（1）程序的测试情况、结果；（2）拟调整事项及其调整分录、未调整事项及其影响，审计范围受到限制情况及其影响。
A46: 5.审计结论可参考：A、未见异常。 B、除上述重大不符事项应当作为调整事项予以调整外，其余未见异常。 C、由于存在以下重大未调整事项（或审计范围受到限制无法获取充分、适当证据），不可确认。

Sheet 明细表（公允价值模式）H3-2
A1: 致同会计师事务所 | P1: 致同会计师事务所
A2: 投资性房地产明细表（公允价值模式） | P2: 投资性房地产明细表（公允价值模式）
A3: =底稿目录!A2 -> 被审计单位： | H3: =底稿目录!A4 -> 编制人： | K3: =底稿目录!A6 -> 编制日期： | N3: 索引号： | O3: H3-2 | T3: =底稿目录!A4 -> 编制人： | W3: =底稿目录!A6 -> 编制日期： | Z3: 索引号： | AA3: H3-2
A4: =底稿目录!A3 -> 截止日：202X年12月31日 | H4: =底稿目录!A5 -> 复核人： | K4: =底稿目录!A7 -> 复核日期： | N4: 页 次： | T4: =底稿目录!A5 -> 复核人： | W4: =底稿目录!A7 -> 复核日期： | Z4: 页 次：
A5: 一、审计目标:
A6: 1. 资产负债表中记录的投资性房地产是存在的，且已记录于恰当的账户；2. 所有应记录的投资性房地产均已记录，所有应当包括在财务报表中的相关披露均已包括；
A7: 3.投资性房地产以恰当的金额包括在财务报表中，与之相关的计价或分摊调整已恰当记录，相关披露已得到恰当计量和描述
A8: 二、审计过程：
A9: 投资性房地产类别 | B9: 投资性房地产名称 | C9: 投资性房地产原值 | P9: 公允价值变动 | X9: 期初净值 | Y9: 期末净值 | Z9: 是否有权属证明 | AA9: 是否抵押受限
C10: 未审数 | I10: 期初调整 | J10: 账项调整 | L10: 审定数 | P10: 未审数 | S10: 期初调整 | T10: 本期变动调整 | U10: 审定数
C11: 期初余额 | D11: 本年增加 | E11: 增加方式 | F11: 本年减少 | G11: 减少方式 | H11: 期末余额 | J11: 本期增加 | K11: 本期减少 | L11: 期初余额 | M11: 本年增加 | N11: 本年减少 | O11: 期末余额 | P11: 期初余额 | Q11: 本年变动 | R11: 期末余额 | U11: 期初余额 | V11: 本年变动 | W11: 期末余额
H12: =C12+D12-F12 -> 0 | L12: =C12+I12 -> 0 | M12: =D12+J12 -> 0 | N12: =F12+K12 -> 0 | O12: =L12+M12-N12 -> 0 | R12: =P12+Q12 -> 0 | U12: =P12+S12 -> 0 | V12: =Q12+T12 -> 0 | W12: =U12+V12 -> 0 | X12: =L12+U12 -> 0 | Y12: =O12+W12 -> 0
H13: =C13+D13-F13 -> 0 | L13: =C13+I13 -> 0 | M13: =D13+J13 -> 0 | N13: =F13+K13 -> 0 | O13: =L13+M13-N13 -> 0 | R13: =P13+Q13 | U13: =P13+S13 -> 0 | V13: =Q13+T13 -> 0 | W13: =U13+V13 -> 0 | X13: =L13+U13 -> 0 | Y13: =O13+W13 -> 0
H14: =C14+D14-F14 -> 0 | L14: =C14+I14 -> 0 | M14: =D14+J14 -> 0 | N14: =F14+K14 -> 0 | O14: =L14+M14-N14 -> 0 | R14: =P14+Q14 | U14: =P14+S14 -> 0 | V14: =Q14+T14 -> 0 | W14: =U14+V14 -> 0 | X14: =L14+U14 -> 0 | Y14: =O14+W14 -> 0
H15: =C15+D15-F15 -> 0 | L15: =C15+I15 -> 0 | M15: =D15+J15 -> 0 | N15: =F15+K15 -> 0 | O15: =L15+M15-N15 -> 0 | R15: =P15+Q15 | U15: =P15+S15 -> 0 | V15: =Q15+T15 -> 0 | W15: =U15+V15 -> 0 | X15: =L15+U15 -> 0 | Y15: =O15+W15 -> 0
H16: =C16+D16-F16 -> 0 | L16: =C16+I16 -> 0 | M16: =D16+J16 -> 0 | N16: =F16+K16 -> 0 | O16: =L16+M16-N16 -> 0 | R16: =P16+Q16 | U16: =P16+S16 -> 0 | V16: =Q16+T16 -> 0 | W16: =U16+V16 -> 0 | X16: =L16+U16 -> 0 | Y16: =O16+W16 -> 0
H17: =C17+D17-F17 -> 0 | L17: =C17+I17 -> 0 | M17: =D17+J17 -> 0 | N17: =F17+K17 -> 0 | O17: =L17+M17-N17 -> 0 | R17: =P17+Q17 | U17: =P17+S17 -> 0 | V17: =Q17+T17 -> 0 | W17: =U17+V17 -> 0 | X17: =L17+U17 -> 0 | Y17: =O17+W17 -> 0
H18: =C18+D18-F18 -> 0 | L18: =C18+I18 -> 0 | M18: =D18+J18 -> 0 | N18: =F18+K18 -> 0 | O18: =L18+M18-N18 -> 0 | R18: =P18+Q18 | U18: =P18+S18 -> 0 | V18: =Q18+T18 -> 0 | W18: =U18+V18 -> 0 | X18: =L18+U18 -> 0 | Y18: =O18+W18 -> 0
H19: =C19+D19-F19 -> 0 | L19: =C19+I19 -> 0 | M19: =D19+J19 -> 0 | N19: =F19+K19 -> 0 | O19: =L19+M19-N19 -> 0 | R19: =P19+Q19 | U19: =P19+S19 -> 0 | V19: =Q19+T19 -> 0 | W19: =U19+V19 -> 0 | X19: =L19+U19 -> 0 | Y19: =O19+W19 -> 0
H20: =C20+D20-F20 -> 0 | L20: =C20+I20 -> 0 | M20: =D20+J20 -> 0 | N20: =F20+K20 -> 0 | O20: =L20+M20-N20 -> 0 | R20: =P20+Q20 | U20: =P20+S20 -> 0 | V20: =Q20+T20 -> 0 | W20: =U20+V20 -> 0 | X20: =L20+U20 -> 0 | Y20: =O20+W20 -> 0
H21: =C21+D21-F21 -> 0 | L21: =C21+I21 -> 0 | M21: =D21+J21 -> 0 | N21: =F21+K21 -> 0 | O21: =L21+M21-N21 -> 0 | R21: =P21+Q21 | U21: =P21+S21 -> 0 | V21: =Q21+T21 -> 0 | W21: =U21+V21 -> 0 | X21: =L21+U21 -> 0 | Y21: =O21+W21 -> 0
H22: =C22+D22-F22 -> 0 | L22: =C22+I22 -> 0 | M22: =D22+J22 -> 0 | N22: =F22+K22 -> 0 | O22: =L22+M22-N22 -> 0 | R22: =P22+Q22 | U22: =P22+S22 -> 0 | V22: =Q22+T22 -> 0 | W22: =U22+V22 -> 0 | X22: =L22+U22 -> 0 | Y22: =O22+W22 -> 0
H23: =C23+D23-F23 -> 0 | L23: =C23+I23 -> 0 | M23: =D23+J23 -> 0 | N23: =F23+K23 -> 0 | O23: =L23+M23-N23 -> 0 | R23: =P23+Q23 | U23: =P23+S23 -> 0 | V23: =Q23+T23 -> 0 | W23: =U23+V23 -> 0 | X23: =L23+U23 -> 0 | Y23: =O23+W23 -> 0
... H26: =C26+D26-F26 -> 0 | L26: =C26+I26 -> 0 | M26: =D26+J26 -> 0 | N26: =F26+K26 -> 0 | O26: =L26+M26-N26 -> 0 | R26: =P26+Q26 | U26: =P26+S26 -> 0 | V26: =Q26+T26 -> 0 | W26: =U26+V26 -> 0 | X26: =L26+U26 -> 0 | Y26: =O26+W26 -> 0
A27: 合计 | C27: =SUM(C12:C26) -> 0 | D27: =SUM(D12:D26) -> 0 | F27: =SUM(F12:F26) -> 0 | H27: =SUM(H12:H26) -> 0 | I27: =SUM(I12:I26) -> 0 | J27: =SUM(J12:J26) -> 0 | K27: =SUM(K12:K26) -> 0 | L27: =SUM(L12:L26) -> 0 | M27: =SUM(M12:M26) -> 0 | N27: =SUM(N12:N26) -> 0 | O27: =SUM(O12:O26) -> 0 | ... Y27: =SUM(Y12:Y26) -> 0
A28: 其中：
A29: =底稿目录!A9 -> 房屋、建筑物 | C29: =SUMPRODUCT(($A$12:$A$26=$A29)*(C$12:C$26)) -> 0 | D29: =SUMPRODUCT(($A$12:$A$26=$A29)*(D$12:D$26)) -> 0 | F29: =SUMPRODUCT(($A$12:$A$26=$A29)*(F$12:F$26)) -> 0 | H29: =SUMPRODUCT(($A$12:$A$26=$A29)*(H$12:H$26)) -> 0 | I29: =SUMPRODUCT(($A$12:$A$26=$A29)*(I$12:I$26)) -> 0 | J29: =SUMPRODUCT(($A$12:$A$26=$A29)*(J$12:J$26)) -> 0 | K29: =SUMPRODUCT(($A$12:$A$26=$A29)*(K$12:K$26)) -> 0 | L29: =SUMPRODUCT(($A$12:$A$26=$A29)*(L$12:L$26)) -> 0 | M29: =SUMPRODUCT(($A$12:$A$26=$A29)*(M$12:M$26)) -> 0 | N29: =SUMPRODUCT(($A$12:$A$26=$A29)*(N$12:N$26)) -> 0 | O29: =SUMPRODUCT(($A$12:$A$26=$A29)*(O$12:O$26)) -> 0 | ... Y29: =SUMPRODUCT(($A$12:$A$26=$A29)*(Y$12:Y$26)) -> 0
A30: =底稿目录!A10 -> 土地使用权 | C30: =SUMPRODUCT(($A$12:$A$26=$A30)*(C$12:C$26)) -> 0 | D30: =SUMPRODUCT(($A$12:$A$26=$A30)*(D$12:D$26)) -> 0 | F30: =SUMPRODUCT(($A$12:$A$26=$A30)*(F$12:F$26)) -> 0 | H30: =SUMPRODUCT(($A$12:$A$26=$A30)*(H$12:H$26)) -> 0 | I30: =SUMPRODUCT(($A$12:$A$26=$A30)*(I$12:I$26)) -> 0 | J30: =SUMPRODUCT(($A$12:$A$26=$A30)*(J$12:J$26)) -> 0 | K30: =SUMPRODUCT(($A$12:$A$26=$A30)*(K$12:K$26)) -> 0 | L30: =SUMPRODUCT(($A$12:$A$26=$A30)*(L$12:L$26)) -> 0 | M30: =SUMPRODUCT(($A$12:$A$26=$A30)*(M$12:M$26)) -> 0 | N30: =SUMPRODUCT(($A$12:$A$26=$A30)*(N$12:N$26)) -> 0 | O30: =SUMPRODUCT(($A$12:$A$26=$A30)*(O$12:O$26)) -> 0 | ... Y30: =SUMPRODUCT(($A$12:$A$26=$A30)*(Y$12:Y$26)) -> 0
A31: =底稿目录!A11 -> 在建工程 | C31: =SUMPRODUCT(($A$12:$A$26=$A31)*(C$12:C$26)) -> 0 | D31: =SUMPRODUCT(($A$12:$A$26=$A31)*(D$12:D$26)) -> 0 | F31: =SUMPRODUCT(($A$12:$A$26=$A31)*(F$12:F$26)) -> 0 | H31: =SUMPRODUCT(($A$12:$A$26=$A31)*(H$12:H$26)) -> 0 | I31: =SUMPRODUCT(($A$12:$A$26=$A31)*(I$12:I$26)) -> 0 | J31: =SUMPRODUCT(($A$12:$A$26=$A31)*(J$12:J$26)) -> 0 | K31: =SUMPRODUCT(($A$12:$A$26=$A31)*(K$12:K$26)) -> 0 | L31: =SUMPRODUCT(($A$12:$A$26=$A31)*(L$12:L$26)) -> 0 | M31: =SUMPRODUCT(($A$12:$A$26=$A31)*(M$12:M$26)) -> 0 | N31: =SUMPRODUCT(($A$12:$A$26=$A31)*(N$12:N$26)) -> 0 | O31: =SUMPRODUCT(($A$12:$A$26=$A31)*(O$12:O$26)) -> 0 | ... Y31: =SUMPRODUCT(($A$12:$A$26=$A31)*(Y$12:Y$26)) -> 0
A32: =底稿目录!A12 -> …… | C32: =SUMPRODUCT(($A$12:$A$26=$A32)*(C$12:C$26)) -> 0 | D32: =SUMPRODUCT(($A$12:$A$26=$A32)*(D$12:D$26)) -> 0 | F32: =SUMPRODUCT(($A$12:$A$26=$A32)*(F$12:F$26)) -> 0 | H32: =SUMPRODUCT(($A$12:$A$26=$A32)*(H$12:H$26)) -> 0 | I32: =SUMPRODUCT(($A$12:$A$26=$A32)*(I$12:I$26)) -> 0 | J32: =SUMPRODUCT(($A$12:$A$26=$A32)*(J$12:J$26)) -> 0 | K32: =SUMPRODUCT(($A$12:$A$26=$A32)*(K$12:K$26)) -> 0 | L32: =SUMPRODUCT(($A$12:$A$26=$A32)*(L$12:L$26)) -> 0 | M32: =SUMPRODUCT(($A$12:$A$26=$A32)*(M$12:M$26)) -> 0 | N32: =SUMPRODUCT(($A$12:$A$26=$A32)*(N$12:N$26)) -> 0 | O32: =SUMPRODUCT(($A$12:$A$26=$A32)*(O$12:O$26)) -> 0 | ... Y32: =SUMPRODUCT(($A$12:$A$26=$A32)*(Y$12:Y$26)) -> 0
A33: 三、审计说明：
A36: 四、审计结论
A41: 提示：
A42: 1、投资性房地产，是指为赚取租金或资本增值，或两者兼有而持有的房地产。投资性房地产应当能够单独计量和出售。
A43: 2、包括：已出租的土地使用权；持有并准备增值后转让的土地使用权；已出租的建筑物。
A44: 3、通常情况下，对企业持有以备经营出租的空置建筑物，如董事会或类似机构作出书面决议，明确表明将其用于经营
A45: 租出且持有意图短期内不再发生变化的，即使尚未签定租赁协议，也应视为投资性房地产。
A46: 4.审计说明可以概述:(1)程序的测试情况、结果;(2)拟调整事项及其调整分录、未调整事项及其影响，审计范围受到限制情况及其影响。
A47: 5.审计结论可参考：A、未见异常。 B、除上述重大不符事项应当作为调整事项予以调整外，其余未见异常。 C、由于存在以下重大未调整事项(或审计范围受到限制无法获取充分、适当证据)，不可确认。

Sheet 调整分录汇总H3-3
A1: 致同会计师事务所
A2: 投资性房地产调整分录汇总表
A3: =底稿目录!A2 -> 被审计单位： | D3: =底稿目录!A4 -> 编制人： | G3: =底稿目录!A6 -> 编制日期： | I3: 索引号： | J3: H3-3
A4: =底稿目录!A3 -> 截止日：202X年12月31日 | D4: =底稿目录!A5 -> 复核人： | G4: =底稿目录!A7 -> 复核日期： | I4: 页 次：
A5: 调整事项说明 | B5: 类别（报表调整/账项调整/其他） | C5: 报表项目 | D5: 科目名称 | E5: 附注项目 | F5: …… | G5: 借方调整金额 | H5: 贷方调整金额 | I5: 索引 | J5: 备注
A21: 提示：本底稿适用于调整分录较多、较复杂的项目，且仅列示与本报表项目相关的审计调整。项目组可根据项目实际情况选择是否使用该底稿。

Sheet 会计政策会计估计检查表H3-4
A1: 致同会计师事务所
A2: 投资性房地产相关会计政策/估计检查表
A3: =底稿目录!A2 -> 被审计单位： | D3: =底稿目录!A4 -> 编制人： | H3: =底稿目录!A6 -> 编制日期： | J3: 索引号： | K3: =底稿目录!F12 -> H3-4
A4: =底稿目录!A3 -> 截止日：202X年12月31日 | D4: =底稿目录!A5 -> 复核人： | H4: =底稿目录!A7 -> 复核日期： | J4: 页 次：
A5: 一、审计目标：
A6: 1.所有应记录的投资性房地产均已记录，所有应当包括在财务报表中的相关披露均已包括； | G6: 2. 所有应记录的投资性房地产均已记录，所有应当包括在财务报表中的相关披露均已包括
A7: 2.投资性房地产以恰当的金额包括在财务报表中，与之相关的计价或分摊调整已恰当记录，相关披露已得到恰当计量和描述 。
A8: 二、审计过程：
A9: （一）分类为投资性房地产的判断依据。
A11: （二）被审计单位对投资性房地产的计量属性的选择及其原因：
A13: （三）成本模式下，被审计单位的投资性房地产折旧政策：
A14: 序号 | B14: 类别 | C14: 折旧年限 | D14: 折旧方法 | E14: 残值率 | F14: 是否符合实际经营情况和会计准则的要求 | G14: 是否与相关资产所包含的经济利益预期实现方式相一致 | H14: 与同行业公司相比，会计政策是否合理 | I14: 是否存在会计政策/会计估计变更 | J14: 会计政策/会计估计变更是否合理 | K14: 备注
A15: 1 | B15: 房屋、建筑物
A16: 2 | B16: 土地使用权
A17: 3 | B17: 在建工程
A18: （四）公允价值模式下，期末投资性房地产公允价值的取得：
A20: （五）如本期存在会计估计变更，原会计估计如下：
A21: 序号 | B21: 类别 | C21: 使用寿命 | D21: 摊销方法 | E21: 残值率
A22: 1 | B22: 房屋、建筑物
A23: 2 | B23: 土地使用权
A24: 3 | B24: 在建工程
A25: 三、审计说明：
A27: 四、审计结论：

Sheet 增减检查表（成本模式）H3-5
A1: 致同会计师事务所
A2: 投资性房地产增减检查表（成本模式）
A3: 被审计单位： | E3: 编制人： | K3: 编制日期： | S3: 索引号： | T3: =底稿目录!F13 -> H3-5
A4: 截止日：202X年12月31日 | E4: 复核人： | K4: 复核日期： | S4: 页 次：
A5: 一、审计目标：
A6: 1.资产负债表中记录的投资性房地产是存在的，且已记录于恰当的账户；2.所有应记录的投资性房地产均已记录，所有应当包括在财务报表中的相关披露均已包括；
A7: 3.记录的投资性房地产由被审计单位拥有或控制；4.投资性房地产以恰当的金额包括在财务报表中，与之相关的计价或分摊调整已恰当记录，相关披露已得到恰当计量和描述。
A8: 二、样本选取标准与规模：
A9: 测试总体： | B9: 如投资性房地产借方发生额所有凭证共XX笔金额XX、贷方发生额所有凭证共XX笔金额XX | I9: 特定样本： | J9: XX金额以上（大额）、关联方/关联交易形成的款项、XX异常款项全部测试，共XX笔；
A10: 抽样总体： | B10: 测试总体扣除特定样本以外的样本，共XX笔、金额XX | I10: 确定的抽样样本量： | K10: 抽取XX笔 | L10: （如果使用了样本计算器计算样本量，样本量计算过程见<XX>底稿）
A11: 抽样方法： | B11: 随机选样/系统选样/货币单元抽样/随意选样（非统计抽样适用） | I11: 抽样过程： | J11: 使用IDEA（XX抽样工具）选择XX数量、金额XX的样本进行测试，抽样工具中的样本选择过程和结果见<XX>底稿
A12: 三、测试：
A13: 测试内容说明：1.原始凭证是否齐全； 2.记账凭证与原始凭证是否相符；3.账务处理是否正确；4.是否记录于恰当的会计期间；5.……
A14: 序号 | B14: 投资性房地产类别 | C14: 投资性房地产名称 | D14: 增减日期 | E14: 增减方式 | F14: 入账凭证号 | G14: 对方科目 | H14: 增减情况 | L14: 支持性文件 | M14: 核对内容 | R14: 索引号 | S14: 是否异常 | T14: 备注说明
H15: 原值 | I15: 累计折旧 | J15: 减值准备 | K15: 净值 | M15: 1 | N15: 2 | O15: 3 | P15: 4 | Q15: 5
A16: 1 | K16: =H16-I16-J16 -> 0 | L16: XX购买合同/协议、发票、验收报告、……
A17: 2 | K17: =H17-I17-J17 -> 0
A18: 3 | K18: =H18-I18-J18 -> 0
A19: 4 | K19: =H19-I19-J19 -> 0
A20: 5 | K20: =H20-I20-J20 -> 0
A21: 6 | K21: =H21-I21-J21 -> 0
A22: 7 | K22: =H22-I22-J22 -> 0
A23: 8 | K23: =H23-I23-J23 -> 0
A24: 9 | K24: =H24-I24-J24 -> 0
A25: 10 | K25: =H25-I25-J25 -> 0
A26: 11 | K26: =H26-I26-J26 -> 0
A27: 12 | K27: =H27-I27-J27 -> 0
A28: 13 | K28: =H28-I28-J28 -> 0
... A30: 15 | K30: =H30-I30-J30 -> 0
A31: …… | K31: =H31-I31-J31 -> 0
A32: 合计 | H32: =SUM(H16:H31) -> 0 | I32: =SUM(I16:I31) -> 0 | J32: =SUM(J16:J31) -> 0 | K32: =SUM(K16:K31) -> 0
A33: 本期新增投资性房地产合计
A34: 检查比例 | H34: =IF(H32=0,0,H32/$H$33) -> 0
A35: 四、审计说明：
A36: 1.如果检查比例较低应扩大检查样本量或说明原因
A37: 2.……
A38: 五、审计结论：
A41: 提示：
A42: 1、本表用于汇总本年度增加、减少投资性房地产的测试情况。
A43: 对于外购的投资性房地产，追查至购买合同/协议、原始发票、验收报告等以确认其有效性、金额的正确性以及新增投资性房地产是否经过有效批准；检查建筑物产权证、土地使用权证等所有权证明文件，确定建筑物、土地使用权是否归被审计单位所有。
...

Sheet 增减检查表（公允价值模式）H3-5
A1: 致同会计师事务所
A2: 投资性房地产增减检查表（公允价值模式）
A3: 被审计单位： | E3: 编制人： | I3: 编制日期： | R3: 索引号： | S3: =底稿目录!F14 -> H3-5
A4: 截止日：202X年12月31日 | E4: 复核人： | I4: 复核日期： | R4: 页 次：
A5: 一、审计目标：
A6: 1.资产负债表中记录的投资性房地产是存在的，且已记录于恰当的账户；2.所有应记录的投资性房地产均已记录，所有应当包括在财务报表中的相关披露均已包括；
A7: 3.记录的投资性房地产由被审计单位拥有或控制；4.投资性房地产以恰当的金额包括在财务报表中，与之相关的计价或分摊调整已恰当记录，相关披露已得到恰当计量和描述。
A8: 二、样本选取标准与规模：
A9: 测试总体： | B9: 如投资性房地产借方发生额所有凭证共XX笔金额XX、贷方发生额所有凭证共XX笔金额XX | I9: 特定样本： | J9: XX金额以上（大额）、关联方/关联交易形成的款项、XX异常款项全部测试，共XX笔；
A10: 抽样总体： | B10: 测试总体扣除特定样本以外的样本，共XX笔、金额XX | I10: 确定的抽样样本量： | K10: 抽取XX笔 | L10: （如果使用了样本计算器计算样本量，样本量计算过程见<XX>底稿）
A11: 抽样方法： | B11: 随机选样/系统选样/货币单元抽样/随意选样（非统计抽样适用） | I11: 抽样过程： | J11: 使用IDEA（XX抽样工具）选择XX数量、金额XX的样本进行测试，抽样工具中的样本选择过程和结果见<XX>底稿
A12: 三、测试：
A13: 测试内容说明：1.原始凭证是否齐全； 2.记账凭证与原始凭证是否相符；3.账务处理是否正确；4.是否记录于恰当的会计期间；5.……
A14: 序号 | B14: 投资性房地产类别 | C14: 投资性房地产名称 | D14: 增减日期 | E14: 增减方式 | F14: 入账凭证号 | G14: 对方科目 | H14: 增减情况 | K14: 支持性文件 | L14: 核对内容 | Q14: 索引号 | R14: 是否异常 | S14: 备注说明
H15: 原价 | I15: 公允价值变动 | J15: 期末余额 | L15: 1 | M15: 2 | N15: 3 | O15: 4 | P15: 5
A16: 1 | E16: 外购 | J16: =H16+I16 -> 0 | K16: XX购买合同/协议、发票、验收报告、……
A17: 2 | J17: =H17+I17 -> 0
A18: 3 | J18: =H18+I18 -> 0
A19: 4 | J19: =H19+I19 -> 0
A20: 5 | J20: =H20+I20 -> 0
A21: 6 | J21: =H21+I21 -> 0
A22: 7 | J22: =H22+I22 -> 0
A23: 8 | J23: =H23+I23 -> 0
A24: 9 | J24: =H24+I24 -> 0
A25: 10 | J25: =H25+I25 -> 0
A26: 11 | J26: =H26+I26 -> 0
A27: 12 | J27: =H27+I27 -> 0
A28: 13 | J28: =H28+I28 -> 0
... A30: 15 | J30: =H30+I30 -> 0
A31: …… | J31: =H31+I31 -> 0
A32: 合计 | H32: =SUM(H16:H31) -> 0 | I32: =SUM(I16:I31) -> 0 | J32: =SUM(J16:J31) -> 0
A33: 本期新增投资性房地产合计 | J33: 0
A34: 检查比例 | J34: =IF(H32=0,0,H32/$J$33) -> 0
A35: 四、审计说明：
A36: 1.如果检查比例较低应扩大检查样本量或说明原因
A37: 2.……
A39: 五、审计结论：

Sheet 互转审核表H3-6
A1: 致同会计师事务所
A2: 投资性房地产与自用房地产互转审核表
A3: =底稿目录!A2 -> 被审计单位： | F3: =底稿目录!A4 -> 编制人： | L3: =底稿目录!A6 -> 编制日期： | V3: 索引号： | W3: =底稿目录!F15 -> H3-6
A4: =底稿目录!A3 -> 截止日：202X年12月31日 | F4: =底稿目录!A5 -> 复核人： | L4: =底稿目录!A7 -> 复核日期： | V4: 页 次：
A5: 一、审计目标：1. 投资性房地产以恰当的金额包括在财务报表中，与之相关的计价或分摊调整已恰当记录，相关披露已得到恰当计量和描述；2. 投资性房地产已被恰当地汇总或分解且表述清楚，相关披露在按照企业会计准则的编制基础下是相关的、可理解的
A6: 二、审计过程：
A7: 投资性房地产类别 | B7: 投资性房地产名称 | C7: 转换方式 | D7: 转换日期 | E7: 转换比例 | F7: 自用房地产转换日价值 | J7: 投资性房地产转换日价值 | S7: 转换影响 | U7: 转换原因 | V7: 批准文件 | W7: 备注
J8: 成本模式 | N8: 公允价值模式
F9: 资产原值 | G9: 累计折旧/摊销 | H9: 减值准备 | I9: 净额 | J9: 资产原值 | K9: 累计折旧 | L9: 减值准备 | M9: 净额 | N9: 账面价值 | O9: 公允价值 | P9: 面积 | Q9: 参考单价 | R9: 参考单价来源 | S9: 当期损益 | T9: 其他综合收益
F10: ① | G10: ② | H10: ③ | I10: ④=①-②-③ | J10: ⑤ | K10: ⑥ | L10: ⑦ | M10: ⑧=⑤-⑥-⑦ | N10: ⑨ | O10: ⑩ | S10: ⑾=⑨-⑩ | T10: ⑿=⑩-⑨
A11: 1.房屋、建筑物 | F11: =SUM(F12:F15) -> 0 | G11: =SUM(G12:G15) -> 0 | H11: =SUM(H12:H15) -> 0 | I11: =SUM(I12:I15) -> 0 | J11: =SUM(J12:J15) -> 0 | K11: =SUM(K12:K15) -> 0 | L11: =SUM(L12:L15) -> 0 | M11: =SUM(M12:M15) -> 0 | ... O11: =SUM(O12:O15) -> 0 | S11: =SUM(S12:S15) -> 0 | T11: =SUM(T12:T15) -> 0
I12: =F12-G12-H12 -> 0 | M12: =J12-K12-L12 -> 0 | N12: =I12 -> 0 | O12: =P12*Q12 -> 0 | S12: =IF(N12>O12,N12-O12,0) -> 0 | T12: =IF(O12>N12,O12-N12,0) -> 0
I13: =F13-G13-H13 -> 0 | M13: =J13-K13-L13 -> 0 | N13: =I13 -> 0 | O13: =P13*Q13 -> 0 | S13: =IF(N13>O13,N13-O13,0) -> 0 | T13: =IF(O13>N13,O13-N13,0) -> 0
I14: =F14-G14-H14 -> 0 | M14: =J14-K14-L14 -> 0 | N14: =I14 -> 0 | O14: =P14*Q14 -> 0 | S14: =IF(N14>O14,N14-O14,0) -> 0 | T14: =IF(O14>N14,O14-N14,0) -> 0
I15: =F15-G15-H15 -> 0 | M15: =J15-K15-L15 -> 0 | N15: =I15 -> 0 | O15: =P15*Q15 -> 0 | S15: =IF(N15>O15,N15-O15,0) -> 0 | T15: =IF(O15>N15,O15-N15,0) -> 0
A16: 2.土地使用权 | F16: =SUM(F17:F20) -> 0 | G16: =SUM(G17:G20) -> 0 | H16: =SUM(H17:H20) -> 0 | I16: =SUM(I17:I20) -> 0 | J16: =SUM(J17:J20) -> 0 | K16: =SUM(K17:K20) -> 0 | L16: =SUM(L17:L20) -> 0 | M16: =SUM(M17:M20) -> 0 | ... O16: =SUM(O17:O20) -> 0 | S16: =SUM(S17:S20) -> 0 | T16: =SUM(T17:T20) -> 0
I17: =F17-G17-H17 -> 0 | M17: =J17-K17-L17 -> 0 | N17: =I17 -> 0 | O17: =P17*Q17 -> 0 | S17: =IF(N17>O17,N17-O17,0) -> 0 | T17: =IF(O17>N17,O17-N17,0) -> 0
I18: =F18-G18-H18 -> 0 | M18: =J18-K18-L18 -> 0 | N18: =I18 -> 0 | O18: =P18*Q18 -> 0 | S18: =IF(N18>O18,N18-O18,0) -> 0 | T18: =IF(O18>N18,O18-N18,0) -> 0
I19: =F19-G19-H19 -> 0 | M19: =J19-K19-L19 -> 0 | N19: =I19 -> 0 | O19: =P19*Q19 -> 0 | S19: =IF(N19>O19,N19-O19,0) -> 0 | T19: =IF(O19>N19,O19-N19,0) -> 0
I20: =F20-G20-H20 -> 0 | M20: =J20-K20-L20 -> 0 | N20: =I20 -> 0 | O20: =P20*Q20 -> 0 | S20: =IF(N20>O20,N20-O20,0) -> 0 | T20: =IF(O20>N20,O20-N20,0) -> 0
A21: 3.在建工程 | F21: =SUM(F22:F25) -> 0 | G21: =SUM(G22:G25) -> 0 | H21: =SUM(H22:H25) -> 0 | I21: =SUM(I22:I25) -> 0 | J21: =SUM(J22:J25) -> 0 | K21: =SUM(K22:K25) -> 0 | L21: =SUM(L22:L25) -> 0 | M21: =SUM(M22:M25) -> 0 | ... O21: =SUM(O22:O25) -> 0 | S21: =SUM(S22:S25) -> 0 | T21: =SUM(T22:T25) -> 0
I22: =F22-G22-H22 -> 0 | M22: =J22-K22-L22 -> 0 | N22: =I22 -> 0 | O22: =P22*Q22 -> 0 | S22: =IF(N22>O22,N22-O22,0) -> 0 | T22: =IF(O22>N22,O22-N22,0) -> 0
I23: =F23-G23-H23 -> 0 | M23: =J23-K23-L23 -> 0 | N23: =I23 -> 0 | O23: =P23*Q23 -> 0 | S23: =IF(N23>O23,N23-O23,0) -> 0 | T23: =IF(O23>N23,O23-N23,0) -> 0
I24: =F24-G24-H24 -> 0 | M24: =J24-K24-L24 -> 0 | N24: =I24 -> 0 | O24: =P24*Q24 -> 0 | S24: =IF(N24>O24,N24-O24,0) -> 0 | T24: =IF(O24>N24,O24-N24,0) -> 0
I25: =F25-G25-H25 -> 0 | M25: =J25-K25-L25 -> 0 | N25: =I25 -> 0 | O25: =P25*Q25 -> 0 | S25: =IF(N25>O25,N25-O25,0) -> 0 | T25: =IF(O25>N25,O25-N25,0) -> 0
A26: 合计 | F26: =F11+F16+F21 -> 0 | G26: =G11+G16+G21 -> 0 | H26: =H11+H16+H21 -> 0 | I26: =I11+I16+I21 -> 0 | J26: =J11+J16+J21 -> 0 | K26: =K11+K16+K21 -> 0 | L26: =L11+L16+L21 -> 0 | M26: =M11+M16+M21 -> 0 | ... O26: =O11+O16+O21 -> 0 | S26: =S11+S16+S21 -> 0 | T26: =T11+T16+T21 -> 0
A27: 三、审计说明：
A30: 四、审计结论：
A35: 提示：
A36: 1、企业必须有确凿证据表明房地产用途发生改变,才能将投资性房地产转换为非投资性房地产或者将非投资性房地产转换为投资性房地产。
A37: 这里的确凿证据包括两个方面：一是企业董事会或类似机构应当就改变房地产用途形成正式的书面决议，
A38: 二是房地产因用途改变而发生实际状态上的改变，从自用状态改为出租状态。
A40: 2、企业将原本用于生产商品、提供劳务或者经营管理的房地产改用于出租，通常应于租赁期开始日，将相应的固定资产或无形资产转换为投资性房地产。
A41: 对不再用于日常生产经营活动且经整理后达到可经营出租状态的建筑物，如果董事会或类似机构作出正式书面决议，明确表明其持有以备经营出租的
A42: 空置建筑物，如董事会或类似机构作出书面决议，明确表明其自用房地产用于经营租出、持有意图短期内不再发生变化的，应视为存货转换为投资性房地产，
A43: 转换日为董事会或类似机构作出书面决议的日期。
A46: 3、采用公允价值模式计量投资性房地产，应当同时满足以下两个条件：（1）投资性房地产所在地有活跃的房地产交易市场；
A47: （2）企业能够从房地产交易市场上取得同类或类似房地产的市场价格及其他相关信息，从而对投资性房地产的公允价值做出科学合理的估计。
... A54: 5、投资性房地产采用公允价值模式计量的，不计提折旧或摊销，应当以资产负债表日的公允价值计量。

Sheet 折旧测算表（成本模式不含减值）H3-7
A1: 致同会计师事务所
A2: 投资性房地产的折旧测算表（成本模式）
A3: =底稿目录!A2 -> 被审计单位： | G3: =底稿目录!A4 -> 编制人： | N3: =底稿目录!A6 -> 编制日期： | R3: 索引号： | S3: H3-7
A4: =底稿目录!A3 -> 截止日：202X年12月31日 | G4: =底稿目录!A5 -> 复核人： | N4: =底稿目录!A7 -> 复核日期： | R4: 页 次：
A5: 一、审计目标：投资性房地产以恰当的金额包括在财务报表中，与之相关的计价或分摊调整已恰当记录，相关披露已得到恰当计量和描述
A6: 二、审计过程：
A7: 折旧期初： | B7: 45658 | C7: 折旧期末： | D7: 46022 | E7: 各列顺序请根据需要进行调整，行数请根据需要增加。非公式列输入数据时请使用“选择性粘贴-数值”。
A8: 投资性房地产编号 | B8: 投资性房地产类别 | C8: 投资性房地产名称 | D8: 管理部门 | E8: 原值 | F8: 累计折旧 | G8: 开始使用日期 | H8: 使用年限 | I8: 残值率 | J8: 账面月折旧额 | K8: 使用月限 | L8: 测算到期日 | M8: 已提折旧月份 | N8: 本期折旧月份 | O8: 测算月折旧 | P8: 当期折旧费用 | Q8: 月折旧额差异 | R8: 累计折旧费用 | S8: 累计折旧额差异
K9: =IF(H9=0,0,IF(RIGHT(H9,1)<>"年",H9*12,IF(LEN(H9)=3,VALUE(LEFT(H9,2))*12,IF(LEN(H9)=2,VALUE(LEFT(H9,1))*12,"??")))) -> 0 | L9: =IF(G9=0,0,DATE(YEAR(G9),MONTH(G9)+K9,DAY(G9)-1)) -> 0 | M9: =IF(G9=0,0,IF(L9>$D$7,DATEDIF(G9,MIN($D$7,L9),"m"),VALUE(DATEDIF(G9,MIN($D$7,L9),"m")+1))) -> 0 | N9: =IF(OR(G9=0,L9<$B$7),0,IF(AND(G9<$B$7,L9>$D$7),VALUE(DATEDIF($B$7,$D$7,"m")+1),IF(AND(G9<$B$7,L9<=$D$7),VALUE(DATEDIF($B$7,L9,"m")+1),IF(AND(G9>=$B$7,L9>$D$7),VALUE(DATEDIF(G9,$D$7,"m")),IF(AND(G9>=$B$7,L9<=$D$7),VALUE(DATEDIF(G9,L9,"m")+1),))))) -> 0 | O9: =IF(K9=0,0,ROUND(((1-I9)/K9)*E9,4)) -> 0 | P9: =ROUND(O9*N9,2) -> 0 | Q9: =ROUND(J9-O9,2) -> 0 | R9: =ROUND(O9*M9,2) -> 0 | S9: =ROUND(F9-R9,2) -> 0
K10: =IF(H10=0,0,IF(RIGHT(H10,1)<>"年",H10*12,IF(LEN(H10)=3,VALUE(LEFT(H10,2))*12,IF(LEN(H10)=2,VALUE(LEFT(H10,1))*12,"??")))) -> 0 | L10: =IF(G10=0,0,DATE(YEAR(G10),MONTH(G10)+K10,DAY(G10)-1)) -> 0 | M10: =IF(G10=0,0,IF(L10>$D$7,DATEDIF(G10,MIN($D$7,L10),"m"),VALUE(DATEDIF(G10,MIN($D$7,L10),"m")+1))) -> 0 | N10: =IF(OR(G10=0,L10<$B$7),0,IF(AND(G10<$B$7,L10>$D$7),VALUE(DATEDIF($B$7,$D$7,"m")+1),IF(AND(G10<$B$7,L10<=$D$7),VALUE(DATEDIF($B$7,L10,"m")+1),IF(AND(G10>=$B$7,L10>$D$7),VALUE(DATEDIF(G10,$D$7,"m")),IF(AND(G10>=$B$7,L10<=$D$7),VALUE(DATEDIF(G10,L10,"m")+1),))))) -> 0 | O10: =IF(K10=0,0,ROUND(((1-I10)/K10)*E10,4)) -> 0 | P10: =ROUND(O10*N10,2) -> 0 | Q10: =ROUND(J10-O10,2) -> 0 | R10: =ROUND(O10*M10,2) -> 0 | S10: =ROUND(F10-R10,2) -> 0
K11: =IF(H11=0,0,IF(RIGHT(H11,1)<>"年",H11*12,IF(LEN(H11)=3,VALUE(LEFT(H11,2))*12,IF(LEN(H11)=2,VALUE(LEFT(H11,1))*12,"??")))) -> 0 | L11: =IF(G11=0,0,DATE(YEAR(G11),MONTH(G11)+K11,DAY(G11)-1)) -> 0 | M11: =IF(G11=0,0,IF(L11>$D$7,DATEDIF(G11,MIN($D$7,L11),"m"),VALUE(DATEDIF(G11,MIN($D$7,L11),"m")+1))) -> 0 | N11: =IF(OR(G11=0,L11<$B$7),0,IF(AND(G11<$B$7,L11>$D$7),VALUE(DATEDIF($B$7,$D$7,"m")+1),IF(AND(G11<$B$7,L11<=$D$7),VALUE(DATEDIF($B$7,L11,"m")+1),IF(AND(G11>=$B$7,L11>$D$7),VALUE(DATEDIF(G11,$D$7,"m")),IF(AND(G11>=$B$7,L11<=$D$7),VALUE(DATEDIF(G11,L11,"m")+1),))))) -> 0 | O11: =IF(K11=0,0,ROUND(((1-I11)/K11)*E11,4)) -> 0 | P11: =ROUND(O11*N11,2) -> 0 | Q11: =ROUND(J11-O11,2) -> 0 | R11: =ROUND(O11*M11,2) -> 0 | S11: =ROUND(F11-R11,2) -> 0
K12: =IF(H12=0,0,IF(RIGHT(H12,1)<>"年",H12*12,IF(LEN(H12)=3,VALUE(LEFT(H12,2))*12,IF(LEN(H12)=2,VALUE(LEFT(H12,1))*12,"??")))) -> 0 | L12: =IF(G12=0,0,DATE(YEAR(G12),MONTH(G12)+K12,DAY(G12)-1)) -> 0 | M12: =IF(G12=0,0,IF(L12>$D$7,DATEDIF(G12,MIN($D$7,L12),"m"),VALUE(DATEDIF(G12,MIN($D$7,L12),"m")+1))) -> 0 | N12: =IF(OR(G12=0,L12<$B$7),0,IF(AND(G12<$B$7,L12>$D$7),VALUE(DATEDIF($B$7,$D$7,"m")+1),IF(AND(G12<$B$7,L12<=$D$7),VALUE(DATEDIF($B$7,L12,"m")+1),IF(AND(G12>=$B$7,L12>$D$7),VALUE(DATEDIF(G12,$D$7,"m")),IF(AND(G12>=$B$7,L12<=$D$7),VALUE(DATEDIF(G12,L12,"m")+1),))))) -> 0 | O12: =IF(K12=0,0,ROUND(((1-I12)/K12)*E12,4)) -> 0 | P12: =ROUND(O12*N12,2) -> 0 | Q12: =ROUND(J12-O12,2) -> 0 | R12: =ROUND(O12*M12,2) -> 0 | S12: =ROUND(F12-R12,2) -> 0
K13: =IF(H13=0,0,IF(RIGHT(H13,1)<>"年",H13*12,IF(LEN(H13)=3,VALUE(LEFT(H13,2))*12,IF(LEN(H13)=2,VALUE(LEFT(H13,1))*12,"??")))) -> 0 | L13: =IF(G13=0,0,DATE(YEAR(G13),MONTH(G13)+K13,DAY(G13)-1)) -> 0 | M13: =IF(G13=0,0,IF(L13>$D$7,DATEDIF(G13,MIN($D$7,L13),"m"),VALUE(DATEDIF(G13,MIN($D$7,L13),"m")+1))) -> 0 | N13: =IF(OR(G13=0,L13<$B$7),0,IF(AND(G13<$B$7,L13>$D$7),VALUE(DATEDIF($B$7,$D$7,"m")+1),IF(AND(G13<$B$7,L13<=$D$7),VALUE(DATEDIF($B$7,L13,"m")+1),IF(AND(G13>=$B$7,L13>$D$7),VALUE(DATEDIF(G13,$D$7,"m")),IF(AND(G13>=$B$7,L13<=$D$7),VALUE(DATEDIF(G13,L13,"m")+1),))))) -> 0 | O13: =IF(K13=0,0,ROUND(((1-I13)/K13)*E13,4)) -> 0 | P13: =ROUND(O13*N13,2) -> 0 | Q13: =ROUND(J13-O13,2) -> 0 | R13: =ROUND(O13*M13,2) -> 0 | S13: =ROUND(F13-R13,2) -> 0
K14: =IF(H14=0,0,IF(RIGHT(H14,1)<>"年",H14*12,IF(LEN(H14)=3,VALUE(LEFT(H14,2))*12,IF(LEN(H14)=2,VALUE(LEFT(H14,1))*12,"??")))) -> 0 | L14: =IF(G14=0,0,DATE(YEAR(G14),MONTH(G14)+K14,DAY(G14)-1)) -> 0 | M14: =IF(G14=0,0,IF(L14>$D$7,DATEDIF(G14,MIN($D$7,L14),"m"),VALUE(DATEDIF(G14,MIN($D$7,L14),"m")+1))) -> 0 | N14: =IF(OR(G14=0,L14<$B$7),0,IF(AND(G14<$B$7,L14>$D$7),VALUE(DATEDIF($B$7,$D$7,"m")+1),IF(AND(G14<$B$7,L14<=$D$7),VALUE(DATEDIF($B$7,L14,"m")+1),IF(AND(G14>=$B$7,L14>$D$7),VALUE(DATEDIF(G14,$D$7,"m")),IF(AND(G14>=$B$7,L14<=$D$7),VALUE(DATEDIF(G14,L14,"m")+1),))))) -> 0 | O14: =IF(K14=0,0,ROUND(((1-I14)/K14)*E14,4)) -> 0 | P14: =ROUND(O14*N14,2) -> 0 | Q14: =ROUND(J14-O14,2) -> 0 | R14: =ROUND(O14*M14,2) -> 0 | S14: =ROUND(F14-R14,2) -> 0
K15: =IF(H15=0,0,IF(RIGHT(H15,1)<>"年",H15*12,IF(LEN(H15)=3,VALUE(LEFT(H15,2))*12,IF(LEN(H15)=2,VALUE(LEFT(H15,1))*12,"??")))) -> 0 | L15: =IF(G15=0,0,DATE(YEAR(G15),MONTH(G15)+K15,DAY(G15)-1)) -> 0 | M15: =IF(G15=0,0,IF(L15>$D$7,DATEDIF(G15,MIN($D$7,L15),"m"),VALUE(DATEDIF(G15,MIN($D$7,L15),"m")+1))) -> 0 | N15: =IF(OR(G15=0,L15<$B$7),0,IF(AND(G15<$B$7,L15>$D$7),VALUE(DATEDIF($B$7,$D$7,"m")+1),IF(AND(G15<$B$7,L15<=$D$7),VALUE(DATEDIF($B$7,L15,"m")+1),IF(AND(G15>=$B$7,L15>$D$7),VALUE(DATEDIF(G15,$D$7,"m")),IF(AND(G15>=$B$7,L15<=$D$7),VALUE(DATEDIF(G15,L15,"m")+1),))))) -> 0 | O15: =IF(K15=0,0,ROUND(((1-I15)/K15)*E15,4)) -> 0 | P15: =ROUND(O15*N15,2) -> 0 | Q15: =ROUND(J15-O15,2) -> 0 | R15: =ROUND(O15*M15,2) -> 0 | S15: =ROUND(F15-R15,2) -> 0
