Workbook

Sheet 底稿目录
A1: 底稿开列时，可先在以下单元格填写有关内容，以便其他底稿引用有关数据：
A2: 被审计单位：
A3: 截止日：202X年12月31日 | D3: 序号 | E3: 内容 | F3: 索引号 | G3: 备注
A4: 编制人： | D4: 1 | E4: 使用权资产实质性程序表 | F4: H8A
A5: 复核人： | D5: 2 | E5: 审定表 | F5: H8-1
A6: 编制日期： | D6: 3 | E6: 附注披露信息（上市公司） | G6: 无需打印
A7: 复核日期： | D7: 4 | E7: 附注披露信息（国企） | G7: 无需打印
A8: 使用权资产类别设置（以下内容请根据实际情况修改）： | D8: 5 | E8: 明细表 | F8: H8-2
A9: 房屋及建筑物 | D9: 6 | E9: 调整分录汇总 | F9: H8-3
A10: 机器设备 | D10: 7 | E10: 租赁的识别 | F10: H8-4
A11: 运输设备 | D11: 8 | E11: 租赁期的确定 | F11: H8-5
A12: 办公设备 | D12: 9 | E12: 使用权资产 租赁负债初始及后续计量（按年） | F12: H8-6 | G12: 选择使用
A13: 其他设备 | D13: 10 | E13: 使用权资产 租赁负债初始及后续计量（按月） | F13: H8-6 | G13: 选择使用
A14: …… | D14: 11 | E14: 租赁变更 | F14: H8-7
D15: 12 | E15: 折旧测算表（不含减值） | F15: H8-8 | G15: 选择使用
A16: 关于工作底稿与审计程序索引号对应的说明 | D16: 13 | E16: 折旧测算表（含减值） | F16: H8-8 | G16: 选择使用
A17: 1.编制的审计工作底稿应与审计程序对应。审计项目组应根据被审计单位实际情况和风险评估情况在实质性程序表中裁剪、修改或增加审计程序，根据实际执行的审计程序完成相应审计工作底稿，编制的工作底稿中应按自然顺序依次编制索引号，并通过唯一的索引号将与实质性程序表中的程序对应关联（即将工作底稿的索引号填入实质性程序表中的底稿索引号列）。 | D17: 14 | E17: 折旧分配分析表 | F17: H8-9
D18: 15 | E18: 减值测算表 | F18: H8-10
D19: 16 | E19: 可收回金额测试表 | F19: H8-11
D20: 17 | E20: 减少检查表 | F20: H8-12
A21: 2.获取的支持性证据应与审计底稿或程序对应。审计项目组在完成底稿时获取的支持性证据应根据底稿索引号编制下一级按自然顺序排序的索引号（如D1-2-1、D1-2-2、……），并在底稿中说明引用的支持性证据、关联索引号。 | D21: 18 | E21: 简化处理的租赁检查表 | F21: H8-13
D22: 19 | E22: 关联交易检查表 | F22: H8-14
A24: 3.工作底稿索引号的编码规则：实质性程序索引号按循环从“D”到“N”,循环内账户以顺序号排列，模板中底稿索引号按账户顺序+自然数顺序（即模板中索引号按二级自然顺序排列，如D1-1、D1-2、D1-3、……D1-N）。

Sheet 使用权资产实质性程序表H8A
A1: 致同会计师事务所
A2: 使用权资产实质性程序表
A3: =底稿目录!A2 -> 被审计单位： | C3: =底稿目录!A4 -> 编制人： | E3: =底稿目录!A6 -> 编制日期： | H3: 索引号： | I3: H8A
A4: =底稿目录!A3 -> 截止日：202X年12月31日 | C4: =底稿目录!A5 -> 复核人： | E4: =底稿目录!A7 -> 复核日期： | H4: 页 次：
A5: 一、本账户涉及的科目
A6: 使用权资产、累计折旧、减值准备
A7: 二、审计目标与认定的对应关系
A8: 审计目标 | G8: 财务报表的认定
A9: A. 资产负债表中记录的使用权资产是存在的，且已记录于恰当的账户 | G9: 存在
A10: B. 所有应记录的使用权资产均已记录，所有应当包括在财务报表中的相关披露均已包括 | G10: 完整性
A11: C. 记录的使用权资产由被审计单位拥有或控制； | G11: 权利和义务
A12: D. 使用权资产以恰当的金额包括在财务报表中，与之相关的计价或分摊调整已恰当记录，相关披露已得到恰当计量和描述 | G12: 准确性、计价和分摊
A13: E. 使用权资产已被恰当地汇总或分解且表述清楚，相关披露在按照企业会计准则的编制基础下是相关的、可理解的 | G13: 列报
A14: 三、计划实施的实质性程序
A15: 序号 | B15: 审计程序 | C15: 程序分类 | D15: 财务报表的认定 | I15: 底稿索引号
D16: 存在 | E16: 完整性 | F16: 权利和 义务 | G16: 准确性、计价和分摊 | H16: 列报 | J16: 根据被审计单位实际情况和风险评估情况裁剪、修改或增加审计程序
A17: 1 | B17: 获取或编制使用权资产的明细表，完成以下工作，并编制审定表 （1）复核加计是否正确，并与总账数和明细账合计数核对是否相符，期初余额与上期审定期末余额是否相符； （2）分析使用权资产与上期变动情况； （3）询问闲置资产或未入账资产处置情况（如有）。 | C17: 常规★ | D17: √ | E17: √ | G17: √ | I17: H8-1 /H8-2
A18: 2 | B18: 在使用手工编制、自定义信息报告、系统生成的非固定格式报告等由被审计单位生成的信息时，测试有关信息准确性和完整性，并考虑针对编制和维护由被审计单位生成的信息的相关控制实施控制测试，以评价该信息是否能够为实现审计目的提供基础。 | C18: 常规★ | D18: √ | E18: √ | G18: √ | I18: T1 / | J18: 可参见《审计手册》4.2.6，由被审计单位生成的信息可能是由系统生成的、或手工编制的、或二者兼而有之的方式生成的。例如，由被审计单位生成的信息可能包括： • 不涉及自定义的、由系统生成的报告（如，固定格式报告）； • 可能通过人工自定义的、由系统生成的报告，例如，（计算机）查询信息或特别定制的报告； • 手工编制的信息，例如，汇总信息的电子表格或用以支持分配、计算以及调节的电子表格； • 其他系统生成或手工编制的信息，例如，由被审计单位编制的客户发票； • 通过影印、拍摄、扫描或其他方式转换成电子形式的文件记录。
A19: 3 | B19: 对期初余额的审计，取得上期使用权资产明细表复核加计是否正确，与总账、明细账合计数是否相符； 重新测算期初累计折旧余额准确性；对单项金额重大资产，进行实地查看资产或检查支持性文件，其他必要追加的审计程序。（适用于首次承接） | C19: 备选 | D19: √ | E19: √ | F19: √ | G19: √ | J19: 由被审计单位生成的信息不包括： • 总分类账或明细分类账、试算平衡表、或经审计的财务报表； • 第三方（除了服务机构）的报表或报告，例如，原始银行对账单，或函证的回函； • 外部数据（例如，第三方发布的数据，如，定价来源）。
A20: 4 | B20: 关注会计政策、会计估计合理性、一贯性，关注其是否利用会计政策和会计估计及其变更操纵利润。 | C20: 常规★ | D20: √ | E20: √ | G20: √ | I20: H8-1 /H8-2
A21: 5 | B21: 检查相关合同的主要条款，询问被审计单位将该合同识别为租赁或者包含租赁的理由，检查租赁的识别和租赁期的确定是否符合企业会计准则的规定 | C21: 常规★ | D21: √ | F21: √ | I21: H8-4 /H8-5
A22: 6 | B22: 检查使用权资产、租赁负债的初始计量和后续计量： （1）获取相关租赁合同/协议，检查初始直接费用、或有租金确认、折现率是否合理，使用权资产和租赁负债的入账价值是否正确和会计处理是否正确。 （2）当存在续租选择权、购买选择权和终止租赁选择权时，了解被审计单位对是否行使相关权利做出的判断，检查其判断依据是否充分，并评估对使用权资产、租赁负债入账价值的影响； （3）按实际利率法重新计算未确认融资费用摊销、租赁负债余额，计算使用权资产余额，与被审计单位账面记录核对是否一致； （4）重估或租赁变更等原因导致租赁付款额发生变动时，重新计量租赁负债账面价值会计处理是否正确； | C22: 常规★ | D22: √ | E22: √ | F22: √ | G22: √ | I22: H8-6 /H8-7
A23: 7 | B23: 检查累计折旧，考虑执行以下程序： （1）获取或编制使用权资产累计折旧明细表，复核加计是否正确，并与总账数和明细账合计数核对是否相符 （2）检查折旧年限的确定是否恰当；续租选择权、购买选择权和终止租赁选择权对租赁期的影响是否已充分考虑，是否根据租赁的具体情况，已合理选择租赁期或者租赁资产预计剩余使用寿命作为折旧年限 （3）重新计算本期折旧金额是否正确，与相关科目核对是否相符。当存在减值时，是否按照扣除减值损失之后的使用权资产账面价值进行后续折旧 （4）检查折旧分配到成本、费用的情况，关注分配是否合理，与上期分配方法是否一致。 | C23: 常规★ | G23: √ | I23: H8-8 /H8-9
A24: 8 | B24: 监盘使用权资产： （1）取得使用权资产存放地点清单等，初步确定监盘方式、时间、监盘计划； （2）获取被审计单位对于使用权资产的盘点计划，制定和实施监盘计划（如有）； （3）取得使用权资产地点清单，初步确定监盘方式、时间、监盘计划； （4）观察被审计单位制定的盘点程序的执行情况 （5）抽取使用权资产盘点，并检查使用权资产的状态（正常、空置、出租等）； （6）评价使用权资产盘点结果，完成监盘小结。 | C24: 备选 | D24: √ | F24: √ | G24: √ | J24: 具体盘点底稿参考固定资产
A25: 9 | B25: 结合使用权资产清单及资产的实际使用情况，了解使用权资产的状态。针对存在减值迹象的使用权资产，考虑执行下列程序： 获取被审计单位在资产负债表日就使用权资产是否可能发生减值迹象的判断的说明，判断其合理性。对于已计提减值准备的使用权资产，检查减值测试相关参数是否合理，减值准备计提是否正确。如存在管理层聘请评估专家出具的评估报告，复核评估报告。 | C25: 常规★ | G25: √ | I25: H8-10 /H8-11
A26: 10 | B26: 检查本期使用权资产的减少： （1）对于因不再使用租赁资产导致的减少，检查使用权资产减少是否与租赁合同/协议约定的租赁结束日一致，租赁资产移交手续是否齐全，会计处理是否正确； （2）对于因转租使用权资产形成融资租赁导致的减少，获取转租合同，检查转租手续是否齐全，判断其会计处理是否正确。 | C26: 常规★ | D26: √ | E26: √ | G26: √ | I26: H8-12
A27: 11 | B27: 当存在将短期租赁和低价值资产租赁进行简化处理情形时，对本期直接计入当期损益的短期租赁费用和低价值资产租赁费用进行复核； | C27: 常规★ | E27: √ | G27: √ | I27: H8-13
A28: 12 | B28: 检查关联交易情况，检查关联交易的真实性、合理性及合规性；检查关联交易会计处理是否正确，考虑是否存在未识别的关联方，检查关联交易和余额披露是否正确。 | C28: 常规★ | D28: √ | E28: √ | F28: √ | G28: √ | H28: √ | I28: H8-14
A29: 13 | B29: 必要时函证租赁资产、租赁期、应付和已付租金、租赁条款等信息。 | C29: IPO/上市/新三板/重组/舞弊应对 | D29: √ | F29: √ | G29: √ | I29: H0
A30: 14 | B30: 根据评估的舞弊风险等因素增加的审计程序。 | C30: IPO/上市/新三板/重组/舞弊应对
A31: 15 | B31: 检查使用权资产是否已按企业会计准则或其他适用的规定在财务报表中做出恰当列报和披露 | C31: 常规★ | H31: √ | I31: A 1-1/A1-15 /A1-16

Sheet 审定表H8-1
A1: 致同会计师事务所
A2: 使用权资产、累计折旧及减值准备审定表
A3: =底稿目录!A2 -> 被审计单位： | C3: =底稿目录!A4 -> 编制人： | F3: =底稿目录!A6 -> 编制日期： | H3: 索引号： | I3: H8-1
A4: =底稿目录!A3 -> 截止日：202X年12月31日 | C4: =底稿目录!A5 -> 复核人： | F4: =底稿目录!A7 -> 复核日期： | H4: 页 次：
A5: 项目 | B5: 期初数 | E5: 期末数 | H5: 本期审定数与上期 审定数的比较
B6: 未审数 | C6: 账项调整 | D6: 审定数 | E6: 未审数 | F6: 账项调整 | G6: 审定数 | H6: 变动额 | I6: 变动率
A7: 一、使用权资产原值
A8: =底稿目录!A9 -> 房屋及建筑物 | B8: ='明细表H8-2'!D34 -> 0 | C8: ='明细表H8-2'!L34 -> 0 | D8: =B8+C8 -> 0 | E8: ='明细表H8-2'!K34 -> 0 | F8: ='明细表H8-2'!L34+'明细表H8-2'!M34+'明细表H8-2'!N34+'明细表H8-2'!O34-'明细表H8-2'!P34-'明细表H8-2'!Q34-'明细表H8-2'!R34 -> 0 | G8: =E8+F8 -> 0 | H8: =G8-D8 -> 0 | I8: =IF(AND(D8=0,H8=0),0,IF(AND(D8=0,H8>0),1,H8/D8)) -> 0
A9: =底稿目录!A10 -> 机器设备 | B9: ='明细表H8-2'!D35 -> 0 | C9: ='明细表H8-2'!L35 -> 0 | D9: =B9+C9 -> 0 | E9: ='明细表H8-2'!K35 -> 0 | F9: ='明细表H8-2'!L35+'明细表H8-2'!M35+'明细表H8-2'!N35+'明细表H8-2'!O35-'明细表H8-2'!P35-'明细表H8-2'!Q35-'明细表H8-2'!R35 -> 0 | G9: =E9+F9 -> 0 | H9: =G9-D9 -> 0 | I9: =IF(AND(D9=0,H9=0),0,IF(AND(D9=0,H9>0),1,H9/D9)) -> 0
A10: =底稿目录!A11 -> 运输设备 | B10: ='明细表H8-2'!D36 -> 0 | C10: ='明细表H8-2'!L36 -> 0 | D10: =B10+C10 -> 0 | E10: ='明细表H8-2'!K36 -> 0 | F10: ='明细表H8-2'!L36+'明细表H8-2'!M36+'明细表H8-2'!N36+'明细表H8-2'!O36-'明细表H8-2'!P36-'明细表H8-2'!Q36-'明细表H8-2'!R36 -> 0 | G10: =E10+F10 -> 0 | H10: =G10-D10 -> 0 | I10: =IF(AND(D10=0,H10=0),0,IF(AND(D10=0,H10>0),1,H10/D10)) -> 0
A11: =底稿目录!A12 -> 办公设备 | B11: ='明细表H8-2'!D37 -> 0 | C11: ='明细表H8-2'!L37 -> 0 | D11: =B11+C11 -> 0 | E11: ='明细表H8-2'!K37 -> 0 | F11: ='明细表H8-2'!L37+'明细表H8-2'!M37+'明细表H8-2'!N37+'明细表H8-2'!O37-'明细表H8-2'!P37-'明细表H8-2'!Q37-'明细表H8-2'!R37 -> 0 | G11: =E11+F11 -> 0 | H11: =G11-D11 -> 0 | I11: =IF(AND(D11=0,H11=0),0,IF(AND(D11=0,H11>0),1,H11/D11)) -> 0
A12: =底稿目录!A13 -> 其他设备 | B12: ='明细表H8-2'!D38 -> 0 | C12: ='明细表H8-2'!L38 -> 0 | D12: =B12+C12 -> 0 | E12: ='明细表H8-2'!K38 -> 0 | F12: ='明细表H8-2'!L38+'明细表H8-2'!M38+'明细表H8-2'!N38+'明细表H8-2'!O38-'明细表H8-2'!P38-'明细表H8-2'!Q38-'明细表H8-2'!R38 -> 0 | G12: =E12+F12 -> 0 | H12: =G12-D12 -> 0 | I12: =IF(AND(D12=0,H12=0),0,IF(AND(D12=0,H12>0),1,H12/D12)) -> 0
A13: 合计 | B13: =SUM(B8:B12) -> 0 | C13: =SUM(C8:C12) -> 0 | D13: =SUM(D8:D12) -> 0 | E13: =SUM(E8:E12) -> 0 | F13: =SUM(F8:F12) -> 0 | G13: =SUM(G8:G12) -> 0 | H13: =G13-D13 -> 0 | I13: =IF(AND(D13=0,H13=0),0,IF(AND(D13=0,H13>0),1,H13/D13)) -> 0
A14: 二、累计折旧
A15: =A8 -> 房屋及建筑物 | B15: ='明细表H8-2'!W34 -> 0 | C15: ='明细表H8-2'!AD34 -> 0 | D15: =B15+C15 -> 0 | E15: ='明细表H8-2'!AC34 -> 0 | F15: ='明细表H8-2'!AD34+'明细表H8-2'!AE34+'明细表H8-2'!AF34-'明细表H8-2'!AG34-'明细表H8-2'!AH34-'明细表H8-2'!AI34 -> 0 | G15: =E15+F15 -> 0 | H15: =G15-D15 -> 0 | I15: =IF(AND(D15=0,H15=0),0,IF(AND(D15=0,H15>0),1,H15/D15)) -> 0
A16: =A9 -> 机器设备 | B16: ='明细表H8-2'!W35 -> 0 | C16: ='明细表H8-2'!AD35 -> 0 | D16: =B16+C16 -> 0 | E16: ='明细表H8-2'!AC35 -> 0 | F16: ='明细表H8-2'!AD35+'明细表H8-2'!AE35+'明细表H8-2'!AF35-'明细表H8-2'!AG35-'明细表H8-2'!AH35-'明细表H8-2'!AI35 -> 0 | G16: =E16+F16 -> 0 | H16: =G16-D16 -> 0 | I16: =IF(AND(D16=0,H16=0),0,IF(AND(D16=0,H16>0),1,H16/D16)) -> 0
A17: =A10 -> 运输设备 | B17: ='明细表H8-2'!W36 -> 0 | C17: ='明细表H8-2'!AD36 -> 0 | D17: =B17+C17 -> 0 | E17: ='明细表H8-2'!AC36 -> 0 | F17: ='明细表H8-2'!AD36+'明细表H8-2'!AE36+'明细表H8-2'!AF36-'明细表H8-2'!AG36-'明细表H8-2'!AH36-'明细表H8-2'!AI36 -> 0 | G17: =E17+F17 -> 0 | H17: =G17-D17 -> 0 | I17: =IF(AND(D17=0,H17=0),0,IF(AND(D17=0,H17>0),1,H17/D17)) -> 0
A18: =A11 -> 办公设备 | B18: ='明细表H8-2'!W37 -> 0 | C18: ='明细表H8-2'!AD37 -> 0 | D18: =B18+C18 -> 0 | E18: ='明细表H8-2'!AC37 -> 0 | F18: ='明细表H8-2'!AD37+'明细表H8-2'!AE37+'明细表H8-2'!AF37-'明细表H8-2'!AG37-'明细表H8-2'!AH37-'明细表H8-2'!AI37 -> 0 | G18: =E18+F18 -> 0 | H18: =G18-D18 -> 0 | I18: =IF(AND(D18=0,H18=0),0,IF(AND(D18=0,H18>0),1,H18/D18)) -> 0
A19: =A12 -> 其他设备 | B19: ='明细表H8-2'!W38 -> 0 | C19: ='明细表H8-2'!AD38 -> 0 | D19: =B19+C19 -> 0 | E19: ='明细表H8-2'!AC38 -> 0 | F19: ='明细表H8-2'!AD38+'明细表H8-2'!AE38+'明细表H8-2'!AF38-'明细表H8-2'!AG38-'明细表H8-2'!AH38-'明细表H8-2'!AI38 -> 0 | G19: =E19+F19 -> 0 | H19: =G19-D19 -> 0 | I19: =IF(AND(D19=0,H19=0),0,IF(AND(D19=0,H19>0),1,H19/D19)) -> 0
A20: 合计 | B20: =SUM(B15:B19) -> 0 | C20: =SUM(C15:C19) -> 0 | D20: =SUM(D15:D19) -> 0 | E20: =SUM(E15:E19) -> 0 | F20: =SUM(F15:F19) -> 0 | G20: =SUM(G15:G19) -> 0 | H20: =G20-D20 -> 0 | I20: =IF(AND(D20=0,H20=0),0,IF(AND(D20=0,H20>0),1,H20/D20)) -> 0
A21: 三、减值准备
A22: =A15 -> 房屋及建筑物 | B22: ='明细表H8-2'!AN34 -> 0 | C22: ='明细表H8-2'!AU34 -> 0 | D22: =B22+C22 -> 0 | E22: ='明细表H8-2'!AT34 -> 0 | F22: ='明细表H8-2'!AU34+'明细表H8-2'!AV34+'明细表H8-2'!AW34-'明细表H8-2'!AX34-'明细表H8-2'!AY34-'明细表H8-2'!AZ34 -> 0 | G22: =E22+F22 -> 0 | H22: =G22-D22 -> 0 | I22: =IF(AND(D22=0,H22=0),0,IF(AND(D22=0,H22>0),1,H22/D22)) -> 0
A23: =A16 -> 机器设备 | B23: ='明细表H8-2'!AN35 -> 0 | C23: ='明细表H8-2'!AU35 -> 0 | D23: =B23+C23 -> 0 | E23: ='明细表H8-2'!AT35 -> 0 | F23: ='明细表H8-2'!AU35+'明细表H8-2'!AV35+'明细表H8-2'!AW35-'明细表H8-2'!AX35-'明细表H8-2'!AY35-'明细表H8-2'!AZ35 -> 0 | G23: =E23+F23 -> 0 | H23: =G23-D23 -> 0 | I23: =IF(AND(D23=0,H23=0),0,IF(AND(D23=0,H23>0),1,H23/D23)) -> 0
A24: =A17 -> 运输设备 | B24: ='明细表H8-2'!AN36 -> 0 | C24: ='明细表H8-2'!AU36 -> 0 | D24: =B24+C24 -> 0 | E24: ='明细表H8-2'!AT36 -> 0 | F24: ='明细表H8-2'!AU36+'明细表H8-2'!AV36+'明细表H8-2'!AW36-'明细表H8-2'!AX36-'明细表H8-2'!AY36-'明细表H8-2'!AZ36 -> 0 | G24: =E24+F24 -> 0 | H24: =G24-D24 -> 0 | I24: =IF(AND(D24=0,H24=0),0,IF(AND(D24=0,H24>0),1,H24/D24)) -> 0
A25: =A18 -> 办公设备 | B25: ='明细表H8-2'!AN37 -> 0 | C25: ='明细表H8-2'!AU37 -> 0 | D25: =B25+C25 -> 0 | E25: ='明细表H8-2'!AT37 -> 0 | F25: ='明细表H8-2'!AU37+'明细表H8-2'!AV37+'明细表H8-2'!AW37-'明细表H8-2'!AX37-'明细表H8-2'!AY37-'明细表H8-2'!AZ37 -> 0 | G25: =E25+F25 -> 0 | H25: =G25-D25 -> 0 | I25: =IF(AND(D25=0,H25=0),0,IF(AND(D25=0,H25>0),1,H25/D25)) -> 0
A26: =A19 -> 其他设备 | B26: ='明细表H8-2'!AN38 -> 0 | C26: ='明细表H8-2'!AU38 -> 0 | D26: =B26+C26 -> 0 | E26: ='明细表H8-2'!AT38 -> 0 | F26: ='明细表H8-2'!AU38+'明细表H8-2'!AV38+'明细表H8-2'!AW38-'明细表H8-2'!AX38-'明细表H8-2'!AY38-'明细表H8-2'!AZ38 -> 0 | G26: =E26+F26 -> 0 | H26: =G26-D26 -> 0 | I26: =IF(AND(D26=0,H26=0),0,IF(AND(D26=0,H26>0),1,H26/D26)) -> 0
A27: 合计 | B27: =SUM(B22:B26) -> 0 | C27: =SUM(C22:C26) -> 0 | D27: =SUM(D22:D26) -> 0 | E27: =SUM(E22:E26) -> 0 | F27: =SUM(F22:F26) -> 0 | G27: =SUM(G22:G26) -> 0 | H27: =G27-D27 -> 0 | I27: =IF(AND(D27=0,H27=0),0,IF(AND(D27=0,H27>0),1,H27/D27)) -> 0
A28: 四、净值
A29: =A22 -> 房屋及建筑物 | B29: =B8-B15-B22 -> 0 | C29: =C8-C15-C22 -> 0 | D29: =D8-D15-D22 -> 0 | E29: =E8-E15-E22 -> 0 | F29: =F8-F15-F22 -> 0 | G29: =G8-G15-G22 -> 0 | H29: =G29-D29 -> 0 | I29: =IF(AND(D29=0,H29=0),0,IF(AND(D29=0,H29>0),1,H29/D29)) -> 0
A30: =A23 -> 机器设备 | B30: =B9-B16-B23 -> 0 | C30: =C9-C16-C23 -> 0 | D30: =D9-D16-D23 -> 0 | E30: =E9-E16-E23 -> 0 | F30: =F9-F16-F23 -> 0 | G30: =G9-G16-G23 -> 0 | H30: =G30-D30 -> 0 | I30: =IF(AND(D30=0,H30=0),0,IF(AND(D30=0,H30>0),1,H30/D30)) -> 0
A31: =A24 -> 运输设备 | B31: =B10-B17-B24 -> 0 | C31: =C10-C17-C24 -> 0 | D31: =D10-D17-D24 -> 0 | E31: =E10-E17-E24 -> 0 | F31: =F10-F17-F24 -> 0 | G31: =G10-G17-G24 -> 0 | H31: =G31-D31 -> 0 | I31: =IF(AND(D31=0,H31=0),0,IF(AND(D31=0,H31>0),1,H31/D31)) -> 0
A32: =A25 -> 办公设备 | B32: =B11-B18-B25 -> 0 | C32: =C11-C18-C25 -> 0 | D32: =D11-D18-D25 -> 0 | E32: =E11-E18-E25 -> 0 | F32: =F11-F18-F25 -> 0 | G32: =G11-G18-G25 -> 0 | H32: =G32-D32 -> 0 | I32: =IF(AND(D32=0,H32=0),0,IF(AND(D32=0,H32>0),1,H32/D32)) -> 0
A33: =A26 -> 其他设备 | B33: =B12-B19-B26 -> 0 | C33: =C12-C19-C26 -> 0 | D33: =D12-D19-D26 -> 0 | E33: =E12-E19-E26 -> 0 | F33: =F12-F19-F26 -> 0 | G33: =G12-G19-G26 -> 0 | H33: =G33-D33 -> 0 | I33: =IF(AND(D33=0,H33=0),0,IF(AND(D33=0,H33>0),1,H33/D33)) -> 0
A34: 合计 | B34: =SUM(B29:B33) -> 0 | C34: =SUM(C29:C33) -> 0 | D34: =SUM(D29:D33) -> 0 | E34: =SUM(E29:E33) -> 0 | F34: =SUM(F29:F33) -> 0 | G34: =SUM(G29:G33) -> 0 | H34: =G34-D34 -> 0 | I34: =IF(AND(D34=0,H34=0),0,IF(AND(D34=0,H34>0),1,H34/D34)) -> 0
A35: 试算平衡表数
A36: 差异 | D36: =D34-D35 -> 0 | G36: =G34-G35 -> 0
A37: 1、审计说明：
A38: （1）使用权资产期末净值较期初净值增加（负数为减少）：
A39: 主要原因（比例超过30%的）：
A41: （2）采用简化处理方法的情况说明：（短期租赁、低价值资产和未纳入租赁负债计量的可变租赁付款额当期计入费用的情况）
...

Sheet 附注披露信息（上市公司）
A1: 致同会计师事务所
A2: 附注披露表（上市公司）
A3: =底稿目录!A2 -> 被审计单位： | C3: =底稿目录!A4 -> 编制人： | E3: =底稿目录!A6 -> 编制日期： | F3: 索引号：
A4: =底稿目录!A3 -> 截止日：202X年12月31日 | C4: =底稿目录!A5 -> 复核人： | E4: =底稿目录!A7 -> 复核日期： | F4: 页 次：
A6: 项 目 | B6: 房屋及建筑物 | C6: 机器设备 | D6: 运输设备 | E6: …… | F6: 合 计 | G6: 返回目录
A7: 一、账面原值：
A8: 1.期初余额
A9: 2.本期增加金额
A10: （1）租入
A11: （2）租赁负债调整
A12: ……
A13: 3.本期减少金额
A14: （1）转租赁为融资租赁
A15: （2）转让或持有待售
A16: （3）其他减少
A17: ……
A18: 4. 期末余额
... A48: 注意：1、本年执行减值测试的，即使未计提减值，也要参照上述要求披露。2、估计可收回金额时通常不应使用重置成本法。】

Sheet 附注披露信息（国企）
A1: 致同会计师事务所
A2: 附注披露信息（国有企业）
A3: =底稿目录!A2 -> 被审计单位： | B3: =底稿目录!A4 -> 编制人： | D3: =底稿目录!A6 -> 编制日期： | E3: 索引号：
A4: =底稿目录!A3 -> 截止日：202X年12月31日 | B4: =底稿目录!A5 -> 复核人： | D4: =底稿目录!A7 -> 复核日期： | E4: 页 次：
A6: 项 目 | B6: 期初余额 | C6: 本期增加 | D6: 本期减少 | E6: 期末余额 | F6: 返回目录
A7: 一、账面原值合计 | B7: XX | C7: XX | D7: XX | E7: XX
A8: 其中：土地
A9: 房屋、建筑物
A10: 机器、运输、办公设备
A11: 其他
A12: 二、累计折旧合计 | B12: XX | C12: XX | D12: XX | E12: XX
A13: 其中：土地
A14: 房屋、建筑物
A15: 机器、运输、办公设备
A16: 其他
A17: 三、使用权资产账面净值合计 | B17: XX | C17: —— | D17: —— | E17: XX
A18: 其中：土地 | C18: —— | D18: ——
A19: 房屋、建筑物 | C19: —— | D19: ——
A20: 机器、运输、办公设备 | C20: —— | D20: ——
A21: 其他 | C21: —— | D21: ——
A22: 四、减值准备合计 | B22: XX | C22: XX | D22: XX | E22: XX
A23: 其中：土地
A24: 房屋、建筑物
A25: 机器、运输、办公设备
A26: 其他 | B26: XX | C26: XX | D26: XX | E26: XX
A27: 五、使用权资产账面价值合计 | B27: XX | C27: —— | D27: —— | E27: XX
A28: 其中：土地 | C28: —— | D28: ——
A29: 房屋、建筑物 | C29: —— | D29: ——
A30: 机器、运输、办公设备 | C30: —— | D30: ——
A31: 其他 | B31: XX | C31: —— | D31: —— | E31: XX

Sheet 明细表H8-2
A1: 致同会计师事务所 | W1: 致同会计师事务所 | AN1: 致同会计师事务所
A2: 使用权资产、累计折旧及减值准备明细表 | W2: 使用权资产、累计折旧及减值准备明细表 | AN2: 使用权资产、累计折旧及减值准备明细表
A3: =底稿目录!A2 -> 被审计单位： | G3: =底稿目录!A4 -> 编制人： | P3: =底稿目录!A6 -> 编制日期： | U3: 索引号： | V3: H8-2 | AC3: =底稿目录!A4 -> 编制人： | AI3: =底稿目录!A6 -> 编制日期： | AL3: 索引号： | AM3: H8-2 | AT3: =底稿目录!A4 -> 编制人： | BA3: =AI3 -> 编制日期： | BE3: 索引号： | BF3: H8-2
A4: =底稿目录!A3 -> 截止日：202X年12月31日 | G4: =底稿目录!A5 -> 复核人： | P4: =底稿目录!A7 -> 复核日期： | U4: 页 次： | AC4: =底稿目录!A5 -> 复核人： | AI4: =底稿目录!A7 -> 复核日期： | AL4: 页 次： | AT4: =底稿目录!A5 -> 复核人： | BA4: =AI4 -> 复核日期： | BE4: 页 次：
A5: 一、审计目标：
A6: 1. 资产负债表中记录的使用权资产是存在的，且已记录于恰当的账户；2. 所有应记录的使用权资产均已记录，所有应当包括在财务报表中的相关披露均已包括；3.使用权资产以恰当的金额包括在财务报表中，与之相关的计价或分摊调整已恰当记录，相关披露已得到恰当计量和描述。
A7: 二、审计过程：
A8: 使用权资产类别 | B8: 使用权资产名称 | C8: 使用权资产编号 | D8: 使用权资产原值 | W8: 累计折旧 | AN8: 减值准备 | BE8: 审定净值
D9: 期初数 | E9: 未审数 | L9: 期初调整 | M9: 账项调整 | S9: 审定数 | W9: 期初数 | X9: 未审数 | AD9: 期初调整 | AE9: 账项调整 | AJ9: 审定数 | AN9: 期初数 | AO9: 未审数 | AU9: 期初调整 | AV9: 账项调整 | BA9: 审定数
E10: 本期增加 | H10: 本期减少 | K10: 期末数 | M10: 本期增加 | P10: 本期减少 | S10: 期初数 | T10: 本期增加 | U10: 本期减少 | V10: 期末数 | X10: 本期增加 | Z10: 本期减少 | AC10: 期末数 | AE10: 本期增加 | AG10: 本期减少 | AJ10: 期初数 | AK10: 本期增加 | AL10: 本期减少 | AM10: 期末数 | AO10: 本期增加 | AQ10: 本期减少 | AT10: 期末数 | AV10: 本期增加 | AX10: 本期减少 | BA10: 期初数 | BB10: 本期增加 | BC10: 本期减少 | BD10: 期末数 | BE10: 期初净值 | BF10: 期末净值
E11: 本期租入 | F11: 租赁负债调整 | G11: 其他增加 | H11: 转租赁为融资租赁 | I11: 转让或持有待售 | J11: 其他减少 | M11: 本期租入 | N11: 租赁负债调整 | O11: 其他增加 | P11: 转租赁为融资租赁 | Q11: 转让或持有待售 | R11: 其他减少 | X11: 本期计提 | Y11: 其他增加 | Z11: 转租赁为融资租赁 | AA11: 转让或持有待售 | AB11: 其他减少 | AE11: 本期计提 | AF11: 其他增加 | AG11: 转租赁为融资租赁 | AH11: 转让或持有待售 | AI11: 其他减少 | AO11: 本期计提 | AP11: 其他增加 | AQ11: 转租赁为融资租赁 | AR11: 转让或持有待售 | AS11: 其他减少 | AV11: 本期计提 | AW11: 其他增加 | AX11: 转租赁为融资租赁 | AY11: 转让或持有待售 | AZ11: 其他减少
K12: =SUM(D12:G12)-SUM(H12:J12) -> 0 | S12: =D12+L12 -> 0 | T12: =(E12+F12+G12)+M12+N12+O12 -> 0 | U12: =(H12+I12+J12)+P12+Q12+R12 -> 0 | V12: =S12+T12-U12 -> 0 | AC12: =SUM(W12:Y12)-SUM(Z12:AB12) -> 0 | AJ12: =W12+AD12 -> 0 | AK12: =X12+AE12+Y12+AF12 -> 0 | AL12: =Z12+AI12+AB12+AA12+AG12+AH12 -> 0 | AM12: =AJ12+AK12-AL12 -> 0 | AT12: =SUM(AN12:AP12)-SUM(AQ12:AS12) -> 0 | BA12: =AN12+AU12 -> 0 | BB12: =AO12+AV12+AP12+AW12 -> 0 | BC12: =AQ12+AZ12+AS12+AR12+AX12+AY12 -> 0 | BD12: =BA12+BB12-BC12 -> 0 | BE12: =S12-AJ12-BA12 -> 0 | BF12: =V12-AM12-BD12 -> 0
K13: =SUM(D13:G13)-SUM(H13:J13) -> 0 | S13: =D13+L13 -> 0 | T13: =(E13+F13+G13)+M13+N13+O13 -> 0 | U13: =(H13+I13+J13)+P13+Q13+R13 -> 0 | V13: =S13+T13-U13 -> 0 | AC13: =SUM(W13:Y13)-SUM(Z13:AB13) -> 0 | AJ13: =W13+AD13 -> 0 | AK13: =X13+AE13+Y13+AF13 -> 0 | AL13: =Z13+AI13+AB13+AA13+AG13+AH13 -> 0 | AM13: =AJ13+AK13-AL13 -> 0 | AT13: =SUM(AN13:AP13)-SUM(AQ13:AS13) -> 0 | BA13: =AN13+AU13 -> 0 | BB13: =AO13+AV13+AP13+AW13 -> 0 | BC13: =AQ13+AZ13+AS13+AR13+AX13+AY13 -> 0 | BD13: =BA13+BB13-BC13 -> 0 | BE13: =S13-AJ13-BA13 -> 0 | BF13: =V13-AM13-BD13 -> 0
K14: =SUM(D14:G14)-SUM(H14:J14) -> 0 | S14: =D14+L14 -> 0 | T14: =(E14+F14+G14)+M14+N14+O14 -> 0 | U14: =(H14+I14+J14)+P14+Q14+R14 -> 0 | V14: =S14+T14-U14 -> 0 | AC14: =SUM(W14:Y14)-SUM(Z14:AB14) -> 0 | AJ14: =W14+AD14 -> 0 | AK14: =X14+AE14+Y14+AF14 -> 0 | AL14: =Z14+AI14+AB14+AA14+AG14+AH14 -> 0 | AM14: =AJ14+AK14-AL14 -> 0 | AT14: =SUM(AN14:AP14)-SUM(AQ14:AS14) -> 0 | BA14: =AN14+AU14 -> 0 | BB14: =AO14+AV14+AP14+AW14 -> 0 | BC14: =AQ14+AZ14+AS14+AR14+AX14+AY14 -> 0 | BD14: =BA14+BB14-BC14 -> 0 | BE14: =S14-AJ14-BA14 -> 0 | BF14: =V14-AM14-BD14 -> 0
K15: =SUM(D15:G15)-SUM(H15:J15) -> 0 | S15: =D15+L15 -> 0 | T15: =(E15+F15+G15)+M15+N15+O15 -> 0 | U15: =(H15+I15+J15)+P15+Q15+R15 -> 0 | V15: =S15+T15-U15 -> 0 | AC15: =SUM(W15:Y15)-SUM(Z15:AB15) -> 0 | AJ15: =W15+AD15 -> 0 | AK15: =X15+AE15+Y15+AF15 -> 0 | AL15: =Z15+AI15+AB15+AA15+AG15+AH15 -> 0 | AM15: =AJ15+AK15-AL15 -> 0 | AT15: =SUM(AN15:AP15)-SUM(AQ15:AS15) -> 0 | BA15: =AN15+AU15 -> 0 | BB15: =AO15+AV15+AP15+AW15 -> 0 | BC15: =AQ15+AZ15+AS15+AR15+AX15+AY15 -> 0 | BD15: =BA15+BB15-BC15 -> 0 | BE15: =S15-AJ15-BA15 -> 0 | BF15: =V15-AM15-BD15 -> 0
K16: =SUM(D16:G16)-SUM(H16:J16) -> 0 | S16: =D16+L16 -> 0 | T16: =(E16+F16+G16)+M16+N16+O16 -> 0 | U16: =(H16+I16+J16)+P16+Q16+R16 -> 0 | V16: =S16+T16-U16 -> 0 | AC16: =SUM(W16:Y16)-SUM(Z16:AB16) -> 0 | AJ16: =W16+AD16 -> 0 | AK16: =X16+AE16+Y16+AF16 -> 0 | AL16: =Z16+AI16+AB16+AA16+AG16+AH16 -> 0 | AM16: =AJ16+AK16-AL16 -> 0 | AT16: =SUM(AN16:AP16)-SUM(AQ16:AS16) -> 0 | BA16: =AN16+AU16 -> 0 | BB16: =AO16+AV16+AP16+AW16 -> 0 | BC16: =AQ16+AZ16+AS16+AR16+AX16+AY16 -> 0 | BD16: =BA16+BB16-BC16 -> 0 | BE16: =S16-AJ16-BA16 -> 0 | BF16: =V16-AM16-BD16 -> 0
K17: =SUM(D17:G17)-SUM(H17:J17) -> 0 | S17: =D17+L17 -> 0 | T17: =(E17+F17+G17)+M17+N17+O17 -> 0 | U17: =(H17+I17+J17)+P17+Q17+R17 -> 0 | V17: =S17+T17-U17 -> 0 | AC17: =SUM(W17:Y17)-SUM(Z17:AB17) -> 0 | AJ17: =W17+AD17 -> 0 | AK17: =X17+AE17+Y17+AF17 -> 0 | AL17: =Z17+AI17+AB17+AA17+AG17+AH17 -> 0 | AM17: =AJ17+AK17-AL17 -> 0 | AT17: =SUM(AN17:AP17)-SUM(AQ17:AS17) -> 0 | BA17: =AN17+AU17 -> 0 | BB17: =AO17+AV17+AP17+AW17 -> 0 | BC17: =AQ17+AZ17+AS17+AR17+AX17+AY17 -> 0 | BD17: =BA17+BB17-BC17 -> 0 | BE17: =S17-AJ17-BA17 -> 0 | BF17: =V17-AM17-BD17 -> 0
K18: =SUM(D18:G18)-SUM(H18:J18) -> 0 | S18: =D18+L18 -> 0 | T18: =(E18+F18+G18)+M18+N18+O18 -> 0 | U18: =(H18+I18+J18)+P18+Q18+R18 -> 0 | V18: =S18+T18-U18 -> 0 | AC18: =SUM(W18:Y18)-SUM(Z18:AB18) -> 0 | AJ18: =W18+AD18 -> 0 | AK18: =X18+AE18+Y18+AF18 -> 0 | AL18: =Z18+AI18+AB18+AA18+AG18+AH18 -> 0 | AM18: =AJ18+AK18-AL18 -> 0 | AT18: =SUM(AN18:AP18)-SUM(AQ18:AS18) -> 0 | BA18: =AN18+AU18 -> 0 | BB18: =AO18+AV18+AP18+AW18 -> 0 | BC18: =AQ18+AZ18+AS18+AR18+AX18+AY18 -> 0 | BD18: =BA18+BB18-BC18 -> 0 | BE18: =S18-AJ18-BA18 -> 0 | BF18: =V18-AM18-BD18 -> 0
K19: =SUM(D19:G19)-SUM(H19:J19) -> 0 | S19: =D19+L19 -> 0 | T19: =(E19+F19+G19)+M19+N19+O19 -> 0 | U19: =(H19+I19+J19)+P19+Q19+R19 -> 0 | V19: =S19+T19-U19 -> 0 | AC19: =SUM(W19:Y19)-SUM(Z19:AB19) -> 0 | AJ19: =W19+AD19 -> 0 | AK19: =X19+AE19+Y19+AF19 -> 0 | AL19: =Z19+AI19+AB19+AA19+AG19+AH19 -> 0 | AM19: =AJ19+AK19-AL19 -> 0 | AT19: =SUM(AN19:AP19)-SUM(AQ19:AS19) -> 0 | BA19: =AN19+AU19 -> 0 | BB19: =AO19+AV19+AP19+AW19 -> 0 | BC19: =AQ19+AZ19+AS19+AR19+AX19+AY19 -> 0 | BD19: =BA19+BB19-BC19 -> 0 | BE19: =S19-AJ19-BA19 -> 0 | BF19: =V19-AM19-BD19 -> 0
K20: =SUM(D20:G20)-SUM(H20:J20) -> 0 | S20: =D20+L20 -> 0 | T20: =(E20+F20+G20)+M20+N20+O20 -> 0 | U20: =(H20+I20+J20)+P20+Q20+R20 -> 0 | V20: =S20+T20-U20 -> 0 | AC20: =SUM(W20:Y20)-SUM(Z20:AB20) -> 0 | AJ20: =W20+AD20 -> 0 | AK20: =X20+AE20+Y20+AF20 -> 0 | AL20: =Z20+AI20+AB20+AA20+AG20+AH20 -> 0 | AM20: =AJ20+AK20-AL20 -> 0 | AT20: =SUM(AN20:AP20)-SUM(AQ20:AS20) -> 0 | BA20: =AN20+AU20 -> 0 | BB20: =AO20+AV20+AP20+AW20 -> 0 | BC20: =AQ20+AZ20+AS20+AR20+AX20+AY20 -> 0 | BD20: =BA20+BB20-BC20 -> 0 | BE20: =S20-AJ20-BA20 -> 0 | BF20: =V20-AM20-BD20 -> 0
K21: =SUM(D21:G21)-SUM(H21:J21) -> 0 | S21: =D21+L21 -> 0 | T21: =(E21+F21+G21)+M21+N21+O21 -> 0 | U21: =(H21+I21+J21)+P21+Q21+R21 -> 0 | V21: =S21+T21-U21 -> 0 | AC21: =SUM(W21:Y21)-SUM(Z21:AB21) -> 0 | AJ21: =W21+AD21 -> 0 | AK21: =X21+AE21+Y21+AF21 -> 0 | AL21: =Z21+AI21+AB21+AA21+AG21+AH21 -> 0 | AM21: =AJ21+AK21-AL21 -> 0 | AT21: =SUM(AN21:AP21)-SUM(AQ21:AS21) -> 0 | BA21: =AN21+AU21 -> 0 | BB21: =AO21+AV21+AP21+AW21 -> 0 | BC21: =AQ21+AZ21+AS21+AR21+AX21+AY21 -> 0 | BD21: =BA21+BB21-BC21 -> 0 | BE21: =S21-AJ21-BA21 -> 0 | BF21: =V21-AM21-BD21 -> 0
K22: =SUM(D22:G22)-SUM(H22:J22) -> 0 | S22: =D22+L22 -> 0 | T22: =(E22+F22+G22)+M22+N22+O22 -> 0 | U22: =(H22+I22+J22)+P22+Q22+R22 -> 0 | V22: =S22+T22-U22 -> 0 | AC22: =SUM(W22:Y22)-SUM(Z22:AB22) -> 0 | AJ22: =W22+AD22 -> 0 | AK22: =X22+AE22+Y22+AF22 -> 0 | AL22: =Z22+AI22+AB22+AA22+AG22+AH22 -> 0 | AM22: =AJ22+AK22-AL22 -> 0 | AT22: =SUM(AN22:AP22)-SUM(AQ22:AS22) -> 0 | BA22: =AN22+AU22 -> 0 | BB22: =AO22+AV22+AP22+AW22 -> 0 | BC22: =AQ22+AZ22+AS22+AR22+AX22+AY22 -> 0 | BD22: =BA22+BB22-BC22 -> 0 | BE22: =S22-AJ22-BA22 -> 0 | BF22: =V22-AM22-BD22 -> 0
K23: =SUM(D23:G23)-SUM(H23:J23) -> 0 | S23: =D23+L23 -> 0 | T23: =(E23+F23+G23)+M23+N23+O23 -> 0 | U23: =(H23+I23+J23)+P23+Q23+R23 -> 0 | V23: =S23+T23-U23 -> 0 | AC23: =SUM(W23:Y23)-SUM(Z23:AB23) -> 0 | AJ23: =W23+AD23 -> 0 | AK23: =X23+AE23+Y23+AF23 -> 0 | AL23: =Z23+AI23+AB23+AA23+AG23+AH23 -> 0 | AM23: =AJ23+AK23-AL23 -> 0 | AT23: =SUM(AN23:AP23)-SUM(AQ23:AS23) -> 0 | BA23: =AN23+AU23 -> 0 | BB23: =AO23+AV23+AP23+AW23 -> 0 | BC23: =AQ23+AZ23+AS23+AR23+AX23+AY23 -> 0 | BD23: =BA23+BB23-BC23 -> 0 | BE23: =S23-AJ23-BA23 -> 0 | BF23: =V23-AM23-BD23 -> 0
... K31: =SUM(D31:G31)-SUM(H31:J31) -> 0 | S31: =D31+L31 -> 0 | T31: =(E31+F31+G31)+M31+N31+O31 -> 0 | U31: =(H31+I31+J31)+P31+Q31+R31 -> 0 | V31: =S31+T31-U31 -> 0 | AC31: =SUM(W31:Y31)-SUM(Z31:AB31) -> 0 | AJ31: =W31+AD31 -> 0 | AK31: =X31+AE31+Y31+AF31 -> 0 | AL31: =Z31+AI31+AB31+AA31+AG31+AH31 -> 0 | AM31: =AJ31+AK31-AL31 -> 0 | AT31: =SUM(AN31:AP31)-SUM(AQ31:AS31) -> 0 | BA31: =AN31+AU31 -> 0 | BB31: =AO31+AV31+AP31+AW31 -> 0 | BC31: =AQ31+AZ31+AS31+AR31+AX31+AY31 -> 0 | BD31: =BA31+BB31-BC31 -> 0 | BE31: =S31-AJ31-BA31 -> 0 | BF31: =V31-AM31-BD31 -> 0
A32: 合计 | D32: =SUM(D12:D31) -> 0 | E32: =SUM(E12:E31) -> 0 | F32: =SUM(F12:F31) -> 0 | G32: =SUM(G12:G31) -> 0 | H32: =SUM(H12:H31) -> 0 | I32: =SUM(I12:I31) -> 0 | J32: =SUM(J12:J31) -> 0 | K32: =SUM(K12:K31) -> 0 | ... BF32: =SUM(BF12:BF31) -> 0
A33: 其中：
A34: =底稿目录!A9 -> 房屋及建筑物 | D34: =SUMPRODUCT(($A$12:$A$31=$A34)*(D$12:D$31)) -> 0 | E34: =SUMPRODUCT(($A$12:$A$31=$A34)*(E$12:E$31)) -> 0 | F34: =SUMPRODUCT(($A$12:$A$31=$A34)*(F$12:F$31)) -> 0 | G34: =SUMPRODUCT(($A$12:$A$31=$A34)*(G$12:G$31)) -> 0 | H34: =SUMPRODUCT(($A$12:$A$31=$A34)*(H$12:H$31)) -> 0 | I34: =SUMPRODUCT(($A$12:$A$31=$A34)*(I$12:I$31)) -> 0 | J34: =SUMPRODUCT(($A$12:$A$31=$A34)*(J$12:J$31)) -> 0 | K34: =SUMPRODUCT(($A$12:$A$31=$A34)*(K$12:K$31)) -> 0 | ... BF34: =SUMPRODUCT(($A$12:$A$31=$A34)*(BF$12:BF$31)) -> 0
A35: =底稿目录!A10 -> 机器设备 | D35: =SUMPRODUCT(($A$12:$A$31=$A35)*(D$12:D$31)) -> 0 | E35: =SUMPRODUCT(($A$12:$A$31=$A35)*(E$12:E$31)) -> 0 | F35: =SUMPRODUCT(($A$12:$A$31=$A35)*(F$12:F$31)) -> 0 | G35: =SUMPRODUCT(($A$12:$A$31=$A35)*(G$12:G$31)) -> 0 | H35: =SUMPRODUCT(($A$12:$A$31=$A35)*(H$12:H$31)) -> 0 | I35: =SUMPRODUCT(($A$12:$A$31=$A35)*(I$12:I$31)) -> 0 | J35: =SUMPRODUCT(($A$12:$A$31=$A35)*(J$12:J$31)) -> 0 | K35: =SUMPRODUCT(($A$12:$A$31=$A35)*(K$12:K$31)) -> 0 | ... P35: =SUMPRODUCT(($A$12:$A$31=$A35)*(P$12:P$31)) -> 0 | Q35: {=SUMPRODUCT(($A$12:$A$31=$A35)*(Q$12:Q$31))} -> 0 | R35: {=SUMPRODUCT(($A$12:$A$31=$A35)*(R$12:R$31))} -> 0 | S35: {=SUMPRODUCT(($A$12:$A$31=$A35)*(S$12:S$31))} -> 0 | T35: {=SUMPRODUCT(($A$12:$A$31=$A35)*(T$12:T$31))} -> 0 | U35: =SUMPRODUCT(($A$12:$A$31=$A35)*(U$12:U$31)) -> 0 | V35: =SUMPRODUCT(($A$12:$A$31=$A35)*(V$12:V$31)) -> 0 | W35: =SUMPRODUCT(($A$12:$A$31=$A35)*(W$12:W$31)) -> 0 | X35: =SUMPRODUCT(($A$12:$A$31=$A35)*(X$12:X$31)) -> 0 | Y35: =SUMPRODUCT(($A$12:$A$31=$A35)*(Y$12:Y$31)) -> 0 | Z35: =SUMPRODUCT(($A$12:$A$31=$A35)*(Z$12:Z$31)) -> 0 | AA35: =SUMPRODUCT(($A$12:$A$31=$A35)*(AA$12:AA$31)) -> 0 | AB35: =SUMPRODUCT(($A$12:$A$31=$A35)*(AB$12:AB$31)) -> 0 | ... BF35: =SUMPRODUCT(($A$12:$A$31=$A35)*(BF$12:BF$31)) -> 0
A36: =底稿目录!A11 -> 运输设备 | D36: =SUMPRODUCT(($A$12:$A$31=$A36)*(D$12:D$31)) -> 0 | E36: =SUMPRODUCT(($A$12:$A$31=$A36)*(E$12:E$31)) -> 0 | F36: =SUMPRODUCT(($A$12:$A$31=$A36)*(F$12:F$31)) -> 0 | G36: =SUMPRODUCT(($A$12:$A$31=$A36)*(G$12:G$31)) -> 0 | H36: =SUMPRODUCT(($A$12:$A$31=$A36)*(H$12:H$31)) -> 0 | I36: =SUMPRODUCT(($A$12:$A$31=$A36)*(I$12:I$31)) -> 0 | J36: =SUMPRODUCT(($A$12:$A$31=$A36)*(J$12:J$31)) -> 0 | K36: =SUMPRODUCT(($A$12:$A$31=$A36)*(K$12:K$31)) -> 0 | ... BF36: =SUMPRODUCT(($A$12:$A$31=$A36)*(BF$12:BF$31)) -> 0
A37: =底稿目录!A12 -> 办公设备 | D37: =SUMPRODUCT(($A$12:$A$31=$A37)*(D$12:D$31)) -> 0 | E37: =SUMPRODUCT(($A$12:$A$31=$A37)*(E$12:E$31)) -> 0 | F37: =SUMPRODUCT(($A$12:$A$31=$A37)*(F$12:F$31)) -> 0 | G37: =SUMPRODUCT(($A$12:$A$31=$A37)*(G$12:G$31)) -> 0 | H37: =SUMPRODUCT(($A$12:$A$31=$A37)*(H$12:H$31)) -> 0 | I37: =SUMPRODUCT(($A$12:$A$31=$A37)*(I$12:I$31)) -> 0 | J37: =SUMPRODUCT(($A$12:$A$31=$A37)*(J$12:J$31)) -> 0 | K37: =SUMPRODUCT(($A$12:$A$31=$A37)*(K$12:K$31)) -> 0 | ... BF37: =SUMPRODUCT(($A$12:$A$31=$A37)*(BF$12:BF$31)) -> 0
A38: =底稿目录!A13 -> 其他设备 | D38: =SUMPRODUCT(($A$12:$A$31=$A38)*(D$12:D$31)) -> 0 | E38: =SUMPRODUCT(($A$12:$A$31=$A38)*(E$12:E$31)) -> 0 | F38: =SUMPRODUCT(($A$12:$A$31=$A38)*(F$12:F$31)) -> 0 | G38: =SUMPRODUCT(($A$12:$A$31=$A38)*(G$12:G$31)) -> 0 | H38: =SUMPRODUCT(($A$12:$A$31=$A38)*(H$12:H$31)) -> 0 | I38: =SUMPRODUCT(($A$12:$A$31=$A38)*(I$12:I$31)) -> 0 | J38: =SUMPRODUCT(($A$12:$A$31=$A38)*(J$12:J$31)) -> 0 | K38: =SUMPRODUCT(($A$12:$A$31=$A38)*(K$12:K$31)) -> 0 | ... BF38: =SUMPRODUCT(($A$12:$A$31=$A38)*(BF$12:BF$31)) -> 0
D39: 三、审计说明： | N39: 四、审计结论：
A45: 提示： | W45: 编制说明： | AN45: 编制说明：
A46: 1.承租人会计处理不再区分经营租赁和融资租赁，而是采用单一的会计处理模型，也就是说，除采用简化处理的短期租赁和低价值资产租赁外， | W46: 承租人通常应当自租赁期开始日起按月计提使用权资产的折旧。 | AN46: 在租赁期开始日后，承租人应当按照《企业会计准则第8号——资产减值》的规定，确定使用权资产是否发生减值，并对已识别的减值损失进行会计处理。
A47: 2.对所有租赁均确认使用权资产和租赁负债，参照固定资产准则对使用权资产计提折旧，采用固定的周期性利率确认每期利息费用。 | W47: 当月计提确有困难的，也可从下月起计提折旧，并在附注中予以披露。 | AN47: 使用权资产减值准备一旦计提，不得转回。
A48: 3.审计说明可以概述:(1)程序的测试情况、结果;(2)拟调整事项及其调整分录、未调整事项及其影响，审计范围受到限制情况及其影响。
A49: 4.审计结论可参考：A、未见异常。 B、除上述重大不符事项应当作为调整事项予以调整外，其余未见异常。 C、由于存在以下重大未调整事项(或审计范围受到限制无法获取充分、适当证据)，不可确认。

Sheet 调整分录汇总H8-3
A1: 致同会计师事务所
A2: 使用权资产调整分录汇总表
A3: =底稿目录!A2 -> 被审计单位： | D3: =底稿目录!A4 -> 编制人： | G3: =底稿目录!A6 -> 编制日期： | I3: 索引号： | J3: H8-3
A4: =底稿目录!A3 -> 截止日：202X年12月31日 | D4: =底稿目录!A5 -> 复核人： | G4: =底稿目录!A7 -> 复核日期： | I4: 页 次：
A5: 调整事项说明 | B5: 类别（报表调整/账项调整/其他） | C5: 报表项目 | D5: 科目名称 | E5: 附注项目 | F5: …… | G5: 借方调整金额 | H5: 贷方调整金额 | I5: 索引 | J5: 备注
A24: 提示：本底稿适用于调整分录较多、较复杂的项目，且仅列示与本报表项目相关的审计调整。项目组可根据项目实际情况选择是否使用该底稿。

Sheet 租赁的识别H8-4
A1: 致同会计师事务所
A2: 租赁的识别
A3: =底稿目录!A2 -> 被审计单位： | D3: =底稿目录!A4 -> 编制人： | E3: =底稿目录!A6 -> 编制日期： | F3: 索引号： | G3: H8-4
A4: =底稿目录!A3 -> 截止日：202X年12月31日 | D4: =底稿目录!A5 -> 复核人： | E4: =底稿目录!A7 -> 复核日期： | F4: 页 次：
A5: 一、审计目标：
A6: 1. 资产负债表中记录的使用权资产是存在的，且已记录于恰当的账户；2. 所有应记录的使用权资产均已记录，所有应当包括在财务报表中的相关披露均已包括；3. 使用权资产以恰当的金额包括在财务报表中，与之相关的计价或分摊调整已恰当记录，相关披露已得到恰当计量和描述。
A7: 二、审计过程：
A9: 1. 租赁的识别
A10: 要素（同时满足） | C10: 公司具体情况 | F10: 是否满足 | G10: 索引
A11: （1）是否存在已识别资产 | F11: =IF(AND(F12="是",F13="否"),"是","否") -> 否 | H11: 通常由合同明确指定，也可以在资产可供客户使用时隐性指定
A12: ①物理可区分 | H12: 如果资产的部分产能在物理上可区分(例如，建筑物的一层)，则该部分产能属于已识别资产
A13: ②供应方实质性替换权 | H13: 如果资产供应方在整个使用期间拥有对该资产的实质性替换权，则该资产不属于已识别资产 | I13: 如果合同仅赋予资产供应方在特定日期或者特定事件发生日或之后拥有替换资产的权利或义务，考虑到资产供应方没有在整个使用期间替换资产的实际能力，资产供应方的替换权不具有实质性。 与资产位于资产供应方所在地相比， 如果资产位于客户所在地或其他位置，替换资产所需要的成本更有可能超过其所能获取的利益。资产供应方在资产运行结果不佳或者进行技术升级的情况下，因修理和维护而替换资产的权利或义务不属于实质性替换权。
A14: 同时符合下列条件时，表明资产供应方拥有资产的实质性替换权：拥有在整个使用期间替换资产的实际能力；通过行使替换资产的权利将获得经济利益。 | H14: 例如，客户无法阻止供应方替换资产，且用于替换的资产对于资产供应方而言易于获得或者可以在合理期间内取得； 替换资产的预期经济利益将超过替换资产所得成本。
A15: （2）是否有权约定使用期间主导已识别资产的使用 | H15: 合同中包含旨在保护资产供应方在已识别资产或其他资产中的权益、保护资产供应方的工作人员或者确保资产供应方不因客户使用租赁资产而违反法律法规的条款和条件，本身不足以否定客户拥有主导资产使用的权利。 | I15: 在合同中，"一定期间" 也可以表述为已识别资产的使用量，例如，某项设备的产出量。如果客户有权在部分合同期内控制已识别资产的使用，则合同包含一项在该部分合同期间的租赁。
A16: ①有权在整个使用期间主导已识别资产的使用目的和使用方式；或 | H16: 如果客户有权在整个使用期间在合同界定的使用权范围内改变资产的使用目的和使用方式，则视为客户有权在该使用期间主导资产的使用目的和使用方式。 | I16: 在判断客户是否有权在整个使用期间主导，已识别资产的使用目的和使用方式时，企业应当考虑在该使用期间与改变资产的使用目的和使用方式最为相关的决策权。相关决策权是指对使用资产所产生的经济利益产生影响的决策权。
A17: ②已识别资产的使用目的和使用方式在使用期间前已预先确定，并且： | H17: 例如，通过设计资产或在合同中对资产的使用做出限制来预先确定相关决策
A18: 有权在整个使用期间自行或主导他人按照其确定的方式运营该资产；或 | H18: 除非资产(或资产的特定方面) 由客户设计，企业应当仅考虑在使用期间对资产使用做出决策的权利。 | I18: 如果客户仅能在使用期间之前指定资产的产出而没有与资产使用相关的任何其他决策权，则该客户享有的权利与任何购买该项商品或服务的其他客户享有的权利并无不同。
A19: 设计了已识别资产(或资产的特定方面)并在设计时已预先确定了该资产在整个使用期间的使用目的和使用方式 | H19: 例如，电厂的使用目的和使用方式，即是否发电、发电时间和发电量；卡车的使用目的和使用方式，即在规定时间内将指定货物从A地运至B地
A20: （3）是否有权获得在使用期间内因使用已识别资产所产生的几乎全部经济利益 | H20: 应当在约定的客户权利范围内考虑其所产生的经济利益； 应当有权获得整个使用期间使用该资产所产生的几乎全部经济利益(例如，在整个使用期间独家使用该资产) | I20: 使用资产所产生的经济利益包括资产的主要产出和副产品(包括来源于这些项目的潜在现金流量)以及通过与第三方之间的商业交易实现的其他经济利益。 如果合同规定客户应向资产供应方或另一方支付因使用资产所产生的部分现金流量作为对价，该现金流量仍应视为客户因使用资产而获得的经济利益的一部分。
A21: 结 论 | C21: =IF(AND(F11="是",F15="是",F20="是"),"合同为租赁或者包含租赁","不包含租赁") -> 不包含租赁
A23: 2.租赁的分拆 | E23: 是否适用
A24: 条件（同时满足） | C24: 公司具体情况 | F24: 是否满足 | G24: 索引
A25: （1）承租人可从单独使用该资产或将其与易于获得的其他资源一起使用中获利； | H25: 易于获得的资源是指出租人或其他供应方单独销售或出租的商品或服务， 或者承租人已从出租人或其他交易中获得的资源
A26: （2）该资产与合同中的其他资产不存在高度依赖或高度关联关系。 | H26: 若承租人租入资产的决定不会对承租人使用合同中的其他资产的权利产生重大影响，则表明该项资产与合同中的其他资产不存在高度依赖或高度关联关系
A27: 结 论 | C27: =IF(AND(F25="是",F26="是"),"构成合同中的一项单独租赁","无须分拆") -> 无须分拆 | I27: 在分拆合同包含的租赁和非租赁部分时，承租人应当按照各项租赁部分单独价格及非租赁部分的单独价格之和的相对比例分担合同对价。
A28: 注1：合同中同时包含多项单独租赁的，承租人和出租人应当将合同予以分拆，并分别各项单独租赁进行会计处理。
A29: 注2：为简化处理，承租人可以按照租赁资产的类别选择是否分拆合同包含的租赁和非租赁部分。
A31: 3.租赁的合并 | E31: 是否适用
A32: 条件（任一） | C32: 公司具体情况 | F32: 是否满足 | G32: 索引
A33: （1）该两份或多份合同基于总体商业目的而订立并构成一揽子交易，若不作为整体考虑则无法理解其总体商业目的； | H33: 在该情况下，对每份合同独立进行会计处理可能无法忠实反映（faithful representation）整个交易
A34: （2）该两份或多份合同中的某份合同的对价金额取决于其他合同的定价或履行情况；
A35: （3）该两份或多份合同让渡的资产使用权合起来构成一项单独租赁。
A36: 结 论 | C36: =IF(OR(F33="是",F34="是",F35="是"),"应当合并为一份合同进行会计处理","单项租赁") -> 单项租赁
A37: 注：两份或多份合同合并为一份合同进行会计处理的，仍然需要区分该一份合同中的租赁部分和非租赁部分。
A39: 4. 短期租赁 | E39: 是否适用 | F39: 是
A40: 条件（同时满足） | C40: 公司具体情况 | F40: 是否满足 | G40: 索引
A41: （1）租赁期不超过12个月 | F41: =IF(AND(F42="是",F43="是"),"是","否") -> 否 | H41: 短期租赁，是指在租赁期开始日，租赁期不超过12个月的租赁
A42: 考虑续租选择权后租赁期不超过12个月 | F42: 是
A43: 续签合同租赁期不超过12个月 | F43: 否
A44: （2）不包含购买选择权 | F44: 是 | H44: 包含购买选择权的租赁不属于短期租赁
...

Sheet 租赁期的确定H8-5
A1: 致同会计师事务所
A2: 租赁期的确定
A3: =底稿目录!A2 -> 被审计单位： | C3: =底稿目录!A4 -> 编制人： | D3: =底稿目录!A6 -> 编制日期： | E3: 索引号： | F3: H8-5
A4: =底稿目录!A3 -> 截止日：202X年12月31日 | C4: =底稿目录!A5 -> 复核人： | D4: =底稿目录!A7 -> 复核日期： | E4: 页 次：
A5: 一、审计目标：
A6: 1. 资产负债表中记录的使用权资产是存在的，且已记录于恰当的账户；2. 所有应记录的使用权资产均已记录，所有应当包括在财务报表中的相关披露均已包括；3. 使用权资产以恰当的金额包括在财务报表中，与之相关的计价或分摊调整已恰当记录，相关披露已得到恰当计量和描述。
A7: 二、审计过程：
A9: 1. 租赁期的确定【承租人有权使用租赁资产且不可撤销的期间】
A10: 项目 | C10: 合同信息 | E10: 是否包含 | F10: 索引
A11: （1）租赁协议约定的起租日或租金起付日 | E11: 不包含 | G11: 租赁协议中对起租日或租金支付时间的约定，并不影响租赁期开始日的判断。
A12: （2）租赁期开始日【出租人提供租赁资产使其可供承租人使用的起始日期】 | E12: 包含 | G12: 租赁期自租赁期开始日起计算，并包括出租人为承租人提供的免租期。 如果承租人在租赁协议约定的起租日或租金起付日之前，已获得对租赁资产使用权的控制，则表明租赁期已经开始。
A13: （3）不可撤销期间 | G13: 在确定租赁期和评估不可撤销租赁期间时，企业应根据租赁条款约定确定可强制执行合同的期间。
A14: ①仅出租人有权终止租赁，则不可撤销的租赁期包括终止租赁选择权所涵盖的期间； | E14: 包含 | G14: 如果只有出租人有权终止租赁，则不可撤销的租赁期包括终止租赁选择权所涵盖的期间。
A15: ②如果只有承租人有权终止租赁，则在确定租赁期时，应将该项权利视为承租人可行使的终止租赁选择权予以考虑； | G15: 应当评估承租人是否合理确定将不行使终止租赁选择权，需考虑的因素详见下（4）。 合理确定将不会行使终止租赁选择权的，租赁期应包括终止租赁选择权涵盖的期间。 | H15: 通常，租赁的不可撤销期间越短，承租人不行使终止租赁选择权的可能性就越大。
A16: ③双方均有权单方面终止，且罚款金额不重大。 | E16: 不包含 | G16: 如果承租人和出租人双方均有权在未经另一方许可的情况下终止租赁，且罚款金额不重大，则该租赁不再可强制执行。 | H16: 应当对罚款作出广义解释以同时涵盖终止租赁付款及其他类型的经济处罚，包括弃置或拆卸不可移除的租赁改良所发生的成本。
A17: （4）续租选择权涵盖的期间 | G17: 应当评估承租人是否合理确定将行使续租选择权。 合理确定将行使续租选择权的，租赁期应包括续租选择权涵盖的期间。 | H17: 同等条件下优先续约不是无条件续约的权利，不属于续约选择权（续约选择权是公司的一项权利，只要公司愿意，都可以无条件续约）
A18: 考虑对承租人行使续租选择权带来经济利益的所有相关事实和情况 | G18: 需考虑的因素：①与市价相比，选择权期间的合同条款和条件；②在合同期内，承租人进行或预期进行重大租赁资产改良；③与终止租赁相关的成本；④租赁资产对承租人运营的重要程度；⑤与行使选择权相关的条件及满足相关条件的可能性。
A19: 与租赁的其他条款相结合判断 | G19: 例如，无论承租人是否行使选择权，均保证向出租人支付基本相等的最低或固定现金，在此情形下，应假设承租人合理确定将行使续租选择权选择权。
A20: （5）购买选择权 | G20: 购买选择权的评估方式应与续租选择权或终止租赁选择权的评估方式相同，购买选择权在经济上与将租赁期延长至租赁资产全部剩余经济寿命的续租选择权类似。
A21: 确定的租赁期（结构化·供H8-6引用）
B22: 起租日 | C22: 44197 | D22: 约满日 | E22: 47848 | F22: 租赁期(月) | G22: =(YEAR($E$22)-YEAR($C$22))*12+MONTH($E$22)-MONTH($C$22)+1 -> 120 | H22: 租赁期(年) | I22: =MAX(1,ROUND($G$22/12,0)) -> 10
A23: 2. 对租赁期和购买选择权的重新评估
A24: 2.1 承租人可控范围内的重大事件或变化的情形 | D24: 是否适用 | E24: 是
A25: 情形 | C25: 合同信息 | E25: 是/否 | F25: 索引
A26: ①重大租赁资产改良 | E26: 是 | G26: 在租赁期开始日未预计到的重大租赁资产改良，在可行使续租选择权、终止租赁选择权或购买选择权时，预期将为承租人带来重大经济利益 | H26: 发生承租人可控范围内的重大事件或变化，且影响承租人是否合理确定将行使相应选择权的，承租人应当对其是否合理确定将行使续租选择权、购买选择权或不行使终止租赁选择权进行重新评估，并根据重新评估结果修改租赁期
A27: ②租赁资产的重大改动或定制化调整 | G27: 在租赁期开始日未预计到的租赁资产的重大改动或定制化调整
A28: ③直接相关的经营决策 | G28: 承租人做出的与行使或不行使选择权直接相关的经营决策。例如，决定续租互补性资产、处置可替代的资产或处置包含相关使用权资产的业务
A29: 结 论 | C29: =IF(OR(E26="是",E27="是",E28="是"),"应当重新评估是否合理确定将行使续租选择权、购买选择权或不行使终止租赁选择权","无需重新评估") -> 应当重新评估是否合理确定将行使续租选择权、购买选择权或不行使终止租赁选择权
A31: 2.2 根据重新评估结果修改租赁期 | D31: 是否适用 | E31: 是
A32: 情形 | C32: 合同信息 | E32: 是/否 | F32: 索引
A33: （1）承租人实际行使了选择权，但该选择权在之前企业确定租赁期时未涵盖； | E33: 是
A34: （2）承租人未实际行使选择权但该选择权在之前企业确定租赁期时已涵盖；
A35: （3）某些事件的发生，导致根据合同规定承租人有义务行使选择权，但该选择权在之前企业确定租赁期时未涵盖；
A36: （4）某些事件的发生，导致根据合同规定禁止承租人行使选择权，但该选择权在之前企业确定租赁期时已涵盖。
A37: 重新确定的租赁期
A39: 三、审计说明：
A42: 四、审计结论：
A45: 提示：
A46: 租赁期是指承租人有权使用租赁资产且不可撤销的期间。
A47: 租赁期自租赁期开始日起计算。

Sheet 使用权资产 租赁负债初始及后续计量（按年）H8-6
A1: 致同会计师事务所
A2: 使用权资产 租赁负债初始及后续计量（按年）
A3: =底稿目录!A2 -> 被审计单位： | D3: =底稿目录!A4 -> 编制人： | F3: =底稿目录!A6 -> 编制日期： | H3: 索引号： | I3: H8-6
A4: =底稿目录!A3 -> 截止日：202X年12月31日 | D4: =底稿目录!A5 -> 复核人： | F4: =底稿目录!A7 -> 复核日期： | H4: 页 次：
A5: 一、审计目标：确认使用权资产与租赁负债按 CAS21 以恰当金额初始确认并后续计量；初始计量：使用权资产=租赁付款额现值(未付部分)+租赁期开始日或之前支付的租赁付款额+初始直接费用+预计复原成本−租赁激励；租赁负债=尚未支付的租赁付款额按增量借款利率/内含利率折现；后续：负债按实际利率法摊余成本，资产按直线法(或其他系统合理方法)折旧，折旧期=min(租赁期,使用寿命)（能合理确定取得所有权时取使用寿命）；相关递延所得税与披露恰当。
A6: 二、审计过程：①核对合同/H8-4识别结论与H8-5租赁期（含续租/终止选择权）；②复核折现率（优先合同内含利率，否则增量借款利率）与付款时点（期初/期末）；③验算表2现值合计=表3负债期初，使用权资产入账=现值+预付+初始直接费用±复原/激励；④抽查后续利息=(期初负债−本期付款)×年折现率、折旧=入账价值/摊销年限，期末勾稽H8-1/H9；⑤复杂长租、非固定年付或需月结时改用「按月」表，并与本表年化结果交叉复核。索引：H8-4 / H8-5 / H8-7 / H8-8 / H9。
A7: 1. 租赁合同的基本信息（H8-5带入 + L9动态期数 + Q9付款时点）
A8: 使用权资产名称 | B8: 租赁期开始日 | C8: 合同约定初始期满日 | D8: 续租期（年） | E8: 租赁期（考虑续租可能后） | F8: 租赁期截止日期 | G8: 增量借款利率 | H8: 折现率 | I8: 使用权资产摊销期限（年） | J8: 适用税率 | K8: 年租金(不含税) | L8: 有效付款期数(年) | M8: 初始直接费用 | N8: 自动自检 | Q8: 付款时点
A9: XX设备 | B9: ='租赁期的确定H8-5'!C22 -> 44197 | C9: 47118 | D9: =2 -> 2 | E9: =(YEAR(C9)-YEAR(B9))+D9+(MONTH(C9)-MONTH(B9)+1)/12 -> 10 | F9: =DATE(YEAR(C9)+D9,MONTH(C9),DAY(C9)) -> 47848 | G9: 0.05 | H9: =G9 -> 0.05 | I9: 10 | J9: 0.25 | K9: 50000 | L9: ='租赁期的确定H8-5'!I22 -> 10 | M9: 15000 | N9: =IF(OR($L$9="",$L$9<1),"待填期数",IF(ABS(INDEX($F$39:$F$50,$L$9))<1,"✓负债期末≈0","×查负债摊销")) -> ✓负债期末≈0 | O9: =IF(OR($L$9="",$L$9<1),"待填期数",IF(ABS(INDEX($I$39:$I$50,MIN($L$9,$I$9)))<1,"✓折旧折尽","×查折旧/寿命")) -> ✓折旧折尽 | P9: =IF(ABS($B$16-$C$16)<0.01,"✓计算区借贷平衡","×计算区不平衡") -> ✓计算区借贷平衡 | Q9: 期初
A10: 【编制入口·必填黄格】先填H8-5的C22起租日/E22约满日 → 本表B9/L9自动带入；再填K9年租金、M9初始直接费用、G9折现率、Q9付款时点(期初/期末)、I9摊销年限。
A11: 计 算 区 域
B12: 借 | C12: 贷 | F12: 借 | G12: 贷
A13: 使用权资产 | B13: =I34 -> 420391.08 | E13: 递延所得税资产 | F13: =J39 -> 93290.159
A14: 租赁负债 | C14: =F34 -> 355391.08 | E14: 递延所得税负债 | G14: =K39 -> 94587.994
A15: 预付租金+初始直接费用 | C15: =H34+G34 -> 65000 | E15: 所得税费用 | F15: =G14-F13 -> 1297.8344
B16: =SUM(B13:B15) -> 420391.08 | C16: =SUM(C13:C15) -> 420391.08
A18: 2. 计算租赁负债余额（L9动态期数 + Q9付款时点，最多30年）
A19: 租金支付日期 | B19: 剩余合同租金（不含税） | C19: 租赁付款额原值 | D19: 租赁负债折现期(年) | E19: 租赁负债折现系数 | F19: 租赁付款额现值 | G19: 租赁预付款 | H19: 初始直接费用 | I19: 使用权资产初始确认金额 | L19: Q9=期初：第0期进预付；Q9=期末：折现期从1起、无租金预付。年租金K9，期数L9（H8-5）。
A20: =IF($L$9>0,$B$9,"") -> 44197 | B20: =IF($L$9>0,$K$9,0) -> 50000 | C20: =IF(OR($L$9<=0,D20="",AND($Q$9<>"期末",D20=0)),0,B20) -> 0 | D20: =IF($L$9>0,IF($Q$9="期末",0+1,0),"") -> 0 | E20: =IF($L$9>0,1/(1+$H$9)^D20,"") -> 1 | F20: =IF($L$9>0,C20*E20,0) -> 0 | G20: =IF(AND($L$9>0,$Q$9<>"期末",D20=0),B20,0) -> 50000 | H20: =$M$9 -> 15000
A21: =IF($L$9>1,DATE(YEAR(A20)+1,MONTH(A20),DAY(A20)),"") -> 44562 | B21: =IF($L$9>1,$K$9,0) -> 50000 | C21: =IF(OR($L$9<=1,D21="",AND($Q$9<>"期末",D21=0)),0,B21) -> 50000 | D21: =IF($L$9>1,IF($Q$9="期末",1+1,1),"") -> 1 | E21: =IF($L$9>1,1/(1+$H$9)^D21,"") -> 0.95238095 | F21: =IF($L$9>1,C21*E21,0) -> 47619.048 | G21: =IF(AND($L$9>1,$Q$9<>"期末",D21=0),B21,0) -> 0 | H21: 0
A22: =IF($L$9>2,DATE(YEAR(A21)+1,MONTH(A21),DAY(A21)),"") -> 44927 | B22: =IF($L$9>2,$K$9,0) -> 50000 | C22: =IF(OR($L$9<=2,D22="",AND($Q$9<>"期末",D22=0)),0,B22) -> 50000 | D22: =IF($L$9>2,IF($Q$9="期末",2+1,2),"") -> 2 | E22: =IF($L$9>2,1/(1+$H$9)^D22,"") -> 0.90702948 | F22: =IF($L$9>2,C22*E22,0) -> 45351.474 | G22: =IF(AND($L$9>2,$Q$9<>"期末",D22=0),B22,0) -> 0 | H22: 0
A23: =IF($L$9>3,DATE(YEAR(A22)+1,MONTH(A22),DAY(A22)),"") -> 45292 | B23: =IF($L$9>3,$K$9,0) -> 50000 | C23: =IF(OR($L$9<=3,D23="",AND($Q$9<>"期末",D23=0)),0,B23) -> 50000 | D23: =IF($L$9>3,IF($Q$9="期末",3+1,3),"") -> 3 | E23: =IF($L$9>3,1/(1+$H$9)^D23,"") -> 0.8638376 | F23: =IF($L$9>3,C23*E23,0) -> 43191.88 | G23: =IF(AND($L$9>3,$Q$9<>"期末",D23=0),B23,0) -> 0 | H23: 0
A24: =IF($L$9>4,DATE(YEAR(A23)+1,MONTH(A23),DAY(A23)),"") -> 45658 | B24: =IF($L$9>4,$K$9,0) -> 50000 | C24: =IF(OR($L$9<=4,D24="",AND($Q$9<>"期末",D24=0)),0,B24) -> 50000 | D24: =IF($L$9>4,IF($Q$9="期末",4+1,4),"") -> 4 | E24: =IF($L$9>4,1/(1+$H$9)^D24,"") -> 0.82270247 | F24: =IF($L$9>4,C24*E24,0) -> 41135.124 | G24: =IF(AND($L$9>4,$Q$9<>"期末",D24=0),B24,0) -> 0 | H24: 0
A25: =IF($L$9>5,DATE(YEAR(A24)+1,MONTH(A24),DAY(A24)),"") -> 46023 | B25: =IF($L$9>5,$K$9,0) -> 50000 | C25: =IF(OR($L$9<=5,D25="",AND($Q$9<>"期末",D25=0)),0,B25) -> 50000 | D25: =IF($L$9>5,IF($Q$9="期末",5+1,5),"") -> 5 | E25: =IF($L$9>5,1/(1+$H$9)^D25,"") -> 0.78352617 | F25: =IF($L$9>5,C25*E25,0) -> 39176.308 | G25: =IF(AND($L$9>5,$Q$9<>"期末",D25=0),B25,0) -> 0 | H25: 0
A26: =IF($L$9>6,DATE(YEAR(A25)+1,MONTH(A25),DAY(A25)),"") -> 46388 | B26: =IF($L$9>6,$K$9,0) -> 50000 | C26: =IF(OR($L$9<=6,D26="",AND($Q$9<>"期末",D26=0)),0,B26) -> 50000 | D26: =IF($L$9>6,IF($Q$9="期末",6+1,6),"") -> 6 | E26: =IF($L$9>6,1/(1+$H$9)^D26,"") -> 0.7462154 | F26: =IF($L$9>6,C26*E26,0) -> 37310.77 | G26: =IF(AND($L$9>6,$Q$9<>"期末",D26=0),B26,0) -> 0 | H26: 0
A27: =IF($L$9>7,DATE(YEAR(A26)+1,MONTH(A26),DAY(A26)),"") -> 46753 | B27: =IF($L$9>7,$K$9,0) -> 50000 | C27: =IF(OR($L$9<=7,D27="",AND($Q$9<>"期末",D27=0)),0,B27) -> 50000 | D27: =IF($L$9>7,IF($Q$9="期末",7+1,7),"") -> 7 | E27: =IF($L$9>7,1/(1+$H$9)^D27,"") -> 0.71068133 | F27: =IF($L$9>7,C27*E27,0) -> 35534.067 | G27: =IF(AND($L$9>7,$Q$9<>"期末",D27=0),B27,0) -> 0 | H27: 0
A28: =IF($L$9>8,DATE(YEAR(A27)+1,MONTH(A27),DAY(A27)),"") -> 47119 | B28: =IF($L$9>8,$K$9,0) -> 50000 | C28: =IF(OR($L$9<=8,D28="",AND($Q$9<>"期末",D28=0)),0,B28) -> 50000 | D28: =IF($L$9>8,IF($Q$9="期末",8+1,8),"") -> 8 | E28: =IF($L$9>8,1/(1+$H$9)^D28,"") -> 0.67683936 | F28: =IF($L$9>8,C28*E28,0) -> 33841.968 | G28: =IF(AND($L$9>8,$Q$9<>"期末",D28=0),B28,0) -> 0 | H28: 0
A29: =IF($L$9>9,DATE(YEAR(A28)+1,MONTH(A28),DAY(A28)),"") -> 47484 | B29: =IF($L$9>9,$K$9,0) -> 50000 | C29: =IF(OR($L$9<=9,D29="",AND($Q$9<>"期末",D29=0)),0,B29) -> 50000 | D29: =IF($L$9>9,IF($Q$9="期末",9+1,9),"") -> 9 | E29: =IF($L$9>9,1/(1+$H$9)^D29,"") -> 0.64460892 | F29: =IF($L$9>9,C29*E29,0) -> 32230.446 | G29: =IF(AND($L$9>9,$Q$9<>"期末",D29=0),B29,0) -> 0 | H29: 0
A30: =IF($L$9>26,DATE(YEAR(#REF!)+1,MONTH(#REF!),DAY(#REF!)),"") | B30: =IF($L$9>26,$K$9,0) -> 0 | C30: =IF(OR($L$9<=26,D30="",AND($Q$9<>"期末",D30=0)),0,B30) -> 0 | D30: =IF($L$9>26,IF($Q$9="期末",26+1,26),"") | E30: =IF($L$9>26,1/(1+$H$9)^D30,"") | F30: =IF($L$9>26,C30*E30,0) -> 0 | G30: =IF(AND($L$9>26,$Q$9<>"期末",D30=0),B30,0) -> 0 | H30: 0
A31: =IF($L$9>27,DATE(YEAR(A30)+1,MONTH(A30),DAY(A30)),"") | B31: =IF($L$9>27,$K$9,0) -> 0 | C31: =IF(OR($L$9<=27,D31="",AND($Q$9<>"期末",D31=0)),0,B31) -> 0 | D31: =IF($L$9>27,IF($Q$9="期末",27+1,27),"") | E31: =IF($L$9>27,1/(1+$H$9)^D31,"") | F31: =IF($L$9>27,C31*E31,0) -> 0 | G31: =IF(AND($L$9>27,$Q$9<>"期末",D31=0),B31,0) -> 0 | H31: 0
A32: =IF($L$9>28,DATE(YEAR(A31)+1,MONTH(A31),DAY(A31)),"") | B32: =IF($L$9>28,$K$9,0) -> 0 | C32: =IF(OR($L$9<=28,D32="",AND($Q$9<>"期末",D32=0)),0,B32) -> 0 | D32: =IF($L$9>28,IF($Q$9="期末",28+1,28),"") | E32: =IF($L$9>28,1/(1+$H$9)^D32,"") | F32: =IF($L$9>28,C32*E32,0) -> 0 | G32: =IF(AND($L$9>28,$Q$9<>"期末",D32=0),B32,0) -> 0 | H32: 0
A33: =IF($L$9>29,DATE(YEAR(A32)+1,MONTH(A32),DAY(A32)),"") | B33: =IF($L$9>29,$K$9,0) -> 0 | C33: =IF(OR($L$9<=29,D33="",AND($Q$9<>"期末",D33=0)),0,B33) -> 0 | D33: =IF($L$9>29,IF($Q$9="期末",29+1,29),"") | E33: =IF($L$9>29,1/(1+$H$9)^D33,"") | F33: =IF($L$9>29,C33*E33,0) -> 0 | G33: =IF(AND($L$9>29,$Q$9<>"期末",D33=0),B33,0) -> 0 | H33: 0
A34: 合计 | B34: =SUM(B20:B33) -> 500000 | C34: =SUM(C20:C33) -> 450000 | F34: =SUM(F20:F33) -> 355391.08 | G34: =SUM(G20:G33) -> 50000 | H34: =SUM(H20:H33) -> 15000 | I34: =F34+G34+H34 -> 420391.08
A36: 3. 租赁负债及使用权资产后续计量（随L9/Q9动态）
A37: 期间 | B37: 租赁负债 | G37: 使用权资产 | J37: 对应递延所得税资产 | K37: 对应递延所得税负债
B38: 期初余额 | C38: 租赁付款额 | D38: 支付月份 | E38: 利息费用 | F38: 期末余额 | G38: 期初余额 | H38: 折旧费用 | I38: 期末余额
A39: =IF($L$9>0,TEXT(YEAR($B$9)+0,"0")&"年度","") -> 2021年度 | B39: =IF($L$9>0,F34,0) -> 355391.08 | C39: =IF($L$9>0,C20,0) -> 0 | D39: =IF($L$9>0,MONTH($B$9),"") -> 1 | E39: =IF($L$9>0,IF($Q$9="期末",B39*$H$9,(B39-C39)*$H$9),0) -> 17769.554 | F39: =IF($L$9>0,IF($Q$9="期末",B39+E39-C39,B39-C39+E39),0) -> 373160.64 | G39: =IF($L$9>0,I34,0) -> 420391.08 | H39: =IF(AND($L$9>0,0<MIN($L$9,$I$9)),$I$34/MIN($L$9,$I$9),0) -> 42039.108 | I39: =IF($L$9>0,G39-H39,0) -> 378351.98 | J39: =IF($L$9>0,F39*$J$9,0) -> 93290.159 | K39: =IF($L$9>0,I39*$J$9,0) -> 94587.994
A40: =IF($L$9>1,TEXT(YEAR($B$9)+1,"0")&"年度","") -> 2022年度 | B40: =IF($L$9>1,B39-C39+E39,0) -> 373160.64 | C40: =IF($L$9>1,C21,0) -> 50000 | D40: =IF($L$9>1,MONTH($B$9),"") -> 1 | E40: =IF($L$9>1,IF($Q$9="期末",B40*$H$9,(B40-C40)*$H$9),0) -> 16158.032 | F40: =IF($L$9>1,IF($Q$9="期末",B40+E40-C40,B40-C40+E40),0) -> 339318.67 | G40: =IF($L$9>1,I39,0) -> 378351.98 | H40: =IF(AND($L$9>1,1<MIN($L$9,$I$9)),$I$34/MIN($L$9,$I$9),0) -> 42039.108 | I40: =IF($L$9>1,G40-H40,0) -> 336312.87 | J40: =IF($L$9>1,F40*$J$9,0) -> 84829.667 | K40: =IF($L$9>1,I40*$J$9,0) -> 84078.217
A41: =IF($L$9>2,TEXT(YEAR($B$9)+2,"0")&"年度","") -> 2023年度 | B41: =IF($L$9>2,B40-C40+E40,0) -> 339318.67 | C41: =IF($L$9>2,C22,0) -> 50000 | D41: =IF($L$9>2,MONTH($B$9),"") -> 1 | E41: =IF($L$9>2,IF($Q$9="期末",B41*$H$9,(B41-C41)*$H$9),0) -> 14465.933 | F41: =IF($L$9>2,IF($Q$9="期末",B41+E41-C41,B41-C41+E41),0) -> 303784.6 | G41: =IF($L$9>2,I40,0) -> 336312.87 | H41: =IF(AND($L$9>2,2<MIN($L$9,$I$9)),$I$34/MIN($L$9,$I$9),0) -> 42039.108 | I41: =IF($L$9>2,G41-H41,0) -> 294273.76 | J41: =IF($L$9>2,F41*$J$9,0) -> 75946.151 | K41: =IF($L$9>2,I41*$J$9,0) -> 73568.44
A42: =IF($L$9>3,TEXT(YEAR($B$9)+3,"0")&"年度","") -> 2024年度 | B42: =IF($L$9>3,B41-C41+E41,0) -> 303784.6 | C42: =IF($L$9>3,C23,0) -> 50000 | D42: =IF($L$9>3,MONTH($B$9),"") -> 1 | E42: =IF($L$9>3,IF($Q$9="期末",B42*$H$9,(B42-C42)*$H$9),0) -> 12689.23 | F42: =IF($L$9>3,IF($Q$9="期末",B42+E42-C42,B42-C42+E42),0) -> 266473.83 | G42: =IF($L$9>3,I41,0) -> 294273.76 | H42: =IF(AND($L$9>3,3<MIN($L$9,$I$9)),$I$34/MIN($L$9,$I$9),0) -> 42039.108 | I42: =IF($L$9>3,G42-H42,0) -> 252234.65 | J42: =IF($L$9>3,F42*$J$9,0) -> 66618.458 | K42: =IF($L$9>3,I42*$J$9,0) -> 63058.663
...

Sheet 使用权资产 租赁负债初始及后续计量（按月）H8-6
A1: 致同会计师事务所
A2: 使用权资产 租赁负债初始及后续计量（按月）
A3: =底稿目录!A2 -> 被审计单位： | E3: =底稿目录!A4 -> 编制人： | I3: =底稿目录!A6 -> 编制日期： | L3: 索引号： | M3: H8-6
A4: =底稿目录!A3 -> 截止日：202X年12月31日 | E4: =底稿目录!A5 -> 复核人： | I4: =底稿目录!A7 -> 复核日期： | L4: 页 次：
A5: 【编制入口·必填黄格】C15/C16默认H8-5；J20默认=按年L9；O20付款时点默认=按年Q9；再填C17折现率、C20年租金、E20支付月、G20初始直接费用、L20寿命月数。
A6: 填表说明（按月·动态）：【核心】J20默认=按年L9；也可直接改年数。C16/C18随年数变；填C15/C17/C20/E20/G20/L20后，明细自动生成。右侧N15:P15为自动自检。月利率=年利率/12。
A7: 1、 | B7: 租赁期开始日*(必填） | C7: 必填项，实际起租/交接日，填写格式为YYYY-MM-DD 如：2021-01-01（驱动B列逐月序列）。
A8: 2、 | B8: 约满日期*(必填） | C8: 必填项，考虑续租可能后的租赁期届满日（应与H8-5一致），格式YYYY-MM-DD；摊销期限C18据此计算。
A9: 3、 | B9: 折现率*(必填） | C9: 按合同内含利率或增量借款利率确定年折现率；利息列使用年利率/12。与按年表H9应一致。
A10: 4、 | B10: 摊销期限 | C10: 租期来自H8-5或J20。寿命短于租期时改L20。
A11: 5、 | B11: 月折旧额 | C11: 月折旧按MIN(C18,L20)次月起折尽；O20=期末时首笔租金不早于起租后12个月。
A13: 输 入 区 域 | D13: 计 算 区 域
A14: 使用权资产名称 | C14: XX设备 | E14: 借 | F14: 贷 | I14: 借 | J14: 贷 | N14: 自动自检
A15: 租赁期开始日 | C15: ='租赁期的确定H8-5'!C22 -> 44197 | D15: 使用权资产 | E15: =K22 -> 418559.45 | H15: 递延所得税资产 | I15: =L22 -> 88758.153 | N15: =IF($C$18<=0,"待填租期",IF(ABS(INDEX($G$22:$G$348,$C$18))<1,"✓末月负债≈0","×查利息/付款")) -> ✓末月负债≈0 | O15: =IF($C$18<=0,"待填租期",IF(ABS($I$349-($E$349+$H$349))<1,"✓折旧合计≈入账","×查折旧折尽")) -> ✓折旧合计≈入账 | P15: =IF(ABS($J$20-'使用权资产 租赁负债初始及后续计量（按年）H8-6'!L9)<0.1,"✓与按年L9一致","△与按年L9不一致") -> ✓与按年L9一致
A16: 约满日期(考虑续租可能后） | C16: ='租赁期的确定H8-5'!E22 -> 47848 | D16: 租赁负债 | F16: =E349 -> 353559.45 | H16: 递延所得税负债 | J16: =M22 -> 104639.86
A17: 本合同折现率（例） | C17: 0.05 | D17: 预付租金 | F17: =H349 -> 65000 | H17: 所得税费用 | I17: =J16-I15 -> 15881.709
A18: 摊销期限 | C18: =(YEAR($C$16)-YEAR($C$15))*12+MONTH($C$16)-MONTH($C$15)+1 -> 120 | E18: =SUM(E15:E17) -> 418559.45 | F18: =SUM(F15:F17) -> 418559.45 | I18: =SUM(I15:I17) -> 104639.86 | J18: =SUM(J15:J17) -> 104639.86
A19: 适用税率 | C19: 0.25
A20: 年租金(不含税)* | C20: 50000 | D20: 每年支付月份* | E20: 1 | F20: 初始直接费用 | G20: 15000 | I20: 租赁期(年)* | J20: ='使用权资产 租赁负债初始及后续计量（按年）H8-6'!L9 -> 10 | K20: 使用寿命(月) | L20: =$J$20*12 -> 120 | N20: 付款时点 | O20: ='使用权资产 租赁负债初始及后续计量（按年）H8-6'!Q9 -> 期初
A21: 期数 | B21: 月份 | C21: 合同租金 （不含税） | D21: 复原成本、终止租赁罚金等 | E21: 租赁付款额现值(折现到租赁期开始日) | F21: 利息费用 | G21: 租赁付款额现值余额 | H21: 使用权资产调整 （租赁期开始日前支付的租金、复原成本等） | I21: 月折旧额（次月起计提） | J21: 使用权资产累计折旧 | K21: 使用权资产余值 | L21: 对应递延所得税资产 | M21: 对应递延所得税负债
A22: 1 | B22: =C15 -> 44197 | C22: =IF(AND(A22<=$C$18,MONTH(B22)=$E$20,B22<=$C$16,IF($O$20="期末",B22>=EDATE($C$15,12),B22>$C$15)),$C$20,0) -> 0 | E22: =(D22+C22)/(POWER((1+$C$17/12),A22-1)) -> 0 | F22: =IF($C$18<=0,0,$C$17/12*E349) -> 1473.1644 | G22: =IF($C$18<=0,0,F22+E349) -> 355032.61 | H22: =IF($O$20="期末",$G$20,$C$20+$G$20) -> 65000 | I22: 0 | J22: 0 | K22: =$E$349+$H$349-I22 -> 418559.45 | L22: =IF(G22=0,0,G22*$C$19) -> 88758.153 | M22: =IF(K22=0,0,K22*$C$19) -> 104639.86
A23: =A22+1 -> 2 | B23: =EDATE(B22,1) -> 44228 | C23: =IF(AND(A23<=$C$18,MONTH(B23)=$E$20,B23<=$C$16,IF($O$20="期末",B23>=EDATE($C$15,12),B23>$C$15)),$C$20,0) -> 0 | E23: =(D23+C23)/(POWER((1+$C$17/12),A23-1)) -> 0 | F23: =IF(OR(B23>$C$16,A23>$C$18),0,$C$17/12*(G22-C23)) -> 1479.3026 | G23: =IF(OR(B23>$C$16,A23>$C$18),0,G22-C23+F23) -> 356511.92 | I23: =IF(OR(B23>$C$16,($A23-1)>=MIN($C$18,$L$20),MIN($C$18,$L$20)<=1),0,($E$349+$H$349)/MAX(MIN($C$18,$L$20)-1,1)) -> 3517.3063 | J23: =IF(I23=0,0,J22+I23) -> 3517.3063 | K23: =IF(OR(B23>$C$16,A23>$C$18),0,K22-I23) -> 415042.14 | L23: =IF(G23=0,0,G23*$C$19) -> 89127.979 | M23: =IF(K23=0,0,K23*$C$19) -> 103760.54
A24: =A23+1 -> 3 | B24: =EDATE(B23,1) -> 44256 | C24: =IF(AND(A24<=$C$18,MONTH(B24)=$E$20,B24<=$C$16,IF($O$20="期末",B24>=EDATE($C$15,12),B24>$C$15)),$C$20,0) -> 0 | E24: =(D24+C24)/(POWER((1+$C$17/12),A24-1)) -> 0 | F24: =IF(OR(B24>$C$16,A24>$C$18),0,$C$17/12*(G23-C24)) -> 1485.4663 | G24: =IF(OR(B24>$C$16,A24>$C$18),0,G23-C24+F24) -> 357997.38 | I24: =IF(OR(B24>$C$16,($A24-1)>=MIN($C$18,$L$20),MIN($C$18,$L$20)<=1),0,($E$349+$H$349)/MAX(MIN($C$18,$L$20)-1,1)) -> 3517.3063 | J24: =IF(I24=0,0,J23+I24) -> 7034.6126 | K24: =IF(OR(B24>$C$16,A24>$C$18),0,K23-I24) -> 411524.84 | L24: =IF(G24=0,0,G24*$C$19) -> 89499.346 | M24: =IF(K24=0,0,K24*$C$19) -> 102881.21
A25: =A24+1 -> 4 | B25: =EDATE(B24,1) -> 44287 | C25: =IF(AND(A25<=$C$18,MONTH(B25)=$E$20,B25<=$C$16,IF($O$20="期末",B25>=EDATE($C$15,12),B25>$C$15)),$C$20,0) -> 0 | E25: =(D25+C25)/(POWER((1+$C$17/12),A25-1)) -> 0 | F25: =IF(OR(B25>$C$16,A25>$C$18),0,$C$17/12*(G24-C25)) -> 1491.6558 | G25: =IF(OR(B25>$C$16,A25>$C$18),0,G24-C25+F25) -> 359489.04 | I25: =IF(OR(B25>$C$16,($A25-1)>=MIN($C$18,$L$20),MIN($C$18,$L$20)<=1),0,($E$349+$H$349)/MAX(MIN($C$18,$L$20)-1,1)) -> 3517.3063 | J25: =IF(I25=0,0,J24+I25) -> 10551.919 | K25: =IF(OR(B25>$C$16,A25>$C$18),0,K24-I25) -> 408007.53 | L25: =IF(G25=0,0,G25*$C$19) -> 89872.26 | M25: =IF(K25=0,0,K25*$C$19) -> 102001.88
A26: =A25+1 -> 5 | B26: =EDATE(B25,1) -> 44317 | C26: =IF(AND(A26<=$C$18,MONTH(B26)=$E$20,B26<=$C$16,IF($O$20="期末",B26>=EDATE($C$15,12),B26>$C$15)),$C$20,0) -> 0 | E26: =(D26+C26)/(POWER((1+$C$17/12),A26-1)) -> 0 | F26: =IF(OR(B26>$C$16,A26>$C$18),0,$C$17/12*(G25-C26)) -> 1497.871 | G26: =IF(OR(B26>$C$16,A26>$C$18),0,G25-C26+F26) -> 360986.91 | I26: =IF(OR(B26>$C$16,($A26-1)>=MIN($C$18,$L$20),MIN($C$18,$L$20)<=1),0,($E$349+$H$349)/MAX(MIN($C$18,$L$20)-1,1)) -> 3517.3063 | J26: =IF(I26=0,0,J25+I26) -> 14069.225 | K26: =IF(OR(B26>$C$16,A26>$C$18),0,K25-I26) -> 404490.22 | L26: =IF(G26=0,0,G26*$C$19) -> 90246.727 | M26: =IF(K26=0,0,K26*$C$19) -> 101122.56
A27: =A26+1 -> 6 | B27: =EDATE(B26,1) -> 44348 | C27: =IF(AND(A27<=$C$18,MONTH(B27)=$E$20,B27<=$C$16,IF($O$20="期末",B27>=EDATE($C$15,12),B27>$C$15)),$C$20,0) -> 0 | E27: =(D27+C27)/(POWER((1+$C$17/12),A27-1)) -> 0 | F27: =IF(OR(B27>$C$16,A27>$C$18),0,$C$17/12*(G26-C27)) -> 1504.1121 | G27: =IF(OR(B27>$C$16,A27>$C$18),0,G26-C27+F27) -> 362491.02 | I27: =IF(OR(B27>$C$16,($A27-1)>=MIN($C$18,$L$20),MIN($C$18,$L$20)<=1),0,($E$349+$H$349)/MAX(MIN($C$18,$L$20)-1,1)) -> 3517.3063 | J27: =IF(I27=0,0,J26+I27) -> 17586.531 | K27: =IF(OR(B27>$C$16,A27>$C$18),0,K26-I27) -> 400972.92 | L27: =IF(G27=0,0,G27*$C$19) -> 90622.755 | M27: =IF(K27=0,0,K27*$C$19) -> 100243.23
A28: =A27+1 -> 7 | B28: =EDATE(B27,1) -> 44378 | C28: =IF(AND(A28<=$C$18,MONTH(B28)=$E$20,B28<=$C$16,IF($O$20="期末",B28>=EDATE($C$15,12),B28>$C$15)),$C$20,0) -> 0 | E28: =(D28+C28)/(POWER((1+$C$17/12),A28-1)) -> 0 | F28: =IF(OR(B28>$C$16,A28>$C$18),0,$C$17/12*(G27-C28)) -> 1510.3793 | G28: =IF(OR(B28>$C$16,A28>$C$18),0,G27-C28+F28) -> 364001.4 | I28: =IF(OR(B28>$C$16,($A28-1)>=MIN($C$18,$L$20),MIN($C$18,$L$20)<=1),0,($E$349+$H$349)/MAX(MIN($C$18,$L$20)-1,1)) -> 3517.3063 | J28: =IF(I28=0,0,J27+I28) -> 21103.838 | K28: =IF(OR(B28>$C$16,A28>$C$18),0,K27-I28) -> 397455.61 | L28: =IF(G28=0,0,G28*$C$19) -> 91000.35 | M28: =IF(K28=0,0,K28*$C$19) -> 99363.903
A29: =A28+1 -> 8 | B29: =EDATE(B28,1) -> 44409 | C29: =IF(AND(A29<=$C$18,MONTH(B29)=$E$20,B29<=$C$16,IF($O$20="期末",B29>=EDATE($C$15,12),B29>$C$15)),$C$20,0) -> 0 | E29: =(D29+C29)/(POWER((1+$C$17/12),A29-1)) -> 0 | F29: =IF(OR(B29>$C$16,A29>$C$18),0,$C$17/12*(G28-C29)) -> 1516.6725 | G29: =IF(OR(B29>$C$16,A29>$C$18),0,G28-C29+F29) -> 365518.07 | I29: =IF(OR(B29>$C$16,($A29-1)>=MIN($C$18,$L$20),MIN($C$18,$L$20)<=1),0,($E$349+$H$349)/MAX(MIN($C$18,$L$20)-1,1)) -> 3517.3063 | J29: =IF(I29=0,0,J28+I29) -> 24621.144 | K29: =IF(OR(B29>$C$16,A29>$C$18),0,K28-I29) -> 393938.3 | L29: =IF(G29=0,0,G29*$C$19) -> 91379.518 | M29: =IF(K29=0,0,K29*$C$19) -> 98484.576
A30: =A29+1 -> 9 | B30: =EDATE(B29,1) -> 44440 | C30: =IF(AND(A30<=$C$18,MONTH(B30)=$E$20,B30<=$C$16,IF($O$20="期末",B30>=EDATE($C$15,12),B30>$C$15)),$C$20,0) -> 0 | E30: =(D30+C30)/(POWER((1+$C$17/12),A30-1)) -> 0 | F30: =IF(OR(B30>$C$16,A30>$C$18),0,$C$17/12*(G29-C30)) -> 1522.992 | G30: =IF(OR(B30>$C$16,A30>$C$18),0,G29-C30+F30) -> 367041.06 | I30: =IF(OR(B30>$C$16,($A30-1)>=MIN($C$18,$L$20),MIN($C$18,$L$20)<=1),0,($E$349+$H$349)/MAX(MIN($C$18,$L$20)-1,1)) -> 3517.3063 | J30: =IF(I30=0,0,J29+I30) -> 28138.45 | K30: =IF(OR(B30>$C$16,A30>$C$18),0,K29-I30) -> 390421 | L30: =IF(G30=0,0,G30*$C$19) -> 91760.266 | M30: =IF(K30=0,0,K30*$C$19) -> 97605.25
A31: =A30+1 -> 10 | B31: =EDATE(B30,1) -> 44470 | C31: =IF(AND(A31<=$C$18,MONTH(B31)=$E$20,B31<=$C$16,IF($O$20="期末",B31>=EDATE($C$15,12),B31>$C$15)),$C$20,0) -> 0 | E31: =(D31+C31)/(POWER((1+$C$17/12),A31-1)) -> 0 | F31: =IF(OR(B31>$C$16,A31>$C$18),0,$C$17/12*(G30-C31)) -> 1529.3378 | G31: =IF(OR(B31>$C$16,A31>$C$18),0,G30-C31+F31) -> 368570.4 | I31: =IF(OR(B31>$C$16,($A31-1)>=MIN($C$18,$L$20),MIN($C$18,$L$20)<=1),0,($E$349+$H$349)/MAX(MIN($C$18,$L$20)-1,1)) -> 3517.3063 | J31: =IF(I31=0,0,J30+I31) -> 31655.757 | K31: =IF(OR(B31>$C$16,A31>$C$18),0,K30-I31) -> 386903.69 | L31: =IF(G31=0,0,G31*$C$19) -> 92142.601 | M31: =IF(K31=0,0,K31*$C$19) -> 96725.923
A32: =A31+1 -> 11 | B32: =EDATE(B31,1) -> 44501 | C32: =IF(AND(A32<=$C$18,MONTH(B32)=$E$20,B32<=$C$16,IF($O$20="期末",B32>=EDATE($C$15,12),B32>$C$15)),$C$20,0) -> 0 | E32: =(D32+C32)/(POWER((1+$C$17/12),A32-1)) -> 0 | F32: =IF(OR(B32>$C$16,A32>$C$18),0,$C$17/12*(G31-C32)) -> 1535.71 | G32: =IF(OR(B32>$C$16,A32>$C$18),0,G31-C32+F32) -> 370106.11 | I32: =IF(OR(B32>$C$16,($A32-1)>=MIN($C$18,$L$20),MIN($C$18,$L$20)<=1),0,($E$349+$H$349)/MAX(MIN($C$18,$L$20)-1,1)) -> 3517.3063 | J32: =IF(I32=0,0,J31+I32) -> 35173.063 | K32: =IF(OR(B32>$C$16,A32>$C$18),0,K31-I32) -> 383386.39 | L32: =IF(G32=0,0,G32*$C$19) -> 92526.528 | M32: =IF(K32=0,0,K32*$C$19) -> 95846.597
A33: =A32+1 -> 12 | B33: =EDATE(B32,1) -> 44531 | C33: =IF(AND(A33<=$C$18,MONTH(B33)=$E$20,B33<=$C$16,IF($O$20="期末",B33>=EDATE($C$15,12),B33>$C$15)),$C$20,0) -> 0 | E33: =(D33+C33)/(POWER((1+$C$17/12),A33-1)) -> 0 | F33: =IF(OR(B33>$C$16,A33>$C$18),0,$C$17/12*(G32-C33)) -> 1542.1088 | G33: =IF(OR(B33>$C$16,A33>$C$18),0,G32-C33+F33) -> 371648.22 | I33: =IF(OR(B33>$C$16,($A33-1)>=MIN($C$18,$L$20),MIN($C$18,$L$20)<=1),0,($E$349+$H$349)/MAX(MIN($C$18,$L$20)-1,1)) -> 3517.3063 | J33: =IF(I33=0,0,J32+I33) -> 38690.369 | K33: =IF(OR(B33>$C$16,A33>$C$18),0,K32-I33) -> 379869.08 | L33: =IF(G33=0,0,G33*$C$19) -> 92912.055 | M33: =IF(K33=0,0,K33*$C$19) -> 94967.27
A34: =A33+1 -> 13 | B34: =EDATE(B33,1) -> 44562 | C34: =IF(AND(A34<=$C$18,MONTH(B34)=$E$20,B34<=$C$16,IF($O$20="期末",B34>=EDATE($C$15,12),B34>$C$15)),$C$20,0) -> 50000 | E34: =(D34+C34)/(POWER((1+$C$17/12),A34-1)) -> 47566.412 | F34: =IF(OR(B34>$C$16,A34>$C$18),0,$C$17/12*(G33-C34)) -> 1340.2009 | G34: =IF(OR(B34>$C$16,A34>$C$18),0,G33-C34+F34) -> 322988.42 | I34: =IF(OR(B34>$C$16,($A34-1)>=MIN($C$18,$L$20),MIN($C$18,$L$20)<=1),0,($E$349+$H$349)/MAX(MIN($C$18,$L$20)-1,1)) -> 3517.3063 | J34: =IF(I34=0,0,J33+I34) -> 42207.676 | K34: =IF(OR(B34>$C$16,A34>$C$18),0,K33-I34) -> 376351.77 | L34: =IF(G34=0,0,G34*$C$19) -> 80747.106 | M34: =IF(K34=0,0,K34*$C$19) -> 94087.943
... A348: =A347+1 -> 327 | B348: =EDATE(B347,1) -> 54118 | C348: =IF(AND(A348<=$C$18,MONTH(B348)=$E$20,B348<=$C$16,IF($O$20="期末",B348>=EDATE($C$15,12),B348>$C$15)),$C$20,0) -> 0 | E348: =(D348+C348)/(POWER((1+$C$17/12),A348-1)) -> 0 | F348: =IF(OR(B348>$C$16,A348>$C$18),0,$C$17/12*(G347-C348)) -> 0 | G348: =IF(OR(B348>$C$16,A348>$C$18),0,G347-C348+F348) -> 0 | I348: =IF(OR(B348>$C$16,($A348-1)>=MIN($C$18,$L$20),MIN($C$18,$L$20)<=1),0,($E$349+$H$349)/MAX(MIN($C$18,$L$20)-1,1)) -> 0 | J348: =IF(I348=0,0,J347+I348) -> 0 | K348: =IF(OR(B348>$C$16,A348>$C$18),0,K347-I348) -> 0 | L348: =IF(G348=0,0,G348*$C$19) -> 0 | M348: =IF(K348=0,0,K348*$C$19) -> 0
B349: 合计 | C349: =SUM(C22:C348) -> 450000 | D349: =SUM(D22:D348) -> 0 | E349: =SUM(E22:E348) -> 353559.45 | F349: =SUM(F22:F348) -> 96440.551 | H349: =SUM(H22:H348) -> 65000 | I349: =SUM(I22:I348) -> 418559.45 | J349: —— | K349: ——
A350: 自检：①H8-5日期已带入；②O20与按年Q9一致；③末月负债≈0；④折旧合计≈入账；⑤J20≈按年L9。
A352: 三、审计说明：
A353: 1.租赁条件是否真实、完整（合同/补充协议/续租与终止选择权，索引H8-4/H8-5）
A354: 2.所采用的折现率是否正确（内含利率或增量借款利率；月利率=年利率/12的口径是否披露）
A355: 3.使用权资产入账价值是否正确（现值+预付/初始直接费用/复原成本−激励；与H9负债初始一致）
...

Sheet 租赁变更H8-7
A1: 致同会计师事务所
A2: 租赁变更
A3: =底稿目录!A2 -> 被审计单位： | D3: =底稿目录!A4 -> 编制人： | F3: =底稿目录!A6 -> 编制日期： | H3: 索引号： | I3: H8-7
A4: =底稿目录!A3 -> 截止日：202X年12月31日 | D4: =底稿目录!A5 -> 复核人： | F4: =底稿目录!A7 -> 复核日期： | H4: 页 次：
A5: 一、审计目标：1. 资产负债表中记录的使用权资产是存在的，且已记录于恰当的账户；2. 所有应记录的使用权资产均已记录，所有应当包括在财务报表中的相关披露均已包括；3. 记录的使用权资产由被审计单位拥有或控制；4. 使用权资产以恰当的金额包括在财务报表中，与之相关的计价或分摊调整已恰当记录，相关披露已得到恰当计量和描述。
A6: 二、审计过程：
A7: 1. 租赁变更情况
A8: 1. 1 租赁变更是否作为一项单独租赁 | D8: 是否适用 | E8: 是
A9: 条件（同时满足） | C9: 合同信息 | E9: 是否满足 | F9: 分析 | I9: 索引
A10: （1）该租赁变更通过增加一项或多项租赁资产的使用权而扩大了租赁范围； | J10: 租赁变更，是指原合同条款之外的租赁范围、租赁对价、租赁期限的变更，包括增加或终止一项或多项租赁资产的使用权，延长或缩短合同规定的租赁期等。
A11: （2）增加的对价与租赁范围扩大部分的单独价格按该合同情况调整后的金额相当。
A12: 结 论 | C12: =IF(AND(E10="是",E11="是"),"应当将该租赁变更作为一项单独租赁进行会计处理","应当分摊变更后合同的对价，重新确定租赁期，并按照变更后租赁付款额和修订后的折现率计算的现值重新计量租赁负债") -> 应当分摊变更后合同的对价，重新确定租赁期，并按照变更后租赁付款额和修订后的折现率计算的现值重新计量租赁负债
A14: 1.2 租赁变更未作为一项单独租赁处理 | D14: 是否适用 | E14: 是
A15: 情形 | C15: 合同信息 | E15: 是/否 | F15: 分析 | I15: 索引
A16: （1）租赁变更导致租赁范围缩小或租赁期缩短 | F16: 承租人应当调减使用权资产的账面价值，以反映租赁的部分终止或完全终止。承租人应将部分终止或完全终止租赁的相关利得或损失计入当期损益。
A17: （2）其他租赁变更 | C17: 第6年末，情况发生变化，合理确定将行使额外5年续租选择权 | E17: 是 | F17: 承租人应当相应调整使用权资产的账面价值。
A18: 结 论
A20: 2. 原租赁合同
A21: 2.1 原租赁合同的基本信息
A22: 使用权资产名称 | B22: 租赁期开始日 | C22: 合同约定初始期满日 | D22: 续租期（年） | E22: 租赁期（考虑续租可能后） | F22: 租赁期截止日期 | G22: 增量借款利率 | H22: 折现率 | I22: 使用权资产摊销期限（年）
A23: XX设备 | B23: 44197 | C23: 47118 | D23: =2 -> 2 | E23: =(YEAR(C23)-YEAR(B23))+D23+(MONTH(C23)-MONTH(B23)+1)/12 -> 10 | F23: =DATE(YEAR(C23)+D23,MONTH(C23),DAY(C23)) -> 47848 | G23: 0.05 | H23: 0.05 | I23: 10
A26: 2.2 计算租赁负债余额
A27: 租金支付日期 | B27: 剩余合同租金（不含税） | C27: 租赁付款额原值 | D27: 租赁负债折现期(年） | E27: 租赁负债折现系数 | F27: 租赁付款额现值 | G27: 租赁预付款 | H27: 初始直接费用 | I27: 使用权资产初始确认金额
A28: 44197 | B28: 50000 | C28: =IF(E28=1,0,B28) -> 0 | D28: 0 | E28: =1/(1+$H$23)^D28 -> 1 | F28: =C28*E28 -> 0 | G28: =B28 -> 50000 | H28: 15000
A29: 44562 | B29: 50000 | C29: =IF(E29=1,0,B29) -> 50000 | D29: =D28+1 -> 1 | E29: =1/(1+$H$23)^D29 -> 0.95238095 | F29: =C29*E29 -> 47619.048
A30: 44927 | B30: 50000 | C30: =IF(E30=1,0,B30) -> 50000 | D30: =D29+1 -> 2 | E30: =1/(1+$H$23)^D30 -> 0.90702948 | F30: =C30*E30 -> 45351.474
A31: 45292 | B31: 50000 | C31: =IF(E31=1,0,B31) -> 50000 | D31: =D30+1 -> 3 | E31: =1/(1+$H$23)^D31 -> 0.8638376 | F31: =C31*E31 -> 43191.88
A32: 45658 | B32: 50000 | C32: =IF(E32=1,0,B32) -> 50000 | D32: =D31+1 -> 4 | E32: =1/(1+$H$23)^D32 -> 0.82270247 | F32: =C32*E32 -> 41135.124
A33: 46023 | B33: 50000 | C33: =IF(E33=1,0,B33) -> 50000 | D33: =D32+1 -> 5 | E33: =1/(1+$H$23)^D33 -> 0.78352617 | F33: =C33*E33 -> 39176.308
A34: 46388 | B34: 50000 | C34: =IF(E34=1,0,B34) -> 50000 | D34: =D33+1 -> 6 | E34: =1/(1+$H$23)^D34 -> 0.7462154 | F34: =C34*E34 -> 37310.77
A35: 46753 | B35: 50000 | C35: =IF(E35=1,0,B35) -> 50000 | D35: =D34+1 -> 7 | E35: =1/(1+$H$23)^D35 -> 0.71068133 | F35: =C35*E35 -> 35534.067
A36: 47119 | B36: 50000 | C36: =IF(E36=1,0,B36) -> 50000 | D36: =D35+1 -> 8 | E36: =1/(1+$H$23)^D36 -> 0.67683936 | F36: =C36*E36 -> 33841.968
A37: 47484 | B37: 50000 | C37: =IF(E37=1,0,B37) -> 50000 | D37: =D36+1 -> 9 | E37: =1/(1+$H$23)^D37 -> 0.64460892 | F37: =C37*E37 -> 32230.446
A38: 合计 | B38: =SUM(B28:B37) -> 500000 | C38: =SUM(C28:C37) -> 450000 | F38: =SUM(F28:F37) -> 355391.08 | G38: =SUM(G28:G37) -> 50000 | H38: =SUM(H28:H37) -> 15000 | I38: =F38+G38+H38 -> 420391.08
A40: 2.3 租赁负债及使用权资产后续计量
A41: 期间 | B41: 租赁负债 | G41: 使用权资产
B42: 期初余额 | C42: 租赁付款额 | D42: 支付月份 | E42: 利息费用 | F42: 期末余额 | G42: 期初余额 | H42: 折旧费用 | I42: 期末余额
