Workbook
Name _1、: #REF!
Name _1、受本循环影响的相关交易和账户余额: #REF!
Name _2、主要业务活动: #REF!
Name _2、注册会计师通常应在本循环中了解与上述业务活动相关的内部控制_如果计划在其他业务循环中对上述: #REF!
Name a暗暗: [1]企业表一!$F$20
Name CarryKnown: #REF!
Name CarryKnownTable: #REF!
Name CarryLikely: #REF!
Name CarryLikelyTable: #REF!
Name Carryover_Effect_of_Prior_Year: #REF!
Name CarryoverTitle: #REF!
Name CC_Instruction: #REF!
Name CE_CarryKnownProtection: #REF!
Name CE_CarryKnownTable: #REF!
Name CE_CarryLikely1Protection: #REF!
Name CE_CarryLikely1Table: #REF!
Name CE_CarryLikely2Protection: #REF!
Name CE_CarryLikely2Table: #REF!
Name CE_CarryTaxable: #REF!
Name CE_Desc: #REF!
Name CE_Income: #REF!
Name CE_KeepFormat: #REF!
Name CE_KnownChange: #REF!
Name CE_KnownFormulaProtection: #REF!
Name CE_KnownImpact: #REF!
Name CE_Likely1Change: #REF!
Name CE_Likely1FormulaProtection: #REF!
Name CE_Likely1Impact: #REF!
Name CE_Likely2Change: #REF!
Name CE_Likely2FormulaProtection: #REF!
Name CE_Likely2Impact: #REF!
Name CE_SheetCorrect: #REF!
Name CE_StatementImpact: #REF!
Name CE_TotalProtection: #REF!
Name CE_WholeSheet: #REF!
Name CE_XF1: #REF!
Name CE_XF1Rng1: #REF!
Name CE_XF1Rng2: #REF!
Name CE_XF2: #REF!
Name CE_XF2Rng1: #REF!
Name CE_XF2Rng2: #REF!
Name CE_XF3: #REF!
Name CE_XF3Rng1: #REF!
Name CE_XF3Rng2: #REF!
Name ChecklistQuestion1: #REF!
Name ChecklistQuestion2: #REF!
Name ChecklistQuestion3: #REF!
Name Conclusions1: #REF!
Name Conclusions2: #REF!
Name Conclusions3: #REF!
Name Conclusions4: #REF!
Name CorrectKey: #REF!
Name Current_Year_Known_and_Likely_Misstatements: #REF!
Name CY_all_Assets: #REF!
Name CY_all_Equity: #REF!
Name CY_all_Income: #REF!
Name CY_all_Liabs: #REF!
Name CY_all_RetEarn_bf: #REF!
Name CY_knw_Assets: #REF!
Name CY_knw_Equity: #REF!

Sheet 底稿目录
A1: 底稿开列时，可先在以下单元格填写有关内容，以便其他底稿引用有关数据：
A2: 被审计单位名称： | D2: 序号 | E2: 内容 | F2: 索引号
A3: 截止日：202X年12月31日 | D3: 1 | E3: 函证结果汇总表 | F3: D0-1
A4: 编制人： | D4: 2 | E4: 核实被函证单位信息 | F4: D0-2
A5: 编制日期： | D5: 3 | E5: 跟函函证过程控制 | F5: D0-3
A6: 复核人： | D6: 4 | E6: 函证差异调节表 | F6: D0-4
A7: 复核日期： | D7: 5 | E7: 应收及销售替代程序检查表 | F7: D0-6
D8: 6 | E8: 邮件传真回函可靠性验证 | F8: D0-7
A9: 关于工作底稿与审计程序索引号对应的说明 | D9: 7 | E9: 函证程序舞弊风险评价表 | F9: D0-8
A10: 1.编制的审计工作底稿应与审计程序对应。审计项目组应根据被审计单位实际情况和风险评估情况在实质性程序表中裁剪、修改或增加审计程序，根据实际执行的审计程序完成相应审计工作底稿，编制的工作底稿中应按自然顺序依次编制索引号，并通过唯一的索引号将与实质性程序表中的程序对应关联（即将工作底稿的索引号填入实质性程序表中的底稿索引号列）。 | D10: 10 | E10: 关联方及交易检查表 | F10: D2-6
D11: 11 | E11: 应收账款检查表 | F11: D2-7
D12: 12 | E12: 坏账准备计提会计政策检查 | F12: D2-8
D13: 13 | E13: 坏账准备测算表 | F13: D2-9
A14: 2.获取的支持性证据应与审计底稿或程序对应。审计项目组在完成底稿时获取的支持性证据应根据底稿索引号编制下一级按自然顺序排序的索引号（如D1-2-1、D1-2-2、……），并在底稿中说明引用的支持性证据、关联索引号。 | D14: 14 | E14: 预期信用损失的计量测试 | F14: D2-10
D15: 15 | E15: 坏账准备转回、核销检查表 | F15: D2-11
D16: 16 | E16: 应收账款质押出售情况检查表 | F16: D2-12
A17: 3.工作底稿索引号的编码规则：实质性程序索引号按循环从“D”到“N”,循环内账户以顺序号排列，模板中底稿索引号按账户顺序+自然数顺序（即模板中索引号按二级自然顺序排列，如D1-1、D1-2、D1-3、……D1-N）。 | D17: 17 | E17: 应收账款业务模式分析 | F17: D2-13

Sheet 附注披露信息(上市公司）D2-1
A1: 致同会计师事务所
A2: 附注披露信息（上市公司）
A3: =底稿目录!A2 -> 被审计单位名称： | C3: =底稿目录!A4 -> 编制人： | E3: =底稿目录!A5 -> 编制日期： | F3: 索引：D2-1
A4: =底稿目录!A3 -> 截止日：202X年12月31日 | C4: =底稿目录!A6 -> 复核人： | E4: =底稿目录!A7 -> 复核日期： | F4: 页次：
A5: 附注披露信息：
A6: 应收账款（以下不适用的，请删除）
A7: （1）应收账款按种类披露
A8: 种类 | B8: 期末数
B9: 金 额 | C9: 比例% | D9: 坏账准备 | E9: 计提比例% | F9: 净额
A10: 单项计提坏账准备的应收账款 | B10: ='应收坏账准备测算D2-9'!#REF! -> #REF! | C10: =B10/$B$17 -> #REF! | D10: ='应收坏账准备测算D2-9'!#REF! -> #REF! | E10: =IF(B10=0,,D10/B10) -> #REF! | F10: =B10-D10 -> #REF!
A11: 按组合计提坏账准备的应收账款
A12: 其中：账龄组合 | B12: ='应收坏账准备测算D2-9'!#REF! -> #REF! | C12: =B12/$B$17 -> #REF! | D12: ='应收坏账准备测算D2-9'!#REF! -> #REF! | E12: =IF(B12=0,,D12/B12) -> #REF! | F12: =B12-D12 -> #REF!
A13: 客户类型组合 | B13: ='应收坏账准备测算D2-9'!#REF! -> #REF! | C13: =B13/$B$17 -> #REF! | D13: ='应收坏账准备测算D2-9'!#REF! -> #REF! | E13: =IF(B13=0,,D13/B13) -> #REF! | F13: =B13-D13 -> #REF!
A14: 产品类型组合 | C14: =B14/$B$17 -> #REF! | E14: =IF(B14=0,,D14/B14) -> 0 | F14: =B14-D14 -> 0
A15: ……组合 | C15: =B15/$B$17 -> #REF! | E15: =IF(B15=0,,D15/B15) -> 0 | F15: =B15-D15 -> 0
A16: 组合小计 | B16: =SUM(B12:B15) -> #REF! | C16: =B16/$B$17 -> #REF! | D16: =SUM(D12:D15) -> #REF! | E16: =IF(B16=0,,D16/B16) -> #REF! | F16: =SUM(F12:F15) -> #REF!
A17: 合 计 | B17: =SUM(B10+B16) -> #REF! | C17: =B17/B17 -> #REF! | D17: =SUM(D10+D16) -> #REF! | E17: =IF(B17=0,,D17/B17) -> #REF! | F17: =SUM(F10+F16) -> #REF!
A18: 应收账款按种类披露（续）
A19: 种类 | B19: 期初数
B20: 金 额 | C20: 比例% | D20: 坏账准备 | E20: 计提比例% | F20: 净额
A21: 单项计提坏账准备的应收账款 | C21: =IF($B$28=0,0,B21/$B$28) -> 0 | E21: =IF(B21=0,0,D21/B21) -> 0 | F21: =B21-D21 -> 0
A22: 按组合计提坏账准备的应收账款
A23: 其中：账龄组合 | C23: =IF($B$28=0,0,B23/$B$28) -> 0 | E23: =IF(B23=0,0,D23/B23) -> 0 | F23: =B23-D23 -> 0
A24: 客户类型组合 | C24: =IF($B$28=0,0,B24/$B$28) -> 0 | E24: =IF(B24=0,0,D24/B24) -> 0 | F24: =B24-D24 -> 0
A25: 产品类型组合 | C25: =IF($B$28=0,0,B25/$B$28) -> 0 | E25: =IF(B25=0,0,D25/B25) -> 0 | F25: =B25-D25 -> 0
A26: ……组合 | C26: =IF($B$28=0,0,B26/$B$28) -> 0 | E26: =IF(B26=0,0,D26/B26) -> 0 | F26: =SUM(F23:F25) -> 0
A27: 组合小计 | B27: =SUM(B23:B26) -> 0 | C27: =SUM(C23:C26) -> 0 | D27: =SUM(D23:D26) -> 0 | E27: =SUM(E23:E26) -> 0 | F27: =B27-D27 -> 0
A28: 合 计 | B28: =SUM(B21+B27) -> 0 | C28: =SUM(C21+C27) -> 0 | D28: =SUM(D21+D27) -> 0 | E28: =SUM(E21+E27) -> 0 | F28: =SUM(F21+F27) -> 0
A29: 注：填写组合名称。账面余额中的比例按期末该类应收账款除以应收账款合计数计算，坏账准备比例按该类应收账款期末已计提坏账准备除以期末该类应收账款余额计算。
A30: 说明：
A31: ①期末单项计提坏账准备的应收账款
A32: 应收账款（按单位） | B32: 账面余额 | C32: 坏账准备 | D32: 计提比例% | E32: 计提理由
D33: =IF(B33=0,0,C33/B33) -> 0
D34: =IF(B34=0,0,C34/B34) -> 0
D35: =IF(B35=0,0,C35/B35) -> 0
D36: =IF(B36=0,0,C36/B36) -> 0
D37: =IF(B37=0,0,C37/B37) -> 0
A38: 合 计 | B38: =SUM(B33:B37) -> 0 | C38: =SUM(C33:C37) -> 0 | D38: =IF(B38=0,0,C38/B38) -> 0
A39: ②按账龄组合计提坏账准备的应收账款：（不适用的删除）
A40: 账 龄 | B40: 期末数
...

Sheet 附注披露信息（国企）D2-1
A1: 致同会计师事务所
A2: 附注披露信息（国企）
A3: =底稿目录!A2 -> 被审计单位名称： | C3: =底稿目录!A4 -> 编制人： | E3: =底稿目录!A5 -> 编制日期： | G3: 索引：D2-1
A4: =底稿目录!A3 -> 截止日：202X年12月31日 | C4: =底稿目录!A6 -> 复核人： | E4: =底稿目录!A7 -> 复核日期： | G4: 页次：1
A5: 附注披露信息：
A6: 应收账款
A7: 应收账款按种类披露
A8: 种 类 | B8: 期末数
B9: 账面余额 | C9: 比例% | D9: 坏账准备 | E9: 比例%
A10: 单项计提坏账准备的应收账款 | B10: ='应收坏账准备测算D2-9'!#REF! -> #REF! | C10: =IF($B$17=0,0,B10/$B$17) -> #REF! | D10: ='应收坏账准备测算D2-9'!#REF! -> #REF! | E10: =IF(B10=0,0,D10/B10) -> #REF!
A11: 按组合计提坏账准备的应收账款
A12: 其中：账龄组合 | B12: ='应收坏账准备测算D2-9'!#REF! -> #REF! | C12: =IF($B$17=0,0,B12/$B$17) -> #REF! | D12: ='应收坏账准备测算D2-9'!#REF! -> #REF! | E12: =IF(B12=0,0,D12/B12) -> #REF!
A13: 客户类型组合 | B13: ='应收坏账准备测算D2-9'!#REF! -> #REF! | C13: =IF($B$17=0,0,B13/$B$17) -> #REF! | D13: ='应收坏账准备测算D2-9'!#REF! -> #REF! | E13: =IF(B13=0,0,D13/B13) -> #REF!
A14: 产品类型组合 | C14: =IF($B$17=0,0,B14/$B$17) -> #REF! | E14: =IF(B14=0,0,D14/B14) -> 0
A15: ……组合 | C15: =IF($B$17=0,0,B15/$B$17) -> #REF! | E15: =IF(B15=0,0,D15/B15) -> 0
A16: 组合小计 | B16: =SUM(B12:B15) -> #REF! | C16: =IF($B$17=0,0,B16/$B$17) -> #REF! | D16: =SUM(D12:D15) -> #REF! | E16: =IF(B16=0,0,D16/B16) -> #REF!
A17: 合 计 | B17: =SUM(B10+B16) -> #REF! | C17: =SUM(C10+C16) -> #REF! | D17: =SUM(D10+D16) -> #REF! | E17: =IF(B17=0,0,D17/B17) -> #REF!
A18: 应收账款按种类披露（续）
A19: 种 类 | B19: 年初数
B20: 账面余额 | C20: 比例% | D20: 坏账准备 | E20: 比例%
A21: 单项计提坏账准备的应收账款 | C21: =IF($B$28=0,0,B21/$B$28) -> 0 | E21: =IF(B21=0,0,D21/B21) -> 0
A22: 按组合计提坏账准备的应收账款
A23: 其中：账龄组合 | C23: =IF($B$28=0,0,B23/$B$28) -> 0 | E23: =IF(B23=0,0,D23/B23) -> 0
A24: 客户类型组合 | C24: =IF($B$28=0,0,B24/$B$28) -> 0 | E24: =IF(B24=0,0,D24/B24) -> 0
A25: 产品类型组合 | C25: =IF($B$28=0,0,B25/$B$28) -> 0 | E25: =IF(B25=0,0,D25/B25) -> 0
A26: ……组合 | C26: =IF($B$28=0,0,B26/$B$28) -> 0 | E26: =IF(B26=0,0,D26/B26) -> 0
A27: 组合小计 | B27: =SUM(B23:B26) -> 0 | C27: =IF($B$28=0,0,B27/$B$28) -> 0 | D27: =SUM(D23:D26) -> 0 | E27: =IF(B27=0,0,D27/B27) -> 0
A28: 合 计 | B28: =SUM(B21+B26+B27) -> 0 | C28: =SUM(C21+C26+C27) -> 0 | D28: =SUM(D21+D26+D27) -> 0 | E28: =IF(B28=0,0,D28/B28) -> 0
A29: （注：①填写组合名称。②账面余额中的比例按年末该类应收账款除以应收账款余额合计数计算，坏账准备比例按该类应收账款年末已计提坏账准备除以年末该类应收账款余额计算。）
A30: （1）按组合计提坏账准备的应收账款
A31: A、采用账龄分析法计提坏账准备的应收账款
A32: 账 龄 | B32: 期末数 | E32: 年初数
B33: 账面余额 | D33: 坏账准备 | E33: 账面余额 | G33: 坏账准备
B34: 金额 | C34: 比例(%) | E34: 金额 | F34: 比例(%)
A35: ='应收坏账准备测算D2-9'!#REF! -> #REF! | B35: ='应收坏账准备测算D2-9'!#REF! -> #REF! | C35: =IF(B35=0,0,B35/$B$41) -> #REF! | D35: ='应收坏账准备测算D2-9'!#REF! -> #REF! | F35: =IF(E35=0,0,E35/$E$41) -> 0
A36: ='应收坏账准备测算D2-9'!#REF! -> #REF! | B36: ='应收坏账准备测算D2-9'!#REF! -> #REF! | C36: =IF(B36=0,0,B36/$B$41) -> #REF! | D36: ='应收坏账准备测算D2-9'!#REF! -> #REF! | F36: =IF(E36=0,0,E36/$E$41) -> 0
A37: ='应收坏账准备测算D2-9'!#REF! -> #REF! | B37: ='应收坏账准备测算D2-9'!#REF! -> #REF! | C37: =IF(B37=0,0,B37/$B$41) -> #REF! | D37: ='应收坏账准备测算D2-9'!#REF! -> #REF! | F37: =IF(E37=0,0,E37/$E$41) -> 0
A38: ='应收坏账准备测算D2-9'!#REF! -> #REF! | B38: ='应收坏账准备测算D2-9'!#REF! -> #REF! | C38: =IF(B38=0,0,B38/$B$41) -> #REF! | D38: ='应收坏账准备测算D2-9'!#REF! -> #REF! | F38: =IF(E38=0,0,E38/$E$41) -> 0
A39: ='应收坏账准备测算D2-9'!#REF! -> #REF! | B39: ='应收坏账准备测算D2-9'!#REF! -> #REF! | C39: =IF(B39=0,0,B39/$B$41) -> #REF! | D39: ='应收坏账准备测算D2-9'!#REF! -> #REF! | F39: =IF(E39=0,0,E39/$E$41) -> 0
A40: ='应收坏账准备测算D2-9'!#REF! -> #REF! | B40: ='应收坏账准备测算D2-9'!#REF! -> #REF! | C40: =IF(B40=0,0,B40/$B$41) -> #REF! | D40: ='应收坏账准备测算D2-9'!#REF! -> #REF! | F40: =IF(E40=0,0,E40/$E$41) -> 0
...

Sheet 关联方及交易检查表D2-6
A1: 致同会计师事务所
A2: 应收账款关联方及交易检查表
A3: 被审计单位： | E3: =底稿目录!A4 -> 编制人： | H3: =底稿目录!A5 -> 编制日期： | K3: 索引号： | L3: =底稿目录!F10 -> D2-6
A4: 截止日：202X年12月31日 | E4: =底稿目录!A6 -> 复核人： | H4: =底稿目录!A7 -> 复核日期： | K4: 页次：
A5: 一、审计目标
A6: 1.资产负债表中记录的应收账款是存在的，且已经记录在恰当的账户中。 2.所有应记录的应收账款均已记录，所有应当包括在财务报表中的相关披露均已包括。
A7: 4.应收账款以恰当的金额包括在财务报表中，与之相关的计价或分摊调整已恰当记录，相关披露已得到恰当计量和描述。
A8: 二、审计过程
A9: 1.……
A12: 关联方名称 | B12: 关联关系 | C12: 期初余额 | D12: 借方发生 | E12: 贷方发生 | F12: 期末余额 | G12: 减：坏账准备 | H12: 账面价值 | I12: 发生时间及账龄 | J12: 发生原因（款项性质） | K12: 期后回款 | L12: 索引号
F13: =C13+D13-E13 -> 0 | H13: =F13-G13 -> 0
F14: =C14+D14-E14 -> 0 | H14: =F14-G14 -> 0
F15: =C15+D15-E15 -> 0 | H15: =F15-G15 -> 0
A16: 合计 | C16: =SUM(C13:C15) -> 0 | D16: =SUM(D13:D15) -> 0 | E16: =SUM(E13:E15) -> 0 | F16: =SUM(F13:F15) -> 0 | G16: =SUM(G13:G15) -> 0 | H16: =SUM(H13:H15) -> 0
A17: 三、审计说明：
A21: 四、审计结论：
B23: 勿删、勿改
B24: 实际控制人
B25: 控股股东
B26: 控股股东、实际控制人的附属企业
B27: 持有5%以上股份的法人或其他组织
B28: 联营企业
B29: 合营企业
B30: 董高监等关键管理人员
B31: 其他关联方

Sheet 应收账款检查表D2-7
A1: 致同会计师事务所
A2: 应收账款检查表
A3: =底稿目录!A2 -> 被审计单位名称： | F3: =底稿目录!A4 -> 编制人： | J3: =底稿目录!A5 -> 编制日期： | P3: 索引号： | Q3: =底稿目录!F11 -> D2-7
A4: =底稿目录!A3 -> 截止日：202X年12月31日 | F4: =底稿目录!A6 -> 复核人： | J4: =底稿目录!A7 -> 复核日期： | P4: 页次：
A5: 一、审计目标：
A6: 1.资产负债表中记录的应收账款是存在的，且已经记录在恰当的账户中；2.应收账款以恰当的金额包括在财务报表中，与之相关的计价或分摊调整已恰当记录，相关披露已得到恰当计量和描述
A7: 二、样本选取标准与规模：
A8: 测试总体： | B8: 如应收账款借方发生额所有凭证共XX笔金额XX、贷方发生额所有凭证共XX笔金额XX | G8: 特定样本： | H8: XX金额以上（大额）、关联方/关联交易形成的款项、XX异常款项全部测试，共XX笔；
A9: 抽样总体： | B9: 测试总体扣除特定样本以外的样本，共XX笔、金额XX | G9: 确定的抽样样本量： | H9: 抽取XX笔 | I9: （如果使用了样本计算器计算样本量，样本量计算过程见<XX>底稿）
A10: 抽样方法： | B10: 随机选样/系统选样/货币单元抽样/随意选样（非统计抽样适用） | G10: 抽样过程： | H10: 使用IDEA（XX抽样工具）选择XX数量、金额XX的样本进行测试，抽样工具中的样本选择过程和结果见<XX>底稿
A11: 三、测试：
A12: 测试内容说明：1.原始凭证是否齐全； 2.记账凭证与原始凭证是否相符；3.账务处理是否正确；4.是否记录于恰当的会计期间；5.……
A13: （1）本期增减变动检查
A14: 客户名称 | B14: 记账凭证 | I14: 支持性文件 | J14: 核对内容 | O14: 索引号 | P14: 是否异常 | Q14: 备注说明
B15: 日期 | C15: 凭证编号 | D15: 业务内容 | E15: 对方科目 | F15: 对方明细科目 | G15: 借方金额 | H15: 贷方金额 | J15: 1 | K15: 2 | L15: 3 | M15: 4 | N15: 5
A31: 合计 | G31: =SUM(G16:G30) -> 0 | H31: =SUM(H16:H30) -> 0
A32: （2）期后收款、调整检查
A33: 客户名称 | B33: 记账凭证 | I33: 支持性文件 | J33: 核对内容 | O33: 索引号 | P33: 是否异常 | Q33: 备注说明
B34: 日期 | C34: 凭证编号 | D34: 业务内容 | E34: 对方科目 | F34: 对方明细科目 | G34: 借方金额 | H34: 贷方金额 | J34: 1 | K34: 2 | L34: 3 | M34: 4 | N34: 5
A43: 合计 | G43: =SUM(G35:G42) -> 0 | H43: =SUM(H35:H42) -> 0
A44: 四、审计说明：
A45: 1.本期发生额、期末余额检查比例： | D45: 方向 | E45: 账面金额 | F45: 检查金额 | G45: 检查比例 | H45: 如果检查比例较低应扩大检查样本量或说明原因
D46: 本期借方 | E46: 0 | F46: =G31 -> 0 | G46: =ROUND(F46/E46,4) -> #DIV/0!
D47: 本期贷方 | E47: 0 | F47: =H31 -> 0 | G47: =ROUND(F47/E47,2) -> #DIV/0!
D48: 期末余额 | E48: 0 | F48: =H43 -> 0 | G48: =ROUND(F48/E48,2) -> #DIV/0!
A49: 2.……
A50: 五、审计结论：

Sheet 坏账准备计提会计政策检查D2-8
A1: 致同会计师事务所
A2: 应收账款坏账准备计提会计政策检查
A3: =底稿目录!A2 -> 被审计单位名称： | C3: =底稿目录!A4 -> 编制人： | F3: =底稿目录!A5 -> 编制日期： | H3: 索引号： | I3: D2-8
A4: =底稿目录!A3 -> 截止日：202X年12月31日 | C4: =底稿目录!A6 -> 复核人： | F4: =底稿目录!A7 -> 复核日期： | H4: 页次：
A5: 一、审计目标：
A6: 应收账款以恰当的金额包括在财务报表中，与之相关的计价或分摊调整已恰当记录，相关披露已得到恰当计量和描述
A7: 二、审计过程：
A8: 1.……
A11: （一）应收账款坏账准备计提会计政策
A15: 【应说明被审计单位应收账款坏账准备信用风险组合划分依据、预期信用损失计量方法等】
A16: （二）被审计单位历史坏账损失情况
A20: 【应说明被审计单位应收账款历史损失率的数据来源，以及项目组核实该等数据所执行的程序。需考虑货币的时间价值】
A21: （三）前瞻性信息的来源及其影响
A25: 【应说明被审计单位确定预期损失率的前瞻性信息来源（包括内部模型、第三方服务机构或利用外部专家工作等，以及项目组对前瞻性信息可靠性所执行的程序】
A26: （四）同行业公司的会计政策
A27: XX
... A40: 提示4：会计政策披露示例参考
A41: 中国中铁 | B41: 对于应收票据及应收账款和合同资产，无论是否存在重大融资成分，本集团均按照整个存续期的预期信用损失计量损失准备。 本集团依据信用风险特征将应收票据及应收账款和合同资产划分为若干组合，在组合基础上计算预期信用损失，确定组合的依据如下： 应收账款组合1 应收中央企业客户 应收账款组合2 应收地方政府/地方国有企业客户 应收账款组合3 应收中国铁路总公司 应收账款组合4 应收海外企业客户 应收账款组合5 应收其他客户 对于划分为组合的应收票据和合同资产，本集团参考历史信用损失经验，结合当前状况以及对未来经济状况的预测，通过违约风险敞口和整个存续期预期信用损失率，计算预期信用损失。
A42: 福耀玻璃 | B42: 当单项金融资产无法以合理成本评估预期信用损失的信息时，本集团依据信用风险特征将应收款项划分为若干组合，在组合基础上计算预期信用损失，确定组合的依据如下：应收票据组合；应收账款组合；其他应收款组合。 对于划分为组合的应收票据，本集团参考历史信用损失经验，结合当前状况以及对未来经济状况的预测，通过违约风险敞口和整个存续期预期信用损失率，计算预期信用损失。 对于划分为组合的应收账款，本集团参考历史信用损失经验，结合当前状况以及对未来经济状况的预测，编制应收账款逾期天数与整个存续期预期信用损失率对照表，计算预期信用损失。 对于划分为组合的其他应收款，本集团参考历史信用损失经验，结合当前状况以及对未来经济状况的预测，通过违约风险敞口和未来12个月内或整个存续期预期信用损失率，计算预期信用损失。 在确定预期信用损失率时，本集团使用内部历史信用损失经验等数据，并结合当前状况和前瞻性信息对历史数据进行调整。在考虑前瞻性信息时，本集团使用的指标包括经济下滑的风险、预期失业率的增长、外部市场环境、技术环境和客户情况的变化等。本集团定期监控并复核与预期信用损失计算相关的假设。
A43: 中煤能源 | B43: 本集团对租赁应收款在单项资产的基础上确定其信用损失，对应收账款、合同资产、债权投资除对发生重大财务困难的债务人在单项资产的基础上确定其信用损失外，对其余款项在组合基础上采用减值矩阵确定相关金融工具的信用损失。 10.2.4 本集团依据信用风险特征将应收票据及应收账款和合同资产划分为若干组合 ，在组合基础上计算预期信用损失，确定组合的依据如下： • 应收账款\合同资产组合A 信用优良。在未来的信用风险很低，自身抗风险能力很强，不确定性因素对其经营与发展的影响很小。 • 应收账款\合同资产组合B ，信用较好。在未来的信用风险较低，自身有一定抗风险能力，但是可能存在一些影响其未来经营与发展的不确定性因素。 • 应收账款\合同资产组合C ，信用一般。在未来存在一定的信用风险，经营状况、盈利水平及未来发展易受不确定因素的影响。 • 应收账款\合同资产组合D ，信用较差。在未来的信用风险较高，未来前景不明朗或不安全，可能出现逾期非常严重的应收账款、合同资产。 对于划分为组合的应收账款，本集团参考历史信用损失经验，结合当前状况以及对未来经济状况的预测，编制应收账款账龄与整个存续期预期信用损失率对照表，计算预期信用损失。 对于划分为组合的合同资产，本集团参考历史信用损失经验，结合当前状况以及对未来经济状况的预测，通过违约风险敞口和整个存续期预期信用损失率，计算预期信用损失。
A44: 长飞光纤 | B44: 对于应收账款，本集团始终按照相当于整个存续期内预期信用损失的金额计量其损失准备。本集团基于历史信用损失经验、使用准备矩阵计算上述金融资产的预期信用损失，相关历史经验根据资产负债表日借款人的特定因素、以及对当前状况和未来经济状况预测的评估进行调整。 本公司根据历史经验，不同细分客户群体发生损失的情况存在差异，将本公司客户细分为以下群体： 群体1：集团外关联方；群体2：中国电信网络运营商及其他信用记录良好的企业；群体3：除群体1、2以外的其他客户。 本集团始终按照相当于整个存续期内预期信用损失的金额计量应收账款的减值准备，并以逾期天数与违约损失率对照表为基础计算其预期信用损失。根据本集团的历史经验，不同细分客户群体发生损失的情况存在差异，因此本集团根据历史经验区分不同的客户群体根据逾期信息计算减值准备。 违约损失率基于过去5年的实际信用损失经验计算，并根据历史数据收集期间的经济状况、当前的经济状况与本集团所认为的预计存续期内的经济状况三者之间的差异进行调整。
A45: 长城汽车 | B45: 本集团对由新收入准则规范的交易形成的未包含重大融资成分或不考虑不超过一年的合同中的融资成分的合同资产与应收账款按照相当于整个存续期内预期信用损失的金额计量损失准备。 本集团对应收账款、其他分类为按摊余成本计量的金融资产和分类为以公允价值计量且其变动计入其他综合收益的债务工具在组合基础上采用减值矩阵确定相关金融工具的信用损失。本集团以共同风险特征为依据，将金融工具分为不同组别。本集团采用的共同信用风险特征包括：金融工具类型、信用风险评级、担保物类型、初始确认日期、剩余合同期限、债务人所处行业、债务人所处地理位置、担保品相对于金融资产的价值等。
A46: 金隅集团 | B46: 对于不含重大融资成分的应收款项以及合同资产，本集团运用简化计量方法，按照相当于整个存续期内的预期信用损失金额计量损失准备。 对于租赁应收款、包含重大融资成分的应收款项以及合同资产，本集团选择运用简化计量方法，按照相当于整个存续期内的预期信用损失金额计量损失准备。 除某些金融资产基于单项为基础评估逾期信用损失之外，本集团还以账龄组合为基础评估以摊余成本计量金融资产的预期信用损失。 本集团在评估预期信用损失时，考虑所有合理且有依据的信息，包括前瞻性信息。

Sheet 应收坏账准备测算D2-9
A1: 致同会计师事务所
A2: 应收账款坏账准备测算表
A3: =底稿目录!A2 -> 被审计单位名称： | C3: =底稿目录!A4 -> 编制人： | E3: =底稿目录!A5 -> 编制日期： | G3: 索引号： | H3: D2-9
A4: =底稿目录!A3 -> 截止日：202X年12月31日 | C4: =底稿目录!A6 -> 复核人： | E4: =底稿目录!A7 -> 复核日期： | G4: 页次：
A5: 一、审计目标
A6: 应收账款以恰当的金额包括在财务报表中，与之相关的计价或分摊调整已恰当记录，相关披露已得到恰当计量和描述
A7: 二、审计过程
A8: 1.……
A11: （一）单项计提坏账准备
A12: 债务人名称 | B12: 审定账面余额 | C12: 预期信用损失率 | D12: 期末应计提坏账准备 | E12: 期末坏账准备账面余额 | F12: 差异 | G12: 计提依据及文件 | H12: 索引号
B13: ① | C13: ② | D13: ③=①×② | E13: ④ | F13: ⑤=③-④
D14: =B14*C14 -> 0 | F14: =D14-E14 -> 0
D15: =B15*C15 -> 0 | F15: =D15-E15 -> 0
D16: =B16*C16 -> 0 | F16: =D16-E16 -> 0
D17: =B17*C17 -> 0 | F17: =D17-E17 -> 0
D18: =B18*C18 -> 0 | F18: =D18-E18 -> 0
A19: 小计 | B19: =SUM(B14:B18) -> 0 | C19: =IF(B19=0,"",D19/B19) -> 0 | D19: =SUM(D14:D18) | E19: =SUM(E14:E18) -> 0 | F19: =SUM(F14:F18) -> 0
A20: （二）账龄组合计提坏账准备
A21: 账龄【账龄以记账凭证日期起计算，逾期则考虑信用期】 | B21: 审定账面余额 | C21: 预期信用损失率 | D21: 期末应计提坏账准备 | E21: 期末坏账准备账面余额 | F21: 差异
B22: ① | C22: ② | D22: ③=①×② | E22: ④ | F22: ⑤=③-④
A23: 组合1：
A24: 1年以内/未逾期 | D24: =B24*C24 -> 0 | F24: =D24-E24 -> 0
A25: 1年-2年/逾期30天以内 | D25: =B25*C25 -> 0 | F25: =D25-E25 -> 0
A26: 2年-3年/逾期30-90天 | D26: =B26*C26 -> 0 | F26: =D26-E26 -> 0
A27: 3年-4年/逾期90天-1年 | D27: =B27*C27 -> 0 | F27: =D27-E27 -> 0
A28: 4年-5年/逾期1年-2年 | D28: =B28*C28 -> 0 | F28: =D28-E28 -> 0
A29: 5年以上/逾期2年以上 | D29: =B29*C29 -> 0 | F29: =D29-E29 -> 0
A30: 小计 | B30: =SUM(B24:B29) -> 0 | D30: =SUM(D24:D29) -> 0 | E30: =SUM(E24:E29) -> 0 | F30: =SUM(F24:F29) -> 0
A31: 组合2：
A32: 1年以内/未逾期 | D32: =B32*C32 -> 0 | F32: =D32-E32 -> 0
A33: 1年-2年/逾期30天以内 | D33: =B33*C33 -> 0 | F33: =D33-E33 -> 0
A34: 2年-3年/逾期30-90天 | D34: =B34*C34 -> 0 | F34: =D34-E34 -> 0
A35: 3年-4年/逾期90天-1年 | D35: =B35*C35 -> 0 | F35: =D35-E35 -> 0
A36: 4年-5年/逾期1年-2年 | D36: =B36*C36 -> 0 | F36: =D36-E36 -> 0
A37: 5年以上/逾期2年以上 | D37: =B37*C37 -> 0 | F37: =D37-E37 -> 0
A38: 小计 | B38: =SUM(B32:B37) -> 0 | D38: =SUM(D32:D37) -> 0 | E38: =SUM(E32:E37) -> 0 | F38: =SUM(F32:F37) -> 0
A39: 合计 | B39: =B38+B30 -> 0 | D39: =D38+D30 -> 0 | E39: =E38+E30 -> 0 | F39: =F38+F30 -> 0
A40: 三、审计说明
A44: 四、审计结论
A46: 提示1：对于资产负债表日已发生信用减值但并非购买或源生已发生信用减值的金融资产，信用损失为该金融资产账面余额与按原实际利率折现的估计未来现金流量的现值之间的差额。
...

Sheet 预期信用损失的计量测试D2-10
A1: 致同会计师事务所
A2: 预期信用损失的计量测试表
A3: =底稿目录!A2 -> 被审计单位名称： | C3: =底稿目录!A4 -> 编制人： | E3: =底稿目录!A5 -> 编制日期： | G3: 索引号： | H3: =底稿目录!F14 -> D2-10
A4: =底稿目录!A3 -> 截止日：202X年12月31日 | C4: =底稿目录!A6 -> 复核人： | E4: =底稿目录!A7 -> 复核日期： | G4: 页次：
A5: 一、审计目标：
A6: 应收账款以恰当的金额包括在财务报表中，与之相关的计价或分摊调整已恰当记录，相关披露已得到恰当计量和描述
A7: 二、审计过程：
A8: 1.……
A10: （一）单项计提的预期信用损失率的确定
A11: 单项计提 | B11: 账面余额 | C11: 不同情形下的未来现金流量① | D11: 折现值② | F11: 发生概率③ | G11: 概率加权④=②×③ | H11: 预期信用损失率⑤ | I11: 对于资产负债表日已发生信用减值但并非购买或源生已发生信用减值的金融资产，信用损失为该金融资产账面余额与按原实际利率折现的估计未来现金流量的现值之间的差额。
D12: 1年 | E12: 2年
G13: =(D13+E13)*F13 -> 0 | I13: 估计预期信用损失的目的并非对最坏的情形或最好的情形作出估计，取而代之的是，预期信用损失的估计应当始终反映发生信用损失的可能性以及不发生信用损失的可能性。
G14: =(D14+E14)*F14 -> 0
G15: =(D15+E15)*F15 -> 0 | I15: 由于预期信用损失考虑付款的金额和时间分布，因此即使企业预计可以全额收款但收款时间晚于合同规定的到期期限，也会产生信用损失。
A16: 实际利率 | C16: 合计 | D16: -- | E16: -- | F16: =IF(B13=0,"",SUM(F13:F15)) | G16: =SUM(G13:G15) -> 0 | H16: =IF(B13=0,"",(B13-G16)/B13)
G17: =(D17+E17)*F17 -> 0 | I17: 企业应当采用相关金融工具初始确认时确定的实际利率或其近似值，将现金流缺口折现为资产负债表日的现值。
G18: =(D18+E18)*F18 -> 0
G19: =(D19+E19)*F19 -> 0
A20: 实际利率 | C20: 合计 | D20: -- | E20: -- | F20: =IF(B17=0,"",SUM(F17:F19)) | G20: =SUM(G17:G19) -> 0 | H20: =IF(B17=0,"",(B17-G20)/B17)
A22: （二）计算历史损失率（示例方法仅供参考）
A23: 方法1：基于观察期赊销额后续回收的减值矩阵 | H23: 【方法可选】
A24: 观察期内应收账款总额 | E24: 累计核销坏账总额
A25: 账龄 | B25: 历史收回金额 | C25: 累计收款额 | D25: 应收账款余额 | E25: 实际信用损失 | F25: 说明 | G25: 历史损失率 | H25: 上期历史损失率
A26: ='坏账准备计提会计政策检查D2-8'!K26 -> 0 | D26: =C24 -> 0 | E26: =$G$24 -> 0 | G26: =E26/D26 -> #DIV/0! | I26: 由于预期信用损失考虑付款的金额和时间分布，因此即使企业预计可以全额收款但收款时间晚于合同规定的到期期限，也会产生信用损失。 自应收票据结转而来的应收账款损失率通常高于原始应收账款的损失率。
A27: ='坏账准备计提会计政策检查D2-8'!K27 -> 0 | C27: =C26+B27 -> 0 | D27: =D26-B26 -> 0 | E27: =$G$24 -> 0 | G27: =E27/D27 -> #DIV/0!
A28: ='坏账准备计提会计政策检查D2-8'!K28 -> 0 | C28: =C27+B28 -> 0 | D28: =D27-B27 -> 0 | E28: =$G$24 -> 0 | G28: =E28/D28 -> #DIV/0!
A29: ='坏账准备计提会计政策检查D2-8'!K29 -> 0 | C29: =C28+B29 -> 0 | D29: =D28-B28 -> 0 | E29: =$G$24 -> 0 | G29: =E29/D29 -> #DIV/0!
A30: ='坏账准备计提会计政策检查D2-8'!K30 -> 0 | C30: =C29+B30 -> 0 | D30: =D29-B29 -> 0 | E30: =$G$24 -> 0 | G30: =E30/D30 -> #DIV/0!
A31: ='坏账准备计提会计政策检查D2-8'!K31 -> 0 | C31: =C30+B31 -> 0 | D31: =D30-B30 -> 0 | E31: =$G$24 -> 0 | F31: 实际损失金额 | G31: =E31/D31 -> #DIV/0!
A32: 合计 | B32: =SUM(B26:B31) -> 0 | C32: -- | D32: -- | E32: -- | G32: -- | H32: --
A34: 方法2：基于滚动率（迁徙率）的减值矩阵-本示例仅计算了1年的回收率，实务中可以计算多期后考虑平均。 | H34: 【方法可选】
A35: 账龄 | B35: 20X8年末余额 | C35: 20X9收回金额 | D35: 20X9年末余额 | E35: 校验 | F35: 实际回收率 | G35: 历史损失率 | H35: 上期历史损失率
A36: ='坏账准备计提会计政策检查D2-8'!K26 -> 0 | F36: =C36/B36 -> #DIV/0! | G36: =(1-F36)*G37 -> #DIV/0! | I36: 由于预期信用损失考虑付款的金额和时间分布，因此即使企业预计可以全额收款但收款时间晚于合同规定的到期期限，也会产生信用损失。 自应收票据结转而来的应收账款损失率通常高于原始应收账款的损失率。
A37: ='坏账准备计提会计政策检查D2-8'!K27 -> 0 | E37: =D37=(B36-C36) -> TRUE | F37: =C37/B37 -> #DIV/0! | G37: =(1-F37)*G38 -> #DIV/0!
A38: ='坏账准备计提会计政策检查D2-8'!K28 -> 0 | E38: =D38=(B37-C37) -> TRUE | F38: =C38/B38 -> #DIV/0! | G38: =(1-F38)*G39 -> #DIV/0!
A39: ='坏账准备计提会计政策检查D2-8'!K29 -> 0 | E39: =D39=(B38-C38) -> TRUE | F39: =C39/B39 -> #DIV/0! | G39: =(1-F39)*G40 -> #DIV/0!
A40: ='坏账准备计提会计政策检查D2-8'!K30 -> 0 | E40: =D40=(B39-C39) -> TRUE | F40: =C40/B40 -> #DIV/0! | G40: =(1-F40)*G41 -> #DIV/0!
A41: ='坏账准备计提会计政策检查D2-8'!K31 -> 0 | E41: =D41>=(B40-C40) -> TRUE | F41: =C41/B41 -> #DIV/0! | G41: =1-F41 -> #DIV/0!
A42: 合计 | B42: =SUM(B36:B41) -> 0 | C42: =SUM(C36:C41) -> 0 | D42: =SUM(D36:D41) -> 0 | F42: =C42/B42 -> #DIV/0! | G42: -- | H42: --
A44: 方法3：基于平均迁徙率的减值矩阵 | H44: 【方法可选】 | I44: 迁徙率是指在一个时间段内没有收回而迁徙至下一个时间段的应收账款的比例。
...

Sheet 坏账准备转回（收回）、核销检查表D2-11
A1: 致同会计师事务所
A2: 大额坏账准备转回、核销检查表
A3: =底稿目录!A2 -> 被审计单位名称： | C3: =底稿目录!A4 -> 编制人： | E3: =底稿目录!A5 -> 编制日期： | G3: 索引号： | H3: =底稿目录!F15 -> D2-11
A4: =底稿目录!A3 -> 截止日：202X年12月31日 | C4: =底稿目录!A6 -> 复核人： | E4: =底稿目录!A7 -> 复核日期： | G4: 页次：
A5: 一、审计目标
A6: 应收账款以恰当的金额包括在财务报表中，与之相关的计价或分摊调整已恰当记录，相关披露已得到恰当计量和描述
A7: 二、审计过程
A8: 1.……
A11: （一）本期重要的坏账准备转回或转销检查
A12: 单位名称 | B12: 转回原因 | C12: 收回方式 | D12: 原确定坏账准备的依据 | E12: 收回或转回金额 | F12: 收回或转回前累计已计提坏账准备金额 | G12: 合理性分析 | H12: 索引号
A16: 合计 | E16: =SUM(E13:E15) -> 0 | F16: =SUM(F13:F15) -> 0
A17: （二）本期重要的核销应收账款检查
A18: 单位名称 | B18: 应收账款性质 | C18: 核销金额 | D18: 核销原因 | E18: 履行的核销程序 | F18: 是否由关联交易产生 | G18: 合理性分析 | H18: 索引号
A22: 合计 | C22: =SUM(C19:C21) -> 0
A23: 三、审计说明
A27: 四、审计结论

Sheet 应收账款质押出售情况检查表D2-12
A1: 致同会计师事务所
A2: 应收账款质押、出售情况检查表
A3: =底稿目录!A2 -> 被审计单位名称： | D3: =底稿目录!A4 -> 编制人： | G3: =底稿目录!A5 -> 编制日期： | J3: 索引号： | K3: D2-12
A4: =底稿目录!A3 -> 截止日：202X年12月31日 | D4: =底稿目录!A6 -> 复核人： | G4: =底稿目录!A7 -> 复核日期： | J4: 页次：
A5: 一、审计目标
A6: 记录的应收账款由被审计单位拥有或控制。
A7: 二、审计过程
A8: 1.检查应收账款询证函回函、会议纪要、借款协议和其他文件，确定应收账款是否已被质押或出售。
A9: 2.了解出售、质押应收账款的原因
A10: 3.取得相关合同，检查凭证记录，分析应收账款转让会计处理是否恰当。
A11: 4.关注业务是否有真实交易背景；
A12: 5.检查买方是否将款项直接付至被审计单位在融资银行开设的保理专户或监管账户中；
A13: 6.……
A14: （一）质押的应收账款
A15: 客户名称 | B15: 期末余额 | C15: 质押金额 | D15: 质权人 | E15: 质押原因 | F15: 质押条件 | G15: 质押期限 | H15: 质押协议 | I15: 索引号
A19: 合计 | B19: =SUM(B16:B18) -> 0 | C19: =SUM(C16:C18) -> 0
A20: （二）出售的应收账款
A21: 客户名称 | B21: 出售前应收账款账面余额 | C21: 出售前应收账款坏账准备余额 | D21: 出售时间 | E21: 出售金额 | F21: 受让人 | G21: 出售原因 | H21: 合同主要条款 | I21: 终止确认、转移分析 | J21: 转移方式 | K21: 索引号
A25: 三、审计说明
A26: 1.核对企业出售应收账款会计处理结果如下表：
A27: 项目 | B27: 报表项目 | C27: 未审数 | D27: 审定数 | E27: 差异
A28: 终止确认金额 | E28: =D28-C28 -> 0
A29: 转移金额 | E29: =D29-C29 -> 0
A30: 确认相关的利得或损失 | E30: =D30-C30 -> 0
A31: 继续确认资产 | E31: =D31-C31 -> 0
A32: 继续确认负债 | E32: =D32-C32 -> 0
A36: 四、审计结论
A38: 提示1：根据证监会《2017年上市公司年报会计监管报告》，应收账款保理后能否终止确认，应综合考虑转移的应收账款结构（如单笔转让、批量转让、部分转让或循环额度转让等）、转让形式
A39: （如转让收取合同现金流量的权利或现金流量过手安排）、保理应收账款的基础特征（如信用风险、延迟支付风险及提前偿还风险特征）等因素，以判断应收账款的所有重大风险是否已经转移。
A40: 不能凭与金融机构签订的形式上无追索权的保理协议而终止确认应收账款。
A41: 提示2：保理合同具体分析可参考应收账款保理合同分析示例。
A42: 提示3：根据《中国注册会计师审计准则问题解答第18号——识别和应对第三方配合实施财务舞弊》，关注是否存在第三方配合下，虚构交易实现资产终止确认，避免计提大额资产减值准备段。
A43: 例如，被审计单位在第三方配合下进行虚假货款回笼，或构建虚假且满足出表条件的应收账款保理业务，降低应收账款余额，以减少信用减值损失的计提

Sheet 应收账款业务模式分析D2-13
A1: 致同会计师事务所
A2: 应收账款业务模式分析
A3: =底稿目录!A2 -> 被审计单位名称： | B3: =底稿目录!A4 -> 编制人： | C3: =底稿目录!A5 -> 编制日期： | D3: 索引号： | E3: D2-13
A4: =底稿目录!A3 -> 截止日：202X年12月31日 | B4: =底稿目录!A6 -> 复核人： | C4: =底稿目录!A7 -> 复核日期： | D4: 页次：
A5: 一、审计目标：
A6: 资产负债表中记录的应收账款是存在的，且已经记录在恰当的账户中
A7: 二、审计过程：
A8: 1.……
A11: （一）应收账款业务模式及依据
A12: 组合名称 | B12: 被审计单位管理应收票据业务模式 | C12: 具体依据 | D12: 索引号 | E12: 备注
A13: XX组合（信用等级高） | B13: 以收取合同现金流量和出售金融资产为目标 | C13: 频繁出售
A14: XX组合（信用等级中） | B14: 以收取合同现金流量为目标
A15: XX组合（信用等级低） | B15: 以收取合同现金流量为目标
A16: （二）应收账款分类判断
A17: 了解并观察被审计单位保理或证券化的实际情况及未来预期 | B17: XX组合（信用等级高） | C17: XX组合（信用等级中） | D17: XX组合（信用等级低） | E17: 备注
A18: 1.被审计单位是否涉及大额且频繁的应收账款保理或证券化且终止确认？ | B18: 是 | C18: 是 | D18: 是
A19: 2.被审计单位持有应收账款的目的是交易性的或基于应收账款的公允价值作出决策并对其进行管理？ | B19: 否 | C19: 是 | D19: 是
A20: 3.未来是否预期会进行大额且频繁的应收账款保理或证券化且可终止确认？ | B20: 否 | C20: 否 | D20: 否
A21: 4.未来是否预期持有应收账款的目的是交易性的或基于应收账款的公允价值作出决策并对其进行管理？ | B21: 否 | C21: 否 | D21: 否
A22: 确定业务模式 | B22: =IF(AND(B18="是",B19="否"),"属于以收取合同现金流量和出售金融资产为目标的业务模式",IF(AND(B18="是",B19="是"),"属于其他业务模式",IF(AND(B20="是",B21<>"是"),"属于以收取合同现金流量和出售金融资产为目标的业务模式",IF(B21="是","属于其他业务模式","属于以收取合同现金流量为目标的业务模式")))) -> 属于以收取合同现金流量和出售金融资产为目标的业务模式 | C22: =IF(AND(C18="是",C19="否"),"属于以收取合同现金流量和出售金融资产为目标的业务模式",IF(AND(C18="是",C19="是"),"属于其他业务模式",IF(AND(C20="是",C21<>"是"),"属于以收取合同现金流量和出售金融资产为目标的业务模式",IF(C21="是","属于其他业务模式","属于以收取合同现金流量为目标的业务模式")))) -> 属于其他业务模式 | D22: =IF(AND(D18="是",D19="否"),"属于以收取合同现金流量和出售金融资产为目标的业务模式",IF(AND(D18="是",D19="是"),"属于其他业务模式",IF(AND(D20="是",D21<>"是"),"属于以收取合同现金流量和出售金融资产为目标的业务模式",IF(D21="是","属于其他业务模式","属于以收取合同现金流量为目标的业务模式")))) -> 属于其他业务模式
A23: 确定报表项目 | B23: =IF(B22="属于以收取合同现金流量和出售金融资产为目标的业务模式","应列报为应收款项融资","") -> 应列报为应收款项融资 | C23: =IF(C22="属于以收取合同现金流量和出售金融资产为目标的业务模式","应列报为应收款项融资","") | D23: =IF(D22="属于以收取合同现金流量和出售金融资产为目标的业务模式","应列报为应收款项融资","")
A24: 三、审计说明：
A28: 四、审计结论：
A30: 提示：《关于修订印发2019年度一般企业财务报表格式的通知》（财会〔2019〕6号）：“应收款项融资”项目，反映资产负债表日以公允价值计量且其变动计入其他综合收益的应收票据和应收账款等。

Sheet GT_Custom
A1: C1 | B1: Custom 1
A2: C2 | B2: Custom 2
A3: C3 | B3: Custom 3
A4: C4 | B4: Custom 4
A5: C5 | B5: Custom 5
A6: C6 | B6: Custom 6
A7: C7 | B7: Custom 7
A8: C8 | B8: Custom 8
