Workbook

Sheet 底稿目录
A1: 底稿开列时，可先在以下单元格填写有关内容，以便其他底稿引用有关数据：
A2: 被审计单位名称： | D2: 序号 | E2: 内容 | F2: 索引号
A3: 会计期间：202X年度 | D3: 1 | E3: 营业收入实质性程序表 | F3: D4-22A
A4: 编制人： | D4: 2 | E4: 重要指标分析 | F4: D4-22
A5: 编制日期： | D5: 3 | E5: 收入与开具发票金额比较分析 | F5: D4-23
A6: 复核人： | D6: 4 | E6: 第三方回款检查 | F6: D4-24
A7: 复核日期： | D7: 5 | E7: 经销商检查 | F7: D4-25
D8: 6 | E8: 境外销售收入检查 | F8: D4-26
D9: 7 | E9: 函证结果汇总表 | F9: D0-1
D10: 8 | E10: 核实被函证单位信息 | F10: D0-2
A11: 关于工作底稿与审计程序索引号对应的说明 | D11: 9 | E11: 跟函函证过程控制 | F11: D0-3
A12: 1.编制的审计工作底稿应与审计程序对应。审计项目组应根据被审计单位实际情况和风险评估情况在实质性程序表中裁剪、修改或增加审计程序，根据实际执行的审计程序完成相应审计工作底稿，编制的工作底稿中应按自然顺序依次编制索引号，并通过唯一的索引号将与实质性程序表中的程序对应关联（即将工作底稿的索引号填入实质性程序表中的底稿索引号列）。 | D12: 10 | E12: 函证差异调节表 | F12: D0-4
D13: 11 | E13: 合同负债及销售替代程序检查表 | F13: D0-5
D14: 12 | E14: 应收及销售替代程序检查表 | F14: D0-6
D15: 13 | E15: 邮件传真回函可靠性验证 | F15: D0-7
A16: 2.获取的支持性证据应与审计底稿或程序对应。审计项目组在完成底稿时获取的支持性证据应根据底稿索引号编制下一级按自然顺序排序的索引号（如D1-2-1、D1-2-2、……），并在底稿中说明引用的支持性证据、关联索引号。 | D16: 14 | E16: 函证程序舞弊风险评价表 | F16: D0-8
D17: 15 | E17: 识别未披露关联方 | F17: D4-27
D18: 16 | E18: 客户信息核查清单 | F18: D4-28
A19: 3.工作底稿索引号的编码规则：实质性程序索引号按循环从“D”到“N”,循环内账户以顺序号排列，模板中底稿索引号按账户顺序+自然数顺序（即模板中索引号按二级自然顺序排列，如D1-1、D1-2、D1-3、……D1-N）。 | D19: 17 | E19: 客户信息检查表 | F19: D4-29
D20: 18 | E20: 客户访谈记录汇总表 | F20: D4-30
D21: 19 | E21: 客户访谈记录 | F21: D4-31
D22: 20 | E22: 客户、供应商等资金流水检查 | F22: D4-32

Sheet 程序表D4-22A
A1: 致同会计师事务所
A2: 营业收入实质性程序表
A3: =底稿目录!A2 -> 被审计单位名称： | D3: =底稿目录!A4 -> 编制人： | G3: =底稿目录!A5 -> 编制日期： | I3: 索引号： | J3: =底稿目录!F3 -> D4-22A
A4: =底稿目录!A3 -> 会计期间：202X年度 | D4: =底稿目录!A6 -> 复核人： | G4: =底稿目录!A7 -> 复核日期： | I4: 页次：
A5: 一、本账户涉及的科目
A6: 主营业务收入、其他业务收入
A7: 二、审计目标和财务报表的认定
A8: 审计目标 | H8: 财务报表的认定
A9: A.利润表中记录的营业收入已发生，且与被审计单位有关，已记录于恰当的账户 | H9: 发生
A10: B.所有应当记录的营业收入均已记录，所有应当包括在财务报表中的相关披露均已包括 | H10: 完整性
A11: C.与营业收入有关的金额及其他数据已恰当记录，相关披露已得到恰当计量和描述 | H11: 准确性
A12: D.与营业收入有关的交易和事项已记录于正确的会计期间 | H12: 截止性
A13: E.营业收入已被恰当地汇总或分解且表述清楚，相关披露在按照企业会计准则的编制基础下是相关的、可理解的 | H13: 列报
A14: 三、计划实施的实质性程序
A15: 序号 | B15: 对应Leap程序 | C15: 审计程序 | D15: 程序分类 | E15: 财务报表认定 | J15: 底稿索引号
E16: 发生 | F16: 完整性 | G16: 准确性 | H16: 截止性 | I16: 列报 | K16: 根据被审计单位实际情况和风险评估情况裁剪、修改或增加审计程序
A17: 1 | C17: 对于通过电子方式自动生成、处理、记录的销售交易,必要时，考虑利用信息系统审计专家的工作。 | D17: IPO/上市/新三板/重组/舞弊应对 | E17: √ | F17: √ | G17: √ | H17: √
A18: 2 | B18: 应对措施-实质性分析 | C18: 分析性程序： （1）结合被审计单位业务特点和其主要客户基本经营信息，分析其客户购买力、结构变化和销售波动情况，是否存在客户异常采购的情况；与其客户信息披露核对（如适用）。 （2）结合存货底稿分析销售收入等财务信息与投入产出率、劳动生产率、产能、水电能耗、运输数量等非财务信息之间的关系。 （3）获取年度预算资料，比较收入金额与年度预算是否存在重大差异，如果发现被审计单位的收入增长幅度明显高于管理层的预期，可以询问管理层的适当人员，并考虑管理层的答复是否与其他审计证据一致。例如，如果管理层表示收入增长是由于销售量增加所致，可以调查与市场需求相关的情况。 （4）将销售收入变动幅度与销售商品及提供劳务收到的现金、应收账款/合同资产、存货、税金等项目的变动幅度进行比较，分析具体原因。 （5）将人均创收金额等指标与同行业及行业领军企业比较是否存在异常，如果被审计单位人均创收超过行业领军企业，应保持警觉，考虑获取的审计证据是否能够支持。 （6）了解期末在手订单情况，分析销售与采购是否配比，以及重要客户大量采购的原因、最终销售情况、终端客户同经销商地域的匹配性。 （7）分析销售收入与销售费用之间的关系，包括销售人员的人均业绩指标、销售人员薪酬、广告费、差旅费，以及销售机构的设置、规模、数量、分布等。 （8）根据增值税发票申报表或普通发票，估算全年收入，与实际收入金额比较。 | D18: IPO/上市/新三板/重组/舞弊应对 | E18: √ | F18: √ | G18: √ | J18: F2-63 /D4-22 /D4-23
A19: 3 | B19: 应对措施-检查 | C19: 对重要客户的货款回收进行检查,关注是否存在第三方回款情况,例如通过第三方账户，包括员工账户和其他个人账户回款，通过保理公司回款的情况。如果存在第三方回款，应获取并检查第三方代付协议，分析第三方回款的必要性和合理性。检查第三方与被审计单位及客户之间是否存在关联关系。必要时，向第三方函证。 | D19: IPO/上市/新三板/重组/舞弊应对 | E19: √ | G19: √ | J19: D4-24
A20: 4 | B20: 应对措施-检查 | C20: 如果被审计单位采用经销商的销售模式，需要关注： （1）检查被审计单位与经销商之间的协议或合同以及实际执行情况，确定与经销商是否为委托代理的关系，对经销商销售收入确认时点是否符合企业会计准则的规定； （2）关注主要的经销商与被审计单位之间是否存在关联方关系，检查出库单、货运单、商品验收单等相关支持性凭证，以确定是否满足收入确认的条件； （3）关注经销商布局的合理性、被审计单位频繁发生经销商加入和退出的情况，以及被审计单位对不稳定经销商的收入确认是否适当、退换货损失的处理是否适当、经销商最终销售情况等； （4）对经销商为委托代理销售的模式，检查被审计单位收入确认是否有代理商的销售清单、货物最终销售证明等支持性凭据。 | D20: IPO/上市/新三板/重组/舞弊应对 | E20: √ | F20: √ | G20: √ | H20: √ | J20: D4-14 /D4-25 /D4-
A21: 5 | B21: 应对措施-检查 | C21: 对境外销售收入，检查向主要国家和地区销售的金额、境外收入占比、结算模式等，不同贸易模式下的收入确认是否符合企业会计准则的规定，关注是否存在第三方回款、是否执行了核查、函证、现场走访等程序。 | D21: IPO/上市/新三板/重组/舞弊应对 | E21: √ | G21: √ | H21: √ | J21: D4-26
A22: 6 | B22: 应对措施-检查 | C22: 如果应收账款、合同资产增长比例高于销售收入的增长比例，考虑扩大函证比例、增加截止测试和期后收款测试的比例、使用与前期不同的抽样方法、实地走访客户等。 | D22: IPO/上市/新三板/重组/舞弊应对 | E22: √ | F22: √ | G22: √
A23: 7 | B23: 应对措施-检查 | C23: 对比历年主要客户清单，找出报告期新增的主要客户、原有主要客户交易额大幅减少或合作关系取消的情况，重点关注变化原因。关注会计期末是否存在突击确认销售以及期后是否存在大量销售退回的情况 | D23: IPO/上市/新三板/重组/舞弊应对 | E23: √ | H23: √
A24: 8 | B24: 应对措施-函证 | C24: 结合应收账款审计，选择主要客户、异常客户收入等执行函证程序。 | D24: IPO/上市/新三板/重组/舞弊应对 | E24: √ | F24: √ | G24: √ | H24: √ | J24: D4-0
A25: 9 | B25: 常规程序(选择“存在重大合同”) | C25: 向被审计单位的客户函证相关的特定合同条款以及是否存在背后协议。相关的会计处理是否适当，往往会受到这些合同条款或协议的影响。例如，商品接受标准、交货与付款条件、不承担期后或持续性的卖方义务、退货权、保证转售金额以及撤销或退款等条款在此种情形下通常是相关的。 | D25: IPO/上市/新三板/重组/舞弊应对 | E25: √ | G25: √
A26: 10 | B26: 应对措施-检查 | C26: 如果被审计单位存在特殊交易模式或创新交易模式，分析其对交易经济实质和收入确认的影响。 | D26: IPO/上市/新三板/重组/舞弊应对 | E26: √
A27: 11 | B27: 常规程序（选择“存在超过被审计单位正常经营范围的交易”） | C27: 考虑大额或异常的交易是否表明存在一个先前没有披露的关联方： （1）查询客户工商、银行、税务信息资料，关注其地址、董事/监事/关键管理人员、联系方式等信息，并与其相关发票信息、网站信息进行核对，识别客户是否存在与被审计单位存在疑似关联关系的信息； （2）选取重要客户，获取关联方关系确认函； （3）取得实际控制人、董高监及其密切家庭人员的对外投资清单，与重要客户的股东和关键经办人员进行比对，关注与发行人实际控制人、董事、监事、高级管理人员关系密切的家庭成员与发行人的客户是否存在关联方关系； （4）取得保荐机构及其关联方、PE投资机构及其关联方、PE投资机构的股东或实际控制人控制或投资的其他企业清单，将这些利益相关方清单和重要客户及其法人、股东和关键经办人员名单进行比对，关注其是否与发行人发生大额交易从而导致发行人在报告期内收入、利润出现较大幅度增长； （5）获取发行人主要股东、董事、监事、关键管理人员及上述利益相关方的确认函，确认除其本人在被审计单位领取薪酬或分得股利外，其本人及其关系密切的家庭成员未与被审计单位有任何形式的交易。 | D27: IPO/上市/新三板/重组/舞弊应对 | E27: √ | G27: √ | H27: √ | I27: √ | J27: D4-27 /D4-29 /D4-
A28: 12 | B28: 应对措施-检查 | C28: 如果存在被审计单位关联方注销及非关联化的情况，需要关注被审计单位将原关联方非关联化行为的动机及后续交易的真实性、公允性。 | D28: IPO/上市/新三板/重组/舞弊应对 | E28: √ | G28: √
A29: 13 | B29: 应对措施-检查 | C29: 结合出库单及销售费用中的运输费等明细，检查货物运输单和提单，必要时向运输单位进行函证或走访，关注货物的流动是否真实发生，从而确定交易的真实性。 | D29: IPO/上市/新三板/重组/舞弊应对 | E29: √
A30: 14 | B30: 应对措施-检查 | C30: 期末在被审计单位的一处或多处发货现场实地观察发货情况或准备发出的商品情况（或待处理的退货），并结合所了解的情况实施适当的销售及存货截止测试。 | D30: IPO/上市/新三板/重组/舞弊应对 | E30: √ | H30: √
A31: 15 | B31: 应对措施-检查 | C31: 关注临近期末的大额销售、退货、调整等情况： （1）向被审计单位负责销售和市场开发的人员询问临近期末的销售或发货情况，向被审计单位内部法律顾问询问临近期末签订的销售合同是否存在异常的合同条款或条件； （2）检查临近期末执行的重要销售合同，以发现是否存在异常的定价、结算、发货、退货、换货或验收条款。对期后实施特定的检查，以发现是否存在改变或撤销合同条款的情况，以及是否存在退款的情况； （3）详细复核被审计单位在临近期末以及期后编制的调整分录，调查性质或金额异常的项目。 | D31: IPO/上市/新三板/重组/舞弊应对 | E31: √ | H31: √
A32: 16 | B32: 应对措施-检查 | C32: 结合存货、固定资产、无形资产循环审计，分析客户、供应商名单以及应收、应付等往来明细，检查是否针对同一对方单位或存在关联关系的对方单位同时存在销售、采购的情况，是否有合理的商业理由，关注是否存在第三方配合舞弊的情形。 | D32: IPO/上市/新三板/重组/舞弊应对 | E32: √ | G32: √ | H32: √
A33: 17 | B33: 应对措施-检查（检查程序中选择是否执行延伸检查） | C33: 如果识别出被审计单位收入真实性存在重大异常情况，且通过常规审计程序无法获取充分、适当的审计证据时，考虑实施“延伸检查”程序，可以实施的“延伸检查”程序包括不限于： （1）利用企业信息查询工具查询公司注册资本、地址、成立时间、经营范围、法定代表人、股东、最终控制人等，了解公司经营范围，判断客户所购产品是否具有合理用途、是否存在关联关系、向客户销售金额是否与客户规模匹配等。 （2）现场走访客户的办公场所、经营场所，访谈客户关键经办人员，或电话访谈关键经办人员。核实被访谈对象对象身份的真实性和适当性，根据实际情况设计访谈计划和访谈提纲，观察对方生产经营情况，判断其与被审计单位之间的交易规模是否和其生产经营规模匹配； （3）了解相关客户向被审计单位进行采购的商业理由、采购被审计单位商品的用途和去向、是否存在销售给被审计单位指定单位的情况、客户与被审计单位是否存在除购销交易以外的资金往来、了解客户从被审计单位采购的商品的生产、库存情况等，必要时进行实地察看。 （4）在采用经销模式的情况下，关注经销商库存量是否存在明显不合理，检查经销商进销存记录、经销商的最终销售实现情况。 （5）当注意到可能存在关联方（例如被审计单位控股股东、实际控制人、关键管理人员）或者第三方客户配合被审计单位虚构收入的迹象时，考虑获取并检查相关关联方或者客户的银行账户资金流水，关注是否存在与被审计单位相关供应商、客户或关联方的异常资金往来；考虑获取其下游客户的订单、对其下游客户进行实地走访等。 | D33: IPO/上市/新三板/重组/舞弊应对 | E33: √ | F33: √ | G33: √ | H33: √ | J33: D4-28 /D4-29 /D4-30 /D4-31 /D4-32
A34: 18 | C34: 根据评估的舞弊风险等因素增加的审计程序。 | D34: IPO/上市/新三板/重组/舞弊应对
A35: 提示：注册会计师在判断是否需要实施“延伸检查”程序及如何实施时，应当根据审计准则的规定，并考虑有经验的专业人士在该场景下通常会作出的合理职业判断。《中国注册会计师审计准则第 1131 号——审计工作底稿》对“有经验的专业人士”进行了定义。此外，实施“延伸检查”程序的可行性和效果受诸多因素影响，注册会计师设计的具体“延伸检查”程序的性质、时间安排和范围，应当针对被审计单位的具体况，与评估的舞弊风险相称，并体现重要性原则。例如，被审计单位所处行业的下游产业链较长，如果对下游产业链的某个或某几个环节实施“延伸检查”程序获取的审计证据，可以应对与收入确认相关的舞弊风险，则“延伸检查”程序无需覆盖所有环节。再者，相对于常规年度财务报表审计而言，在首次公开发行股票并上市审计（IPO 审计）中，由于存在监管要求和相关方的配合，注册会计师实施“延伸检查”程序通常相对可行。

Sheet 重要指标分析表D4-22
A1: 致同会计师事务所
A2: 主营业务收入重要指标分析表
A3: =底稿目录!A2 -> 被审计单位名称： | C3: =底稿目录!$A$4 -> 编制人： | E3: =底稿目录!$A$5 -> 编制日期： | G3: 索引号： | H3: =底稿目录!F4 -> D4-22
A4: =底稿目录!A3 -> 会计期间：202X年度 | C4: =底稿目录!$A$6 -> 复核人： | E4: =底稿目录!$A$7 -> 复核日期： | G4: 页 次：
A5: 一、审计目标
A6: 1.利润表中记录的主营业务收入已发生，且与被审计单位有关；2.所有应当记录的营业收入均已记录；
A7: 3.与主营业务收入有关的金额及其他数据已恰当记录，相关披露已得到恰当计量和描述。
A8: 二、审计过程
A9: 1.向被审计单位询问，并获取年度预算、业绩考核指标等资料。
A11: 指标名称 | B11: 本期 | C11: 上期 | D11: 同行业公司1 | E11: 同行业公司2 | F11: 同行业公司3 | G11: …… | H11: 合理性分析
A12: 年度预算
A13: 主营业务收入
A14: 销售人员数量
A15: 销售人员人均创收
A16: 销售区域分布是否变化（占比和区域数量等）
A17: 销售人员业绩指标
A18: 销售人员薪酬
A19: 期末在手订单
A20: 息税前利润（利润总额＋财务费用）
A21: 薪酬总额（支付给职工以及为职工支付的现金+期末应付职工薪酬-期初应付职工薪酬）
A22: 人力投入回报率(ROP)
A23: 运输费用/营业收入
... A28: 四、审计结论

Sheet 收入与开具发票金额比较分析D4-23
A1: 致同会计师事务所
A2: 收入与开具发票金额比较分析
A3: =底稿目录!A2 -> 被审计单位名称： | D3: =底稿目录!$A$4 -> 编制人： | G3: =底稿目录!$A$5 -> 编制日期： | J3: 索引号： | K3: =底稿目录!F5 -> D4-23
A4: =底稿目录!A3 -> 会计期间：202X年度 | D4: =底稿目录!$A$6 -> 复核人： | G4: =底稿目录!$A$7 -> 复核日期： | J4: 页次：
A5: 一、审计目标：
A7: 二、审计过程：
A8: 1.……
A10: 月份 | B10: 本期账面确认收入 | E10: 本期开具发票的金额
B11: 主营业务收入 | C11: 其他业务收入 | D11: 营业收入合计 | E11: 增值税发票金额 | F11: 防伪税控开具的增值税发票份数 | G11: 普通发票金额 | H11: 开具的普通发票份数 | I11: 申报的开票金额合计 | J11: 差异 | K11: 索引号
A12: 1月 | D12: =B12+C12 -> 0 | I12: =E12+G12 -> 0 | J12: =D12-I12 -> 0
A13: 2月 | D13: =B13+C13 -> 0 | I13: =E13+G13 -> 0 | J13: =D13-I13 -> 0
A14: 3月 | D14: =B14+C14 -> 0 | I14: =E14+G14 -> 0 | J14: =D14-I14 -> 0
A15: 4月 | D15: =B15+C15 -> 0 | I15: =E15+G15 -> 0 | J15: =D15-I15 -> 0
A16: 5月 | D16: =B16+C16 -> 0 | I16: =E16+G16 -> 0 | J16: =D16-I16 -> 0
A17: 6月 | D17: =B17+C17 -> 0 | I17: =E17+G17 -> 0 | J17: =D17-I17 -> 0
A18: 7月 | D18: =B18+C18 -> 0 | I18: =E18+G18 -> 0 | J18: =D18-I18 -> 0
A19: 8月 | D19: =B19+C19 -> 0 | I19: =E19+G19 -> 0 | J19: =D19-I19 -> 0
A20: 9月 | D20: =B20+C20 -> 0 | I20: =E20+G20 -> 0 | J20: =D20-I20 -> 0
A21: 10月 | D21: =B21+C21 -> 0 | I21: =E21+G21 -> 0 | J21: =D21-I21 -> 0
A22: 11月 | D22: =B22+C22 -> 0 | I22: =E22+G22 -> 0 | J22: =D22-I22 -> 0
A23: 12月 | D23: =B23+C23 -> 0 | I23: =E23+G23 -> 0 | J23: =D23-I23 -> 0
A24: 合计 | B24: =SUM(B12:B23) -> 0 | C24: =SUM(C12:C23) -> 0 | D24: =SUM(D12:D23) -> 0 | E24: =SUM(E12:E23) -> 0 | F24: =SUM(F12:F23) -> 0 | G24: =SUM(G12:G23) -> 0 | H24: =SUM(H12:H23) -> 0 | I24: =SUM(I12:I23) -> 0 | J24: =SUM(J12:J23) -> 0
A25: 三、审计说明：
A29: 四、审计结论：

Sheet 第三方回款检查D4-24
A1: 致同会计师事务所
A2: 第三方回款检查
A3: =底稿目录!A2 -> 被审计单位名称： | D3: =底稿目录!$A$4 -> 编制人： | G3: =底稿目录!A5 -> 编制日期： | L3: 索引号： | M3: =底稿目录!F6 -> D4-24
A4: =底稿目录!A3 -> 会计期间：202X年度 | D4: =底稿目录!$A$6 -> 复核人： | G4: =底稿目录!A7 -> 复核日期： | L4: 页次：
A5: 一、审计目标：
A6: 1.利润表中记录的营业收入已发生，且与被审计单位有关，已记录于恰当的账户。2.与营业收入有关的金额及其他数据已恰当记录，相关披露已得到恰当计量和描述。
A7: 二、审计过程：
A8: 1.向被审计单位管理层了解第三方回款原因，获取代付协议，检查第三方回款合理性；
A9: 2.向第三方回款单位函证；
A10: 3.关注被审计单位涉及第三方回款的销售的资金流、实物流与合同约定及商业实质是否一致
A11: 4.核查被审计单位及其实际控制人、董监高或其他关联方与第三方回款的支付方是否存在关联关系或其他利益安排
A12: 5.对于异常的第三方回款，追查期后资金流向；
A13: 6.……
A14: 序号 | B14: 客户名称 | C14: 本年度销售金额 | D14: 期末应收账款余额 | E14: 本年度第三方回款金额 | F14: 第三方回款方名称 | G14: 第三方回款原因 | H14: 第三方回款方与客户关系 | I14: 第三方回款方与被审计单位关系 | J14: 是否有代付协议 | K14: 是否函证 | L14: 合理性分析 | M14: 索引
A23: 三、审计说明：
A24: 1.第三方回函检查明细详见银行流水双向核对表<E1-31>、应收账款检查表<D2-7>
A27: 四、审计结论：

Sheet 经销商检查D4-25
A1: 致同会计师事务所
A2: 经销商检查
A3: =底稿目录!A2 -> 被审计单位名称： | E3: =底稿目录!A4 -> 编制人： | I3: =底稿目录!A5 -> 编制日期： | L3: 索引号： | M3: =底稿目录!F7 -> D4-25
A4: =底稿目录!A3 -> 会计期间：202X年度 | E4: =底稿目录!A6 -> 复核人： | I4: =底稿目录!A7 -> 复核日期： | L4: 页 次：
A5: 一、审计目标：
A6: 利润表中记录的营业收入已发生，且与被审计单位有关，已记录于恰当的账户。
A7: 二、审计过程：
A8: 1.关注客户基本情况是否同销售规模相匹配；
A9: 2.记录经销商情况（是否关联方、是否非法人、销售费用承担方式、补贴或返利情况）；
A10: 3.……
A11: 序号 | B11: 客户名称 | C11: 经销商 | D11: 本期销售数量 | E11: 本期销售金额 | F11: 占同类交易比例 | G11: 期末应收账款余额 | H11: 是否关联方 | I11: 个人/企业 | J11: 销售费用承担方式 | K11: 补贴或返利 | L11: 终端销售金额 | M11: 备注
A12: 1
A13: 2
A14: 3
A15: 4
A16: 5
A17: 6
A18: 7
A19: 8
A20: 9
A21: 10
A23: 三、审计说明：
A27: 四、审计结论：

Sheet 境外销售收入检查D4-26
A1: 致同会计师事务所
A2: 境外销售收入检查
A3: =底稿目录!A2 -> 被审计单位名称： | G3: =底稿目录!A4 -> 编制人： | L3: =底稿目录!A5 -> 编制日期： | R3: 索引号： | S3: =底稿目录!F8 -> D4-26
A4: =底稿目录!A3 -> 会计期间：202X年度 | G4: =底稿目录!A6 -> 复核人： | L4: =底稿目录!A7 -> 复核日期： | R4: 页次：
A5: 一、审计目标：
A6: 确定对境外销售业务的真实性和交易实质
A7: 二、审计过程：
A8: 1.对主要目的国、主要海外客户以及对应的主要贸易条款、付款方式等进行分析和记录；
A9: 2.记录已执行的海关查询、函证等程序。
A11: 客户名称 | B11: 所在国家/地区 | C11: 产品种类 | D11: 业务模式 （直销客户/经销商） | E11: 本期销售金额 | F11: 占同类交易比例 | G11: 贸易模式 （填EXW/FOB/CIF等） | H11: 主要贸易条款 （与商品控制权转移时点相关的约定） | I11: 出口结算模式 （填汇款/托收/信用证/银行保函等） | J11: 是否存在第三方回款 | K11: 第三方回款原因 | L11: 核查程序确认的销售金额 | M11: 差异 | N11: 差异原因分析 | O11: 相关程序索引 （对已执行的程序表中索引号）
O12: 实地走访 | P12: 交易函证 | Q12: 海关函证 | R12: 核对报关单 | S12: 电子口岸数据查询
A30: 三、审计说明：
A31: 【记录发现的差异或者其他异常交易安排的迹象，以及所执行的应对措施。】
A32: 四、审计结论：

Sheet 识别未披露的关联方D4-27
A1: 致同会计师事务所
A2: 识别未披露的关联方
A3: =底稿目录!A2 -> 被审计单位名称： | H3: =底稿目录!A4 -> 编制人： | O3: =底稿目录!A5 -> 编制日期： | Q3: 索引号： | R3: =底稿目录!F17 -> D4-27
A4: =底稿目录!A3 -> 会计期间：202X年度 | H4: =底稿目录!A6 -> 复核人： | O4: =底稿目录!A7 -> 复核日期： | Q4: 页次：
A5: 一、审计目标：
A6: 主要或异常客户是否与被审计单位存在关联方关系。
A7: 二、审计过程：
A8: 1.选择大额、异常的客户或交易。
A9: 2.查询客户工商、银行、税务信息资料，关注其地址、董事/监事/关键管理人员、联系方式等信息，并与其相关发票信息、网站信息进行核对，识别客户是否存在与被审计单位存在疑似关联关系的信息。
A10: 3.选取重要客户，获取关联方关系确认函。
A11: 4.取得发行人实际控制人、董高监及其密切家庭人员的对外投资清单，与重要客户的股东和关键经办人员进行比对，关注与发行人实际控制人、董事、监事、高级管理人员关系密切的家庭成员与发行人的客户是否存在关联方关系。
A12: 5.取得保荐机构及其关联方、PE投资机构及其关联方、PE投资机构的股东或实际控制人控制或投资的其他企业清单，将这些利益相关方清单和重要客户及其法人、股东和关键经办人员名单进行比对，关注其是否与发行人发生大额交易从而导致发行人在报告期内收入、利润出现较大幅度增长。
A13: 6.获取发行人主要股东、董事、监事、关键管理人员及上述利益相关方的确认函，确认除其本人在被审计单位领取薪酬或分得股利外，其本人及其关系密切的家庭成员未与被审计单位有任何形式的交易。
A14: 序号 | B14: 姓名 | C14: 个人客户 | D14: 客户法人 | E14: 合同签订人 | F14: 高管亲属 | G14: 财务部门 | H14: 管理部门 | I14: 技术部门 | J14: 生产部门 | K14: 营销部门 | L14: … | M14: 总计 | N14: 客户与公司员工或高管或/和亲属重名（Y/N） | O14: 公司股东/高管/亲属/员工 | P14: 20XX年度销售额 | Q14: 说明 | R14: 索引号
A15: 1 | B15: 陈XX | D15: 1 | J15: 1 | M15: =SUM(C15:L15) -> 2 | N15: Y | O15: 公司员工 | P15: 942.91 | Q15: 经销商：AAA公司之法人
A16: 2 | B16: 李YY | C16: 1 | G16: 1 | M16: =SUM(C16:L16) -> 2 | N16: Y | O16: 公司股东 | P16: 557.16
A17: 3 | M17: =SUM(C17:L17)
A18: 4 | M18: =SUM(C18:L18)
A19: 5 | M19: =SUM(C19:L19)
A20: 6
A21: 7
A22: 8
A23: 9
A24: 10
A27: 三、审计说明：
A28: 1.公司的主要股东、高管、股东及高管的家属、公司员工名单见< >，主要概况：
A29: XX公司：高管亲属338；之财务部门65；之管理部门323；之技术部门686；之生产部门1344；之营销部门1165；
A30: 2.客户的法人及关键管理人员概况：
A31: 个人经销商70；副经销商1874；客户法人1697；客户合同签订人39。
A32: 3.对比后，有54个姓名存在重复，涉及127人，其中客户60个；涉及2013年销售额约2.1亿元；
A33: 抽取销售额大于500万的个人客户约11个，涉及27人；涉及2013年销售额约为1.43亿，占2013年总销售额的比例约为67.58%。
A34: 4.获取27人的身份证复印件；对身份证信息的身份证号码、家庭地址，做交叉对比。
A35: 核对未发现身份证号码、登记地址有和公司员工重复的现象。
A36: 四、审计结论：
A37: 未识别出重要客户与公司存在关联方关系。

Sheet 客户信息核查清单D4-28
A1: 致同会计师事务所
A2: 客户信息核查清单
A3: =底稿目录!A2 -> 被审计单位名称： | E3: =底稿目录!A4 -> 编制人： | K3: =底稿目录!A5 -> 编制日期： | N3: 索引号： | O3: =底稿目录!F18 -> D4-28
A4: =底稿目录!A3 -> 会计期间：202X年度 | E4: =底稿目录!A6 -> 复核人： | K4: =底稿目录!A7 -> 复核日期： | N4: 页次：
A5: 一、审计目标：
A6: 润表中记录的营业收入已发生，且与被审计单位有关，已记录于恰当的账户。
A7: 二、审计过程：
A8: 1.核查主要客户及交易真实性，包括调查交易对手背景和商业目的等。
A9: 2.对比历年主要客户清单，找出报告期新增的主要客户、原有主要客户交易额大幅减少或合作关系取消的情况，重点关注变化原因。项目组根据客户集中度和风险情况，抽取报告期各期（___）个客户/项目
A10: 考虑实施包括查询工商资料、互联网查询、电话访谈关键经办人员、实地走访客户等程序，并编制执行结果汇总表。
A12: 序号 | B12: 客户名称 | C12: 选取原因 | D12: 销售金额 | E12: 占总交易 比重 | F12: 应收账款 期末余额 | G12: 占期末余额比重 | H12: 合同负债 期末余额 | I12: 占期末余额比重 | J12: 核查方式（√） | O12: 索引号
J13: 工商资料查询 | K13: 互联网信息查询 | L13: 函证 | M13: 视频、电话访谈 | N13: 实地走访
A14: 1 | B14: 客户1 | C14: 新增主要客户
A15: 2 | B15: 客户2 | C15: 第一大客户
A25: 三、审计说明：
A29: 四、审计结论：

Sheet 客户信息检查表D4-29
A1: 致同会计师事务所
A2: 客户信息检查表
A3: =底稿目录!A2 -> 被审计单位名称： | E3: =底稿目录!A4 -> 编制人： | I3: =底稿目录!A5 -> 编制日期： | L3: 索引号： | M3: =底稿目录!F19 -> D4-29
A4: =底稿目录!A3 -> 会计期间：202X年度 | E4: =底稿目录!A6 -> 复核人： | I4: =底稿目录!A7 -> 复核日期： | L4: 页次：
A5: 一、审计目标：
A6: 润表中记录的营业收入已发生，且与被审计单位有关，已记录于恰当的账户。
A7: 二、审计过程
A8: 1.……
A10: 项目 | C10: 客户1XXX | D10: 客户2XXX | E10: 客户3XXX | F10: 客户4XXX | G10: 客户5XXX | H10: 客户6XXX | I10: 客户7XXX | J10: 客户8XXX | K10: 客户9XXX | L10: 客户10XXX | M10: ……
A11: 统一社会信用代码
A12: 注册地址
A13: 办公地址
A14: 网站地址
A15: 网站IP地址
A16: 企业邮箱
A17: 成立时间
A18: 注册资本/实缴资本
A19: 经营范围
A20: 人员规模/社保缴纳人数
A21: 法定代表人
A22: 股东名称及 持股比例 | B22: 股东1及持股比例
B23: 股东2及持股比例
B24: 股东3及持股比例
B25: 股东4及持股比例
B26: 股东5及持股比例
B27: ……
A28: 关键管理人员 | B28: 董事长
B29: 总经理
B30: ……
A31: 关键经办人员
A34: 实际控制人
A35: 是否为关联方
A36: 是否同时为供应商（含同一实际控制人）
A37: 开始合作时间
A38: 是否长期拖欠款项
A39: 经营状态
A40: 是否列入失信人
A41: 信息来源
A42: 三、审计说明：
A46: 四、审计结论：
...

Sheet 客户访谈记录汇总表D4-30
A1: 致同会计师事务所（特殊普通合伙）
A2: 客户访谈记录汇总表
A3: =底稿目录!A2 -> 被审计单位名称： | C3: =底稿目录!A4 -> 编制人： | E3: =底稿目录!A5 -> 编制日期： | F3: 索引号： | G3: =底稿目录!F20 -> D4-30
A4: =底稿目录!A3 -> 会计期间：202X年度 | C4: =底稿目录!A6 -> 复核人： | E4: =底稿目录!A7 -> 复核日期： | F4: 页次：
A5: 项目 | B5: 客户1 | C5: 客户2 | D5: 客户3 | E5: 客户4 | F5: 客户5 | G5: 客户6
A6: 访谈时间
A7: 访谈原因 | B7: 发行人第X大客户/本期新增客户/采购价格异常客户/……
A8: 访谈方式 | B8: 实地走访/视频访谈/电话访谈/……
A9: 被访谈公司注册地址
A10: 实地走访公司地址
A11: 接受访谈人员及身份 | B11: 身份信息、职务信息、具体负责的工作等
A12: 参与访谈的审计人员
A13: 参与访谈的其他人员
A14: 访谈人员行程信息 | B14: 车票、机票、住宿发票复印件或照片，住宿酒店照片
A15: 是否现场函证
A16: 访谈关注要点
A17: 合同执行核对情况
A18: 交易金额核对是否一致
A19: 往来余额核对是否一致
A20: ……
A21: 访谈结论
A22: 访谈表索引
A23: 提示1：走访的范围：主要客户（如前十名客户）；新增的主要客户；存在疑虑的重要客户
A24: 提示2：访谈需核对和注意事项
A25: 1.走访地址与注册地址是否一致？不一致的原因是否合理？公司基本情况是否与工商信息查询信息一致？走访的公司地址是否与百度地图等查询走访地址一致？
A26: 2.交易内容是否与走访公司实际业务范围一致？
... A34: 10.保留访谈对象身份证复印件、名片/工牌复印件、与访谈对象合影（厂区门口、仓库、车间等地）、走访公司工作现场照片

Sheet 客户访谈记录 D4-31
A1: 致同会计师事务所
A2: 客户访谈记录
A3: =底稿目录!A2 -> 被审计单位名称： | B3: =底稿目录!A4 -> 编制人： | D3: =底稿目录!A5 -> 编制日期： | F3: 索引号： | G3: =底稿目录!F21 -> D4-31
A4: =底稿目录!A3 -> 会计期间：202X年度 | B4: =底稿目录!A6 -> 复核人： | D4: =底稿目录!A7 -> 复核日期： | F4: 页次：
A5: 访谈对象：
A6: 访谈时间及地点：
A7: 接受访谈人员及职务：
A8: 访谈人：
A9: 访谈内容：【根据被审计单位实际情况、关注的客户主要风险情况修改访谈内容】
A10: 一、接受访谈人介绍，包括姓名、任职的公司、职务、具体负责的工作等
A12: 二、客户的基本情况（附有关部门盖章确认的工商登记证明文件、主体纳税证明等）
A13: 公司名称： | D13: 注册资本：
A14: 成立日期： | D14: 经济性质：
A15: 法定代表人： | D15: 股权结构：
A16: 三、与客户业务情况
A17: 1.客户与发行人的业务关系为 | D17: [ ]客户是终端客户 [ ]客户是经销商(客户) [ ]客户是供应商 [ ]客户既是客户又是供应商 [ ]客户是ABC的关联方
A18: 2.客户与发行人的结算方式
A19: （1）客户向发行人的采购 | D19: [ ] 预付款方式 [ ] 货到付款方式 [ ] 赊销方式 [ ] 预付款方式和赊销方式兼有
A20: （2）客户向发行人的销售 | D20: [ ] 预收款方式 [ ] 货到收款方式 [ ] 赊销方式 [ ] 预收款方式和赊销方式兼有
A21: 3.20XX年度至今客户与发行人交易情况
A22: （1）所有的交易行为是否签订合同 | D22: [ ] 是 [ ] 否
A23: （2）客户向发行人采购产品质量情况（适用客户） | D23: [ ] 良好 [ ]一般 [ ] 产品质量不稳定 [ ] 产品质量差
A24: （3）客户与发行人是否定了约定除质量问题以外的退、换货条款 | D24: [ ]是 [ ]否
A25: （4）20XX年度至今客户与发行人约定了除质量问题以外的退、换货条款，而发生的退换货金额 | D25: [ ] 无 [ ]20万元以下 [ ]20-50万元 [ ]50-100万元 [ ] 100万元以上
A26: （5）客户向发行人采购的产品验收入库情况 | D26: [ ]检验合格后计量入库签收确认收到货物 [ ]直接计量入库签收确认收到货物 [ ]其他方式请描述
A27: （6）客户与发行人的交易是否存在返利的约定 | D27: [ ]是 [ ]否
A28: 如存在返利请说明以下情况：
A29: A.通过何种方式支付返利 | D29: [ ]现金 [ ]其他方式
A30: B.20XX年度至今返利金额 | D30: [ ]10万元以下 [ ]10-50万元 [ ]50-100万元 [ ]100万元以上
A31: （7）客户作为发行人的经销商购买的货物是否已经最终销售(适用经销商) | D31: [ ]是 [ ]否
A32: 4.客户除了上述与被审计单位采购以外，是否还存在其他的资金往来？ | D32: [ ]是 [ ]否
A33: 5.其他重要事项
A34: 四、关联关系情况
A35: 发行人的实际控制人、自然人股东、董事、监事或高管人员及主要关联方是否在客户持有股份（关联方情况详见附表) | D35: [ ]是 [ ]否
A36: 是否担任职务 | D36: [ ]是 [ ]否
A37: 是否和客户有交易 | D37: [ ]是 [ ]否
A39: 附：1.供应商盖章确认的工商登记证明文件、……
A40: 2.跟函回函
A41: 3.XX产品销售明细账、XX产品库存商品明细账
A42: 4.XXX账户资金流水
...

Sheet 访谈记录与核对示例
A1: 致同会计师事务所（特殊普通合伙）
A2: 访谈记录与核对
A3: =底稿目录!A2 -> 被审计单位名称： | E3: =底稿目录!A4 -> 编制人： | G3: =底稿目录!A5 -> 编制日期： | I3: 索引：
A4: =底稿目录!A3 -> 会计期间：202X年度 | E4: =底稿目录!A6 -> 复核人： | G4: =底稿目录!A7 -> 复核日期： | I4: 页次：
A5: 走访公司名称：
A6: 一、走访的公司基本信息 | H6: 〔随需填写〕
A7: 【XYZ公司的基本情况，包括：XYZ公司法定代表人、注册地、注册资本、成立时间，股权关系等；公司营业执照复印件或照片、公司章程等】
A8: 工商信息查询结果、天眼查等查询结果：
A10: 百度地图等查询走访地址的结果：
A12: 二、交易基本信息 | H12: 〔随需填写〕
A13: 【XYZ公司与发行人的业务关系，发生业务的起始时间、交易金额、交易量、交易量是否异常，若异常应在访谈结论中明确交易量异常变动的原因，XYZ公司原行业状况、与发行人的交易占XYZ公司的总交易比重（公司基本情况需通过获取XYZ公司工商资料，并与发行人记录情况、增值税发票、XYZ公司网站信息等核对】
A14: 如： | B14: 与发行人合作从2006年至今已超过了5年，XYZ公司主要从发行人采购AAA材料，最近三年一期（2010年、2011年、2012年）的交易量和交易金额，占总交易额比重分别为 ；三年的交易量、交易金额稳步上升，交易比重保持平稳，未见异常变动。发行人的销售员经常到访XYZ公司维护客户关系，两家公司的合作关系良好，均有继续合作发展的意愿。
B15: 检查了XYZ公司的营业执照、组织机构代码证、税务登记证、章程等工商资料（若为特许经营行业，应检查相应证照）并取得复印件，与发行人记录情况、增值税发票、XYZ公司网站的相关信息等核对一致。【若为新增、异常客户/供应商或关联方客户/供应商，考虑获取XYZ公司的工商登记资料、纳税资料、银行账户流水等资料，并了解公司的实际控制人、关键经办人员等相关情况进行核对分析，包括核对XYZ公司的经营业绩、银行账户往来是否与其声称的经营状况和营运能力、现金流量相关等】
B16: XYZ公司不是ABC的关联方
B17: XYZ公司今年对AAA材料的采购目标为3亿（含税），其中约有20%采购自发行人
B18: XYZ公司的业务区域主要集中在山西陕西地区
B19: XYZ公司所在行业具有季节性，春、夏、秋为旺季，冬为淡季；因此原材料采购呈现类似特征。
B20: ……
A21: 三、与发行人的主要合同条款核对 | H21: 〔随需填写〕
A22: 【询问及取得合同样本：核对XYZ公司与发行人的合同条款（交易模式、交易规模、付款方式、付款期限、运输条款、运输保险受益人、销售佣金比例、质保金比例、信用期等）】
A23: 如： | B23: 项目 | C23: 询问所得信息 | G23: 来自发行人合同条款
B24: 交易模式 | C24: 包销 | G24: 与合同条款一致
B25: 交易标的 | C25: AAA材料 | G25: 与合同条款一致
B26: 交易规模 | C26: 500-600吨（含税金额约5000-6000万） | D26: 500-600吨（含税金额约5000-6000万） | G26: 与合同条款一致
B27: 付款方式 | C27: 银行承兑汇票或银行转账 | G27: 与合同条款一致
B28: 预付款项及质保金
B29: 付款期限 | C29: 收货验收后，3个月内（较同行业稍优惠，行业平均约为2.5月，75天） | G29: 与合同条款一致
B30: 订货到发货时间 | C30: 1个月以内，基本在1周之内发货（一般每月发一次订单） | G30: 合同条款为1个月之内
B31: 佣金返利 | C31: 5-6%，每季度按5%结算一次，全年若超过6000万采购量，按全年5.5%结算差额部分，若超过7000万，按全年6%结算差额部分；每年4月份进行全年佣金返利。 | G31: 与合同条款一致
B32: 佣金水平 | C32: 略高于同行业的返利水平，行业平均为4.8-5.5% | G32: 与合同条款一致
B33: 运输方式及费用承担 | C33: 实际承运单位：。物流公司汽运运输，运输时间3-5天，运费由发行人负责；运费中含保险费，保险受益人为发行人 | G33: 与合同条款一致
B34: 交付方式 | C34: XYZ收到材料，验收合格后，在发行人的验收单和物流公司的运单上签字确认后，交付完毕 | G34: 与合同条款一致
B35: 质量保证 | C35: 收货验收后质保1个月 | G35: 与合同条款一致
B36: 验收或检验 | C36: 出具验收报告/验收单 | G36: 与凭证检查情况一致
B37: 退货、换货情况 | C37: 合作5年来，仅在3年前发生过一次质保期内的质量问题，换货解决，价值约为20万 | G37: 与从发行人处获取的信息一致
B38: 是否涉及委托加工
B39: 是否存在实物返利
B40: 现金交易情况
B41: 第三方收款/付款
B42: 代收款、代付款情况
...

Sheet 客户、供应商等资金流水检查D4-32
A1: 致同会计师事务所
A2: 客户、供应商等资金流水检查
A3: =底稿目录!A2 -> 被审计单位名称： | C3: =底稿目录!A4 -> 编制人： | F3: =底稿目录!A5 -> 编制日期： | H3: 索引号： | I3: =底稿目录!F22 -> D4-32
A4: =底稿目录!A3 -> 会计期间：202X年度 | C4: =底稿目录!A6 -> 复核人： | F4: =底稿目录!A7 -> 复核日期： | H4: 页次：
A5: 一、审计目标：
A6: 润表中记录的营业收入已发生，且与被审计单位有关，已记录于恰当的账户。
A7: 二、审计过程：
A8: 1.获取被审计单位主要供应商、客户资金流水，检查是否与被审计单位控股股东、实际控制人以及其他关联方存在大额资金往来，如有，应确定该等资金往来是否与被审计单位收入舞弊有关。
A9: 2.获取被审计单位控股股东、实际控制人、关键管理人员以及其他关联方银行账户资金流水，检查是否存在前述各方提供资金配合被审计单位虚构收入的情况。
A11: 序号 | B11: 单位名称/姓名 | C11: 本期交易金额 | D11: 占同类交易比例 | E11: 开户银行 | F11: 账号 | G11: 资金流水获取途径 | H11: 是否发现异常交易 | I11: 索引号
B12: 主要供应商
A13: 1
A14: 2
A15: 3
A16: 4
A17: 5
A18: ……
B19: 主要客户
A20: 1
A21: 2
A22: 3
A23: 4
A24: 5
A25: ……
B26: 控股股东
A27: 1
A28: 2
A29: ……
B30: 实际控制人
A31: 1
A32: 2
A33: ……
B34: 关键管理人员
A35: 1
A36: 2
A37: 3
A38: 4
A39: 5
A40: ……
B41: 其他关联方
...
