Workbook
Name _13102: #REF!
Name _13302: #REF!
Name _13398: #REF!
Name _18102: #REF!
Name _18198: #REF!
Name _2003附注: [1]附注汇总!$C$5:$AY$646
Name _2其他资产_开办费除外_明细表: #REF!
Name _scn11: #REF!
Name _scn15: #REF!
Name _scn16: #REF!
Name _scn17: #REF!
Name _scn19: #REF!
Name _scn2: #REF!
Name _scn20: #REF!
Name _scn3: #REF!
Name _scn4: #REF!
Name _scn5: #REF!
Name _scn6: #REF!
Name _scn7: #REF!
Name _scn8: #REF!
Name _scn9: #REF!
Name _scq1: #REF!
Name _scq11: #REF!
Name _scq15: #REF!
Name _scq16: #REF!
Name _scq17: #REF!
Name _scq19: #REF!
Name _scq2: #REF!
Name _scq20: #REF!
Name _scq3: #REF!
Name _scq4: #REF!
Name _scq5: #REF!
Name _scq6: #REF!
Name _scq7: #REF!
Name _scq8: #REF!
Name _scq9: #REF!
Name a: #REF!
Name Approach: [2]选择键!$G$2:$G$6
Name as: #REF!
Name AS2WebLink1: #REF!
Name AS2WebLink10: #REF!
Name AS2WebLink11: #REF!
Name AS2WebLink12: #REF!
Name AS2WebLink13: #REF!
Name AS2WebLink14: #REF!
Name AS2WebLink15: #REF!
Name AS2WebLink16: #REF!
Name AS2WebLink17: #REF!
Name AS2WebLink18: #REF!
Name AS2WebLink19: #REF!
Name AS2WebLink2: #REF!
Name AS2WebLink21: #REF!
Name AS2WebLink22: #REF!
Name AS2WebLink23: #REF!
Name AS2WebLink24: #REF!
Name AS2WebLink3: #REF!
Name AS2WebLink4: #REF!
Name AS2WebLink5: #REF!
Name AS2WebLink6: #REF!
Name AS2WebLink7: #REF!

Sheet 合并TB资产负债
A1: 合并资产负债表试算平衡
A2: 客户名称： | D2: 编制： | F2: 复核： | I2: 索引：
A3: 会计时点：2019.12.31 | D3: =CONCATENATE("日期：",TEXT(NOW(),"yyyy.mm.dd")) -> 日期：2026.05.03 | F3: 日期： | I3: 分页：
A4: 项目 | B4: 审定汇总 | C4: 合并权益抵销 | E4: 合并往来交易抵销 | G4: 合并报表调整 | I4: 合并审定数
C5: 借方 | D5: 贷方 | E5: 借方 | F5: 贷方 | G5: 借方 | H5: 贷方
A6: 流动资产：
A7: 货币资金 | B7: 0 | C7: 0 | D7: 0 | E7: 0 | F7: 0 | G7: 0 | H7: 0 | I7: =B7+E7+G7-F7-H7+C7-D7 -> 0
A8: 交易性金融资产 | B8: 0 | C8: 0 | D8: 0 | E8: 0 | F8: 0 | G8: 0 | H8: 0 | I8: =B8+E8+G8-F8-H8+C8-D8 -> 0
A9: 以公允价值计量且其变动计入当期损益的金融资产 | B9: 0 | C9: 0 | D9: 0 | E9: 0 | F9: 0 | G9: 0 | H9: 0 | I9: =B9+E9+G9-F9-H9+C9-D9 -> 0
A10: 衍生金融资产 | B10: 0 | C10: 0 | D10: 0 | E10: 0 | F10: 0 | G10: 0 | H10: 0 | I10: =B10+E10+G10-F10-H10+C10-D10 -> 0
A11: 应收票据 | B11: 0 | C11: 0 | D11: 0 | E11: 0 | F11: 0 | G11: 0 | H11: 0 | I11: =B11+E11+G11-F11-H11+C11-D11 -> 0
A12: 应收账款 | B12: 0 | C12: 0 | D12: 0 | E12: 0 | F12: 0 | G12: 0 | H12: 0 | I12: =B12+E12+G12-F12-H12+C12-D12 -> 0
A13: 应收款项融资 | B13: 0 | C13: 0 | D13: 0 | E13: 0 | F13: 0 | G13: 0 | H13: 0 | I13: =B13+E13+G13-F13-H13+C13-D13 -> 0
A14: 预付款项 | B14: 0 | C14: 0 | D14: 0 | E14: 0 | F14: 0 | G14: 0 | H14: 0 | I14: =B14+E14+G14-F14-H14+C14-D14 -> 0
A15: 其他应收款 | B15: 0 | C15: 0 | D15: 0 | E15: 0 | F15: 0 | G15: 0 | H15: 0 | I15: =B15+E15+G15-F15-H15+C15-D15 -> 0
A16: 其中：应收利息 | B16: 0 | C16: 0 | D16: 0 | E16: 0 | F16: 0 | G16: 0 | H16: 0 | I16: =B16+E16+G16-F16-H16+C16-D16 -> 0
A17: 应收股利 | B17: 0 | C17: 0 | D17: 0 | E17: 0 | F17: 0 | G17: 0 | H17: 0 | I17: =B17+E17+G17-F17-H17+C17-D17 -> 0
A18: 存货 | B18: 0 | C18: 0 | D18: 0 | E18: 0 | F18: 0 | G18: 0 | H18: 0 | I18: =B18+E18+G18-F18-H18+C18-D18 -> 0
... A22: 其他流动资产 | B22: 0 | C22: 0 | D22: 0 | E22: 0 | F22: 0 | G22: 0 | H22: 0 | I22: =B22+E22+G22-F22-H22+C22-D22 -> 0
A23: 0 | B23: 0 | C23: 0 | D23: 0 | E23: 0 | F23: 0 | G23: 0 | H23: 0 | I23: =B23+E23+G23-F23-H23+C23-D23 -> 0
A24: 0 | B24: 0 | C24: 0 | D24: 0 | E24: 0 | F24: 0 | G24: 0 | H24: 0 | I24: =B24+E24+G24-F24-H24+C24-D24 -> 0
A25: 流动资产合计 | B25: =SUM(B7:B24)-B16-B17 -> 0 | C25: =SUM(C7:C24)-C16-C17 -> 0 | D25: =SUM(D7:D24)-D16-D17 -> 0 | E25: =SUM(E7:E24)-E16-E17 -> 0 | F25: =SUM(F7:F24)-F16-F17 -> 0 | G25: =SUM(G7:G24)-G16-G17 -> 0 | H25: =SUM(H7:H24)-H16-H17 -> 0 | I25: =SUM(I7:I24)-I16-I17 -> 0
A26: 非流动资产:
A27: 债权投资 | B27: 0 | C27: 0 | D27: 0 | E27: 0 | F27: 0 | G27: 0 | H27: 0 | I27: =B27+E27+G27-F27-H27+C27-D27 -> 0
A28: 可供出售金融资产 | B28: 0 | C28: 0 | D28: 0 | E28: 0 | F28: 0 | G28: 0 | H28: 0 | I28: =B28+E28+G28-F28-H28+C28-D28 -> 0
A29: 其他债权投资 | B29: 0 | C29: 0 | D29: 0 | E29: 0 | F29: 0 | G29: 0 | H29: 0 | I29: =B29+E29+G29-F29-H29+C29-D29 -> 0
A30: 持有至到期投资 | B30: 0 | C30: 0 | D30: 0 | E30: 0 | F30: 0 | G30: 0 | H30: 0 | I30: =B30+E30+G30-F30-H30+C30-D30 -> 0
A31: 长期应收款 | B31: 0 | C31: 0 | D31: 0 | E31: 0 | F31: 0 | G31: 0 | H31: 0 | I31: =B31+E31+G31-F31-H31+C31-D31 -> 0
A32: 设定受益计划净资产 | B32: 0 | C32: 0 | D32: 0 | E32: 0 | F32: 0 | G32: 0 | H32: 0 | I32: =B32+E32+G32-F32-H32+C32-D32 -> 0
A33: 长期股权投资 | B33: 0 | C33: 0 | D33: 0 | E33: 0 | F33: 0 | G33: 0 | H33: 0 | I33: =B33+E33+G33-F33-H33+C33-D33 -> 0
A34: 其他权益工具投资 | B34: 0 | C34: 0 | D34: 0 | E34: 0 | F34: 0 | G34: 0 | H34: 0 | I34: =B34+E34+G34-F34-H34+C34-D34 -> 0
A35: 其他非流动金融资产 | B35: 0 | C35: 0 | D35: 0 | E35: 0 | F35: 0 | G35: 0 | H35: 0 | I35: =B35+E35+G35-F35-H35+C35-D35 -> 0
A36: 投资性房地产 | B36: 0 | C36: 0 | D36: 0 | E36: 0 | F36: 0 | G36: 0 | H36: 0 | I36: =B36+E36+G36-F36-H36+C36-D36 -> 0
A37: 固定资产 | B37: 0 | C37: 0 | D37: 0 | E37: 0 | F37: 0 | G37: 0 | H37: 0 | I37: =B37+E37+G37-F37-H37+C37-D37 -> 0
A38: 在建工程 | B38: 0 | C38: 0 | D38: 0 | E38: 0 | F38: 0 | G38: 0 | H38: 0 | I38: =B38+E38+G38-F38-H38+C38-D38 -> 0
... A47: 其他非流动资产 | B47: 0 | C47: 0 | D47: 0 | E47: 0 | F47: 0 | G47: 0 | H47: 0 | I47: =B47+E47+G47-F47-H47+C47-D47 -> 0
A48: 0 | B48: 0 | C48: 0 | D48: 0 | E48: 0 | F48: 0 | G48: 0 | H48: 0 | I48: =B48+E48+G48-F48-H48+C48-D48 -> 0
A49: 0 | B49: 0 | C49: 0 | D49: 0 | E49: 0 | F49: 0 | G49: 0 | H49: 0 | I49: =B49+E49+G49-F49-H49+C49-D49 -> 0
A50: 0 | B50: 0 | C50: 0 | D50: 0 | E50: 0 | F50: 0 | G50: 0 | H50: 0 | I50: =B50+E50+G50-F50-H50+C50-D50 -> 0
A51: 非流动资产合计 | B51: =SUM(B27:B50) -> 0 | C51: =SUM(C27:C50) -> 0 | D51: =SUM(D27:D50) -> 0 | E51: =SUM(E27:E50) -> 0 | F51: =SUM(F27:F50) -> 0 | G51: =SUM(G27:G50) -> 0 | H51: =SUM(H27:H50) -> 0 | I51: =SUM(I27:I50) -> 0
...

Sheet 合并TB损益
A1: 合并利润及利润分配表试算平衡
A2: 客户名称： | D2: 编制： | G2: 复核：
A3: 会计期间：2019年度 | D3: =CONCATENATE("日期：",TEXT(NOW(),"yyyy.mm.dd")) -> 日期：2026.05.03 | G3: =合并TB资产负债!F3 -> 日期：
A4: 项目 | B4: 审定汇总 | C4: 合并权益抵销 | E4: 合并往来交易抵销 | G4: 合并报表调整 | I4: 合并审定数
C5: 借方 | D5: 贷方 | E5: 借方 | F5: 贷方 | G5: 借方 | H5: 贷方
A6: 一、营业收入 | B6: 0 | C6: 0 | D6: 0 | E6: 0 | F6: 0 | G6: 0 | H6: 0 | I6: =B6-E6-G6+F6+H6-C6+D6 -> 0
A7: 其中：主营业务收入 | B7: 0 | C7: 0 | D7: 0 | E7: 0 | F7: 0 | G7: 0 | H7: 0 | I7: =B7-E7-G7+F7+H7-C7+D7 -> 0
A8: 其他业务收入 | B8: 0 | C8: 0 | D8: 0 | E8: 0 | F8: 0 | G8: 0 | H8: 0 | I8: =B8-E8-G8+F8+H8-C8+D8 -> 0
A9: 减：营业成本 | B9: 0 | C9: 0 | D9: 0 | E9: 0 | F9: 0 | G9: 0 | H9: 0 | I9: =B9+E9+G9-F9-H9+C9-D9 -> 0
A10: 其中：主营业务成本 | B10: 0 | C10: 0 | D10: 0 | E10: 0 | F10: 0 | G10: 0 | H10: 0 | I10: =B10+E10+G10-F10-H10+C10-D10 -> 0
A11: 其他业务成本 | B11: 0 | C11: 0 | D11: 0 | E11: 0 | F11: 0 | G11: 0 | H11: 0 | I11: =B11+E11+G11-F11-H11+C11-D11 -> 0
A12: 税金及附加 | B12: 0 | C12: 0 | D12: 0 | E12: 0 | F12: 0 | G12: 0 | H12: 0 | I12: =B12+E12+G12-F12-H12+C12-D12 -> 0
A13: 销售费用 | B13: 0 | C13: 0 | D13: 0 | E13: 0 | F13: 0 | G13: 0 | H13: 0 | I13: =B13+E13+G13-F13-H13+C13-D13 -> 0
A14: 管理费用 | B14: 0 | C14: 0 | D14: 0 | E14: 0 | F14: 0 | G14: 0 | H14: 0 | I14: =B14+E14+G14-F14-H14+C14-D14 -> 0
A15: 研发费用 | B15: 0 | C15: 0 | D15: 0 | E15: 0 | F15: 0 | G15: 0 | H15: 0 | I15: =B15+E15+G15-F15-H15+C15-D15 -> 0
A16: 财务费用 | B16: 0 | C16: 0 | D16: 0 | E16: 0 | F16: 0 | G16: 0 | H16: 0 | I16: =B16+E16+G16-F16-H16+C16-D16 -> 0
A17: 其中：利息费用 | B17: 0 | C17: 0 | D17: 0 | E17: 0 | F17: 0 | G17: 0 | H17: 0 | I17: =B17+E17+G17-F17-H17+C17-D17 -> 0
A18: 利息收入 | B18: 0 | C18: 0 | D18: 0 | E18: 0 | F18: 0 | G18: 0 | H18: 0 | I18: =B18+E18+G18-F18-H18+C18-D18 -> 0
A19: 加：其他收益 | B19: 0 | C19: 0 | D19: 0 | E19: 0 | F19: 0 | G19: 0 | H19: 0 | I19: =B19-E19-G19+F19+H19-C19+D19 -> 0
A20: 投资收益（损失以“－”号填列） | B20: 0 | C20: 0 | D20: 0 | E20: 0 | F20: 0 | G20: 0 | H20: 0 | I20: =B20-E20-G20+F20+H20-C20+D20 -> 0
A21: 其中：对联营企业和合营企业的投资收益 | B21: 0 | C21: 0 | D21: 0 | E21: 0 | F21: 0 | G21: 0 | H21: 0 | I21: =B21-E21-G21+F21+H21-C21+D21 -> 0
A22: 以摊余成本计量的金融资产终止确认收益（损失以“-”号填列） | B22: 0 | C22: 0 | D22: 0 | E22: 0 | F22: 0 | G22: 0 | H22: 0 | I22: =B22-E22-G22+F22+H22-C22+D22 -> 0
A23: 净敞口套期收益（损失以“-”号填列） | B23: 0 | C23: 0 | D23: 0 | E23: 0 | F23: 0 | G23: 0 | H23: 0 | I23: =B23-E23-G23+F23+H23-C23+D23 -> 0
A24: 公允价值变动收益（损失以“－”号填列） | B24: 0 | C24: 0 | D24: 0 | E24: 0 | F24: 0 | G24: 0 | H24: 0 | I24: =B24-E24-G24+F24+H24-C24+D24 -> 0
A25: 信用减值损失(损失以“-”号填列） | B25: 0 | C25: 0 | D25: 0 | E25: 0 | F25: 0 | G25: 0 | H25: 0 | I25: =B25-E25-G25+F25+H25-C25+D25 -> 0
A26: 资产减值损失(损失以“-”号填列） | B26: 0 | C26: 0 | D26: 0 | E26: 0 | F26: 0 | G26: 0 | H26: 0 | I26: =B26-E26-G26+F26+H26-C26+D26 -> 0
A27: 资产处置收益(损失以“-”号填列） | B27: 0 | C27: 0 | D27: 0 | E27: 0 | F27: 0 | G27: 0 | H27: 0 | I27: =B27-E27-G27+F27+H27-C27+D27 -> 0
A28: 二、营业利润（亏损以“－”号填列） | B28: =SUM(B6)-SUM(B9,B12:B16)+SUM(B19:B20)+SUM(B23:B27) -> 0 | C28: =SUM(C6)-SUM(C9,C12:C16)+SUM(C19:C20)+SUM(C23:C27) -> 0 | D28: =SUM(D6)-SUM(D9,D12:D16)+SUM(D19:D20)+SUM(D23:D27) -> 0 | E28: =SUM(E6)-SUM(E9,E12:E16)+SUM(E19:E20)+SUM(E23:E27) -> 0 | F28: =SUM(F6)-SUM(F9,F12:F16)+SUM(F19:F20)+SUM(F23:F27) -> 0 | G28: =SUM(G6)-SUM(G9,G12:G16)+SUM(G19:G20)+SUM(G23:G27) -> 0 | H28: =SUM(H6)-SUM(H9,H12:H16)+SUM(H19:H20)+SUM(H23:H27) -> 0 | I28: =SUM(I6)-SUM(I9,I12:I16)+SUM(I19:I20)+SUM(I23:I27) -> 0
A29: 加：营业外收入 | B29: 0 | C29: 0 | D29: 0 | E29: 0 | F29: 0 | G29: 0 | H29: 0 | I29: =B29-E29-G29+F29+H29-C29+D29 -> 0
A30: 减：营业外支出 | B30: 0 | C30: 0 | D30: 0 | E30: 0 | F30: 0 | G30: 0 | H30: 0 | I30: =B30+E30+G30-F30-H30+C30-D30 -> 0
A31: 三、利润总额（亏损总额以“－”号填列） | B31: =SUM(B28)+SUM(B29)-SUM(B30) -> 0 | C31: =SUM(C28)+SUM(C29)-SUM(C30) -> 0 | D31: =SUM(D28)+SUM(D29)-SUM(D30) -> 0 | E31: =SUM(E28)+SUM(E29)-SUM(E30) -> 0 | F31: =SUM(F28)+SUM(F29)-SUM(F30) -> 0 | G31: =SUM(G28)+SUM(G29)-SUM(G30) -> 0 | H31: =SUM(H28)+SUM(H29)-SUM(H30) -> 0 | I31: =SUM(I28)+SUM(I29)-SUM(I30) -> 0
A32: 减：所得税费用 | B32: 0 | C32: 0 | D32: 0 | E32: 0 | F32: 0 | G32: 0 | H32: 0 | I32: =B32+E32+G32-F32-H32+C32-D32 -> 0
A33: 0 | B33: 0 | C33: 0 | D33: 0 | E33: 0 | F33: 0 | G33: 0 | H33: 0 | I33: =B33+E33+G33-F33-H33+C33-D33 -> 0
A34: 四、净利润（净亏损以“－”号填列） | B34: =B31-B32-B33 -> 0 | C34: =C31-C32-C33 -> 0 | D34: =D31-D32-D33 -> 0 | E34: =E31-E32-E33 -> 0 | F34: =F31-F32-F33 -> 0 | G34: =G31-G32-G33 -> 0 | H34: =H31-H32-H33 -> 0 | I34: =I31-I32-I33 -> 0
A35: （一）按经营持续性分类
A36: 其中：持续经营净利润（净亏损以“-”号填列） | B36: 0 | I36: =B36-E36-G36+F36+H36-C36+D36 -> 0
A37: 终止经营净利润（净亏损以“-”号填列） | B37: 0 | I37: =B37-E37-G37+F37+H37-C37+D37 -> 0
A38: （二）按所有权归属分类
A39: 其中：归属于母公司股东的净利润（净亏损以“-”号填列） | B39: 0 | C39: =C34-C40 -> 0 | D39: =D34-D40 -> 0 | E39: =E34-E40 -> 0 | F39: =F34-F40 -> 0 | G39: =G34-G40 -> 0 | H39: =H34-H40 -> 0 | I39: =I34-I40 -> 0
A40: 少数股东损益（净亏损以“-”号填列） | B40: 0 | C40: 0 | D40: 0 | E40: 0 | F40: 0 | G40: 0 | H40: 0 | I40: =B40+E40+G40-F40-H40+C40-D40 -> 0
...

Sheet TB合并CF
A1: 合并现金流量表试算平衡
A2: 客户名称： | B2: 编制： | D2: 复核： | E2: 索引：
A3: 会计时点：2019.12.31 | B3: =CONCATENATE("日期：",TEXT(NOW(),"yyyy.mm.dd")) -> 日期：2026.05.03 | D3: 日期： | E3: 分页：
A4: 项目 | B4: 审定汇总 | C4: 汇总抵销 | D4: 报表调整 | E4: 合并审定数
A6: 一、经营活动产生的现金流量
A7: 销售商品、提供劳务收到的现金
A8: 收到的税费返还
A9: 收到的其他与经营活动有关的现金
A10: 经营活动现金流入小计
A11: 购买商品、接受劳务支付的现金
A12: 支付给职工以及为职工支付的现金
A13: 支付各项税费
A14: 支付的其他与经营活动有关的现金
A15: 经营活动现金流出小计
A16: 经营活动产生的现金流量净额
A17: 二、投资活动产生的现金流量
... A34: 收到的其他与筹资活动有关的现金
A35: 0
A36: 筹资活动现金流入小计
A37: 偿还债务支付的现金
A38: 分配股利、利润或偿付利息支付的现金
A39: 其中:子公司支付少数股东的现金股利
A40: 支付其他与筹资活动有关的现金
A41: 其中:子公司减资支付给少数股东的现金
A42: 筹资活动现金流出小计
A43: 筹资活动产生的现金流量净额
A45: 四、汇率变动对现金及现金等价物的影响
A46: 五、现金及现金等价物净增加额
A47: 加：期初现金及现金等价物余额
A48: 六、期末现金及现金等价物余额
... A52: 1、将净利润调节为经营活动现金流量：
A53: 净利润 | B53: 0 | E53: =SUM(B53:D53) -> 0
A54: 加：资产减值损失 | B54: 0 | E54: =SUM(B54:D54) -> 0
A55: 信用减值损失 | B55: 0 | E55: =SUM(B55:D55) -> 0
A56: 固定资产折旧、油气资产折耗、生产性生物资产折旧 | B56: 0 | E56: =SUM(B56:D56) -> 0
A57: 无形资产摊销 | B57: 0 | E57: =SUM(B57:D57) -> 0
A58: 长期待摊费用摊销 | B58: 0 | E58: =SUM(B58:D58) -> 0
A59: 处置固定资产、无形资产和其他长期资产的损失（收益以“－”号填列） | B59: 0 | E59: =SUM(B59:D59) -> 0
A60: 固定资产报废损失（收益以“－”号填列） | B60: 0 | E60: =SUM(B60:D60) -> 0
A61: 公允价值变动损失（收益以“－”号填列） | B61: 0 | E61: =SUM(B61:D61) -> 0
...
