Workbook

Sheet 底稿目录
A1: 底稿开列时，可先在以下单元格填写有关内容，以便其他底稿引用有关数据：
A2: 被审计单位：
A3: 截止日：202X年12月31日 | D3: 序号 | E3: 内容 | F3: 索引号
A4: 编制人： | E4: 交易性金融负债实质性程序表 | F4: G10A
A5: 编制日期： | D5: 1 | E5: 审定表 | F5: G10-1
A6: 复核人： | D6: 2 | E6: 附注披露信息（上市公司） | G6: 无需打印
A7: 复核日期： | D7: 3 | E7: 附注披露信息（国企） | G7: 无需打印
D8: 4 | E8: 明细表 | F8: G10-2
A9: 关于工作底稿与审计程序索引号对应的说明 | D9: 5 | E9: 调整分录汇总 | F9: G10-3
A10: 1.编制的审计工作底稿应与审计程序对应。审计项目组应根据被审计单位实际情况和风险评估情况在实质性程序表中裁剪、修改或增加审计程序，根据实际执行的审计程序完成相应审计工作底稿，编制的工作底稿中应按自然顺序依次编制索引号，并通过唯一的索引号将与实质性程序表中的程序对应关联（即将工作底稿的索引号填入实质性程序表中的底稿索引号列）。 | D10: 6 | E10: 分类的适当性检查表 | F10: G10-4
D11: 7 | E11: 公允价值测试表 | F11: G10-5
D12: 8 | E12: 第三层次公允价值计量的调节表 | F12: G10-6
D13: 9 | E13: 函证结果汇总表 | F13: G0-1
A14: 2.获取的支持性证据应与审计底稿或程序对应。审计项目组在完成底稿时获取的支持性证据应根据底稿索引号编制下一级按自然顺序排序的索引号（如D1-2-1、D1-2-2、……），并在底稿中说明引用的支持性证据、关联索引号。 | D14: 10 | E14: 核实被函证单位信息 | F14: G0-2
D15: 11 | E15: 跟函函证过程控制 | F15: G0-3
D16: 12 | E16: 函证差异核对表（证券投资） | F16: G0-4
A17: 3.工作底稿索引号的编码规则：实质性程序索引号按循环从“D”到“N”,循环内账户以顺序号排列，模板中底稿索引号按账户顺序+自然数顺序（即模板中索引号按二级自然顺序排列，如D1-1、D1-2、D1-3、……D1-N）。 | D17: 13 | E17: 函证差异核对表(非证券投资) | F17: G0-5
D18: 14 | E18: 替代程序检查表 | F18: G0-6
D19: 15 | E19: 邮件传真回函可靠性验证 | F19: G0-7
D20: 16 | E20: 函证程序舞弊风险评价表 | F20: G0-8
D21: 17 | E21: 凭证检查表 | F21: G10-7
D22: 18 | E22: 衍生金融工具核查表 | F22: G10-8

Sheet 交易性金融负债实质性程序表G10A
A1: 致同会计师事务所
A2: 交易性金融负债实质性程序表
A3: =底稿目录!A2 -> 被审计单位： | C3: =底稿目录!A4 -> 编制人： | F3: =底稿目录!A5 -> 编制日期： | H3: 索引号： | I3: =底稿目录!F4 -> G10A
A4: =底稿目录!A3 -> 截止日：202X年12月31日 | C4: =底稿目录!A6 -> 复核人： | F4: =底稿目录!A7 -> 复核日期： | H4: 页 次：
A5: 一、本账户涉及的科目
A6: 交易性金融负债
A7: 二、审计目标与认定的对应关系
A8: 审计目标 | G8: 财务报表的认定
A9: A. 资产负债表中记录的交易性金融负债是存在的，且已记录于恰当的账户 | G9: 存在
A10: B. 所有应记录的交易性金融负债均已记录，所有应当包括在财务报表中的相关披露均已包括 | G10: 完整性
A11: C. 记录的交易性金融负债由被审计单位拥有或控制 | G11: 权利和义务
A12: D. 交易性金融负债以恰当的金额包括在财务报表中，与之相关的计价或分摊调整已恰当记录，相关披露已得到恰当计量和描述 | G12: 准确性、计价和分摊
A13: E. 交易性金融负债已被恰当地汇总或分解且表述清楚，相关披露在按照企业会计准则的编制基础下是相关的、可理解的 | G13: 列报
A14: 三、计划实施的实质性程序
A15: 序号 | B15: 审计程序 | C15: 程序分类 | D15: 财务报表的认定 | I15: 底稿索引号
D16: 存在 | E16: 完整性 | F16: 权利和 义务 | G16: 准确性、计价和分摊 | H16: 列报 | J16: 根据被审计单位实际情况和风险评估情况裁剪、修改或增加审计程序
A17: 1 | B17: 获取或编制交易性金融负债的明细表，完成以下工作，并编制审定表 （1）复核加计是否正确，与总账、明细账合计数核对是否相符，将期初余额与上期期末余额核对； （2）追查明细表至调节表/将重大头寸与相应证券记录清单/证券服务机构提供的所有投资账户的电子文件/对账单（在可能的情况下自行进入交易系统获得对账单））核对一致; （3）与上年明细项目进行比较，确定与上年分类相同； （4）与应付利息、投资收益、公允价值变动损益等项目的变动进行核对，复核其勾稽关系； （5）调查重大或者异常的调节项目，并与客户的适当人员讨论差异，考虑回复的可信度并确认相关解释，以及采取适当的措施； （6）检查非记账本位币计量的交易性金融负债的折算汇率及折算是否正确。 | C17: 常规★ | D17: √ | E17: √ | G17: √ | I17: G10-1 /G10-2
A18: 2 | B18: 在使用手工编制、自定义信息报告、系统生成的非固定格式报告等由被审计单位生成的信息时，测试有关信息准确性和完整性，并考虑针对编制和维护由被审计单位生成的信息的相关控制实施控制测试，以评价该信息是否能够为实现审计目的提供基础。 | C18: 常规★ | E18: √ | G18: √ | I18: T1 /G0-2
A19: 3 | B19: 对期初余额的审计，取得交易性金融负债期初余额明细表复核加计是否正确，与总账、明细账合计数是否相符，确定会计政策及程序是否适当，确定计算的准确性；检查期初负债是否在本期支付；将重大负债与其支持性文件核对一致；确定是否需要补充必要的程序，如果是，执行适当的应对程序。（适用于首次承接） | C19: 备选 | D19: √ | E19: √ | F19: √ | G19: √
A20: 4 | B20: 根据实际情况，实施以下分析程序： （1）获取增、减分析表，确定增加内容及减少方式、对损益的影响； （2）复核年度各项金融资产的总体合理性；对变化较大的项目或没有变动的项目进行复核，与被审计单位适当人员讨论原因，判断其存在的合理性，是否存在减值。 | C20: 常规★ | D20: √ | G20: √ | I20: G10-1 /G10-2
A21: 5 | B21: 确认交易性金融负债会计政策、会计处理是否合理并与前期一致，会计估计是否合理，实施以下程序： （1）关注被审计单位管理金融工具的业务模式，并结合合同现金流量特征，分析管理层对投资分类是否合理； （2）与管理层讨论交易性金融负债分类是否符合企业会计准则，是否根据确定的分类选用了正确的核算方法； （3）是否发现管理层在以前年度运用的重大判断和估计存在不合理的情形。如果存在，记录下管理层是否在当年进行了恰当的会计处理和披露，并选用了更为准确的判断和假设。 | C21: 常规★ | D21: √ | E21: √ | G21: √ | I21: G10-1 /G10-2 /G10-4
A22: 6 | B22: 对于本期新增的交易性金融负债，执行以下程序： （1）获取本期增加的金融负债投资的合约、协议、中介机构报告等（若适用），查验金融负债的分类及计价是否正确；追查至相应的原始凭证及支持文件，检查其是否经过授权审批，确认是否符合合同协议条款的规定；必要时进行穿透核查，明确相关金融产品的资金投向，是否存在定向投资要求、投资对象是否与控股股东存在关联关系等； （2）对本期增加中的特定项目（如金额重大或性质特殊的）进行以下测试：检查非货币性资产交换、债务重组、企业合并、投资等发生取得金融负债的会计处理是否正确； | C22: 常规★ | D22: √ | F22: √ | G22: √ | I22: G10-2 /G10-7
A23: 7 | B23: 关注单独的重大交易性金融负债转移或处置，考虑实施以下程序： （1）获取本期减少的金融负债投资的合约、协议、中介机构报告等（若适用），查验金融负债转移的处理及计价是否正确；追查至相应的原始凭证及支持文件，检查其是否经过授权审批，确认是否符合合同协议条款的规定； （2）对本期减少中的特定项目进行以下测试：检查非货币性资产交换、债务重组、企业合并、投资等发生金融负债转移的会计处理是否正确； （3）重新计算相关的利得或损失； （4）关注处置日期是否记录恰当，会计处理是否恰当。 | C23: 常规★ | D23: √ | E23: √ | F23: √ | G23: √ | I23: G10-2 /G10-7
A24: 8 | B24: 资产负债表日至审计工作日间，新增、售出、兑换、处置或偿付的大额出售或购买交易，确认是否被记录在恰当时期内；检查报表日后的证券处置是否出现亏损，如果确认亏损，确定这些亏损是否应该记录在报表期。 | C24: 常规★ | D24: √ | E24: √ | G24: √ | I24: G10-2 /G10-7
A25: 9 | B25: 复核交易性金融负债计价方法，检查其是否按公允价值计量，前后期是否一致；复核公允价值取得依据是否充分；与被审计单位讨论以确定实际利率确定依据是否充分，非本期新增投资，复核实际利率是否与前期一致；复核计算持有期间的利息收入和投资收益；检查会计处理是否正确。若选择利用专家工作的审计程序，参考“S12利用专家的工作”相关程序执行。 | C25: 常规★ | G25: √ | I25: G10-5 /G10-6
A26: 10 | B26: 对于衍生金融工具，执行以下程序： （1）复核衍生金融工具交易对手的信用状况，确定衍生金融资产的交易对手能够履行他们的合同义务； （2）检查贷款或权益、投资协议、销售合同等，了解其中是否包含嵌入衍生金融工具； （3）阅读治理层的会议纪要，以及治理层收到的与衍生活动相关的文件和报告等其他信息； （4）确定金融工具的会计处理是合理的，估值结果是恰当的； （5）确定是否应引入估价专家，以协助评价该企业估值专家对该金融工具的估值工作。若选择利用专家工作的审计程序，参考“S12利用专家的工作”相关程序执行。 | C26: 常规★ | D26: √ | E26: √ | F26: √ | G26: √ | I26: G10-8
A27: 11 | B27: 实施函证程序： （1）以积极方式进行函证，设计询证函、发函前核实被函证单位信息； （2）注册会计师独立收发询证函； （3）编制函证结果汇总表，检查发函、回函物流信息和轨迹、比对回函印章和签字等以核实回函的真实性，检查回函是否相符，对不符事项查明原因确定是否存在错报； （4）如果未收到回函，应当考虑与被询证者联系，要求对方作出回应或再次寄发询证函，无法收到的回函实施替代程序； （5）如果管理层不允许寄发询证函的，询问管理层不允许寄发的原因，并就其原因的正当、合理性收集证据；考虑实施替代审计程序以获取相关、可靠的审计证据； （6）如果管理层不允许寄发询证函的原因不合理、或者认为回函不可靠，评价对评估的重大错报风险以及其他审计程序的性质、时间安排和范围的影响，并确定其对审计工作和审计意见的影响。 | C27: 常规★ | D27: √ | E27: √ | F27: √ | G27: √ | I27: G0
A28: 12 | B28: 检查关联方交易： （1）了解关联交易的商业理由、交易事项的目的、价格和条件，考虑对关联方交易性金融资产的合理性、合法性； （2）检查对关联方交易性金融资产的真实性相关的支持性文件、检查会计处理是否正确； （3）考虑向关联方或其他注册会计师函证重大的关联交易和余额（包括担保和其他重要信息）； （4）必要时，向与交易相关的人员和机构函证或与其讨论有关信息； （5）考虑是否存在未识别的关联方，关联交易和余额披露是否正确。 | C28: 常规★ | D28: √ | E28: √ | F28: √ | G28: √ | H28: √ | I28: G10-6
A29: 13 | B29: 根据评估的舞弊风险等因素增加的审计程序。 | C29: IPO/上市/新三板/重组/舞弊应对
A30: 14 | B30: 检查交易性金融负债是否已按企业会计准则或其他适用的规定在财务报表中做出恰当列报和披露。 | C30: 常规★ | H30: √ | I30: A1-1/A1-15 /A1-16

Sheet 审定表G10-1
A1: 致同会计师事务所
A2: 交易性金融负债审定表
A3: =底稿目录!A2 -> 被审计单位： | D3: =底稿目录!A4 -> 编制人： | G3: =底稿目录!A5 -> 编制日期： | I3: 索引号： | J3: =底稿目录!F5 -> G10-1
A4: =底稿目录!A3 -> 截止日：202X年12月31日 | D4: =底稿目录!A6 -> 复核人： | G4: =底稿目录!A7 -> 复核日期： | I4: 页 次：
A5: 项目 | B5: 期初数 | E5: 期末数 | H5: 本期与上期比较 | J5: 原因分析
B6: 未审数 | C6: 账项调整 | D6: 审定数 | E6: 未审数 | F6: 账项调整 | G6: 审定数 | H6: 变动额 | I6: 变动率
A7: （一）初始金额
A8: 交易性金融负债 | B8: =SUM(B9:B11) -> 0 | C8: =SUM(C9:C11) -> 0 | D8: =SUM(D9:D11) -> 0 | E8: =SUM(E9:E11) -> 0 | F8: =SUM(F9:F11) -> 0 | G8: =SUM(G9:G11) -> 0 | H8: =SUM(H9:H11) -> 0 | I8: =IF(AND(D8=0,G8=0),"",IF(AND(D8=0,G8>0),1,H8/D8))
A9: 其中：发行的交易性债券 | D9: =B9+C9 -> 0 | G9: =E9+F9 -> 0 | H9: =G9-D9 -> 0 | I9: =IF(AND(D9=0,G9=0),"",IF(AND(D9=0,G9>0),1,H9/D9))
A10: 衍生金融负债 | D10: =B10+C10 -> 0 | G10: =E10+F10 -> 0 | H10: =G10-D10 -> 0 | I10: =IF(AND(D10=0,G10=0),"",IF(AND(D10=0,G10>0),1,H10/D10))
A11: 其他 | D11: =B11+C11 -> 0 | G11: =E11+F11 -> 0 | H11: =G11-D11 -> 0 | I11: =IF(AND(D11=0,G11=0),"",IF(AND(D11=0,G11>0),1,H11/D11))
A12: 指定为以公允价值计量且其变动计入当期损益的金融负债 | B12: =SUM(B13:B15) -> 0 | C12: =SUM(C13:C15) -> 0 | D12: =SUM(D13:D15) -> 0 | E12: =SUM(E13:E15) -> 0 | F12: =SUM(F13:F15) -> 0 | G12: =SUM(G13:G15) -> 0 | H12: =SUM(H13:H15) -> 0 | I12: =IF(AND(D12=0,G12=0),"",IF(AND(D12=0,G12>0),1,H12/D12))
A13: 其中：债券 | D13: =B13+C13 -> 0 | G13: =E13+F13 -> 0 | H13: =G13-D13 -> 0 | I13: =IF(AND(D13=0,G13=0),"",IF(AND(D13=0,G13>0),1,H13/D13))
A14: 混合工具 | D14: =B14+C14 -> 0 | G14: =E14+F14 -> 0 | H14: =G14-D14 -> 0 | I14: =IF(AND(D14=0,G14=0),"",IF(AND(D14=0,G14>0),1,H14/D14))
A15: 其他 | D15: =B15+C15 -> 0 | G15: =E15+F15 -> 0 | H15: =G15-D15 -> 0 | I15: =IF(AND(D15=0,G15=0),"",IF(AND(D15=0,G15>0),1,H15/D15))
A16: 初始成本小计 | B16: =SUM(B8,B12) -> 0 | C16: =SUM(C8,C12) -> 0 | D16: =SUM(D8,D12) -> 0 | E16: =SUM(E8,E12) -> 0 | F16: =SUM(F8,F12) -> 0 | G16: =SUM(G8,G12) -> 0 | H16: =SUM(H8,H12) -> 0 | I16: =IF(AND(D16=0,G16=0),"",IF(AND(D16=0,G16>0),1,H16/D16))
A17: （二）累计公允价值变动
A18: 交易性金融负债 | B18: =SUM(B19:B21) -> 0 | C18: =SUM(C19:C21) -> 0 | D18: =SUM(D19:D21) -> 0 | E18: =SUM(E19:E21) -> 0 | F18: =SUM(F19:F21) -> 0 | G18: =SUM(G19:G21) -> 0 | H18: =SUM(H19:H21) -> 0 | I18: =IF(AND(D18=0,G18=0),"",IF(AND(D18=0,G18>0),1,H18/D18))
A19: 其中：发行的交易性债券 | D19: =B19+C19 -> 0 | G19: =E19+F19 -> 0 | H19: =G19-D19 -> 0 | I19: =IF(AND(D19=0,G19=0),"",IF(AND(D19=0,G19>0),1,H19/D19))
A20: 衍生金融负债 | D20: =B20+C20 -> 0 | G20: =E20+F20 -> 0 | H20: =G20-D20 -> 0 | I20: =IF(AND(D20=0,G20=0),"",IF(AND(D20=0,G20>0),1,H20/D20))
A21: 其他 | D21: =B21+C21 -> 0 | G21: =E21+F21 -> 0 | H21: =G21-D21 -> 0 | I21: =IF(AND(D21=0,G21=0),"",IF(AND(D21=0,G21>0),1,H21/D21))
A22: 指定为以公允价值计量且其变动计入当期损益的金融负债 | B22: =SUM(B23:B25) -> 0 | C22: =SUM(C23:C25) -> 0 | D22: =SUM(D23:D25) -> 0 | E22: =SUM(E23:E25) -> 0 | F22: =SUM(F23:F25) -> 0 | G22: =SUM(G23:G25) -> 0 | H22: =SUM(H23:H25) -> 0 | I22: =IF(AND(D22=0,G22=0),"",IF(AND(D22=0,G22>0),1,H22/D22))
A23: 其中：债券 | D23: =B23+C23 -> 0 | G23: =E23+F23 -> 0 | H23: =G23-D23 -> 0 | I23: =IF(AND(D23=0,G23=0),"",IF(AND(D23=0,G23>0),1,H23/D23))
A24: 混合工具 | D24: =B24+C24 -> 0 | G24: =E24+F24 -> 0 | H24: =G24-D24 -> 0 | I24: =IF(AND(D24=0,G24=0),"",IF(AND(D24=0,G24>0),1,H24/D24))
A25: 其他 | D25: =B25+C25 -> 0 | G25: =E25+F25 -> 0 | H25: =G25-D25 -> 0 | I25: =IF(AND(D25=0,G25=0),"",IF(AND(D25=0,G25>0),1,H25/D25))
A26: 公允价值变动小计 | B26: =SUM(B18,B22) -> 0 | C26: =SUM(C18,C22) -> 0 | D26: =SUM(D18,D22) -> 0 | E26: =SUM(E18,E22) -> 0 | F26: =SUM(F18,F22) -> 0 | G26: =SUM(G18,G22) -> 0 | H26: =SUM(H18,H22) -> 0 | I26: =IF(AND(D26=0,G26=0),"",IF(AND(D26=0,G26>0),1,H26/D26))
A27: （三）账面余额（公允价值）
A28: 交易性金融负债 | B28: =B8+B18 -> 0 | C28: =C8+C18 -> 0 | D28: =D8+D18 -> 0 | E28: =E8+E18 -> 0 | F28: =F8+F18 -> 0 | G28: =G8+G18 -> 0 | H28: =H8+H18 -> 0 | I28: =IF(AND(D28=0,G28=0),"",IF(AND(D28=0,G28>0),1,H28/D28))
A29: 其中：发行的交易性债券 | B29: =B9+B19 -> 0 | C29: =C9+C19 -> 0 | D29: =D9+D19 -> 0 | E29: =E9+E19 -> 0 | F29: =F9+F19 -> 0 | G29: =G9+G19 -> 0 | H29: =H9+H19 -> 0 | I29: =IF(AND(D29=0,G29=0),"",IF(AND(D29=0,G29>0),1,H29/D29))
A30: 衍生金融负债 | B30: =B10+B20 -> 0 | C30: =C10+C20 -> 0 | D30: =D10+D20 -> 0 | E30: =E10+E20 -> 0 | F30: =F10+F20 -> 0 | G30: =G10+G20 -> 0 | H30: =H10+H20 -> 0 | I30: =IF(AND(D30=0,G30=0),"",IF(AND(D30=0,G30>0),1,H30/D30))
A31: 其他 | B31: =B11+B21 -> 0 | C31: =C11+C21 -> 0 | D31: =D11+D21 -> 0 | E31: =E11+E21 -> 0 | F31: =F11+F21 -> 0 | G31: =G11+G21 -> 0 | H31: =H11+H21 -> 0 | I31: =IF(AND(D31=0,G31=0),"",IF(AND(D31=0,G31>0),1,H31/D31))
A32: 指定为以公允价值计量且其变动计入当期损益的金融负债 | B32: =B12+B22 -> 0 | C32: =C12+C22 -> 0 | D32: =D12+D22 -> 0 | E32: =E12+E22 -> 0 | F32: =F12+F22 -> 0 | G32: =G12+G22 -> 0 | H32: =H12+H22 -> 0 | I32: =IF(AND(D32=0,G32=0),"",IF(AND(D32=0,G32>0),1,H32/D32))
A33: 其中：债券 | B33: =B13+B23 -> 0 | C33: =C13+C23 -> 0 | D33: =D13+D23 -> 0 | E33: =E13+E23 -> 0 | F33: =F13+F23 -> 0 | G33: =G13+G23 -> 0 | H33: =H13+H23 -> 0 | I33: =IF(AND(D33=0,G33=0),"",IF(AND(D33=0,G33>0),1,H33/D33))
A34: 混合工具 | B34: =B14+B24 -> 0 | C34: =C14+C24 -> 0 | D34: =D14+D24 -> 0 | E34: =E14+E24 -> 0 | F34: =F14+F24 -> 0 | G34: =G14+G24 -> 0 | H34: =H14+H24 -> 0 | I34: =IF(AND(D34=0,G34=0),"",IF(AND(D34=0,G34>0),1,H34/D34))
A35: 其他 | B35: =B15+B25 -> 0 | C35: =C15+C25 -> 0 | D35: =D15+D25 -> 0 | E35: =E15+E25 -> 0 | F35: =F15+F25 -> 0 | G35: =G15+G25 -> 0 | H35: =H15+H25 -> 0 | I35: =IF(AND(D35=0,G35=0),"",IF(AND(D35=0,G35>0),1,H35/D35))
A36: 账面余额（公允价值）合计 | B36: =SUM(B28,B32) -> 0 | C36: =SUM(C28,C32) -> 0 | D36: =SUM(D28,D32) -> 0 | E36: =SUM(E28,E32) -> 0 | F36: =SUM(F28,F32) -> 0 | G36: =SUM(G28,G32) -> 0 | H36: =SUM(H28,H32) -> 0 | I36: =IF(AND(D36=0,G36=0),"",IF(AND(D36=0,G36>0),1,H36/D36))
A37: 试算平衡表数
A38: 差异数 | D38: =D36-D37 -> 0 | G38: =G36-G37 -> 0
A40: 1、审计说明
A41: （1）交易性金融负债本期较上期增加（负数为减少）： | D41: =IF(AND(D36=0,G36=0),0,IF(AND(D36=0,G36>0),1,(G36-D36)/D36)) -> 0
...

Sheet 附注披露信息（上市公司）
A1: 致同会计师事务所
A2: 附注披露信息（上市公司）
A3: =底稿目录!A2 -> 被审计单位： | B3: =底稿目录!A4 -> 编制人： | C3: =底稿目录!A5 -> 编制日期： | D3: 索引号： | E3: =底稿目录!F6 -> 0
A4: =底稿目录!A3 -> 截止日：202X年12月31日 | B4: =底稿目录!A6 -> 复核人： | C4: =底稿目录!A7 -> 复核日期： | D4: 页次：
A5: 附注披露信息
A6: 交易性金融负债
A7: 项 目 | B7: 期初余额 | C7: 本期增加 | D7: 本期减少 | E7: 期末余额
A8: 交易性金融负债 | B8: =B9+B10+B11 -> 0 | E8: =E9+E10+E11 -> 0
A9: 其中：发行的交易性债券 | B9: ='审定表G10-1'!D29 -> 0 | E9: ='审定表G10-1'!G29 -> 0
A10: 衍生金融负债 | B10: ='审定表G10-1'!D30 -> 0 | E10: ='审定表G10-1'!G30 -> 0
A11: 其他 | B11: ='审定表G10-1'!D31 -> 0 | E11: ='审定表G10-1'!G31 -> 0
A12: 指定为以公允价值计量且其变动计入当期损益的金融负债 | B12: =B13+B14 -> 0 | E12: =E13+E14 -> 0
A13: 其中：债券 | B13: ='审定表G10-1'!D33 -> 0 | E13: ='审定表G10-1'!G33 -> 0
A14: 其他 | B14: ='审定表G10-1'!D34+'审定表G10-1'!D35 -> 0 | E14: ='审定表G10-1'!G34+'审定表G10-1'!G35 -> 0
A15: 合 计 | B15: =B8+B12 -> 0 | E15: =E8+E12 -> 0
A16: [对于指定为以公允价值计量且其变动计入当期损益的金融负债，
A17: 1、对于指定为以公允价值计量且其变动计入当期损益的金融负债，应单独列示期初余额、期末余额，并披露指定的理由和依据。
A18: 项 目 | B18: 期初余额 | C18: 期末余额 | D18: 指定的理由和依据
A22: 合 计
A23: 2、需区分企业自身信用风险变动引起的该金融负债公允价值变动金额计入其他综合收益和该金融负债 (包括企业自身信用风险变动的影响) 的全部利得或损失计入当期损益两种情况，按照《企业会计准则第37号——金融工具列报》第41-43条的规定进行披露。]
A24: [例如：
A25: 对于指定为以公允价值计量且其变动计入当期损益的金融负债，2023年公允价值的变动情况如下表所示：
A26: 项 目 | B26: 2023年公允价值变动额 | C26: 因自身信用风险变动引起的公允价值本年变动额 | D26: 因自身信用风险变动引起的公允价值累计变动额
A27: 发行的普通债权
A30: 合 计
A31: 2023年12月31日，指定为以公允价值计量且其变动计入当期损益的金融负债的账面价值与按合同约定到期应支付债权人金额之间的差额为[XX]元。]
A32: X、衍生金融负债
A33: （提示：企业衍生金融工具业务具有重要性的，单独披露衍生金融负债。）
A34: （15号文第二十条（三），分类列示衍生金融负债期初余额、期末余额，披露其形成的原因以及相关会计处理。）
A35: 项 目 | B35: 期末余额 | C35: 上年年末余额
A41: 合 计 | B41: =SUM(B36:B40) -> 0 | C41: =SUM(C36:C40) -> 0
A42: 说明：（衍生金融负债产生的原因以及相关会计处理。）

Sheet 附注披露信息（国企）
A1: 致同会计师事务所
A2: 附注披露信息（国企）
A3: =底稿目录!A2 -> 被审计单位： | B3: =底稿目录!A4 -> 编制人： | C3: =底稿目录!A5 -> 编制日期： | D3: 索引号： | E3: =底稿目录!F7 -> 0
A4: =底稿目录!A3 -> 截止日：202X年12月31日 | B4: =底稿目录!A6 -> 复核人： | C4: =底稿目录!A7 -> 复核日期： | D4: 页次：
A5: 附注披露信息
A6: 交易性金融负债
A7: 项 目 | B7: 期末公允价值 | C7: 期初公允价值
A8: 交易性金融负债 | B8: =B9+B10+B11 -> 0 | C8: =C9+C10+C11 -> 0
A9: 其中：发行的交易性债券 | B9: ='审定表G10-1'!G29 -> 0 | C9: ='审定表G10-1'!D29 -> 0
A10: 衍生金融负债 | B10: ='审定表G10-1'!G30 -> 0 | C10: ='审定表G10-1'!D30 -> 0
A11: 其他 | B11: ='审定表G10-1'!G31 -> 0 | C11: ='审定表G10-1'!D31 -> 0
A12: 指定为以公允价值计量且其变动计入当期损益的金融负债
A13: 其他 | B13: ='审定表G10-1'!G34+'审定表G10-1'!G35 -> 0 | C13: ='审定表G10-1'!D34+'审定表G10-1'!D35 -> 0
A14: 合 计 | B14: =SUM(B8:B13)-B9 -> 0 | C14: =SUM(C8:C13)-C9 -> 0
A15: 注： [对于指定为以公允价值计量且其变动计入当期损益的金融负债，需区分企业自身信用风险变动引起的该金融负债公允价值变动金额计入其他综合收益和该金融负债 (包括企业自身信用风险变动的影响) 的全部利得或损失计入当期损益两种情况，按照《企业会计准则第37号——金融工具列报》第41-43条的规定进行披露。]
A16: [例如：
A17: 对于指定为以公允价值计量且其变动计入当期损益的金融负债，202X年公允价值的变动情况如下表所示：
A18: 项 目 | B18: 202X年公允价值变动额 | C18: 因自身信用风险变动引起的公允价值本年变动额 | D18: 因自身信用风险变动引起的公允价值累计变动额
A19: 发行的普通债权
A22: 合 计 | B22: =SUM(B19:B21) -> 0 | C22: =SUM(C19:C21) -> 0 | D22: =SUM(D19:D21) -> 0
A23: 202X年12月31日，指定为以公允价值计量且其变动计入当期损益的金融负债的账面价值与按合同约定到期应支付债权人金额之间的差额为人民币[XX]元。]

Sheet 明细表G10-2
A1: 致同会计师事务所
A2: 交易性金融负债明细表
A3: =底稿目录!A2 -> 被审计单位： | H3: =底稿目录!A4 -> 编制人： | L3: =底稿目录!A5 -> 编制日期： | R3: 索引号： | S3: =底稿目录!F8 -> G10-2
A4: =底稿目录!A3 -> 截止日：202X年12月31日 | H4: 复核人： | L4: =底稿目录!A7 -> 复核日期： | R4: 页 次：
A5: 一、审计目标
A6: 1、资产负债表中记录的交易性金融负债是存在的，且已经记录在恰当的账户中；2、所有应记录的交易性金融负债均已记录，所有应当包括在财务报表中的相关披露均已包括；
A7: 3、交易性金融负债以恰当的金额包括在财务报表中，与之相关的计价或分摊调整已恰当记录，相关披露已得到恰当计量和描述
A8: 二、审计过程
A9: 类别 | B9: 项目【按明细项目列示，如债券名称】 | C9: 期初余额 | H9: 本期变动（增加“+”/减少“—”） | K9: 期末余额 | P9: 到期日 | Q9: 票面利率 | R9: 期末应付利息 | S9: 发行文件索引
C10: 初始确认金额 | D10: 累计公允价值变动 | E10: 公允价值 | F10: 期初调整数 | G10: 期初审定数 | H10: 初始确认金额 | I10: 本期公允价值变动 | J10: 计入财务费用的利息 | K10: 初始确认金额 | L10: 累计公允价值变动 | M10: 公允价值 | N10: 调整数 | O10: 审定数
A11: 指定类 | B11: 短期融资券 | E11: =C11+D11 -> 0 | G11: =E11+F11 -> 0 | K11: =C11+H11 -> 0 | L11: =D11+I11+J11 -> 0 | M11: =K11+L11 -> 0 | O11: =M11+N11 -> 0
E12: =C12+D12 -> 0 | G12: =E12+F12 -> 0 | K12: =C12+H12 -> 0 | L12: =D12+I12+J12 -> 0 | M12: =K12+L12 -> 0 | O12: =M12+N12 -> 0
E13: =C13+D13 -> 0 | G13: =E13+F13 -> 0 | K13: =C13+H13 -> 0 | L13: =D13+I13+J13 -> 0 | M13: =K13+L13 -> 0 | O13: =M13+N13 -> 0
E14: =C14+D14 -> 0 | G14: =E14+F14 -> 0 | K14: =C14+H14 -> 0 | L14: =D14+I14+J14 -> 0 | M14: =K14+L14 -> 0 | O14: =M14+N14 -> 0
E15: =C15+D15 -> 0 | G15: =E15+F15 -> 0 | K15: =C15+H15 -> 0 | L15: =D15+I15+J15 -> 0 | M15: =K15+L15 -> 0 | O15: =M15+N15 -> 0
E16: =C16+D16 -> 0 | G16: =E16+F16 -> 0 | K16: =C16+H16 -> 0 | L16: =D16+I16+J16 -> 0 | M16: =K16+L16 -> 0 | O16: =M16+N16 -> 0
E17: =C17+D17 -> 0 | G17: =E17+F17 -> 0 | K17: =C17+H17 -> 0 | L17: =D17+I17+J17 -> 0 | M17: =K17+L17 -> 0 | O17: =M17+N17 -> 0
E18: =C18+D18 -> 0 | G18: =E18+F18 -> 0 | K18: =C18+H18 -> 0 | L18: =D18+I18+J18 -> 0 | M18: =K18+L18 -> 0 | O18: =M18+N18 -> 0
E19: =C19+D19 -> 0 | G19: =E19+F19 -> 0 | K19: =C19+H19 -> 0 | L19: =D19+I19+J19 -> 0 | M19: =K19+L19 -> 0 | O19: =M19+N19 -> 0
E20: =C20+D20 -> 0 | G20: =E20+F20 -> 0 | K20: =C20+H20 -> 0 | L20: =D20+I20+J20 -> 0 | M20: =K20+L20 -> 0 | O20: =M20+N20 -> 0
A21: 合计 | C21: =SUM(C11:C20) -> 0 | D21: =SUM(D11:D20) -> 0 | E21: =SUM(E11:E20) -> 0 | F21: =SUM(F11:F20) -> 0 | G21: =SUM(G11:G20) -> 0 | H21: =SUM(H11:H20) -> 0 | I21: =SUM(I11:I20) -> 0 | J21: =SUM(J11:J20) -> 0 | ... N21: =SUM(N11:N20) -> 0 | O21: =M21+N21 -> 0 | P21: -- | Q21: -- | R21: =SUM(R11:R20) -> 0 | S21: --
A22: 三、审计说明：
B23: 本期计入“财务费用”的利息金额为：
A27: 四、审计结论：
A31: 编制说明【非打印内容】：
A32: 1．编制时应列入交易性金融负债的每一明细账户。2．外币交易性金融负债应列明原币金额及折合汇率（自行添加项目）。
A33: 3.审计说明可以概述:(1)程序的测试情况、结果;(2)拟调整事项及其调整分录、未调整事项及其影响，审计范围受到限制情况及其影响。
A34: 4.审计结论可参考:A、未见异常。 B、除上述重大不符事项应当作为调整事项予以调整外，其余未见异常。由于存在以下重大未调整事项(或审计范围受到限制无法获取充分、适当证据)，不可确认。

Sheet 调整分录汇总G10-3
A1: 致同会计师事务所
A2: 交易性金融负债调整分录汇总表
A3: =底稿目录!A2 -> 被审计单位： | D3: =底稿目录!A4 -> 编制人： | G3: =底稿目录!A5 -> 编制日期： | I3: 索引号： | J3: =底稿目录!F9 -> G10-3
A4: =底稿目录!A3 -> 截止日：202X年12月31日 | D4: =底稿目录!A6 -> 复核人： | G4: =底稿目录!A7 -> 复核日期： | I4: 页 次：1
A5: 调整事项说明 | B5: 类别（报表调整/账项调整/其他） | C5: 报表项目 | D5: 科目名称 | E5: 附注项目 | F5: …… | G5: 借方调整金额 | H5: 贷方调整金额 | I5: 索引 | J5: 备注

Sheet 分类的适当性检查表G10-4
A1: 致同会计师事务所
A2: 划分为以公允价值计量且其变动计入当期损益的金融负债的适当性检查表
A3: =底稿目录!A2 -> 被审计单位： | D3: =底稿目录!A4 -> 编制人： | F3: =底稿目录!A5 -> 编制日期： | G3: 索引号： | H3: =底稿目录!F10 -> G10-4
A4: =底稿目录!A3 -> 截止日：202X年12月31日 | D4: =底稿目录!A6 -> 复核人： | F4: =底稿目录!A7 -> 复核日期： | G4: 页 次：
A5: 一、审计目标 | B5: 确定以公允价值计量且其变动计入当期损益的金融负债分类是否正确。
A6: 二、审计过程 | B6: 1. 以公允价值计量且其变动计入当期损益的金融负债的指定是否符合准则要求、会计处理是否合理并与前期一致。
B7: 2. 就管理层将投资确定为非交易性的目的获取书面声明，询问管理层持有相关资产的目的，实施以下程序印证管理层的答复，确定相关资产的分类是否正确：
B8: 2.1 考虑管理层以前所述的对于负债管理模式的实际实施情况；
B9: 2.2 复核包括预算、管理层会议纪要等在内的文件和报告记录，检查管理层是否对负债的管理模式的进行了明确的书面指定。
B10: 3. 与管理层讨论金融负债分类是否符合企业会计准则，是否根据确定的分类选用了正确的核算方法。
B11: 4. 是否发现管理层在以前年度运用的重大判断和估计存在不合理的情形。如果存在，记录管理层是否在当年进行了恰当的会计处理和披露，并选用了更为准确的判断和假设。
A12: 项目名称 | B12: 期末账面价值 | C12: “交易性”[需属于下列任一情形之一] | F12: “初始确认时指定”[满足下列条件之一] | H12: 书面文件索引号
C13: 取得相关金融负债的目的，主要是为了近期出售或回购 | D13: 相关金融负债在初始确认时属于集中管理的可辨认金融工具组合的一部分，且有客观证据表明近期实际存在短期获利模式 | E13: 相关金融负债属于衍生工具（但符合财务担保合同定义的衍生工具以及被指定为有效套期工具的衍生工具除外） | F13: 能够消除或显著减少会计错配 | G13: 根据正式书面文件载明的企业风险管理或投资策略，以公允价值为基础对金融负债组合或金融资产和金融负债组合进行管理和业绩评价，并在企业内部以此为基础向关键管理人员报告
A14: 短期融资券 | B14: ='明细表G10-2'!M11 -> 0
B15: ='明细表G10-2'!M12 -> 0
B16: ='明细表G10-2'!M13 -> 0
B17: ='明细表G10-2'!M14 -> 0
B18: ='明细表G10-2'!M15 -> 0
B19: ='明细表G10-2'!M16 -> 0
B20: ='明细表G10-2'!M19 -> 0
B21: ='明细表G10-2'!M20 -> 0
A22: 合计 | B22: =SUM(B14:B21) -> 0
A24: 三、审计说明：
A27: 四、审计结论

Sheet 公允价值测试表G10-5
A1: 致同会计师事务所
A2: 交易性金融负债公允价值测试表
A3: =底稿目录!A2 -> 被审计单位： | E3: =底稿目录!A4 -> 编制人： | L3: =底稿目录!A5 -> 编制日期： | Q3: 索引号： | R3: =底稿目录!F11 -> G10-5
A4: =底稿目录!A3 -> 截止日：202X年12月31日 | E4: =底稿目录!A6 -> 复核人： | L4: =底稿目录!A7 -> 复核日期： | Q4: 页 次：
A5: 一、审计目标 | B5: 确定被审计单位交易性金融负债以公允价值计量。
A6: 二、审计过程
A7: 项目【按明细项目列示，如债券名称】 | B7: 期末未审数 | F7: 期末审定数 | J7: 差异 | K7: 估值方法 | L7: 估值方法与上期是否一致 | M7: 第一层次 | N7: 第二层次 | O7: 第三层次 | R7: 估值文件索引号
B8: 数量（张/股） | C8: 单位公允价值 | D8: 公允价值 | E8: 公允价值层次 | F8: 数量（张/股） | G8: 单位公允价值 | H8: 公允价值 | I8: 公允价值层次 | M8: 公允价值来源机构 | N8: 输入值来源及调整考虑因素 | O8: 估值技术 | P8: 不可观察输入值 | Q8: 数值
D9: =B9*C9 -> 0 | E9: 第二层次 | H9: =F9*G9 -> 0 | I9: 第二层次 | J9: =H9-D9 -> 0 | N9: 以合同规定的未来现金流量按照市场上具有可比信用等级并在相同条件下提供几乎相同现金流量的利率进行折现后的现值确定
D10: =B10*C10 -> 0 | H10: =F10*G10 -> 0 | I10: 第三层次 | J10: =H10-D10 -> 0
H11: =F11*G11 -> 0 | J11: =H11-D11 -> 0
H12: =F12*G12 -> 0 | J12: =H12-D12 -> 0
H13: =F13*G13 -> 0 | J13: =H13-D13 -> 0
H14: =F14*G14 -> 0 | J14: =H14-D14 -> 0
H15: =F15*G15 -> 0 | J15: =H15-D15 -> 0
H16: =F16*G16 -> 0 | J16: =H16-D16 -> 0
H17: =F17*G17 -> 0 | J17: =H17-D17 -> 0
H18: =F18*G18 -> 0 | J18: =H18-D18 -> 0
A19: 合计 | D19: =SUM(D9:D18) -> 0 | H19: =SUM(H9:H18) -> 0 | J19: =SUM(J9:J18) -> 0
A20: 三、审计说明：
A21: 了解专家资质及利用估值专家的工作详见：B21、C25、S12、S13
A24: 四、审计结论：
A26: 编制说明：
A27: 1、公允价值的层次
A28: （1）第一层次——相同资产或负债在活跃市场中的报价（未经调整的）。只有在交易所或活跃指数/市场上进行交易的工具才能归入第一层次。
A29: 这一层次包括上市的权益证券和债权工具以及交易所交易的衍生产品如股指期货（基于Nasdaq、S&P500等指数）等。
A30: （2）第二层次——直接（即价格）或间接（即从价格推导出）地使用除第一层次中的资产或负债的市场报价之外的可观察输入值。
A31: 这一层次包括大部分场外交易的衍生工具和债券，交易性贷款和发行的结构型债务工具。
A32: （3）第三层次——资产或负债使用了任何非基于可观察市场数据的输入值（不可观察输入值）。
A33: 这一层次包括一项或多项重大输入为不可观察变量的股权和债券工具。所采用的估值模型通常为现金流折现模型。
A34: 2、概述：（1）程序的测试情况、结果；
... A36: 参考结论：
A37: A、 | B37: 未见异常。
A38: B、 | B38: 除以下重大不符事项应当作为调整事项予以调整外，其余未见异常。
A39: C、 | B39: 由于存在以下重大未调整事项（或审计范围受到限制无法获取充分、适当证据），不可确认。

Sheet 第三层次公允价值计量的调节表G10-6
A1: 致同会计师事务所
A2: 第三层次公允价值计量的调节表
A3: =底稿目录!A2 -> 被审计单位： | F3: =底稿目录!A4 -> 编制人： | I3: =底稿目录!A5 -> 编制日期： | L3: 索引号： | M3: =底稿目录!F12 -> G10-6
A4: =底稿目录!A3 -> 截止日：202X年12月31日 | F4: =底稿目录!A6 -> 复核人： | I4: =底稿目录!A7 -> 复核日期： | L4: 页次：
A5: 一、审计目标 | C5: 确定第三层次公允价值计量披露是否适当
A6: 二、审计过程 | C6: 1 | D6: 取得第三层次公允价值计量金融资产明细清单，复核加计是否正确；
C7: 2 | D7: 确定第三层次公允价值计量调节过程披露是否适当
A8: 项目名称 | C8: 期初余额 | D8: 转入第三层次 | E8: 转出第三层次 | F8: 当期利得或损失总额 | H8: 购买、发行、出售和结算 | L8: 期末余额 | M8: 对于在报告期末发行的负债，计入损益的当期未实现利得或损失的变动
F9: 公允价值变动损益 | G9: 投资收益 | H9: 购入 | I9: 发行 | J9: 出售 | K9: 结算
L10: =C10+D10-E10+F10+H10+I10-J10-K10 -> 0
L11: =C11+D11-E11+F11+H11+I11-J11-K11 -> 0
L12: =C12+D12-E12+F12+H12+I12-J12-K12 -> 0
L13: =C13+D13-E13+F13+H13+I13-J13-K13 -> 0
L14: =C14+D14-E14+F14+H14+I14-J14-K14 -> 0
L15: =C15+D15-E15+F15+H15+I15-J15-K15 -> 0
L16: =C16+D16-E16+F16+H16+I16-J16-K16 -> 0
L17: =C17+D17-E17+F17+H17+I17-J17-K17 -> 0
L18: =C18+D18-E18+F18+H18+I18-J18-K18 -> 0
A19: 合 计 | C19: =SUM(C10:C18) -> 0 | D19: =SUM(D10:D18) -> 0 | E19: =SUM(E10:E18) -> 0 | F19: =SUM(F10:F18) -> 0 | G19: =SUM(G10:G18) -> 0 | H19: =SUM(H10:H18) -> 0 | I19: =SUM(I10:I18) -> 0 | J19: =SUM(J10:J18) -> 0 | ... L19: =SUM(L10:L18) -> 0
A20: 三、审计说明：
A22: 四、审计结论：

Sheet 凭证检查表G10-7
A1: 致同会计师事务所
A2: 交易性金融负债凭证检查表
A3: =底稿目录!A2 -> 被审计单位： | E3: =底稿目录!A4 -> 编制人： | J3: =底稿目录!A5 -> 编制日期： | P3: 索引号： | Q3: =底稿目录!F21 -> G10-7
A4: =底稿目录!A3 -> 截止日：202X年12月31日 | E4: =底稿目录!A6 -> 复核人： | J4: =底稿目录!A7 -> 复核日期： | P4: 页 次：
A5: 一、审计目标
A6: 1、资产负债表中记录的交易性金融负债是存在的，且已经记录在恰当的账户中；2、记录的交易性金融负债由被审计单位拥有或控制；
A7: 3、交易性金融负债以恰当的金额包括在财务报表中，与之相关的计价或分摊调整已恰当记录，相关披露已得到恰当计量和描述
A8: 二、样本选取方法与规模：
A9: 测试总体： | B9: 如交易性金融负债借方发生额所有凭证共XX笔金额XX、贷方发生额所有凭证共XX笔金额XX | G9: 特定样本： | H9: XX金额以上（大额）、关联方/关联交易形成的款项、XX异常款项全部测试，共XX笔；
A10: 抽样总体： | B10: 测试总体扣除特定样本以外的样本，共XX笔、金额XX | F10: 确定的抽样样本量： | G10: 抽取XX笔（如果使用了样本计算器计算样本量，样本量计算过程见<XX>底稿）
A11: 抽样方法： | B11: 随机选样/系统选样/货币单元抽样/随意选样（非统计抽样适用） | F11: 抽样过程： | G11: 使用IDEA（XX抽样工具）选择XX数量、金额XX的样本进行测试，抽样工具中的样本选择过程和结果见<XX>底稿
A12: 三、测试：
A13: 测试内容说明：1.原始凭证内容完整；2.有授权批准；3.账务处理正确；4.初始成本计算正确；5.利息计算正确；6.公允价值符合准则要求。
A14: 1.本期发生额检查
A15: 记账凭证 | H15: 支持性文件 | I15: 核对内容 | O15: 索引号 | P15: 是否异常 | Q15: 备注说明
A16: 日期 | B16: 凭证编号 | C16: 业务内容 | D16: 对方科目 | E16: 对方明细科目 | F16: 借方金额 | G16: 贷方金额 | I16: 1 | J16: 2 | K16: 3 | L16: 4 | M16: 5 | N16: 6
A26: 合计 | F26: =SUM(F17:F25) -> 0 | G26: =SUM(G17:G25) -> 0
A27: 本期发生额
A28: 检查比例 | F28: =F26/F27 -> #DIV/0! | G28: =G26/G27 -> #DIV/0!
A29: 2.期后处置、新增检查表
C30: 记账凭证 | H30: 支持性文件 | I30: 核对内容 | O30: 索引号 | P30: 是否异常 | Q30: 备注说明
A31: 日期 | B31: 凭证编号 | C31: 业务内容 | D31: 对方科目 | E31: 对方明细科目 | F31: 借方金额 | G31: 贷方金额 | I31: 1 | J31: 2 | K31: 3 | L31: 4 | M31: 5 | N31: 6
A37: 合计 | F37: =SUM(F32:F36) -> 0 | G37: =SUM(G32:G36) -> 0
A38: 四、审计说明：
A40: 五、审计结论：
A44: 编制说明：
A45: 1、概述：（1）程序的测试情况、结果；
A46: （2）拟调整事项及其调整分录、未调整事项及其影响，审计范围受到限制情况及其影响。
A47: 参考结论：
A48: A、 | B48: 未见异常。
A49: B、 | B49: 除以下重大不符事项应当作为调整事项予以调整外，其余未见异常。
A50: C、 | B50: 由于存在以下重大未调整事项（或审计范围受到限制无法获取充分、适当证据），不可确认。
A52: 2、选取测试项目的方法：包括选取全部项目、选取特定项目和审计抽样。
A53: （1） | B53: 当存在下列情形之一时，注册会计师应当考虑选取全部项目进行测试：
B54: （一）总体由少量的大额项目构成；
B55: （二）存在特别风险且其他方法未提供充分、适当的审计证据；
B56: （三）由于信息系统自动执行的计算或其他程序具有重复性，对全部项目进行检查符合成本效益原则。
B58: 特别风险涉及的事项包括但不限于：
B59: （1）舞弊风险（如1141准则的示例）；（2）重大非常规交易（如企业购并、债务重组、非货币性资产交换、
B60: 重大或有事项、持续经营、违反法律法规等）；(3)重大关联交易；(4)重大判断事项（如重大会计估计、
...

Sheet 衍生金融工具核查表G10-8
A1: 致同会计师事务所
A2: 衍生金融工具核查表
A3: =底稿目录!A2 -> 被审计单位： | D3: =底稿目录!A4 -> 编制人： | F3: =底稿目录!A5 -> 编制日期： | G3: 索引号： | H3: =底稿目录!F22 -> G10-8
A4: =底稿目录!A3 -> 截止日：202X年12月31日 | D4: =底稿目录!A6 -> 复核人： | F4: =底稿目录!A7 -> 复核日期： | G4: 页 次：
A5: 一、审计目标 | C5: 确定衍生工具投资活动计量是否准确。
A6: 二、审计过程
A7: 1 | B7: 确定衍生工具
C8: 工具名称：___________________________________________
A9: A | B9: 复核与(主合同的)交易对方所签订贷款、投资、存款或其它工具的协议
A10: B | B10: 在协议中有无提及任何有下列影响的项目(即是否存在任何衍生工具或附于主合同的衍生工具？) | F10: 回答
B11: 合同所要求的部分/全部现金流量将依据以下各特定项目予以修正：
C12: (1)利率 | G12: (是或否)
C13: (2)金融工具价格 | G13: (是或否)
C14: (3)商品价格 | G14: (是或否)
C15: (4)汇率 | G15: (是或否)
C16: (5)价格或利率指数 | G16: (是或否)
C17: (6)信用等级/信用指数 | G17: (是或否)
C18: (7)其它非金融变量(请注明：______________) | G18: (是或否)
C19: (8)其它非金融变量非合同某一方特有的(请注明：________) | G19: (是或否)
C20: (如果对于上述B项的任何答案为否，即表示不附有任何衍生工具，则无需回答下列问题)
A21: C | B21: 所包含的衍生工具是否属于嵌入衍生工具？
C22: 如果上述B项的任何答案为是，即表明存在附于主合同的衍生工具，请回答下列问题：
C23: (1)有关衍生工具不可以独立于该金融工具进行合约转让 | G23: (是或否)
C24: (2)有关衍生工具具有与主金融工具(主合同)相同的交易对方 | G24: (是或否)
C25: 如果上述C项的任何答案为否，即表明不存在任何嵌入衍生工具，则无需回答下列问题。有关衍生工具应与主合同相分离并进行不同核算。
C26: 对衍生工具(不是嵌入衍生工具)执行的额外工作：
C27: (a)说明有关性质 | G27: (描述性)
C28: (b)增设新的科目描述及编码以确认所包含的衍生工具 | G28: (描述性)
C29: (c)说明适用于有关衍生工具的会计政策 | G29: (描述性)
A30: D | B30: 嵌入衍生工具是否应与主合同分离？
C31: 如果上述1C的任何答案为是，即表明衍生工具嵌入主合同。请针对各项确定的嵌入衍生工具回答下列问题以总结有关嵌入衍生工具是否与主合同分离并作为衍生工具进行会计处理？
C32: (1)嵌入衍生工具的经济特征及风险与主合同的经济特征及风险并不紧密相关。 | G32: 是或否
C33: 指引：
C34: 嵌入衍生工具与主合同并不紧密相关的例子，这种情况下需要与主合同分离
C35: (a)在债务工具中是否嵌入了信用衍生工具？
C36: (b)是否存在可转换债券？
C37: (c)金融工具中是否嵌入了卖出/买入期权？
C38: (d)是否拥有将某项债务工具到期日予以展期的选择权？
C39: (e)是否存在任何债务性证券/带息的租赁保险合同/与货物/权益价格挂钩的本金金额？
C40: 嵌入衍生工具与主合同紧密相关的例子
...
