Workbook

Sheet 底稿目录
A1: 底稿开列时，可先在以下单元格填写有关内容，以便其他底稿引用有关数据：
A2: 被审计单位：
A3: 截止日：202X年12月31日 | D3: 序号 | E3: 内容 | F3: 索引号
A4: 编制人： | E4: 其他权益工具投资实质性程序表 | F4: G8A
A5: 编制日期： | D5: 1 | E5: 审定表 | F5: G8-1 | G5: 无需打印
A6: 复核人： | D6: 2 | E6: 附注披露信息（上市公司） | G6: 无需打印
A7: 复核日期： | D7: 3 | E7: 附注披露信息（国企）
D8: 4 | E8: 明细表 | F8: G8-2
A9: 关于工作底稿与审计程序索引号对应的说明 | D9: 5 | E9: 调整分录汇总 | F9: G8-3
A10: 1.编制的审计工作底稿应与审计程序对应。审计项目组应根据被审计单位实际情况和风险评估情况在实质性程序表中裁剪、修改或增加审计程序，根据实际执行的审计程序完成相应审计工作底稿，编制的工作底稿中应按自然顺序依次编制索引号，并通过唯一的索引号将与实质性程序表中的程序对应关联（即将工作底稿的索引号填入实质性程序表中的底稿索引号列）。 | D10: 6 | E10: 公允价值测试表 | F10: G8-4
D11: 7 | E11: 指定的适当性检查表 | F11: G8-5
D12: 8 | E12: 函证结果汇总表 | F12: G0-1
D13: 9 | E13: 核实被函证单位信息 | F13: G0-2
A14: 2.获取的支持性证据应与审计底稿或程序对应。审计项目组在完成底稿时获取的支持性证据应根据底稿索引号编制下一级按自然顺序排序的索引号（如D1-2-1、D1-2-2、……），并在底稿中说明引用的支持性证据、关联索引号。 | D14: 10 | E14: 跟函函证过程控制 | F14: G0-3
D15: 11 | E15: 函证差异核对表（证券投资） | F15: G0-4
D16: 12 | E16: 函证差异核对表(非证券投资) | F16: G0-5
A17: 3.工作底稿索引号的编码规则：实质性程序索引号按循环从“D”到“N”,循环内账户以顺序号排列，模板中底稿索引号按账户顺序+自然数顺序（即模板中索引号按二级自然顺序排列，如D1-1、D1-2、D1-3、……D1-N）。 | D17: 13 | E17: 替代程序检查表 | F17: G0-6
D18: 14 | E18: 邮件传真回函可靠性验证 | F18: G0-7
D19: 15 | E19: 函证程序舞弊风险评价表 | F19: G0-8
D20: 16 | E20: 凭证检查表 | F20: G8-6

Sheet 其他权益工具投资实质性程序表G8A
A1: 致同会计师事务所
A2: 其他权益工具投资实质性程序表
A3: =底稿目录!A2 -> 被审计单位： | C3: =底稿目录!A4 -> 编制人： | F3: =底稿目录!A5 -> 编制日期： | H3: 索引号： | I3: =底稿目录!F4 -> G8A
A4: =底稿目录!A3 -> 截止日：202X年12月31日 | C4: =底稿目录!A6 -> 复核人： | F4: =底稿目录!A7 -> 复核日期： | H4: 页 次：
A5: 一、本账户涉及的科目
A6: 其他权益工具投资
A7: 二、审计目标与认定的对应关系
A8: 审计目标 | G8: 财务报表的认定
A9: A. 资产负债表中记录的其他权益工具投资是存在的，且已记录于恰当的账户 | G9: 存在
A10: B. 所有应记录的其他权益工具投资均已记录，所有应当包括在财务报表中的相关披露均已包括 | G10: 完整性
A11: C. 记录的其他权益工具投资由被审计单位拥有或控制 | G11: 权利和义务
A12: D. 其他权益工具投资以恰当的金额包括在财务报表中，与之相关的计价或分摊调整已恰当记录，相关披露已得到恰当计量和描述 | G12: 准确性、计价和分摊
A13: E. 其他权益工具投资已被恰当地汇总或分解且表述清楚，相关披露在按照企业会计准则的编制基础下是相关的、可理解的 | G13: 列报
A14: 三、计划实施的实质性程序
A15: 序号 | B15: 审计程序 | C15: 程序分类 | D15: 财务报表的认定 | I15: 底稿索引号
D16: 存在 | E16: 完整性 | F16: 权利和 义务 | G16: 准确性、计价和分摊 | H16: 列报
A17: 1 | B17: 获取或编制其他权益工具投资的明细表，完成以下工作，并编制审定表 （1）复核加计是否正确，与总账、明细账合计数核对是否相符,将期初余额与上期期末余额核对； （2）追查明细表至调节表/将重大头寸与相应证券记录清单/证券服务机构提供的所有投资账户的电子文件/对账单（在可能的情况下自行进入交易系统获得对账单））核对一致; （3）与上年明细项目进行比较，确定与上年分类相同； （4）与应收利息、投资收益、公允价值变动损益等项目的变动进行核对，复核其勾稽关系； （5）调查重大或者异常的调节项目，并与客户的适当人员讨论差异，考虑回复的可信度并确认相关解释，以及采取适当的措施； （6）检查非记账本位币计量的其他权益工具投资的折算汇率及折算是否正确。 | C17: 常规★ | D17: √ | E17: √ | G17: √ | I17: G8-1 /G8-2
A18: 2 | B18: 在使用手工编制、自定义信息报告、系统生成的非固定格式报告等由被审计单位生成的信息时，测试有关信息准确性和完整性，并考虑针对编制和维护由被审计单位生成的信息的相关控制实施控制测试，以评价该信息是否能够为实现审计目的提供基础。 | C18: 常规★ | E18: √ | G18: √ | I18: T1 /G0-2
A19: 3 | B19: 对期初余额的审计，取得其他权益工具投资期初余额明细表复核加计是否正确，与总账、明细账合计数是否相符，确定会计政策及程序是否适当，确定计算的准确性；检查期初投资在本期处置情况，确定证券投资是否在第一个季度亏损出售；将重大投资与其支持性文件核对一致；确定是否需要补充必要的程序，如果是，执行适当的应对程序。（适用于首次承接） | C19: 备选 | D19: √ | E19: √ | F19: √ | G19: √
A20: 4 | B20: 根据实际情况，实施以下分析程序： （1）获取增、减分析表，确定增加内容及减少方式、对损益的影响； （2）复核年度其他权益工具投资的总体合理性；对变化较大的项目或没有变动的项目进行复核，与被审计单位适当人员讨论原因，判断其存在的合理性，是否存在减值； （3）结合其他权益工具投资循环中投资收益的审计，计算年度其他权益工具投资循环收益占利润总额的比例，分析公司对投资循环收益的依赖程度，判断其盈利能力和稳定性。 | C20: 常规★ | D20: √ | G20: √ | I20: G8-1 /G8-2
A21: 5 | B21: 确认其他权益工具投资会计政策、会计处理是否合理并与前期一致，会计估计是否合理，实施以下程序： （1）关注被审计单位管理金融工具的业务模式，并结合合同现金流量特征，分析管理层对金融资产分类是否合理； （2）与管理层讨论其他权益工具投资分类是否符合企业会计准则，是否根据确定的分类选用了正确的核算方法； （3）是否发现管理层在以前年度运用的重大判断和估计存在不合理的情形。如果存在，记录下管理层是否在当年进行了恰当的会计处理和披露，并选用了更为准确的判断和假设； （4）核对相关资产减值准备本期与以前年度计提方法是否一致，如有差异，查明政策调整的原因，并确定政策改变对本期损益的影响，提请被审计单位做适当披露。 | C21: 常规★ | D21: √ | E21: √ | G21: √ | I21: G8-1 /G8-2
A22: 6 | B22: 对于本期新增的其他权益工具投资，执行以下程序： （1）获取本期增加的其他权益工具投资的合约、协议、中介机构报告等（若适用），查验其他权益工具投资的分类及计价是否正确；追查至相应的原始凭证及支持文件，检查其是否经过授权审批，确认是否符合合同协议条款的规定；必要时进行穿透核查，明确相关金融产品的资金投向，是否存在定向投资要求、投资对象是否与控股股东存在关联关系等； （2）对本期增加中的特定项目（如金额重大或性质特殊的）进行以下测试：检查非货币性资产交换、债务重组、企业合并、投资等发生取得其他权益工具的会计处理是否正确； | C22: 常规★ | D22: √ | E22: √ | G22: √ | I22: G8-2 /G8-6
A23: 7 | B23: 关注单独的重大其他权益工具投资转移或处置，考虑实施以下程序： （1）获取本期减少的其他权益工具投资投资的合约、协议、中介机构报告等（若适用），查验其他权益工具投资转移的处理及计价是否正确；追查至相应的原始凭证及支持文件，检查其是否经过授权审批，确认是否符合合同协议条款的规定； （2）对本期减少中的特定项目进行以下测试：检查非货币性资产交换、债务重组、企业合并、投资等发生其他权益工具投资转移的会计处理是否正确； （3）重新计算相关的利得或损失； （4）关注处置日期是否记录恰当，会计处理是否恰当。 | C23: 常规★ | D23: √ | F23: √ | G23: √ | I23: G8-2 /G8-6
A24: 8 | B24: 向相关机构发函，并确定是否存在变现限制，同时记录函证过程： （1）以积极方式进行函证，设计询证函、发函前核实被函证单位信息； （2）注册会计师独立收发询证函； （3）编制函证结果汇总表，检查发函、回函物流信息和轨迹、比对回函印章和签字等以核实回函的真实性，检查回函是否相符，对不符事项查明原因确定是否存在错报； （4）如果未收到回函，应当考虑与被询证者联系，要求对方作出回应或再次寄发询证函，无法收到的回函实施替代程序； （5）如果管理层不允许寄发询证函的，询问管理层不允许寄发的原因，并就其原因的正当、合理性收集证据；考虑实施替代审计程序以获取相关、可靠的审计证据； （6）如果管理层不允许寄发询证函的原因不合理、或者认为回函不可靠，评价对评估的重大错报风险以及其他审计程序的性质、时间安排和范围的影响，并确定其对审计工作和审计意见的影响。 | C24: 常规★ | D24: √ | E24: √ | F24: √ | G24: √ | I24: G0
A25: 9 | B25: 资产负债表日至审计工作日间，新增、售出、兑换、处置或偿付的大额出售或购买交易，确认是否被记录在恰当时期内；检查报表日后的证券处置是否出现亏损，如果确认亏损，确定这些亏损是否应该记录在报表期。 | C25: 常规★ | D25: √ | E25: √ | G25: √ | I25: G8-2
A26: 10 | B26: 针对公允价值计量的投资，复核其他权益工具投资计价方法，检查其是否按公允价值计量，前后期是否一致；复核公允价值取得依据是否充分；与被审计单位讨论以确定实际利率确定依据是否充分，非本期新增投资，复核实际利率是否与前期一致；复核计算持有期间的利息收入和投资收益；检查会计处理是否正确。若选择利用专家工作的审计程序，参考“S12利用专家的工作”相关程序执行。 | C26: 常规★ | G26: √ | I26: G8-4
A27: 11 | B27: 询问各项投资是否存在任何限制、抵押或留置权。 检查有无变现存在重大限制的资产，如有，则查明情况，作出记录。 | C27: 常规★ | F27: √ | I27: G8-2
A28: 12 | B28: 检查关联方交易： （1）了解关联交易的商业理由、交易事项的目的、价格和条件，考虑对关联方交易性金融资产的合理性、合法性； （2）检查对关联方交易性金融资产的真实性相关的支持性文件、检查会计处理是否正确； （3）考虑向关联方或其他注册会计师函证重大的关联交易和余额（包括担保和其他重要信息）； （4）必要时，向与交易相关的人员和机构函证或与其讨论有关信息； （5）考虑是否存在未识别的关联方，关联交易和余额披露是否正确。 | C28: 常规★ | D28: √ | E28: √ | F28: √ | G28: √ | H28: √ | I28: G8-6
A29: 13 | B29: 根据评估的舞弊风险等因素增加的审计程序。 | C29: IPO/上市/新三板/重组/舞弊应对
A30: 14 | B30: 检查其他权益工具投资是否已按企业会计准则或其他适用的规定在财务报表中做出恰当列报和披露。 | C30: 常规★ | H30: √ | I30: A1-1/A1-15 /A1-16

Sheet 审定表G8-1
A1: 致同会计师事务所
A2: 其他权益工具投资审定表
A3: =底稿目录!A2 -> 被审计单位： | D3: =底稿目录!A4 -> 编制人： | G3: =底稿目录!A5 -> 编制日期： | I3: 索引号： | J3: =底稿目录!F5 -> G8-1
A4: =底稿目录!A3 -> 截止日：202X年12月31日 | D4: =底稿目录!A6 -> 复核人： | G4: =底稿目录!A7 -> 复核日期： | I4: 页 次：
A5: 项目 | B5: 期初数 | E5: 期末数 | H5: 本期与上期审定数比较 | J5: 原因分析
B6: 未审数 | C6: 账项调整 | D6: 审定数 | E6: 未审数 | F6: 账项调整 | G6: 审定数 | H6: 变动额 | I6: 变动率
A7: 公允价值
A8: ='明细表G8-2'!A11 -> 0 | B8: ='明细表G8-2'!E11 -> 0 | C8: ='明细表G8-2'!G11 -> 0 | D8: =B8+C8 -> 0 | E8: ='明细表G8-2'!Q11 -> 0 | F8: ='明细表G8-2'!S11 -> 0 | G8: =E8+F8 -> 0 | H8: =G8-D8 -> 0 | I8: =IF(AND(D8=0,G8=0),"",IF(AND(D8=0,G8>0),1,H8/D8))
A9: ='明细表G8-2'!A12 -> 0 | B9: ='明细表G8-2'!E12 -> 0 | C9: ='明细表G8-2'!G12 -> 0 | D9: =B9+C9 -> 0 | E9: ='明细表G8-2'!Q12 -> 0 | F9: ='明细表G8-2'!S12 -> 0 | G9: =E9+F9 -> 0 | H9: =G9-D9 -> 0 | I9: =IF(AND(D9=0,G9=0),"",IF(AND(D9=0,G9>0),1,H9/D9))
B10: ='明细表G8-2'!E13 -> 0 | C10: ='明细表G8-2'!G13 -> 0 | D10: =B10+C10 -> 0 | E10: ='明细表G8-2'!Q13 -> 0 | F10: ='明细表G8-2'!S13 -> 0 | G10: =E10+F10 -> 0 | H10: =G10-D10 -> 0 | I10: =IF(AND(D10=0,G10=0),"",IF(AND(D10=0,G10>0),1,H10/D10))
B11: ='明细表G8-2'!E14 -> 0 | C11: ='明细表G8-2'!G14 -> 0 | D11: =B11+C11 -> 0 | E11: ='明细表G8-2'!Q14 -> 0 | F11: ='明细表G8-2'!S14 -> 0 | G11: =E11+F11 -> 0 | H11: =G11-D11 -> 0 | I11: =IF(AND(D11=0,G11=0),"",IF(AND(D11=0,G11>0),1,H11/D11))
B12: ='明细表G8-2'!E15 -> 0 | C12: ='明细表G8-2'!G15 -> 0 | D12: =B12+C12 -> 0 | E12: ='明细表G8-2'!Q15 -> 0 | F12: ='明细表G8-2'!S15 -> 0 | G12: =E12+F12 -> 0 | H12: =G12-D12 -> 0 | I12: =IF(AND(D12=0,G12=0),"",IF(AND(D12=0,G12>0),1,H12/D12))
B13: ='明细表G8-2'!E16 -> 0 | C13: ='明细表G8-2'!G16 -> 0 | D13: =B13+C13 -> 0 | E13: ='明细表G8-2'!Q16 -> 0 | F13: ='明细表G8-2'!S16 -> 0 | G13: =E13+F13 -> 0 | H13: =G13-D13 -> 0 | I13: =IF(AND(D13=0,G13=0),"",IF(AND(D13=0,G13>0),1,H13/D13))
B14: ='明细表G8-2'!E17 -> 0 | C14: ='明细表G8-2'!G17 -> 0 | D14: =B14+C14 -> 0 | E14: ='明细表G8-2'!Q17 -> 0 | F14: ='明细表G8-2'!S17 -> 0 | G14: =E14+F14 -> 0 | H14: =G14-D14 -> 0 | I14: =IF(AND(D14=0,G14=0),"",IF(AND(D14=0,G14>0),1,H14/D14))
B15: ='明细表G8-2'!E18 -> 0 | C15: ='明细表G8-2'!G18 -> 0 | D15: =B15+C15 -> 0 | E15: ='明细表G8-2'!Q18 -> 0 | F15: ='明细表G8-2'!S18 -> 0 | G15: =E15+F15 -> 0 | H15: =G15-D15 -> 0 | I15: =IF(AND(D15=0,G15=0),"",IF(AND(D15=0,G15>0),1,H15/D15))
B16: ='明细表G8-2'!E19 -> 0 | C16: ='明细表G8-2'!G19 -> 0 | D16: =B16+C16 -> 0 | E16: ='明细表G8-2'!Q19 -> 0 | F16: ='明细表G8-2'!S19 -> 0 | G16: =E16+F16 -> 0 | H16: =G16-D16 -> 0 | I16: =IF(AND(D16=0,G16=0),"",IF(AND(D16=0,G16>0),1,H16/D16))
B17: ='明细表G8-2'!E20 -> 0 | C17: ='明细表G8-2'!G20 -> 0 | D17: =B17+C17 -> 0 | E17: ='明细表G8-2'!Q20 -> 0 | F17: ='明细表G8-2'!S20 -> 0 | G17: =E17+F17 -> 0 | H17: =G17-D17 -> 0 | I17: =IF(AND(D17=0,G17=0),"",IF(AND(D17=0,G17>0),1,H17/D17))
A18: 合计 | B18: =SUM(B8:B17) -> 0 | C18: =SUM(C8:C17) -> 0 | D18: =SUM(D8:D17) -> 0 | E18: =SUM(E8:E17) -> 0 | F18: =SUM(F8:F17) -> 0 | G18: =SUM(G8:G17) -> 0 | H18: =SUM(H8:H17) -> 0 | I18: =IF(AND(D18=0,G18=0),"",IF(AND(D18=0,G18>0),1,H18/D18))
A19: 试算平衡表数
A20: 差异数 | D20: =D18-D19 -> 0 | G20: =G18-G19 -> 0
A21: 1、审计说明 | G21: 2、审计结论
A22: （1）其他权益工具投资本期较上期增加（负数为减少）： | D22: =IF(AND(D18=0,G18=0),0,IF(AND(D18=0,G18>0),1,(G18-D18)/D18)) -> 0
A23: 主要原因（比例超过30%的）：
A25: （2）情况说明

Sheet 附注披露信息（上市公司）
A1: 致同会计师事务所
A2: 附注披露信息（上市公司）
A3: =底稿目录!A2 -> 被审计单位： | C3: =底稿目录!A4 -> 编制人： | E3: =底稿目录!A5 -> 编制日期： | F3: 索引号： | G3: =底稿目录!F6 -> 0
A4: =底稿目录!A3 -> 截止日：202X年12月31日 | C4: =底稿目录!A6 -> 复核人： | E4: =底稿目录!A7 -> 复核日期： | F4: 页次：
A5: 附注披露信息
A6: 其他权益工具投资
A7: （15号文第十九条（九）分项列示其他权益工具投资期初余额、期末余额、本期计入其他综合收益的利得和损失、本期末累计计入其他综合收益的利得和损失、本期确认的股利收入以及指定为以公允价值计量且其变动计入其他综合收益的原因。本期存在终止确认的，应分项披露终止确认的原因，以及因终止确认转入留存收益的累计利得和损失。）
A8: 项 目 | B8: 期末余额 | C8: 上年年末余额
A12: 合 计 | B12: =SUM(B9:B11) -> 0 | C12: =SUM(C9:C11) -> 0
A13: 【披露企业将上述各项目指定为以公允价值计量且其变动计入其他综合收益的原因。例如：
A14: 由于[项目名称1]是本公司出于战略目的而计划长期持有的投资，因此本公司将其指定为以公允价值计量且其变动计入其他综合收益的金融资产。】
A15: 项 目 | B15: 本期计入其他综合收益的利得和损失 | C15: 本期末累计计入其他综合收益的利得和损失 | D15: 本期确认的股利收入 | E15: 因终止确认转入留存收益的累计利得和损失 | F15: 终止确认的原因

Sheet 附注披露信息（国企）
A1: 致同会计师事务所
A2: 附注披露信息（国企）
A3: =底稿目录!A2 -> 被审计单位： | C3: =底稿目录!A4 -> 编制人： | E3: =底稿目录!A5 -> 编制日期： | F3: 索引号： | G3: =底稿目录!F7 -> 0
A4: =底稿目录!A3 -> 截止日：202X年12月31日 | C4: =底稿目录!A6 -> 复核人： | E4: =底稿目录!A7 -> 复核日期： | F4: 页次：
A5: 附注披露信息
A6: 其他权益工具投资
A7: （1）其他权益工具投资情况
A8: 项 目 | B8: 期末余额 | C8: 期初余额
A12: 合 计 | B12: =SUM(B9:B11) -> 0 | C12: =SUM(C9:C11) -> 0
A13: [披露企业将上述各项目指定为以公允价值计量且其变动计入其他综合收益的原因。例如： 由于[项目名称1]是本公司出于战略目的而计划长期持有的投资，因此本公司将其指定为以公允价值计量且其变动计入其他综合收益的金融资产。]
A14: （2）期末其他权益工具投资情况
A15: 项目名称 | B15: 本期确认的股利收入 | C15: 本期计入其他综合收益的利得或损失 | D15: 截至期末累计计入其他综合收益的利得或损失 | E15: 其他综合收益转入留存收益的金额 | F15: 其他综合收益转入留存收益的原因
A20: 合 计 | B20: =SUM(B16:B19) -> 0 | C20: =SUM(C16:C19) -> 0 | D20: =SUM(D16:D19) -> 0 | E20: =SUM(E16:E19) -> 0

Sheet 明细表G8-2
A1: 致同会计师事务所 | N1: 致同会计师事务所
A2: 其他权益工具投资明细表 | N2: 其他权益工具投资明细表
A3: =底稿目录!A2 -> 被审计单位： | D3: =底稿目录!A4 -> 编制人： | F3: =底稿目录!A5 -> 编制日期： | L3: 索引号： | M3: =底稿目录!F8 -> G8-2 | N3: =A3 -> 被审计单位： | Q3: =D3 -> 编制人： | S3: =F3 -> 编制日期： | V3: =L3 -> 索引号： | W3: =M3 -> G8-2
A4: =底稿目录!A3 -> 截止日：202X年12月31日 | D4: =底稿目录!A6 -> 复核人： | F4: =底稿目录!A7 -> 复核日期： | L4: 页 次： | N4: =A4 -> 截止日：202X年12月31日 | Q4: =D4 -> 复核人： | S4: =F4 -> 复核日期： | V4: =L4 -> 页 次： | W4: =M4 -> 0
A5: 一、审计目标 | N5: =A5 -> 一、审计目标
A6: 1.资产负债表中记录的其他权益工具投资是存在的，且已经记录在恰当的账户中；2.所有应记录的其他权益工具投资均已记录，所有应当包括在财务报表中的相关披露均已包括； | N6: =A6 -> 1.资产负债表中记录的其他权益工具投资是存在的，且已经记录在恰当的账户中；2.所有应记录的其他权益工具投资均已记录，所有应当包括在财务报表中的相关披露均已包括；
A7: 3.其他权益工具投资以恰当的金额包括在财务报表中，与之相关的计价或分摊调整已恰当记录，相关披露已得到恰当计量和描述 | N7: =A7 -> 3.其他权益工具投资以恰当的金额包括在财务报表中，与之相关的计价或分摊调整已恰当记录，相关披露已得到恰当计量和描述
A8: 二、审计过程 | N8: =A8 -> 二、审计过程
A9: 被投资单位名称 | B9: 投资比例 | C9: 期初余额 | G9: 期初调整数 | H9: 期初审定数 | I9: 本期变动 | O9: 期末余额 | S9: 调整数 | T9: 审定数 | U9: 指定为以公允价值计量且其变动计入其他综合收益的原因 | V9: 其他综合收益转入留存收益的原因 | W9: 发函情况
C10: 成本 | D10: 累计公允价值变动 | E10: 合计 | F10: 计入其他综合收益的累计利得或损失 | I10: 成本 | J10: 本期公允价值变动 | K10: 处置时公允价值变动结转 | L10: 其他综合收益转入留存收益 | M10: 合计 | N10: 本期确认的股利收入 | O10: 成本 | P10: 累计公允价值变动 | Q10: 合计 | R10: 计入其他综合收益的累计利得或损失
E11: =SUM(C11:D11) -> 0 | H11: =E11+G11 -> 0 | M11: =SUM(I11:K11) -> 0 | O11: =C11+I11 -> 0 | P11: =D11+J11+K11 -> 0 | Q11: =SUM(O11:P11) -> 0 | R11: =F11+J11+L11 -> 0 | T11: =Q11+S11 -> 0 | U11: 公司出于战略目的而计划长期持有
E12: =SUM(C12:D12) -> 0 | H12: =E12+G12 -> 0 | M12: =SUM(I12:K12) -> 0 | O12: =C12+I12 -> 0 | P12: =D12+J12+K12 -> 0 | Q12: =SUM(O12:P12) -> 0 | R12: =F12+J12+L12 -> 0 | T12: =Q12+S12
E13: =SUM(C13:D13) -> 0 | H13: =E13+G13 -> 0 | M13: =SUM(I13:K13) -> 0 | O13: =C13+I13 -> 0 | P13: =D13+J13+K13 -> 0 | Q13: =SUM(O13:P13) -> 0 | R13: =F13+J13+L13 | T13: =Q13+S13 -> 0
E14: =SUM(C14:D14) -> 0 | H14: =E14+G14 -> 0 | M14: =SUM(I14:K14) -> 0 | O14: =C14+I14 -> 0 | P14: =D14+J14+K14 -> 0 | Q14: =SUM(O14:P14) -> 0 | R14: =F14+J14+L14 | T14: =Q14+S14 -> 0
E15: =SUM(C15:D15) -> 0 | H15: =E15+G15 -> 0 | M15: =SUM(I15:K15) -> 0 | O15: =C15+I15 -> 0 | P15: =D15+J15+K15 -> 0 | Q15: =SUM(O15:P15) -> 0 | R15: =F15+J15+L15 | T15: =Q15+S15 -> 0
E16: =SUM(C16:D16) -> 0 | H16: =E16+G16 -> 0 | M16: =SUM(I16:K16) -> 0 | O16: =C16+I16 -> 0 | P16: =D16+J16+K16 -> 0 | Q16: =SUM(O16:P16) -> 0 | R16: =F16+J16+L16 | T16: =Q16+S16 -> 0
E17: =SUM(C17:D17) -> 0 | H17: =E17+G17 -> 0 | M17: =SUM(I17:K17) -> 0 | O17: =C17+I17 -> 0 | P17: =D17+J17+K17 -> 0 | Q17: =SUM(O17:P17) -> 0 | R17: =F17+J17+L17 | T17: =Q17+S17 -> 0
E18: =SUM(C18:D18) -> 0 | H18: =E18+G18 -> 0 | M18: =SUM(I18:K18) -> 0 | O18: =C18+I18 -> 0 | P18: =D18+J18+K18 -> 0 | Q18: =SUM(O18:P18) -> 0 | R18: =F18+J18+L18 | T18: =Q18+S18 -> 0
E19: =SUM(C19:D19) -> 0 | H19: =E19+G19 -> 0 | M19: =SUM(I19:K19) -> 0 | O19: =C19+I19 -> 0 | P19: =D19+J19+K19 -> 0 | Q19: =SUM(O19:P19) -> 0 | R19: =F19+J19+L19 | T19: =Q19+S19 -> 0
E20: =SUM(C20:D20) -> 0 | H20: =E20+G20 -> 0 | M20: =SUM(I20:K20) -> 0 | O20: =C20+I20 -> 0 | P20: =D20+J20+K20 -> 0 | Q20: =SUM(O20:P20) -> 0 | R20: =F20+J20+L20 | T20: =Q20+S20 -> 0
A21: 合计 | C21: =SUM(C11:C20) -> 0 | D21: =SUM(D11:D20) -> 0 | E21: =SUM(E11:E20) -> 0 | F21: =SUM(F11:F20) -> 0 | G21: =SUM(G11:G20) -> 0 | H21: =SUM(H11:H20) -> 0 | I21: =SUM(I11:I20) -> 0 | J21: =SUM(J11:J20) -> 0 | ... T21: =SUM(T11:T20) -> 0
A22: 三、审计说明： | N22: =A22 -> 三、审计说明：
A26: 四、审计结论： | N26: =A26 -> 四、审计结论：
A28: 注1：权益工具投资一般不符合本金加利息的合同现金流量特征，因此应当分类为以公允价值计量且其变动计入当期损益的金融资产。然而在初始确认时，企业可以将非交易性权益工具投资指定为以公允价值计量且其变动计入其他综合收益的金融资产。该指定一经作出，不得撤销。
A29: 注2：股利收入的确认条件：（1）企业收取股利的权利已经确立——权益工具发行方宣布股利时；（2）与股利相关的经济利益很可能流入企业；（3）股利的金额能够可靠计量。
A30: 注3：终止确认时（包括处置、转为长期股权投资），之前计入其他综合收益的累计利得或损失应当从其他综合收益中转出，计入留存收益（盈余公积、未分配利润）。
A31: 提示：
A32: 1.根据《中国注册会计师审计准则问题解答第18号——识别和应对第三方配合实施财务舞弊》：当期存在大额对外投资时，需考虑是否存在通过被审计单位将资金投入被投资单位，
A33: 再从被投资单位套取资金（如投资私募基金后，在私募基金配合下将投资款从私募基金转出），如果还识别出被审计单位存在可能导致关联方资金占用以及其他套取资金行为的舞弊风险因素，则很可能表面存在第三方配合舞弊，应采取恰当的措施应对。
A34: 2.审计说明可以概述:(1)程序的测试情况、结果;(2)拟调整事项及其调整分录、未调整事项及其影响，审计范围受到限制情况及其影响。
A35: 3.审计结论可参考:A、未见异常。 B、除上述重大不符事项应当作为调整事项予以调整外，其余未见异常。由于存在以下重大未调整事项(或审计范围受到限制无法获取充分、适当证据)，不可确认。

Sheet 调整分录汇总G8-3
A1: 致同会计师事务所
A2: 其他权益工具投资调整分录汇总表
A3: =底稿目录!A2 -> 被审计单位： | D3: =底稿目录!A4 -> 编制人： | G3: =底稿目录!A5 -> 编制日期： | I3: 索引号： | J3: =底稿目录!F9 -> G8-3
A4: =底稿目录!A3 -> 截止日：202X年12月31日 | D4: =底稿目录!A6 -> 复核人： | G4: =底稿目录!A7 -> 复核日期： | I4: 页 次：1
A5: 调整事项说明 | B5: 类别（报表调整/账项调整/其他） | C5: 报表项目 | D5: 科目名称 | E5: 附注项目 | F5: …… | G5: 借方调整金额 | H5: 贷方调整金额 | I5: 索引 | J5: 备注

Sheet 公允价值测试表G8-4
A1: 致同会计师事务所
A2: 公允价值测试表
A3: =底稿目录!A2 -> 被审计单位： | F3: =底稿目录!A4 -> 编制人： | J3: =底稿目录!A5 -> 编制日期： | R3: 索引号： | S3: =底稿目录!F10 -> G8-4
A4: =底稿目录!A3 -> 截止日：202X年12月31日 | F4: =底稿目录!A6 -> 复核人： | J4: =底稿目录!A7 -> 复核日期： | R4: 页 次：
A5: 一、审计目标 | C5: 确定被审计单位其他权益工具投资以公允价值计量。
A6: 二、审计过程
A7: 被投资单位名称 | B7: 初始投资日期 | C7: 期末未审数 | G7: 期末审定数 | K7: 差异 | L7: 估值方法 | M7: 估值方法与上期是否一致 | N7: 第一层次 | O7: 第二层次 | P7: 第三层次 | S7: 估值文件索引号
C8: 数量（张/股） | D8: 单位公允价值 | E8: 公允价值 | F8: 公允价值层次 | G8: 数量（张/股） | H8: 单位公允价值 | I8: 公允价值 | J8: 公允价值层次 | N8: 公允价值来源机构 | O8: 输入值来源及调整考虑因素 | P8: 估值技术 | Q8: 不可观察输入值 | R8: 数值
A9: ='明细表G8-2'!A11 -> 0 | E9: =C9*D9 -> 0 | F9: 第二层次 | I9: =G9*H9 -> 0 | J9: 第二层次 | K9: =I9-E9 -> 0 | P9: 市场法（可比公司法） | Q9: EBITDA乘数 非流通折价 | R9: 10 17%
A10: ='明细表G8-2'!A12 -> 0 | E10: =C10*D10 -> 0 | I10: =G10*H10 -> 0 | J10: 第三层次 | K10: =I10-E10 -> 0 | P10: 收益法（折现现金流量法） | Q10: 加权平均资本成本 长期收入增长率 长期税前营业利润率 非流通折价 | R10: 16% 2% 10.3% 20%
A11: ='明细表G8-2'!A13 -> 0 | I11: =G11*H11 -> 0 | K11: =I11-E11 -> 0
A12: ='明细表G8-2'!A14 -> 0 | I12: =G12*H12 -> 0 | K12: =I12-E12 -> 0
A13: ='明细表G8-2'!A15 -> 0 | I13: =G13*H13 -> 0 | K13: =I13-E13 -> 0
A14: ='明细表G8-2'!A16 -> 0 | I14: =G14*H14 -> 0 | K14: =I14-E14 -> 0
A15: ='明细表G8-2'!A17 -> 0 | I15: =G15*H15 -> 0 | K15: =I15-E15 -> 0
A16: ='明细表G8-2'!A18 -> 0 | I16: =G16*H16 -> 0 | K16: =I16-E16 -> 0
A17: ='明细表G8-2'!A19 -> 0 | I17: =G17*H17 -> 0 | K17: =I17-E17 -> 0
A18: ='明细表G8-2'!A20 -> 0 | I18: =G18*H18 -> 0 | K18: =I18-E18 -> 0
A19: 合计 | E19: =SUM(E9:E18) -> 0 | I19: =SUM(I9:I18) -> 0 | K19: =SUM(K9:K18) -> 0
A20: 三、审计说明：
A21: 了解专家资质及利用估值专家的工作详见：B21、C25、S12、S13
A24: 四、审计结论：
A26: 编制说明：
A27: 1、公允价值的层次
A28: （1）第一层次——相同资产或负债在活跃市场中的报价（未经调整的）。只有在交易所或活跃指数/市场上进行交易的工具才能归入第一层次。
A29: 这一层次包括上市的权益证券和债权工具以及交易所交易的衍生产品如股指期货（基于Nasdaq、S&P500等指数）等。
A30: （2）第二层次——直接（即价格）或间接（即从价格推导出）地使用除第一层次中的资产或负债的市场报价之外的可观察输入值。
A31: 这一层次包括大部分场外交易的衍生工具和债券，交易性贷款和发行的结构型债务工具。
A32: （3）第三层次——资产或负债使用了任何非基于可观察市场数据的输入值（不可观察输入值）。
A33: 这一层次包括一项或多项重大输入为不可观察变量的股权和债券工具。所采用的估值模型通常为现金流折现模型。
A35: 2、概述：（1）程序的测试情况、结果；
... A37: 参考结论：
A38: A、 | C38: 未见异常。
A39: B、 | C39: 除以下重大不符事项应当作为调整事项予以调整外，其余未见异常。
A40: C、 | C40: 由于存在以下重大未调整事项（或审计范围受到限制无法获取充分、适当证据），不可确认。

Sheet 指定的适当性检查表G8-5
A1: 致同会计师事务所
A2: 指定为其他权益工具投资的适当性检查表
A3: =底稿目录!A2 -> 被审计单位： | D3: =底稿目录!A4 -> 编制人： | F3: =底稿目录!A5 -> 编制日期： | G3: 索引号： | H3: =底稿目录!F11 -> G8-5
A4: =底稿目录!A3 -> 截止日：202X年12月31日 | D4: =底稿目录!A6 -> 复核人： | F4: =底稿目录!A7 -> 复核日期： | G4: 页 次：
A5: 一、审计目标 | B5: 债权投资以恰当的金额包括在财务报表中，与之相关的计价或分摊调整已恰当记录，相关披露已得到恰当计量和描述
A6: 二、审计过程 | B6: 1. 其他权益工具投资的指定是否符合准则要求、会计处理是否合理并与前期一致。
B7: 2. 就管理层将投资确定为非交易性的目的获取书面声明，询问管理层持有相关资产的目的，实施以下程序印证管理层的答复，确定相关资产的分类是否正确：
B8: 2.1 考虑管理层以前所述的对于投资持有目的的实际实施情况；
B9: 2.2 复核包括预算、管理层会议纪要等在内的文件和报告记录，检查管理层是否对投资的持有目的进行了明确的书面指定；
B10: 3. 与管理层讨论金融资产分类是否符合企业会计准则，是否根据确定的分类选用了正确的核算方法。 | F10: 2.3 考虑管理层选择指定为其他权益工具投资的理由。
B11: 4. 是否发现管理层在以前年度运用的重大判断和估计存在不合理的情形。如果存在，记录管理层是否在当年进行了恰当的会计处理和披露，并选用了更为准确的判断和假设。
A12: 被投资单位名称 | B12: 期末账面价值 | C12: “非交易性”[需不属于下列任一情形之一] | F12: “权益工具投资”[需满足】 | H12: 书面文件索引号
C13: 取得相关金融资产的目的，主要是为了近期出售或回购 | D13: 相关金融资产在初始确认时属于集中管理的可辨认金融工具组合的一部分，且有客观证据表明近期实际存在短期获利模式 | E13: 相关金融资产属于衍生工具（但符合财务担保合同定义的衍生工具以及被指定为有效套期工具的衍生工具除外） | F13: 对于工具发行方来说，满足《企业会计准则第37号——金融工具列报》中权益工具定义 | G13: 不属于：可回售工具（如开放式基金）或发行方仅在清算时才有义务向另一方按比例交付其净资产的金融工具（如合伙企业约定了固定期限、封闭式基金、理财产品的份额、信托计划等寿命固定的结构化主体的份额，实务中也称有限寿命工具）
A14: ='明细表G8-2'!A11 -> 0 | B14: ='明细表G8-2'!Q11 -> 0 | C14: 否 | D14: 否 | E14: 否 | F14: 满足 | G14: 满足
A15: ='明细表G8-2'!A12 -> 0 | B15: ='明细表G8-2'!Q12 -> 0
A16: ='明细表G8-2'!A13 -> 0 | B16: ='明细表G8-2'!Q13 -> 0
A17: ='明细表G8-2'!A14 -> 0 | B17: ='明细表G8-2'!Q14 -> 0
A18: ='明细表G8-2'!A15 -> 0 | B18: ='明细表G8-2'!Q15 -> 0
A19: ='明细表G8-2'!A16 -> 0 | B19: ='明细表G8-2'!Q16 -> 0
A20: ='明细表G8-2'!A17 -> 0 | B20: ='明细表G8-2'!Q17 -> 0
A21: ='明细表G8-2'!A18 -> 0 | B21: ='明细表G8-2'!Q18 -> 0
A22: ='明细表G8-2'!A19 -> 0 | B22: ='明细表G8-2'!Q19 -> 0
A23: ='明细表G8-2'!A20 -> 0 | B23: ='明细表G8-2'!Q20 -> 0
A24: 合计 | B24: =SUM(B14:B23) -> 0
A25: 三、审计说明：
A27: 四、审计结论
A31: 注1：权益工具，是指能证明拥有某个企业在扣除所有负债后的资产中的剩余权益的合同。
A32: 注2：符合金融负债定义但是被分类为权益工具的特殊金融工具（包括可回售工具和发行方仅在清算时才有义务向另一方按比例交付其净资产的金融工具）本身并不符合权益工具的定义，因此从投资方的角度也就不符合
A33: 指定为以公允价值计量且其变动计入其他综合收益的金融资产的条件。
A34: 注3：可回售工具，是指根据合同约定，持有方有权将该工具回售给发行方以获取现金或其他金融资产的权利，或者在未来某一不确定事项发生或者持有方死亡或退休时，自动回售给发行方的金融工具。例如某些合作制法人的
A35: 可随时回售的“权益”或者某些开放式基金的可随时赎回的基金份额。
A36: 注4：发行方仅在清算时才有义务向另一方按比例交付其净资产的金融工具，产生上述合同义务的清算确定将会发生并且不受发行方的控制（如发行方本身是有限寿命主体），或者发生与否取决于该工具的持有方。

Sheet 凭证检查表G8-6
A1: 致同会计师事务所
A2: 其他权益工具投资凭证检查表
A3: =底稿目录!A2 -> 被审计单位： | E3: =底稿目录!A4 -> 编制人： | J3: =底稿目录!A5 -> 编制日期： | P3: 索引号： | Q3: =底稿目录!F20 -> G8-6
A4: =底稿目录!A3 -> 截止日：202X年12月31日 | E4: =底稿目录!A6 -> 复核人： | J4: =底稿目录!A7 -> 复核日期： | P4: 页 次：
A5: 一、审计目标
A6: 1.资产负债表中记录的交易性金融资产是存在的，且已经记录在恰当的账户中；2.记录的交易性金融资产由被审计单位拥有或控制；
A7: 3.交易性金融资产以恰当的金额包括在财务报表中，与之相关的计价或分摊调整已恰当记录，相关披露已得到恰当计量和描述
A8: 二、样本选取标准与规模：
A9: 测试总体： | B9: 如借方发生额所有凭证共XX笔金额XX、贷方发生额所有凭证共XX笔金额XX | G9: 特定样本： | H9: XX金额以上（大额）、关联方/关联交易形成的款项、XX异常款项全部测试，共XX笔；
A10: 抽样总体： | B10: 测试总体扣除特定样本以外的样本，共XX笔、金额XX | G10: 确定的抽样样本量： | H10: 抽取XX笔（如果使用了样本计算器计算样本量，样本量计算过程见<XX>底稿）
A11: 抽样方法： | B11: 随机选样/系统选样/货币单元抽样/随意选样（非统计抽样适用） | G11: 抽样过程： | H11: 使用IDEA（XX抽样工具）选择XX数量、金额XX的样本进行测试，抽样工具中的样本选择过程和结果见<XX>底稿
A12: 三、测试：
A13: 测试内容说明：1.原始凭证内容完整；2.有授权批准；3.账务处理正确；4.初始成本计算正确；5.股利收入处理正确；6.公允价值符合准则要求。
A14: 1.本期发生额检查
A15: 记账凭证 | H15: 支持性文件 | I15: 核对内容 | O15: 索引号 | P15: 是否异常 | Q15: 备注说明
A16: 日期 | B16: 凭证编号 | C16: 业务内容 | D16: 对方科目 | E16: 明细科目 | F16: 借方金额 | G16: 贷方金额 | I16: 1 | J16: 2 | K16: 3 | L16: 4 | M16: 5 | N16: 6
H17: 付款审批单、银行回单、投资协议、交易确认单、……
A28: 合计 | F28: =SUM(F17:F27) -> 0 | G28: =SUM(G17:G27) -> 0
A29: 本期发生额
A30: 检查比例 | F30: =F28/F29 -> #DIV/0! | G30: =G28/G29 -> #DIV/0!
A31: 2.期后处置、新增检查表
C32: 记账凭证 | H32: 支持性文件 | I32: 核对内容 | O32: 索引号 | P32: 是否异常 | Q32: 备注说明
A33: 日期 | B33: 凭证编号 | C33: 业务内容 | D33: 对方科目 | E33: 对方明细科目 | F33: 借方金额 | G33: 贷方金额 | I33: 1 | J33: 2 | K33: 3 | L33: 4 | M33: 5 | N33: 6
O34: 123 | Q34: K1-17-1
A39: 合计 | F39: =SUM(F34:F38) -> 0 | G39: =SUM(G34:G38) -> 0
A40: 四、审计说明：
A43: 五、审计结论：
A47: 编制说明：
A48: 1、概述：（1）程序的测试情况、结果；
A49: （2）拟调整事项及其调整分录、未调整事项及其影响，审计范围受到限制情况及其影响。
A50: 参考结论：
A51: A、 | B51: 未见异常。
A52: B、 | B52: 除以下重大不符事项应当作为调整事项予以调整外，其余未见异常。
A53: C、 | B53: 由于存在以下重大未调整事项（或审计范围受到限制无法获取充分、适当证据），不可确认。
A55: 2、选取测试项目的方法：包括选取全部项目、选取特定项目和审计抽样。
A56: （1） | B56: 当存在下列情形之一时，注册会计师应当考虑选取全部项目进行测试：
B57: （一）总体由少量的大额项目构成；
B58: （二）存在特别风险且其他方法未提供充分、适当的审计证据；
B59: （三）由于信息系统自动执行的计算或其他程序具有重复性，对全部项目进行检查符合成本效益原则。
B61: 特别风险涉及的事项包括但不限于：
...

Sheet 参考中证协《非上市公司股权估值指引》
B2: 中证协《非上市公司股权估值指引》
